# 32-block urban grid. The command origin is the south-west corner, one block above the road surface.
# North-south streets
fill ~0 ~-1 ~0 ~4 ~-1 ~351 minecraft:gray_concrete
fill ~32 ~-1 ~0 ~36 ~-1 ~351 minecraft:gray_concrete
fill ~64 ~-1 ~0 ~68 ~-1 ~351 minecraft:gray_concrete
fill ~96 ~-1 ~0 ~100 ~-1 ~351 minecraft:gray_concrete
fill ~128 ~-1 ~0 ~132 ~-1 ~351 minecraft:gray_concrete
fill ~160 ~-1 ~0 ~168 ~-1 ~351 minecraft:gray_concrete
fill ~192 ~-1 ~0 ~196 ~-1 ~351 minecraft:gray_concrete
fill ~224 ~-1 ~0 ~228 ~-1 ~351 minecraft:gray_concrete
fill ~256 ~-1 ~0 ~260 ~-1 ~351 minecraft:gray_concrete
fill ~288 ~-1 ~0 ~292 ~-1 ~351 minecraft:gray_concrete
fill ~320 ~-1 ~0 ~324 ~-1 ~351 minecraft:gray_concrete
fill ~352 ~-1 ~0 ~356 ~-1 ~351 minecraft:gray_concrete
fill ~379 ~-1 ~0 ~383 ~-1 ~351 minecraft:gray_concrete
# East-west streets
fill ~0 ~-1 ~0 ~383 ~-1 ~4 minecraft:gray_concrete
fill ~0 ~-1 ~32 ~383 ~-1 ~36 minecraft:gray_concrete
fill ~0 ~-1 ~64 ~383 ~-1 ~68 minecraft:gray_concrete
fill ~0 ~-1 ~96 ~383 ~-1 ~100 minecraft:gray_concrete
fill ~0 ~-1 ~128 ~383 ~-1 ~132 minecraft:gray_concrete
fill ~0 ~-1 ~160 ~383 ~-1 ~168 minecraft:gray_concrete
fill ~0 ~-1 ~192 ~383 ~-1 ~196 minecraft:gray_concrete
fill ~0 ~-1 ~224 ~383 ~-1 ~228 minecraft:gray_concrete
fill ~0 ~-1 ~256 ~383 ~-1 ~260 minecraft:gray_concrete
fill ~0 ~-1 ~288 ~383 ~-1 ~292 minecraft:gray_concrete
fill ~0 ~-1 ~320 ~383 ~-1 ~324 minecraft:gray_concrete
fill ~0 ~-1 ~347 ~383 ~-1 ~351 minecraft:gray_concrete
# Central boulevard and markings
fill ~160 ~-1 ~0 ~168 ~-1 ~351 minecraft:black_concrete
fill ~164 ~-1 ~0 ~164 ~-1 ~351 minecraft:yellow_concrete
fill ~0 ~-1 ~160 ~383 ~-1 ~168 minecraft:black_concrete
fill ~0 ~-1 ~164 ~383 ~-1 ~164 minecraft:yellow_concrete
# Main sidewalks
fill ~158 ~-1 ~0 ~159 ~-1 ~351 minecraft:smooth_stone
fill ~169 ~-1 ~0 ~170 ~-1 ~351 minecraft:smooth_stone
fill ~0 ~-1 ~158 ~383 ~-1 ~159 minecraft:smooth_stone
fill ~0 ~-1 ~169 ~383 ~-1 ~170 minecraft:smooth_stone
# Southern elevated-highway footprint
fill ~0 ~-1 ~352 ~383 ~-1 ~383 minecraft:stone
fill ~0 ~0 ~362 ~383 ~0 ~374 minecraft:deepslate_tiles
fill ~0 ~1 ~361 ~383 ~1 ~361 minecraft:iron_bars
fill ~0 ~1 ~375 ~383 ~1 ~375 minecraft:iron_bars
fill ~0 ~1 ~368 ~383 ~1 ~368 minecraft:yellow_concrete
fill ~0 ~1 ~365 ~383 ~1 ~365 minecraft:white_concrete
fill ~0 ~1 ~371 ~383 ~1 ~371 minecraft:white_concrete
# Broken interchange ramps at the western edge
fill ~0 ~0 ~336 ~31 ~0 ~343 minecraft:deepslate_tiles
fill ~8 ~1 ~344 ~39 ~1 ~351 minecraft:deepslate_tiles
fill ~16 ~2 ~352 ~47 ~2 ~359 minecraft:deepslate_tiles
fill ~24 ~3 ~360 ~55 ~3 ~367 minecraft:deepslate_tiles
fill ~32 ~4 ~368 ~63 ~4 ~375 minecraft:deepslate_tiles
fill ~48 ~4 ~368 ~55 ~4 ~375 minecraft:air
fill ~56 ~4 ~368 ~63 ~4 ~375 minecraft:air
# Rail and freight corridor
fill ~224 ~-1 ~326 ~351 ~-1 ~346 minecraft:gravel
fill ~224 ~0 ~330 ~351 ~0 ~330 minecraft:rail
fill ~224 ~0 ~335 ~351 ~0 ~335 minecraft:rail
fill ~224 ~0 ~340 ~351 ~0 ~340 minecraft:rail
fill ~224 ~0 ~345 ~351 ~0 ~345 minecraft:rail

