# Civic square / emergency assembly area
fill ~172 ~-1 ~172 ~195 ~-1 ~195 minecraft:stone_bricks
fill ~178 ~-1 ~178 ~189 ~-1 ~189 minecraft:mossy_stone_bricks
setblock ~183 ~0 ~183 minecraft:campfire
setblock ~184 ~0 ~183 minecraft:campfire
setblock ~183 ~0 ~184 minecraft:campfire
setblock ~184 ~0 ~184 minecraft:campfire
# Street trees and lamps: sparse, asymmetric, intentionally not pristine.
setblock ~20 ~0 ~20 minecraft:oak_sapling
setblock ~52 ~0 ~20 minecraft:oak_sapling
setblock ~84 ~0 ~52 minecraft:oak_sapling
setblock ~116 ~0 ~84 minecraft:oak_sapling
setblock ~20 ~0 ~116 minecraft:oak_sapling
setblock ~148 ~0 ~52 minecraft:oak_sapling
setblock ~180 ~0 ~20 minecraft:iron_bars
setblock ~180 ~1 ~20 minecraft:iron_bars
setblock ~180 ~2 ~20 minecraft:lantern
setblock ~212 ~0 ~52 minecraft:iron_bars
setblock ~212 ~1 ~52 minecraft:iron_bars
setblock ~212 ~2 ~52 minecraft:lantern
setblock ~244 ~0 ~148 minecraft:iron_bars
setblock ~244 ~1 ~148 minecraft:iron_bars
setblock ~244 ~2 ~148 minecraft:lantern
setblock ~308 ~0 ~180 minecraft:iron_bars
setblock ~308 ~1 ~180 minecraft:iron_bars
setblock ~308 ~2 ~180 minecraft:lantern
# Vacant lots, rubble and abandoned loading areas
fill ~38 ~-1 ~198 ~61 ~-1 ~221 minecraft:coarse_dirt
fill ~70 ~-1 ~198 ~93 ~-1 ~221 minecraft:gravel
fill ~102 ~-1 ~198 ~125 ~-1 ~221 minecraft:cracked_stone_bricks
setblock ~45 ~0 ~205 minecraft:iron_trapdoor
setblock ~51 ~0 ~211 minecraft:barrel
setblock ~78 ~0 ~214 minecraft:damaged_anvil
setblock ~111 ~0 ~207 minecraft:cobweb
setblock ~118 ~0 ~215 minecraft:grindstone
# Industrial containment and scrap silhouettes
fill ~262 ~0 ~294 ~285 ~2 ~317 minecraft:iron_bars
fill ~268 ~0 ~300 ~272 ~3 ~304 minecraft:oxidized_copper
fill ~278 ~0 ~306 ~282 ~4 ~312 minecraft:weathered_copper
setblock ~238 ~0 ~304 minecraft:yellow_concrete
setblock ~239 ~0 ~304 minecraft:black_concrete
setblock ~240 ~0 ~304 minecraft:yellow_concrete
# City editing reference corners
setblock ~0 ~0 ~0 minecraft:lime_concrete
setblock ~383 ~0 ~0 minecraft:lime_concrete
setblock ~0 ~0 ~383 minecraft:lime_concrete
setblock ~383 ~0 ~383 minecraft:lime_concrete
