# Buildings 169..176
# 169 small_office style=bay_office context=waterfront_front facing=north
fill ~114 ~-3 ~-70 ~119 ~-1 ~-63 minecraft:stone
fill ~114 ~0 ~-70 ~119 ~7 ~-63 minecraft:bricks
fill ~115 ~1 ~-69 ~118 ~6 ~-64 minecraft:air
fill ~115 ~4 ~-69 ~118 ~4 ~-64 minecraft:smooth_stone
fill ~116 ~2 ~-70 ~116 ~3 ~-70 minecraft:gray_stained_glass
fill ~116 ~2 ~-63 ~116 ~3 ~-63 minecraft:light_gray_stained_glass
fill ~114 ~2 ~-68 ~114 ~3 ~-68 minecraft:gray_stained_glass
fill ~119 ~2 ~-68 ~119 ~3 ~-68 minecraft:light_gray_stained_glass
fill ~114 ~2 ~-65 ~114 ~3 ~-65 minecraft:gray_stained_glass
fill ~119 ~2 ~-65 ~119 ~3 ~-65 minecraft:light_gray_stained_glass
setblock ~116 ~1 ~-70 minecraft:iron_door[half=lower,facing=north]
setblock ~116 ~2 ~-70 minecraft:iron_door[half=upper,facing=north]
fill ~115 ~1 ~-70 ~115 ~7 ~-70 minecraft:weathered_cut_copper
# 170 row_house style=japanese_house context=local_front facing=south
fill ~-64 ~-3 ~-119 ~-61 ~-1 ~-114 minecraft:stone
fill ~-64 ~0 ~-119 ~-61 ~5 ~-114 minecraft:stone_bricks
fill ~-63 ~1 ~-118 ~-62 ~4 ~-115 minecraft:air
fill ~-63 ~4 ~-118 ~-62 ~4 ~-115 minecraft:smooth_stone
fill ~-64 ~2 ~-117 ~-64 ~3 ~-117 minecraft:gray_stained_glass
fill ~-61 ~2 ~-117 ~-61 ~3 ~-117 minecraft:light_gray_stained_glass
setblock ~-62 ~1 ~-114 minecraft:iron_door[half=lower,facing=south]
setblock ~-62 ~2 ~-114 minecraft:iron_door[half=upper,facing=south]
fill ~-64 ~6 ~-119 ~-61 ~6 ~-114 minecraft:smooth_stone_slab
fill ~-63 ~7 ~-118 ~-62 ~7 ~-115 minecraft:smooth_stone_slab
setblock ~-62 ~3 ~-113 minecraft:dark_oak_slab[type=top]
# 171 small_office style=civic_modern context=collector_front facing=east
fill ~74 ~-3 ~-23 ~79 ~-1 ~-20 minecraft:stone
fill ~74 ~0 ~-23 ~79 ~7 ~-20 minecraft:bricks
fill ~75 ~1 ~-22 ~78 ~6 ~-21 minecraft:air
fill ~75 ~4 ~-22 ~78 ~4 ~-21 minecraft:smooth_stone
fill ~76 ~2 ~-23 ~76 ~3 ~-23 minecraft:gray_stained_glass
fill ~76 ~2 ~-20 ~76 ~3 ~-20 minecraft:light_gray_stained_glass
setblock ~79 ~1 ~-21 minecraft:iron_door[half=lower,facing=east]
setblock ~79 ~2 ~-21 minecraft:iron_door[half=upper,facing=east]
# 172 workshop style=loading_bay context=collector_front facing=north
fill ~-70 ~-3 ~-82 ~-67 ~-1 ~-77 minecraft:stone
fill ~-70 ~0 ~-82 ~-67 ~7 ~-77 minecraft:calcite
fill ~-69 ~1 ~-81 ~-68 ~6 ~-78 minecraft:air
fill ~-69 ~4 ~-81 ~-68 ~4 ~-78 minecraft:smooth_stone
fill ~-70 ~2 ~-80 ~-70 ~3 ~-80 minecraft:gray_stained_glass
fill ~-67 ~2 ~-80 ~-67 ~3 ~-80 minecraft:light_gray_stained_glass
setblock ~-68 ~1 ~-82 minecraft:iron_door[half=lower,facing=north]
setblock ~-68 ~2 ~-82 minecraft:iron_door[half=upper,facing=north]
fill ~-68 ~1 ~-82 ~-69 ~4 ~-82 minecraft:polished_blackstone
fill ~-68 ~5 ~-82 ~-69 ~5 ~-82 minecraft:light_blue_stained_glass
fill ~-68 ~9 ~-80 ~-68 ~10 ~-78 minecraft:iron_block
fill ~-70 ~8 ~-82 ~-67 ~8 ~-77 minecraft:stone_brick_slab
# 173 row_house style=stepped_house context=local_front facing=south
fill ~19 ~-3 ~-53 ~22 ~-1 ~-48 minecraft:stone
fill ~19 ~0 ~-53 ~22 ~11 ~-48 minecraft:white_terracotta
fill ~20 ~1 ~-52 ~21 ~10 ~-49 minecraft:air
fill ~20 ~4 ~-52 ~21 ~4 ~-49 minecraft:smooth_stone
fill ~20 ~8 ~-52 ~21 ~8 ~-49 minecraft:smooth_stone
fill ~19 ~2 ~-51 ~19 ~3 ~-51 minecraft:gray_stained_glass
fill ~22 ~2 ~-51 ~22 ~3 ~-51 minecraft:light_gray_stained_glass
fill ~19 ~6 ~-51 ~19 ~7 ~-51 minecraft:gray_stained_glass
fill ~22 ~6 ~-51 ~22 ~7 ~-51 minecraft:light_gray_stained_glass
setblock ~21 ~1 ~-48 minecraft:iron_door[half=lower,facing=south]
setblock ~21 ~2 ~-48 minecraft:iron_door[half=upper,facing=south]
fill ~19 ~12 ~-53 ~22 ~12 ~-48 minecraft:stone_brick_slab
fill ~20 ~13 ~-52 ~21 ~13 ~-49 minecraft:stone_brick_slab
setblock ~21 ~3 ~-47 minecraft:dark_oak_slab[type=top]
# 174 small_office style=civic_modern context=collector_front facing=west
fill ~-71 ~-3 ~-99 ~-65 ~-1 ~-95 minecraft:stone
fill ~-71 ~0 ~-99 ~-65 ~11 ~-95 minecraft:stone_bricks
fill ~-70 ~1 ~-98 ~-66 ~10 ~-96 minecraft:air
fill ~-70 ~4 ~-98 ~-66 ~4 ~-96 minecraft:smooth_stone
fill ~-70 ~8 ~-98 ~-66 ~8 ~-96 minecraft:smooth_stone
fill ~-69 ~2 ~-99 ~-69 ~3 ~-99 minecraft:gray_stained_glass
fill ~-69 ~2 ~-95 ~-69 ~3 ~-95 minecraft:light_gray_stained_glass
fill ~-71 ~2 ~-97 ~-71 ~3 ~-97 minecraft:gray_stained_glass
fill ~-65 ~2 ~-97 ~-65 ~3 ~-97 minecraft:light_gray_stained_glass
fill ~-69 ~6 ~-99 ~-69 ~7 ~-99 minecraft:gray_stained_glass
fill ~-69 ~6 ~-95 ~-69 ~7 ~-95 minecraft:light_gray_stained_glass
fill ~-71 ~6 ~-97 ~-71 ~7 ~-97 minecraft:gray_stained_glass
fill ~-65 ~6 ~-97 ~-65 ~7 ~-97 minecraft:light_gray_stained_glass
setblock ~-71 ~1 ~-97 minecraft:iron_door[half=lower,facing=west]
setblock ~-71 ~2 ~-97 minecraft:iron_door[half=upper,facing=west]
fill ~-71 ~7 ~-99 ~-65 ~11 ~-95 minecraft:air
fill ~-70 ~7 ~-98 ~-66 ~11 ~-96 minecraft:stone_bricks
fill ~-69 ~8 ~-97 ~-67 ~10 ~-97 minecraft:air
fill ~-70 ~12 ~-98 ~-66 ~12 ~-96 minecraft:smooth_stone_slab
fill ~-69 ~13 ~-97 ~-67 ~14 ~-96 minecraft:light_gray_concrete
setblock ~-66 ~13 ~-96 minecraft:lightning_rod
# 175 workshop style=industrial_shed context=arterial_front facing=west
fill ~-31 ~-3 ~-32 ~-25 ~-1 ~-28 minecraft:stone
fill ~-31 ~0 ~-32 ~-25 ~11 ~-28 minecraft:light_gray_concrete
fill ~-30 ~1 ~-31 ~-26 ~10 ~-29 minecraft:air
fill ~-30 ~4 ~-31 ~-26 ~4 ~-29 minecraft:smooth_stone
fill ~-30 ~8 ~-31 ~-26 ~8 ~-29 minecraft:smooth_stone
fill ~-29 ~2 ~-32 ~-29 ~3 ~-32 minecraft:gray_stained_glass
fill ~-29 ~2 ~-28 ~-29 ~3 ~-28 minecraft:light_gray_stained_glass
fill ~-31 ~2 ~-30 ~-31 ~3 ~-30 minecraft:gray_stained_glass
fill ~-25 ~2 ~-30 ~-25 ~3 ~-30 minecraft:light_gray_stained_glass
fill ~-29 ~6 ~-32 ~-29 ~7 ~-32 minecraft:gray_stained_glass
fill ~-29 ~6 ~-28 ~-29 ~7 ~-28 minecraft:light_gray_stained_glass
fill ~-31 ~6 ~-30 ~-31 ~7 ~-30 minecraft:gray_stained_glass
fill ~-25 ~6 ~-30 ~-25 ~7 ~-30 minecraft:light_gray_stained_glass
setblock ~-31 ~1 ~-30 minecraft:iron_door[half=lower,facing=west]
setblock ~-31 ~2 ~-30 minecraft:iron_door[half=upper,facing=west]
fill ~-31 ~1 ~-30 ~-31 ~4 ~-30 minecraft:polished_blackstone
fill ~-31 ~5 ~-30 ~-31 ~5 ~-30 minecraft:light_blue_stained_glass
fill ~-29 ~13 ~-30 ~-27 ~14 ~-29 minecraft:iron_block
fill ~-31 ~12 ~-32 ~-25 ~12 ~-28 minecraft:smooth_stone_slab
# 176 workshop style=sawtooth context=collector_front facing=east
fill ~73 ~-3 ~-50 ~79 ~-1 ~-46 minecraft:stone
fill ~73 ~0 ~-50 ~79 ~11 ~-46 minecraft:smooth_sandstone
fill ~74 ~1 ~-49 ~78 ~10 ~-47 minecraft:air
fill ~74 ~4 ~-49 ~78 ~4 ~-47 minecraft:smooth_stone
fill ~74 ~8 ~-49 ~78 ~8 ~-47 minecraft:smooth_stone
fill ~75 ~2 ~-50 ~75 ~3 ~-50 minecraft:gray_stained_glass
fill ~75 ~2 ~-46 ~75 ~3 ~-46 minecraft:light_gray_stained_glass
fill ~73 ~2 ~-48 ~73 ~3 ~-48 minecraft:gray_stained_glass
fill ~79 ~2 ~-48 ~79 ~3 ~-48 minecraft:light_gray_stained_glass
fill ~75 ~6 ~-50 ~75 ~7 ~-50 minecraft:gray_stained_glass
fill ~75 ~6 ~-46 ~75 ~7 ~-46 minecraft:light_gray_stained_glass
fill ~73 ~6 ~-48 ~73 ~7 ~-48 minecraft:gray_stained_glass
fill ~79 ~6 ~-48 ~79 ~7 ~-48 minecraft:light_gray_stained_glass
setblock ~79 ~1 ~-48 minecraft:iron_door[half=lower,facing=east]
setblock ~79 ~2 ~-48 minecraft:iron_door[half=upper,facing=east]
fill ~79 ~1 ~-48 ~79 ~4 ~-48 minecraft:polished_blackstone
fill ~79 ~5 ~-48 ~79 ~5 ~-48 minecraft:light_blue_stained_glass
fill ~75 ~13 ~-48 ~77 ~14 ~-47 minecraft:iron_block
fill ~73 ~12 ~-50 ~79 ~12 ~-46 minecraft:stone_brick_slab
