# Buildings 249..256
# 249 row_house style=rowhouse context=arterial_front facing=north
fill ~-113 ~-3 ~6 ~-110 ~-1 ~11 minecraft:stone
fill ~-113 ~0 ~6 ~-110 ~5 ~11 minecraft:white_terracotta
fill ~-112 ~1 ~7 ~-111 ~4 ~10 minecraft:air
fill ~-112 ~4 ~7 ~-111 ~4 ~10 minecraft:smooth_stone
fill ~-113 ~2 ~8 ~-113 ~3 ~8 minecraft:gray_stained_glass
fill ~-110 ~2 ~8 ~-110 ~3 ~8 minecraft:light_gray_stained_glass
setblock ~-111 ~1 ~6 minecraft:iron_door[half=lower,facing=north]
setblock ~-111 ~2 ~6 minecraft:iron_door[half=upper,facing=north]
fill ~-113 ~6 ~6 ~-110 ~6 ~11 minecraft:dark_oak_slab
fill ~-112 ~7 ~7 ~-111 ~7 ~10 minecraft:dark_oak_slab
setblock ~-111 ~3 ~5 minecraft:dark_oak_slab[type=top]
# 250 workshop style=loading_bay context=local_front facing=west
fill ~-62 ~-3 ~69 ~-57 ~-1 ~72 minecraft:stone
fill ~-62 ~0 ~69 ~-57 ~7 ~72 minecraft:smooth_sandstone
fill ~-61 ~1 ~70 ~-58 ~6 ~71 minecraft:air
fill ~-61 ~4 ~70 ~-58 ~4 ~71 minecraft:smooth_stone
fill ~-60 ~2 ~69 ~-60 ~3 ~69 minecraft:gray_stained_glass
fill ~-60 ~2 ~72 ~-60 ~3 ~72 minecraft:light_gray_stained_glass
setblock ~-62 ~1 ~71 minecraft:iron_door[half=lower,facing=west]
setblock ~-62 ~2 ~71 minecraft:iron_door[half=upper,facing=west]
fill ~-62 ~1 ~71 ~-62 ~4 ~70 minecraft:polished_blackstone
fill ~-62 ~5 ~71 ~-62 ~5 ~70 minecraft:light_blue_stained_glass
fill ~-60 ~9 ~71 ~-58 ~10 ~71 minecraft:iron_block
fill ~-62 ~8 ~69 ~-57 ~8 ~72 minecraft:stone_brick_slab
# 251 workshop style=industrial_shed context=local_front facing=south
fill ~-16 ~-3 ~17 ~-13 ~-1 ~22 minecraft:stone
fill ~-16 ~0 ~17 ~-13 ~9 ~22 minecraft:white_terracotta
fill ~-15 ~1 ~18 ~-14 ~8 ~21 minecraft:air
fill ~-15 ~4 ~18 ~-14 ~4 ~21 minecraft:smooth_stone
fill ~-15 ~8 ~18 ~-14 ~8 ~21 minecraft:smooth_stone
fill ~-16 ~2 ~19 ~-16 ~3 ~19 minecraft:gray_stained_glass
fill ~-13 ~2 ~19 ~-13 ~3 ~19 minecraft:light_gray_stained_glass
fill ~-16 ~6 ~19 ~-16 ~7 ~19 minecraft:gray_stained_glass
fill ~-13 ~6 ~19 ~-13 ~7 ~19 minecraft:light_gray_stained_glass
setblock ~-14 ~1 ~22 minecraft:iron_door[half=lower,facing=south]
setblock ~-14 ~2 ~22 minecraft:iron_door[half=upper,facing=south]
fill ~-14 ~1 ~22 ~-15 ~4 ~22 minecraft:polished_blackstone
fill ~-14 ~5 ~22 ~-15 ~5 ~22 minecraft:light_blue_stained_glass
fill ~-14 ~11 ~19 ~-14 ~12 ~21 minecraft:iron_block
fill ~-16 ~10 ~17 ~-13 ~10 ~22 minecraft:stone_brick_slab
# 252 small_office style=setback_tower context=arterial_front facing=north
fill ~-18 ~-3 ~6 ~-15 ~-1 ~11 minecraft:stone
fill ~-18 ~0 ~6 ~-15 ~11 ~11 minecraft:bricks
fill ~-17 ~1 ~7 ~-16 ~10 ~10 minecraft:air
fill ~-17 ~4 ~7 ~-16 ~4 ~10 minecraft:smooth_stone
fill ~-17 ~8 ~7 ~-16 ~8 ~10 minecraft:smooth_stone
fill ~-18 ~2 ~8 ~-18 ~3 ~8 minecraft:gray_stained_glass
fill ~-15 ~2 ~8 ~-15 ~3 ~8 minecraft:light_gray_stained_glass
fill ~-18 ~6 ~8 ~-18 ~7 ~8 minecraft:gray_stained_glass
fill ~-15 ~6 ~8 ~-15 ~7 ~8 minecraft:light_gray_stained_glass
setblock ~-16 ~1 ~6 minecraft:iron_door[half=lower,facing=north]
setblock ~-16 ~2 ~6 minecraft:iron_door[half=upper,facing=north]
fill ~-18 ~7 ~6 ~-15 ~11 ~11 minecraft:air
fill ~-17 ~7 ~7 ~-16 ~11 ~10 minecraft:bricks
fill ~-16 ~8 ~8 ~-17 ~10 ~9 minecraft:air
fill ~-17 ~12 ~7 ~-16 ~12 ~10 minecraft:deepslate_tile_slab
fill ~-16 ~13 ~8 ~-16 ~14 ~10 minecraft:light_gray_concrete
setblock ~-16 ~13 ~9 minecraft:lightning_rod
# 253 small_office style=bay_office context=local_front facing=north
fill ~51 ~-3 ~-96 ~54 ~-1 ~-91 minecraft:stone
fill ~51 ~0 ~-96 ~54 ~9 ~-91 minecraft:bricks
fill ~52 ~1 ~-95 ~53 ~8 ~-92 minecraft:air
fill ~52 ~4 ~-95 ~53 ~4 ~-92 minecraft:smooth_stone
fill ~52 ~8 ~-95 ~53 ~8 ~-92 minecraft:smooth_stone
fill ~51 ~2 ~-94 ~51 ~3 ~-94 minecraft:gray_stained_glass
fill ~54 ~2 ~-94 ~54 ~3 ~-94 minecraft:light_gray_stained_glass
fill ~51 ~6 ~-94 ~51 ~7 ~-94 minecraft:gray_stained_glass
fill ~54 ~6 ~-94 ~54 ~7 ~-94 minecraft:light_gray_stained_glass
setblock ~53 ~1 ~-96 minecraft:iron_door[half=lower,facing=north]
setblock ~53 ~2 ~-96 minecraft:iron_door[half=upper,facing=north]
# 254 workshop style=sawtooth context=local_front facing=east
fill ~52 ~-3 ~-45 ~57 ~-1 ~-42 minecraft:stone
fill ~52 ~0 ~-45 ~57 ~11 ~-42 minecraft:smooth_sandstone
fill ~53 ~1 ~-44 ~56 ~10 ~-43 minecraft:air
fill ~53 ~4 ~-44 ~56 ~4 ~-43 minecraft:smooth_stone
fill ~53 ~8 ~-44 ~56 ~8 ~-43 minecraft:smooth_stone
fill ~54 ~2 ~-45 ~54 ~3 ~-45 minecraft:gray_stained_glass
fill ~54 ~2 ~-42 ~54 ~3 ~-42 minecraft:light_gray_stained_glass
fill ~54 ~6 ~-45 ~54 ~7 ~-45 minecraft:gray_stained_glass
fill ~54 ~6 ~-42 ~54 ~7 ~-42 minecraft:light_gray_stained_glass
setblock ~57 ~1 ~-43 minecraft:iron_door[half=lower,facing=east]
setblock ~57 ~2 ~-43 minecraft:iron_door[half=upper,facing=east]
fill ~57 ~1 ~-43 ~57 ~4 ~-44 minecraft:polished_blackstone
fill ~57 ~5 ~-43 ~57 ~5 ~-44 minecraft:light_blue_stained_glass
fill ~54 ~13 ~-43 ~56 ~14 ~-43 minecraft:iron_block
fill ~52 ~12 ~-45 ~57 ~12 ~-42 minecraft:stone_brick_slab
# 255 workshop style=sawtooth context=local_front facing=west
fill ~-71 ~-3 ~-104 ~-65 ~-1 ~-100 minecraft:stone
fill ~-71 ~0 ~-104 ~-65 ~9 ~-100 minecraft:bricks
fill ~-70 ~1 ~-103 ~-66 ~8 ~-101 minecraft:air
fill ~-70 ~4 ~-103 ~-66 ~4 ~-101 minecraft:smooth_stone
fill ~-70 ~8 ~-103 ~-66 ~8 ~-101 minecraft:smooth_stone
fill ~-69 ~2 ~-104 ~-69 ~3 ~-104 minecraft:gray_stained_glass
fill ~-69 ~2 ~-100 ~-69 ~3 ~-100 minecraft:light_gray_stained_glass
fill ~-71 ~2 ~-102 ~-71 ~3 ~-102 minecraft:gray_stained_glass
fill ~-65 ~2 ~-102 ~-65 ~3 ~-102 minecraft:light_gray_stained_glass
fill ~-69 ~6 ~-104 ~-69 ~7 ~-104 minecraft:gray_stained_glass
fill ~-69 ~6 ~-100 ~-69 ~7 ~-100 minecraft:light_gray_stained_glass
fill ~-71 ~6 ~-102 ~-71 ~7 ~-102 minecraft:gray_stained_glass
fill ~-65 ~6 ~-102 ~-65 ~7 ~-102 minecraft:light_gray_stained_glass
setblock ~-71 ~1 ~-102 minecraft:iron_door[half=lower,facing=west]
setblock ~-71 ~2 ~-102 minecraft:iron_door[half=upper,facing=west]
fill ~-71 ~1 ~-102 ~-71 ~4 ~-102 minecraft:polished_blackstone
fill ~-71 ~5 ~-102 ~-71 ~5 ~-102 minecraft:light_blue_stained_glass
fill ~-69 ~11 ~-102 ~-67 ~12 ~-101 minecraft:iron_block
fill ~-71 ~10 ~-104 ~-65 ~10 ~-100 minecraft:deepslate_tile_slab
fill ~-69 ~11 ~-102 ~-67 ~12 ~-101 minecraft:light_gray_concrete
setblock ~-66 ~11 ~-101 minecraft:lightning_rod
# 256 row_house style=rowhouse context=arterial_front facing=north
fill ~115 ~-3 ~6 ~119 ~-1 ~12 minecraft:stone
fill ~115 ~0 ~6 ~119 ~9 ~12 minecraft:white_concrete
fill ~116 ~1 ~7 ~118 ~8 ~11 minecraft:air
fill ~116 ~4 ~7 ~118 ~4 ~11 minecraft:smooth_stone
fill ~116 ~8 ~7 ~118 ~8 ~11 minecraft:smooth_stone
fill ~117 ~2 ~6 ~117 ~3 ~6 minecraft:gray_stained_glass
fill ~117 ~2 ~12 ~117 ~3 ~12 minecraft:light_gray_stained_glass
fill ~115 ~2 ~8 ~115 ~3 ~8 minecraft:gray_stained_glass
fill ~119 ~2 ~8 ~119 ~3 ~8 minecraft:light_gray_stained_glass
fill ~117 ~6 ~6 ~117 ~7 ~6 minecraft:gray_stained_glass
fill ~117 ~6 ~12 ~117 ~7 ~12 minecraft:light_gray_stained_glass
fill ~115 ~6 ~8 ~115 ~7 ~8 minecraft:gray_stained_glass
fill ~119 ~6 ~8 ~119 ~7 ~8 minecraft:light_gray_stained_glass
setblock ~117 ~1 ~6 minecraft:iron_door[half=lower,facing=north]
setblock ~117 ~2 ~6 minecraft:iron_door[half=upper,facing=north]
fill ~115 ~10 ~6 ~119 ~10 ~12 minecraft:smooth_stone_slab
fill ~116 ~11 ~7 ~118 ~11 ~11 minecraft:smooth_stone_slab
setblock ~117 ~3 ~5 minecraft:dark_oak_slab[type=top]
