# Buildings 281..288
# 281 shop_house style=arcade_shop context=collector_front facing=west
fill ~-82 ~-3 ~94 ~-77 ~-1 ~97 minecraft:stone
fill ~-82 ~0 ~94 ~-77 ~11 ~97 minecraft:calcite
fill ~-81 ~1 ~95 ~-78 ~10 ~96 minecraft:air
fill ~-81 ~4 ~95 ~-78 ~4 ~96 minecraft:smooth_stone
fill ~-81 ~8 ~95 ~-78 ~8 ~96 minecraft:smooth_stone
fill ~-80 ~2 ~94 ~-80 ~3 ~94 minecraft:gray_stained_glass
fill ~-80 ~2 ~97 ~-80 ~3 ~97 minecraft:light_gray_stained_glass
fill ~-80 ~6 ~94 ~-80 ~7 ~94 minecraft:gray_stained_glass
fill ~-80 ~6 ~97 ~-80 ~7 ~97 minecraft:light_gray_stained_glass
setblock ~-82 ~1 ~96 minecraft:iron_door[half=lower,facing=west]
setblock ~-82 ~2 ~96 minecraft:iron_door[half=upper,facing=west]
fill ~-82 ~1 ~95 ~-82 ~3 ~96 minecraft:cyan_stained_glass
setblock ~-82 ~1 ~96 minecraft:iron_door[half=lower,facing=west]
setblock ~-82 ~2 ~96 minecraft:iron_door[half=upper,facing=west]
setblock ~-83 ~3 ~96 minecraft:red_wool
fill ~-82 ~4 ~95 ~-82 ~4 ~96 minecraft:gray_concrete
fill ~-82 ~12 ~94 ~-77 ~12 ~97 minecraft:stone_brick_slab
# 282 small_office style=bay_office context=local_front facing=north
fill ~29 ~-3 ~110 ~32 ~-1 ~115 minecraft:stone
fill ~29 ~0 ~110 ~32 ~5 ~115 minecraft:mud_bricks
fill ~30 ~1 ~111 ~31 ~4 ~114 minecraft:air
fill ~30 ~4 ~111 ~31 ~4 ~114 minecraft:smooth_stone
fill ~29 ~2 ~112 ~29 ~3 ~112 minecraft:gray_stained_glass
fill ~32 ~2 ~112 ~32 ~3 ~112 minecraft:light_gray_stained_glass
setblock ~31 ~1 ~110 minecraft:iron_door[half=lower,facing=north]
setblock ~31 ~2 ~110 minecraft:iron_door[half=upper,facing=north]
# 283 local_shop style=corner_store context=arterial_front facing=north
fill ~96 ~-3 ~-15 ~99 ~-1 ~-10 minecraft:stone
fill ~96 ~0 ~-15 ~99 ~9 ~-10 minecraft:bricks
fill ~97 ~1 ~-14 ~98 ~8 ~-11 minecraft:air
fill ~97 ~4 ~-14 ~98 ~4 ~-11 minecraft:smooth_stone
fill ~97 ~8 ~-14 ~98 ~8 ~-11 minecraft:smooth_stone
fill ~96 ~2 ~-13 ~96 ~3 ~-13 minecraft:gray_stained_glass
fill ~99 ~2 ~-13 ~99 ~3 ~-13 minecraft:light_gray_stained_glass
fill ~96 ~6 ~-13 ~96 ~7 ~-13 minecraft:gray_stained_glass
fill ~99 ~6 ~-13 ~99 ~7 ~-13 minecraft:light_gray_stained_glass
setblock ~98 ~1 ~-15 minecraft:iron_door[half=lower,facing=north]
setblock ~98 ~2 ~-15 minecraft:iron_door[half=upper,facing=north]
fill ~97 ~1 ~-15 ~98 ~3 ~-15 minecraft:cyan_stained_glass
setblock ~98 ~1 ~-15 minecraft:iron_door[half=lower,facing=north]
setblock ~98 ~2 ~-15 minecraft:iron_door[half=upper,facing=north]
setblock ~98 ~3 ~-16 minecraft:red_wool
fill ~96 ~10 ~-15 ~99 ~10 ~-10 minecraft:deepslate_tile_slab
# 284 shop_house style=storefront context=collector_front facing=south
fill ~-126 ~-3 ~34 ~-122 ~-1 ~40 minecraft:stone
fill ~-126 ~0 ~34 ~-122 ~9 ~40 minecraft:mud_bricks
fill ~-125 ~1 ~35 ~-123 ~8 ~39 minecraft:air
fill ~-125 ~4 ~35 ~-123 ~4 ~39 minecraft:smooth_stone
fill ~-125 ~8 ~35 ~-123 ~8 ~39 minecraft:smooth_stone
fill ~-124 ~2 ~34 ~-124 ~3 ~34 minecraft:gray_stained_glass
fill ~-124 ~2 ~40 ~-124 ~3 ~40 minecraft:light_gray_stained_glass
fill ~-126 ~2 ~36 ~-126 ~3 ~36 minecraft:gray_stained_glass
fill ~-122 ~2 ~36 ~-122 ~3 ~36 minecraft:light_gray_stained_glass
fill ~-124 ~6 ~34 ~-124 ~7 ~34 minecraft:gray_stained_glass
fill ~-124 ~6 ~40 ~-124 ~7 ~40 minecraft:light_gray_stained_glass
fill ~-126 ~6 ~36 ~-126 ~7 ~36 minecraft:gray_stained_glass
fill ~-122 ~6 ~36 ~-122 ~7 ~36 minecraft:light_gray_stained_glass
setblock ~-124 ~1 ~40 minecraft:iron_door[half=lower,facing=south]
setblock ~-124 ~2 ~40 minecraft:iron_door[half=upper,facing=south]
fill ~-125 ~1 ~40 ~-123 ~3 ~40 minecraft:cyan_stained_glass
setblock ~-124 ~1 ~40 minecraft:iron_door[half=lower,facing=south]
setblock ~-124 ~2 ~40 minecraft:iron_door[half=upper,facing=south]
setblock ~-124 ~3 ~41 minecraft:red_wool
fill ~-126 ~10 ~34 ~-122 ~10 ~40 minecraft:deepslate_tile_slab
# 285 workshop style=industrial_shed context=arterial_front facing=south
fill ~55 ~-3 ~-16 ~59 ~-1 ~-10 minecraft:stone
fill ~55 ~0 ~-16 ~59 ~7 ~-10 minecraft:bricks
fill ~56 ~1 ~-15 ~58 ~6 ~-11 minecraft:air
fill ~56 ~4 ~-15 ~58 ~4 ~-11 minecraft:smooth_stone
fill ~57 ~2 ~-16 ~57 ~3 ~-16 minecraft:gray_stained_glass
fill ~57 ~2 ~-10 ~57 ~3 ~-10 minecraft:light_gray_stained_glass
fill ~55 ~2 ~-14 ~55 ~3 ~-14 minecraft:gray_stained_glass
fill ~59 ~2 ~-14 ~59 ~3 ~-14 minecraft:light_gray_stained_glass
setblock ~57 ~1 ~-10 minecraft:iron_door[half=lower,facing=south]
setblock ~57 ~2 ~-10 minecraft:iron_door[half=upper,facing=south]
fill ~57 ~1 ~-10 ~57 ~4 ~-10 minecraft:polished_blackstone
fill ~57 ~5 ~-10 ~57 ~5 ~-10 minecraft:light_blue_stained_glass
fill ~57 ~9 ~-14 ~58 ~10 ~-12 minecraft:iron_block
fill ~55 ~8 ~-16 ~59 ~8 ~-10 minecraft:deepslate_tile_slab
# 286 row_house style=stepped_house context=arterial_front facing=west
fill ~-31 ~-3 ~-27 ~-25 ~-1 ~-23 minecraft:stone
fill ~-31 ~0 ~-27 ~-25 ~9 ~-23 minecraft:white_terracotta
fill ~-30 ~1 ~-26 ~-26 ~8 ~-24 minecraft:air
fill ~-30 ~4 ~-26 ~-26 ~4 ~-24 minecraft:smooth_stone
fill ~-30 ~8 ~-26 ~-26 ~8 ~-24 minecraft:smooth_stone
fill ~-29 ~2 ~-27 ~-29 ~3 ~-27 minecraft:gray_stained_glass
fill ~-29 ~2 ~-23 ~-29 ~3 ~-23 minecraft:light_gray_stained_glass
fill ~-31 ~2 ~-25 ~-31 ~3 ~-25 minecraft:gray_stained_glass
fill ~-25 ~2 ~-25 ~-25 ~3 ~-25 minecraft:light_gray_stained_glass
fill ~-29 ~6 ~-27 ~-29 ~7 ~-27 minecraft:gray_stained_glass
fill ~-29 ~6 ~-23 ~-29 ~7 ~-23 minecraft:light_gray_stained_glass
fill ~-31 ~6 ~-25 ~-31 ~7 ~-25 minecraft:gray_stained_glass
fill ~-25 ~6 ~-25 ~-25 ~7 ~-25 minecraft:light_gray_stained_glass
setblock ~-31 ~1 ~-25 minecraft:iron_door[half=lower,facing=west]
setblock ~-31 ~2 ~-25 minecraft:iron_door[half=upper,facing=west]
fill ~-31 ~10 ~-27 ~-25 ~10 ~-23 minecraft:stone_brick_slab
fill ~-30 ~11 ~-26 ~-26 ~11 ~-24 minecraft:stone_brick_slab
setblock ~-32 ~3 ~-25 minecraft:dark_oak_slab[type=top]
# 287 small_office style=civic_modern context=arterial_front facing=north
fill ~44 ~-3 ~6 ~47 ~-1 ~11 minecraft:stone
fill ~44 ~0 ~6 ~47 ~11 ~11 minecraft:bricks
fill ~45 ~1 ~7 ~46 ~10 ~10 minecraft:air
fill ~45 ~4 ~7 ~46 ~4 ~10 minecraft:smooth_stone
fill ~45 ~8 ~7 ~46 ~8 ~10 minecraft:smooth_stone
fill ~44 ~2 ~8 ~44 ~3 ~8 minecraft:gray_stained_glass
fill ~47 ~2 ~8 ~47 ~3 ~8 minecraft:light_gray_stained_glass
fill ~44 ~6 ~8 ~44 ~7 ~8 minecraft:gray_stained_glass
fill ~47 ~6 ~8 ~47 ~7 ~8 minecraft:light_gray_stained_glass
setblock ~46 ~1 ~6 minecraft:iron_door[half=lower,facing=north]
setblock ~46 ~2 ~6 minecraft:iron_door[half=upper,facing=north]
fill ~44 ~7 ~6 ~47 ~11 ~11 minecraft:air
fill ~45 ~7 ~7 ~46 ~11 ~10 minecraft:bricks
fill ~46 ~8 ~8 ~45 ~10 ~9 minecraft:air
fill ~45 ~12 ~7 ~46 ~12 ~10 minecraft:deepslate_tile_slab
# 288 workshop style=sawtooth context=local_front facing=west
fill ~67 ~-3 ~41 ~72 ~-1 ~44 minecraft:stone
fill ~67 ~0 ~41 ~72 ~9 ~44 minecraft:stone_bricks
fill ~68 ~1 ~42 ~71 ~8 ~43 minecraft:air
fill ~68 ~4 ~42 ~71 ~4 ~43 minecraft:smooth_stone
fill ~68 ~8 ~42 ~71 ~8 ~43 minecraft:smooth_stone
fill ~69 ~2 ~41 ~69 ~3 ~41 minecraft:gray_stained_glass
fill ~69 ~2 ~44 ~69 ~3 ~44 minecraft:light_gray_stained_glass
fill ~69 ~6 ~41 ~69 ~7 ~41 minecraft:gray_stained_glass
fill ~69 ~6 ~44 ~69 ~7 ~44 minecraft:light_gray_stained_glass
setblock ~67 ~1 ~43 minecraft:iron_door[half=lower,facing=west]
setblock ~67 ~2 ~43 minecraft:iron_door[half=upper,facing=west]
fill ~67 ~1 ~43 ~67 ~4 ~42 minecraft:polished_blackstone
fill ~67 ~5 ~43 ~67 ~5 ~42 minecraft:light_blue_stained_glass
fill ~69 ~11 ~43 ~71 ~12 ~43 minecraft:iron_block
fill ~67 ~10 ~41 ~72 ~10 ~44 minecraft:stone_brick_slab
fill ~69 ~11 ~43 ~71 ~12 ~43 minecraft:light_gray_concrete
setblock ~71 ~11 ~43 minecraft:lightning_rod
