# Buildings 225..232
# 225 row_house style=rowhouse context=waterfront_front facing=south
fill ~114 ~-3 ~-123 ~119 ~-1 ~-116 minecraft:stone
fill ~114 ~0 ~-123 ~119 ~5 ~-116 minecraft:white_concrete
fill ~115 ~1 ~-122 ~118 ~4 ~-117 minecraft:air
fill ~115 ~4 ~-122 ~118 ~4 ~-117 minecraft:smooth_stone
fill ~116 ~2 ~-123 ~116 ~3 ~-123 minecraft:gray_stained_glass
fill ~116 ~2 ~-116 ~116 ~3 ~-116 minecraft:light_gray_stained_glass
fill ~114 ~2 ~-121 ~114 ~3 ~-121 minecraft:gray_stained_glass
fill ~119 ~2 ~-121 ~119 ~3 ~-121 minecraft:light_gray_stained_glass
fill ~114 ~2 ~-118 ~114 ~3 ~-118 minecraft:gray_stained_glass
fill ~119 ~2 ~-118 ~119 ~3 ~-118 minecraft:light_gray_stained_glass
setblock ~116 ~1 ~-116 minecraft:iron_door[half=lower,facing=south]
setblock ~116 ~2 ~-116 minecraft:iron_door[half=upper,facing=south]
fill ~114 ~6 ~-123 ~119 ~6 ~-116 minecraft:smooth_stone_slab
fill ~115 ~7 ~-122 ~118 ~7 ~-117 minecraft:smooth_stone_slab
setblock ~116 ~3 ~-115 minecraft:dark_oak_slab[type=top]
fill ~115 ~1 ~-116 ~115 ~5 ~-116 minecraft:cyan_terracotta
# 226 local_shop style=arcade_shop context=collector_front facing=south
fill ~35 ~-3 ~58 ~40 ~-1 ~65 minecraft:stone
fill ~35 ~0 ~58 ~40 ~5 ~65 minecraft:bricks
fill ~36 ~1 ~59 ~39 ~4 ~64 minecraft:air
fill ~36 ~4 ~59 ~39 ~4 ~64 minecraft:smooth_stone
fill ~37 ~2 ~58 ~37 ~3 ~58 minecraft:gray_stained_glass
fill ~37 ~2 ~65 ~37 ~3 ~65 minecraft:light_gray_stained_glass
fill ~35 ~2 ~60 ~35 ~3 ~60 minecraft:gray_stained_glass
fill ~40 ~2 ~60 ~40 ~3 ~60 minecraft:light_gray_stained_glass
fill ~35 ~2 ~63 ~35 ~3 ~63 minecraft:gray_stained_glass
fill ~40 ~2 ~63 ~40 ~3 ~63 minecraft:light_gray_stained_glass
setblock ~37 ~1 ~65 minecraft:iron_door[half=lower,facing=south]
setblock ~37 ~2 ~65 minecraft:iron_door[half=upper,facing=south]
fill ~36 ~1 ~65 ~39 ~3 ~65 minecraft:cyan_stained_glass
setblock ~37 ~1 ~65 minecraft:iron_door[half=lower,facing=south]
setblock ~37 ~2 ~65 minecraft:iron_door[half=upper,facing=south]
setblock ~37 ~3 ~66 minecraft:red_wool
fill ~36 ~4 ~65 ~39 ~4 ~65 doomsday_decoration:hollowbrick
fill ~35 ~6 ~58 ~40 ~6 ~65 minecraft:deepslate_tile_slab
fill ~36 ~1 ~65 ~36 ~5 ~65 doomsday_decoration:hollowbrick
setblock ~37 ~3 ~65 minecraft:red_carpet
# 227 local_shop style=storefront context=collector_front facing=west
fill ~-82 ~-3 ~109 ~-76 ~-1 ~113 minecraft:stone
fill ~-82 ~0 ~109 ~-76 ~7 ~113 minecraft:mud_bricks
fill ~-81 ~1 ~110 ~-77 ~6 ~112 minecraft:air
fill ~-81 ~4 ~110 ~-77 ~4 ~112 minecraft:smooth_stone
fill ~-80 ~2 ~109 ~-80 ~3 ~109 minecraft:gray_stained_glass
fill ~-80 ~2 ~113 ~-80 ~3 ~113 minecraft:light_gray_stained_glass
fill ~-82 ~2 ~111 ~-82 ~3 ~111 minecraft:gray_stained_glass
fill ~-76 ~2 ~111 ~-76 ~3 ~111 minecraft:light_gray_stained_glass
setblock ~-82 ~1 ~111 minecraft:iron_door[half=lower,facing=west]
setblock ~-82 ~2 ~111 minecraft:iron_door[half=upper,facing=west]
fill ~-82 ~1 ~110 ~-82 ~3 ~112 minecraft:cyan_stained_glass
setblock ~-82 ~1 ~111 minecraft:iron_door[half=lower,facing=west]
setblock ~-82 ~2 ~111 minecraft:iron_door[half=upper,facing=west]
setblock ~-83 ~3 ~111 minecraft:red_wool
fill ~-82 ~8 ~109 ~-76 ~8 ~113 minecraft:deepslate_tile_slab
# 228 workshop style=sawtooth context=local_front facing=south
fill ~-115 ~-3 ~74 ~-112 ~-1 ~79 minecraft:stone
fill ~-115 ~0 ~74 ~-112 ~7 ~79 minecraft:white_terracotta
fill ~-114 ~1 ~75 ~-113 ~6 ~78 minecraft:air
fill ~-114 ~4 ~75 ~-113 ~4 ~78 minecraft:smooth_stone
fill ~-115 ~2 ~76 ~-115 ~3 ~76 minecraft:gray_stained_glass
fill ~-112 ~2 ~76 ~-112 ~3 ~76 minecraft:light_gray_stained_glass
setblock ~-113 ~1 ~79 minecraft:iron_door[half=lower,facing=south]
setblock ~-113 ~2 ~79 minecraft:iron_door[half=upper,facing=south]
fill ~-113 ~1 ~79 ~-114 ~4 ~79 minecraft:polished_blackstone
fill ~-113 ~5 ~79 ~-114 ~5 ~79 minecraft:light_blue_stained_glass
fill ~-113 ~9 ~76 ~-113 ~10 ~78 minecraft:iron_block
fill ~-115 ~8 ~74 ~-112 ~8 ~79 minecraft:dark_oak_slab
# 229 local_shop style=arcade_shop context=collector_front facing=west
fill ~52 ~-3 ~115 ~57 ~-1 ~118 minecraft:stone
fill ~52 ~0 ~115 ~57 ~9 ~118 minecraft:gray_concrete
fill ~53 ~1 ~116 ~56 ~8 ~117 minecraft:air
fill ~53 ~4 ~116 ~56 ~4 ~117 minecraft:smooth_stone
fill ~53 ~8 ~116 ~56 ~8 ~117 minecraft:smooth_stone
fill ~54 ~2 ~115 ~54 ~3 ~115 minecraft:gray_stained_glass
fill ~54 ~2 ~118 ~54 ~3 ~118 minecraft:light_gray_stained_glass
fill ~54 ~6 ~115 ~54 ~7 ~115 minecraft:gray_stained_glass
fill ~54 ~6 ~118 ~54 ~7 ~118 minecraft:light_gray_stained_glass
setblock ~52 ~1 ~117 minecraft:iron_door[half=lower,facing=west]
setblock ~52 ~2 ~117 minecraft:iron_door[half=upper,facing=west]
fill ~52 ~1 ~116 ~52 ~3 ~117 minecraft:cyan_stained_glass
setblock ~52 ~1 ~117 minecraft:iron_door[half=lower,facing=west]
setblock ~52 ~2 ~117 minecraft:iron_door[half=upper,facing=west]
setblock ~51 ~3 ~117 minecraft:red_wool
fill ~52 ~4 ~116 ~52 ~4 ~117 doomsday_decoration:ironsheetwall_1
fill ~52 ~10 ~115 ~57 ~10 ~118 minecraft:smooth_stone_slab
# 230 row_house style=japanese_house context=collector_front facing=east
fill ~-99 ~-3 ~58 ~-94 ~-1 ~61 minecraft:stone
fill ~-99 ~0 ~58 ~-94 ~5 ~61 minecraft:mud_bricks
fill ~-98 ~1 ~59 ~-95 ~4 ~60 minecraft:air
fill ~-98 ~4 ~59 ~-95 ~4 ~60 minecraft:smooth_stone
fill ~-97 ~2 ~58 ~-97 ~3 ~58 minecraft:gray_stained_glass
fill ~-97 ~2 ~61 ~-97 ~3 ~61 minecraft:light_gray_stained_glass
setblock ~-94 ~1 ~60 minecraft:iron_door[half=lower,facing=east]
setblock ~-94 ~2 ~60 minecraft:iron_door[half=upper,facing=east]
fill ~-99 ~6 ~58 ~-94 ~6 ~61 minecraft:deepslate_tile_slab
fill ~-98 ~7 ~59 ~-95 ~7 ~60 minecraft:deepslate_tile_slab
setblock ~-93 ~3 ~60 minecraft:dark_oak_slab[type=top]
# 231 shop_house style=arcade_shop context=collector_front facing=west
fill ~-92 ~-3 ~-42 ~-86 ~-1 ~-38 minecraft:stone
fill ~-92 ~0 ~-42 ~-86 ~11 ~-38 minecraft:smooth_sandstone
fill ~-91 ~1 ~-41 ~-87 ~10 ~-39 minecraft:air
fill ~-91 ~4 ~-41 ~-87 ~4 ~-39 minecraft:smooth_stone
fill ~-91 ~8 ~-41 ~-87 ~8 ~-39 minecraft:smooth_stone
fill ~-90 ~2 ~-42 ~-90 ~3 ~-42 minecraft:gray_stained_glass
fill ~-90 ~2 ~-38 ~-90 ~3 ~-38 minecraft:light_gray_stained_glass
fill ~-92 ~2 ~-40 ~-92 ~3 ~-40 minecraft:gray_stained_glass
fill ~-86 ~2 ~-40 ~-86 ~3 ~-40 minecraft:light_gray_stained_glass
fill ~-90 ~6 ~-42 ~-90 ~7 ~-42 minecraft:gray_stained_glass
fill ~-90 ~6 ~-38 ~-90 ~7 ~-38 minecraft:light_gray_stained_glass
fill ~-92 ~6 ~-40 ~-92 ~7 ~-40 minecraft:gray_stained_glass
fill ~-86 ~6 ~-40 ~-86 ~7 ~-40 minecraft:light_gray_stained_glass
setblock ~-92 ~1 ~-40 minecraft:iron_door[half=lower,facing=west]
setblock ~-92 ~2 ~-40 minecraft:iron_door[half=upper,facing=west]
fill ~-92 ~1 ~-41 ~-92 ~3 ~-39 minecraft:cyan_stained_glass
setblock ~-92 ~1 ~-40 minecraft:iron_door[half=lower,facing=west]
setblock ~-92 ~2 ~-40 minecraft:iron_door[half=upper,facing=west]
setblock ~-93 ~3 ~-40 minecraft:red_wool
fill ~-92 ~4 ~-41 ~-92 ~4 ~-39 minecraft:brown_terracotta
fill ~-92 ~12 ~-42 ~-86 ~12 ~-38 minecraft:stone_brick_slab
fill ~-90 ~13 ~-40 ~-88 ~14 ~-39 minecraft:light_gray_concrete
setblock ~-87 ~13 ~-39 minecraft:lightning_rod
# 232 row_house style=rowhouse context=arterial_front facing=south
fill ~101 ~-3 ~-15 ~104 ~-1 ~-10 minecraft:stone
fill ~101 ~0 ~-15 ~104 ~5 ~-10 minecraft:bricks
fill ~102 ~1 ~-14 ~103 ~4 ~-11 minecraft:air
fill ~102 ~4 ~-14 ~103 ~4 ~-11 minecraft:smooth_stone
fill ~101 ~2 ~-13 ~101 ~3 ~-13 minecraft:gray_stained_glass
fill ~104 ~2 ~-13 ~104 ~3 ~-13 minecraft:light_gray_stained_glass
setblock ~103 ~1 ~-10 minecraft:iron_door[half=lower,facing=south]
setblock ~103 ~2 ~-10 minecraft:iron_door[half=upper,facing=south]
fill ~101 ~6 ~-15 ~104 ~6 ~-10 minecraft:deepslate_tile_slab
fill ~102 ~7 ~-14 ~103 ~7 ~-11 minecraft:deepslate_tile_slab
setblock ~103 ~3 ~-9 minecraft:dark_oak_slab[type=top]
