# Buildings 51..75
# 051 warehouse 56,50 66,62 h=10
fill ~56 ~-3 ~50 ~66 ~-1 ~62 minecraft:stone
fill ~56 ~0 ~50 ~66 ~10 ~62 minecraft:deepslate_bricks
fill ~57 ~1 ~51 ~65 ~9 ~61 minecraft:air
fill ~57 ~4 ~51 ~65 ~4 ~61 minecraft:smooth_stone
fill ~57 ~8 ~51 ~65 ~8 ~61 minecraft:smooth_stone
fill ~56 ~2 ~52 ~56 ~3 ~60 minecraft:gray_stained_glass
fill ~66 ~2 ~52 ~66 ~3 ~60 minecraft:light_gray_stained_glass
fill ~56 ~6 ~52 ~56 ~7 ~60 minecraft:gray_stained_glass
fill ~66 ~6 ~52 ~66 ~7 ~60 minecraft:light_gray_stained_glass
fill ~57 ~0 ~50 ~60 ~3 ~50 minecraft:oxidized_cut_copper
setblock ~58 ~1 ~50 minecraft:iron_door[half=lower,facing=north]
setblock ~58 ~2 ~50 minecraft:iron_door[half=upper,facing=north]
fill ~56 ~11 ~50 ~66 ~11 ~62 minecraft:deepslate_tile_slab
# 052 shop_house 64,-55 77,-44 h=10
fill ~64 ~-3 ~-55 ~77 ~-1 ~-44 minecraft:stone
fill ~64 ~0 ~-55 ~77 ~10 ~-44 minecraft:bricks
fill ~65 ~1 ~-54 ~76 ~9 ~-45 minecraft:air
fill ~65 ~4 ~-54 ~76 ~4 ~-45 minecraft:smooth_stone
fill ~65 ~8 ~-54 ~76 ~8 ~-45 minecraft:smooth_stone
fill ~66 ~2 ~-55 ~75 ~3 ~-55 minecraft:gray_stained_glass
fill ~66 ~2 ~-44 ~75 ~3 ~-44 minecraft:light_gray_stained_glass
fill ~66 ~6 ~-55 ~75 ~7 ~-55 minecraft:gray_stained_glass
fill ~66 ~6 ~-44 ~75 ~7 ~-44 minecraft:light_gray_stained_glass
fill ~65 ~0 ~-55 ~68 ~3 ~-55 doomsday_decoration:hollowbrick
setblock ~66 ~1 ~-55 minecraft:iron_door[half=lower,facing=north]
setblock ~66 ~2 ~-55 minecraft:iron_door[half=upper,facing=north]
fill ~64 ~11 ~-55 ~77 ~11 ~-44 minecraft:deepslate_tile_slab
# 053 market 100,10 105,22 h=7
fill ~100 ~-3 ~10 ~105 ~-1 ~22 minecraft:stone
fill ~100 ~0 ~10 ~105 ~7 ~22 minecraft:bricks
fill ~101 ~1 ~11 ~104 ~6 ~21 minecraft:air
fill ~101 ~4 ~11 ~104 ~4 ~21 minecraft:smooth_stone
fill ~102 ~2 ~10 ~103 ~3 ~10 minecraft:gray_stained_glass
fill ~102 ~2 ~22 ~103 ~3 ~22 minecraft:light_gray_stained_glass
fill ~101 ~0 ~10 ~104 ~3 ~10 minecraft:weathered_cut_copper
setblock ~102 ~1 ~10 minecraft:iron_door[half=lower,facing=north]
setblock ~102 ~2 ~10 minecraft:iron_door[half=upper,facing=north]
fill ~100 ~8 ~10 ~105 ~8 ~22 minecraft:deepslate_tile_slab
# 054 local_shop -121,1 -111,10 h=11
fill ~-121 ~-3 ~1 ~-111 ~-1 ~10 minecraft:stone
fill ~-121 ~0 ~1 ~-111 ~11 ~10 minecraft:calcite
fill ~-120 ~1 ~2 ~-112 ~10 ~9 minecraft:air
fill ~-120 ~4 ~2 ~-112 ~4 ~9 minecraft:smooth_stone
fill ~-120 ~8 ~2 ~-112 ~8 ~9 minecraft:smooth_stone
fill ~-121 ~2 ~3 ~-121 ~3 ~8 minecraft:gray_stained_glass
fill ~-111 ~2 ~3 ~-111 ~3 ~8 minecraft:light_gray_stained_glass
fill ~-121 ~6 ~3 ~-121 ~7 ~8 minecraft:gray_stained_glass
fill ~-111 ~6 ~3 ~-111 ~7 ~8 minecraft:light_gray_stained_glass
fill ~-120 ~0 ~1 ~-117 ~3 ~1 minecraft:gray_concrete
setblock ~-119 ~1 ~1 minecraft:iron_door[half=lower,facing=north]
setblock ~-119 ~2 ~1 minecraft:iron_door[half=upper,facing=north]
fill ~-121 ~12 ~1 ~-111 ~12 ~10 minecraft:stone_brick_slab
# 055 local_shop 87,-73 94,-63 h=9
fill ~87 ~-3 ~-73 ~94 ~-1 ~-63 minecraft:stone
fill ~87 ~0 ~-73 ~94 ~9 ~-63 minecraft:white_terracotta
fill ~88 ~1 ~-72 ~93 ~8 ~-64 minecraft:air
fill ~88 ~4 ~-72 ~93 ~4 ~-64 minecraft:smooth_stone
fill ~88 ~8 ~-72 ~93 ~8 ~-64 minecraft:smooth_stone
fill ~89 ~2 ~-73 ~92 ~3 ~-73 minecraft:gray_stained_glass
fill ~89 ~2 ~-63 ~92 ~3 ~-63 minecraft:light_gray_stained_glass
fill ~89 ~6 ~-73 ~92 ~7 ~-73 minecraft:gray_stained_glass
fill ~89 ~6 ~-63 ~92 ~7 ~-63 minecraft:light_gray_stained_glass
fill ~88 ~0 ~-73 ~91 ~3 ~-73 minecraft:dark_oak_planks
setblock ~89 ~1 ~-73 minecraft:iron_door[half=lower,facing=north]
setblock ~89 ~2 ~-73 minecraft:iron_door[half=upper,facing=north]
fill ~87 ~10 ~-73 ~94 ~10 ~-63 minecraft:dark_oak_slab
# 056 community -123,87 -112,94 h=7
fill ~-123 ~-3 ~87 ~-112 ~-1 ~94 minecraft:stone
fill ~-123 ~0 ~87 ~-112 ~7 ~94 minecraft:calcite
fill ~-122 ~1 ~88 ~-113 ~6 ~93 minecraft:air
fill ~-122 ~4 ~88 ~-113 ~4 ~93 minecraft:smooth_stone
fill ~-121 ~2 ~87 ~-114 ~3 ~87 minecraft:gray_stained_glass
fill ~-121 ~2 ~94 ~-114 ~3 ~94 minecraft:light_gray_stained_glass
fill ~-122 ~0 ~87 ~-119 ~3 ~87 minecraft:gray_concrete
setblock ~-121 ~1 ~87 minecraft:iron_door[half=lower,facing=north]
setblock ~-121 ~2 ~87 minecraft:iron_door[half=upper,facing=north]
fill ~-123 ~8 ~87 ~-112 ~8 ~94 minecraft:stone_brick_slab
# 057 detached_house -125,-68 -114,-61 h=7
fill ~-125 ~-3 ~-68 ~-114 ~-1 ~-61 minecraft:stone
fill ~-125 ~0 ~-68 ~-114 ~7 ~-61 minecraft:mud_bricks
fill ~-124 ~1 ~-67 ~-115 ~6 ~-62 minecraft:air
fill ~-124 ~4 ~-67 ~-115 ~4 ~-62 minecraft:smooth_stone
fill ~-123 ~2 ~-68 ~-116 ~3 ~-68 minecraft:gray_stained_glass
fill ~-123 ~2 ~-61 ~-116 ~3 ~-61 minecraft:light_gray_stained_glass
fill ~-124 ~0 ~-68 ~-121 ~3 ~-68 minecraft:spruce_planks
setblock ~-123 ~1 ~-68 minecraft:iron_door[half=lower,facing=north]
setblock ~-123 ~2 ~-68 minecraft:iron_door[half=upper,facing=north]
fill ~-125 ~8 ~-68 ~-114 ~8 ~-61 minecraft:deepslate_tile_slab
# 058 shop_house -70,38 -64,53 h=8
fill ~-70 ~-3 ~38 ~-64 ~-1 ~53 minecraft:stone
fill ~-70 ~0 ~38 ~-64 ~8 ~53 minecraft:light_gray_concrete
fill ~-69 ~1 ~39 ~-65 ~7 ~52 minecraft:air
fill ~-69 ~4 ~39 ~-65 ~4 ~52 minecraft:smooth_stone
fill ~-68 ~2 ~38 ~-66 ~3 ~38 minecraft:gray_stained_glass
fill ~-68 ~2 ~53 ~-66 ~3 ~53 minecraft:light_gray_stained_glass
fill ~-68 ~6 ~38 ~-66 ~7 ~38 minecraft:gray_stained_glass
fill ~-68 ~6 ~53 ~-66 ~7 ~53 minecraft:light_gray_stained_glass
fill ~-69 ~0 ~38 ~-66 ~3 ~38 doomsday_decoration:porcelainbrickwall
setblock ~-68 ~1 ~38 minecraft:iron_door[half=lower,facing=north]
setblock ~-68 ~2 ~38 minecraft:iron_door[half=upper,facing=north]
fill ~-70 ~9 ~38 ~-64 ~9 ~53 minecraft:smooth_stone_slab
# 059 restaurant 103,-4 108,5 h=5
fill ~103 ~-3 ~-4 ~108 ~-1 ~5 minecraft:stone
fill ~103 ~0 ~-4 ~108 ~5 ~5 minecraft:white_concrete
fill ~104 ~1 ~-3 ~107 ~4 ~4 minecraft:air
fill ~104 ~4 ~-3 ~107 ~4 ~4 minecraft:smooth_stone
fill ~103 ~2 ~-2 ~103 ~3 ~3 minecraft:gray_stained_glass
fill ~108 ~2 ~-2 ~108 ~3 ~3 minecraft:light_gray_stained_glass
fill ~104 ~0 ~-4 ~107 ~3 ~-4 minecraft:cyan_terracotta
setblock ~105 ~1 ~-4 minecraft:iron_door[half=lower,facing=north]
setblock ~105 ~2 ~-4 minecraft:iron_door[half=upper,facing=north]
fill ~103 ~6 ~-4 ~108 ~6 ~5 minecraft:smooth_stone_slab
# 060 community -58,83 -52,90 h=11
fill ~-58 ~-3 ~83 ~-52 ~-1 ~90 minecraft:stone
fill ~-58 ~0 ~83 ~-52 ~11 ~90 minecraft:calcite
fill ~-57 ~1 ~84 ~-53 ~10 ~89 minecraft:air
fill ~-57 ~4 ~84 ~-53 ~4 ~89 minecraft:smooth_stone
fill ~-57 ~8 ~84 ~-53 ~8 ~89 minecraft:smooth_stone
fill ~-58 ~2 ~85 ~-58 ~3 ~88 minecraft:gray_stained_glass
fill ~-52 ~2 ~85 ~-52 ~3 ~88 minecraft:light_gray_stained_glass
fill ~-58 ~6 ~85 ~-58 ~7 ~88 minecraft:gray_stained_glass
fill ~-52 ~6 ~85 ~-52 ~7 ~88 minecraft:light_gray_stained_glass
fill ~-57 ~0 ~83 ~-54 ~3 ~83 minecraft:gray_concrete
setblock ~-56 ~1 ~83 minecraft:iron_door[half=lower,facing=north]
setblock ~-56 ~2 ~83 minecraft:iron_door[half=upper,facing=north]
fill ~-58 ~12 ~83 ~-52 ~12 ~90 minecraft:stone_brick_slab
# 061 restaurant 67,-38 77,-30 h=12
fill ~67 ~-3 ~-38 ~77 ~-1 ~-30 minecraft:stone
fill ~67 ~0 ~-38 ~77 ~12 ~-30 minecraft:smooth_sandstone
fill ~68 ~1 ~-37 ~76 ~11 ~-31 minecraft:air
fill ~68 ~4 ~-37 ~76 ~4 ~-31 minecraft:smooth_stone
fill ~68 ~8 ~-37 ~76 ~8 ~-31 minecraft:smooth_stone
fill ~67 ~2 ~-36 ~67 ~3 ~-32 minecraft:gray_stained_glass
fill ~77 ~2 ~-36 ~77 ~3 ~-32 minecraft:light_gray_stained_glass
fill ~67 ~6 ~-36 ~67 ~7 ~-32 minecraft:gray_stained_glass
fill ~77 ~6 ~-36 ~77 ~7 ~-32 minecraft:light_gray_stained_glass
fill ~67 ~10 ~-36 ~67 ~11 ~-32 minecraft:gray_stained_glass
fill ~77 ~10 ~-36 ~77 ~11 ~-32 minecraft:light_gray_stained_glass
fill ~68 ~0 ~-38 ~71 ~3 ~-38 minecraft:brown_terracotta
setblock ~69 ~1 ~-38 minecraft:iron_door[half=lower,facing=north]
setblock ~69 ~2 ~-38 minecraft:iron_door[half=upper,facing=north]
fill ~67 ~13 ~-38 ~77 ~13 ~-30 minecraft:stone_brick_slab
# 062 midrise_housing 16,-6 24,2 h=16
fill ~16 ~-3 ~-6 ~24 ~-1 ~2 minecraft:stone
fill ~16 ~0 ~-6 ~24 ~16 ~2 minecraft:bricks
fill ~17 ~1 ~-5 ~23 ~15 ~1 minecraft:air
fill ~17 ~4 ~-5 ~23 ~4 ~1 minecraft:smooth_stone
fill ~17 ~8 ~-5 ~23 ~8 ~1 minecraft:smooth_stone
fill ~17 ~12 ~-5 ~23 ~12 ~1 minecraft:smooth_stone
fill ~16 ~2 ~-4 ~16 ~3 ~0 minecraft:gray_stained_glass
fill ~24 ~2 ~-4 ~24 ~3 ~0 minecraft:light_gray_stained_glass
fill ~16 ~6 ~-4 ~16 ~7 ~0 minecraft:gray_stained_glass
fill ~24 ~6 ~-4 ~24 ~7 ~0 minecraft:light_gray_stained_glass
fill ~16 ~10 ~-4 ~16 ~11 ~0 minecraft:gray_stained_glass
fill ~24 ~10 ~-4 ~24 ~11 ~0 minecraft:light_gray_stained_glass
fill ~16 ~14 ~-4 ~16 ~15 ~0 minecraft:gray_stained_glass
fill ~24 ~14 ~-4 ~24 ~15 ~0 minecraft:light_gray_stained_glass
fill ~17 ~0 ~-6 ~20 ~3 ~-6 doomsday_decoration:redbrick
setblock ~18 ~1 ~-6 minecraft:iron_door[half=lower,facing=north]
setblock ~18 ~2 ~-6 minecraft:iron_door[half=upper,facing=north]
fill ~16 ~17 ~-6 ~24 ~17 ~2 minecraft:deepslate_tile_slab
# 063 hotel -18,11 -9,20 h=24
fill ~-18 ~-3 ~11 ~-9 ~-1 ~20 minecraft:stone
fill ~-18 ~0 ~11 ~-9 ~24 ~20 minecraft:bricks
fill ~-17 ~1 ~12 ~-10 ~23 ~19 minecraft:air
fill ~-17 ~4 ~12 ~-10 ~4 ~19 minecraft:smooth_stone
fill ~-17 ~8 ~12 ~-10 ~8 ~19 minecraft:smooth_stone
fill ~-17 ~12 ~12 ~-10 ~12 ~19 minecraft:smooth_stone
fill ~-17 ~16 ~12 ~-10 ~16 ~19 minecraft:smooth_stone
fill ~-17 ~20 ~12 ~-10 ~20 ~19 minecraft:smooth_stone
fill ~-18 ~2 ~13 ~-18 ~3 ~18 minecraft:gray_stained_glass
fill ~-9 ~2 ~13 ~-9 ~3 ~18 minecraft:light_gray_stained_glass
fill ~-18 ~6 ~13 ~-18 ~7 ~18 minecraft:gray_stained_glass
fill ~-9 ~6 ~13 ~-9 ~7 ~18 minecraft:light_gray_stained_glass
fill ~-18 ~10 ~13 ~-18 ~11 ~18 minecraft:gray_stained_glass
fill ~-9 ~10 ~13 ~-9 ~11 ~18 minecraft:light_gray_stained_glass
fill ~-18 ~14 ~13 ~-18 ~15 ~18 minecraft:gray_stained_glass
fill ~-9 ~14 ~13 ~-9 ~15 ~18 minecraft:light_gray_stained_glass
fill ~-18 ~18 ~13 ~-18 ~19 ~18 minecraft:gray_stained_glass
fill ~-9 ~18 ~13 ~-9 ~19 ~18 minecraft:light_gray_stained_glass
fill ~-18 ~22 ~13 ~-18 ~23 ~18 minecraft:gray_stained_glass
fill ~-9 ~22 ~13 ~-9 ~23 ~18 minecraft:light_gray_stained_glass
fill ~-17 ~0 ~11 ~-14 ~3 ~11 doomsday_decoration:redbrick
setblock ~-16 ~1 ~11 minecraft:iron_door[half=lower,facing=north]
setblock ~-16 ~2 ~11 minecraft:iron_door[half=upper,facing=north]
fill ~-18 ~25 ~11 ~-9 ~25 ~20 minecraft:deepslate_tile_slab
# 064 detached_house -99,-63 -91,-50 h=9
fill ~-99 ~-3 ~-63 ~-91 ~-1 ~-50 minecraft:stone
fill ~-99 ~0 ~-63 ~-91 ~9 ~-50 minecraft:calcite
fill ~-98 ~1 ~-62 ~-92 ~8 ~-51 minecraft:air
fill ~-98 ~4 ~-62 ~-92 ~4 ~-51 minecraft:smooth_stone
fill ~-98 ~8 ~-62 ~-92 ~8 ~-51 minecraft:smooth_stone
fill ~-97 ~2 ~-63 ~-93 ~3 ~-63 minecraft:gray_stained_glass
fill ~-97 ~2 ~-50 ~-93 ~3 ~-50 minecraft:light_gray_stained_glass
fill ~-97 ~6 ~-63 ~-93 ~7 ~-63 minecraft:gray_stained_glass
fill ~-97 ~6 ~-50 ~-93 ~7 ~-50 minecraft:light_gray_stained_glass
fill ~-98 ~0 ~-63 ~-95 ~3 ~-63 minecraft:gray_concrete
setblock ~-97 ~1 ~-63 minecraft:iron_door[half=lower,facing=north]
setblock ~-97 ~2 ~-63 minecraft:iron_door[half=upper,facing=north]
fill ~-99 ~10 ~-63 ~-91 ~10 ~-50 minecraft:stone_brick_slab
# 065 clinic -69,25 -61,36 h=16
fill ~-69 ~-3 ~25 ~-61 ~-1 ~36 minecraft:stone
fill ~-69 ~0 ~25 ~-61 ~16 ~36 minecraft:light_gray_concrete
fill ~-68 ~1 ~26 ~-62 ~15 ~35 minecraft:air
fill ~-68 ~4 ~26 ~-62 ~4 ~35 minecraft:smooth_stone
fill ~-68 ~8 ~26 ~-62 ~8 ~35 minecraft:smooth_stone
fill ~-68 ~12 ~26 ~-62 ~12 ~35 minecraft:smooth_stone
fill ~-69 ~2 ~27 ~-69 ~3 ~34 minecraft:gray_stained_glass
fill ~-61 ~2 ~27 ~-61 ~3 ~34 minecraft:light_gray_stained_glass
fill ~-69 ~6 ~27 ~-69 ~7 ~34 minecraft:gray_stained_glass
fill ~-61 ~6 ~27 ~-61 ~7 ~34 minecraft:light_gray_stained_glass
fill ~-69 ~10 ~27 ~-69 ~11 ~34 minecraft:gray_stained_glass
fill ~-61 ~10 ~27 ~-61 ~11 ~34 minecraft:light_gray_stained_glass
fill ~-69 ~14 ~27 ~-69 ~15 ~34 minecraft:gray_stained_glass
fill ~-61 ~14 ~27 ~-61 ~15 ~34 minecraft:light_gray_stained_glass
fill ~-68 ~0 ~25 ~-65 ~3 ~25 doomsday_decoration:porcelainbrickwall
setblock ~-67 ~1 ~25 minecraft:iron_door[half=lower,facing=north]
setblock ~-67 ~2 ~25 minecraft:iron_door[half=upper,facing=north]
fill ~-69 ~17 ~25 ~-61 ~17 ~36 minecraft:smooth_stone_slab
# 066 small_office -6,46 7,59 h=24
fill ~-6 ~-3 ~46 ~7 ~-1 ~59 minecraft:stone
fill ~-6 ~0 ~46 ~7 ~24 ~59 minecraft:bricks
fill ~-5 ~1 ~47 ~6 ~23 ~58 minecraft:air
fill ~-5 ~4 ~47 ~6 ~4 ~58 minecraft:smooth_stone
fill ~-5 ~8 ~47 ~6 ~8 ~58 minecraft:smooth_stone
fill ~-5 ~12 ~47 ~6 ~12 ~58 minecraft:smooth_stone
fill ~-5 ~16 ~47 ~6 ~16 ~58 minecraft:smooth_stone
fill ~-5 ~20 ~47 ~6 ~20 ~58 minecraft:smooth_stone
fill ~-4 ~2 ~46 ~5 ~3 ~46 minecraft:gray_stained_glass
fill ~-4 ~2 ~59 ~5 ~3 ~59 minecraft:light_gray_stained_glass
fill ~-4 ~6 ~46 ~5 ~7 ~46 minecraft:gray_stained_glass
fill ~-4 ~6 ~59 ~5 ~7 ~59 minecraft:light_gray_stained_glass
fill ~-4 ~10 ~46 ~5 ~11 ~46 minecraft:gray_stained_glass
fill ~-4 ~10 ~59 ~5 ~11 ~59 minecraft:light_gray_stained_glass
fill ~-4 ~14 ~46 ~5 ~15 ~46 minecraft:gray_stained_glass
fill ~-4 ~14 ~59 ~5 ~15 ~59 minecraft:light_gray_stained_glass
fill ~-4 ~18 ~46 ~5 ~19 ~46 minecraft:gray_stained_glass
fill ~-4 ~18 ~59 ~5 ~19 ~59 minecraft:light_gray_stained_glass
fill ~-4 ~22 ~46 ~5 ~23 ~46 minecraft:gray_stained_glass
fill ~-4 ~22 ~59 ~5 ~23 ~59 minecraft:light_gray_stained_glass
fill ~-5 ~0 ~46 ~-2 ~3 ~46 doomsday_decoration:redbrick
setblock ~-4 ~1 ~46 minecraft:iron_door[half=lower,facing=north]
setblock ~-4 ~2 ~46 minecraft:iron_door[half=upper,facing=north]
fill ~-6 ~25 ~46 ~7 ~25 ~59 minecraft:deepslate_tile_slab
# 067 hotel -36,-40 -30,-29 h=24
fill ~-36 ~-3 ~-40 ~-30 ~-1 ~-29 minecraft:stone
fill ~-36 ~0 ~-40 ~-30 ~24 ~-29 minecraft:light_gray_concrete
fill ~-35 ~1 ~-39 ~-31 ~23 ~-30 minecraft:air
fill ~-35 ~4 ~-39 ~-31 ~4 ~-30 minecraft:smooth_stone
fill ~-35 ~8 ~-39 ~-31 ~8 ~-30 minecraft:smooth_stone
fill ~-35 ~12 ~-39 ~-31 ~12 ~-30 minecraft:smooth_stone
fill ~-35 ~16 ~-39 ~-31 ~16 ~-30 minecraft:smooth_stone
fill ~-35 ~20 ~-39 ~-31 ~20 ~-30 minecraft:smooth_stone
fill ~-36 ~2 ~-38 ~-36 ~3 ~-31 minecraft:gray_stained_glass
fill ~-30 ~2 ~-38 ~-30 ~3 ~-31 minecraft:light_gray_stained_glass
fill ~-36 ~6 ~-38 ~-36 ~7 ~-31 minecraft:gray_stained_glass
fill ~-30 ~6 ~-38 ~-30 ~7 ~-31 minecraft:light_gray_stained_glass
fill ~-36 ~10 ~-38 ~-36 ~11 ~-31 minecraft:gray_stained_glass
fill ~-30 ~10 ~-38 ~-30 ~11 ~-31 minecraft:light_gray_stained_glass
fill ~-36 ~14 ~-38 ~-36 ~15 ~-31 minecraft:gray_stained_glass
fill ~-30 ~14 ~-38 ~-30 ~15 ~-31 minecraft:light_gray_stained_glass
fill ~-36 ~18 ~-38 ~-36 ~19 ~-31 minecraft:gray_stained_glass
fill ~-30 ~18 ~-38 ~-30 ~19 ~-31 minecraft:light_gray_stained_glass
fill ~-36 ~22 ~-38 ~-36 ~23 ~-31 minecraft:gray_stained_glass
fill ~-30 ~22 ~-38 ~-30 ~23 ~-31 minecraft:light_gray_stained_glass
fill ~-35 ~0 ~-40 ~-32 ~3 ~-40 doomsday_decoration:cementwall
setblock ~-34 ~1 ~-40 minecraft:iron_door[half=lower,facing=north]
setblock ~-34 ~2 ~-40 minecraft:iron_door[half=upper,facing=north]
fill ~-36 ~25 ~-40 ~-30 ~25 ~-29 minecraft:smooth_stone_slab
# 068 garage 25,-124 35,-109 h=6
fill ~25 ~-3 ~-124 ~35 ~-1 ~-109 minecraft:stone
fill ~25 ~0 ~-124 ~35 ~6 ~-109 minecraft:bricks
fill ~26 ~1 ~-123 ~34 ~5 ~-110 minecraft:air
fill ~26 ~4 ~-123 ~34 ~4 ~-110 minecraft:smooth_stone
fill ~25 ~2 ~-122 ~25 ~3 ~-111 minecraft:gray_stained_glass
fill ~35 ~2 ~-122 ~35 ~3 ~-111 minecraft:light_gray_stained_glass
fill ~26 ~0 ~-124 ~29 ~3 ~-124 minecraft:gray_concrete
setblock ~27 ~1 ~-124 minecraft:iron_door[half=lower,facing=north]
setblock ~27 ~2 ~-124 minecraft:iron_door[half=upper,facing=north]
fill ~25 ~7 ~-124 ~35 ~7 ~-109 minecraft:deepslate_tile_slab
# 069 detached_house -109,111 -104,119 h=9
fill ~-109 ~-3 ~111 ~-104 ~-1 ~119 minecraft:stone
fill ~-109 ~0 ~111 ~-104 ~9 ~119 minecraft:calcite
fill ~-108 ~1 ~112 ~-105 ~8 ~118 minecraft:air
fill ~-108 ~4 ~112 ~-105 ~4 ~118 minecraft:smooth_stone
fill ~-108 ~8 ~112 ~-105 ~8 ~118 minecraft:smooth_stone
fill ~-107 ~2 ~111 ~-106 ~3 ~111 minecraft:gray_stained_glass
fill ~-107 ~2 ~119 ~-106 ~3 ~119 minecraft:light_gray_stained_glass
fill ~-107 ~6 ~111 ~-106 ~7 ~111 minecraft:gray_stained_glass
fill ~-107 ~6 ~119 ~-106 ~7 ~119 minecraft:light_gray_stained_glass
fill ~-108 ~0 ~111 ~-105 ~3 ~111 minecraft:gray_concrete
setblock ~-107 ~1 ~111 minecraft:iron_door[half=lower,facing=north]
setblock ~-107 ~2 ~111 minecraft:iron_door[half=upper,facing=north]
fill ~-109 ~10 ~111 ~-104 ~10 ~119 minecraft:stone_brick_slab
# 070 utility 69,38 78,50 h=8
fill ~69 ~-3 ~38 ~78 ~-1 ~50 minecraft:stone
fill ~69 ~0 ~38 ~78 ~8 ~50 minecraft:stone_bricks
fill ~70 ~1 ~39 ~77 ~7 ~49 minecraft:air
fill ~70 ~4 ~39 ~77 ~4 ~49 minecraft:smooth_stone
fill ~71 ~2 ~38 ~76 ~3 ~38 minecraft:gray_stained_glass
fill ~71 ~2 ~50 ~76 ~3 ~50 minecraft:light_gray_stained_glass
fill ~71 ~6 ~38 ~76 ~7 ~38 minecraft:gray_stained_glass
fill ~71 ~6 ~50 ~76 ~7 ~50 minecraft:light_gray_stained_glass
fill ~70 ~0 ~38 ~73 ~3 ~38 minecraft:orange_terracotta
setblock ~71 ~1 ~38 minecraft:iron_door[half=lower,facing=north]
setblock ~71 ~2 ~38 minecraft:iron_door[half=upper,facing=north]
fill ~69 ~9 ~38 ~78 ~9 ~50 minecraft:stone_brick_slab
fill ~76 ~6 ~48 ~78 ~9 ~50 minecraft:air
setblock ~76 ~6 ~48 minecraft:cobweb
# 071 warehouse 63,-90 73,-81 h=12
fill ~63 ~-3 ~-90 ~73 ~-1 ~-81 minecraft:stone
fill ~63 ~0 ~-90 ~73 ~12 ~-81 minecraft:stone_bricks
fill ~64 ~1 ~-89 ~72 ~11 ~-82 minecraft:air
fill ~64 ~4 ~-89 ~72 ~4 ~-82 minecraft:smooth_stone
fill ~64 ~8 ~-89 ~72 ~8 ~-82 minecraft:smooth_stone
fill ~65 ~2 ~-90 ~71 ~3 ~-90 minecraft:gray_stained_glass
fill ~65 ~2 ~-81 ~71 ~3 ~-81 minecraft:light_gray_stained_glass
fill ~65 ~6 ~-90 ~71 ~7 ~-90 minecraft:gray_stained_glass
fill ~65 ~6 ~-81 ~71 ~7 ~-81 minecraft:light_gray_stained_glass
fill ~65 ~10 ~-90 ~71 ~11 ~-90 minecraft:gray_stained_glass
fill ~65 ~10 ~-81 ~71 ~11 ~-81 minecraft:light_gray_stained_glass
fill ~64 ~0 ~-90 ~67 ~3 ~-90 doomsday_decoration:ironsheetwall_2
setblock ~65 ~1 ~-90 minecraft:iron_door[half=lower,facing=north]
setblock ~65 ~2 ~-90 minecraft:iron_door[half=upper,facing=north]
fill ~63 ~13 ~-90 ~73 ~13 ~-81 minecraft:smooth_stone_slab
# 072 lowrise_housing -44,-51 -35,-44 h=16
fill ~-44 ~-3 ~-51 ~-35 ~-1 ~-44 minecraft:stone
fill ~-44 ~0 ~-51 ~-35 ~16 ~-44 minecraft:bricks
fill ~-43 ~1 ~-50 ~-36 ~15 ~-45 minecraft:air
fill ~-43 ~4 ~-50 ~-36 ~4 ~-45 minecraft:smooth_stone
fill ~-43 ~8 ~-50 ~-36 ~8 ~-45 minecraft:smooth_stone
fill ~-43 ~12 ~-50 ~-36 ~12 ~-45 minecraft:smooth_stone
fill ~-44 ~2 ~-49 ~-44 ~3 ~-46 minecraft:gray_stained_glass
fill ~-35 ~2 ~-49 ~-35 ~3 ~-46 minecraft:light_gray_stained_glass
fill ~-44 ~6 ~-49 ~-44 ~7 ~-46 minecraft:gray_stained_glass
fill ~-35 ~6 ~-49 ~-35 ~7 ~-46 minecraft:light_gray_stained_glass
fill ~-44 ~10 ~-49 ~-44 ~11 ~-46 minecraft:gray_stained_glass
fill ~-35 ~10 ~-49 ~-35 ~11 ~-46 minecraft:light_gray_stained_glass
fill ~-44 ~14 ~-49 ~-44 ~15 ~-46 minecraft:gray_stained_glass
fill ~-35 ~14 ~-49 ~-35 ~15 ~-46 minecraft:light_gray_stained_glass
fill ~-43 ~0 ~-51 ~-40 ~3 ~-51 doomsday_decoration:hollowbrick
setblock ~-42 ~1 ~-51 minecraft:iron_door[half=lower,facing=north]
setblock ~-42 ~2 ~-51 minecraft:iron_door[half=upper,facing=north]
fill ~-44 ~17 ~-51 ~-35 ~17 ~-44 minecraft:deepslate_tile_slab
# 073 row_house -125,-58 -115,-50 h=7
fill ~-125 ~-3 ~-58 ~-115 ~-1 ~-50 minecraft:stone
fill ~-125 ~0 ~-58 ~-115 ~7 ~-50 minecraft:calcite
fill ~-124 ~1 ~-57 ~-116 ~6 ~-51 minecraft:air
fill ~-124 ~4 ~-57 ~-116 ~4 ~-51 minecraft:smooth_stone
fill ~-123 ~2 ~-58 ~-117 ~3 ~-58 minecraft:gray_stained_glass
fill ~-123 ~2 ~-50 ~-117 ~3 ~-50 minecraft:light_gray_stained_glass
fill ~-124 ~0 ~-58 ~-121 ~3 ~-58 minecraft:gray_concrete
setblock ~-123 ~1 ~-58 minecraft:iron_door[half=lower,facing=north]
setblock ~-123 ~2 ~-58 minecraft:iron_door[half=upper,facing=north]
fill ~-125 ~8 ~-58 ~-115 ~8 ~-50 minecraft:stone_brick_slab
# 074 detached_house -86,106 -81,112 h=5
fill ~-86 ~-3 ~106 ~-81 ~-1 ~112 minecraft:stone
fill ~-86 ~0 ~106 ~-81 ~5 ~112 minecraft:mud_bricks
fill ~-85 ~1 ~107 ~-82 ~4 ~111 minecraft:air
fill ~-85 ~4 ~107 ~-82 ~4 ~111 minecraft:smooth_stone
fill ~-84 ~2 ~106 ~-83 ~3 ~106 minecraft:gray_stained_glass
fill ~-84 ~2 ~112 ~-83 ~3 ~112 minecraft:light_gray_stained_glass
fill ~-85 ~0 ~106 ~-82 ~3 ~106 minecraft:spruce_planks
setblock ~-84 ~1 ~106 minecraft:iron_door[half=lower,facing=north]
setblock ~-84 ~2 ~106 minecraft:iron_door[half=upper,facing=north]
fill ~-86 ~6 ~106 ~-81 ~6 ~112 minecraft:deepslate_tile_slab
# 075 lowrise_housing -6,76 4,84 h=16
fill ~-6 ~-3 ~76 ~4 ~-1 ~84 minecraft:stone
fill ~-6 ~0 ~76 ~4 ~16 ~84 minecraft:smooth_sandstone
fill ~-5 ~1 ~77 ~3 ~15 ~83 minecraft:air
fill ~-5 ~4 ~77 ~3 ~4 ~83 minecraft:smooth_stone
fill ~-5 ~8 ~77 ~3 ~8 ~83 minecraft:smooth_stone
fill ~-5 ~12 ~77 ~3 ~12 ~83 minecraft:smooth_stone
fill ~-6 ~2 ~78 ~-6 ~3 ~82 minecraft:gray_stained_glass
fill ~4 ~2 ~78 ~4 ~3 ~82 minecraft:light_gray_stained_glass
fill ~-6 ~6 ~78 ~-6 ~7 ~82 minecraft:gray_stained_glass
fill ~4 ~6 ~78 ~4 ~7 ~82 minecraft:light_gray_stained_glass
fill ~-6 ~10 ~78 ~-6 ~11 ~82 minecraft:gray_stained_glass
fill ~4 ~10 ~78 ~4 ~11 ~82 minecraft:light_gray_stained_glass
fill ~-6 ~14 ~78 ~-6 ~15 ~82 minecraft:gray_stained_glass
fill ~4 ~14 ~78 ~4 ~15 ~82 minecraft:light_gray_stained_glass
fill ~-5 ~0 ~76 ~-2 ~3 ~76 minecraft:brown_terracotta
setblock ~-4 ~1 ~76 minecraft:iron_door[half=lower,facing=north]
setblock ~-4 ~2 ~76 minecraft:iron_door[half=upper,facing=north]
fill ~-6 ~17 ~76 ~4 ~17 ~84 minecraft:stone_brick_slab
