# Buildings 33..40
# 033 shop_house style=corner_store context=collector_front facing=north
fill ~93 ~-3 ~77 ~103 ~-1 ~84 minecraft:stone
fill ~93 ~0 ~77 ~103 ~5 ~84 minecraft:white_concrete
fill ~94 ~1 ~78 ~102 ~4 ~83 minecraft:air
fill ~94 ~4 ~78 ~102 ~4 ~83 minecraft:smooth_stone
fill ~95 ~2 ~77 ~95 ~3 ~77 minecraft:gray_stained_glass
fill ~95 ~2 ~84 ~95 ~3 ~84 minecraft:light_gray_stained_glass
fill ~98 ~2 ~77 ~98 ~3 ~77 minecraft:gray_stained_glass
fill ~98 ~2 ~84 ~98 ~3 ~84 minecraft:light_gray_stained_glass
fill ~101 ~2 ~77 ~101 ~3 ~77 minecraft:gray_stained_glass
fill ~101 ~2 ~84 ~101 ~3 ~84 minecraft:light_gray_stained_glass
fill ~93 ~2 ~79 ~93 ~3 ~79 minecraft:gray_stained_glass
fill ~103 ~2 ~79 ~103 ~3 ~79 minecraft:light_gray_stained_glass
fill ~93 ~2 ~82 ~93 ~3 ~82 minecraft:gray_stained_glass
fill ~103 ~2 ~82 ~103 ~3 ~82 minecraft:light_gray_stained_glass
setblock ~98 ~1 ~77 minecraft:iron_door[half=lower,facing=north]
setblock ~98 ~2 ~77 minecraft:iron_door[half=upper,facing=north]
fill ~94 ~1 ~77 ~102 ~3 ~77 minecraft:cyan_stained_glass
setblock ~98 ~1 ~77 minecraft:iron_door[half=lower,facing=north]
setblock ~98 ~2 ~77 minecraft:iron_door[half=upper,facing=north]
setblock ~98 ~3 ~76 minecraft:red_wool
fill ~93 ~6 ~77 ~103 ~6 ~84 minecraft:smooth_stone_slab
fill ~94 ~1 ~77 ~94 ~5 ~77 minecraft:cyan_terracotta
fill ~98 ~1 ~77 ~98 ~5 ~77 minecraft:cyan_terracotta
fill ~102 ~1 ~77 ~102 ~5 ~77 minecraft:cyan_terracotta
setblock ~95 ~3 ~77 minecraft:red_carpet
setblock ~100 ~3 ~77 minecraft:red_carpet
# 034 restaurant_block style=arcade_shop context=station_front facing=north
fill ~-68 ~-3 ~-45 ~-62 ~-1 ~-36 minecraft:stone
fill ~-68 ~0 ~-45 ~-62 ~12 ~-36 minecraft:smooth_sandstone
fill ~-67 ~1 ~-44 ~-63 ~11 ~-37 minecraft:air
fill ~-67 ~4 ~-44 ~-63 ~4 ~-37 minecraft:smooth_stone
fill ~-67 ~8 ~-44 ~-63 ~8 ~-37 minecraft:smooth_stone
fill ~-66 ~2 ~-45 ~-66 ~3 ~-45 minecraft:gray_stained_glass
fill ~-66 ~2 ~-36 ~-66 ~3 ~-36 minecraft:light_gray_stained_glass
fill ~-68 ~2 ~-43 ~-68 ~3 ~-43 minecraft:gray_stained_glass
fill ~-62 ~2 ~-43 ~-62 ~3 ~-43 minecraft:light_gray_stained_glass
fill ~-68 ~2 ~-40 ~-68 ~3 ~-40 minecraft:gray_stained_glass
fill ~-62 ~2 ~-40 ~-62 ~3 ~-40 minecraft:light_gray_stained_glass
fill ~-66 ~6 ~-45 ~-66 ~7 ~-45 minecraft:gray_stained_glass
fill ~-66 ~6 ~-36 ~-66 ~7 ~-36 minecraft:light_gray_stained_glass
fill ~-68 ~6 ~-43 ~-68 ~7 ~-43 minecraft:gray_stained_glass
fill ~-62 ~6 ~-43 ~-62 ~7 ~-43 minecraft:light_gray_stained_glass
fill ~-68 ~6 ~-40 ~-68 ~7 ~-40 minecraft:gray_stained_glass
fill ~-62 ~6 ~-40 ~-62 ~7 ~-40 minecraft:light_gray_stained_glass
fill ~-66 ~10 ~-45 ~-66 ~11 ~-45 minecraft:gray_stained_glass
fill ~-66 ~10 ~-36 ~-66 ~11 ~-36 minecraft:light_gray_stained_glass
fill ~-68 ~10 ~-43 ~-68 ~11 ~-43 minecraft:gray_stained_glass
fill ~-62 ~10 ~-43 ~-62 ~11 ~-43 minecraft:light_gray_stained_glass
fill ~-68 ~10 ~-40 ~-68 ~11 ~-40 minecraft:gray_stained_glass
fill ~-62 ~10 ~-40 ~-62 ~11 ~-40 minecraft:light_gray_stained_glass
setblock ~-65 ~1 ~-45 minecraft:iron_door[half=lower,facing=north]
setblock ~-65 ~2 ~-45 minecraft:iron_door[half=upper,facing=north]
fill ~-67 ~1 ~-45 ~-63 ~3 ~-45 minecraft:cyan_stained_glass
setblock ~-65 ~1 ~-45 minecraft:iron_door[half=lower,facing=north]
setblock ~-65 ~2 ~-45 minecraft:iron_door[half=upper,facing=north]
setblock ~-65 ~3 ~-46 minecraft:red_wool
fill ~-67 ~4 ~-45 ~-63 ~4 ~-45 minecraft:brown_terracotta
fill ~-68 ~13 ~-45 ~-62 ~13 ~-36 minecraft:stone_brick_slab
fill ~-67 ~1 ~-45 ~-67 ~7 ~-45 minecraft:brown_terracotta
fill ~-63 ~1 ~-45 ~-63 ~7 ~-45 minecraft:brown_terracotta
# 035 clinic style=balcony_block context=collector_front facing=east
fill ~-92 ~-3 ~-60 ~-85 ~-1 ~-54 minecraft:stone
fill ~-92 ~0 ~-60 ~-85 ~16 ~-54 minecraft:bricks
fill ~-91 ~1 ~-59 ~-86 ~15 ~-55 minecraft:air
fill ~-91 ~4 ~-59 ~-86 ~4 ~-55 minecraft:smooth_stone
fill ~-91 ~8 ~-59 ~-86 ~8 ~-55 minecraft:smooth_stone
fill ~-91 ~12 ~-59 ~-86 ~12 ~-55 minecraft:smooth_stone
fill ~-90 ~2 ~-60 ~-90 ~3 ~-60 minecraft:gray_stained_glass
fill ~-90 ~2 ~-54 ~-90 ~3 ~-54 minecraft:light_gray_stained_glass
fill ~-87 ~2 ~-60 ~-87 ~3 ~-60 minecraft:gray_stained_glass
fill ~-87 ~2 ~-54 ~-87 ~3 ~-54 minecraft:light_gray_stained_glass
fill ~-92 ~2 ~-58 ~-92 ~3 ~-58 minecraft:gray_stained_glass
fill ~-85 ~2 ~-58 ~-85 ~3 ~-58 minecraft:light_gray_stained_glass
fill ~-90 ~6 ~-60 ~-90 ~7 ~-60 minecraft:gray_stained_glass
fill ~-90 ~6 ~-54 ~-90 ~7 ~-54 minecraft:light_gray_stained_glass
fill ~-87 ~6 ~-60 ~-87 ~7 ~-60 minecraft:gray_stained_glass
fill ~-87 ~6 ~-54 ~-87 ~7 ~-54 minecraft:light_gray_stained_glass
fill ~-92 ~6 ~-58 ~-92 ~7 ~-58 minecraft:gray_stained_glass
fill ~-85 ~6 ~-58 ~-85 ~7 ~-58 minecraft:light_gray_stained_glass
fill ~-90 ~10 ~-60 ~-90 ~11 ~-60 minecraft:gray_stained_glass
fill ~-90 ~10 ~-54 ~-90 ~11 ~-54 minecraft:light_gray_stained_glass
fill ~-87 ~10 ~-60 ~-87 ~11 ~-60 minecraft:gray_stained_glass
fill ~-87 ~10 ~-54 ~-87 ~11 ~-54 minecraft:light_gray_stained_glass
fill ~-92 ~10 ~-58 ~-92 ~11 ~-58 minecraft:gray_stained_glass
fill ~-85 ~10 ~-58 ~-85 ~11 ~-58 minecraft:light_gray_stained_glass
fill ~-90 ~14 ~-60 ~-90 ~15 ~-60 minecraft:gray_stained_glass
fill ~-90 ~14 ~-54 ~-90 ~15 ~-54 minecraft:light_gray_stained_glass
fill ~-87 ~14 ~-60 ~-87 ~15 ~-60 minecraft:gray_stained_glass
fill ~-87 ~14 ~-54 ~-87 ~15 ~-54 minecraft:light_gray_stained_glass
fill ~-92 ~14 ~-58 ~-92 ~15 ~-58 minecraft:gray_stained_glass
fill ~-85 ~14 ~-58 ~-85 ~15 ~-58 minecraft:light_gray_stained_glass
setblock ~-85 ~1 ~-57 minecraft:iron_door[half=lower,facing=east]
setblock ~-85 ~2 ~-57 minecraft:iron_door[half=upper,facing=east]
fill ~-84 ~4 ~-58 ~-84 ~4 ~-56 minecraft:smooth_stone_slab
fill ~-84 ~8 ~-58 ~-84 ~8 ~-56 minecraft:smooth_stone_slab
fill ~-84 ~12 ~-58 ~-84 ~12 ~-56 minecraft:smooth_stone_slab
fill ~-92 ~17 ~-60 ~-85 ~17 ~-54 minecraft:deepslate_tile_slab
fill ~-85 ~1 ~-59 ~-85 ~7 ~-59 doomsday_decoration:hollowbrick
fill ~-85 ~1 ~-55 ~-85 ~7 ~-55 doomsday_decoration:hollowbrick
# 036 restaurant style=corner_store context=collector_front facing=north
fill ~-92 ~-3 ~-82 ~-87 ~-1 ~-74 minecraft:stone
fill ~-92 ~0 ~-82 ~-87 ~7 ~-74 minecraft:white_terracotta
fill ~-91 ~1 ~-81 ~-88 ~6 ~-75 minecraft:air
fill ~-91 ~4 ~-81 ~-88 ~4 ~-75 minecraft:smooth_stone
fill ~-90 ~2 ~-82 ~-90 ~3 ~-82 minecraft:gray_stained_glass
fill ~-90 ~2 ~-74 ~-90 ~3 ~-74 minecraft:light_gray_stained_glass
fill ~-92 ~2 ~-80 ~-92 ~3 ~-80 minecraft:gray_stained_glass
fill ~-87 ~2 ~-80 ~-87 ~3 ~-80 minecraft:light_gray_stained_glass
fill ~-92 ~2 ~-77 ~-92 ~3 ~-77 minecraft:gray_stained_glass
fill ~-87 ~2 ~-77 ~-87 ~3 ~-77 minecraft:light_gray_stained_glass
setblock ~-90 ~1 ~-82 minecraft:iron_door[half=lower,facing=north]
setblock ~-90 ~2 ~-82 minecraft:iron_door[half=upper,facing=north]
fill ~-91 ~1 ~-82 ~-88 ~3 ~-82 minecraft:cyan_stained_glass
setblock ~-90 ~1 ~-82 minecraft:iron_door[half=lower,facing=north]
setblock ~-90 ~2 ~-82 minecraft:iron_door[half=upper,facing=north]
setblock ~-90 ~3 ~-83 minecraft:red_wool
fill ~-92 ~8 ~-82 ~-87 ~8 ~-74 minecraft:dark_oak_slab
fill ~-91 ~1 ~-82 ~-91 ~7 ~-82 minecraft:dark_oak_planks
setblock ~-90 ~3 ~-82 minecraft:red_carpet
# 037 clinic style=balcony_block context=collector_front facing=east
fill ~-102 ~-3 ~63 ~-94 ~-1 ~70 minecraft:stone
fill ~-102 ~0 ~63 ~-94 ~7 ~70 minecraft:mud_bricks
fill ~-101 ~1 ~64 ~-95 ~6 ~69 minecraft:air
fill ~-101 ~4 ~64 ~-95 ~4 ~69 minecraft:smooth_stone
fill ~-100 ~2 ~63 ~-100 ~3 ~63 minecraft:gray_stained_glass
fill ~-100 ~2 ~70 ~-100 ~3 ~70 minecraft:light_gray_stained_glass
fill ~-97 ~2 ~63 ~-97 ~3 ~63 minecraft:gray_stained_glass
fill ~-97 ~2 ~70 ~-97 ~3 ~70 minecraft:light_gray_stained_glass
fill ~-102 ~2 ~65 ~-102 ~3 ~65 minecraft:gray_stained_glass
fill ~-94 ~2 ~65 ~-94 ~3 ~65 minecraft:light_gray_stained_glass
fill ~-102 ~2 ~68 ~-102 ~3 ~68 minecraft:gray_stained_glass
fill ~-94 ~2 ~68 ~-94 ~3 ~68 minecraft:light_gray_stained_glass
setblock ~-94 ~1 ~66 minecraft:iron_door[half=lower,facing=east]
setblock ~-94 ~2 ~66 minecraft:iron_door[half=upper,facing=east]
fill ~-93 ~4 ~65 ~-93 ~4 ~68 minecraft:smooth_stone_slab
fill ~-102 ~8 ~63 ~-94 ~8 ~70 minecraft:deepslate_tile_slab
fill ~-94 ~1 ~64 ~-94 ~7 ~64 minecraft:spruce_planks
fill ~-94 ~1 ~68 ~-94 ~7 ~68 minecraft:spruce_planks
# 038 detached_house style=rowhouse context=local_front facing=west
fill ~67 ~-3 ~12 ~74 ~-1 ~25 minecraft:stone
fill ~67 ~0 ~12 ~74 ~8 ~25 minecraft:light_gray_concrete
fill ~68 ~1 ~13 ~73 ~7 ~24 minecraft:air
fill ~68 ~4 ~13 ~73 ~4 ~24 minecraft:smooth_stone
fill ~69 ~2 ~12 ~69 ~3 ~12 minecraft:gray_stained_glass
fill ~69 ~2 ~25 ~69 ~3 ~25 minecraft:light_gray_stained_glass
fill ~72 ~2 ~12 ~72 ~3 ~12 minecraft:gray_stained_glass
fill ~72 ~2 ~25 ~72 ~3 ~25 minecraft:light_gray_stained_glass
fill ~67 ~2 ~14 ~67 ~3 ~14 minecraft:gray_stained_glass
fill ~74 ~2 ~14 ~74 ~3 ~14 minecraft:light_gray_stained_glass
fill ~67 ~2 ~17 ~67 ~3 ~17 minecraft:gray_stained_glass
fill ~74 ~2 ~17 ~74 ~3 ~17 minecraft:light_gray_stained_glass
fill ~67 ~2 ~20 ~67 ~3 ~20 minecraft:gray_stained_glass
fill ~74 ~2 ~20 ~74 ~3 ~20 minecraft:light_gray_stained_glass
fill ~67 ~2 ~23 ~67 ~3 ~23 minecraft:gray_stained_glass
fill ~74 ~2 ~23 ~74 ~3 ~23 minecraft:light_gray_stained_glass
fill ~69 ~6 ~12 ~69 ~7 ~12 minecraft:gray_stained_glass
fill ~69 ~6 ~25 ~69 ~7 ~25 minecraft:light_gray_stained_glass
fill ~72 ~6 ~12 ~72 ~7 ~12 minecraft:gray_stained_glass
fill ~72 ~6 ~25 ~72 ~7 ~25 minecraft:light_gray_stained_glass
fill ~67 ~6 ~14 ~67 ~7 ~14 minecraft:gray_stained_glass
fill ~74 ~6 ~14 ~74 ~7 ~14 minecraft:light_gray_stained_glass
fill ~67 ~6 ~17 ~67 ~7 ~17 minecraft:gray_stained_glass
fill ~74 ~6 ~17 ~74 ~7 ~17 minecraft:light_gray_stained_glass
fill ~67 ~6 ~20 ~67 ~7 ~20 minecraft:gray_stained_glass
fill ~74 ~6 ~20 ~74 ~7 ~20 minecraft:light_gray_stained_glass
fill ~67 ~6 ~23 ~67 ~7 ~23 minecraft:gray_stained_glass
fill ~74 ~6 ~23 ~74 ~7 ~23 minecraft:light_gray_stained_glass
setblock ~67 ~1 ~17 minecraft:iron_door[half=lower,facing=west]
setblock ~67 ~2 ~17 minecraft:iron_door[half=upper,facing=west]
fill ~67 ~9 ~12 ~74 ~9 ~25 minecraft:smooth_stone_slab
fill ~68 ~10 ~13 ~73 ~10 ~24 minecraft:smooth_stone_slab
setblock ~66 ~3 ~17 minecraft:dark_oak_slab[type=top]
fill ~67 ~1 ~13 ~67 ~7 ~13 doomsday_decoration:porcelainbrickwall
fill ~67 ~1 ~17 ~67 ~7 ~17 doomsday_decoration:porcelainbrickwall
fill ~67 ~1 ~21 ~67 ~7 ~21 doomsday_decoration:porcelainbrickwall
# 039 large_retail style=arcade_shop context=arterial_front facing=west
fill ~-31 ~-3 ~65 ~-23 ~-1 ~72 minecraft:stone
fill ~-31 ~0 ~65 ~-23 ~10 ~72 minecraft:light_gray_concrete
fill ~-30 ~1 ~66 ~-24 ~9 ~71 minecraft:air
fill ~-30 ~4 ~66 ~-24 ~4 ~71 minecraft:smooth_stone
fill ~-30 ~8 ~66 ~-24 ~8 ~71 minecraft:smooth_stone
fill ~-29 ~2 ~65 ~-29 ~3 ~65 minecraft:gray_stained_glass
fill ~-29 ~2 ~72 ~-29 ~3 ~72 minecraft:light_gray_stained_glass
fill ~-26 ~2 ~65 ~-26 ~3 ~65 minecraft:gray_stained_glass
fill ~-26 ~2 ~72 ~-26 ~3 ~72 minecraft:light_gray_stained_glass
fill ~-31 ~2 ~67 ~-31 ~3 ~67 minecraft:gray_stained_glass
fill ~-23 ~2 ~67 ~-23 ~3 ~67 minecraft:light_gray_stained_glass
fill ~-31 ~2 ~70 ~-31 ~3 ~70 minecraft:gray_stained_glass
fill ~-23 ~2 ~70 ~-23 ~3 ~70 minecraft:light_gray_stained_glass
fill ~-29 ~6 ~65 ~-29 ~7 ~65 minecraft:gray_stained_glass
fill ~-29 ~6 ~72 ~-29 ~7 ~72 minecraft:light_gray_stained_glass
fill ~-26 ~6 ~65 ~-26 ~7 ~65 minecraft:gray_stained_glass
fill ~-26 ~6 ~72 ~-26 ~7 ~72 minecraft:light_gray_stained_glass
fill ~-31 ~6 ~67 ~-31 ~7 ~67 minecraft:gray_stained_glass
fill ~-23 ~6 ~67 ~-23 ~7 ~67 minecraft:light_gray_stained_glass
fill ~-31 ~6 ~70 ~-31 ~7 ~70 minecraft:gray_stained_glass
fill ~-23 ~6 ~70 ~-23 ~7 ~70 minecraft:light_gray_stained_glass
setblock ~-31 ~1 ~68 minecraft:iron_door[half=lower,facing=west]
setblock ~-31 ~2 ~68 minecraft:iron_door[half=upper,facing=west]
fill ~-31 ~1 ~66 ~-31 ~3 ~71 minecraft:cyan_stained_glass
setblock ~-31 ~1 ~68 minecraft:iron_door[half=lower,facing=west]
setblock ~-31 ~2 ~68 minecraft:iron_door[half=upper,facing=west]
setblock ~-32 ~3 ~68 minecraft:red_wool
fill ~-31 ~4 ~66 ~-31 ~4 ~71 doomsday_decoration:porcelainbrickwall
fill ~-31 ~11 ~65 ~-23 ~11 ~72 minecraft:smooth_stone_slab
fill ~-29 ~12 ~67 ~-27 ~13 ~69 minecraft:light_gray_concrete
setblock ~-26 ~12 ~68 minecraft:lightning_rod
fill ~-31 ~1 ~66 ~-31 ~7 ~66 doomsday_decoration:porcelainbrickwall
fill ~-31 ~1 ~70 ~-31 ~7 ~70 doomsday_decoration:porcelainbrickwall
fill ~-30 ~6 ~66 ~-24 ~10 ~71 minecraft:light_gray_concrete
fill ~-29 ~7 ~67 ~-25 ~9 ~70 minecraft:air
setblock ~-31 ~3 ~67 minecraft:red_carpet
# 040 community style=setback_block context=collector_front facing=east
fill ~85 ~-3 ~17 ~92 ~-1 ~22 minecraft:stone
fill ~85 ~0 ~17 ~92 ~7 ~22 minecraft:white_concrete
fill ~86 ~1 ~18 ~91 ~6 ~21 minecraft:air
fill ~86 ~4 ~18 ~91 ~4 ~21 minecraft:smooth_stone
fill ~87 ~2 ~17 ~87 ~3 ~17 minecraft:gray_stained_glass
fill ~87 ~2 ~22 ~87 ~3 ~22 minecraft:light_gray_stained_glass
fill ~90 ~2 ~17 ~90 ~3 ~17 minecraft:gray_stained_glass
fill ~90 ~2 ~22 ~90 ~3 ~22 minecraft:light_gray_stained_glass
fill ~85 ~2 ~19 ~85 ~3 ~19 minecraft:gray_stained_glass
fill ~92 ~2 ~19 ~92 ~3 ~19 minecraft:light_gray_stained_glass
setblock ~92 ~1 ~19 minecraft:iron_door[half=lower,facing=east]
setblock ~92 ~2 ~19 minecraft:iron_door[half=upper,facing=east]
fill ~92 ~1 ~18 ~92 ~7 ~18 minecraft:cyan_terracotta
