# Buildings 41..48
# 041 workshop style=loading_bay context=local_front facing=north
fill ~-1 ~-3 ~-38 ~8 ~-1 ~-28 minecraft:stone
fill ~-1 ~0 ~-38 ~8 ~12 ~-28 minecraft:white_terracotta
fill ~0 ~1 ~-37 ~7 ~11 ~-29 minecraft:air
fill ~0 ~4 ~-37 ~7 ~4 ~-29 minecraft:smooth_stone
fill ~0 ~8 ~-37 ~7 ~8 ~-29 minecraft:smooth_stone
fill ~1 ~2 ~-38 ~1 ~3 ~-38 minecraft:gray_stained_glass
fill ~1 ~2 ~-28 ~1 ~3 ~-28 minecraft:light_gray_stained_glass
fill ~4 ~2 ~-38 ~4 ~3 ~-38 minecraft:gray_stained_glass
fill ~4 ~2 ~-28 ~4 ~3 ~-28 minecraft:light_gray_stained_glass
fill ~-1 ~2 ~-36 ~-1 ~3 ~-36 minecraft:gray_stained_glass
fill ~8 ~2 ~-36 ~8 ~3 ~-36 minecraft:light_gray_stained_glass
fill ~-1 ~2 ~-33 ~-1 ~3 ~-33 minecraft:gray_stained_glass
fill ~8 ~2 ~-33 ~8 ~3 ~-33 minecraft:light_gray_stained_glass
fill ~-1 ~2 ~-30 ~-1 ~3 ~-30 minecraft:gray_stained_glass
fill ~8 ~2 ~-30 ~8 ~3 ~-30 minecraft:light_gray_stained_glass
fill ~1 ~6 ~-38 ~1 ~7 ~-38 minecraft:gray_stained_glass
fill ~1 ~6 ~-28 ~1 ~7 ~-28 minecraft:light_gray_stained_glass
fill ~4 ~6 ~-38 ~4 ~7 ~-38 minecraft:gray_stained_glass
fill ~4 ~6 ~-28 ~4 ~7 ~-28 minecraft:light_gray_stained_glass
fill ~-1 ~6 ~-36 ~-1 ~7 ~-36 minecraft:gray_stained_glass
fill ~8 ~6 ~-36 ~8 ~7 ~-36 minecraft:light_gray_stained_glass
fill ~-1 ~6 ~-33 ~-1 ~7 ~-33 minecraft:gray_stained_glass
fill ~8 ~6 ~-33 ~8 ~7 ~-33 minecraft:light_gray_stained_glass
fill ~-1 ~6 ~-30 ~-1 ~7 ~-30 minecraft:gray_stained_glass
fill ~8 ~6 ~-30 ~8 ~7 ~-30 minecraft:light_gray_stained_glass
fill ~1 ~10 ~-38 ~1 ~11 ~-38 minecraft:gray_stained_glass
fill ~1 ~10 ~-28 ~1 ~11 ~-28 minecraft:light_gray_stained_glass
fill ~4 ~10 ~-38 ~4 ~11 ~-38 minecraft:gray_stained_glass
fill ~4 ~10 ~-28 ~4 ~11 ~-28 minecraft:light_gray_stained_glass
fill ~-1 ~10 ~-36 ~-1 ~11 ~-36 minecraft:gray_stained_glass
fill ~8 ~10 ~-36 ~8 ~11 ~-36 minecraft:light_gray_stained_glass
fill ~-1 ~10 ~-33 ~-1 ~11 ~-33 minecraft:gray_stained_glass
fill ~8 ~10 ~-33 ~8 ~11 ~-33 minecraft:light_gray_stained_glass
fill ~-1 ~10 ~-30 ~-1 ~11 ~-30 minecraft:gray_stained_glass
fill ~8 ~10 ~-30 ~8 ~11 ~-30 minecraft:light_gray_stained_glass
setblock ~3 ~1 ~-38 minecraft:iron_door[half=lower,facing=north]
setblock ~3 ~2 ~-38 minecraft:iron_door[half=upper,facing=north]
fill ~1 ~1 ~-38 ~6 ~4 ~-38 minecraft:polished_blackstone
fill ~1 ~5 ~-38 ~6 ~5 ~-38 minecraft:light_blue_stained_glass
fill ~1 ~14 ~-36 ~3 ~15 ~-34 minecraft:iron_block
fill ~-1 ~13 ~-38 ~8 ~13 ~-28 minecraft:stone_brick_slab
fill ~0 ~1 ~-38 ~0 ~7 ~-38 minecraft:gray_concrete
fill ~4 ~1 ~-38 ~4 ~7 ~-38 minecraft:gray_concrete
# 042 midrise_housing style=mixed_facade context=arterial_front facing=south
fill ~60 ~-3 ~-18 ~70 ~-1 ~-10 minecraft:stone
fill ~60 ~0 ~-18 ~70 ~12 ~-10 minecraft:bricks
fill ~61 ~1 ~-17 ~69 ~11 ~-11 minecraft:air
fill ~61 ~4 ~-17 ~69 ~4 ~-11 minecraft:smooth_stone
fill ~61 ~8 ~-17 ~69 ~8 ~-11 minecraft:smooth_stone
fill ~62 ~2 ~-18 ~62 ~3 ~-18 minecraft:gray_stained_glass
fill ~62 ~2 ~-10 ~62 ~3 ~-10 minecraft:light_gray_stained_glass
fill ~65 ~2 ~-18 ~65 ~3 ~-18 minecraft:gray_stained_glass
fill ~65 ~2 ~-10 ~65 ~3 ~-10 minecraft:light_gray_stained_glass
fill ~68 ~2 ~-18 ~68 ~3 ~-18 minecraft:gray_stained_glass
fill ~68 ~2 ~-10 ~68 ~3 ~-10 minecraft:light_gray_stained_glass
fill ~60 ~2 ~-16 ~60 ~3 ~-16 minecraft:gray_stained_glass
fill ~70 ~2 ~-16 ~70 ~3 ~-16 minecraft:light_gray_stained_glass
fill ~60 ~2 ~-13 ~60 ~3 ~-13 minecraft:gray_stained_glass
fill ~70 ~2 ~-13 ~70 ~3 ~-13 minecraft:light_gray_stained_glass
fill ~62 ~6 ~-18 ~62 ~7 ~-18 minecraft:gray_stained_glass
fill ~62 ~6 ~-10 ~62 ~7 ~-10 minecraft:light_gray_stained_glass
fill ~65 ~6 ~-18 ~65 ~7 ~-18 minecraft:gray_stained_glass
fill ~65 ~6 ~-10 ~65 ~7 ~-10 minecraft:light_gray_stained_glass
fill ~68 ~6 ~-18 ~68 ~7 ~-18 minecraft:gray_stained_glass
fill ~68 ~6 ~-10 ~68 ~7 ~-10 minecraft:light_gray_stained_glass
fill ~60 ~6 ~-16 ~60 ~7 ~-16 minecraft:gray_stained_glass
fill ~70 ~6 ~-16 ~70 ~7 ~-16 minecraft:light_gray_stained_glass
fill ~60 ~6 ~-13 ~60 ~7 ~-13 minecraft:gray_stained_glass
fill ~70 ~6 ~-13 ~70 ~7 ~-13 minecraft:light_gray_stained_glass
fill ~62 ~10 ~-18 ~62 ~11 ~-18 minecraft:gray_stained_glass
fill ~62 ~10 ~-10 ~62 ~11 ~-10 minecraft:light_gray_stained_glass
fill ~65 ~10 ~-18 ~65 ~11 ~-18 minecraft:gray_stained_glass
fill ~65 ~10 ~-10 ~65 ~11 ~-10 minecraft:light_gray_stained_glass
fill ~68 ~10 ~-18 ~68 ~11 ~-18 minecraft:gray_stained_glass
fill ~68 ~10 ~-10 ~68 ~11 ~-10 minecraft:light_gray_stained_glass
fill ~60 ~10 ~-16 ~60 ~11 ~-16 minecraft:gray_stained_glass
fill ~70 ~10 ~-16 ~70 ~11 ~-16 minecraft:light_gray_stained_glass
fill ~60 ~10 ~-13 ~60 ~11 ~-13 minecraft:gray_stained_glass
fill ~70 ~10 ~-13 ~70 ~11 ~-13 minecraft:light_gray_stained_glass
setblock ~65 ~1 ~-10 minecraft:iron_door[half=lower,facing=south]
setblock ~65 ~2 ~-10 minecraft:iron_door[half=upper,facing=south]
fill ~60 ~13 ~-18 ~70 ~13 ~-10 minecraft:deepslate_tile_slab
fill ~62 ~14 ~-16 ~64 ~15 ~-14 minecraft:light_gray_concrete
setblock ~65 ~14 ~-15 minecraft:lightning_rod
fill ~61 ~1 ~-10 ~61 ~7 ~-10 doomsday_decoration:hollowbrick
fill ~65 ~1 ~-10 ~65 ~7 ~-10 doomsday_decoration:hollowbrick
fill ~69 ~1 ~-10 ~69 ~7 ~-10 doomsday_decoration:hollowbrick
fill ~62 ~14 ~-16 ~65 ~16 ~-13 minecraft:light_gray_concrete
setblock ~68 ~14 ~-12 minecraft:lightning_rod
# 043 community style=balcony_block context=collector_front facing=north
fill ~67 ~-3 ~-64 ~74 ~-1 ~-51 minecraft:stone
fill ~67 ~0 ~-64 ~74 ~16 ~-51 minecraft:bricks
fill ~68 ~1 ~-63 ~73 ~15 ~-52 minecraft:air
fill ~68 ~4 ~-63 ~73 ~4 ~-52 minecraft:smooth_stone
fill ~68 ~8 ~-63 ~73 ~8 ~-52 minecraft:smooth_stone
fill ~68 ~12 ~-63 ~73 ~12 ~-52 minecraft:smooth_stone
fill ~69 ~2 ~-64 ~69 ~3 ~-64 minecraft:gray_stained_glass
fill ~69 ~2 ~-51 ~69 ~3 ~-51 minecraft:light_gray_stained_glass
fill ~72 ~2 ~-64 ~72 ~3 ~-64 minecraft:gray_stained_glass
fill ~72 ~2 ~-51 ~72 ~3 ~-51 minecraft:light_gray_stained_glass
fill ~67 ~2 ~-62 ~67 ~3 ~-62 minecraft:gray_stained_glass
fill ~74 ~2 ~-62 ~74 ~3 ~-62 minecraft:light_gray_stained_glass
fill ~67 ~2 ~-59 ~67 ~3 ~-59 minecraft:gray_stained_glass
fill ~74 ~2 ~-59 ~74 ~3 ~-59 minecraft:light_gray_stained_glass
fill ~67 ~2 ~-56 ~67 ~3 ~-56 minecraft:gray_stained_glass
fill ~74 ~2 ~-56 ~74 ~3 ~-56 minecraft:light_gray_stained_glass
fill ~67 ~2 ~-53 ~67 ~3 ~-53 minecraft:gray_stained_glass
fill ~74 ~2 ~-53 ~74 ~3 ~-53 minecraft:light_gray_stained_glass
fill ~69 ~6 ~-64 ~69 ~7 ~-64 minecraft:gray_stained_glass
fill ~69 ~6 ~-51 ~69 ~7 ~-51 minecraft:light_gray_stained_glass
fill ~72 ~6 ~-64 ~72 ~7 ~-64 minecraft:gray_stained_glass
fill ~72 ~6 ~-51 ~72 ~7 ~-51 minecraft:light_gray_stained_glass
fill ~67 ~6 ~-62 ~67 ~7 ~-62 minecraft:gray_stained_glass
fill ~74 ~6 ~-62 ~74 ~7 ~-62 minecraft:light_gray_stained_glass
fill ~67 ~6 ~-59 ~67 ~7 ~-59 minecraft:gray_stained_glass
fill ~74 ~6 ~-59 ~74 ~7 ~-59 minecraft:light_gray_stained_glass
fill ~67 ~6 ~-56 ~67 ~7 ~-56 minecraft:gray_stained_glass
fill ~74 ~6 ~-56 ~74 ~7 ~-56 minecraft:light_gray_stained_glass
fill ~67 ~6 ~-53 ~67 ~7 ~-53 minecraft:gray_stained_glass
fill ~74 ~6 ~-53 ~74 ~7 ~-53 minecraft:light_gray_stained_glass
fill ~69 ~10 ~-64 ~69 ~11 ~-64 minecraft:gray_stained_glass
fill ~69 ~10 ~-51 ~69 ~11 ~-51 minecraft:light_gray_stained_glass
fill ~72 ~10 ~-64 ~72 ~11 ~-64 minecraft:gray_stained_glass
fill ~72 ~10 ~-51 ~72 ~11 ~-51 minecraft:light_gray_stained_glass
fill ~67 ~10 ~-62 ~67 ~11 ~-62 minecraft:gray_stained_glass
fill ~74 ~10 ~-62 ~74 ~11 ~-62 minecraft:light_gray_stained_glass
fill ~67 ~10 ~-59 ~67 ~11 ~-59 minecraft:gray_stained_glass
fill ~74 ~10 ~-59 ~74 ~11 ~-59 minecraft:light_gray_stained_glass
fill ~67 ~10 ~-56 ~67 ~11 ~-56 minecraft:gray_stained_glass
fill ~74 ~10 ~-56 ~74 ~11 ~-56 minecraft:light_gray_stained_glass
fill ~67 ~10 ~-53 ~67 ~11 ~-53 minecraft:gray_stained_glass
fill ~74 ~10 ~-53 ~74 ~11 ~-53 minecraft:light_gray_stained_glass
fill ~69 ~14 ~-64 ~69 ~15 ~-64 minecraft:gray_stained_glass
fill ~69 ~14 ~-51 ~69 ~15 ~-51 minecraft:light_gray_stained_glass
fill ~72 ~14 ~-64 ~72 ~15 ~-64 minecraft:gray_stained_glass
fill ~72 ~14 ~-51 ~72 ~15 ~-51 minecraft:light_gray_stained_glass
fill ~67 ~14 ~-62 ~67 ~15 ~-62 minecraft:gray_stained_glass
fill ~74 ~14 ~-62 ~74 ~15 ~-62 minecraft:light_gray_stained_glass
fill ~67 ~14 ~-59 ~67 ~15 ~-59 minecraft:gray_stained_glass
fill ~74 ~14 ~-59 ~74 ~15 ~-59 minecraft:light_gray_stained_glass
fill ~67 ~14 ~-56 ~67 ~15 ~-56 minecraft:gray_stained_glass
fill ~74 ~14 ~-56 ~74 ~15 ~-56 minecraft:light_gray_stained_glass
fill ~67 ~14 ~-53 ~67 ~15 ~-53 minecraft:gray_stained_glass
fill ~74 ~14 ~-53 ~74 ~15 ~-53 minecraft:light_gray_stained_glass
setblock ~70 ~1 ~-64 minecraft:iron_door[half=lower,facing=north]
setblock ~70 ~2 ~-64 minecraft:iron_door[half=upper,facing=north]
fill ~69 ~4 ~-65 ~72 ~4 ~-65 minecraft:smooth_stone_slab
fill ~69 ~8 ~-65 ~72 ~8 ~-65 minecraft:smooth_stone_slab
fill ~69 ~12 ~-65 ~72 ~12 ~-65 minecraft:smooth_stone_slab
fill ~67 ~17 ~-64 ~74 ~17 ~-51 minecraft:deepslate_tile_slab
fill ~68 ~1 ~-64 ~68 ~7 ~-64 doomsday_decoration:hollowbrick
fill ~72 ~1 ~-64 ~72 ~7 ~-64 doomsday_decoration:hollowbrick
# 044 medical_center style=setback_tower context=arterial_front facing=west
fill ~-31 ~-3 ~90 ~-25 ~-1 ~95 minecraft:stone
fill ~-31 ~0 ~90 ~-25 ~11 ~95 minecraft:mud_bricks
fill ~-30 ~1 ~91 ~-26 ~10 ~94 minecraft:air
fill ~-30 ~4 ~91 ~-26 ~4 ~94 minecraft:smooth_stone
fill ~-30 ~8 ~91 ~-26 ~8 ~94 minecraft:smooth_stone
fill ~-29 ~2 ~90 ~-29 ~3 ~90 minecraft:gray_stained_glass
fill ~-29 ~2 ~95 ~-29 ~3 ~95 minecraft:light_gray_stained_glass
fill ~-31 ~2 ~92 ~-31 ~3 ~92 minecraft:gray_stained_glass
fill ~-25 ~2 ~92 ~-25 ~3 ~92 minecraft:light_gray_stained_glass
fill ~-29 ~6 ~90 ~-29 ~7 ~90 minecraft:gray_stained_glass
fill ~-29 ~6 ~95 ~-29 ~7 ~95 minecraft:light_gray_stained_glass
fill ~-31 ~6 ~92 ~-31 ~7 ~92 minecraft:gray_stained_glass
fill ~-25 ~6 ~92 ~-25 ~7 ~92 minecraft:light_gray_stained_glass
setblock ~-31 ~1 ~92 minecraft:iron_door[half=lower,facing=west]
setblock ~-31 ~2 ~92 minecraft:iron_door[half=upper,facing=west]
fill ~-31 ~7 ~90 ~-25 ~11 ~95 minecraft:air
fill ~-30 ~7 ~91 ~-26 ~11 ~94 minecraft:mud_bricks
fill ~-29 ~8 ~92 ~-27 ~10 ~93 minecraft:air
fill ~-30 ~12 ~91 ~-26 ~12 ~94 minecraft:deepslate_tile_slab
fill ~-31 ~1 ~91 ~-31 ~7 ~91 minecraft:spruce_planks
# 045 waterfront_hotel style=setback_tower context=waterfront_front facing=north
fill ~108 ~-3 ~37 ~118 ~-1 ~43 minecraft:stone
fill ~108 ~0 ~37 ~118 ~5 ~43 minecraft:white_concrete
fill ~109 ~1 ~38 ~117 ~4 ~42 minecraft:air
fill ~109 ~4 ~38 ~117 ~4 ~42 minecraft:smooth_stone
fill ~110 ~2 ~37 ~110 ~3 ~37 minecraft:gray_stained_glass
fill ~110 ~2 ~43 ~110 ~3 ~43 minecraft:light_gray_stained_glass
fill ~113 ~2 ~37 ~113 ~3 ~37 minecraft:gray_stained_glass
fill ~113 ~2 ~43 ~113 ~3 ~43 minecraft:light_gray_stained_glass
fill ~116 ~2 ~37 ~116 ~3 ~37 minecraft:gray_stained_glass
fill ~116 ~2 ~43 ~116 ~3 ~43 minecraft:light_gray_stained_glass
fill ~108 ~2 ~39 ~108 ~3 ~39 minecraft:gray_stained_glass
fill ~118 ~2 ~39 ~118 ~3 ~39 minecraft:light_gray_stained_glass
setblock ~113 ~1 ~37 minecraft:iron_door[half=lower,facing=north]
setblock ~113 ~2 ~37 minecraft:iron_door[half=upper,facing=north]
fill ~109 ~1 ~37 ~109 ~5 ~37 minecraft:cyan_terracotta
fill ~113 ~1 ~37 ~113 ~5 ~37 minecraft:cyan_terracotta
fill ~117 ~1 ~37 ~117 ~5 ~37 minecraft:cyan_terracotta
# 046 restaurant style=storefront context=collector_front facing=west
fill ~-89 ~-3 ~8 ~-78 ~-1 ~15 minecraft:stone
fill ~-89 ~0 ~8 ~-78 ~8 ~15 minecraft:smooth_sandstone
fill ~-88 ~1 ~9 ~-79 ~7 ~14 minecraft:air
fill ~-88 ~4 ~9 ~-79 ~4 ~14 minecraft:smooth_stone
fill ~-87 ~2 ~8 ~-87 ~3 ~8 minecraft:gray_stained_glass
fill ~-87 ~2 ~15 ~-87 ~3 ~15 minecraft:light_gray_stained_glass
fill ~-84 ~2 ~8 ~-84 ~3 ~8 minecraft:gray_stained_glass
fill ~-84 ~2 ~15 ~-84 ~3 ~15 minecraft:light_gray_stained_glass
fill ~-81 ~2 ~8 ~-81 ~3 ~8 minecraft:gray_stained_glass
fill ~-81 ~2 ~15 ~-81 ~3 ~15 minecraft:light_gray_stained_glass
fill ~-89 ~2 ~10 ~-89 ~3 ~10 minecraft:gray_stained_glass
fill ~-78 ~2 ~10 ~-78 ~3 ~10 minecraft:light_gray_stained_glass
fill ~-89 ~2 ~13 ~-89 ~3 ~13 minecraft:gray_stained_glass
fill ~-78 ~2 ~13 ~-78 ~3 ~13 minecraft:light_gray_stained_glass
fill ~-87 ~6 ~8 ~-87 ~7 ~8 minecraft:gray_stained_glass
fill ~-87 ~6 ~15 ~-87 ~7 ~15 minecraft:light_gray_stained_glass
fill ~-84 ~6 ~8 ~-84 ~7 ~8 minecraft:gray_stained_glass
fill ~-84 ~6 ~15 ~-84 ~7 ~15 minecraft:light_gray_stained_glass
fill ~-81 ~6 ~8 ~-81 ~7 ~8 minecraft:gray_stained_glass
fill ~-81 ~6 ~15 ~-81 ~7 ~15 minecraft:light_gray_stained_glass
fill ~-89 ~6 ~10 ~-89 ~7 ~10 minecraft:gray_stained_glass
fill ~-78 ~6 ~10 ~-78 ~7 ~10 minecraft:light_gray_stained_glass
fill ~-89 ~6 ~13 ~-89 ~7 ~13 minecraft:gray_stained_glass
fill ~-78 ~6 ~13 ~-78 ~7 ~13 minecraft:light_gray_stained_glass
setblock ~-89 ~1 ~11 minecraft:iron_door[half=lower,facing=west]
setblock ~-89 ~2 ~11 minecraft:iron_door[half=upper,facing=west]
fill ~-89 ~1 ~9 ~-89 ~3 ~14 minecraft:cyan_stained_glass
setblock ~-89 ~1 ~11 minecraft:iron_door[half=lower,facing=west]
setblock ~-89 ~2 ~11 minecraft:iron_door[half=upper,facing=west]
setblock ~-90 ~3 ~11 minecraft:red_wool
fill ~-89 ~9 ~8 ~-78 ~9 ~15 minecraft:stone_brick_slab
fill ~-89 ~1 ~9 ~-89 ~7 ~9 minecraft:brown_terracotta
fill ~-89 ~1 ~13 ~-89 ~7 ~13 minecraft:brown_terracotta
fill ~-88 ~6 ~9 ~-79 ~8 ~14 minecraft:smooth_sandstone
fill ~-87 ~7 ~10 ~-80 ~7 ~13 minecraft:air
setblock ~-89 ~3 ~10 minecraft:red_carpet
# 047 midrise_housing style=setback_block context=collector_front facing=east
fill ~-116 ~-3 ~-35 ~-104 ~-1 ~-28 minecraft:stone
fill ~-116 ~0 ~-35 ~-104 ~9 ~-28 minecraft:mud_bricks
fill ~-115 ~1 ~-34 ~-105 ~8 ~-29 minecraft:air
fill ~-115 ~4 ~-34 ~-105 ~4 ~-29 minecraft:smooth_stone
fill ~-115 ~8 ~-34 ~-105 ~8 ~-29 minecraft:smooth_stone
fill ~-114 ~2 ~-35 ~-114 ~3 ~-35 minecraft:gray_stained_glass
fill ~-114 ~2 ~-28 ~-114 ~3 ~-28 minecraft:light_gray_stained_glass
fill ~-111 ~2 ~-35 ~-111 ~3 ~-35 minecraft:gray_stained_glass
fill ~-111 ~2 ~-28 ~-111 ~3 ~-28 minecraft:light_gray_stained_glass
fill ~-108 ~2 ~-35 ~-108 ~3 ~-35 minecraft:gray_stained_glass
fill ~-108 ~2 ~-28 ~-108 ~3 ~-28 minecraft:light_gray_stained_glass
fill ~-116 ~2 ~-33 ~-116 ~3 ~-33 minecraft:gray_stained_glass
fill ~-104 ~2 ~-33 ~-104 ~3 ~-33 minecraft:light_gray_stained_glass
fill ~-116 ~2 ~-30 ~-116 ~3 ~-30 minecraft:gray_stained_glass
fill ~-104 ~2 ~-30 ~-104 ~3 ~-30 minecraft:light_gray_stained_glass
fill ~-114 ~6 ~-35 ~-114 ~7 ~-35 minecraft:gray_stained_glass
fill ~-114 ~6 ~-28 ~-114 ~7 ~-28 minecraft:light_gray_stained_glass
fill ~-111 ~6 ~-35 ~-111 ~7 ~-35 minecraft:gray_stained_glass
fill ~-111 ~6 ~-28 ~-111 ~7 ~-28 minecraft:light_gray_stained_glass
fill ~-108 ~6 ~-35 ~-108 ~7 ~-35 minecraft:gray_stained_glass
fill ~-108 ~6 ~-28 ~-108 ~7 ~-28 minecraft:light_gray_stained_glass
fill ~-116 ~6 ~-33 ~-116 ~7 ~-33 minecraft:gray_stained_glass
fill ~-104 ~6 ~-33 ~-104 ~7 ~-33 minecraft:light_gray_stained_glass
fill ~-116 ~6 ~-30 ~-116 ~7 ~-30 minecraft:gray_stained_glass
fill ~-104 ~6 ~-30 ~-104 ~7 ~-30 minecraft:light_gray_stained_glass
setblock ~-104 ~1 ~-32 minecraft:iron_door[half=lower,facing=east]
setblock ~-104 ~2 ~-32 minecraft:iron_door[half=upper,facing=east]
fill ~-104 ~1 ~-34 ~-104 ~7 ~-34 minecraft:spruce_planks
fill ~-104 ~1 ~-30 ~-104 ~7 ~-30 minecraft:spruce_planks
# 048 lowrise_housing style=japanese_house context=local_front facing=north
fill ~33 ~-3 ~23 ~40 ~-1 ~31 minecraft:stone
fill ~33 ~0 ~23 ~40 ~20 ~31 minecraft:light_gray_concrete
fill ~34 ~1 ~24 ~39 ~19 ~30 minecraft:air
fill ~34 ~4 ~24 ~39 ~4 ~30 minecraft:smooth_stone
fill ~34 ~8 ~24 ~39 ~8 ~30 minecraft:smooth_stone
fill ~34 ~12 ~24 ~39 ~12 ~30 minecraft:smooth_stone
fill ~34 ~16 ~24 ~39 ~16 ~30 minecraft:smooth_stone
fill ~35 ~2 ~23 ~35 ~3 ~23 minecraft:gray_stained_glass
fill ~35 ~2 ~31 ~35 ~3 ~31 minecraft:light_gray_stained_glass
fill ~38 ~2 ~23 ~38 ~3 ~23 minecraft:gray_stained_glass
fill ~38 ~2 ~31 ~38 ~3 ~31 minecraft:light_gray_stained_glass
fill ~33 ~2 ~25 ~33 ~3 ~25 minecraft:gray_stained_glass
fill ~40 ~2 ~25 ~40 ~3 ~25 minecraft:light_gray_stained_glass
fill ~33 ~2 ~28 ~33 ~3 ~28 minecraft:gray_stained_glass
fill ~40 ~2 ~28 ~40 ~3 ~28 minecraft:light_gray_stained_glass
fill ~35 ~6 ~23 ~35 ~7 ~23 minecraft:gray_stained_glass
fill ~35 ~6 ~31 ~35 ~7 ~31 minecraft:light_gray_stained_glass
fill ~38 ~6 ~23 ~38 ~7 ~23 minecraft:gray_stained_glass
fill ~38 ~6 ~31 ~38 ~7 ~31 minecraft:light_gray_stained_glass
fill ~33 ~6 ~25 ~33 ~7 ~25 minecraft:gray_stained_glass
fill ~40 ~6 ~25 ~40 ~7 ~25 minecraft:light_gray_stained_glass
fill ~33 ~6 ~28 ~33 ~7 ~28 minecraft:gray_stained_glass
fill ~40 ~6 ~28 ~40 ~7 ~28 minecraft:light_gray_stained_glass
fill ~35 ~10 ~23 ~35 ~11 ~23 minecraft:gray_stained_glass
fill ~35 ~10 ~31 ~35 ~11 ~31 minecraft:light_gray_stained_glass
fill ~38 ~10 ~23 ~38 ~11 ~23 minecraft:gray_stained_glass
fill ~38 ~10 ~31 ~38 ~11 ~31 minecraft:light_gray_stained_glass
fill ~33 ~10 ~25 ~33 ~11 ~25 minecraft:gray_stained_glass
fill ~40 ~10 ~25 ~40 ~11 ~25 minecraft:light_gray_stained_glass
fill ~33 ~10 ~28 ~33 ~11 ~28 minecraft:gray_stained_glass
fill ~40 ~10 ~28 ~40 ~11 ~28 minecraft:light_gray_stained_glass
fill ~35 ~14 ~23 ~35 ~15 ~23 minecraft:gray_stained_glass
fill ~35 ~14 ~31 ~35 ~15 ~31 minecraft:light_gray_stained_glass
fill ~38 ~14 ~23 ~38 ~15 ~23 minecraft:gray_stained_glass
fill ~38 ~14 ~31 ~38 ~15 ~31 minecraft:light_gray_stained_glass
fill ~33 ~14 ~25 ~33 ~15 ~25 minecraft:gray_stained_glass
fill ~40 ~14 ~25 ~40 ~15 ~25 minecraft:light_gray_stained_glass
fill ~33 ~14 ~28 ~33 ~15 ~28 minecraft:gray_stained_glass
fill ~40 ~14 ~28 ~40 ~15 ~28 minecraft:light_gray_stained_glass
fill ~35 ~18 ~23 ~35 ~19 ~23 minecraft:gray_stained_glass
fill ~35 ~18 ~31 ~35 ~19 ~31 minecraft:light_gray_stained_glass
fill ~38 ~18 ~23 ~38 ~19 ~23 minecraft:gray_stained_glass
fill ~38 ~18 ~31 ~38 ~19 ~31 minecraft:light_gray_stained_glass
fill ~33 ~18 ~25 ~33 ~19 ~25 minecraft:gray_stained_glass
fill ~40 ~18 ~25 ~40 ~19 ~25 minecraft:light_gray_stained_glass
fill ~33 ~18 ~28 ~33 ~19 ~28 minecraft:gray_stained_glass
fill ~40 ~18 ~28 ~40 ~19 ~28 minecraft:light_gray_stained_glass
setblock ~36 ~1 ~23 minecraft:iron_door[half=lower,facing=north]
setblock ~36 ~2 ~23 minecraft:iron_door[half=upper,facing=north]
fill ~33 ~21 ~23 ~40 ~21 ~31 minecraft:smooth_stone_slab
fill ~34 ~22 ~24 ~39 ~22 ~30 minecraft:smooth_stone_slab
setblock ~36 ~3 ~22 minecraft:dark_oak_slab[type=top]
fill ~35 ~22 ~25 ~37 ~23 ~27 minecraft:light_gray_concrete
setblock ~38 ~22 ~26 minecraft:lightning_rod
fill ~34 ~1 ~23 ~34 ~7 ~23 doomsday_decoration:cementwall
fill ~38 ~1 ~23 ~38 ~7 ~23 doomsday_decoration:cementwall
