# Buildings 49..56
# 049 local_shop style=storefront context=local_front facing=east
fill ~-125 ~-3 ~94 ~-116 ~-1 ~100 minecraft:stone
fill ~-125 ~0 ~94 ~-116 ~7 ~100 minecraft:calcite
fill ~-124 ~1 ~95 ~-117 ~6 ~99 minecraft:air
fill ~-124 ~4 ~95 ~-117 ~4 ~99 minecraft:smooth_stone
fill ~-123 ~2 ~94 ~-123 ~3 ~94 minecraft:gray_stained_glass
fill ~-123 ~2 ~100 ~-123 ~3 ~100 minecraft:light_gray_stained_glass
fill ~-120 ~2 ~94 ~-120 ~3 ~94 minecraft:gray_stained_glass
fill ~-120 ~2 ~100 ~-120 ~3 ~100 minecraft:light_gray_stained_glass
fill ~-125 ~2 ~96 ~-125 ~3 ~96 minecraft:gray_stained_glass
fill ~-116 ~2 ~96 ~-116 ~3 ~96 minecraft:light_gray_stained_glass
setblock ~-116 ~1 ~97 minecraft:iron_door[half=lower,facing=east]
setblock ~-116 ~2 ~97 minecraft:iron_door[half=upper,facing=east]
fill ~-116 ~1 ~95 ~-116 ~3 ~99 minecraft:cyan_stained_glass
setblock ~-116 ~1 ~97 minecraft:iron_door[half=lower,facing=east]
setblock ~-116 ~2 ~97 minecraft:iron_door[half=upper,facing=east]
setblock ~-115 ~3 ~97 minecraft:red_wool
fill ~-125 ~8 ~94 ~-116 ~8 ~100 minecraft:stone_brick_slab
# 050 midrise_housing style=mixed_facade context=collector_front facing=south
fill ~-121 ~-3 ~1 ~-111 ~-1 ~10 minecraft:stone
fill ~-121 ~0 ~1 ~-111 ~11 ~10 minecraft:calcite
fill ~-120 ~1 ~2 ~-112 ~10 ~9 minecraft:air
fill ~-120 ~4 ~2 ~-112 ~4 ~9 minecraft:smooth_stone
fill ~-120 ~8 ~2 ~-112 ~8 ~9 minecraft:smooth_stone
fill ~-119 ~2 ~1 ~-119 ~3 ~1 minecraft:gray_stained_glass
fill ~-119 ~2 ~10 ~-119 ~3 ~10 minecraft:light_gray_stained_glass
fill ~-116 ~2 ~1 ~-116 ~3 ~1 minecraft:gray_stained_glass
fill ~-116 ~2 ~10 ~-116 ~3 ~10 minecraft:light_gray_stained_glass
fill ~-113 ~2 ~1 ~-113 ~3 ~1 minecraft:gray_stained_glass
fill ~-113 ~2 ~10 ~-113 ~3 ~10 minecraft:light_gray_stained_glass
fill ~-121 ~2 ~3 ~-121 ~3 ~3 minecraft:gray_stained_glass
fill ~-111 ~2 ~3 ~-111 ~3 ~3 minecraft:light_gray_stained_glass
fill ~-121 ~2 ~6 ~-121 ~3 ~6 minecraft:gray_stained_glass
fill ~-111 ~2 ~6 ~-111 ~3 ~6 minecraft:light_gray_stained_glass
fill ~-119 ~6 ~1 ~-119 ~7 ~1 minecraft:gray_stained_glass
fill ~-119 ~6 ~10 ~-119 ~7 ~10 minecraft:light_gray_stained_glass
fill ~-116 ~6 ~1 ~-116 ~7 ~1 minecraft:gray_stained_glass
fill ~-116 ~6 ~10 ~-116 ~7 ~10 minecraft:light_gray_stained_glass
fill ~-113 ~6 ~1 ~-113 ~7 ~1 minecraft:gray_stained_glass
fill ~-113 ~6 ~10 ~-113 ~7 ~10 minecraft:light_gray_stained_glass
fill ~-121 ~6 ~3 ~-121 ~7 ~3 minecraft:gray_stained_glass
fill ~-111 ~6 ~3 ~-111 ~7 ~3 minecraft:light_gray_stained_glass
fill ~-121 ~6 ~6 ~-121 ~7 ~6 minecraft:gray_stained_glass
fill ~-111 ~6 ~6 ~-111 ~7 ~6 minecraft:light_gray_stained_glass
setblock ~-116 ~1 ~10 minecraft:iron_door[half=lower,facing=south]
setblock ~-116 ~2 ~10 minecraft:iron_door[half=upper,facing=south]
fill ~-121 ~12 ~1 ~-111 ~12 ~10 minecraft:stone_brick_slab
# 051 waterfront_hotel style=setback_tower context=waterfront_front facing=west
fill ~87 ~-3 ~-73 ~94 ~-1 ~-63 minecraft:stone
fill ~87 ~0 ~-73 ~94 ~9 ~-63 minecraft:white_terracotta
fill ~88 ~1 ~-72 ~93 ~8 ~-64 minecraft:air
fill ~88 ~4 ~-72 ~93 ~4 ~-64 minecraft:smooth_stone
fill ~88 ~8 ~-72 ~93 ~8 ~-64 minecraft:smooth_stone
fill ~89 ~2 ~-73 ~89 ~3 ~-73 minecraft:gray_stained_glass
fill ~89 ~2 ~-63 ~89 ~3 ~-63 minecraft:light_gray_stained_glass
fill ~92 ~2 ~-73 ~92 ~3 ~-73 minecraft:gray_stained_glass
fill ~92 ~2 ~-63 ~92 ~3 ~-63 minecraft:light_gray_stained_glass
fill ~87 ~2 ~-71 ~87 ~3 ~-71 minecraft:gray_stained_glass
fill ~94 ~2 ~-71 ~94 ~3 ~-71 minecraft:light_gray_stained_glass
fill ~87 ~2 ~-68 ~87 ~3 ~-68 minecraft:gray_stained_glass
fill ~94 ~2 ~-68 ~94 ~3 ~-68 minecraft:light_gray_stained_glass
fill ~87 ~2 ~-65 ~87 ~3 ~-65 minecraft:gray_stained_glass
fill ~94 ~2 ~-65 ~94 ~3 ~-65 minecraft:light_gray_stained_glass
fill ~89 ~6 ~-73 ~89 ~7 ~-73 minecraft:gray_stained_glass
fill ~89 ~6 ~-63 ~89 ~7 ~-63 minecraft:light_gray_stained_glass
fill ~92 ~6 ~-73 ~92 ~7 ~-73 minecraft:gray_stained_glass
fill ~92 ~6 ~-63 ~92 ~7 ~-63 minecraft:light_gray_stained_glass
fill ~87 ~6 ~-71 ~87 ~7 ~-71 minecraft:gray_stained_glass
fill ~94 ~6 ~-71 ~94 ~7 ~-71 minecraft:light_gray_stained_glass
fill ~87 ~6 ~-68 ~87 ~7 ~-68 minecraft:gray_stained_glass
fill ~94 ~6 ~-68 ~94 ~7 ~-68 minecraft:light_gray_stained_glass
fill ~87 ~6 ~-65 ~87 ~7 ~-65 minecraft:gray_stained_glass
fill ~94 ~6 ~-65 ~94 ~7 ~-65 minecraft:light_gray_stained_glass
setblock ~87 ~1 ~-68 minecraft:iron_door[half=lower,facing=west]
setblock ~87 ~2 ~-68 minecraft:iron_door[half=upper,facing=west]
fill ~89 ~11 ~-71 ~91 ~12 ~-69 minecraft:light_gray_concrete
setblock ~92 ~11 ~-70 minecraft:lightning_rod
# 052 small_office style=bay_office context=back_block facing=north
fill ~-122 ~-3 ~111 ~-116 ~-1 ~117 minecraft:stone
fill ~-122 ~0 ~111 ~-116 ~7 ~117 minecraft:white_terracotta
fill ~-121 ~1 ~112 ~-117 ~6 ~116 minecraft:air
fill ~-121 ~4 ~112 ~-117 ~4 ~116 minecraft:smooth_stone
fill ~-120 ~2 ~111 ~-120 ~3 ~111 minecraft:gray_stained_glass
fill ~-120 ~2 ~117 ~-120 ~3 ~117 minecraft:light_gray_stained_glass
fill ~-122 ~2 ~113 ~-122 ~3 ~113 minecraft:gray_stained_glass
fill ~-116 ~2 ~113 ~-116 ~3 ~113 minecraft:light_gray_stained_glass
setblock ~-119 ~1 ~111 minecraft:iron_door[half=lower,facing=north]
setblock ~-119 ~2 ~111 minecraft:iron_door[half=upper,facing=north]
# 053 workshop style=industrial_shed context=back_block facing=north
fill ~-125 ~-3 ~-68 ~-114 ~-1 ~-61 minecraft:stone
fill ~-125 ~0 ~-68 ~-114 ~7 ~-61 minecraft:mud_bricks
fill ~-124 ~1 ~-67 ~-115 ~6 ~-62 minecraft:air
fill ~-124 ~4 ~-67 ~-115 ~4 ~-62 minecraft:smooth_stone
fill ~-123 ~2 ~-68 ~-123 ~3 ~-68 minecraft:gray_stained_glass
fill ~-123 ~2 ~-61 ~-123 ~3 ~-61 minecraft:light_gray_stained_glass
fill ~-120 ~2 ~-68 ~-120 ~3 ~-68 minecraft:gray_stained_glass
fill ~-120 ~2 ~-61 ~-120 ~3 ~-61 minecraft:light_gray_stained_glass
fill ~-117 ~2 ~-68 ~-117 ~3 ~-68 minecraft:gray_stained_glass
fill ~-117 ~2 ~-61 ~-117 ~3 ~-61 minecraft:light_gray_stained_glass
fill ~-125 ~2 ~-66 ~-125 ~3 ~-66 minecraft:gray_stained_glass
fill ~-114 ~2 ~-66 ~-114 ~3 ~-66 minecraft:light_gray_stained_glass
fill ~-125 ~2 ~-63 ~-125 ~3 ~-63 minecraft:gray_stained_glass
fill ~-114 ~2 ~-63 ~-114 ~3 ~-63 minecraft:light_gray_stained_glass
setblock ~-120 ~1 ~-68 minecraft:iron_door[half=lower,facing=north]
setblock ~-120 ~2 ~-68 minecraft:iron_door[half=upper,facing=north]
fill ~-123 ~1 ~-68 ~-116 ~4 ~-68 minecraft:polished_blackstone
fill ~-123 ~5 ~-68 ~-116 ~5 ~-68 minecraft:light_blue_stained_glass
fill ~-123 ~9 ~-66 ~-121 ~10 ~-64 minecraft:iron_block
fill ~-125 ~8 ~-68 ~-114 ~8 ~-61 minecraft:deepslate_tile_slab
# 054 row_house style=japanese_house context=back_block facing=east
fill ~-70 ~-3 ~38 ~-64 ~-1 ~53 minecraft:stone
fill ~-70 ~0 ~38 ~-64 ~8 ~53 minecraft:light_gray_concrete
fill ~-69 ~1 ~39 ~-65 ~7 ~52 minecraft:air
fill ~-69 ~4 ~39 ~-65 ~4 ~52 minecraft:smooth_stone
fill ~-68 ~2 ~38 ~-68 ~3 ~38 minecraft:gray_stained_glass
fill ~-68 ~2 ~53 ~-68 ~3 ~53 minecraft:light_gray_stained_glass
fill ~-70 ~2 ~40 ~-70 ~3 ~40 minecraft:gray_stained_glass
fill ~-64 ~2 ~40 ~-64 ~3 ~40 minecraft:light_gray_stained_glass
fill ~-70 ~2 ~43 ~-70 ~3 ~43 minecraft:gray_stained_glass
fill ~-64 ~2 ~43 ~-64 ~3 ~43 minecraft:light_gray_stained_glass
fill ~-70 ~2 ~46 ~-70 ~3 ~46 minecraft:gray_stained_glass
fill ~-64 ~2 ~46 ~-64 ~3 ~46 minecraft:light_gray_stained_glass
fill ~-70 ~2 ~49 ~-70 ~3 ~49 minecraft:gray_stained_glass
fill ~-64 ~2 ~49 ~-64 ~3 ~49 minecraft:light_gray_stained_glass
fill ~-68 ~6 ~38 ~-68 ~7 ~38 minecraft:gray_stained_glass
fill ~-68 ~6 ~53 ~-68 ~7 ~53 minecraft:light_gray_stained_glass
fill ~-70 ~6 ~40 ~-70 ~7 ~40 minecraft:gray_stained_glass
fill ~-64 ~6 ~40 ~-64 ~7 ~40 minecraft:light_gray_stained_glass
fill ~-70 ~6 ~43 ~-70 ~7 ~43 minecraft:gray_stained_glass
fill ~-64 ~6 ~43 ~-64 ~7 ~43 minecraft:light_gray_stained_glass
fill ~-70 ~6 ~46 ~-70 ~7 ~46 minecraft:gray_stained_glass
fill ~-64 ~6 ~46 ~-64 ~7 ~46 minecraft:light_gray_stained_glass
fill ~-70 ~6 ~49 ~-70 ~7 ~49 minecraft:gray_stained_glass
fill ~-64 ~6 ~49 ~-64 ~7 ~49 minecraft:light_gray_stained_glass
setblock ~-64 ~1 ~43 minecraft:iron_door[half=lower,facing=east]
setblock ~-64 ~2 ~43 minecraft:iron_door[half=upper,facing=east]
fill ~-70 ~9 ~38 ~-64 ~9 ~53 minecraft:smooth_stone_slab
fill ~-69 ~10 ~39 ~-65 ~10 ~52 minecraft:smooth_stone_slab
setblock ~-63 ~3 ~43 minecraft:dark_oak_slab[type=top]
fill ~-68 ~10 ~40 ~-66 ~11 ~42 minecraft:light_gray_concrete
setblock ~-65 ~10 ~41 minecraft:lightning_rod
# 055 apartment style=setback_block context=waterfront_front facing=west
fill ~103 ~-3 ~-4 ~108 ~-1 ~5 minecraft:stone
fill ~103 ~0 ~-4 ~108 ~5 ~5 minecraft:white_concrete
fill ~104 ~1 ~-3 ~107 ~4 ~4 minecraft:air
fill ~104 ~4 ~-3 ~107 ~4 ~4 minecraft:smooth_stone
fill ~105 ~2 ~-4 ~105 ~3 ~-4 minecraft:gray_stained_glass
fill ~105 ~2 ~5 ~105 ~3 ~5 minecraft:light_gray_stained_glass
fill ~103 ~2 ~-2 ~103 ~3 ~-2 minecraft:gray_stained_glass
fill ~108 ~2 ~-2 ~108 ~3 ~-2 minecraft:light_gray_stained_glass
fill ~103 ~2 ~1 ~103 ~3 ~1 minecraft:gray_stained_glass
fill ~108 ~2 ~1 ~108 ~3 ~1 minecraft:light_gray_stained_glass
setblock ~103 ~1 ~0 minecraft:iron_door[half=lower,facing=west]
setblock ~103 ~2 ~0 minecraft:iron_door[half=upper,facing=west]
# 056 logistics style=sawtooth context=local_front facing=west
fill ~12 ~-3 ~-125 ~26 ~-1 ~-112 minecraft:stone
fill ~12 ~0 ~-125 ~26 ~10 ~-112 minecraft:bricks
fill ~13 ~1 ~-124 ~25 ~9 ~-113 minecraft:air
fill ~13 ~4 ~-124 ~25 ~4 ~-113 minecraft:smooth_stone
fill ~13 ~8 ~-124 ~25 ~8 ~-113 minecraft:smooth_stone
fill ~14 ~2 ~-125 ~14 ~3 ~-125 minecraft:gray_stained_glass
fill ~14 ~2 ~-112 ~14 ~3 ~-112 minecraft:light_gray_stained_glass
fill ~17 ~2 ~-125 ~17 ~3 ~-125 minecraft:gray_stained_glass
fill ~17 ~2 ~-112 ~17 ~3 ~-112 minecraft:light_gray_stained_glass
fill ~20 ~2 ~-125 ~20 ~3 ~-125 minecraft:gray_stained_glass
fill ~20 ~2 ~-112 ~20 ~3 ~-112 minecraft:light_gray_stained_glass
fill ~23 ~2 ~-125 ~23 ~3 ~-125 minecraft:gray_stained_glass
fill ~23 ~2 ~-112 ~23 ~3 ~-112 minecraft:light_gray_stained_glass
fill ~12 ~2 ~-123 ~12 ~3 ~-123 minecraft:gray_stained_glass
fill ~26 ~2 ~-123 ~26 ~3 ~-123 minecraft:light_gray_stained_glass
fill ~12 ~2 ~-120 ~12 ~3 ~-120 minecraft:gray_stained_glass
fill ~26 ~2 ~-120 ~26 ~3 ~-120 minecraft:light_gray_stained_glass
fill ~12 ~2 ~-117 ~12 ~3 ~-117 minecraft:gray_stained_glass
fill ~26 ~2 ~-117 ~26 ~3 ~-117 minecraft:light_gray_stained_glass
fill ~12 ~2 ~-114 ~12 ~3 ~-114 minecraft:gray_stained_glass
fill ~26 ~2 ~-114 ~26 ~3 ~-114 minecraft:light_gray_stained_glass
fill ~14 ~6 ~-125 ~14 ~7 ~-125 minecraft:gray_stained_glass
fill ~14 ~6 ~-112 ~14 ~7 ~-112 minecraft:light_gray_stained_glass
fill ~17 ~6 ~-125 ~17 ~7 ~-125 minecraft:gray_stained_glass
fill ~17 ~6 ~-112 ~17 ~7 ~-112 minecraft:light_gray_stained_glass
fill ~20 ~6 ~-125 ~20 ~7 ~-125 minecraft:gray_stained_glass
fill ~20 ~6 ~-112 ~20 ~7 ~-112 minecraft:light_gray_stained_glass
fill ~23 ~6 ~-125 ~23 ~7 ~-125 minecraft:gray_stained_glass
fill ~23 ~6 ~-112 ~23 ~7 ~-112 minecraft:light_gray_stained_glass
fill ~12 ~6 ~-123 ~12 ~7 ~-123 minecraft:gray_stained_glass
fill ~26 ~6 ~-123 ~26 ~7 ~-123 minecraft:light_gray_stained_glass
fill ~12 ~6 ~-120 ~12 ~7 ~-120 minecraft:gray_stained_glass
fill ~26 ~6 ~-120 ~26 ~7 ~-120 minecraft:light_gray_stained_glass
fill ~12 ~6 ~-117 ~12 ~7 ~-117 minecraft:gray_stained_glass
fill ~26 ~6 ~-117 ~26 ~7 ~-117 minecraft:light_gray_stained_glass
fill ~12 ~6 ~-114 ~12 ~7 ~-114 minecraft:gray_stained_glass
fill ~26 ~6 ~-114 ~26 ~7 ~-114 minecraft:light_gray_stained_glass
setblock ~12 ~1 ~-120 minecraft:iron_door[half=lower,facing=west]
setblock ~12 ~2 ~-120 minecraft:iron_door[half=upper,facing=west]
fill ~12 ~1 ~-123 ~12 ~4 ~-114 minecraft:polished_blackstone
fill ~12 ~5 ~-123 ~12 ~5 ~-114 minecraft:light_blue_stained_glass
fill ~14 ~12 ~-123 ~16 ~13 ~-121 minecraft:iron_block
fill ~12 ~11 ~-125 ~26 ~11 ~-112 minecraft:deepslate_tile_slab
