# Buildings 177..184
# 177 local_shop style=corner_store context=arterial_front facing=north
fill ~66 ~-3 ~6 ~69 ~-1 ~11 minecraft:stone
fill ~66 ~0 ~6 ~69 ~7 ~11 minecraft:smooth_sandstone
fill ~67 ~1 ~7 ~68 ~6 ~10 minecraft:air
fill ~67 ~4 ~7 ~68 ~4 ~10 minecraft:smooth_stone
fill ~66 ~2 ~8 ~66 ~3 ~8 minecraft:gray_stained_glass
fill ~69 ~2 ~8 ~69 ~3 ~8 minecraft:light_gray_stained_glass
setblock ~68 ~1 ~6 minecraft:iron_door[half=lower,facing=north]
setblock ~68 ~2 ~6 minecraft:iron_door[half=upper,facing=north]
fill ~67 ~1 ~6 ~68 ~3 ~6 minecraft:cyan_stained_glass
setblock ~68 ~1 ~6 minecraft:iron_door[half=lower,facing=north]
setblock ~68 ~2 ~6 minecraft:iron_door[half=upper,facing=north]
setblock ~68 ~3 ~5 minecraft:red_wool
fill ~66 ~8 ~6 ~69 ~8 ~11 minecraft:stone_brick_slab
# 178 shop_house style=storefront context=local_front facing=south
fill ~-16 ~-3 ~-54 ~-12 ~-1 ~-48 minecraft:stone
fill ~-16 ~0 ~-54 ~-12 ~9 ~-48 minecraft:light_gray_concrete
fill ~-15 ~1 ~-53 ~-13 ~8 ~-49 minecraft:air
fill ~-15 ~4 ~-53 ~-13 ~4 ~-49 minecraft:smooth_stone
fill ~-15 ~8 ~-53 ~-13 ~8 ~-49 minecraft:smooth_stone
fill ~-14 ~2 ~-54 ~-14 ~3 ~-54 minecraft:gray_stained_glass
fill ~-14 ~2 ~-48 ~-14 ~3 ~-48 minecraft:light_gray_stained_glass
fill ~-16 ~2 ~-52 ~-16 ~3 ~-52 minecraft:gray_stained_glass
fill ~-12 ~2 ~-52 ~-12 ~3 ~-52 minecraft:light_gray_stained_glass
fill ~-14 ~6 ~-54 ~-14 ~7 ~-54 minecraft:gray_stained_glass
fill ~-14 ~6 ~-48 ~-14 ~7 ~-48 minecraft:light_gray_stained_glass
fill ~-16 ~6 ~-52 ~-16 ~7 ~-52 minecraft:gray_stained_glass
fill ~-12 ~6 ~-52 ~-12 ~7 ~-52 minecraft:light_gray_stained_glass
setblock ~-14 ~1 ~-48 minecraft:iron_door[half=lower,facing=south]
setblock ~-14 ~2 ~-48 minecraft:iron_door[half=upper,facing=south]
fill ~-15 ~1 ~-48 ~-13 ~3 ~-48 minecraft:cyan_stained_glass
setblock ~-14 ~1 ~-48 minecraft:iron_door[half=lower,facing=south]
setblock ~-14 ~2 ~-48 minecraft:iron_door[half=upper,facing=south]
setblock ~-14 ~3 ~-47 minecraft:red_wool
fill ~-16 ~10 ~-54 ~-12 ~10 ~-48 minecraft:smooth_stone_slab
# 179 workshop style=industrial_shed context=arterial_front facing=south
fill ~73 ~-3 ~-17 ~78 ~-1 ~-10 minecraft:stone
fill ~73 ~0 ~-17 ~78 ~7 ~-10 minecraft:light_gray_concrete
fill ~74 ~1 ~-16 ~77 ~6 ~-11 minecraft:air
fill ~74 ~4 ~-16 ~77 ~4 ~-11 minecraft:smooth_stone
fill ~75 ~2 ~-17 ~75 ~3 ~-17 minecraft:gray_stained_glass
fill ~75 ~2 ~-10 ~75 ~3 ~-10 minecraft:light_gray_stained_glass
fill ~73 ~2 ~-15 ~73 ~3 ~-15 minecraft:gray_stained_glass
fill ~78 ~2 ~-15 ~78 ~3 ~-15 minecraft:light_gray_stained_glass
fill ~73 ~2 ~-12 ~73 ~3 ~-12 minecraft:gray_stained_glass
fill ~78 ~2 ~-12 ~78 ~3 ~-12 minecraft:light_gray_stained_glass
setblock ~75 ~1 ~-10 minecraft:iron_door[half=lower,facing=south]
setblock ~75 ~2 ~-10 minecraft:iron_door[half=upper,facing=south]
fill ~75 ~1 ~-10 ~76 ~4 ~-10 minecraft:polished_blackstone
fill ~75 ~5 ~-10 ~76 ~5 ~-10 minecraft:light_blue_stained_glass
fill ~75 ~9 ~-15 ~77 ~10 ~-13 minecraft:iron_block
fill ~73 ~8 ~-17 ~78 ~8 ~-10 minecraft:smooth_stone_slab
fill ~74 ~1 ~-10 ~74 ~7 ~-10 doomsday_decoration:porcelainbrickwall
# 180 row_house style=stepped_house context=collector_front facing=west
fill ~52 ~-3 ~102 ~57 ~-1 ~105 minecraft:stone
fill ~52 ~0 ~102 ~57 ~11 ~105 minecraft:deepslate_bricks
fill ~53 ~1 ~103 ~56 ~10 ~104 minecraft:air
fill ~53 ~4 ~103 ~56 ~4 ~104 minecraft:smooth_stone
fill ~53 ~8 ~103 ~56 ~8 ~104 minecraft:smooth_stone
fill ~54 ~2 ~102 ~54 ~3 ~102 minecraft:gray_stained_glass
fill ~54 ~2 ~105 ~54 ~3 ~105 minecraft:light_gray_stained_glass
fill ~54 ~6 ~102 ~54 ~7 ~102 minecraft:gray_stained_glass
fill ~54 ~6 ~105 ~54 ~7 ~105 minecraft:light_gray_stained_glass
setblock ~52 ~1 ~104 minecraft:iron_door[half=lower,facing=west]
setblock ~52 ~2 ~104 minecraft:iron_door[half=upper,facing=west]
fill ~52 ~12 ~102 ~57 ~12 ~105 minecraft:deepslate_tile_slab
fill ~53 ~13 ~103 ~56 ~13 ~104 minecraft:deepslate_tile_slab
setblock ~51 ~3 ~104 minecraft:dark_oak_slab[type=top]
fill ~54 ~13 ~104 ~56 ~14 ~104 minecraft:light_gray_concrete
setblock ~56 ~13 ~104 minecraft:lightning_rod
# 181 row_house style=japanese_house context=collector_front facing=west
fill ~-96 ~-3 ~-99 ~-90 ~-1 ~-95 minecraft:stone
fill ~-96 ~0 ~-99 ~-90 ~7 ~-95 minecraft:bricks
fill ~-95 ~1 ~-98 ~-91 ~6 ~-96 minecraft:air
fill ~-95 ~4 ~-98 ~-91 ~4 ~-96 minecraft:smooth_stone
fill ~-94 ~2 ~-99 ~-94 ~3 ~-99 minecraft:gray_stained_glass
fill ~-94 ~2 ~-95 ~-94 ~3 ~-95 minecraft:light_gray_stained_glass
fill ~-96 ~2 ~-97 ~-96 ~3 ~-97 minecraft:gray_stained_glass
fill ~-90 ~2 ~-97 ~-90 ~3 ~-97 minecraft:light_gray_stained_glass
setblock ~-96 ~1 ~-97 minecraft:iron_door[half=lower,facing=west]
setblock ~-96 ~2 ~-97 minecraft:iron_door[half=upper,facing=west]
fill ~-96 ~8 ~-99 ~-90 ~8 ~-95 minecraft:deepslate_tile_slab
fill ~-95 ~9 ~-98 ~-91 ~9 ~-96 minecraft:deepslate_tile_slab
setblock ~-97 ~3 ~-97 minecraft:dark_oak_slab[type=top]
# 182 workshop style=loading_bay context=collector_front facing=north
fill ~-87 ~-3 ~114 ~-83 ~-1 ~120 minecraft:stone
fill ~-87 ~0 ~114 ~-83 ~11 ~120 minecraft:calcite
fill ~-86 ~1 ~115 ~-84 ~10 ~119 minecraft:air
fill ~-86 ~4 ~115 ~-84 ~4 ~119 minecraft:smooth_stone
fill ~-86 ~8 ~115 ~-84 ~8 ~119 minecraft:smooth_stone
fill ~-85 ~2 ~114 ~-85 ~3 ~114 minecraft:gray_stained_glass
fill ~-85 ~2 ~120 ~-85 ~3 ~120 minecraft:light_gray_stained_glass
fill ~-87 ~2 ~116 ~-87 ~3 ~116 minecraft:gray_stained_glass
fill ~-83 ~2 ~116 ~-83 ~3 ~116 minecraft:light_gray_stained_glass
fill ~-85 ~6 ~114 ~-85 ~7 ~114 minecraft:gray_stained_glass
fill ~-85 ~6 ~120 ~-85 ~7 ~120 minecraft:light_gray_stained_glass
fill ~-87 ~6 ~116 ~-87 ~7 ~116 minecraft:gray_stained_glass
fill ~-83 ~6 ~116 ~-83 ~7 ~116 minecraft:light_gray_stained_glass
setblock ~-85 ~1 ~114 minecraft:iron_door[half=lower,facing=north]
setblock ~-85 ~2 ~114 minecraft:iron_door[half=upper,facing=north]
fill ~-85 ~1 ~114 ~-85 ~4 ~114 minecraft:polished_blackstone
fill ~-85 ~5 ~114 ~-85 ~5 ~114 minecraft:light_blue_stained_glass
fill ~-85 ~13 ~116 ~-84 ~14 ~118 minecraft:iron_block
fill ~-87 ~12 ~114 ~-83 ~12 ~120 minecraft:stone_brick_slab
# 183 row_house style=rowhouse context=collector_front facing=west
fill ~40 ~-3 ~-49 ~47 ~-1 ~-44 minecraft:stone
fill ~40 ~0 ~-49 ~47 ~9 ~-44 minecraft:smooth_sandstone
fill ~41 ~1 ~-48 ~46 ~8 ~-45 minecraft:air
fill ~41 ~4 ~-48 ~46 ~4 ~-45 minecraft:smooth_stone
fill ~41 ~8 ~-48 ~46 ~8 ~-45 minecraft:smooth_stone
fill ~42 ~2 ~-49 ~42 ~3 ~-49 minecraft:gray_stained_glass
fill ~42 ~2 ~-44 ~42 ~3 ~-44 minecraft:light_gray_stained_glass
fill ~45 ~2 ~-49 ~45 ~3 ~-49 minecraft:gray_stained_glass
fill ~45 ~2 ~-44 ~45 ~3 ~-44 minecraft:light_gray_stained_glass
fill ~40 ~2 ~-47 ~40 ~3 ~-47 minecraft:gray_stained_glass
fill ~47 ~2 ~-47 ~47 ~3 ~-47 minecraft:light_gray_stained_glass
fill ~42 ~6 ~-49 ~42 ~7 ~-49 minecraft:gray_stained_glass
fill ~42 ~6 ~-44 ~42 ~7 ~-44 minecraft:light_gray_stained_glass
fill ~45 ~6 ~-49 ~45 ~7 ~-49 minecraft:gray_stained_glass
fill ~45 ~6 ~-44 ~45 ~7 ~-44 minecraft:light_gray_stained_glass
fill ~40 ~6 ~-47 ~40 ~7 ~-47 minecraft:gray_stained_glass
fill ~47 ~6 ~-47 ~47 ~7 ~-47 minecraft:light_gray_stained_glass
setblock ~40 ~1 ~-47 minecraft:iron_door[half=lower,facing=west]
setblock ~40 ~2 ~-47 minecraft:iron_door[half=upper,facing=west]
fill ~40 ~10 ~-49 ~47 ~10 ~-44 minecraft:stone_brick_slab
fill ~41 ~11 ~-48 ~46 ~11 ~-45 minecraft:stone_brick_slab
setblock ~39 ~3 ~-47 minecraft:dark_oak_slab[type=top]
fill ~42 ~11 ~-47 ~44 ~12 ~-45 minecraft:light_gray_concrete
setblock ~45 ~11 ~-46 minecraft:lightning_rod
fill ~40 ~1 ~-48 ~40 ~7 ~-48 minecraft:brown_terracotta
# 184 shop_house style=arcade_shop context=local_front facing=east
fill ~-5 ~-3 ~89 ~0 ~-1 ~92 minecraft:stone
fill ~-5 ~0 ~89 ~0 ~5 ~92 minecraft:bricks
fill ~-4 ~1 ~90 ~-1 ~4 ~91 minecraft:air
fill ~-4 ~4 ~90 ~-1 ~4 ~91 minecraft:smooth_stone
fill ~-3 ~2 ~89 ~-3 ~3 ~89 minecraft:gray_stained_glass
fill ~-3 ~2 ~92 ~-3 ~3 ~92 minecraft:light_gray_stained_glass
setblock ~0 ~1 ~91 minecraft:iron_door[half=lower,facing=east]
setblock ~0 ~2 ~91 minecraft:iron_door[half=upper,facing=east]
fill ~0 ~1 ~90 ~0 ~3 ~91 minecraft:cyan_stained_glass
setblock ~0 ~1 ~91 minecraft:iron_door[half=lower,facing=east]
setblock ~0 ~2 ~91 minecraft:iron_door[half=upper,facing=east]
setblock ~1 ~3 ~91 minecraft:red_wool
fill ~0 ~4 ~90 ~0 ~4 ~91 doomsday_decoration:hollowbrick
fill ~-5 ~6 ~89 ~0 ~6 ~92 minecraft:deepslate_tile_slab
