# Buildings 113..120
# 113 midrise_housing style=setback_block context=collector_front facing=north
fill ~5 ~-3 ~-59 ~15 ~-1 ~-50 minecraft:stone
fill ~5 ~0 ~-59 ~15 ~16 ~-50 minecraft:light_gray_concrete
fill ~6 ~1 ~-58 ~14 ~15 ~-51 minecraft:air
fill ~6 ~4 ~-58 ~14 ~4 ~-51 minecraft:smooth_stone
fill ~6 ~8 ~-58 ~14 ~8 ~-51 minecraft:smooth_stone
fill ~6 ~12 ~-58 ~14 ~12 ~-51 minecraft:smooth_stone
fill ~7 ~2 ~-59 ~7 ~3 ~-59 minecraft:gray_stained_glass
fill ~7 ~2 ~-50 ~7 ~3 ~-50 minecraft:light_gray_stained_glass
fill ~10 ~2 ~-59 ~10 ~3 ~-59 minecraft:gray_stained_glass
fill ~10 ~2 ~-50 ~10 ~3 ~-50 minecraft:light_gray_stained_glass
fill ~13 ~2 ~-59 ~13 ~3 ~-59 minecraft:gray_stained_glass
fill ~13 ~2 ~-50 ~13 ~3 ~-50 minecraft:light_gray_stained_glass
fill ~5 ~2 ~-57 ~5 ~3 ~-57 minecraft:gray_stained_glass
fill ~15 ~2 ~-57 ~15 ~3 ~-57 minecraft:light_gray_stained_glass
fill ~5 ~2 ~-54 ~5 ~3 ~-54 minecraft:gray_stained_glass
fill ~15 ~2 ~-54 ~15 ~3 ~-54 minecraft:light_gray_stained_glass
fill ~7 ~6 ~-59 ~7 ~7 ~-59 minecraft:gray_stained_glass
fill ~7 ~6 ~-50 ~7 ~7 ~-50 minecraft:light_gray_stained_glass
fill ~10 ~6 ~-59 ~10 ~7 ~-59 minecraft:gray_stained_glass
fill ~10 ~6 ~-50 ~10 ~7 ~-50 minecraft:light_gray_stained_glass
fill ~13 ~6 ~-59 ~13 ~7 ~-59 minecraft:gray_stained_glass
fill ~13 ~6 ~-50 ~13 ~7 ~-50 minecraft:light_gray_stained_glass
fill ~5 ~6 ~-57 ~5 ~7 ~-57 minecraft:gray_stained_glass
fill ~15 ~6 ~-57 ~15 ~7 ~-57 minecraft:light_gray_stained_glass
fill ~5 ~6 ~-54 ~5 ~7 ~-54 minecraft:gray_stained_glass
fill ~15 ~6 ~-54 ~15 ~7 ~-54 minecraft:light_gray_stained_glass
fill ~7 ~10 ~-59 ~7 ~11 ~-59 minecraft:gray_stained_glass
fill ~7 ~10 ~-50 ~7 ~11 ~-50 minecraft:light_gray_stained_glass
fill ~10 ~10 ~-59 ~10 ~11 ~-59 minecraft:gray_stained_glass
fill ~10 ~10 ~-50 ~10 ~11 ~-50 minecraft:light_gray_stained_glass
fill ~13 ~10 ~-59 ~13 ~11 ~-59 minecraft:gray_stained_glass
fill ~13 ~10 ~-50 ~13 ~11 ~-50 minecraft:light_gray_stained_glass
fill ~5 ~10 ~-57 ~5 ~11 ~-57 minecraft:gray_stained_glass
fill ~15 ~10 ~-57 ~15 ~11 ~-57 minecraft:light_gray_stained_glass
fill ~5 ~10 ~-54 ~5 ~11 ~-54 minecraft:gray_stained_glass
fill ~15 ~10 ~-54 ~15 ~11 ~-54 minecraft:light_gray_stained_glass
fill ~7 ~14 ~-59 ~7 ~15 ~-59 minecraft:gray_stained_glass
fill ~7 ~14 ~-50 ~7 ~15 ~-50 minecraft:light_gray_stained_glass
fill ~10 ~14 ~-59 ~10 ~15 ~-59 minecraft:gray_stained_glass
fill ~10 ~14 ~-50 ~10 ~15 ~-50 minecraft:light_gray_stained_glass
fill ~13 ~14 ~-59 ~13 ~15 ~-59 minecraft:gray_stained_glass
fill ~13 ~14 ~-50 ~13 ~15 ~-50 minecraft:light_gray_stained_glass
fill ~5 ~14 ~-57 ~5 ~15 ~-57 minecraft:gray_stained_glass
fill ~15 ~14 ~-57 ~15 ~15 ~-57 minecraft:light_gray_stained_glass
fill ~5 ~14 ~-54 ~5 ~15 ~-54 minecraft:gray_stained_glass
fill ~15 ~14 ~-54 ~15 ~15 ~-54 minecraft:light_gray_stained_glass
setblock ~10 ~1 ~-59 minecraft:iron_door[half=lower,facing=north]
setblock ~10 ~2 ~-59 minecraft:iron_door[half=upper,facing=north]
fill ~5 ~11 ~-59 ~15 ~16 ~-50 minecraft:air
fill ~6 ~11 ~-58 ~14 ~16 ~-51 minecraft:light_gray_concrete
fill ~7 ~12 ~-57 ~13 ~15 ~-52 minecraft:air
fill ~6 ~17 ~-58 ~14 ~17 ~-51 minecraft:smooth_stone_slab
# 114 logistics style=industrial_shed context=collector_front facing=west
fill ~60 ~-3 ~-120 ~69 ~-1 ~-109 minecraft:stone
fill ~60 ~0 ~-120 ~69 ~10 ~-109 minecraft:stone_bricks
fill ~61 ~1 ~-119 ~68 ~9 ~-110 minecraft:air
fill ~61 ~4 ~-119 ~68 ~4 ~-110 minecraft:smooth_stone
fill ~61 ~8 ~-119 ~68 ~8 ~-110 minecraft:smooth_stone
fill ~62 ~2 ~-120 ~62 ~3 ~-120 minecraft:gray_stained_glass
fill ~62 ~2 ~-109 ~62 ~3 ~-109 minecraft:light_gray_stained_glass
fill ~65 ~2 ~-120 ~65 ~3 ~-120 minecraft:gray_stained_glass
fill ~65 ~2 ~-109 ~65 ~3 ~-109 minecraft:light_gray_stained_glass
fill ~60 ~2 ~-118 ~60 ~3 ~-118 minecraft:gray_stained_glass
fill ~69 ~2 ~-118 ~69 ~3 ~-118 minecraft:light_gray_stained_glass
fill ~60 ~2 ~-115 ~60 ~3 ~-115 minecraft:gray_stained_glass
fill ~69 ~2 ~-115 ~69 ~3 ~-115 minecraft:light_gray_stained_glass
fill ~60 ~2 ~-112 ~60 ~3 ~-112 minecraft:gray_stained_glass
fill ~69 ~2 ~-112 ~69 ~3 ~-112 minecraft:light_gray_stained_glass
fill ~62 ~6 ~-120 ~62 ~7 ~-120 minecraft:gray_stained_glass
fill ~62 ~6 ~-109 ~62 ~7 ~-109 minecraft:light_gray_stained_glass
fill ~65 ~6 ~-120 ~65 ~7 ~-120 minecraft:gray_stained_glass
fill ~65 ~6 ~-109 ~65 ~7 ~-109 minecraft:light_gray_stained_glass
fill ~60 ~6 ~-118 ~60 ~7 ~-118 minecraft:gray_stained_glass
fill ~69 ~6 ~-118 ~69 ~7 ~-118 minecraft:light_gray_stained_glass
fill ~60 ~6 ~-115 ~60 ~7 ~-115 minecraft:gray_stained_glass
fill ~69 ~6 ~-115 ~69 ~7 ~-115 minecraft:light_gray_stained_glass
fill ~60 ~6 ~-112 ~60 ~7 ~-112 minecraft:gray_stained_glass
fill ~69 ~6 ~-112 ~69 ~7 ~-112 minecraft:light_gray_stained_glass
setblock ~60 ~1 ~-115 minecraft:iron_door[half=lower,facing=west]
setblock ~60 ~2 ~-115 minecraft:iron_door[half=upper,facing=west]
fill ~60 ~1 ~-118 ~60 ~4 ~-111 minecraft:polished_blackstone
fill ~60 ~5 ~-118 ~60 ~5 ~-111 minecraft:light_blue_stained_glass
fill ~62 ~12 ~-118 ~64 ~13 ~-116 minecraft:iron_block
fill ~60 ~11 ~-120 ~69 ~11 ~-109 minecraft:smooth_stone_slab
fill ~62 ~12 ~-118 ~64 ~13 ~-116 minecraft:light_gray_concrete
setblock ~65 ~12 ~-117 minecraft:lightning_rod
# 115 detached_house style=stepped_house context=local_front facing=east
fill ~-2 ~-3 ~114 ~6 ~-1 ~122 minecraft:stone
fill ~-2 ~0 ~114 ~6 ~7 ~122 minecraft:white_terracotta
fill ~-1 ~1 ~115 ~5 ~6 ~121 minecraft:air
fill ~-1 ~4 ~115 ~5 ~4 ~121 minecraft:smooth_stone
fill ~0 ~2 ~114 ~0 ~3 ~114 minecraft:gray_stained_glass
fill ~0 ~2 ~122 ~0 ~3 ~122 minecraft:light_gray_stained_glass
fill ~3 ~2 ~114 ~3 ~3 ~114 minecraft:gray_stained_glass
fill ~3 ~2 ~122 ~3 ~3 ~122 minecraft:light_gray_stained_glass
fill ~-2 ~2 ~116 ~-2 ~3 ~116 minecraft:gray_stained_glass
fill ~6 ~2 ~116 ~6 ~3 ~116 minecraft:light_gray_stained_glass
fill ~-2 ~2 ~119 ~-2 ~3 ~119 minecraft:gray_stained_glass
fill ~6 ~2 ~119 ~6 ~3 ~119 minecraft:light_gray_stained_glass
setblock ~6 ~1 ~118 minecraft:iron_door[half=lower,facing=east]
setblock ~6 ~2 ~118 minecraft:iron_door[half=upper,facing=east]
fill ~-2 ~8 ~114 ~6 ~8 ~122 minecraft:dark_oak_slab
fill ~-1 ~9 ~115 ~5 ~9 ~121 minecraft:dark_oak_slab
setblock ~7 ~3 ~118 minecraft:dark_oak_slab[type=top]
# 116 large_retail style=storefront context=arterial_front facing=west
fill ~48 ~-3 ~107 ~57 ~-1 ~118 minecraft:stone
fill ~48 ~0 ~107 ~57 ~6 ~118 minecraft:stone_bricks
fill ~49 ~1 ~108 ~56 ~5 ~117 minecraft:air
fill ~49 ~4 ~108 ~56 ~4 ~117 minecraft:smooth_stone
fill ~50 ~2 ~107 ~50 ~3 ~107 minecraft:gray_stained_glass
fill ~50 ~2 ~118 ~50 ~3 ~118 minecraft:light_gray_stained_glass
fill ~53 ~2 ~107 ~53 ~3 ~107 minecraft:gray_stained_glass
fill ~53 ~2 ~118 ~53 ~3 ~118 minecraft:light_gray_stained_glass
fill ~48 ~2 ~109 ~48 ~3 ~109 minecraft:gray_stained_glass
fill ~57 ~2 ~109 ~57 ~3 ~109 minecraft:light_gray_stained_glass
fill ~48 ~2 ~112 ~48 ~3 ~112 minecraft:gray_stained_glass
fill ~57 ~2 ~112 ~57 ~3 ~112 minecraft:light_gray_stained_glass
fill ~48 ~2 ~115 ~48 ~3 ~115 minecraft:gray_stained_glass
fill ~57 ~2 ~115 ~57 ~3 ~115 minecraft:light_gray_stained_glass
setblock ~48 ~1 ~112 minecraft:iron_door[half=lower,facing=west]
setblock ~48 ~2 ~112 minecraft:iron_door[half=upper,facing=west]
fill ~48 ~1 ~108 ~48 ~3 ~117 minecraft:cyan_stained_glass
setblock ~48 ~1 ~112 minecraft:iron_door[half=lower,facing=west]
setblock ~48 ~2 ~112 minecraft:iron_door[half=upper,facing=west]
setblock ~47 ~3 ~112 minecraft:red_wool
fill ~48 ~7 ~107 ~57 ~7 ~118 minecraft:stone_brick_slab
# 117 clinic style=balcony_block context=collector_front facing=east
fill ~40 ~-3 ~-48 ~46 ~-1 ~-34 minecraft:stone
fill ~40 ~0 ~-48 ~46 ~8 ~-34 minecraft:smooth_sandstone
fill ~41 ~1 ~-47 ~45 ~7 ~-35 minecraft:air
fill ~41 ~4 ~-47 ~45 ~4 ~-35 minecraft:smooth_stone
fill ~42 ~2 ~-48 ~42 ~3 ~-48 minecraft:gray_stained_glass
fill ~42 ~2 ~-34 ~42 ~3 ~-34 minecraft:light_gray_stained_glass
fill ~40 ~2 ~-46 ~40 ~3 ~-46 minecraft:gray_stained_glass
fill ~46 ~2 ~-46 ~46 ~3 ~-46 minecraft:light_gray_stained_glass
fill ~40 ~2 ~-43 ~40 ~3 ~-43 minecraft:gray_stained_glass
fill ~46 ~2 ~-43 ~46 ~3 ~-43 minecraft:light_gray_stained_glass
fill ~40 ~2 ~-40 ~40 ~3 ~-40 minecraft:gray_stained_glass
fill ~46 ~2 ~-40 ~46 ~3 ~-40 minecraft:light_gray_stained_glass
fill ~40 ~2 ~-37 ~40 ~3 ~-37 minecraft:gray_stained_glass
fill ~46 ~2 ~-37 ~46 ~3 ~-37 minecraft:light_gray_stained_glass
fill ~42 ~6 ~-48 ~42 ~7 ~-48 minecraft:gray_stained_glass
fill ~42 ~6 ~-34 ~42 ~7 ~-34 minecraft:light_gray_stained_glass
fill ~40 ~6 ~-46 ~40 ~7 ~-46 minecraft:gray_stained_glass
fill ~46 ~6 ~-46 ~46 ~7 ~-46 minecraft:light_gray_stained_glass
fill ~40 ~6 ~-43 ~40 ~7 ~-43 minecraft:gray_stained_glass
fill ~46 ~6 ~-43 ~46 ~7 ~-43 minecraft:light_gray_stained_glass
fill ~40 ~6 ~-40 ~40 ~7 ~-40 minecraft:gray_stained_glass
fill ~46 ~6 ~-40 ~46 ~7 ~-40 minecraft:light_gray_stained_glass
fill ~40 ~6 ~-37 ~40 ~7 ~-37 minecraft:gray_stained_glass
fill ~46 ~6 ~-37 ~46 ~7 ~-37 minecraft:light_gray_stained_glass
setblock ~46 ~1 ~-43 minecraft:iron_door[half=lower,facing=east]
setblock ~46 ~2 ~-43 minecraft:iron_door[half=upper,facing=east]
fill ~47 ~4 ~-46 ~47 ~4 ~-36 minecraft:smooth_stone_slab
fill ~40 ~9 ~-48 ~46 ~9 ~-34 minecraft:stone_brick_slab
fill ~42 ~10 ~-46 ~44 ~11 ~-44 minecraft:light_gray_concrete
setblock ~45 ~10 ~-45 minecraft:lightning_rod
# 118 waterfront_hotel style=bay_office context=waterfront_front facing=west
fill ~102 ~-3 ~25 ~108 ~-1 ~35 minecraft:stone
fill ~102 ~0 ~25 ~108 ~11 ~35 minecraft:bricks
fill ~103 ~1 ~26 ~107 ~10 ~34 minecraft:air
fill ~103 ~4 ~26 ~107 ~4 ~34 minecraft:smooth_stone
fill ~103 ~8 ~26 ~107 ~8 ~34 minecraft:smooth_stone
fill ~104 ~2 ~25 ~104 ~3 ~25 minecraft:gray_stained_glass
fill ~104 ~2 ~35 ~104 ~3 ~35 minecraft:light_gray_stained_glass
fill ~102 ~2 ~27 ~102 ~3 ~27 minecraft:gray_stained_glass
fill ~108 ~2 ~27 ~108 ~3 ~27 minecraft:light_gray_stained_glass
fill ~102 ~2 ~30 ~102 ~3 ~30 minecraft:gray_stained_glass
fill ~108 ~2 ~30 ~108 ~3 ~30 minecraft:light_gray_stained_glass
fill ~102 ~2 ~33 ~102 ~3 ~33 minecraft:gray_stained_glass
fill ~108 ~2 ~33 ~108 ~3 ~33 minecraft:light_gray_stained_glass
fill ~104 ~6 ~25 ~104 ~7 ~25 minecraft:gray_stained_glass
fill ~104 ~6 ~35 ~104 ~7 ~35 minecraft:light_gray_stained_glass
fill ~102 ~6 ~27 ~102 ~7 ~27 minecraft:gray_stained_glass
fill ~108 ~6 ~27 ~108 ~7 ~27 minecraft:light_gray_stained_glass
fill ~102 ~6 ~30 ~102 ~7 ~30 minecraft:gray_stained_glass
fill ~108 ~6 ~30 ~108 ~7 ~30 minecraft:light_gray_stained_glass
fill ~102 ~6 ~33 ~102 ~7 ~33 minecraft:gray_stained_glass
fill ~108 ~6 ~33 ~108 ~7 ~33 minecraft:light_gray_stained_glass
setblock ~102 ~1 ~30 minecraft:iron_door[half=lower,facing=west]
setblock ~102 ~2 ~30 minecraft:iron_door[half=upper,facing=west]
fill ~102 ~7 ~25 ~108 ~11 ~35 minecraft:air
fill ~103 ~7 ~26 ~107 ~11 ~34 minecraft:bricks
fill ~104 ~8 ~27 ~106 ~10 ~33 minecraft:air
fill ~103 ~12 ~26 ~107 ~12 ~34 minecraft:deepslate_tile_slab
fill ~102 ~2 ~27 ~102 ~7 ~33 minecraft:blue_stained_glass
# 119 restaurant style=corner_store context=collector_front facing=north
fill ~-67 ~-3 ~80 ~-62 ~-1 ~87 minecraft:stone
fill ~-67 ~0 ~80 ~-62 ~9 ~87 minecraft:white_terracotta
fill ~-66 ~1 ~81 ~-63 ~8 ~86 minecraft:air
fill ~-66 ~4 ~81 ~-63 ~4 ~86 minecraft:smooth_stone
fill ~-66 ~8 ~81 ~-63 ~8 ~86 minecraft:smooth_stone
fill ~-65 ~2 ~80 ~-65 ~3 ~80 minecraft:gray_stained_glass
fill ~-65 ~2 ~87 ~-65 ~3 ~87 minecraft:light_gray_stained_glass
fill ~-67 ~2 ~82 ~-67 ~3 ~82 minecraft:gray_stained_glass
fill ~-62 ~2 ~82 ~-62 ~3 ~82 minecraft:light_gray_stained_glass
fill ~-67 ~2 ~85 ~-67 ~3 ~85 minecraft:gray_stained_glass
fill ~-62 ~2 ~85 ~-62 ~3 ~85 minecraft:light_gray_stained_glass
fill ~-65 ~6 ~80 ~-65 ~7 ~80 minecraft:gray_stained_glass
fill ~-65 ~6 ~87 ~-65 ~7 ~87 minecraft:light_gray_stained_glass
fill ~-67 ~6 ~82 ~-67 ~7 ~82 minecraft:gray_stained_glass
fill ~-62 ~6 ~82 ~-62 ~7 ~82 minecraft:light_gray_stained_glass
fill ~-67 ~6 ~85 ~-67 ~7 ~85 minecraft:gray_stained_glass
fill ~-62 ~6 ~85 ~-62 ~7 ~85 minecraft:light_gray_stained_glass
setblock ~-65 ~1 ~80 minecraft:iron_door[half=lower,facing=north]
setblock ~-65 ~2 ~80 minecraft:iron_door[half=upper,facing=north]
fill ~-66 ~1 ~80 ~-63 ~3 ~80 minecraft:cyan_stained_glass
setblock ~-65 ~1 ~80 minecraft:iron_door[half=lower,facing=north]
setblock ~-65 ~2 ~80 minecraft:iron_door[half=upper,facing=north]
setblock ~-65 ~3 ~79 minecraft:red_wool
fill ~-67 ~10 ~80 ~-62 ~10 ~87 minecraft:dark_oak_slab
# 120 hotel style=setback_tower context=arterial_front facing=west
fill ~27 ~-3 ~59 ~33 ~-1 ~70 minecraft:stone
fill ~27 ~0 ~59 ~33 ~8 ~70 minecraft:smooth_sandstone
fill ~28 ~1 ~60 ~32 ~7 ~69 minecraft:air
fill ~28 ~4 ~60 ~32 ~4 ~69 minecraft:smooth_stone
fill ~29 ~2 ~59 ~29 ~3 ~59 minecraft:gray_stained_glass
fill ~29 ~2 ~70 ~29 ~3 ~70 minecraft:light_gray_stained_glass
fill ~27 ~2 ~61 ~27 ~3 ~61 minecraft:gray_stained_glass
fill ~33 ~2 ~61 ~33 ~3 ~61 minecraft:light_gray_stained_glass
fill ~27 ~2 ~64 ~27 ~3 ~64 minecraft:gray_stained_glass
fill ~33 ~2 ~64 ~33 ~3 ~64 minecraft:light_gray_stained_glass
fill ~27 ~2 ~67 ~27 ~3 ~67 minecraft:gray_stained_glass
fill ~33 ~2 ~67 ~33 ~3 ~67 minecraft:light_gray_stained_glass
fill ~29 ~6 ~59 ~29 ~7 ~59 minecraft:gray_stained_glass
fill ~29 ~6 ~70 ~29 ~7 ~70 minecraft:light_gray_stained_glass
fill ~27 ~6 ~61 ~27 ~7 ~61 minecraft:gray_stained_glass
fill ~33 ~6 ~61 ~33 ~7 ~61 minecraft:light_gray_stained_glass
fill ~27 ~6 ~64 ~27 ~7 ~64 minecraft:gray_stained_glass
fill ~33 ~6 ~64 ~33 ~7 ~64 minecraft:light_gray_stained_glass
fill ~27 ~6 ~67 ~27 ~7 ~67 minecraft:gray_stained_glass
fill ~33 ~6 ~67 ~33 ~7 ~67 minecraft:light_gray_stained_glass
setblock ~27 ~1 ~64 minecraft:iron_door[half=lower,facing=west]
setblock ~27 ~2 ~64 minecraft:iron_door[half=upper,facing=west]
fill ~29 ~10 ~61 ~31 ~11 ~63 minecraft:light_gray_concrete
setblock ~32 ~10 ~62 minecraft:lightning_rod
