# Buildings 185..192
# 185 small_office style=bay_office context=collector_front facing=west
fill ~-82 ~-3 ~52 ~-77 ~-1 ~55 minecraft:stone
fill ~-82 ~0 ~52 ~-77 ~9 ~55 minecraft:light_gray_concrete
fill ~-81 ~1 ~53 ~-78 ~8 ~54 minecraft:air
fill ~-81 ~4 ~53 ~-78 ~4 ~54 minecraft:smooth_stone
fill ~-81 ~8 ~53 ~-78 ~8 ~54 minecraft:smooth_stone
fill ~-80 ~2 ~52 ~-80 ~3 ~52 minecraft:gray_stained_glass
fill ~-80 ~2 ~55 ~-80 ~3 ~55 minecraft:light_gray_stained_glass
fill ~-80 ~6 ~52 ~-80 ~7 ~52 minecraft:gray_stained_glass
fill ~-80 ~6 ~55 ~-80 ~7 ~55 minecraft:light_gray_stained_glass
setblock ~-82 ~1 ~54 minecraft:iron_door[half=lower,facing=west]
setblock ~-82 ~2 ~54 minecraft:iron_door[half=upper,facing=west]
# 186 shop_house style=arcade_shop context=local_front facing=south
fill ~-62 ~-3 ~-62 ~-57 ~-1 ~-55 minecraft:stone
fill ~-62 ~0 ~-62 ~-57 ~11 ~-55 minecraft:bricks
fill ~-61 ~1 ~-61 ~-58 ~10 ~-56 minecraft:air
fill ~-61 ~4 ~-61 ~-58 ~4 ~-56 minecraft:smooth_stone
fill ~-61 ~8 ~-61 ~-58 ~8 ~-56 minecraft:smooth_stone
fill ~-60 ~2 ~-62 ~-60 ~3 ~-62 minecraft:gray_stained_glass
fill ~-60 ~2 ~-55 ~-60 ~3 ~-55 minecraft:light_gray_stained_glass
fill ~-62 ~2 ~-60 ~-62 ~3 ~-60 minecraft:gray_stained_glass
fill ~-57 ~2 ~-60 ~-57 ~3 ~-60 minecraft:light_gray_stained_glass
fill ~-62 ~2 ~-57 ~-62 ~3 ~-57 minecraft:gray_stained_glass
fill ~-57 ~2 ~-57 ~-57 ~3 ~-57 minecraft:light_gray_stained_glass
fill ~-60 ~6 ~-62 ~-60 ~7 ~-62 minecraft:gray_stained_glass
fill ~-60 ~6 ~-55 ~-60 ~7 ~-55 minecraft:light_gray_stained_glass
fill ~-62 ~6 ~-60 ~-62 ~7 ~-60 minecraft:gray_stained_glass
fill ~-57 ~6 ~-60 ~-57 ~7 ~-60 minecraft:light_gray_stained_glass
fill ~-62 ~6 ~-57 ~-62 ~7 ~-57 minecraft:gray_stained_glass
fill ~-57 ~6 ~-57 ~-57 ~7 ~-57 minecraft:light_gray_stained_glass
setblock ~-60 ~1 ~-55 minecraft:iron_door[half=lower,facing=south]
setblock ~-60 ~2 ~-55 minecraft:iron_door[half=upper,facing=south]
fill ~-61 ~1 ~-55 ~-58 ~3 ~-55 minecraft:cyan_stained_glass
setblock ~-60 ~1 ~-55 minecraft:iron_door[half=lower,facing=south]
setblock ~-60 ~2 ~-55 minecraft:iron_door[half=upper,facing=south]
setblock ~-60 ~3 ~-54 minecraft:red_wool
fill ~-61 ~4 ~-55 ~-58 ~4 ~-55 doomsday_decoration:hollowbrick
fill ~-62 ~12 ~-62 ~-57 ~12 ~-55 minecraft:deepslate_tile_slab
fill ~-60 ~13 ~-60 ~-58 ~14 ~-58 minecraft:light_gray_concrete
setblock ~-58 ~13 ~-59 minecraft:lightning_rod
fill ~-61 ~1 ~-55 ~-61 ~7 ~-55 doomsday_decoration:hollowbrick
setblock ~-60 ~3 ~-55 minecraft:red_carpet
# 187 local_shop style=corner_store context=arterial_front facing=west
fill ~-31 ~-3 ~84 ~-25 ~-1 ~88 minecraft:stone
fill ~-31 ~0 ~84 ~-25 ~7 ~88 minecraft:bricks
fill ~-30 ~1 ~85 ~-26 ~6 ~87 minecraft:air
fill ~-30 ~4 ~85 ~-26 ~4 ~87 minecraft:smooth_stone
fill ~-29 ~2 ~84 ~-29 ~3 ~84 minecraft:gray_stained_glass
fill ~-29 ~2 ~88 ~-29 ~3 ~88 minecraft:light_gray_stained_glass
fill ~-31 ~2 ~86 ~-31 ~3 ~86 minecraft:gray_stained_glass
fill ~-25 ~2 ~86 ~-25 ~3 ~86 minecraft:light_gray_stained_glass
setblock ~-31 ~1 ~86 minecraft:iron_door[half=lower,facing=west]
setblock ~-31 ~2 ~86 minecraft:iron_door[half=upper,facing=west]
fill ~-31 ~1 ~85 ~-31 ~3 ~87 minecraft:cyan_stained_glass
setblock ~-31 ~1 ~86 minecraft:iron_door[half=lower,facing=west]
setblock ~-31 ~2 ~86 minecraft:iron_door[half=upper,facing=west]
setblock ~-32 ~3 ~86 minecraft:red_wool
fill ~-31 ~8 ~84 ~-25 ~8 ~88 minecraft:deepslate_tile_slab
# 188 shop_house style=corner_store context=local_front facing=north
fill ~46 ~-3 ~23 ~50 ~-1 ~29 minecraft:stone
fill ~46 ~0 ~23 ~50 ~7 ~29 minecraft:light_gray_concrete
fill ~47 ~1 ~24 ~49 ~6 ~28 minecraft:air
fill ~47 ~4 ~24 ~49 ~4 ~28 minecraft:smooth_stone
fill ~48 ~2 ~23 ~48 ~3 ~23 minecraft:gray_stained_glass
fill ~48 ~2 ~29 ~48 ~3 ~29 minecraft:light_gray_stained_glass
fill ~46 ~2 ~25 ~46 ~3 ~25 minecraft:gray_stained_glass
fill ~50 ~2 ~25 ~50 ~3 ~25 minecraft:light_gray_stained_glass
setblock ~48 ~1 ~23 minecraft:iron_door[half=lower,facing=north]
setblock ~48 ~2 ~23 minecraft:iron_door[half=upper,facing=north]
fill ~47 ~1 ~23 ~49 ~3 ~23 minecraft:cyan_stained_glass
setblock ~48 ~1 ~23 minecraft:iron_door[half=lower,facing=north]
setblock ~48 ~2 ~23 minecraft:iron_door[half=upper,facing=north]
setblock ~48 ~3 ~22 minecraft:red_wool
fill ~46 ~8 ~23 ~50 ~8 ~29 minecraft:smooth_stone_slab
# 189 row_house style=japanese_house context=local_front facing=south
fill ~-29 ~-3 ~-55 ~-24 ~-1 ~-48 minecraft:stone
fill ~-29 ~0 ~-55 ~-24 ~11 ~-48 minecraft:bricks
fill ~-28 ~1 ~-54 ~-25 ~10 ~-49 minecraft:air
fill ~-28 ~4 ~-54 ~-25 ~4 ~-49 minecraft:smooth_stone
fill ~-28 ~8 ~-54 ~-25 ~8 ~-49 minecraft:smooth_stone
fill ~-27 ~2 ~-55 ~-27 ~3 ~-55 minecraft:gray_stained_glass
fill ~-27 ~2 ~-48 ~-27 ~3 ~-48 minecraft:light_gray_stained_glass
fill ~-29 ~2 ~-53 ~-29 ~3 ~-53 minecraft:gray_stained_glass
fill ~-24 ~2 ~-53 ~-24 ~3 ~-53 minecraft:light_gray_stained_glass
fill ~-29 ~2 ~-50 ~-29 ~3 ~-50 minecraft:gray_stained_glass
fill ~-24 ~2 ~-50 ~-24 ~3 ~-50 minecraft:light_gray_stained_glass
fill ~-27 ~6 ~-55 ~-27 ~7 ~-55 minecraft:gray_stained_glass
fill ~-27 ~6 ~-48 ~-27 ~7 ~-48 minecraft:light_gray_stained_glass
fill ~-29 ~6 ~-53 ~-29 ~7 ~-53 minecraft:gray_stained_glass
fill ~-24 ~6 ~-53 ~-24 ~7 ~-53 minecraft:light_gray_stained_glass
fill ~-29 ~6 ~-50 ~-29 ~7 ~-50 minecraft:gray_stained_glass
fill ~-24 ~6 ~-50 ~-24 ~7 ~-50 minecraft:light_gray_stained_glass
setblock ~-27 ~1 ~-48 minecraft:iron_door[half=lower,facing=south]
setblock ~-27 ~2 ~-48 minecraft:iron_door[half=upper,facing=south]
fill ~-29 ~12 ~-55 ~-24 ~12 ~-48 minecraft:deepslate_tile_slab
fill ~-28 ~13 ~-54 ~-25 ~13 ~-49 minecraft:deepslate_tile_slab
setblock ~-27 ~3 ~-47 minecraft:dark_oak_slab[type=top]
fill ~-27 ~13 ~-53 ~-25 ~14 ~-51 minecraft:light_gray_concrete
setblock ~-25 ~13 ~-52 minecraft:lightning_rod
fill ~-28 ~1 ~-48 ~-28 ~7 ~-48 doomsday_decoration:redbrick
# 190 small_office style=bay_office context=arterial_front facing=south
fill ~60 ~-3 ~7 ~64 ~-1 ~13 minecraft:stone
fill ~60 ~0 ~7 ~64 ~5 ~13 minecraft:light_gray_concrete
fill ~61 ~1 ~8 ~63 ~4 ~12 minecraft:air
fill ~61 ~4 ~8 ~63 ~4 ~12 minecraft:smooth_stone
fill ~62 ~2 ~7 ~62 ~3 ~7 minecraft:gray_stained_glass
fill ~62 ~2 ~13 ~62 ~3 ~13 minecraft:light_gray_stained_glass
fill ~60 ~2 ~9 ~60 ~3 ~9 minecraft:gray_stained_glass
fill ~64 ~2 ~9 ~64 ~3 ~9 minecraft:light_gray_stained_glass
setblock ~62 ~1 ~13 minecraft:iron_door[half=lower,facing=south]
setblock ~62 ~2 ~13 minecraft:iron_door[half=upper,facing=south]
# 191 local_shop style=storefront context=local_front facing=east
fill ~-17 ~-3 ~32 ~-12 ~-1 ~35 minecraft:stone
fill ~-17 ~0 ~32 ~-12 ~11 ~35 minecraft:bricks
fill ~-16 ~1 ~33 ~-13 ~10 ~34 minecraft:air
fill ~-16 ~4 ~33 ~-13 ~4 ~34 minecraft:smooth_stone
fill ~-16 ~8 ~33 ~-13 ~8 ~34 minecraft:smooth_stone
fill ~-15 ~2 ~32 ~-15 ~3 ~32 minecraft:gray_stained_glass
fill ~-15 ~2 ~35 ~-15 ~3 ~35 minecraft:light_gray_stained_glass
fill ~-15 ~6 ~32 ~-15 ~7 ~32 minecraft:gray_stained_glass
fill ~-15 ~6 ~35 ~-15 ~7 ~35 minecraft:light_gray_stained_glass
setblock ~-12 ~1 ~34 minecraft:iron_door[half=lower,facing=east]
setblock ~-12 ~2 ~34 minecraft:iron_door[half=upper,facing=east]
fill ~-12 ~1 ~33 ~-12 ~3 ~34 minecraft:cyan_stained_glass
setblock ~-12 ~1 ~34 minecraft:iron_door[half=lower,facing=east]
setblock ~-12 ~2 ~34 minecraft:iron_door[half=upper,facing=east]
setblock ~-11 ~3 ~34 minecraft:red_wool
fill ~-17 ~12 ~32 ~-12 ~12 ~35 minecraft:deepslate_tile_slab
# 192 small_office style=civic_modern context=local_front facing=south
fill ~0 ~-3 ~16 ~4 ~-1 ~22 minecraft:stone
fill ~0 ~0 ~16 ~4 ~9 ~22 minecraft:white_terracotta
fill ~1 ~1 ~17 ~3 ~8 ~21 minecraft:air
fill ~1 ~4 ~17 ~3 ~4 ~21 minecraft:smooth_stone
fill ~1 ~8 ~17 ~3 ~8 ~21 minecraft:smooth_stone
fill ~2 ~2 ~16 ~2 ~3 ~16 minecraft:gray_stained_glass
fill ~2 ~2 ~22 ~2 ~3 ~22 minecraft:light_gray_stained_glass
fill ~0 ~2 ~18 ~0 ~3 ~18 minecraft:gray_stained_glass
fill ~4 ~2 ~18 ~4 ~3 ~18 minecraft:light_gray_stained_glass
fill ~2 ~6 ~16 ~2 ~7 ~16 minecraft:gray_stained_glass
fill ~2 ~6 ~22 ~2 ~7 ~22 minecraft:light_gray_stained_glass
fill ~0 ~6 ~18 ~0 ~7 ~18 minecraft:gray_stained_glass
fill ~4 ~6 ~18 ~4 ~7 ~18 minecraft:light_gray_stained_glass
setblock ~2 ~1 ~22 minecraft:iron_door[half=lower,facing=south]
setblock ~2 ~2 ~22 minecraft:iron_door[half=upper,facing=south]
fill ~2 ~11 ~18 ~3 ~12 ~20 minecraft:light_gray_concrete
setblock ~3 ~11 ~19 minecraft:lightning_rod
