# Buildings 9..16
# 009 workshop style=sawtooth context=local_front facing=east
fill ~-14 ~-3 ~75 ~0 ~-1 ~85 minecraft:stone
fill ~-14 ~0 ~75 ~0 ~8 ~85 minecraft:bricks
fill ~-13 ~1 ~76 ~-1 ~7 ~84 minecraft:air
fill ~-13 ~4 ~76 ~-1 ~4 ~84 minecraft:smooth_stone
fill ~-12 ~2 ~75 ~-12 ~3 ~75 minecraft:gray_stained_glass
fill ~-12 ~2 ~85 ~-12 ~3 ~85 minecraft:light_gray_stained_glass
fill ~-9 ~2 ~75 ~-9 ~3 ~75 minecraft:gray_stained_glass
fill ~-9 ~2 ~85 ~-9 ~3 ~85 minecraft:light_gray_stained_glass
fill ~-6 ~2 ~75 ~-6 ~3 ~75 minecraft:gray_stained_glass
fill ~-6 ~2 ~85 ~-6 ~3 ~85 minecraft:light_gray_stained_glass
fill ~-3 ~2 ~75 ~-3 ~3 ~75 minecraft:gray_stained_glass
fill ~-3 ~2 ~85 ~-3 ~3 ~85 minecraft:light_gray_stained_glass
fill ~-14 ~2 ~77 ~-14 ~3 ~77 minecraft:gray_stained_glass
fill ~0 ~2 ~77 ~0 ~3 ~77 minecraft:light_gray_stained_glass
fill ~-14 ~2 ~80 ~-14 ~3 ~80 minecraft:gray_stained_glass
fill ~0 ~2 ~80 ~0 ~3 ~80 minecraft:light_gray_stained_glass
fill ~-14 ~2 ~83 ~-14 ~3 ~83 minecraft:gray_stained_glass
fill ~0 ~2 ~83 ~0 ~3 ~83 minecraft:light_gray_stained_glass
fill ~-12 ~6 ~75 ~-12 ~7 ~75 minecraft:gray_stained_glass
fill ~-12 ~6 ~85 ~-12 ~7 ~85 minecraft:light_gray_stained_glass
fill ~-9 ~6 ~75 ~-9 ~7 ~75 minecraft:gray_stained_glass
fill ~-9 ~6 ~85 ~-9 ~7 ~85 minecraft:light_gray_stained_glass
fill ~-6 ~6 ~75 ~-6 ~7 ~75 minecraft:gray_stained_glass
fill ~-6 ~6 ~85 ~-6 ~7 ~85 minecraft:light_gray_stained_glass
fill ~-3 ~6 ~75 ~-3 ~7 ~75 minecraft:gray_stained_glass
fill ~-3 ~6 ~85 ~-3 ~7 ~85 minecraft:light_gray_stained_glass
fill ~-14 ~6 ~77 ~-14 ~7 ~77 minecraft:gray_stained_glass
fill ~0 ~6 ~77 ~0 ~7 ~77 minecraft:light_gray_stained_glass
fill ~-14 ~6 ~80 ~-14 ~7 ~80 minecraft:gray_stained_glass
fill ~0 ~6 ~80 ~0 ~7 ~80 minecraft:light_gray_stained_glass
fill ~-14 ~6 ~83 ~-14 ~7 ~83 minecraft:gray_stained_glass
fill ~0 ~6 ~83 ~0 ~7 ~83 minecraft:light_gray_stained_glass
setblock ~0 ~1 ~80 minecraft:iron_door[half=lower,facing=east]
setblock ~0 ~2 ~80 minecraft:iron_door[half=upper,facing=east]
fill ~0 ~1 ~77 ~0 ~4 ~83 minecraft:polished_blackstone
fill ~0 ~5 ~77 ~0 ~5 ~83 minecraft:light_blue_stained_glass
fill ~-12 ~10 ~77 ~-10 ~11 ~79 minecraft:iron_block
fill ~-14 ~9 ~75 ~0 ~9 ~85 minecraft:deepslate_tile_slab
fill ~-12 ~10 ~77 ~-10 ~11 ~79 minecraft:light_gray_concrete
setblock ~-9 ~10 ~78 minecraft:lightning_rod
fill ~0 ~1 ~76 ~0 ~7 ~76 doomsday_decoration:hollowbrick
fill ~0 ~1 ~80 ~0 ~7 ~80 doomsday_decoration:hollowbrick
fill ~0 ~1 ~84 ~0 ~7 ~84 doomsday_decoration:hollowbrick
# 010 shop_house style=arcade_shop context=collector_front facing=east
fill ~84 ~-3 ~53 ~92 ~-1 ~62 minecraft:stone
fill ~84 ~0 ~53 ~92 ~9 ~62 minecraft:white_concrete
fill ~85 ~1 ~54 ~91 ~8 ~61 minecraft:air
fill ~85 ~4 ~54 ~91 ~4 ~61 minecraft:smooth_stone
fill ~85 ~8 ~54 ~91 ~8 ~61 minecraft:smooth_stone
fill ~86 ~2 ~53 ~86 ~3 ~53 minecraft:gray_stained_glass
fill ~86 ~2 ~62 ~86 ~3 ~62 minecraft:light_gray_stained_glass
fill ~89 ~2 ~53 ~89 ~3 ~53 minecraft:gray_stained_glass
fill ~89 ~2 ~62 ~89 ~3 ~62 minecraft:light_gray_stained_glass
fill ~84 ~2 ~55 ~84 ~3 ~55 minecraft:gray_stained_glass
fill ~92 ~2 ~55 ~92 ~3 ~55 minecraft:light_gray_stained_glass
fill ~84 ~2 ~58 ~84 ~3 ~58 minecraft:gray_stained_glass
fill ~92 ~2 ~58 ~92 ~3 ~58 minecraft:light_gray_stained_glass
fill ~86 ~6 ~53 ~86 ~7 ~53 minecraft:gray_stained_glass
fill ~86 ~6 ~62 ~86 ~7 ~62 minecraft:light_gray_stained_glass
fill ~89 ~6 ~53 ~89 ~7 ~53 minecraft:gray_stained_glass
fill ~89 ~6 ~62 ~89 ~7 ~62 minecraft:light_gray_stained_glass
fill ~84 ~6 ~55 ~84 ~7 ~55 minecraft:gray_stained_glass
fill ~92 ~6 ~55 ~92 ~7 ~55 minecraft:light_gray_stained_glass
fill ~84 ~6 ~58 ~84 ~7 ~58 minecraft:gray_stained_glass
fill ~92 ~6 ~58 ~92 ~7 ~58 minecraft:light_gray_stained_glass
setblock ~92 ~1 ~57 minecraft:iron_door[half=lower,facing=east]
setblock ~92 ~2 ~57 minecraft:iron_door[half=upper,facing=east]
fill ~92 ~1 ~54 ~92 ~3 ~61 minecraft:cyan_stained_glass
setblock ~92 ~1 ~57 minecraft:iron_door[half=lower,facing=east]
setblock ~92 ~2 ~57 minecraft:iron_door[half=upper,facing=east]
setblock ~93 ~3 ~57 minecraft:red_wool
fill ~92 ~4 ~54 ~92 ~4 ~61 minecraft:cyan_terracotta
fill ~84 ~10 ~53 ~92 ~10 ~62 minecraft:smooth_stone_slab
fill ~92 ~1 ~54 ~92 ~7 ~54 minecraft:cyan_terracotta
fill ~92 ~1 ~58 ~92 ~7 ~58 minecraft:cyan_terracotta
fill ~85 ~6 ~54 ~91 ~9 ~61 minecraft:white_concrete
fill ~86 ~7 ~55 ~90 ~8 ~60 minecraft:air
setblock ~92 ~3 ~55 minecraft:red_carpet
setblock ~92 ~3 ~60 minecraft:red_carpet
# 011 supermarket style=arcade_shop context=collector_front facing=north
fill ~42 ~-3 ~-64 ~48 ~-1 ~-50 minecraft:stone
fill ~42 ~0 ~-64 ~48 ~10 ~-50 minecraft:bricks
fill ~43 ~1 ~-63 ~47 ~9 ~-51 minecraft:air
fill ~43 ~4 ~-63 ~47 ~4 ~-51 minecraft:smooth_stone
fill ~43 ~8 ~-63 ~47 ~8 ~-51 minecraft:smooth_stone
fill ~44 ~2 ~-64 ~44 ~3 ~-64 minecraft:gray_stained_glass
fill ~44 ~2 ~-50 ~44 ~3 ~-50 minecraft:light_gray_stained_glass
fill ~42 ~2 ~-62 ~42 ~3 ~-62 minecraft:gray_stained_glass
fill ~48 ~2 ~-62 ~48 ~3 ~-62 minecraft:light_gray_stained_glass
fill ~42 ~2 ~-59 ~42 ~3 ~-59 minecraft:gray_stained_glass
fill ~48 ~2 ~-59 ~48 ~3 ~-59 minecraft:light_gray_stained_glass
fill ~42 ~2 ~-56 ~42 ~3 ~-56 minecraft:gray_stained_glass
fill ~48 ~2 ~-56 ~48 ~3 ~-56 minecraft:light_gray_stained_glass
fill ~42 ~2 ~-53 ~42 ~3 ~-53 minecraft:gray_stained_glass
fill ~48 ~2 ~-53 ~48 ~3 ~-53 minecraft:light_gray_stained_glass
fill ~44 ~6 ~-64 ~44 ~7 ~-64 minecraft:gray_stained_glass
fill ~44 ~6 ~-50 ~44 ~7 ~-50 minecraft:light_gray_stained_glass
fill ~42 ~6 ~-62 ~42 ~7 ~-62 minecraft:gray_stained_glass
fill ~48 ~6 ~-62 ~48 ~7 ~-62 minecraft:light_gray_stained_glass
fill ~42 ~6 ~-59 ~42 ~7 ~-59 minecraft:gray_stained_glass
fill ~48 ~6 ~-59 ~48 ~7 ~-59 minecraft:light_gray_stained_glass
fill ~42 ~6 ~-56 ~42 ~7 ~-56 minecraft:gray_stained_glass
fill ~48 ~6 ~-56 ~48 ~7 ~-56 minecraft:light_gray_stained_glass
fill ~42 ~6 ~-53 ~42 ~7 ~-53 minecraft:gray_stained_glass
fill ~48 ~6 ~-53 ~48 ~7 ~-53 minecraft:light_gray_stained_glass
setblock ~45 ~1 ~-64 minecraft:iron_door[half=lower,facing=north]
setblock ~45 ~2 ~-64 minecraft:iron_door[half=upper,facing=north]
fill ~43 ~1 ~-64 ~47 ~3 ~-64 minecraft:cyan_stained_glass
setblock ~45 ~1 ~-64 minecraft:iron_door[half=lower,facing=north]
setblock ~45 ~2 ~-64 minecraft:iron_door[half=upper,facing=north]
setblock ~45 ~3 ~-65 minecraft:red_wool
fill ~43 ~4 ~-64 ~47 ~4 ~-64 doomsday_decoration:hollowbrick
fill ~42 ~11 ~-64 ~48 ~11 ~-50 minecraft:deepslate_tile_slab
fill ~43 ~1 ~-64 ~43 ~7 ~-64 doomsday_decoration:hollowbrick
fill ~47 ~1 ~-64 ~47 ~7 ~-64 doomsday_decoration:hollowbrick
# 012 local_shop style=arcade_shop context=local_front facing=north
fill ~-125 ~-3 ~-55 ~-117 ~-1 ~-45 minecraft:stone
fill ~-125 ~0 ~-55 ~-117 ~11 ~-45 minecraft:calcite
fill ~-124 ~1 ~-54 ~-118 ~10 ~-46 minecraft:air
fill ~-124 ~4 ~-54 ~-118 ~4 ~-46 minecraft:smooth_stone
fill ~-124 ~8 ~-54 ~-118 ~8 ~-46 minecraft:smooth_stone
fill ~-123 ~2 ~-55 ~-123 ~3 ~-55 minecraft:gray_stained_glass
fill ~-123 ~2 ~-45 ~-123 ~3 ~-45 minecraft:light_gray_stained_glass
fill ~-120 ~2 ~-55 ~-120 ~3 ~-55 minecraft:gray_stained_glass
fill ~-120 ~2 ~-45 ~-120 ~3 ~-45 minecraft:light_gray_stained_glass
fill ~-125 ~2 ~-53 ~-125 ~3 ~-53 minecraft:gray_stained_glass
fill ~-117 ~2 ~-53 ~-117 ~3 ~-53 minecraft:light_gray_stained_glass
fill ~-125 ~2 ~-50 ~-125 ~3 ~-50 minecraft:gray_stained_glass
fill ~-117 ~2 ~-50 ~-117 ~3 ~-50 minecraft:light_gray_stained_glass
fill ~-125 ~2 ~-47 ~-125 ~3 ~-47 minecraft:gray_stained_glass
fill ~-117 ~2 ~-47 ~-117 ~3 ~-47 minecraft:light_gray_stained_glass
fill ~-123 ~6 ~-55 ~-123 ~7 ~-55 minecraft:gray_stained_glass
fill ~-123 ~6 ~-45 ~-123 ~7 ~-45 minecraft:light_gray_stained_glass
fill ~-120 ~6 ~-55 ~-120 ~7 ~-55 minecraft:gray_stained_glass
fill ~-120 ~6 ~-45 ~-120 ~7 ~-45 minecraft:light_gray_stained_glass
fill ~-125 ~6 ~-53 ~-125 ~7 ~-53 minecraft:gray_stained_glass
fill ~-117 ~6 ~-53 ~-117 ~7 ~-53 minecraft:light_gray_stained_glass
fill ~-125 ~6 ~-50 ~-125 ~7 ~-50 minecraft:gray_stained_glass
fill ~-117 ~6 ~-50 ~-117 ~7 ~-50 minecraft:light_gray_stained_glass
fill ~-125 ~6 ~-47 ~-125 ~7 ~-47 minecraft:gray_stained_glass
fill ~-117 ~6 ~-47 ~-117 ~7 ~-47 minecraft:light_gray_stained_glass
setblock ~-121 ~1 ~-55 minecraft:iron_door[half=lower,facing=north]
setblock ~-121 ~2 ~-55 minecraft:iron_door[half=upper,facing=north]
fill ~-124 ~1 ~-55 ~-118 ~3 ~-55 minecraft:cyan_stained_glass
setblock ~-121 ~1 ~-55 minecraft:iron_door[half=lower,facing=north]
setblock ~-121 ~2 ~-55 minecraft:iron_door[half=upper,facing=north]
setblock ~-121 ~3 ~-56 minecraft:red_wool
fill ~-124 ~4 ~-55 ~-118 ~4 ~-55 minecraft:gray_concrete
fill ~-125 ~12 ~-55 ~-117 ~12 ~-45 minecraft:stone_brick_slab
fill ~-123 ~13 ~-53 ~-121 ~14 ~-51 minecraft:light_gray_concrete
setblock ~-120 ~13 ~-52 minecraft:lightning_rod
fill ~-124 ~1 ~-55 ~-124 ~7 ~-55 minecraft:gray_concrete
fill ~-120 ~1 ~-55 ~-120 ~7 ~-55 minecraft:gray_concrete
fill ~-124 ~6 ~-54 ~-118 ~11 ~-46 minecraft:calcite
fill ~-123 ~7 ~-53 ~-119 ~10 ~-47 minecraft:air
setblock ~-123 ~3 ~-55 minecraft:red_carpet
# 013 garage style=industrial_shed context=collector_front facing=south
fill ~30 ~-3 ~-123 ~45 ~-1 ~-106 minecraft:stone
fill ~30 ~0 ~-123 ~45 ~9 ~-106 minecraft:bricks
fill ~31 ~1 ~-122 ~44 ~8 ~-107 minecraft:air
fill ~31 ~4 ~-122 ~44 ~4 ~-107 minecraft:smooth_stone
fill ~31 ~8 ~-122 ~44 ~8 ~-107 minecraft:smooth_stone
fill ~32 ~2 ~-123 ~32 ~3 ~-123 minecraft:gray_stained_glass
fill ~32 ~2 ~-106 ~32 ~3 ~-106 minecraft:light_gray_stained_glass
fill ~35 ~2 ~-123 ~35 ~3 ~-123 minecraft:gray_stained_glass
fill ~35 ~2 ~-106 ~35 ~3 ~-106 minecraft:light_gray_stained_glass
fill ~38 ~2 ~-123 ~38 ~3 ~-123 minecraft:gray_stained_glass
fill ~38 ~2 ~-106 ~38 ~3 ~-106 minecraft:light_gray_stained_glass
fill ~41 ~2 ~-123 ~41 ~3 ~-123 minecraft:gray_stained_glass
fill ~41 ~2 ~-106 ~41 ~3 ~-106 minecraft:light_gray_stained_glass
fill ~30 ~2 ~-121 ~30 ~3 ~-121 minecraft:gray_stained_glass
fill ~45 ~2 ~-121 ~45 ~3 ~-121 minecraft:light_gray_stained_glass
fill ~30 ~2 ~-118 ~30 ~3 ~-118 minecraft:gray_stained_glass
fill ~45 ~2 ~-118 ~45 ~3 ~-118 minecraft:light_gray_stained_glass
fill ~30 ~2 ~-115 ~30 ~3 ~-115 minecraft:gray_stained_glass
fill ~45 ~2 ~-115 ~45 ~3 ~-115 minecraft:light_gray_stained_glass
fill ~30 ~2 ~-112 ~30 ~3 ~-112 minecraft:gray_stained_glass
fill ~45 ~2 ~-112 ~45 ~3 ~-112 minecraft:light_gray_stained_glass
fill ~30 ~2 ~-109 ~30 ~3 ~-109 minecraft:gray_stained_glass
fill ~45 ~2 ~-109 ~45 ~3 ~-109 minecraft:light_gray_stained_glass
fill ~32 ~6 ~-123 ~32 ~7 ~-123 minecraft:gray_stained_glass
fill ~32 ~6 ~-106 ~32 ~7 ~-106 minecraft:light_gray_stained_glass
fill ~35 ~6 ~-123 ~35 ~7 ~-123 minecraft:gray_stained_glass
fill ~35 ~6 ~-106 ~35 ~7 ~-106 minecraft:light_gray_stained_glass
fill ~38 ~6 ~-123 ~38 ~7 ~-123 minecraft:gray_stained_glass
fill ~38 ~6 ~-106 ~38 ~7 ~-106 minecraft:light_gray_stained_glass
fill ~41 ~6 ~-123 ~41 ~7 ~-123 minecraft:gray_stained_glass
fill ~41 ~6 ~-106 ~41 ~7 ~-106 minecraft:light_gray_stained_glass
fill ~30 ~6 ~-121 ~30 ~7 ~-121 minecraft:gray_stained_glass
fill ~45 ~6 ~-121 ~45 ~7 ~-121 minecraft:light_gray_stained_glass
fill ~30 ~6 ~-118 ~30 ~7 ~-118 minecraft:gray_stained_glass
fill ~45 ~6 ~-118 ~45 ~7 ~-118 minecraft:light_gray_stained_glass
fill ~30 ~6 ~-115 ~30 ~7 ~-115 minecraft:gray_stained_glass
fill ~45 ~6 ~-115 ~45 ~7 ~-115 minecraft:light_gray_stained_glass
fill ~30 ~6 ~-112 ~30 ~7 ~-112 minecraft:gray_stained_glass
fill ~45 ~6 ~-112 ~45 ~7 ~-112 minecraft:light_gray_stained_glass
fill ~30 ~6 ~-109 ~30 ~7 ~-109 minecraft:gray_stained_glass
fill ~45 ~6 ~-109 ~45 ~7 ~-109 minecraft:light_gray_stained_glass
setblock ~35 ~1 ~-106 minecraft:iron_door[half=lower,facing=south]
setblock ~35 ~2 ~-106 minecraft:iron_door[half=upper,facing=south]
fill ~32 ~1 ~-106 ~43 ~4 ~-106 minecraft:polished_blackstone
fill ~32 ~5 ~-106 ~43 ~5 ~-106 minecraft:light_blue_stained_glass
fill ~32 ~11 ~-121 ~34 ~12 ~-119 minecraft:iron_block
fill ~30 ~10 ~-123 ~45 ~10 ~-106 minecraft:deepslate_tile_slab
fill ~31 ~1 ~-106 ~31 ~7 ~-106 minecraft:gray_concrete
fill ~35 ~1 ~-106 ~35 ~7 ~-106 minecraft:gray_concrete
fill ~39 ~1 ~-106 ~39 ~7 ~-106 minecraft:gray_concrete
fill ~43 ~1 ~-106 ~43 ~7 ~-106 minecraft:gray_concrete
# 014 workshop style=sawtooth context=local_front facing=north
fill ~69 ~-3 ~-32 ~76 ~-1 ~-24 minecraft:stone
fill ~69 ~0 ~-32 ~76 ~12 ~-24 minecraft:bricks
fill ~70 ~1 ~-31 ~75 ~11 ~-25 minecraft:air
fill ~70 ~4 ~-31 ~75 ~4 ~-25 minecraft:smooth_stone
fill ~70 ~8 ~-31 ~75 ~8 ~-25 minecraft:smooth_stone
fill ~71 ~2 ~-32 ~71 ~3 ~-32 minecraft:gray_stained_glass
fill ~71 ~2 ~-24 ~71 ~3 ~-24 minecraft:light_gray_stained_glass
fill ~74 ~2 ~-32 ~74 ~3 ~-32 minecraft:gray_stained_glass
fill ~74 ~2 ~-24 ~74 ~3 ~-24 minecraft:light_gray_stained_glass
fill ~69 ~2 ~-30 ~69 ~3 ~-30 minecraft:gray_stained_glass
fill ~76 ~2 ~-30 ~76 ~3 ~-30 minecraft:light_gray_stained_glass
fill ~69 ~2 ~-27 ~69 ~3 ~-27 minecraft:gray_stained_glass
fill ~76 ~2 ~-27 ~76 ~3 ~-27 minecraft:light_gray_stained_glass
fill ~71 ~6 ~-32 ~71 ~7 ~-32 minecraft:gray_stained_glass
fill ~71 ~6 ~-24 ~71 ~7 ~-24 minecraft:light_gray_stained_glass
fill ~74 ~6 ~-32 ~74 ~7 ~-32 minecraft:gray_stained_glass
fill ~74 ~6 ~-24 ~74 ~7 ~-24 minecraft:light_gray_stained_glass
fill ~69 ~6 ~-30 ~69 ~7 ~-30 minecraft:gray_stained_glass
fill ~76 ~6 ~-30 ~76 ~7 ~-30 minecraft:light_gray_stained_glass
fill ~69 ~6 ~-27 ~69 ~7 ~-27 minecraft:gray_stained_glass
fill ~76 ~6 ~-27 ~76 ~7 ~-27 minecraft:light_gray_stained_glass
fill ~71 ~10 ~-32 ~71 ~11 ~-32 minecraft:gray_stained_glass
fill ~71 ~10 ~-24 ~71 ~11 ~-24 minecraft:light_gray_stained_glass
fill ~74 ~10 ~-32 ~74 ~11 ~-32 minecraft:gray_stained_glass
fill ~74 ~10 ~-24 ~74 ~11 ~-24 minecraft:light_gray_stained_glass
fill ~69 ~10 ~-30 ~69 ~11 ~-30 minecraft:gray_stained_glass
fill ~76 ~10 ~-30 ~76 ~11 ~-30 minecraft:light_gray_stained_glass
fill ~69 ~10 ~-27 ~69 ~11 ~-27 minecraft:gray_stained_glass
fill ~76 ~10 ~-27 ~76 ~11 ~-27 minecraft:light_gray_stained_glass
setblock ~72 ~1 ~-32 minecraft:iron_door[half=lower,facing=north]
setblock ~72 ~2 ~-32 minecraft:iron_door[half=upper,facing=north]
fill ~71 ~1 ~-32 ~74 ~4 ~-32 minecraft:polished_blackstone
fill ~71 ~5 ~-32 ~74 ~5 ~-32 minecraft:light_blue_stained_glass
fill ~71 ~14 ~-30 ~73 ~15 ~-28 minecraft:iron_block
fill ~69 ~13 ~-32 ~76 ~13 ~-24 minecraft:deepslate_tile_slab
fill ~70 ~1 ~-32 ~70 ~7 ~-32 doomsday_decoration:hollowbrick
fill ~74 ~1 ~-32 ~74 ~7 ~-32 doomsday_decoration:hollowbrick
# 015 hotel style=setback_tower context=arterial_front facing=south
fill ~8 ~-3 ~-24 ~16 ~-1 ~-10 minecraft:stone
fill ~8 ~0 ~-24 ~16 ~12 ~-10 minecraft:light_gray_concrete
fill ~9 ~1 ~-23 ~15 ~11 ~-11 minecraft:air
fill ~9 ~4 ~-23 ~15 ~4 ~-11 minecraft:smooth_stone
fill ~9 ~8 ~-23 ~15 ~8 ~-11 minecraft:smooth_stone
fill ~10 ~2 ~-24 ~10 ~3 ~-24 minecraft:gray_stained_glass
fill ~10 ~2 ~-10 ~10 ~3 ~-10 minecraft:light_gray_stained_glass
fill ~13 ~2 ~-24 ~13 ~3 ~-24 minecraft:gray_stained_glass
fill ~13 ~2 ~-10 ~13 ~3 ~-10 minecraft:light_gray_stained_glass
fill ~8 ~2 ~-22 ~8 ~3 ~-22 minecraft:gray_stained_glass
fill ~16 ~2 ~-22 ~16 ~3 ~-22 minecraft:light_gray_stained_glass
fill ~8 ~2 ~-19 ~8 ~3 ~-19 minecraft:gray_stained_glass
fill ~16 ~2 ~-19 ~16 ~3 ~-19 minecraft:light_gray_stained_glass
fill ~8 ~2 ~-16 ~8 ~3 ~-16 minecraft:gray_stained_glass
fill ~16 ~2 ~-16 ~16 ~3 ~-16 minecraft:light_gray_stained_glass
fill ~8 ~2 ~-13 ~8 ~3 ~-13 minecraft:gray_stained_glass
fill ~16 ~2 ~-13 ~16 ~3 ~-13 minecraft:light_gray_stained_glass
fill ~10 ~6 ~-24 ~10 ~7 ~-24 minecraft:gray_stained_glass
fill ~10 ~6 ~-10 ~10 ~7 ~-10 minecraft:light_gray_stained_glass
fill ~13 ~6 ~-24 ~13 ~7 ~-24 minecraft:gray_stained_glass
fill ~13 ~6 ~-10 ~13 ~7 ~-10 minecraft:light_gray_stained_glass
fill ~8 ~6 ~-22 ~8 ~7 ~-22 minecraft:gray_stained_glass
fill ~16 ~6 ~-22 ~16 ~7 ~-22 minecraft:light_gray_stained_glass
fill ~8 ~6 ~-19 ~8 ~7 ~-19 minecraft:gray_stained_glass
fill ~16 ~6 ~-19 ~16 ~7 ~-19 minecraft:light_gray_stained_glass
fill ~8 ~6 ~-16 ~8 ~7 ~-16 minecraft:gray_stained_glass
fill ~16 ~6 ~-16 ~16 ~7 ~-16 minecraft:light_gray_stained_glass
fill ~8 ~6 ~-13 ~8 ~7 ~-13 minecraft:gray_stained_glass
fill ~16 ~6 ~-13 ~16 ~7 ~-13 minecraft:light_gray_stained_glass
fill ~10 ~10 ~-24 ~10 ~11 ~-24 minecraft:gray_stained_glass
fill ~10 ~10 ~-10 ~10 ~11 ~-10 minecraft:light_gray_stained_glass
fill ~13 ~10 ~-24 ~13 ~11 ~-24 minecraft:gray_stained_glass
fill ~13 ~10 ~-10 ~13 ~11 ~-10 minecraft:light_gray_stained_glass
fill ~8 ~10 ~-22 ~8 ~11 ~-22 minecraft:gray_stained_glass
fill ~16 ~10 ~-22 ~16 ~11 ~-22 minecraft:light_gray_stained_glass
fill ~8 ~10 ~-19 ~8 ~11 ~-19 minecraft:gray_stained_glass
fill ~16 ~10 ~-19 ~16 ~11 ~-19 minecraft:light_gray_stained_glass
fill ~8 ~10 ~-16 ~8 ~11 ~-16 minecraft:gray_stained_glass
fill ~16 ~10 ~-16 ~16 ~11 ~-16 minecraft:light_gray_stained_glass
fill ~8 ~10 ~-13 ~8 ~11 ~-13 minecraft:gray_stained_glass
fill ~16 ~10 ~-13 ~16 ~11 ~-13 minecraft:light_gray_stained_glass
setblock ~12 ~1 ~-10 minecraft:iron_door[half=lower,facing=south]
setblock ~12 ~2 ~-10 minecraft:iron_door[half=upper,facing=south]
fill ~8 ~7 ~-24 ~16 ~12 ~-10 minecraft:air
fill ~9 ~7 ~-23 ~15 ~12 ~-11 minecraft:light_gray_concrete
fill ~10 ~8 ~-22 ~14 ~11 ~-12 minecraft:air
fill ~9 ~13 ~-23 ~15 ~13 ~-11 minecraft:smooth_stone_slab
fill ~10 ~14 ~-22 ~12 ~15 ~-20 minecraft:light_gray_concrete
setblock ~13 ~14 ~-21 minecraft:lightning_rod
fill ~9 ~1 ~-10 ~9 ~7 ~-10 doomsday_decoration:cementwall
fill ~13 ~1 ~-10 ~13 ~7 ~-10 doomsday_decoration:cementwall
fill ~10 ~14 ~-22 ~13 ~16 ~-19 minecraft:light_gray_concrete
setblock ~14 ~14 ~-12 minecraft:lightning_rod
# 016 supermarket style=arcade_shop context=collector_front facing=east
fill ~80 ~-3 ~24 ~92 ~-1 ~28 minecraft:stone
fill ~80 ~0 ~24 ~92 ~7 ~28 minecraft:white_concrete
fill ~81 ~1 ~25 ~91 ~6 ~27 minecraft:air
fill ~81 ~4 ~25 ~91 ~4 ~27 minecraft:smooth_stone
fill ~82 ~2 ~24 ~82 ~3 ~24 minecraft:gray_stained_glass
fill ~82 ~2 ~28 ~82 ~3 ~28 minecraft:light_gray_stained_glass
fill ~85 ~2 ~24 ~85 ~3 ~24 minecraft:gray_stained_glass
fill ~85 ~2 ~28 ~85 ~3 ~28 minecraft:light_gray_stained_glass
fill ~88 ~2 ~24 ~88 ~3 ~24 minecraft:gray_stained_glass
fill ~88 ~2 ~28 ~88 ~3 ~28 minecraft:light_gray_stained_glass
fill ~80 ~2 ~26 ~80 ~3 ~26 minecraft:gray_stained_glass
fill ~92 ~2 ~26 ~92 ~3 ~26 minecraft:light_gray_stained_glass
setblock ~92 ~1 ~26 minecraft:iron_door[half=lower,facing=east]
setblock ~92 ~2 ~26 minecraft:iron_door[half=upper,facing=east]
fill ~92 ~1 ~25 ~92 ~3 ~27 minecraft:cyan_stained_glass
setblock ~92 ~1 ~26 minecraft:iron_door[half=lower,facing=east]
setblock ~92 ~2 ~26 minecraft:iron_door[half=upper,facing=east]
setblock ~93 ~3 ~26 minecraft:red_wool
fill ~92 ~4 ~25 ~92 ~4 ~27 minecraft:cyan_terracotta
fill ~80 ~8 ~24 ~92 ~8 ~28 minecraft:smooth_stone_slab
