# Buildings 33..40
# 033 clinic style=setback_block context=collector_front facing=north
fill ~-109 ~-3 ~-67 ~-101 ~-1 ~-57 minecraft:stone
fill ~-109 ~0 ~-67 ~-101 ~9 ~-57 minecraft:calcite
fill ~-108 ~1 ~-66 ~-102 ~8 ~-58 minecraft:air
fill ~-108 ~4 ~-66 ~-102 ~4 ~-58 minecraft:smooth_stone
fill ~-108 ~8 ~-66 ~-102 ~8 ~-58 minecraft:smooth_stone
fill ~-107 ~2 ~-67 ~-107 ~3 ~-67 minecraft:gray_stained_glass
fill ~-107 ~2 ~-57 ~-107 ~3 ~-57 minecraft:light_gray_stained_glass
fill ~-104 ~2 ~-67 ~-104 ~3 ~-67 minecraft:gray_stained_glass
fill ~-104 ~2 ~-57 ~-104 ~3 ~-57 minecraft:light_gray_stained_glass
fill ~-109 ~2 ~-65 ~-109 ~3 ~-65 minecraft:gray_stained_glass
fill ~-101 ~2 ~-65 ~-101 ~3 ~-65 minecraft:light_gray_stained_glass
fill ~-109 ~2 ~-62 ~-109 ~3 ~-62 minecraft:gray_stained_glass
fill ~-101 ~2 ~-62 ~-101 ~3 ~-62 minecraft:light_gray_stained_glass
fill ~-109 ~2 ~-59 ~-109 ~3 ~-59 minecraft:gray_stained_glass
fill ~-101 ~2 ~-59 ~-101 ~3 ~-59 minecraft:light_gray_stained_glass
fill ~-107 ~6 ~-67 ~-107 ~7 ~-67 minecraft:gray_stained_glass
fill ~-107 ~6 ~-57 ~-107 ~7 ~-57 minecraft:light_gray_stained_glass
fill ~-104 ~6 ~-67 ~-104 ~7 ~-67 minecraft:gray_stained_glass
fill ~-104 ~6 ~-57 ~-104 ~7 ~-57 minecraft:light_gray_stained_glass
fill ~-109 ~6 ~-65 ~-109 ~7 ~-65 minecraft:gray_stained_glass
fill ~-101 ~6 ~-65 ~-101 ~7 ~-65 minecraft:light_gray_stained_glass
fill ~-109 ~6 ~-62 ~-109 ~7 ~-62 minecraft:gray_stained_glass
fill ~-101 ~6 ~-62 ~-101 ~7 ~-62 minecraft:light_gray_stained_glass
fill ~-109 ~6 ~-59 ~-109 ~7 ~-59 minecraft:gray_stained_glass
fill ~-101 ~6 ~-59 ~-101 ~7 ~-59 minecraft:light_gray_stained_glass
setblock ~-105 ~1 ~-67 minecraft:iron_door[half=lower,facing=north]
setblock ~-105 ~2 ~-67 minecraft:iron_door[half=upper,facing=north]
fill ~-107 ~11 ~-65 ~-105 ~12 ~-63 minecraft:light_gray_concrete
setblock ~-104 ~11 ~-64 minecraft:lightning_rod
# 034 midrise_housing style=setback_block context=arterial_front facing=south
fill ~-83 ~-3 ~-54 ~-71 ~-1 ~-42 minecraft:stone
fill ~-83 ~0 ~-54 ~-71 ~10 ~-42 minecraft:light_gray_concrete
fill ~-82 ~1 ~-53 ~-72 ~9 ~-43 minecraft:air
fill ~-82 ~4 ~-53 ~-72 ~4 ~-43 minecraft:smooth_stone
fill ~-82 ~8 ~-53 ~-72 ~8 ~-43 minecraft:smooth_stone
fill ~-81 ~2 ~-54 ~-81 ~3 ~-54 minecraft:gray_stained_glass
fill ~-81 ~2 ~-42 ~-81 ~3 ~-42 minecraft:light_gray_stained_glass
fill ~-78 ~2 ~-54 ~-78 ~3 ~-54 minecraft:gray_stained_glass
fill ~-78 ~2 ~-42 ~-78 ~3 ~-42 minecraft:light_gray_stained_glass
fill ~-75 ~2 ~-54 ~-75 ~3 ~-54 minecraft:gray_stained_glass
fill ~-75 ~2 ~-42 ~-75 ~3 ~-42 minecraft:light_gray_stained_glass
fill ~-83 ~2 ~-52 ~-83 ~3 ~-52 minecraft:gray_stained_glass
fill ~-71 ~2 ~-52 ~-71 ~3 ~-52 minecraft:light_gray_stained_glass
fill ~-83 ~2 ~-49 ~-83 ~3 ~-49 minecraft:gray_stained_glass
fill ~-71 ~2 ~-49 ~-71 ~3 ~-49 minecraft:light_gray_stained_glass
fill ~-83 ~2 ~-46 ~-83 ~3 ~-46 minecraft:gray_stained_glass
fill ~-71 ~2 ~-46 ~-71 ~3 ~-46 minecraft:light_gray_stained_glass
fill ~-81 ~6 ~-54 ~-81 ~7 ~-54 minecraft:gray_stained_glass
fill ~-81 ~6 ~-42 ~-81 ~7 ~-42 minecraft:light_gray_stained_glass
fill ~-78 ~6 ~-54 ~-78 ~7 ~-54 minecraft:gray_stained_glass
fill ~-78 ~6 ~-42 ~-78 ~7 ~-42 minecraft:light_gray_stained_glass
fill ~-75 ~6 ~-54 ~-75 ~7 ~-54 minecraft:gray_stained_glass
fill ~-75 ~6 ~-42 ~-75 ~7 ~-42 minecraft:light_gray_stained_glass
fill ~-83 ~6 ~-52 ~-83 ~7 ~-52 minecraft:gray_stained_glass
fill ~-71 ~6 ~-52 ~-71 ~7 ~-52 minecraft:light_gray_stained_glass
fill ~-83 ~6 ~-49 ~-83 ~7 ~-49 minecraft:gray_stained_glass
fill ~-71 ~6 ~-49 ~-71 ~7 ~-49 minecraft:light_gray_stained_glass
fill ~-83 ~6 ~-46 ~-83 ~7 ~-46 minecraft:gray_stained_glass
fill ~-71 ~6 ~-46 ~-71 ~7 ~-46 minecraft:light_gray_stained_glass
setblock ~-78 ~1 ~-42 minecraft:iron_door[half=lower,facing=south]
setblock ~-78 ~2 ~-42 minecraft:iron_door[half=upper,facing=south]
fill ~-83 ~7 ~-54 ~-71 ~10 ~-42 minecraft:air
fill ~-82 ~7 ~-53 ~-72 ~10 ~-43 minecraft:light_gray_concrete
fill ~-81 ~8 ~-52 ~-73 ~9 ~-44 minecraft:air
fill ~-82 ~11 ~-53 ~-72 ~11 ~-43 minecraft:smooth_stone_slab
# 035 garage style=industrial_shed context=local_front facing=west
fill ~74 ~-3 ~86 ~88 ~-1 ~105 minecraft:stone
fill ~74 ~0 ~86 ~88 ~10 ~105 minecraft:stone_bricks
fill ~75 ~1 ~87 ~87 ~9 ~104 minecraft:air
fill ~75 ~4 ~87 ~87 ~4 ~104 minecraft:smooth_stone
fill ~75 ~8 ~87 ~87 ~8 ~104 minecraft:smooth_stone
fill ~76 ~2 ~86 ~76 ~3 ~86 minecraft:gray_stained_glass
fill ~76 ~2 ~105 ~76 ~3 ~105 minecraft:light_gray_stained_glass
fill ~79 ~2 ~86 ~79 ~3 ~86 minecraft:gray_stained_glass
fill ~79 ~2 ~105 ~79 ~3 ~105 minecraft:light_gray_stained_glass
fill ~82 ~2 ~86 ~82 ~3 ~86 minecraft:gray_stained_glass
fill ~82 ~2 ~105 ~82 ~3 ~105 minecraft:light_gray_stained_glass
fill ~85 ~2 ~86 ~85 ~3 ~86 minecraft:gray_stained_glass
fill ~85 ~2 ~105 ~85 ~3 ~105 minecraft:light_gray_stained_glass
fill ~74 ~2 ~88 ~74 ~3 ~88 minecraft:gray_stained_glass
fill ~88 ~2 ~88 ~88 ~3 ~88 minecraft:light_gray_stained_glass
fill ~74 ~2 ~91 ~74 ~3 ~91 minecraft:gray_stained_glass
fill ~88 ~2 ~91 ~88 ~3 ~91 minecraft:light_gray_stained_glass
fill ~74 ~2 ~94 ~74 ~3 ~94 minecraft:gray_stained_glass
fill ~88 ~2 ~94 ~88 ~3 ~94 minecraft:light_gray_stained_glass
fill ~74 ~2 ~97 ~74 ~3 ~97 minecraft:gray_stained_glass
fill ~88 ~2 ~97 ~88 ~3 ~97 minecraft:light_gray_stained_glass
fill ~74 ~2 ~100 ~74 ~3 ~100 minecraft:gray_stained_glass
fill ~88 ~2 ~100 ~88 ~3 ~100 minecraft:light_gray_stained_glass
fill ~74 ~2 ~103 ~74 ~3 ~103 minecraft:gray_stained_glass
fill ~88 ~2 ~103 ~88 ~3 ~103 minecraft:light_gray_stained_glass
fill ~76 ~6 ~86 ~76 ~7 ~86 minecraft:gray_stained_glass
fill ~76 ~6 ~105 ~76 ~7 ~105 minecraft:light_gray_stained_glass
fill ~79 ~6 ~86 ~79 ~7 ~86 minecraft:gray_stained_glass
fill ~79 ~6 ~105 ~79 ~7 ~105 minecraft:light_gray_stained_glass
fill ~82 ~6 ~86 ~82 ~7 ~86 minecraft:gray_stained_glass
fill ~82 ~6 ~105 ~82 ~7 ~105 minecraft:light_gray_stained_glass
fill ~85 ~6 ~86 ~85 ~7 ~86 minecraft:gray_stained_glass
fill ~85 ~6 ~105 ~85 ~7 ~105 minecraft:light_gray_stained_glass
fill ~74 ~6 ~88 ~74 ~7 ~88 minecraft:gray_stained_glass
fill ~88 ~6 ~88 ~88 ~7 ~88 minecraft:light_gray_stained_glass
fill ~74 ~6 ~91 ~74 ~7 ~91 minecraft:gray_stained_glass
fill ~88 ~6 ~91 ~88 ~7 ~91 minecraft:light_gray_stained_glass
fill ~74 ~6 ~94 ~74 ~7 ~94 minecraft:gray_stained_glass
fill ~88 ~6 ~94 ~88 ~7 ~94 minecraft:light_gray_stained_glass
fill ~74 ~6 ~97 ~74 ~7 ~97 minecraft:gray_stained_glass
fill ~88 ~6 ~97 ~88 ~7 ~97 minecraft:light_gray_stained_glass
fill ~74 ~6 ~100 ~74 ~7 ~100 minecraft:gray_stained_glass
fill ~88 ~6 ~100 ~88 ~7 ~100 minecraft:light_gray_stained_glass
fill ~74 ~6 ~103 ~74 ~7 ~103 minecraft:gray_stained_glass
fill ~88 ~6 ~103 ~88 ~7 ~103 minecraft:light_gray_stained_glass
setblock ~74 ~1 ~91 minecraft:iron_door[half=lower,facing=west]
setblock ~74 ~2 ~91 minecraft:iron_door[half=upper,facing=west]
fill ~74 ~1 ~88 ~74 ~4 ~103 minecraft:polished_blackstone
fill ~74 ~5 ~88 ~74 ~5 ~103 minecraft:light_blue_stained_glass
fill ~76 ~12 ~88 ~78 ~13 ~90 minecraft:iron_block
fill ~74 ~11 ~86 ~88 ~11 ~105 minecraft:stone_brick_slab
fill ~86 ~8 ~103 ~88 ~12 ~105 minecraft:air
setblock ~86 ~8 ~103 minecraft:cobweb
# 036 lowrise_housing style=japanese_house context=back_block facing=west
fill ~68 ~-3 ~-54 ~76 ~-1 ~-45 minecraft:stone
fill ~68 ~0 ~-54 ~76 ~10 ~-45 minecraft:bricks
fill ~69 ~1 ~-53 ~75 ~9 ~-46 minecraft:air
fill ~69 ~4 ~-53 ~75 ~4 ~-46 minecraft:smooth_stone
fill ~69 ~8 ~-53 ~75 ~8 ~-46 minecraft:smooth_stone
fill ~70 ~2 ~-54 ~70 ~3 ~-54 minecraft:gray_stained_glass
fill ~70 ~2 ~-45 ~70 ~3 ~-45 minecraft:light_gray_stained_glass
fill ~73 ~2 ~-54 ~73 ~3 ~-54 minecraft:gray_stained_glass
fill ~73 ~2 ~-45 ~73 ~3 ~-45 minecraft:light_gray_stained_glass
fill ~68 ~2 ~-52 ~68 ~3 ~-52 minecraft:gray_stained_glass
fill ~76 ~2 ~-52 ~76 ~3 ~-52 minecraft:light_gray_stained_glass
fill ~68 ~2 ~-49 ~68 ~3 ~-49 minecraft:gray_stained_glass
fill ~76 ~2 ~-49 ~76 ~3 ~-49 minecraft:light_gray_stained_glass
fill ~70 ~6 ~-54 ~70 ~7 ~-54 minecraft:gray_stained_glass
fill ~70 ~6 ~-45 ~70 ~7 ~-45 minecraft:light_gray_stained_glass
fill ~73 ~6 ~-54 ~73 ~7 ~-54 minecraft:gray_stained_glass
fill ~73 ~6 ~-45 ~73 ~7 ~-45 minecraft:light_gray_stained_glass
fill ~68 ~6 ~-52 ~68 ~7 ~-52 minecraft:gray_stained_glass
fill ~76 ~6 ~-52 ~76 ~7 ~-52 minecraft:light_gray_stained_glass
fill ~68 ~6 ~-49 ~68 ~7 ~-49 minecraft:gray_stained_glass
fill ~76 ~6 ~-49 ~76 ~7 ~-49 minecraft:light_gray_stained_glass
setblock ~68 ~1 ~-50 minecraft:iron_door[half=lower,facing=west]
setblock ~68 ~2 ~-50 minecraft:iron_door[half=upper,facing=west]
fill ~68 ~11 ~-54 ~76 ~11 ~-45 minecraft:deepslate_tile_slab
fill ~69 ~12 ~-53 ~75 ~12 ~-46 minecraft:deepslate_tile_slab
setblock ~67 ~3 ~-50 minecraft:dark_oak_slab[type=top]
fill ~70 ~12 ~-52 ~72 ~13 ~-50 minecraft:light_gray_concrete
setblock ~73 ~12 ~-51 minecraft:lightning_rod
# 037 midrise_housing style=balcony_block context=collector_front facing=north
fill ~-24 ~-3 ~97 ~-14 ~-1 ~110 minecraft:stone
fill ~-24 ~0 ~97 ~-14 ~5 ~110 minecraft:white_terracotta
fill ~-23 ~1 ~98 ~-15 ~4 ~109 minecraft:air
fill ~-23 ~4 ~98 ~-15 ~4 ~109 minecraft:smooth_stone
fill ~-22 ~2 ~97 ~-22 ~3 ~97 minecraft:gray_stained_glass
fill ~-22 ~2 ~110 ~-22 ~3 ~110 minecraft:light_gray_stained_glass
fill ~-19 ~2 ~97 ~-19 ~3 ~97 minecraft:gray_stained_glass
fill ~-19 ~2 ~110 ~-19 ~3 ~110 minecraft:light_gray_stained_glass
fill ~-16 ~2 ~97 ~-16 ~3 ~97 minecraft:gray_stained_glass
fill ~-16 ~2 ~110 ~-16 ~3 ~110 minecraft:light_gray_stained_glass
fill ~-24 ~2 ~99 ~-24 ~3 ~99 minecraft:gray_stained_glass
fill ~-14 ~2 ~99 ~-14 ~3 ~99 minecraft:light_gray_stained_glass
fill ~-24 ~2 ~102 ~-24 ~3 ~102 minecraft:gray_stained_glass
fill ~-14 ~2 ~102 ~-14 ~3 ~102 minecraft:light_gray_stained_glass
fill ~-24 ~2 ~105 ~-24 ~3 ~105 minecraft:gray_stained_glass
fill ~-14 ~2 ~105 ~-14 ~3 ~105 minecraft:light_gray_stained_glass
fill ~-24 ~2 ~108 ~-24 ~3 ~108 minecraft:gray_stained_glass
fill ~-14 ~2 ~108 ~-14 ~3 ~108 minecraft:light_gray_stained_glass
setblock ~-19 ~1 ~97 minecraft:iron_door[half=lower,facing=north]
setblock ~-19 ~2 ~97 minecraft:iron_door[half=upper,facing=north]
fill ~-22 ~4 ~96 ~-16 ~4 ~96 minecraft:smooth_stone_slab
fill ~-24 ~6 ~97 ~-14 ~6 ~110 minecraft:dark_oak_slab
# 038 fish_market style=setback_block context=waterfront_front facing=south
fill ~95 ~-3 ~-14 ~101 ~-1 ~-3 minecraft:stone
fill ~95 ~0 ~-14 ~101 ~5 ~-3 minecraft:bricks
fill ~96 ~1 ~-13 ~100 ~4 ~-4 minecraft:air
fill ~96 ~4 ~-13 ~100 ~4 ~-4 minecraft:smooth_stone
fill ~97 ~2 ~-14 ~97 ~3 ~-14 minecraft:gray_stained_glass
fill ~97 ~2 ~-3 ~97 ~3 ~-3 minecraft:light_gray_stained_glass
fill ~95 ~2 ~-12 ~95 ~3 ~-12 minecraft:gray_stained_glass
fill ~101 ~2 ~-12 ~101 ~3 ~-12 minecraft:light_gray_stained_glass
fill ~95 ~2 ~-9 ~95 ~3 ~-9 minecraft:gray_stained_glass
fill ~101 ~2 ~-9 ~101 ~3 ~-9 minecraft:light_gray_stained_glass
fill ~95 ~2 ~-6 ~95 ~3 ~-6 minecraft:gray_stained_glass
fill ~101 ~2 ~-6 ~101 ~3 ~-6 minecraft:light_gray_stained_glass
setblock ~98 ~1 ~-3 minecraft:iron_door[half=lower,facing=south]
setblock ~98 ~2 ~-3 minecraft:iron_door[half=upper,facing=south]
# 039 utility style=loading_bay context=collector_front facing=south
fill ~53 ~-3 ~54 ~66 ~-1 ~66 minecraft:stone
fill ~53 ~0 ~54 ~66 ~6 ~66 minecraft:deepslate_bricks
fill ~54 ~1 ~55 ~65 ~5 ~65 minecraft:air
fill ~54 ~4 ~55 ~65 ~4 ~65 minecraft:smooth_stone
fill ~55 ~2 ~54 ~55 ~3 ~54 minecraft:gray_stained_glass
fill ~55 ~2 ~66 ~55 ~3 ~66 minecraft:light_gray_stained_glass
fill ~58 ~2 ~54 ~58 ~3 ~54 minecraft:gray_stained_glass
fill ~58 ~2 ~66 ~58 ~3 ~66 minecraft:light_gray_stained_glass
fill ~61 ~2 ~54 ~61 ~3 ~54 minecraft:gray_stained_glass
fill ~61 ~2 ~66 ~61 ~3 ~66 minecraft:light_gray_stained_glass
fill ~64 ~2 ~54 ~64 ~3 ~54 minecraft:gray_stained_glass
fill ~64 ~2 ~66 ~64 ~3 ~66 minecraft:light_gray_stained_glass
fill ~53 ~2 ~56 ~53 ~3 ~56 minecraft:gray_stained_glass
fill ~66 ~2 ~56 ~66 ~3 ~56 minecraft:light_gray_stained_glass
fill ~53 ~2 ~59 ~53 ~3 ~59 minecraft:gray_stained_glass
fill ~66 ~2 ~59 ~66 ~3 ~59 minecraft:light_gray_stained_glass
fill ~53 ~2 ~62 ~53 ~3 ~62 minecraft:gray_stained_glass
fill ~66 ~2 ~62 ~66 ~3 ~62 minecraft:light_gray_stained_glass
setblock ~58 ~1 ~66 minecraft:iron_door[half=lower,facing=south]
setblock ~58 ~2 ~66 minecraft:iron_door[half=upper,facing=south]
fill ~55 ~1 ~66 ~64 ~4 ~66 minecraft:polished_blackstone
fill ~55 ~5 ~66 ~64 ~5 ~66 minecraft:light_blue_stained_glass
fill ~55 ~8 ~56 ~57 ~9 ~58 minecraft:iron_block
fill ~53 ~7 ~54 ~66 ~7 ~66 minecraft:deepslate_tile_slab
# 040 mixed_use style=setback_block context=arterial_front facing=east
fill ~-52 ~-3 ~-88 ~-36 ~-1 ~-71 minecraft:stone
fill ~-52 ~0 ~-88 ~-36 ~12 ~-71 minecraft:bricks
fill ~-51 ~1 ~-87 ~-37 ~11 ~-72 minecraft:air
fill ~-51 ~4 ~-87 ~-37 ~4 ~-72 minecraft:smooth_stone
fill ~-51 ~8 ~-87 ~-37 ~8 ~-72 minecraft:smooth_stone
fill ~-50 ~2 ~-88 ~-50 ~3 ~-88 minecraft:gray_stained_glass
fill ~-50 ~2 ~-71 ~-50 ~3 ~-71 minecraft:light_gray_stained_glass
fill ~-47 ~2 ~-88 ~-47 ~3 ~-88 minecraft:gray_stained_glass
fill ~-47 ~2 ~-71 ~-47 ~3 ~-71 minecraft:light_gray_stained_glass
fill ~-44 ~2 ~-88 ~-44 ~3 ~-88 minecraft:gray_stained_glass
fill ~-44 ~2 ~-71 ~-44 ~3 ~-71 minecraft:light_gray_stained_glass
fill ~-41 ~2 ~-88 ~-41 ~3 ~-88 minecraft:gray_stained_glass
fill ~-41 ~2 ~-71 ~-41 ~3 ~-71 minecraft:light_gray_stained_glass
fill ~-38 ~2 ~-88 ~-38 ~3 ~-88 minecraft:gray_stained_glass
fill ~-38 ~2 ~-71 ~-38 ~3 ~-71 minecraft:light_gray_stained_glass
fill ~-52 ~2 ~-86 ~-52 ~3 ~-86 minecraft:gray_stained_glass
fill ~-36 ~2 ~-86 ~-36 ~3 ~-86 minecraft:light_gray_stained_glass
fill ~-52 ~2 ~-83 ~-52 ~3 ~-83 minecraft:gray_stained_glass
fill ~-36 ~2 ~-83 ~-36 ~3 ~-83 minecraft:light_gray_stained_glass
fill ~-52 ~2 ~-80 ~-52 ~3 ~-80 minecraft:gray_stained_glass
fill ~-36 ~2 ~-80 ~-36 ~3 ~-80 minecraft:light_gray_stained_glass
fill ~-52 ~2 ~-77 ~-52 ~3 ~-77 minecraft:gray_stained_glass
fill ~-36 ~2 ~-77 ~-36 ~3 ~-77 minecraft:light_gray_stained_glass
fill ~-52 ~2 ~-74 ~-52 ~3 ~-74 minecraft:gray_stained_glass
fill ~-36 ~2 ~-74 ~-36 ~3 ~-74 minecraft:light_gray_stained_glass
fill ~-50 ~6 ~-88 ~-50 ~7 ~-88 minecraft:gray_stained_glass
fill ~-50 ~6 ~-71 ~-50 ~7 ~-71 minecraft:light_gray_stained_glass
fill ~-47 ~6 ~-88 ~-47 ~7 ~-88 minecraft:gray_stained_glass
fill ~-47 ~6 ~-71 ~-47 ~7 ~-71 minecraft:light_gray_stained_glass
fill ~-44 ~6 ~-88 ~-44 ~7 ~-88 minecraft:gray_stained_glass
fill ~-44 ~6 ~-71 ~-44 ~7 ~-71 minecraft:light_gray_stained_glass
fill ~-41 ~6 ~-88 ~-41 ~7 ~-88 minecraft:gray_stained_glass
fill ~-41 ~6 ~-71 ~-41 ~7 ~-71 minecraft:light_gray_stained_glass
fill ~-38 ~6 ~-88 ~-38 ~7 ~-88 minecraft:gray_stained_glass
fill ~-38 ~6 ~-71 ~-38 ~7 ~-71 minecraft:light_gray_stained_glass
fill ~-52 ~6 ~-86 ~-52 ~7 ~-86 minecraft:gray_stained_glass
fill ~-36 ~6 ~-86 ~-36 ~7 ~-86 minecraft:light_gray_stained_glass
fill ~-52 ~6 ~-83 ~-52 ~7 ~-83 minecraft:gray_stained_glass
fill ~-36 ~6 ~-83 ~-36 ~7 ~-83 minecraft:light_gray_stained_glass
fill ~-52 ~6 ~-80 ~-52 ~7 ~-80 minecraft:gray_stained_glass
fill ~-36 ~6 ~-80 ~-36 ~7 ~-80 minecraft:light_gray_stained_glass
fill ~-52 ~6 ~-77 ~-52 ~7 ~-77 minecraft:gray_stained_glass
fill ~-36 ~6 ~-77 ~-36 ~7 ~-77 minecraft:light_gray_stained_glass
fill ~-52 ~6 ~-74 ~-52 ~7 ~-74 minecraft:gray_stained_glass
fill ~-36 ~6 ~-74 ~-36 ~7 ~-74 minecraft:light_gray_stained_glass
fill ~-50 ~10 ~-88 ~-50 ~11 ~-88 minecraft:gray_stained_glass
fill ~-50 ~10 ~-71 ~-50 ~11 ~-71 minecraft:light_gray_stained_glass
fill ~-47 ~10 ~-88 ~-47 ~11 ~-88 minecraft:gray_stained_glass
fill ~-47 ~10 ~-71 ~-47 ~11 ~-71 minecraft:light_gray_stained_glass
fill ~-44 ~10 ~-88 ~-44 ~11 ~-88 minecraft:gray_stained_glass
fill ~-44 ~10 ~-71 ~-44 ~11 ~-71 minecraft:light_gray_stained_glass
fill ~-41 ~10 ~-88 ~-41 ~11 ~-88 minecraft:gray_stained_glass
fill ~-41 ~10 ~-71 ~-41 ~11 ~-71 minecraft:light_gray_stained_glass
fill ~-38 ~10 ~-88 ~-38 ~11 ~-88 minecraft:gray_stained_glass
fill ~-38 ~10 ~-71 ~-38 ~11 ~-71 minecraft:light_gray_stained_glass
fill ~-52 ~10 ~-86 ~-52 ~11 ~-86 minecraft:gray_stained_glass
fill ~-36 ~10 ~-86 ~-36 ~11 ~-86 minecraft:light_gray_stained_glass
fill ~-52 ~10 ~-83 ~-52 ~11 ~-83 minecraft:gray_stained_glass
fill ~-36 ~10 ~-83 ~-36 ~11 ~-83 minecraft:light_gray_stained_glass
fill ~-52 ~10 ~-80 ~-52 ~11 ~-80 minecraft:gray_stained_glass
fill ~-36 ~10 ~-80 ~-36 ~11 ~-80 minecraft:light_gray_stained_glass
fill ~-52 ~10 ~-77 ~-52 ~11 ~-77 minecraft:gray_stained_glass
fill ~-36 ~10 ~-77 ~-36 ~11 ~-77 minecraft:light_gray_stained_glass
fill ~-52 ~10 ~-74 ~-52 ~11 ~-74 minecraft:gray_stained_glass
fill ~-36 ~10 ~-74 ~-36 ~11 ~-74 minecraft:light_gray_stained_glass
setblock ~-36 ~1 ~-83 minecraft:iron_door[half=lower,facing=east]
setblock ~-36 ~2 ~-83 minecraft:iron_door[half=upper,facing=east]
fill ~-52 ~7 ~-88 ~-36 ~12 ~-71 minecraft:air
fill ~-51 ~7 ~-87 ~-37 ~12 ~-72 minecraft:bricks
fill ~-50 ~8 ~-86 ~-38 ~11 ~-73 minecraft:air
fill ~-51 ~13 ~-87 ~-37 ~13 ~-72 minecraft:deepslate_tile_slab
