# Buildings 217..224
# 217 shop_house style=corner_store context=arterial_front facing=south
fill ~27 ~-3 ~6 ~32 ~-1 ~13 minecraft:stone
fill ~27 ~0 ~6 ~32 ~7 ~13 minecraft:bricks
fill ~28 ~1 ~7 ~31 ~6 ~12 minecraft:air
fill ~28 ~4 ~7 ~31 ~4 ~12 minecraft:smooth_stone
fill ~29 ~2 ~6 ~29 ~3 ~6 minecraft:gray_stained_glass
fill ~29 ~2 ~13 ~29 ~3 ~13 minecraft:light_gray_stained_glass
fill ~27 ~2 ~8 ~27 ~3 ~8 minecraft:gray_stained_glass
fill ~32 ~2 ~8 ~32 ~3 ~8 minecraft:light_gray_stained_glass
fill ~27 ~2 ~11 ~27 ~3 ~11 minecraft:gray_stained_glass
fill ~32 ~2 ~11 ~32 ~3 ~11 minecraft:light_gray_stained_glass
setblock ~29 ~1 ~13 minecraft:iron_door[half=lower,facing=south]
setblock ~29 ~2 ~13 minecraft:iron_door[half=upper,facing=south]
fill ~28 ~1 ~13 ~31 ~3 ~13 minecraft:cyan_stained_glass
setblock ~29 ~1 ~13 minecraft:iron_door[half=lower,facing=south]
setblock ~29 ~2 ~13 minecraft:iron_door[half=upper,facing=south]
setblock ~29 ~3 ~14 minecraft:red_wool
fill ~27 ~8 ~6 ~32 ~8 ~13 minecraft:deepslate_tile_slab
fill ~28 ~1 ~13 ~28 ~7 ~13 doomsday_decoration:redbrick
setblock ~29 ~3 ~13 minecraft:red_carpet
# 218 shop_house style=storefront context=local_front facing=south
fill ~15 ~-3 ~-53 ~18 ~-1 ~-48 minecraft:stone
fill ~15 ~0 ~-53 ~18 ~9 ~-48 minecraft:white_terracotta
fill ~16 ~1 ~-52 ~17 ~8 ~-49 minecraft:air
fill ~16 ~4 ~-52 ~17 ~4 ~-49 minecraft:smooth_stone
fill ~16 ~8 ~-52 ~17 ~8 ~-49 minecraft:smooth_stone
fill ~15 ~2 ~-51 ~15 ~3 ~-51 minecraft:gray_stained_glass
fill ~18 ~2 ~-51 ~18 ~3 ~-51 minecraft:light_gray_stained_glass
fill ~15 ~6 ~-51 ~15 ~7 ~-51 minecraft:gray_stained_glass
fill ~18 ~6 ~-51 ~18 ~7 ~-51 minecraft:light_gray_stained_glass
setblock ~17 ~1 ~-48 minecraft:iron_door[half=lower,facing=south]
setblock ~17 ~2 ~-48 minecraft:iron_door[half=upper,facing=south]
fill ~16 ~1 ~-48 ~17 ~3 ~-48 minecraft:cyan_stained_glass
setblock ~17 ~1 ~-48 minecraft:iron_door[half=lower,facing=south]
setblock ~17 ~2 ~-48 minecraft:iron_door[half=upper,facing=south]
setblock ~17 ~3 ~-47 minecraft:red_wool
fill ~15 ~10 ~-53 ~18 ~10 ~-48 minecraft:stone_brick_slab
# 219 local_shop style=arcade_shop context=collector_front facing=south
fill ~-15 ~-3 ~-83 ~-10 ~-1 ~-76 minecraft:stone
fill ~-15 ~0 ~-83 ~-10 ~11 ~-76 minecraft:smooth_sandstone
fill ~-14 ~1 ~-82 ~-11 ~10 ~-77 minecraft:air
fill ~-14 ~4 ~-82 ~-11 ~4 ~-77 minecraft:smooth_stone
fill ~-14 ~8 ~-82 ~-11 ~8 ~-77 minecraft:smooth_stone
fill ~-13 ~2 ~-83 ~-13 ~3 ~-83 minecraft:gray_stained_glass
fill ~-13 ~2 ~-76 ~-13 ~3 ~-76 minecraft:light_gray_stained_glass
fill ~-15 ~2 ~-81 ~-15 ~3 ~-81 minecraft:gray_stained_glass
fill ~-10 ~2 ~-81 ~-10 ~3 ~-81 minecraft:light_gray_stained_glass
fill ~-15 ~2 ~-78 ~-15 ~3 ~-78 minecraft:gray_stained_glass
fill ~-10 ~2 ~-78 ~-10 ~3 ~-78 minecraft:light_gray_stained_glass
fill ~-13 ~6 ~-83 ~-13 ~7 ~-83 minecraft:gray_stained_glass
fill ~-13 ~6 ~-76 ~-13 ~7 ~-76 minecraft:light_gray_stained_glass
fill ~-15 ~6 ~-81 ~-15 ~7 ~-81 minecraft:gray_stained_glass
fill ~-10 ~6 ~-81 ~-10 ~7 ~-81 minecraft:light_gray_stained_glass
fill ~-15 ~6 ~-78 ~-15 ~7 ~-78 minecraft:gray_stained_glass
fill ~-10 ~6 ~-78 ~-10 ~7 ~-78 minecraft:light_gray_stained_glass
setblock ~-13 ~1 ~-76 minecraft:iron_door[half=lower,facing=south]
setblock ~-13 ~2 ~-76 minecraft:iron_door[half=upper,facing=south]
fill ~-14 ~1 ~-76 ~-11 ~3 ~-76 minecraft:cyan_stained_glass
setblock ~-13 ~1 ~-76 minecraft:iron_door[half=lower,facing=south]
setblock ~-13 ~2 ~-76 minecraft:iron_door[half=upper,facing=south]
setblock ~-13 ~3 ~-75 minecraft:red_wool
fill ~-14 ~4 ~-76 ~-11 ~4 ~-76 minecraft:brown_terracotta
fill ~-15 ~12 ~-83 ~-10 ~12 ~-76 minecraft:stone_brick_slab
fill ~-13 ~13 ~-81 ~-11 ~14 ~-79 minecraft:light_gray_concrete
setblock ~-11 ~13 ~-80 minecraft:lightning_rod
fill ~-14 ~1 ~-76 ~-14 ~7 ~-76 minecraft:brown_terracotta
setblock ~-13 ~3 ~-76 minecraft:red_carpet
# 220 workshop style=sawtooth context=collector_front facing=west
fill ~52 ~-3 ~50 ~57 ~-1 ~53 minecraft:stone
fill ~52 ~0 ~50 ~57 ~7 ~53 minecraft:deepslate_bricks
fill ~53 ~1 ~51 ~56 ~6 ~52 minecraft:air
fill ~53 ~4 ~51 ~56 ~4 ~52 minecraft:smooth_stone
fill ~54 ~2 ~50 ~54 ~3 ~50 minecraft:gray_stained_glass
fill ~54 ~2 ~53 ~54 ~3 ~53 minecraft:light_gray_stained_glass
setblock ~52 ~1 ~52 minecraft:iron_door[half=lower,facing=west]
setblock ~52 ~2 ~52 minecraft:iron_door[half=upper,facing=west]
fill ~52 ~1 ~52 ~52 ~4 ~51 minecraft:polished_blackstone
fill ~52 ~5 ~52 ~52 ~5 ~51 minecraft:light_blue_stained_glass
fill ~54 ~9 ~52 ~56 ~10 ~52 minecraft:iron_block
fill ~52 ~8 ~50 ~57 ~8 ~53 minecraft:deepslate_tile_slab
# 221 local_shop style=storefront context=local_front facing=east
fill ~52 ~-3 ~26 ~57 ~-1 ~29 minecraft:stone
fill ~52 ~0 ~26 ~57 ~7 ~29 minecraft:smooth_sandstone
fill ~53 ~1 ~27 ~56 ~6 ~28 minecraft:air
fill ~53 ~4 ~27 ~56 ~4 ~28 minecraft:smooth_stone
fill ~54 ~2 ~26 ~54 ~3 ~26 minecraft:gray_stained_glass
fill ~54 ~2 ~29 ~54 ~3 ~29 minecraft:light_gray_stained_glass
setblock ~57 ~1 ~28 minecraft:iron_door[half=lower,facing=east]
setblock ~57 ~2 ~28 minecraft:iron_door[half=upper,facing=east]
fill ~57 ~1 ~27 ~57 ~3 ~28 minecraft:cyan_stained_glass
setblock ~57 ~1 ~28 minecraft:iron_door[half=lower,facing=east]
setblock ~57 ~2 ~28 minecraft:iron_door[half=upper,facing=east]
setblock ~58 ~3 ~28 minecraft:red_wool
fill ~52 ~8 ~26 ~57 ~8 ~29 minecraft:stone_brick_slab
# 222 row_house style=rowhouse context=station_front facing=north
fill ~-73 ~-3 ~-45 ~-70 ~-1 ~-40 minecraft:stone
fill ~-73 ~0 ~-45 ~-70 ~9 ~-40 minecraft:bricks
fill ~-72 ~1 ~-44 ~-71 ~8 ~-41 minecraft:air
fill ~-72 ~4 ~-44 ~-71 ~4 ~-41 minecraft:smooth_stone
fill ~-72 ~8 ~-44 ~-71 ~8 ~-41 minecraft:smooth_stone
fill ~-73 ~2 ~-43 ~-73 ~3 ~-43 minecraft:gray_stained_glass
fill ~-70 ~2 ~-43 ~-70 ~3 ~-43 minecraft:light_gray_stained_glass
fill ~-73 ~6 ~-43 ~-73 ~7 ~-43 minecraft:gray_stained_glass
fill ~-70 ~6 ~-43 ~-70 ~7 ~-43 minecraft:light_gray_stained_glass
setblock ~-71 ~1 ~-45 minecraft:iron_door[half=lower,facing=north]
setblock ~-71 ~2 ~-45 minecraft:iron_door[half=upper,facing=north]
fill ~-73 ~10 ~-45 ~-70 ~10 ~-40 minecraft:deepslate_tile_slab
fill ~-72 ~11 ~-44 ~-71 ~11 ~-41 minecraft:deepslate_tile_slab
setblock ~-71 ~3 ~-46 minecraft:dark_oak_slab[type=top]
fill ~-71 ~11 ~-43 ~-71 ~12 ~-41 minecraft:light_gray_concrete
setblock ~-71 ~11 ~-42 minecraft:lightning_rod
# 223 shop_house style=storefront context=collector_front facing=east
fill ~-106 ~-3 ~25 ~-101 ~-1 ~28 minecraft:stone
fill ~-106 ~0 ~25 ~-101 ~9 ~28 minecraft:calcite
fill ~-105 ~1 ~26 ~-102 ~8 ~27 minecraft:air
fill ~-105 ~4 ~26 ~-102 ~4 ~27 minecraft:smooth_stone
fill ~-105 ~8 ~26 ~-102 ~8 ~27 minecraft:smooth_stone
fill ~-104 ~2 ~25 ~-104 ~3 ~25 minecraft:gray_stained_glass
fill ~-104 ~2 ~28 ~-104 ~3 ~28 minecraft:light_gray_stained_glass
fill ~-104 ~6 ~25 ~-104 ~7 ~25 minecraft:gray_stained_glass
fill ~-104 ~6 ~28 ~-104 ~7 ~28 minecraft:light_gray_stained_glass
setblock ~-101 ~1 ~27 minecraft:iron_door[half=lower,facing=east]
setblock ~-101 ~2 ~27 minecraft:iron_door[half=upper,facing=east]
fill ~-101 ~1 ~26 ~-101 ~3 ~27 minecraft:cyan_stained_glass
setblock ~-101 ~1 ~27 minecraft:iron_door[half=lower,facing=east]
setblock ~-101 ~2 ~27 minecraft:iron_door[half=upper,facing=east]
setblock ~-100 ~3 ~27 minecraft:red_wool
fill ~-106 ~10 ~25 ~-101 ~10 ~28 minecraft:stone_brick_slab
# 224 local_shop style=arcade_shop context=collector_front facing=west
fill ~28 ~-3 ~43 ~33 ~-1 ~46 minecraft:stone
fill ~28 ~0 ~43 ~33 ~5 ~46 minecraft:bricks
fill ~29 ~1 ~44 ~32 ~4 ~45 minecraft:air
fill ~29 ~4 ~44 ~32 ~4 ~45 minecraft:smooth_stone
fill ~30 ~2 ~43 ~30 ~3 ~43 minecraft:gray_stained_glass
fill ~30 ~2 ~46 ~30 ~3 ~46 minecraft:light_gray_stained_glass
setblock ~28 ~1 ~45 minecraft:iron_door[half=lower,facing=west]
setblock ~28 ~2 ~45 minecraft:iron_door[half=upper,facing=west]
fill ~28 ~1 ~44 ~28 ~3 ~45 minecraft:cyan_stained_glass
setblock ~28 ~1 ~45 minecraft:iron_door[half=lower,facing=west]
setblock ~28 ~2 ~45 minecraft:iron_door[half=upper,facing=west]
setblock ~27 ~3 ~45 minecraft:red_wool
fill ~28 ~4 ~44 ~28 ~4 ~45 doomsday_decoration:hollowbrick
fill ~28 ~6 ~43 ~33 ~6 ~46 minecraft:deepslate_tile_slab
