# Buildings 26..50
# 026 local_shop -102,50 -94,56 h=11
fill ~-102 ~-3 ~50 ~-94 ~-1 ~56 minecraft:stone
fill ~-102 ~0 ~50 ~-94 ~11 ~56 minecraft:white_terracotta
fill ~-101 ~1 ~51 ~-95 ~10 ~55 minecraft:air
fill ~-101 ~4 ~51 ~-95 ~4 ~55 minecraft:smooth_stone
fill ~-101 ~8 ~51 ~-95 ~8 ~55 minecraft:smooth_stone
fill ~-102 ~2 ~52 ~-102 ~3 ~54 minecraft:gray_stained_glass
fill ~-94 ~2 ~52 ~-94 ~3 ~54 minecraft:light_gray_stained_glass
fill ~-102 ~6 ~52 ~-102 ~7 ~54 minecraft:gray_stained_glass
fill ~-94 ~6 ~52 ~-94 ~7 ~54 minecraft:light_gray_stained_glass
fill ~-101 ~0 ~50 ~-98 ~3 ~50 minecraft:dark_oak_planks
setblock ~-100 ~1 ~50 minecraft:iron_door[half=lower,facing=north]
setblock ~-100 ~2 ~50 minecraft:iron_door[half=upper,facing=north]
fill ~-102 ~12 ~50 ~-94 ~12 ~56 minecraft:dark_oak_slab
# 027 retail -7,-46 0,-38 h=16
fill ~-7 ~-3 ~-46 ~0 ~-1 ~-38 minecraft:stone
fill ~-7 ~0 ~-46 ~0 ~16 ~-38 minecraft:white_terracotta
fill ~-6 ~1 ~-45 ~-1 ~15 ~-39 minecraft:air
fill ~-6 ~4 ~-45 ~-1 ~4 ~-39 minecraft:smooth_stone
fill ~-6 ~8 ~-45 ~-1 ~8 ~-39 minecraft:smooth_stone
fill ~-6 ~12 ~-45 ~-1 ~12 ~-39 minecraft:smooth_stone
fill ~-5 ~2 ~-46 ~-2 ~3 ~-46 minecraft:gray_stained_glass
fill ~-5 ~2 ~-38 ~-2 ~3 ~-38 minecraft:light_gray_stained_glass
fill ~-5 ~6 ~-46 ~-2 ~7 ~-46 minecraft:gray_stained_glass
fill ~-5 ~6 ~-38 ~-2 ~7 ~-38 minecraft:light_gray_stained_glass
fill ~-5 ~10 ~-46 ~-2 ~11 ~-46 minecraft:gray_stained_glass
fill ~-5 ~10 ~-38 ~-2 ~11 ~-38 minecraft:light_gray_stained_glass
fill ~-5 ~14 ~-46 ~-2 ~15 ~-46 minecraft:gray_stained_glass
fill ~-5 ~14 ~-38 ~-2 ~15 ~-38 minecraft:light_gray_stained_glass
fill ~-6 ~0 ~-46 ~-3 ~3 ~-46 minecraft:gray_concrete
setblock ~-5 ~1 ~-46 minecraft:iron_door[half=lower,facing=north]
setblock ~-5 ~2 ~-46 minecraft:iron_door[half=upper,facing=north]
fill ~-7 ~17 ~-46 ~0 ~17 ~-38 minecraft:stone_brick_slab
# 028 small_office 3,-49 13,-37 h=24
fill ~3 ~-3 ~-49 ~13 ~-1 ~-37 minecraft:stone
fill ~3 ~0 ~-49 ~13 ~24 ~-37 minecraft:bricks
fill ~4 ~1 ~-48 ~12 ~23 ~-38 minecraft:air
fill ~4 ~4 ~-48 ~12 ~4 ~-38 minecraft:smooth_stone
fill ~4 ~8 ~-48 ~12 ~8 ~-38 minecraft:smooth_stone
fill ~4 ~12 ~-48 ~12 ~12 ~-38 minecraft:smooth_stone
fill ~4 ~16 ~-48 ~12 ~16 ~-38 minecraft:smooth_stone
fill ~4 ~20 ~-48 ~12 ~20 ~-38 minecraft:smooth_stone
fill ~5 ~2 ~-49 ~11 ~3 ~-49 minecraft:gray_stained_glass
fill ~5 ~2 ~-37 ~11 ~3 ~-37 minecraft:light_gray_stained_glass
fill ~5 ~6 ~-49 ~11 ~7 ~-49 minecraft:gray_stained_glass
fill ~5 ~6 ~-37 ~11 ~7 ~-37 minecraft:light_gray_stained_glass
fill ~5 ~10 ~-49 ~11 ~11 ~-49 minecraft:gray_stained_glass
fill ~5 ~10 ~-37 ~11 ~11 ~-37 minecraft:light_gray_stained_glass
fill ~5 ~14 ~-49 ~11 ~15 ~-49 minecraft:gray_stained_glass
fill ~5 ~14 ~-37 ~11 ~15 ~-37 minecraft:light_gray_stained_glass
fill ~5 ~18 ~-49 ~11 ~19 ~-49 minecraft:gray_stained_glass
fill ~5 ~18 ~-37 ~11 ~19 ~-37 minecraft:light_gray_stained_glass
fill ~5 ~22 ~-49 ~11 ~23 ~-49 minecraft:gray_stained_glass
fill ~5 ~22 ~-37 ~11 ~23 ~-37 minecraft:light_gray_stained_glass
fill ~4 ~0 ~-49 ~7 ~3 ~-49 doomsday_decoration:redbrick
setblock ~5 ~1 ~-49 minecraft:iron_door[half=lower,facing=north]
setblock ~5 ~2 ~-49 minecraft:iron_door[half=upper,facing=north]
fill ~3 ~25 ~-49 ~13 ~25 ~-37 minecraft:deepslate_tile_slab
# 029 row_house -71,110 -65,117 h=7
fill ~-71 ~-3 ~110 ~-65 ~-1 ~117 minecraft:stone
fill ~-71 ~0 ~110 ~-65 ~7 ~117 minecraft:calcite
fill ~-70 ~1 ~111 ~-66 ~6 ~116 minecraft:air
fill ~-70 ~4 ~111 ~-66 ~4 ~116 minecraft:smooth_stone
fill ~-69 ~2 ~110 ~-67 ~3 ~110 minecraft:gray_stained_glass
fill ~-69 ~2 ~117 ~-67 ~3 ~117 minecraft:light_gray_stained_glass
fill ~-70 ~0 ~110 ~-67 ~3 ~110 minecraft:gray_concrete
setblock ~-69 ~1 ~110 minecraft:iron_door[half=lower,facing=north]
setblock ~-69 ~2 ~110 minecraft:iron_door[half=upper,facing=north]
fill ~-71 ~8 ~110 ~-65 ~8 ~117 minecraft:stone_brick_slab
# 030 clinic 17,-58 25,-45 h=10
fill ~17 ~-3 ~-58 ~25 ~-1 ~-45 minecraft:stone
fill ~17 ~0 ~-58 ~25 ~10 ~-45 minecraft:light_gray_concrete
fill ~18 ~1 ~-57 ~24 ~9 ~-46 minecraft:air
fill ~18 ~4 ~-57 ~24 ~4 ~-46 minecraft:smooth_stone
fill ~18 ~8 ~-57 ~24 ~8 ~-46 minecraft:smooth_stone
fill ~17 ~2 ~-56 ~17 ~3 ~-47 minecraft:gray_stained_glass
fill ~25 ~2 ~-56 ~25 ~3 ~-47 minecraft:light_gray_stained_glass
fill ~17 ~6 ~-56 ~17 ~7 ~-47 minecraft:gray_stained_glass
fill ~25 ~6 ~-56 ~25 ~7 ~-47 minecraft:light_gray_stained_glass
fill ~18 ~0 ~-58 ~21 ~3 ~-58 doomsday_decoration:porcelainbrickwall
setblock ~19 ~1 ~-58 minecraft:iron_door[half=lower,facing=north]
setblock ~19 ~2 ~-58 minecraft:iron_door[half=upper,facing=north]
fill ~17 ~11 ~-58 ~25 ~11 ~-45 minecraft:smooth_stone_slab
# 031 row_house -123,-24 -117,-14 h=9
fill ~-123 ~-3 ~-24 ~-117 ~-1 ~-14 minecraft:stone
fill ~-123 ~0 ~-24 ~-117 ~9 ~-14 minecraft:mud_bricks
fill ~-122 ~1 ~-23 ~-118 ~8 ~-15 minecraft:air
fill ~-122 ~4 ~-23 ~-118 ~4 ~-15 minecraft:smooth_stone
fill ~-122 ~8 ~-23 ~-118 ~8 ~-15 minecraft:smooth_stone
fill ~-121 ~2 ~-24 ~-119 ~3 ~-24 minecraft:gray_stained_glass
fill ~-121 ~2 ~-14 ~-119 ~3 ~-14 minecraft:light_gray_stained_glass
fill ~-121 ~6 ~-24 ~-119 ~7 ~-24 minecraft:gray_stained_glass
fill ~-121 ~6 ~-14 ~-119 ~7 ~-14 minecraft:light_gray_stained_glass
fill ~-122 ~0 ~-24 ~-119 ~3 ~-24 minecraft:spruce_planks
setblock ~-121 ~1 ~-24 minecraft:iron_door[half=lower,facing=north]
setblock ~-121 ~2 ~-24 minecraft:iron_door[half=upper,facing=north]
fill ~-123 ~10 ~-24 ~-117 ~10 ~-14 minecraft:deepslate_tile_slab
# 032 detached_house 41,92 51,102 h=7
fill ~41 ~-3 ~92 ~51 ~-1 ~102 minecraft:stone
fill ~41 ~0 ~92 ~51 ~7 ~102 minecraft:white_terracotta
fill ~42 ~1 ~93 ~50 ~6 ~101 minecraft:air
fill ~42 ~4 ~93 ~50 ~4 ~101 minecraft:smooth_stone
fill ~43 ~2 ~92 ~49 ~3 ~92 minecraft:gray_stained_glass
fill ~43 ~2 ~102 ~49 ~3 ~102 minecraft:light_gray_stained_glass
fill ~42 ~0 ~92 ~45 ~3 ~92 minecraft:dark_oak_planks
setblock ~43 ~1 ~92 minecraft:iron_door[half=lower,facing=north]
setblock ~43 ~2 ~92 minecraft:iron_door[half=upper,facing=north]
fill ~41 ~8 ~92 ~51 ~8 ~102 minecraft:dark_oak_slab
# 033 community 80,-61 86,-55 h=7
fill ~80 ~-3 ~-61 ~86 ~-1 ~-55 minecraft:stone
fill ~80 ~0 ~-61 ~86 ~7 ~-55 minecraft:mud_bricks
fill ~81 ~1 ~-60 ~85 ~6 ~-56 minecraft:air
fill ~81 ~4 ~-60 ~85 ~4 ~-56 minecraft:smooth_stone
fill ~80 ~2 ~-59 ~80 ~3 ~-57 minecraft:gray_stained_glass
fill ~86 ~2 ~-59 ~86 ~3 ~-57 minecraft:light_gray_stained_glass
fill ~81 ~0 ~-61 ~84 ~3 ~-61 minecraft:spruce_planks
setblock ~82 ~1 ~-61 minecraft:iron_door[half=lower,facing=north]
setblock ~82 ~2 ~-61 minecraft:iron_door[half=upper,facing=north]
fill ~80 ~8 ~-61 ~86 ~8 ~-55 minecraft:deepslate_tile_slab
# 034 detached_house -124,31 -117,42 h=7
fill ~-124 ~-3 ~31 ~-117 ~-1 ~42 minecraft:stone
fill ~-124 ~0 ~31 ~-117 ~7 ~42 minecraft:white_terracotta
fill ~-123 ~1 ~32 ~-118 ~6 ~41 minecraft:air
fill ~-123 ~4 ~32 ~-118 ~4 ~41 minecraft:smooth_stone
fill ~-124 ~2 ~33 ~-124 ~3 ~40 minecraft:gray_stained_glass
fill ~-117 ~2 ~33 ~-117 ~3 ~40 minecraft:light_gray_stained_glass
fill ~-123 ~0 ~31 ~-120 ~3 ~31 minecraft:dark_oak_planks
setblock ~-122 ~1 ~31 minecraft:iron_door[half=lower,facing=north]
setblock ~-122 ~2 ~31 minecraft:iron_door[half=upper,facing=north]
fill ~-124 ~8 ~31 ~-117 ~8 ~42 minecraft:dark_oak_slab
# 035 shop_house -19,71 -10,80 h=12
fill ~-19 ~-3 ~71 ~-10 ~-1 ~80 minecraft:stone
fill ~-19 ~0 ~71 ~-10 ~12 ~80 minecraft:bricks
fill ~-18 ~1 ~72 ~-11 ~11 ~79 minecraft:air
fill ~-18 ~4 ~72 ~-11 ~4 ~79 minecraft:smooth_stone
fill ~-18 ~8 ~72 ~-11 ~8 ~79 minecraft:smooth_stone
fill ~-17 ~2 ~71 ~-12 ~3 ~71 minecraft:gray_stained_glass
fill ~-17 ~2 ~80 ~-12 ~3 ~80 minecraft:light_gray_stained_glass
fill ~-17 ~6 ~71 ~-12 ~7 ~71 minecraft:gray_stained_glass
fill ~-17 ~6 ~80 ~-12 ~7 ~80 minecraft:light_gray_stained_glass
fill ~-17 ~10 ~71 ~-12 ~11 ~71 minecraft:gray_stained_glass
fill ~-17 ~10 ~80 ~-12 ~11 ~80 minecraft:light_gray_stained_glass
fill ~-18 ~0 ~71 ~-15 ~3 ~71 doomsday_decoration:hollowbrick
setblock ~-17 ~1 ~71 minecraft:iron_door[half=lower,facing=north]
setblock ~-17 ~2 ~71 minecraft:iron_door[half=upper,facing=north]
fill ~-19 ~13 ~71 ~-10 ~13 ~80 minecraft:deepslate_tile_slab
# 036 detached_house -109,-67 -101,-57 h=9
fill ~-109 ~-3 ~-67 ~-101 ~-1 ~-57 minecraft:stone
fill ~-109 ~0 ~-67 ~-101 ~9 ~-57 minecraft:calcite
fill ~-108 ~1 ~-66 ~-102 ~8 ~-58 minecraft:air
fill ~-108 ~4 ~-66 ~-102 ~4 ~-58 minecraft:smooth_stone
fill ~-108 ~8 ~-66 ~-102 ~8 ~-58 minecraft:smooth_stone
fill ~-107 ~2 ~-67 ~-103 ~3 ~-67 minecraft:gray_stained_glass
fill ~-107 ~2 ~-57 ~-103 ~3 ~-57 minecraft:light_gray_stained_glass
fill ~-107 ~6 ~-67 ~-103 ~7 ~-67 minecraft:gray_stained_glass
fill ~-107 ~6 ~-57 ~-103 ~7 ~-57 minecraft:light_gray_stained_glass
fill ~-108 ~0 ~-67 ~-105 ~3 ~-67 minecraft:gray_concrete
setblock ~-107 ~1 ~-67 minecraft:iron_door[half=lower,facing=north]
setblock ~-107 ~2 ~-67 minecraft:iron_door[half=upper,facing=north]
fill ~-109 ~10 ~-67 ~-101 ~10 ~-57 minecraft:stone_brick_slab
# 037 workshop -83,-54 -71,-42 h=10
fill ~-83 ~-3 ~-54 ~-71 ~-1 ~-42 minecraft:stone
fill ~-83 ~0 ~-54 ~-71 ~10 ~-42 minecraft:light_gray_concrete
fill ~-82 ~1 ~-53 ~-72 ~9 ~-43 minecraft:air
fill ~-82 ~4 ~-53 ~-72 ~4 ~-43 minecraft:smooth_stone
fill ~-82 ~8 ~-53 ~-72 ~8 ~-43 minecraft:smooth_stone
fill ~-83 ~2 ~-52 ~-83 ~3 ~-44 minecraft:gray_stained_glass
fill ~-71 ~2 ~-52 ~-71 ~3 ~-44 minecraft:light_gray_stained_glass
fill ~-83 ~6 ~-52 ~-83 ~7 ~-44 minecraft:gray_stained_glass
fill ~-71 ~6 ~-52 ~-71 ~7 ~-44 minecraft:light_gray_stained_glass
fill ~-82 ~0 ~-54 ~-79 ~3 ~-54 doomsday_decoration:porcelainbrickwall
setblock ~-81 ~1 ~-54 minecraft:iron_door[half=lower,facing=north]
setblock ~-81 ~2 ~-54 minecraft:iron_door[half=upper,facing=north]
fill ~-83 ~11 ~-54 ~-71 ~11 ~-42 minecraft:smooth_stone_slab
# 038 garage 74,86 88,105 h=10
fill ~74 ~-3 ~86 ~88 ~-1 ~105 minecraft:stone
fill ~74 ~0 ~86 ~88 ~10 ~105 minecraft:stone_bricks
fill ~75 ~1 ~87 ~87 ~9 ~104 minecraft:air
fill ~75 ~4 ~87 ~87 ~4 ~104 minecraft:smooth_stone
fill ~75 ~8 ~87 ~87 ~8 ~104 minecraft:smooth_stone
fill ~74 ~2 ~88 ~74 ~3 ~103 minecraft:gray_stained_glass
fill ~88 ~2 ~88 ~88 ~3 ~103 minecraft:light_gray_stained_glass
fill ~74 ~6 ~88 ~74 ~7 ~103 minecraft:gray_stained_glass
fill ~88 ~6 ~88 ~88 ~7 ~103 minecraft:light_gray_stained_glass
fill ~75 ~0 ~86 ~78 ~3 ~86 minecraft:orange_terracotta
setblock ~76 ~1 ~86 minecraft:iron_door[half=lower,facing=north]
setblock ~76 ~2 ~86 minecraft:iron_door[half=upper,facing=north]
fill ~74 ~11 ~86 ~88 ~11 ~105 minecraft:stone_brick_slab
fill ~86 ~8 ~103 ~88 ~11 ~105 minecraft:air
setblock ~86 ~8 ~103 minecraft:cobweb
# 039 row_house -24,97 -14,110 h=5
fill ~-24 ~-3 ~97 ~-14 ~-1 ~110 minecraft:stone
fill ~-24 ~0 ~97 ~-14 ~5 ~110 minecraft:white_terracotta
fill ~-23 ~1 ~98 ~-15 ~4 ~109 minecraft:air
fill ~-23 ~4 ~98 ~-15 ~4 ~109 minecraft:smooth_stone
fill ~-24 ~2 ~99 ~-24 ~3 ~108 minecraft:gray_stained_glass
fill ~-14 ~2 ~99 ~-14 ~3 ~108 minecraft:light_gray_stained_glass
fill ~-23 ~0 ~97 ~-20 ~3 ~97 minecraft:dark_oak_planks
setblock ~-22 ~1 ~97 minecraft:iron_door[half=lower,facing=north]
setblock ~-22 ~2 ~97 minecraft:iron_door[half=upper,facing=north]
fill ~-24 ~6 ~97 ~-14 ~6 ~110 minecraft:dark_oak_slab
# 040 warehouse 95,-14 101,-3 h=5
fill ~95 ~-3 ~-14 ~101 ~-1 ~-3 minecraft:stone
fill ~95 ~0 ~-14 ~101 ~5 ~-3 minecraft:bricks
fill ~96 ~1 ~-13 ~100 ~4 ~-4 minecraft:air
fill ~96 ~4 ~-13 ~100 ~4 ~-4 minecraft:smooth_stone
fill ~95 ~2 ~-12 ~95 ~3 ~-5 minecraft:gray_stained_glass
fill ~101 ~2 ~-12 ~101 ~3 ~-5 minecraft:light_gray_stained_glass
fill ~96 ~0 ~-14 ~99 ~3 ~-14 minecraft:weathered_cut_copper
setblock ~97 ~1 ~-14 minecraft:iron_door[half=lower,facing=north]
setblock ~97 ~2 ~-14 minecraft:iron_door[half=upper,facing=north]
fill ~95 ~6 ~-14 ~101 ~6 ~-3 minecraft:deepslate_tile_slab
# 041 local_shop -123,-12 -113,-2 h=11
fill ~-123 ~-3 ~-12 ~-113 ~-1 ~-2 minecraft:stone
fill ~-123 ~0 ~-12 ~-113 ~11 ~-2 minecraft:mud_bricks
fill ~-122 ~1 ~-11 ~-114 ~10 ~-3 minecraft:air
fill ~-122 ~4 ~-11 ~-114 ~4 ~-3 minecraft:smooth_stone
fill ~-122 ~8 ~-11 ~-114 ~8 ~-3 minecraft:smooth_stone
fill ~-121 ~2 ~-12 ~-115 ~3 ~-12 minecraft:gray_stained_glass
fill ~-121 ~2 ~-2 ~-115 ~3 ~-2 minecraft:light_gray_stained_glass
fill ~-121 ~6 ~-12 ~-115 ~7 ~-12 minecraft:gray_stained_glass
fill ~-121 ~6 ~-2 ~-115 ~7 ~-2 minecraft:light_gray_stained_glass
fill ~-122 ~0 ~-12 ~-119 ~3 ~-12 minecraft:spruce_planks
setblock ~-121 ~1 ~-12 minecraft:iron_door[half=lower,facing=north]
setblock ~-121 ~2 ~-12 minecraft:iron_door[half=upper,facing=north]
fill ~-123 ~12 ~-12 ~-113 ~12 ~-2 minecraft:deepslate_tile_slab
# 042 workshop -27,60 -21,70 h=8
fill ~-27 ~-3 ~60 ~-21 ~-1 ~70 minecraft:stone
fill ~-27 ~0 ~60 ~-21 ~8 ~70 minecraft:smooth_sandstone
fill ~-26 ~1 ~61 ~-22 ~7 ~69 minecraft:air
fill ~-26 ~4 ~61 ~-22 ~4 ~69 minecraft:smooth_stone
fill ~-25 ~2 ~60 ~-23 ~3 ~60 minecraft:gray_stained_glass
fill ~-25 ~2 ~70 ~-23 ~3 ~70 minecraft:light_gray_stained_glass
fill ~-25 ~6 ~60 ~-23 ~7 ~60 minecraft:gray_stained_glass
fill ~-25 ~6 ~70 ~-23 ~7 ~70 minecraft:light_gray_stained_glass
fill ~-26 ~0 ~60 ~-23 ~3 ~60 minecraft:brown_terracotta
setblock ~-25 ~1 ~60 minecraft:iron_door[half=lower,facing=north]
setblock ~-25 ~2 ~60 minecraft:iron_door[half=upper,facing=north]
fill ~-27 ~9 ~60 ~-21 ~9 ~70 minecraft:stone_brick_slab
# 043 warehouse -52,-88 -36,-71 h=12
fill ~-52 ~-3 ~-88 ~-36 ~-1 ~-71 minecraft:stone
fill ~-52 ~0 ~-88 ~-36 ~12 ~-71 minecraft:bricks
fill ~-51 ~1 ~-87 ~-37 ~11 ~-72 minecraft:air
fill ~-51 ~4 ~-87 ~-37 ~4 ~-72 minecraft:smooth_stone
fill ~-51 ~8 ~-87 ~-37 ~8 ~-72 minecraft:smooth_stone
fill ~-52 ~2 ~-86 ~-52 ~3 ~-73 minecraft:gray_stained_glass
fill ~-36 ~2 ~-86 ~-36 ~3 ~-73 minecraft:light_gray_stained_glass
fill ~-52 ~6 ~-86 ~-52 ~7 ~-73 minecraft:gray_stained_glass
fill ~-36 ~6 ~-86 ~-36 ~7 ~-73 minecraft:light_gray_stained_glass
fill ~-52 ~10 ~-86 ~-52 ~11 ~-73 minecraft:gray_stained_glass
fill ~-36 ~10 ~-86 ~-36 ~11 ~-73 minecraft:light_gray_stained_glass
fill ~-51 ~0 ~-88 ~-48 ~3 ~-88 minecraft:gray_concrete
setblock ~-50 ~1 ~-88 minecraft:iron_door[half=lower,facing=north]
setblock ~-50 ~2 ~-88 minecraft:iron_door[half=upper,facing=north]
fill ~-52 ~13 ~-88 ~-36 ~13 ~-71 minecraft:deepslate_tile_slab
# 044 garage 89,85 98,96 h=6
fill ~89 ~-3 ~85 ~98 ~-1 ~96 minecraft:stone
fill ~89 ~0 ~85 ~98 ~6 ~96 minecraft:stone_bricks
fill ~90 ~1 ~86 ~97 ~5 ~95 minecraft:air
fill ~90 ~4 ~86 ~97 ~4 ~95 minecraft:smooth_stone
fill ~91 ~2 ~85 ~96 ~3 ~85 minecraft:gray_stained_glass
fill ~91 ~2 ~96 ~96 ~3 ~96 minecraft:light_gray_stained_glass
fill ~90 ~0 ~85 ~93 ~3 ~85 minecraft:orange_terracotta
setblock ~91 ~1 ~85 minecraft:iron_door[half=lower,facing=north]
setblock ~91 ~2 ~85 minecraft:iron_door[half=upper,facing=north]
fill ~89 ~7 ~85 ~98 ~7 ~96 minecraft:stone_brick_slab
# 045 local_shop -75,84 -70,94 h=7
fill ~-75 ~-3 ~84 ~-70 ~-1 ~94 minecraft:stone
fill ~-75 ~0 ~84 ~-70 ~7 ~94 minecraft:calcite
fill ~-74 ~1 ~85 ~-71 ~6 ~93 minecraft:air
fill ~-74 ~4 ~85 ~-71 ~4 ~93 minecraft:smooth_stone
fill ~-73 ~2 ~84 ~-72 ~3 ~84 minecraft:gray_stained_glass
fill ~-73 ~2 ~94 ~-72 ~3 ~94 minecraft:light_gray_stained_glass
fill ~-74 ~0 ~84 ~-71 ~3 ~84 minecraft:gray_concrete
setblock ~-73 ~1 ~84 minecraft:iron_door[half=lower,facing=north]
setblock ~-73 ~2 ~84 minecraft:iron_door[half=upper,facing=north]
fill ~-75 ~8 ~84 ~-70 ~8 ~94 minecraft:stone_brick_slab
# 046 retail -10,-57 1,-50 h=12
fill ~-10 ~-3 ~-57 ~1 ~-1 ~-50 minecraft:stone
fill ~-10 ~0 ~-57 ~1 ~12 ~-50 minecraft:light_gray_concrete
fill ~-9 ~1 ~-56 ~0 ~11 ~-51 minecraft:air
fill ~-9 ~4 ~-56 ~0 ~4 ~-51 minecraft:smooth_stone
fill ~-9 ~8 ~-56 ~0 ~8 ~-51 minecraft:smooth_stone
fill ~-8 ~2 ~-57 ~-1 ~3 ~-57 minecraft:gray_stained_glass
fill ~-8 ~2 ~-50 ~-1 ~3 ~-50 minecraft:light_gray_stained_glass
fill ~-8 ~6 ~-57 ~-1 ~7 ~-57 minecraft:gray_stained_glass
fill ~-8 ~6 ~-50 ~-1 ~7 ~-50 minecraft:light_gray_stained_glass
fill ~-8 ~10 ~-57 ~-1 ~11 ~-57 minecraft:gray_stained_glass
fill ~-8 ~10 ~-50 ~-1 ~11 ~-50 minecraft:light_gray_stained_glass
fill ~-9 ~0 ~-57 ~-6 ~3 ~-57 doomsday_decoration:cementwall
setblock ~-8 ~1 ~-57 minecraft:iron_door[half=lower,facing=north]
setblock ~-8 ~2 ~-57 minecraft:iron_door[half=upper,facing=north]
fill ~-10 ~13 ~-57 ~1 ~13 ~-50 minecraft:smooth_stone_slab
# 047 mixed_use 14,12 23,20 h=12
fill ~14 ~-3 ~12 ~23 ~-1 ~20 minecraft:stone
fill ~14 ~0 ~12 ~23 ~12 ~20 minecraft:light_gray_concrete
fill ~15 ~1 ~13 ~22 ~11 ~19 minecraft:air
fill ~15 ~4 ~13 ~22 ~4 ~19 minecraft:smooth_stone
fill ~15 ~8 ~13 ~22 ~8 ~19 minecraft:smooth_stone
fill ~16 ~2 ~12 ~21 ~3 ~12 minecraft:gray_stained_glass
fill ~16 ~2 ~20 ~21 ~3 ~20 minecraft:light_gray_stained_glass
fill ~16 ~6 ~12 ~21 ~7 ~12 minecraft:gray_stained_glass
fill ~16 ~6 ~20 ~21 ~7 ~20 minecraft:light_gray_stained_glass
fill ~16 ~10 ~12 ~21 ~11 ~12 minecraft:gray_stained_glass
fill ~16 ~10 ~20 ~21 ~11 ~20 minecraft:light_gray_stained_glass
fill ~15 ~0 ~12 ~18 ~3 ~12 doomsday_decoration:cementwall
setblock ~16 ~1 ~12 minecraft:iron_door[half=lower,facing=north]
setblock ~16 ~2 ~12 minecraft:iron_door[half=upper,facing=north]
fill ~14 ~13 ~12 ~23 ~13 ~20 minecraft:smooth_stone_slab
# 048 local_shop -118,55 -107,66 h=9
fill ~-118 ~-3 ~55 ~-107 ~-1 ~66 minecraft:stone
fill ~-118 ~0 ~55 ~-107 ~9 ~66 minecraft:white_terracotta
fill ~-117 ~1 ~56 ~-108 ~8 ~65 minecraft:air
fill ~-117 ~4 ~56 ~-108 ~4 ~65 minecraft:smooth_stone
fill ~-117 ~8 ~56 ~-108 ~8 ~65 minecraft:smooth_stone
fill ~-116 ~2 ~55 ~-109 ~3 ~55 minecraft:gray_stained_glass
fill ~-116 ~2 ~66 ~-109 ~3 ~66 minecraft:light_gray_stained_glass
fill ~-116 ~6 ~55 ~-109 ~7 ~55 minecraft:gray_stained_glass
fill ~-116 ~6 ~66 ~-109 ~7 ~66 minecraft:light_gray_stained_glass
fill ~-117 ~0 ~55 ~-114 ~3 ~55 minecraft:dark_oak_planks
setblock ~-116 ~1 ~55 minecraft:iron_door[half=lower,facing=north]
setblock ~-116 ~2 ~55 minecraft:iron_door[half=upper,facing=north]
fill ~-118 ~10 ~55 ~-107 ~10 ~66 minecraft:dark_oak_slab
# 049 local_shop -111,-28 -100,-21 h=5
fill ~-111 ~-3 ~-28 ~-100 ~-1 ~-21 minecraft:stone
fill ~-111 ~0 ~-28 ~-100 ~5 ~-21 minecraft:calcite
fill ~-110 ~1 ~-27 ~-101 ~4 ~-22 minecraft:air
fill ~-110 ~4 ~-27 ~-101 ~4 ~-22 minecraft:smooth_stone
fill ~-109 ~2 ~-28 ~-102 ~3 ~-28 minecraft:gray_stained_glass
fill ~-109 ~2 ~-21 ~-102 ~3 ~-21 minecraft:light_gray_stained_glass
fill ~-110 ~0 ~-28 ~-107 ~3 ~-28 minecraft:gray_concrete
setblock ~-109 ~1 ~-28 minecraft:iron_door[half=lower,facing=north]
setblock ~-109 ~2 ~-28 minecraft:iron_door[half=upper,facing=north]
fill ~-111 ~6 ~-28 ~-100 ~6 ~-21 minecraft:stone_brick_slab
# 050 office 11,-120 24,-109 h=10
fill ~11 ~-3 ~-120 ~24 ~-1 ~-109 minecraft:stone
fill ~11 ~0 ~-120 ~24 ~10 ~-109 minecraft:bricks
fill ~12 ~1 ~-119 ~23 ~9 ~-110 minecraft:air
fill ~12 ~4 ~-119 ~23 ~4 ~-110 minecraft:smooth_stone
fill ~12 ~8 ~-119 ~23 ~8 ~-110 minecraft:smooth_stone
fill ~11 ~2 ~-118 ~11 ~3 ~-111 minecraft:gray_stained_glass
fill ~24 ~2 ~-118 ~24 ~3 ~-111 minecraft:light_gray_stained_glass
fill ~11 ~6 ~-118 ~11 ~7 ~-111 minecraft:gray_stained_glass
fill ~24 ~6 ~-118 ~24 ~7 ~-111 minecraft:light_gray_stained_glass
fill ~12 ~0 ~-120 ~15 ~3 ~-120 minecraft:gray_concrete
setblock ~13 ~1 ~-120 minecraft:iron_door[half=lower,facing=north]
setblock ~13 ~2 ~-120 minecraft:iron_door[half=upper,facing=north]
fill ~11 ~11 ~-120 ~24 ~11 ~-109 minecraft:deepslate_tile_slab
