# Buildings 25..32
# 025 small_office style=civic_modern context=back_block facing=south
fill ~3 ~-3 ~-49 ~13 ~-1 ~-37 minecraft:stone
fill ~3 ~0 ~-49 ~13 ~24 ~-37 minecraft:bricks
fill ~4 ~1 ~-48 ~12 ~23 ~-38 minecraft:air
fill ~4 ~4 ~-48 ~12 ~4 ~-38 minecraft:smooth_stone
fill ~4 ~8 ~-48 ~12 ~8 ~-38 minecraft:smooth_stone
fill ~4 ~12 ~-48 ~12 ~12 ~-38 minecraft:smooth_stone
fill ~4 ~16 ~-48 ~12 ~16 ~-38 minecraft:smooth_stone
fill ~4 ~20 ~-48 ~12 ~20 ~-38 minecraft:smooth_stone
fill ~5 ~2 ~-49 ~5 ~3 ~-49 minecraft:gray_stained_glass
fill ~5 ~2 ~-37 ~5 ~3 ~-37 minecraft:light_gray_stained_glass
fill ~8 ~2 ~-49 ~8 ~3 ~-49 minecraft:gray_stained_glass
fill ~8 ~2 ~-37 ~8 ~3 ~-37 minecraft:light_gray_stained_glass
fill ~11 ~2 ~-49 ~11 ~3 ~-49 minecraft:gray_stained_glass
fill ~11 ~2 ~-37 ~11 ~3 ~-37 minecraft:light_gray_stained_glass
fill ~3 ~2 ~-47 ~3 ~3 ~-47 minecraft:gray_stained_glass
fill ~13 ~2 ~-47 ~13 ~3 ~-47 minecraft:light_gray_stained_glass
fill ~3 ~2 ~-44 ~3 ~3 ~-44 minecraft:gray_stained_glass
fill ~13 ~2 ~-44 ~13 ~3 ~-44 minecraft:light_gray_stained_glass
fill ~3 ~2 ~-41 ~3 ~3 ~-41 minecraft:gray_stained_glass
fill ~13 ~2 ~-41 ~13 ~3 ~-41 minecraft:light_gray_stained_glass
fill ~5 ~6 ~-49 ~5 ~7 ~-49 minecraft:gray_stained_glass
fill ~5 ~6 ~-37 ~5 ~7 ~-37 minecraft:light_gray_stained_glass
fill ~8 ~6 ~-49 ~8 ~7 ~-49 minecraft:gray_stained_glass
fill ~8 ~6 ~-37 ~8 ~7 ~-37 minecraft:light_gray_stained_glass
fill ~11 ~6 ~-49 ~11 ~7 ~-49 minecraft:gray_stained_glass
fill ~11 ~6 ~-37 ~11 ~7 ~-37 minecraft:light_gray_stained_glass
fill ~3 ~6 ~-47 ~3 ~7 ~-47 minecraft:gray_stained_glass
fill ~13 ~6 ~-47 ~13 ~7 ~-47 minecraft:light_gray_stained_glass
fill ~3 ~6 ~-44 ~3 ~7 ~-44 minecraft:gray_stained_glass
fill ~13 ~6 ~-44 ~13 ~7 ~-44 minecraft:light_gray_stained_glass
fill ~3 ~6 ~-41 ~3 ~7 ~-41 minecraft:gray_stained_glass
fill ~13 ~6 ~-41 ~13 ~7 ~-41 minecraft:light_gray_stained_glass
fill ~5 ~10 ~-49 ~5 ~11 ~-49 minecraft:gray_stained_glass
fill ~5 ~10 ~-37 ~5 ~11 ~-37 minecraft:light_gray_stained_glass
fill ~8 ~10 ~-49 ~8 ~11 ~-49 minecraft:gray_stained_glass
fill ~8 ~10 ~-37 ~8 ~11 ~-37 minecraft:light_gray_stained_glass
fill ~11 ~10 ~-49 ~11 ~11 ~-49 minecraft:gray_stained_glass
fill ~11 ~10 ~-37 ~11 ~11 ~-37 minecraft:light_gray_stained_glass
fill ~3 ~10 ~-47 ~3 ~11 ~-47 minecraft:gray_stained_glass
fill ~13 ~10 ~-47 ~13 ~11 ~-47 minecraft:light_gray_stained_glass
fill ~3 ~10 ~-44 ~3 ~11 ~-44 minecraft:gray_stained_glass
fill ~13 ~10 ~-44 ~13 ~11 ~-44 minecraft:light_gray_stained_glass
fill ~3 ~10 ~-41 ~3 ~11 ~-41 minecraft:gray_stained_glass
fill ~13 ~10 ~-41 ~13 ~11 ~-41 minecraft:light_gray_stained_glass
fill ~5 ~14 ~-49 ~5 ~15 ~-49 minecraft:gray_stained_glass
fill ~5 ~14 ~-37 ~5 ~15 ~-37 minecraft:light_gray_stained_glass
fill ~8 ~14 ~-49 ~8 ~15 ~-49 minecraft:gray_stained_glass
fill ~8 ~14 ~-37 ~8 ~15 ~-37 minecraft:light_gray_stained_glass
fill ~11 ~14 ~-49 ~11 ~15 ~-49 minecraft:gray_stained_glass
fill ~11 ~14 ~-37 ~11 ~15 ~-37 minecraft:light_gray_stained_glass
fill ~3 ~14 ~-47 ~3 ~15 ~-47 minecraft:gray_stained_glass
fill ~13 ~14 ~-47 ~13 ~15 ~-47 minecraft:light_gray_stained_glass
fill ~3 ~14 ~-44 ~3 ~15 ~-44 minecraft:gray_stained_glass
fill ~13 ~14 ~-44 ~13 ~15 ~-44 minecraft:light_gray_stained_glass
fill ~3 ~14 ~-41 ~3 ~15 ~-41 minecraft:gray_stained_glass
fill ~13 ~14 ~-41 ~13 ~15 ~-41 minecraft:light_gray_stained_glass
fill ~5 ~18 ~-49 ~5 ~19 ~-49 minecraft:gray_stained_glass
fill ~5 ~18 ~-37 ~5 ~19 ~-37 minecraft:light_gray_stained_glass
fill ~8 ~18 ~-49 ~8 ~19 ~-49 minecraft:gray_stained_glass
fill ~8 ~18 ~-37 ~8 ~19 ~-37 minecraft:light_gray_stained_glass
fill ~11 ~18 ~-49 ~11 ~19 ~-49 minecraft:gray_stained_glass
fill ~11 ~18 ~-37 ~11 ~19 ~-37 minecraft:light_gray_stained_glass
fill ~3 ~18 ~-47 ~3 ~19 ~-47 minecraft:gray_stained_glass
fill ~13 ~18 ~-47 ~13 ~19 ~-47 minecraft:light_gray_stained_glass
fill ~3 ~18 ~-44 ~3 ~19 ~-44 minecraft:gray_stained_glass
fill ~13 ~18 ~-44 ~13 ~19 ~-44 minecraft:light_gray_stained_glass
fill ~3 ~18 ~-41 ~3 ~19 ~-41 minecraft:gray_stained_glass
fill ~13 ~18 ~-41 ~13 ~19 ~-41 minecraft:light_gray_stained_glass
fill ~5 ~22 ~-49 ~5 ~23 ~-49 minecraft:gray_stained_glass
fill ~5 ~22 ~-37 ~5 ~23 ~-37 minecraft:light_gray_stained_glass
fill ~8 ~22 ~-49 ~8 ~23 ~-49 minecraft:gray_stained_glass
fill ~8 ~22 ~-37 ~8 ~23 ~-37 minecraft:light_gray_stained_glass
fill ~11 ~22 ~-49 ~11 ~23 ~-49 minecraft:gray_stained_glass
fill ~11 ~22 ~-37 ~11 ~23 ~-37 minecraft:light_gray_stained_glass
fill ~3 ~22 ~-47 ~3 ~23 ~-47 minecraft:gray_stained_glass
fill ~13 ~22 ~-47 ~13 ~23 ~-47 minecraft:light_gray_stained_glass
fill ~3 ~22 ~-44 ~3 ~23 ~-44 minecraft:gray_stained_glass
fill ~13 ~22 ~-44 ~13 ~23 ~-44 minecraft:light_gray_stained_glass
fill ~3 ~22 ~-41 ~3 ~23 ~-41 minecraft:gray_stained_glass
fill ~13 ~22 ~-41 ~13 ~23 ~-41 minecraft:light_gray_stained_glass
setblock ~8 ~1 ~-37 minecraft:iron_door[half=lower,facing=south]
setblock ~8 ~2 ~-37 minecraft:iron_door[half=upper,facing=south]
fill ~3 ~19 ~-49 ~13 ~24 ~-37 minecraft:air
fill ~4 ~19 ~-48 ~12 ~24 ~-38 minecraft:bricks
fill ~5 ~20 ~-47 ~11 ~23 ~-39 minecraft:air
fill ~4 ~25 ~-48 ~12 ~25 ~-38 minecraft:deepslate_tile_slab
# 026 workshop style=industrial_shed context=back_block facing=east
fill ~-71 ~-3 ~110 ~-65 ~-1 ~117 minecraft:stone
fill ~-71 ~0 ~110 ~-65 ~7 ~117 minecraft:calcite
fill ~-70 ~1 ~111 ~-66 ~6 ~116 minecraft:air
fill ~-70 ~4 ~111 ~-66 ~4 ~116 minecraft:smooth_stone
fill ~-69 ~2 ~110 ~-69 ~3 ~110 minecraft:gray_stained_glass
fill ~-69 ~2 ~117 ~-69 ~3 ~117 minecraft:light_gray_stained_glass
fill ~-71 ~2 ~112 ~-71 ~3 ~112 minecraft:gray_stained_glass
fill ~-65 ~2 ~112 ~-65 ~3 ~112 minecraft:light_gray_stained_glass
fill ~-71 ~2 ~115 ~-71 ~3 ~115 minecraft:gray_stained_glass
fill ~-65 ~2 ~115 ~-65 ~3 ~115 minecraft:light_gray_stained_glass
setblock ~-65 ~1 ~113 minecraft:iron_door[half=lower,facing=east]
setblock ~-65 ~2 ~113 minecraft:iron_door[half=upper,facing=east]
fill ~-65 ~1 ~112 ~-65 ~4 ~115 minecraft:polished_blackstone
fill ~-65 ~5 ~112 ~-65 ~5 ~115 minecraft:light_blue_stained_glass
fill ~-69 ~9 ~112 ~-67 ~10 ~114 minecraft:iron_block
fill ~-71 ~8 ~110 ~-65 ~8 ~117 minecraft:stone_brick_slab
# 027 workshop style=industrial_shed context=local_front facing=east
fill ~17 ~-3 ~-58 ~25 ~-1 ~-45 minecraft:stone
fill ~17 ~0 ~-58 ~25 ~10 ~-45 minecraft:light_gray_concrete
fill ~18 ~1 ~-57 ~24 ~9 ~-46 minecraft:air
fill ~18 ~4 ~-57 ~24 ~4 ~-46 minecraft:smooth_stone
fill ~18 ~8 ~-57 ~24 ~8 ~-46 minecraft:smooth_stone
fill ~19 ~2 ~-58 ~19 ~3 ~-58 minecraft:gray_stained_glass
fill ~19 ~2 ~-45 ~19 ~3 ~-45 minecraft:light_gray_stained_glass
fill ~22 ~2 ~-58 ~22 ~3 ~-58 minecraft:gray_stained_glass
fill ~22 ~2 ~-45 ~22 ~3 ~-45 minecraft:light_gray_stained_glass
fill ~17 ~2 ~-56 ~17 ~3 ~-56 minecraft:gray_stained_glass
fill ~25 ~2 ~-56 ~25 ~3 ~-56 minecraft:light_gray_stained_glass
fill ~17 ~2 ~-53 ~17 ~3 ~-53 minecraft:gray_stained_glass
fill ~25 ~2 ~-53 ~25 ~3 ~-53 minecraft:light_gray_stained_glass
fill ~17 ~2 ~-50 ~17 ~3 ~-50 minecraft:gray_stained_glass
fill ~25 ~2 ~-50 ~25 ~3 ~-50 minecraft:light_gray_stained_glass
fill ~17 ~2 ~-47 ~17 ~3 ~-47 minecraft:gray_stained_glass
fill ~25 ~2 ~-47 ~25 ~3 ~-47 minecraft:light_gray_stained_glass
fill ~19 ~6 ~-58 ~19 ~7 ~-58 minecraft:gray_stained_glass
fill ~19 ~6 ~-45 ~19 ~7 ~-45 minecraft:light_gray_stained_glass
fill ~22 ~6 ~-58 ~22 ~7 ~-58 minecraft:gray_stained_glass
fill ~22 ~6 ~-45 ~22 ~7 ~-45 minecraft:light_gray_stained_glass
fill ~17 ~6 ~-56 ~17 ~7 ~-56 minecraft:gray_stained_glass
fill ~25 ~6 ~-56 ~25 ~7 ~-56 minecraft:light_gray_stained_glass
fill ~17 ~6 ~-53 ~17 ~7 ~-53 minecraft:gray_stained_glass
fill ~25 ~6 ~-53 ~25 ~7 ~-53 minecraft:light_gray_stained_glass
fill ~17 ~6 ~-50 ~17 ~7 ~-50 minecraft:gray_stained_glass
fill ~25 ~6 ~-50 ~25 ~7 ~-50 minecraft:light_gray_stained_glass
fill ~17 ~6 ~-47 ~17 ~7 ~-47 minecraft:gray_stained_glass
fill ~25 ~6 ~-47 ~25 ~7 ~-47 minecraft:light_gray_stained_glass
setblock ~25 ~1 ~-53 minecraft:iron_door[half=lower,facing=east]
setblock ~25 ~2 ~-53 minecraft:iron_door[half=upper,facing=east]
fill ~25 ~1 ~-56 ~25 ~4 ~-47 minecraft:polished_blackstone
fill ~25 ~5 ~-56 ~25 ~5 ~-47 minecraft:light_blue_stained_glass
fill ~19 ~12 ~-56 ~21 ~13 ~-54 minecraft:iron_block
fill ~17 ~11 ~-58 ~25 ~11 ~-45 minecraft:smooth_stone_slab
fill ~19 ~12 ~-56 ~21 ~13 ~-54 minecraft:light_gray_concrete
setblock ~22 ~12 ~-55 minecraft:lightning_rod
# 028 row_house style=stepped_house context=back_block facing=north
fill ~-123 ~-3 ~-24 ~-117 ~-1 ~-14 minecraft:stone
fill ~-123 ~0 ~-24 ~-117 ~9 ~-14 minecraft:mud_bricks
fill ~-122 ~1 ~-23 ~-118 ~8 ~-15 minecraft:air
fill ~-122 ~4 ~-23 ~-118 ~4 ~-15 minecraft:smooth_stone
fill ~-122 ~8 ~-23 ~-118 ~8 ~-15 minecraft:smooth_stone
fill ~-121 ~2 ~-24 ~-121 ~3 ~-24 minecraft:gray_stained_glass
fill ~-121 ~2 ~-14 ~-121 ~3 ~-14 minecraft:light_gray_stained_glass
fill ~-123 ~2 ~-22 ~-123 ~3 ~-22 minecraft:gray_stained_glass
fill ~-117 ~2 ~-22 ~-117 ~3 ~-22 minecraft:light_gray_stained_glass
fill ~-123 ~2 ~-19 ~-123 ~3 ~-19 minecraft:gray_stained_glass
fill ~-117 ~2 ~-19 ~-117 ~3 ~-19 minecraft:light_gray_stained_glass
fill ~-123 ~2 ~-16 ~-123 ~3 ~-16 minecraft:gray_stained_glass
fill ~-117 ~2 ~-16 ~-117 ~3 ~-16 minecraft:light_gray_stained_glass
fill ~-121 ~6 ~-24 ~-121 ~7 ~-24 minecraft:gray_stained_glass
fill ~-121 ~6 ~-14 ~-121 ~7 ~-14 minecraft:light_gray_stained_glass
fill ~-123 ~6 ~-22 ~-123 ~7 ~-22 minecraft:gray_stained_glass
fill ~-117 ~6 ~-22 ~-117 ~7 ~-22 minecraft:light_gray_stained_glass
fill ~-123 ~6 ~-19 ~-123 ~7 ~-19 minecraft:gray_stained_glass
fill ~-117 ~6 ~-19 ~-117 ~7 ~-19 minecraft:light_gray_stained_glass
fill ~-123 ~6 ~-16 ~-123 ~7 ~-16 minecraft:gray_stained_glass
fill ~-117 ~6 ~-16 ~-117 ~7 ~-16 minecraft:light_gray_stained_glass
setblock ~-120 ~1 ~-24 minecraft:iron_door[half=lower,facing=north]
setblock ~-120 ~2 ~-24 minecraft:iron_door[half=upper,facing=north]
fill ~-123 ~10 ~-24 ~-117 ~10 ~-14 minecraft:deepslate_tile_slab
fill ~-122 ~11 ~-23 ~-118 ~11 ~-15 minecraft:deepslate_tile_slab
setblock ~-120 ~3 ~-25 minecraft:dark_oak_slab[type=top]
# 029 large_retail style=corner_store context=arterial_front facing=north
fill ~41 ~-3 ~92 ~51 ~-1 ~102 minecraft:stone
fill ~41 ~0 ~92 ~51 ~7 ~102 minecraft:white_terracotta
fill ~42 ~1 ~93 ~50 ~6 ~101 minecraft:air
fill ~42 ~4 ~93 ~50 ~4 ~101 minecraft:smooth_stone
fill ~43 ~2 ~92 ~43 ~3 ~92 minecraft:gray_stained_glass
fill ~43 ~2 ~102 ~43 ~3 ~102 minecraft:light_gray_stained_glass
fill ~46 ~2 ~92 ~46 ~3 ~92 minecraft:gray_stained_glass
fill ~46 ~2 ~102 ~46 ~3 ~102 minecraft:light_gray_stained_glass
fill ~49 ~2 ~92 ~49 ~3 ~92 minecraft:gray_stained_glass
fill ~49 ~2 ~102 ~49 ~3 ~102 minecraft:light_gray_stained_glass
fill ~41 ~2 ~94 ~41 ~3 ~94 minecraft:gray_stained_glass
fill ~51 ~2 ~94 ~51 ~3 ~94 minecraft:light_gray_stained_glass
fill ~41 ~2 ~97 ~41 ~3 ~97 minecraft:gray_stained_glass
fill ~51 ~2 ~97 ~51 ~3 ~97 minecraft:light_gray_stained_glass
fill ~41 ~2 ~100 ~41 ~3 ~100 minecraft:gray_stained_glass
fill ~51 ~2 ~100 ~51 ~3 ~100 minecraft:light_gray_stained_glass
setblock ~46 ~1 ~92 minecraft:iron_door[half=lower,facing=north]
setblock ~46 ~2 ~92 minecraft:iron_door[half=upper,facing=north]
fill ~42 ~1 ~92 ~50 ~3 ~92 minecraft:cyan_stained_glass
setblock ~46 ~1 ~92 minecraft:iron_door[half=lower,facing=north]
setblock ~46 ~2 ~92 minecraft:iron_door[half=upper,facing=north]
setblock ~46 ~3 ~91 minecraft:red_wool
fill ~41 ~8 ~92 ~51 ~8 ~102 minecraft:dark_oak_slab
# 030 lowrise_housing style=rowhouse context=back_block facing=north
fill ~80 ~-3 ~-61 ~86 ~-1 ~-55 minecraft:stone
fill ~80 ~0 ~-61 ~86 ~7 ~-55 minecraft:mud_bricks
fill ~81 ~1 ~-60 ~85 ~6 ~-56 minecraft:air
fill ~81 ~4 ~-60 ~85 ~4 ~-56 minecraft:smooth_stone
fill ~82 ~2 ~-61 ~82 ~3 ~-61 minecraft:gray_stained_glass
fill ~82 ~2 ~-55 ~82 ~3 ~-55 minecraft:light_gray_stained_glass
fill ~80 ~2 ~-59 ~80 ~3 ~-59 minecraft:gray_stained_glass
fill ~86 ~2 ~-59 ~86 ~3 ~-59 minecraft:light_gray_stained_glass
setblock ~83 ~1 ~-61 minecraft:iron_door[half=lower,facing=north]
setblock ~83 ~2 ~-61 minecraft:iron_door[half=upper,facing=north]
fill ~80 ~8 ~-61 ~86 ~8 ~-55 minecraft:deepslate_tile_slab
fill ~81 ~9 ~-60 ~85 ~9 ~-56 minecraft:deepslate_tile_slab
setblock ~83 ~3 ~-62 minecraft:dark_oak_slab[type=top]
# 031 detached_house style=japanese_house context=local_front facing=north
fill ~-124 ~-3 ~31 ~-117 ~-1 ~42 minecraft:stone
fill ~-124 ~0 ~31 ~-117 ~7 ~42 minecraft:white_terracotta
fill ~-123 ~1 ~32 ~-118 ~6 ~41 minecraft:air
fill ~-123 ~4 ~32 ~-118 ~4 ~41 minecraft:smooth_stone
fill ~-122 ~2 ~31 ~-122 ~3 ~31 minecraft:gray_stained_glass
fill ~-122 ~2 ~42 ~-122 ~3 ~42 minecraft:light_gray_stained_glass
fill ~-119 ~2 ~31 ~-119 ~3 ~31 minecraft:gray_stained_glass
fill ~-119 ~2 ~42 ~-119 ~3 ~42 minecraft:light_gray_stained_glass
fill ~-124 ~2 ~33 ~-124 ~3 ~33 minecraft:gray_stained_glass
fill ~-117 ~2 ~33 ~-117 ~3 ~33 minecraft:light_gray_stained_glass
fill ~-124 ~2 ~36 ~-124 ~3 ~36 minecraft:gray_stained_glass
fill ~-117 ~2 ~36 ~-117 ~3 ~36 minecraft:light_gray_stained_glass
fill ~-124 ~2 ~39 ~-124 ~3 ~39 minecraft:gray_stained_glass
fill ~-117 ~2 ~39 ~-117 ~3 ~39 minecraft:light_gray_stained_glass
setblock ~-121 ~1 ~31 minecraft:iron_door[half=lower,facing=north]
setblock ~-121 ~2 ~31 minecraft:iron_door[half=upper,facing=north]
fill ~-124 ~8 ~31 ~-117 ~8 ~42 minecraft:dark_oak_slab
fill ~-123 ~9 ~32 ~-118 ~9 ~41 minecraft:dark_oak_slab
setblock ~-121 ~3 ~30 minecraft:dark_oak_slab[type=top]
# 032 small_office style=bay_office context=back_block facing=south
fill ~-19 ~-3 ~71 ~-10 ~-1 ~80 minecraft:stone
fill ~-19 ~0 ~71 ~-10 ~12 ~80 minecraft:bricks
fill ~-18 ~1 ~72 ~-11 ~11 ~79 minecraft:air
fill ~-18 ~4 ~72 ~-11 ~4 ~79 minecraft:smooth_stone
fill ~-18 ~8 ~72 ~-11 ~8 ~79 minecraft:smooth_stone
fill ~-17 ~2 ~71 ~-17 ~3 ~71 minecraft:gray_stained_glass
fill ~-17 ~2 ~80 ~-17 ~3 ~80 minecraft:light_gray_stained_glass
fill ~-14 ~2 ~71 ~-14 ~3 ~71 minecraft:gray_stained_glass
fill ~-14 ~2 ~80 ~-14 ~3 ~80 minecraft:light_gray_stained_glass
fill ~-19 ~2 ~73 ~-19 ~3 ~73 minecraft:gray_stained_glass
fill ~-10 ~2 ~73 ~-10 ~3 ~73 minecraft:light_gray_stained_glass
fill ~-19 ~2 ~76 ~-19 ~3 ~76 minecraft:gray_stained_glass
fill ~-10 ~2 ~76 ~-10 ~3 ~76 minecraft:light_gray_stained_glass
fill ~-17 ~6 ~71 ~-17 ~7 ~71 minecraft:gray_stained_glass
fill ~-17 ~6 ~80 ~-17 ~7 ~80 minecraft:light_gray_stained_glass
fill ~-14 ~6 ~71 ~-14 ~7 ~71 minecraft:gray_stained_glass
fill ~-14 ~6 ~80 ~-14 ~7 ~80 minecraft:light_gray_stained_glass
fill ~-19 ~6 ~73 ~-19 ~7 ~73 minecraft:gray_stained_glass
fill ~-10 ~6 ~73 ~-10 ~7 ~73 minecraft:light_gray_stained_glass
fill ~-19 ~6 ~76 ~-19 ~7 ~76 minecraft:gray_stained_glass
fill ~-10 ~6 ~76 ~-10 ~7 ~76 minecraft:light_gray_stained_glass
fill ~-17 ~10 ~71 ~-17 ~11 ~71 minecraft:gray_stained_glass
fill ~-17 ~10 ~80 ~-17 ~11 ~80 minecraft:light_gray_stained_glass
fill ~-14 ~10 ~71 ~-14 ~11 ~71 minecraft:gray_stained_glass
fill ~-14 ~10 ~80 ~-14 ~11 ~80 minecraft:light_gray_stained_glass
fill ~-19 ~10 ~73 ~-19 ~11 ~73 minecraft:gray_stained_glass
fill ~-10 ~10 ~73 ~-10 ~11 ~73 minecraft:light_gray_stained_glass
fill ~-19 ~10 ~76 ~-19 ~11 ~76 minecraft:gray_stained_glass
fill ~-10 ~10 ~76 ~-10 ~11 ~76 minecraft:light_gray_stained_glass
setblock ~-15 ~1 ~80 minecraft:iron_door[half=lower,facing=south]
setblock ~-15 ~2 ~80 minecraft:iron_door[half=upper,facing=south]
fill ~-19 ~7 ~71 ~-10 ~12 ~80 minecraft:air
fill ~-18 ~7 ~72 ~-11 ~12 ~79 minecraft:bricks
fill ~-17 ~8 ~73 ~-12 ~11 ~78 minecraft:air
fill ~-18 ~13 ~72 ~-11 ~13 ~79 minecraft:deepslate_tile_slab
fill ~-17 ~2 ~80 ~-12 ~7 ~80 minecraft:blue_stained_glass
fill ~-12 ~10 ~78 ~-10 ~14 ~80 minecraft:air
setblock ~-12 ~10 ~78 minecraft:cobweb
