# Buildings 49..56
# 049 supermarket style=arcade_shop context=collector_front facing=east
fill ~7 ~-3 ~9 ~15 ~-1 ~20 minecraft:stone
fill ~7 ~0 ~9 ~15 ~20 ~20 minecraft:bricks
fill ~8 ~1 ~10 ~14 ~19 ~19 minecraft:air
fill ~8 ~4 ~10 ~14 ~4 ~19 minecraft:smooth_stone
fill ~8 ~8 ~10 ~14 ~8 ~19 minecraft:smooth_stone
fill ~8 ~12 ~10 ~14 ~12 ~19 minecraft:smooth_stone
fill ~8 ~16 ~10 ~14 ~16 ~19 minecraft:smooth_stone
fill ~9 ~2 ~9 ~9 ~3 ~9 minecraft:gray_stained_glass
fill ~9 ~2 ~20 ~9 ~3 ~20 minecraft:light_gray_stained_glass
fill ~12 ~2 ~9 ~12 ~3 ~9 minecraft:gray_stained_glass
fill ~12 ~2 ~20 ~12 ~3 ~20 minecraft:light_gray_stained_glass
fill ~7 ~2 ~11 ~7 ~3 ~11 minecraft:gray_stained_glass
fill ~15 ~2 ~11 ~15 ~3 ~11 minecraft:light_gray_stained_glass
fill ~7 ~2 ~14 ~7 ~3 ~14 minecraft:gray_stained_glass
fill ~15 ~2 ~14 ~15 ~3 ~14 minecraft:light_gray_stained_glass
fill ~7 ~2 ~17 ~7 ~3 ~17 minecraft:gray_stained_glass
fill ~15 ~2 ~17 ~15 ~3 ~17 minecraft:light_gray_stained_glass
fill ~9 ~6 ~9 ~9 ~7 ~9 minecraft:gray_stained_glass
fill ~9 ~6 ~20 ~9 ~7 ~20 minecraft:light_gray_stained_glass
fill ~12 ~6 ~9 ~12 ~7 ~9 minecraft:gray_stained_glass
fill ~12 ~6 ~20 ~12 ~7 ~20 minecraft:light_gray_stained_glass
fill ~7 ~6 ~11 ~7 ~7 ~11 minecraft:gray_stained_glass
fill ~15 ~6 ~11 ~15 ~7 ~11 minecraft:light_gray_stained_glass
fill ~7 ~6 ~14 ~7 ~7 ~14 minecraft:gray_stained_glass
fill ~15 ~6 ~14 ~15 ~7 ~14 minecraft:light_gray_stained_glass
fill ~7 ~6 ~17 ~7 ~7 ~17 minecraft:gray_stained_glass
fill ~15 ~6 ~17 ~15 ~7 ~17 minecraft:light_gray_stained_glass
fill ~9 ~10 ~9 ~9 ~11 ~9 minecraft:gray_stained_glass
fill ~9 ~10 ~20 ~9 ~11 ~20 minecraft:light_gray_stained_glass
fill ~12 ~10 ~9 ~12 ~11 ~9 minecraft:gray_stained_glass
fill ~12 ~10 ~20 ~12 ~11 ~20 minecraft:light_gray_stained_glass
fill ~7 ~10 ~11 ~7 ~11 ~11 minecraft:gray_stained_glass
fill ~15 ~10 ~11 ~15 ~11 ~11 minecraft:light_gray_stained_glass
fill ~7 ~10 ~14 ~7 ~11 ~14 minecraft:gray_stained_glass
fill ~15 ~10 ~14 ~15 ~11 ~14 minecraft:light_gray_stained_glass
fill ~7 ~10 ~17 ~7 ~11 ~17 minecraft:gray_stained_glass
fill ~15 ~10 ~17 ~15 ~11 ~17 minecraft:light_gray_stained_glass
fill ~9 ~14 ~9 ~9 ~15 ~9 minecraft:gray_stained_glass
fill ~9 ~14 ~20 ~9 ~15 ~20 minecraft:light_gray_stained_glass
fill ~12 ~14 ~9 ~12 ~15 ~9 minecraft:gray_stained_glass
fill ~12 ~14 ~20 ~12 ~15 ~20 minecraft:light_gray_stained_glass
fill ~7 ~14 ~11 ~7 ~15 ~11 minecraft:gray_stained_glass
fill ~15 ~14 ~11 ~15 ~15 ~11 minecraft:light_gray_stained_glass
fill ~7 ~14 ~14 ~7 ~15 ~14 minecraft:gray_stained_glass
fill ~15 ~14 ~14 ~15 ~15 ~14 minecraft:light_gray_stained_glass
fill ~7 ~14 ~17 ~7 ~15 ~17 minecraft:gray_stained_glass
fill ~15 ~14 ~17 ~15 ~15 ~17 minecraft:light_gray_stained_glass
fill ~9 ~18 ~9 ~9 ~19 ~9 minecraft:gray_stained_glass
fill ~9 ~18 ~20 ~9 ~19 ~20 minecraft:light_gray_stained_glass
fill ~12 ~18 ~9 ~12 ~19 ~9 minecraft:gray_stained_glass
fill ~12 ~18 ~20 ~12 ~19 ~20 minecraft:light_gray_stained_glass
fill ~7 ~18 ~11 ~7 ~19 ~11 minecraft:gray_stained_glass
fill ~15 ~18 ~11 ~15 ~19 ~11 minecraft:light_gray_stained_glass
fill ~7 ~18 ~14 ~7 ~19 ~14 minecraft:gray_stained_glass
fill ~15 ~18 ~14 ~15 ~19 ~14 minecraft:light_gray_stained_glass
fill ~7 ~18 ~17 ~7 ~19 ~17 minecraft:gray_stained_glass
fill ~15 ~18 ~17 ~15 ~19 ~17 minecraft:light_gray_stained_glass
setblock ~15 ~1 ~14 minecraft:iron_door[half=lower,facing=east]
setblock ~15 ~2 ~14 minecraft:iron_door[half=upper,facing=east]
fill ~15 ~1 ~10 ~15 ~3 ~19 minecraft:cyan_stained_glass
setblock ~15 ~1 ~14 minecraft:iron_door[half=lower,facing=east]
setblock ~15 ~2 ~14 minecraft:iron_door[half=upper,facing=east]
setblock ~16 ~3 ~14 minecraft:red_wool
fill ~15 ~4 ~10 ~15 ~4 ~19 doomsday_decoration:redbrick
fill ~7 ~21 ~9 ~15 ~21 ~20 minecraft:deepslate_tile_slab
fill ~15 ~1 ~10 ~15 ~7 ~10 doomsday_decoration:redbrick
fill ~15 ~1 ~14 ~15 ~7 ~14 doomsday_decoration:redbrick
fill ~15 ~1 ~18 ~15 ~7 ~18 doomsday_decoration:redbrick
# 050 shop_house style=corner_store context=collector_front facing=east
fill ~19 ~-3 ~-27 ~28 ~-1 ~-13 minecraft:stone
fill ~19 ~0 ~-27 ~28 ~12 ~-13 minecraft:white_terracotta
fill ~20 ~1 ~-26 ~27 ~11 ~-14 minecraft:air
fill ~20 ~4 ~-26 ~27 ~4 ~-14 minecraft:smooth_stone
fill ~20 ~8 ~-26 ~27 ~8 ~-14 minecraft:smooth_stone
fill ~21 ~2 ~-27 ~21 ~3 ~-27 minecraft:gray_stained_glass
fill ~21 ~2 ~-13 ~21 ~3 ~-13 minecraft:light_gray_stained_glass
fill ~24 ~2 ~-27 ~24 ~3 ~-27 minecraft:gray_stained_glass
fill ~24 ~2 ~-13 ~24 ~3 ~-13 minecraft:light_gray_stained_glass
fill ~19 ~2 ~-25 ~19 ~3 ~-25 minecraft:gray_stained_glass
fill ~28 ~2 ~-25 ~28 ~3 ~-25 minecraft:light_gray_stained_glass
fill ~19 ~2 ~-22 ~19 ~3 ~-22 minecraft:gray_stained_glass
fill ~28 ~2 ~-22 ~28 ~3 ~-22 minecraft:light_gray_stained_glass
fill ~19 ~2 ~-19 ~19 ~3 ~-19 minecraft:gray_stained_glass
fill ~28 ~2 ~-19 ~28 ~3 ~-19 minecraft:light_gray_stained_glass
fill ~19 ~2 ~-16 ~19 ~3 ~-16 minecraft:gray_stained_glass
fill ~28 ~2 ~-16 ~28 ~3 ~-16 minecraft:light_gray_stained_glass
fill ~21 ~6 ~-27 ~21 ~7 ~-27 minecraft:gray_stained_glass
fill ~21 ~6 ~-13 ~21 ~7 ~-13 minecraft:light_gray_stained_glass
fill ~24 ~6 ~-27 ~24 ~7 ~-27 minecraft:gray_stained_glass
fill ~24 ~6 ~-13 ~24 ~7 ~-13 minecraft:light_gray_stained_glass
fill ~19 ~6 ~-25 ~19 ~7 ~-25 minecraft:gray_stained_glass
fill ~28 ~6 ~-25 ~28 ~7 ~-25 minecraft:light_gray_stained_glass
fill ~19 ~6 ~-22 ~19 ~7 ~-22 minecraft:gray_stained_glass
fill ~28 ~6 ~-22 ~28 ~7 ~-22 minecraft:light_gray_stained_glass
fill ~19 ~6 ~-19 ~19 ~7 ~-19 minecraft:gray_stained_glass
fill ~28 ~6 ~-19 ~28 ~7 ~-19 minecraft:light_gray_stained_glass
fill ~19 ~6 ~-16 ~19 ~7 ~-16 minecraft:gray_stained_glass
fill ~28 ~6 ~-16 ~28 ~7 ~-16 minecraft:light_gray_stained_glass
fill ~21 ~10 ~-27 ~21 ~11 ~-27 minecraft:gray_stained_glass
fill ~21 ~10 ~-13 ~21 ~11 ~-13 minecraft:light_gray_stained_glass
fill ~24 ~10 ~-27 ~24 ~11 ~-27 minecraft:gray_stained_glass
fill ~24 ~10 ~-13 ~24 ~11 ~-13 minecraft:light_gray_stained_glass
fill ~19 ~10 ~-25 ~19 ~11 ~-25 minecraft:gray_stained_glass
fill ~28 ~10 ~-25 ~28 ~11 ~-25 minecraft:light_gray_stained_glass
fill ~19 ~10 ~-22 ~19 ~11 ~-22 minecraft:gray_stained_glass
fill ~28 ~10 ~-22 ~28 ~11 ~-22 minecraft:light_gray_stained_glass
fill ~19 ~10 ~-19 ~19 ~11 ~-19 minecraft:gray_stained_glass
fill ~28 ~10 ~-19 ~28 ~11 ~-19 minecraft:light_gray_stained_glass
fill ~19 ~10 ~-16 ~19 ~11 ~-16 minecraft:gray_stained_glass
fill ~28 ~10 ~-16 ~28 ~11 ~-16 minecraft:light_gray_stained_glass
setblock ~28 ~1 ~-22 minecraft:iron_door[half=lower,facing=east]
setblock ~28 ~2 ~-22 minecraft:iron_door[half=upper,facing=east]
fill ~28 ~1 ~-26 ~28 ~3 ~-14 minecraft:cyan_stained_glass
setblock ~28 ~1 ~-22 minecraft:iron_door[half=lower,facing=east]
setblock ~28 ~2 ~-22 minecraft:iron_door[half=upper,facing=east]
setblock ~29 ~3 ~-22 minecraft:red_wool
fill ~19 ~13 ~-27 ~28 ~13 ~-13 minecraft:stone_brick_slab
fill ~28 ~1 ~-26 ~28 ~7 ~-26 minecraft:gray_concrete
fill ~28 ~1 ~-22 ~28 ~7 ~-22 minecraft:gray_concrete
fill ~28 ~1 ~-18 ~28 ~7 ~-18 minecraft:gray_concrete
fill ~28 ~1 ~-14 ~28 ~7 ~-14 minecraft:gray_concrete
fill ~20 ~6 ~-26 ~27 ~12 ~-14 minecraft:white_terracotta
fill ~21 ~7 ~-25 ~26 ~11 ~-15 minecraft:air
setblock ~28 ~3 ~-25 minecraft:red_carpet
setblock ~28 ~3 ~-20 minecraft:red_carpet
setblock ~28 ~3 ~-15 minecraft:red_carpet
# 051 clinic style=mixed_facade context=collector_front facing=south
fill ~-28 ~-3 ~-85 ~-18 ~-1 ~-76 minecraft:stone
fill ~-28 ~0 ~-85 ~-18 ~8 ~-76 minecraft:light_gray_concrete
fill ~-27 ~1 ~-84 ~-19 ~7 ~-77 minecraft:air
fill ~-27 ~4 ~-84 ~-19 ~4 ~-77 minecraft:smooth_stone
fill ~-26 ~2 ~-85 ~-26 ~3 ~-85 minecraft:gray_stained_glass
fill ~-26 ~2 ~-76 ~-26 ~3 ~-76 minecraft:light_gray_stained_glass
fill ~-23 ~2 ~-85 ~-23 ~3 ~-85 minecraft:gray_stained_glass
fill ~-23 ~2 ~-76 ~-23 ~3 ~-76 minecraft:light_gray_stained_glass
fill ~-20 ~2 ~-85 ~-20 ~3 ~-85 minecraft:gray_stained_glass
fill ~-20 ~2 ~-76 ~-20 ~3 ~-76 minecraft:light_gray_stained_glass
fill ~-28 ~2 ~-83 ~-28 ~3 ~-83 minecraft:gray_stained_glass
fill ~-18 ~2 ~-83 ~-18 ~3 ~-83 minecraft:light_gray_stained_glass
fill ~-28 ~2 ~-80 ~-28 ~3 ~-80 minecraft:gray_stained_glass
fill ~-18 ~2 ~-80 ~-18 ~3 ~-80 minecraft:light_gray_stained_glass
fill ~-26 ~6 ~-85 ~-26 ~7 ~-85 minecraft:gray_stained_glass
fill ~-26 ~6 ~-76 ~-26 ~7 ~-76 minecraft:light_gray_stained_glass
fill ~-23 ~6 ~-85 ~-23 ~7 ~-85 minecraft:gray_stained_glass
fill ~-23 ~6 ~-76 ~-23 ~7 ~-76 minecraft:light_gray_stained_glass
fill ~-20 ~6 ~-85 ~-20 ~7 ~-85 minecraft:gray_stained_glass
fill ~-20 ~6 ~-76 ~-20 ~7 ~-76 minecraft:light_gray_stained_glass
fill ~-28 ~6 ~-83 ~-28 ~7 ~-83 minecraft:gray_stained_glass
fill ~-18 ~6 ~-83 ~-18 ~7 ~-83 minecraft:light_gray_stained_glass
fill ~-28 ~6 ~-80 ~-28 ~7 ~-80 minecraft:gray_stained_glass
fill ~-18 ~6 ~-80 ~-18 ~7 ~-80 minecraft:light_gray_stained_glass
setblock ~-23 ~1 ~-76 minecraft:iron_door[half=lower,facing=south]
setblock ~-23 ~2 ~-76 minecraft:iron_door[half=upper,facing=south]
fill ~-28 ~9 ~-85 ~-18 ~9 ~-76 minecraft:smooth_stone_slab
fill ~-26 ~10 ~-83 ~-24 ~11 ~-81 minecraft:light_gray_concrete
setblock ~-23 ~10 ~-82 minecraft:lightning_rod
fill ~-27 ~1 ~-76 ~-27 ~7 ~-76 doomsday_decoration:porcelainbrickwall
fill ~-23 ~1 ~-76 ~-23 ~7 ~-76 doomsday_decoration:porcelainbrickwall
fill ~-19 ~1 ~-76 ~-19 ~7 ~-76 doomsday_decoration:porcelainbrickwall
# 052 medical_center style=bay_office context=arterial_front facing=west
fill ~-31 ~-3 ~-22 ~-16 ~-1 ~-10 minecraft:stone
fill ~-31 ~0 ~-22 ~-16 ~12 ~-10 minecraft:white_terracotta
fill ~-30 ~1 ~-21 ~-17 ~11 ~-11 minecraft:air
fill ~-30 ~4 ~-21 ~-17 ~4 ~-11 minecraft:smooth_stone
fill ~-30 ~8 ~-21 ~-17 ~8 ~-11 minecraft:smooth_stone
fill ~-29 ~2 ~-22 ~-29 ~3 ~-22 minecraft:gray_stained_glass
fill ~-29 ~2 ~-10 ~-29 ~3 ~-10 minecraft:light_gray_stained_glass
fill ~-26 ~2 ~-22 ~-26 ~3 ~-22 minecraft:gray_stained_glass
fill ~-26 ~2 ~-10 ~-26 ~3 ~-10 minecraft:light_gray_stained_glass
fill ~-23 ~2 ~-22 ~-23 ~3 ~-22 minecraft:gray_stained_glass
fill ~-23 ~2 ~-10 ~-23 ~3 ~-10 minecraft:light_gray_stained_glass
fill ~-20 ~2 ~-22 ~-20 ~3 ~-22 minecraft:gray_stained_glass
fill ~-20 ~2 ~-10 ~-20 ~3 ~-10 minecraft:light_gray_stained_glass
fill ~-31 ~2 ~-20 ~-31 ~3 ~-20 minecraft:gray_stained_glass
fill ~-16 ~2 ~-20 ~-16 ~3 ~-20 minecraft:light_gray_stained_glass
fill ~-31 ~2 ~-17 ~-31 ~3 ~-17 minecraft:gray_stained_glass
fill ~-16 ~2 ~-17 ~-16 ~3 ~-17 minecraft:light_gray_stained_glass
fill ~-31 ~2 ~-14 ~-31 ~3 ~-14 minecraft:gray_stained_glass
fill ~-16 ~2 ~-14 ~-16 ~3 ~-14 minecraft:light_gray_stained_glass
fill ~-29 ~6 ~-22 ~-29 ~7 ~-22 minecraft:gray_stained_glass
fill ~-29 ~6 ~-10 ~-29 ~7 ~-10 minecraft:light_gray_stained_glass
fill ~-26 ~6 ~-22 ~-26 ~7 ~-22 minecraft:gray_stained_glass
fill ~-26 ~6 ~-10 ~-26 ~7 ~-10 minecraft:light_gray_stained_glass
fill ~-23 ~6 ~-22 ~-23 ~7 ~-22 minecraft:gray_stained_glass
fill ~-23 ~6 ~-10 ~-23 ~7 ~-10 minecraft:light_gray_stained_glass
fill ~-20 ~6 ~-22 ~-20 ~7 ~-22 minecraft:gray_stained_glass
fill ~-20 ~6 ~-10 ~-20 ~7 ~-10 minecraft:light_gray_stained_glass
fill ~-31 ~6 ~-20 ~-31 ~7 ~-20 minecraft:gray_stained_glass
fill ~-16 ~6 ~-20 ~-16 ~7 ~-20 minecraft:light_gray_stained_glass
fill ~-31 ~6 ~-17 ~-31 ~7 ~-17 minecraft:gray_stained_glass
fill ~-16 ~6 ~-17 ~-16 ~7 ~-17 minecraft:light_gray_stained_glass
fill ~-31 ~6 ~-14 ~-31 ~7 ~-14 minecraft:gray_stained_glass
fill ~-16 ~6 ~-14 ~-16 ~7 ~-14 minecraft:light_gray_stained_glass
fill ~-29 ~10 ~-22 ~-29 ~11 ~-22 minecraft:gray_stained_glass
fill ~-29 ~10 ~-10 ~-29 ~11 ~-10 minecraft:light_gray_stained_glass
fill ~-26 ~10 ~-22 ~-26 ~11 ~-22 minecraft:gray_stained_glass
fill ~-26 ~10 ~-10 ~-26 ~11 ~-10 minecraft:light_gray_stained_glass
fill ~-23 ~10 ~-22 ~-23 ~11 ~-22 minecraft:gray_stained_glass
fill ~-23 ~10 ~-10 ~-23 ~11 ~-10 minecraft:light_gray_stained_glass
fill ~-20 ~10 ~-22 ~-20 ~11 ~-22 minecraft:gray_stained_glass
fill ~-20 ~10 ~-10 ~-20 ~11 ~-10 minecraft:light_gray_stained_glass
fill ~-31 ~10 ~-20 ~-31 ~11 ~-20 minecraft:gray_stained_glass
fill ~-16 ~10 ~-20 ~-16 ~11 ~-20 minecraft:light_gray_stained_glass
fill ~-31 ~10 ~-17 ~-31 ~11 ~-17 minecraft:gray_stained_glass
fill ~-16 ~10 ~-17 ~-16 ~11 ~-17 minecraft:light_gray_stained_glass
fill ~-31 ~10 ~-14 ~-31 ~11 ~-14 minecraft:gray_stained_glass
fill ~-16 ~10 ~-14 ~-16 ~11 ~-14 minecraft:light_gray_stained_glass
setblock ~-31 ~1 ~-17 minecraft:iron_door[half=lower,facing=west]
setblock ~-31 ~2 ~-17 minecraft:iron_door[half=upper,facing=west]
fill ~-31 ~7 ~-22 ~-16 ~12 ~-10 minecraft:air
fill ~-30 ~7 ~-21 ~-17 ~12 ~-11 minecraft:white_terracotta
fill ~-29 ~8 ~-20 ~-18 ~11 ~-12 minecraft:air
fill ~-30 ~13 ~-21 ~-17 ~13 ~-11 minecraft:stone_brick_slab
fill ~-31 ~2 ~-20 ~-31 ~7 ~-12 minecraft:blue_stained_glass
fill ~-31 ~1 ~-21 ~-31 ~7 ~-21 minecraft:gray_concrete
fill ~-31 ~1 ~-17 ~-31 ~7 ~-17 minecraft:gray_concrete
fill ~-31 ~1 ~-13 ~-31 ~7 ~-13 minecraft:gray_concrete
# 053 utility style=loading_bay context=collector_front facing=east
fill ~6 ~-3 ~-102 ~17 ~-1 ~-91 minecraft:stone
fill ~6 ~0 ~-102 ~17 ~9 ~-91 minecraft:bricks
fill ~7 ~1 ~-101 ~16 ~8 ~-92 minecraft:air
fill ~7 ~4 ~-101 ~16 ~4 ~-92 minecraft:smooth_stone
fill ~7 ~8 ~-101 ~16 ~8 ~-92 minecraft:smooth_stone
fill ~8 ~2 ~-102 ~8 ~3 ~-102 minecraft:gray_stained_glass
fill ~8 ~2 ~-91 ~8 ~3 ~-91 minecraft:light_gray_stained_glass
fill ~11 ~2 ~-102 ~11 ~3 ~-102 minecraft:gray_stained_glass
fill ~11 ~2 ~-91 ~11 ~3 ~-91 minecraft:light_gray_stained_glass
fill ~14 ~2 ~-102 ~14 ~3 ~-102 minecraft:gray_stained_glass
fill ~14 ~2 ~-91 ~14 ~3 ~-91 minecraft:light_gray_stained_glass
fill ~6 ~2 ~-100 ~6 ~3 ~-100 minecraft:gray_stained_glass
fill ~17 ~2 ~-100 ~17 ~3 ~-100 minecraft:light_gray_stained_glass
fill ~6 ~2 ~-97 ~6 ~3 ~-97 minecraft:gray_stained_glass
fill ~17 ~2 ~-97 ~17 ~3 ~-97 minecraft:light_gray_stained_glass
fill ~6 ~2 ~-94 ~6 ~3 ~-94 minecraft:gray_stained_glass
fill ~17 ~2 ~-94 ~17 ~3 ~-94 minecraft:light_gray_stained_glass
fill ~8 ~6 ~-102 ~8 ~7 ~-102 minecraft:gray_stained_glass
fill ~8 ~6 ~-91 ~8 ~7 ~-91 minecraft:light_gray_stained_glass
fill ~11 ~6 ~-102 ~11 ~7 ~-102 minecraft:gray_stained_glass
fill ~11 ~6 ~-91 ~11 ~7 ~-91 minecraft:light_gray_stained_glass
fill ~14 ~6 ~-102 ~14 ~7 ~-102 minecraft:gray_stained_glass
fill ~14 ~6 ~-91 ~14 ~7 ~-91 minecraft:light_gray_stained_glass
fill ~6 ~6 ~-100 ~6 ~7 ~-100 minecraft:gray_stained_glass
fill ~17 ~6 ~-100 ~17 ~7 ~-100 minecraft:light_gray_stained_glass
fill ~6 ~6 ~-97 ~6 ~7 ~-97 minecraft:gray_stained_glass
fill ~17 ~6 ~-97 ~17 ~7 ~-97 minecraft:light_gray_stained_glass
fill ~6 ~6 ~-94 ~6 ~7 ~-94 minecraft:gray_stained_glass
fill ~17 ~6 ~-94 ~17 ~7 ~-94 minecraft:light_gray_stained_glass
setblock ~17 ~1 ~-97 minecraft:iron_door[half=lower,facing=east]
setblock ~17 ~2 ~-97 minecraft:iron_door[half=upper,facing=east]
fill ~17 ~1 ~-100 ~17 ~4 ~-93 minecraft:polished_blackstone
fill ~17 ~5 ~-100 ~17 ~5 ~-93 minecraft:light_blue_stained_glass
fill ~8 ~11 ~-100 ~10 ~12 ~-98 minecraft:iron_block
fill ~6 ~10 ~-102 ~17 ~10 ~-91 minecraft:deepslate_tile_slab
fill ~17 ~1 ~-101 ~17 ~7 ~-101 minecraft:gray_concrete
fill ~17 ~1 ~-97 ~17 ~7 ~-97 minecraft:gray_concrete
fill ~17 ~1 ~-93 ~17 ~7 ~-93 minecraft:gray_concrete
# 054 detached_house style=japanese_house context=local_front facing=west
fill ~-75 ~-3 ~-75 ~-67 ~-1 ~-66 minecraft:stone
fill ~-75 ~0 ~-75 ~-67 ~10 ~-66 minecraft:bricks
fill ~-74 ~1 ~-74 ~-68 ~9 ~-67 minecraft:air
fill ~-74 ~4 ~-74 ~-68 ~4 ~-67 minecraft:smooth_stone
fill ~-74 ~8 ~-74 ~-68 ~8 ~-67 minecraft:smooth_stone
fill ~-73 ~2 ~-75 ~-73 ~3 ~-75 minecraft:gray_stained_glass
fill ~-73 ~2 ~-66 ~-73 ~3 ~-66 minecraft:light_gray_stained_glass
fill ~-70 ~2 ~-75 ~-70 ~3 ~-75 minecraft:gray_stained_glass
fill ~-70 ~2 ~-66 ~-70 ~3 ~-66 minecraft:light_gray_stained_glass
fill ~-75 ~2 ~-73 ~-75 ~3 ~-73 minecraft:gray_stained_glass
fill ~-67 ~2 ~-73 ~-67 ~3 ~-73 minecraft:light_gray_stained_glass
fill ~-75 ~2 ~-70 ~-75 ~3 ~-70 minecraft:gray_stained_glass
fill ~-67 ~2 ~-70 ~-67 ~3 ~-70 minecraft:light_gray_stained_glass
fill ~-73 ~6 ~-75 ~-73 ~7 ~-75 minecraft:gray_stained_glass
fill ~-73 ~6 ~-66 ~-73 ~7 ~-66 minecraft:light_gray_stained_glass
fill ~-70 ~6 ~-75 ~-70 ~7 ~-75 minecraft:gray_stained_glass
fill ~-70 ~6 ~-66 ~-70 ~7 ~-66 minecraft:light_gray_stained_glass
fill ~-75 ~6 ~-73 ~-75 ~7 ~-73 minecraft:gray_stained_glass
fill ~-67 ~6 ~-73 ~-67 ~7 ~-73 minecraft:light_gray_stained_glass
fill ~-75 ~6 ~-70 ~-75 ~7 ~-70 minecraft:gray_stained_glass
fill ~-67 ~6 ~-70 ~-67 ~7 ~-70 minecraft:light_gray_stained_glass
setblock ~-75 ~1 ~-71 minecraft:iron_door[half=lower,facing=west]
setblock ~-75 ~2 ~-71 minecraft:iron_door[half=upper,facing=west]
fill ~-75 ~11 ~-75 ~-67 ~11 ~-66 minecraft:deepslate_tile_slab
fill ~-74 ~12 ~-74 ~-68 ~12 ~-67 minecraft:deepslate_tile_slab
setblock ~-76 ~3 ~-71 minecraft:dark_oak_slab[type=top]
fill ~-73 ~12 ~-73 ~-71 ~13 ~-71 minecraft:light_gray_concrete
setblock ~-70 ~12 ~-72 minecraft:lightning_rod
fill ~-75 ~1 ~-74 ~-75 ~7 ~-74 doomsday_decoration:hollowbrick
fill ~-75 ~1 ~-70 ~-75 ~7 ~-70 doomsday_decoration:hollowbrick
# 055 community style=mixed_facade context=collector_front facing=west
fill ~-92 ~-3 ~-19 ~-82 ~-1 ~-13 minecraft:stone
fill ~-92 ~0 ~-19 ~-82 ~12 ~-13 minecraft:light_gray_concrete
fill ~-91 ~1 ~-18 ~-83 ~11 ~-14 minecraft:air
fill ~-91 ~4 ~-18 ~-83 ~4 ~-14 minecraft:smooth_stone
fill ~-91 ~8 ~-18 ~-83 ~8 ~-14 minecraft:smooth_stone
fill ~-90 ~2 ~-19 ~-90 ~3 ~-19 minecraft:gray_stained_glass
fill ~-90 ~2 ~-13 ~-90 ~3 ~-13 minecraft:light_gray_stained_glass
fill ~-87 ~2 ~-19 ~-87 ~3 ~-19 minecraft:gray_stained_glass
fill ~-87 ~2 ~-13 ~-87 ~3 ~-13 minecraft:light_gray_stained_glass
fill ~-84 ~2 ~-19 ~-84 ~3 ~-19 minecraft:gray_stained_glass
fill ~-84 ~2 ~-13 ~-84 ~3 ~-13 minecraft:light_gray_stained_glass
fill ~-92 ~2 ~-17 ~-92 ~3 ~-17 minecraft:gray_stained_glass
fill ~-82 ~2 ~-17 ~-82 ~3 ~-17 minecraft:light_gray_stained_glass
fill ~-90 ~6 ~-19 ~-90 ~7 ~-19 minecraft:gray_stained_glass
fill ~-90 ~6 ~-13 ~-90 ~7 ~-13 minecraft:light_gray_stained_glass
fill ~-87 ~6 ~-19 ~-87 ~7 ~-19 minecraft:gray_stained_glass
fill ~-87 ~6 ~-13 ~-87 ~7 ~-13 minecraft:light_gray_stained_glass
fill ~-84 ~6 ~-19 ~-84 ~7 ~-19 minecraft:gray_stained_glass
fill ~-84 ~6 ~-13 ~-84 ~7 ~-13 minecraft:light_gray_stained_glass
fill ~-92 ~6 ~-17 ~-92 ~7 ~-17 minecraft:gray_stained_glass
fill ~-82 ~6 ~-17 ~-82 ~7 ~-17 minecraft:light_gray_stained_glass
fill ~-90 ~10 ~-19 ~-90 ~11 ~-19 minecraft:gray_stained_glass
fill ~-90 ~10 ~-13 ~-90 ~11 ~-13 minecraft:light_gray_stained_glass
fill ~-87 ~10 ~-19 ~-87 ~11 ~-19 minecraft:gray_stained_glass
fill ~-87 ~10 ~-13 ~-87 ~11 ~-13 minecraft:light_gray_stained_glass
fill ~-84 ~10 ~-19 ~-84 ~11 ~-19 minecraft:gray_stained_glass
fill ~-84 ~10 ~-13 ~-84 ~11 ~-13 minecraft:light_gray_stained_glass
fill ~-92 ~10 ~-17 ~-92 ~11 ~-17 minecraft:gray_stained_glass
fill ~-82 ~10 ~-17 ~-82 ~11 ~-17 minecraft:light_gray_stained_glass
setblock ~-92 ~1 ~-16 minecraft:iron_door[half=lower,facing=west]
setblock ~-92 ~2 ~-16 minecraft:iron_door[half=upper,facing=west]
fill ~-92 ~13 ~-19 ~-82 ~13 ~-13 minecraft:smooth_stone_slab
fill ~-92 ~1 ~-18 ~-92 ~7 ~-18 doomsday_decoration:porcelainbrickwall
fill ~-92 ~1 ~-14 ~-92 ~7 ~-14 doomsday_decoration:porcelainbrickwall
# 056 community style=balcony_block context=collector_front facing=west
fill ~-89 ~-3 ~19 ~-82 ~-1 ~29 minecraft:stone
fill ~-89 ~0 ~19 ~-82 ~8 ~29 minecraft:smooth_sandstone
fill ~-88 ~1 ~20 ~-83 ~7 ~28 minecraft:air
fill ~-88 ~4 ~20 ~-83 ~4 ~28 minecraft:smooth_stone
fill ~-87 ~2 ~19 ~-87 ~3 ~19 minecraft:gray_stained_glass
fill ~-87 ~2 ~29 ~-87 ~3 ~29 minecraft:light_gray_stained_glass
fill ~-84 ~2 ~19 ~-84 ~3 ~19 minecraft:gray_stained_glass
fill ~-84 ~2 ~29 ~-84 ~3 ~29 minecraft:light_gray_stained_glass
fill ~-89 ~2 ~21 ~-89 ~3 ~21 minecraft:gray_stained_glass
fill ~-82 ~2 ~21 ~-82 ~3 ~21 minecraft:light_gray_stained_glass
fill ~-89 ~2 ~24 ~-89 ~3 ~24 minecraft:gray_stained_glass
fill ~-82 ~2 ~24 ~-82 ~3 ~24 minecraft:light_gray_stained_glass
fill ~-89 ~2 ~27 ~-89 ~3 ~27 minecraft:gray_stained_glass
fill ~-82 ~2 ~27 ~-82 ~3 ~27 minecraft:light_gray_stained_glass
fill ~-87 ~6 ~19 ~-87 ~7 ~19 minecraft:gray_stained_glass
fill ~-87 ~6 ~29 ~-87 ~7 ~29 minecraft:light_gray_stained_glass
fill ~-84 ~6 ~19 ~-84 ~7 ~19 minecraft:gray_stained_glass
fill ~-84 ~6 ~29 ~-84 ~7 ~29 minecraft:light_gray_stained_glass
fill ~-89 ~6 ~21 ~-89 ~7 ~21 minecraft:gray_stained_glass
fill ~-82 ~6 ~21 ~-82 ~7 ~21 minecraft:light_gray_stained_glass
fill ~-89 ~6 ~24 ~-89 ~7 ~24 minecraft:gray_stained_glass
fill ~-82 ~6 ~24 ~-82 ~7 ~24 minecraft:light_gray_stained_glass
fill ~-89 ~6 ~27 ~-89 ~7 ~27 minecraft:gray_stained_glass
fill ~-82 ~6 ~27 ~-82 ~7 ~27 minecraft:light_gray_stained_glass
setblock ~-89 ~1 ~24 minecraft:iron_door[half=lower,facing=west]
setblock ~-89 ~2 ~24 minecraft:iron_door[half=upper,facing=west]
fill ~-90 ~4 ~21 ~-90 ~4 ~27 minecraft:smooth_stone_slab
fill ~-89 ~9 ~19 ~-82 ~9 ~29 minecraft:stone_brick_slab
fill ~-89 ~1 ~20 ~-89 ~7 ~20 minecraft:brown_terracotta
fill ~-89 ~1 ~24 ~-89 ~7 ~24 minecraft:brown_terracotta
fill ~-89 ~1 ~28 ~-89 ~7 ~28 minecraft:brown_terracotta
