# Buildings 193..200
# 193 community style=balcony_block context=collector_front facing=north
fill ~52 ~-3 ~26 ~56 ~-1 ~31 minecraft:stone
fill ~52 ~0 ~26 ~56 ~5 ~31 minecraft:smooth_sandstone
fill ~53 ~1 ~27 ~55 ~4 ~30 minecraft:air
fill ~53 ~4 ~27 ~55 ~4 ~30 minecraft:smooth_stone
fill ~54 ~2 ~26 ~54 ~3 ~26 minecraft:gray_stained_glass
fill ~54 ~2 ~31 ~54 ~3 ~31 minecraft:light_gray_stained_glass
fill ~52 ~2 ~28 ~52 ~3 ~28 minecraft:gray_stained_glass
fill ~56 ~2 ~28 ~56 ~3 ~28 minecraft:light_gray_stained_glass
setblock ~54 ~1 ~26 minecraft:iron_door[half=lower,facing=north]
setblock ~54 ~2 ~26 minecraft:iron_door[half=upper,facing=north]
fill ~54 ~4 ~25 ~54 ~4 ~25 minecraft:smooth_stone_slab
fill ~52 ~6 ~26 ~56 ~6 ~31 minecraft:stone_brick_slab
# 194 utility style=industrial_shed context=waterfront_front facing=west
fill ~89 ~-3 ~-87 ~96 ~-1 ~-81 minecraft:stone
fill ~89 ~0 ~-87 ~96 ~6 ~-81 minecraft:bricks
fill ~90 ~1 ~-86 ~95 ~5 ~-82 minecraft:air
fill ~90 ~4 ~-86 ~95 ~4 ~-82 minecraft:smooth_stone
fill ~91 ~2 ~-87 ~91 ~3 ~-87 minecraft:gray_stained_glass
fill ~91 ~2 ~-81 ~91 ~3 ~-81 minecraft:light_gray_stained_glass
fill ~94 ~2 ~-87 ~94 ~3 ~-87 minecraft:gray_stained_glass
fill ~94 ~2 ~-81 ~94 ~3 ~-81 minecraft:light_gray_stained_glass
fill ~89 ~2 ~-85 ~89 ~3 ~-85 minecraft:gray_stained_glass
fill ~96 ~2 ~-85 ~96 ~3 ~-85 minecraft:light_gray_stained_glass
setblock ~89 ~1 ~-84 minecraft:iron_door[half=lower,facing=west]
setblock ~89 ~2 ~-84 minecraft:iron_door[half=upper,facing=west]
fill ~89 ~1 ~-85 ~89 ~4 ~-83 minecraft:polished_blackstone
fill ~89 ~5 ~-85 ~89 ~5 ~-83 minecraft:light_blue_stained_glass
fill ~91 ~8 ~-85 ~93 ~9 ~-83 minecraft:iron_block
fill ~89 ~7 ~-87 ~96 ~7 ~-81 minecraft:deepslate_tile_slab
# 195 garage style=industrial_shed context=back_block facing=west
fill ~27 ~-3 ~-125 ~31 ~-1 ~-120 minecraft:stone
fill ~27 ~0 ~-125 ~31 ~10 ~-120 minecraft:stone_bricks
fill ~28 ~1 ~-124 ~30 ~9 ~-121 minecraft:air
fill ~28 ~4 ~-124 ~30 ~4 ~-121 minecraft:smooth_stone
fill ~28 ~8 ~-124 ~30 ~8 ~-121 minecraft:smooth_stone
fill ~29 ~2 ~-125 ~29 ~3 ~-125 minecraft:gray_stained_glass
fill ~29 ~2 ~-120 ~29 ~3 ~-120 minecraft:light_gray_stained_glass
fill ~27 ~2 ~-123 ~27 ~3 ~-123 minecraft:gray_stained_glass
fill ~31 ~2 ~-123 ~31 ~3 ~-123 minecraft:light_gray_stained_glass
fill ~29 ~6 ~-125 ~29 ~7 ~-125 minecraft:gray_stained_glass
fill ~29 ~6 ~-120 ~29 ~7 ~-120 minecraft:light_gray_stained_glass
fill ~27 ~6 ~-123 ~27 ~7 ~-123 minecraft:gray_stained_glass
fill ~31 ~6 ~-123 ~31 ~7 ~-123 minecraft:light_gray_stained_glass
setblock ~27 ~1 ~-123 minecraft:iron_door[half=lower,facing=west]
setblock ~27 ~2 ~-123 minecraft:iron_door[half=upper,facing=west]
fill ~27 ~1 ~-123 ~27 ~4 ~-122 minecraft:polished_blackstone
fill ~27 ~5 ~-123 ~27 ~5 ~-122 minecraft:light_blue_stained_glass
fill ~29 ~12 ~-123 ~30 ~13 ~-121 minecraft:iron_block
fill ~27 ~11 ~-125 ~31 ~11 ~-120 minecraft:smooth_stone_slab
fill ~29 ~12 ~-123 ~30 ~13 ~-121 minecraft:light_gray_concrete
setblock ~30 ~12 ~-122 minecraft:lightning_rod
# 196 warehouse style=sawtooth context=back_block facing=south
fill ~-115 ~-3 ~-92 ~-111 ~-1 ~-86 minecraft:stone
fill ~-115 ~0 ~-92 ~-111 ~6 ~-86 minecraft:bricks
fill ~-114 ~1 ~-91 ~-112 ~5 ~-87 minecraft:air
fill ~-114 ~4 ~-91 ~-112 ~4 ~-87 minecraft:smooth_stone
fill ~-113 ~2 ~-92 ~-113 ~3 ~-92 minecraft:gray_stained_glass
fill ~-113 ~2 ~-86 ~-113 ~3 ~-86 minecraft:light_gray_stained_glass
fill ~-115 ~2 ~-90 ~-115 ~3 ~-90 minecraft:gray_stained_glass
fill ~-111 ~2 ~-90 ~-111 ~3 ~-90 minecraft:light_gray_stained_glass
setblock ~-113 ~1 ~-86 minecraft:iron_door[half=lower,facing=south]
setblock ~-113 ~2 ~-86 minecraft:iron_door[half=upper,facing=south]
fill ~-113 ~1 ~-86 ~-113 ~4 ~-86 minecraft:polished_blackstone
fill ~-113 ~5 ~-86 ~-113 ~5 ~-86 minecraft:light_blue_stained_glass
fill ~-113 ~8 ~-90 ~-112 ~9 ~-88 minecraft:iron_block
fill ~-115 ~7 ~-92 ~-111 ~7 ~-86 minecraft:deepslate_tile_slab
# 197 warehouse style=loading_bay context=back_block facing=east
fill ~-48 ~-3 ~-113 ~-41 ~-1 ~-108 minecraft:stone
fill ~-48 ~0 ~-113 ~-41 ~8 ~-108 minecraft:stone_bricks
fill ~-47 ~1 ~-112 ~-42 ~7 ~-109 minecraft:air
fill ~-47 ~4 ~-112 ~-42 ~4 ~-109 minecraft:smooth_stone
fill ~-46 ~2 ~-113 ~-46 ~3 ~-113 minecraft:gray_stained_glass
fill ~-46 ~2 ~-108 ~-46 ~3 ~-108 minecraft:light_gray_stained_glass
fill ~-43 ~2 ~-113 ~-43 ~3 ~-113 minecraft:gray_stained_glass
fill ~-43 ~2 ~-108 ~-43 ~3 ~-108 minecraft:light_gray_stained_glass
fill ~-48 ~2 ~-111 ~-48 ~3 ~-111 minecraft:gray_stained_glass
fill ~-41 ~2 ~-111 ~-41 ~3 ~-111 minecraft:light_gray_stained_glass
fill ~-46 ~6 ~-113 ~-46 ~7 ~-113 minecraft:gray_stained_glass
fill ~-46 ~6 ~-108 ~-46 ~7 ~-108 minecraft:light_gray_stained_glass
fill ~-43 ~6 ~-113 ~-43 ~7 ~-113 minecraft:gray_stained_glass
fill ~-43 ~6 ~-108 ~-43 ~7 ~-108 minecraft:light_gray_stained_glass
fill ~-48 ~6 ~-111 ~-48 ~7 ~-111 minecraft:gray_stained_glass
fill ~-41 ~6 ~-111 ~-41 ~7 ~-111 minecraft:light_gray_stained_glass
setblock ~-41 ~1 ~-111 minecraft:iron_door[half=lower,facing=east]
setblock ~-41 ~2 ~-111 minecraft:iron_door[half=upper,facing=east]
fill ~-41 ~1 ~-111 ~-41 ~4 ~-110 minecraft:polished_blackstone
fill ~-41 ~5 ~-111 ~-41 ~5 ~-110 minecraft:light_blue_stained_glass
fill ~-46 ~10 ~-111 ~-44 ~11 ~-109 minecraft:iron_block
fill ~-48 ~9 ~-113 ~-41 ~9 ~-108 minecraft:smooth_stone_slab
# 198 garage style=sawtooth context=local_front facing=south
fill ~-118 ~-3 ~-122 ~-110 ~-1 ~-117 minecraft:stone
fill ~-118 ~0 ~-122 ~-110 ~8 ~-117 minecraft:bricks
fill ~-117 ~1 ~-121 ~-111 ~7 ~-118 minecraft:air
fill ~-117 ~4 ~-121 ~-111 ~4 ~-118 minecraft:smooth_stone
fill ~-116 ~2 ~-122 ~-116 ~3 ~-122 minecraft:gray_stained_glass
fill ~-116 ~2 ~-117 ~-116 ~3 ~-117 minecraft:light_gray_stained_glass
fill ~-113 ~2 ~-122 ~-113 ~3 ~-122 minecraft:gray_stained_glass
fill ~-113 ~2 ~-117 ~-113 ~3 ~-117 minecraft:light_gray_stained_glass
fill ~-118 ~2 ~-120 ~-118 ~3 ~-120 minecraft:gray_stained_glass
fill ~-110 ~2 ~-120 ~-110 ~3 ~-120 minecraft:light_gray_stained_glass
fill ~-116 ~6 ~-122 ~-116 ~7 ~-122 minecraft:gray_stained_glass
fill ~-116 ~6 ~-117 ~-116 ~7 ~-117 minecraft:light_gray_stained_glass
fill ~-113 ~6 ~-122 ~-113 ~7 ~-122 minecraft:gray_stained_glass
fill ~-113 ~6 ~-117 ~-113 ~7 ~-117 minecraft:light_gray_stained_glass
fill ~-118 ~6 ~-120 ~-118 ~7 ~-120 minecraft:gray_stained_glass
fill ~-110 ~6 ~-120 ~-110 ~7 ~-120 minecraft:light_gray_stained_glass
setblock ~-114 ~1 ~-117 minecraft:iron_door[half=lower,facing=south]
setblock ~-114 ~2 ~-117 minecraft:iron_door[half=upper,facing=south]
fill ~-116 ~1 ~-117 ~-112 ~4 ~-117 minecraft:polished_blackstone
fill ~-116 ~5 ~-117 ~-112 ~5 ~-117 minecraft:light_blue_stained_glass
fill ~-116 ~10 ~-120 ~-114 ~11 ~-118 minecraft:iron_block
fill ~-118 ~9 ~-122 ~-110 ~9 ~-117 minecraft:deepslate_tile_slab
fill ~-116 ~10 ~-120 ~-114 ~11 ~-118 minecraft:light_gray_concrete
setblock ~-113 ~10 ~-119 minecraft:lightning_rod
# 199 logistics style=sawtooth context=collector_front facing=south
fill ~-110 ~-3 ~-90 ~-106 ~-1 ~-84 minecraft:stone
fill ~-110 ~0 ~-90 ~-106 ~6 ~-84 minecraft:stone_bricks
fill ~-109 ~1 ~-89 ~-107 ~5 ~-85 minecraft:air
fill ~-109 ~4 ~-89 ~-107 ~4 ~-85 minecraft:smooth_stone
fill ~-108 ~2 ~-90 ~-108 ~3 ~-90 minecraft:gray_stained_glass
fill ~-108 ~2 ~-84 ~-108 ~3 ~-84 minecraft:light_gray_stained_glass
fill ~-110 ~2 ~-88 ~-110 ~3 ~-88 minecraft:gray_stained_glass
fill ~-106 ~2 ~-88 ~-106 ~3 ~-88 minecraft:light_gray_stained_glass
setblock ~-108 ~1 ~-84 minecraft:iron_door[half=lower,facing=south]
setblock ~-108 ~2 ~-84 minecraft:iron_door[half=upper,facing=south]
fill ~-108 ~1 ~-84 ~-108 ~4 ~-84 minecraft:polished_blackstone
fill ~-108 ~5 ~-84 ~-108 ~5 ~-84 minecraft:light_blue_stained_glass
fill ~-108 ~8 ~-88 ~-107 ~9 ~-86 minecraft:iron_block
fill ~-110 ~7 ~-90 ~-106 ~7 ~-84 minecraft:smooth_stone_slab
# 200 garage style=sawtooth context=back_block facing=south
fill ~-123 ~-3 ~-92 ~-119 ~-1 ~-87 minecraft:stone
fill ~-123 ~0 ~-92 ~-119 ~8 ~-87 minecraft:bricks
fill ~-122 ~1 ~-91 ~-120 ~7 ~-88 minecraft:air
fill ~-122 ~4 ~-91 ~-120 ~4 ~-88 minecraft:smooth_stone
fill ~-121 ~2 ~-92 ~-121 ~3 ~-92 minecraft:gray_stained_glass
fill ~-121 ~2 ~-87 ~-121 ~3 ~-87 minecraft:light_gray_stained_glass
fill ~-123 ~2 ~-90 ~-123 ~3 ~-90 minecraft:gray_stained_glass
fill ~-119 ~2 ~-90 ~-119 ~3 ~-90 minecraft:light_gray_stained_glass
fill ~-121 ~6 ~-92 ~-121 ~7 ~-92 minecraft:gray_stained_glass
fill ~-121 ~6 ~-87 ~-121 ~7 ~-87 minecraft:light_gray_stained_glass
fill ~-123 ~6 ~-90 ~-123 ~7 ~-90 minecraft:gray_stained_glass
fill ~-119 ~6 ~-90 ~-119 ~7 ~-90 minecraft:light_gray_stained_glass
setblock ~-121 ~1 ~-87 minecraft:iron_door[half=lower,facing=south]
setblock ~-121 ~2 ~-87 minecraft:iron_door[half=upper,facing=south]
fill ~-121 ~1 ~-87 ~-121 ~4 ~-87 minecraft:polished_blackstone
fill ~-121 ~5 ~-87 ~-121 ~5 ~-87 minecraft:light_blue_stained_glass
fill ~-121 ~10 ~-90 ~-120 ~11 ~-88 minecraft:iron_block
fill ~-123 ~9 ~-92 ~-119 ~9 ~-87 minecraft:deepslate_tile_slab
