# Buildings 201..225
# 201 lowrise_housing 5,76 9,84 h=7
fill ~5 ~-3 ~76 ~9 ~-1 ~84 minecraft:stone
fill ~5 ~0 ~76 ~9 ~7 ~84 minecraft:smooth_sandstone
fill ~6 ~1 ~77 ~8 ~6 ~83 minecraft:air
fill ~6 ~4 ~77 ~8 ~4 ~83 minecraft:smooth_stone
fill ~7 ~2 ~76 ~7 ~3 ~76 minecraft:gray_stained_glass
fill ~7 ~2 ~84 ~7 ~3 ~84 minecraft:light_gray_stained_glass
fill ~6 ~0 ~76 ~8 ~3 ~76 minecraft:brown_terracotta
setblock ~7 ~1 ~76 minecraft:iron_door[half=lower,facing=north]
setblock ~7 ~2 ~76 minecraft:iron_door[half=upper,facing=north]
fill ~5 ~8 ~76 ~9 ~8 ~84 minecraft:stone_brick_slab
# 202 garage -107,-126 -103,-121 h=10
fill ~-107 ~-3 ~-126 ~-103 ~-1 ~-121 minecraft:stone
fill ~-107 ~0 ~-126 ~-103 ~10 ~-121 minecraft:stone_bricks
fill ~-106 ~1 ~-125 ~-104 ~9 ~-122 minecraft:air
fill ~-106 ~4 ~-125 ~-104 ~4 ~-122 minecraft:smooth_stone
fill ~-106 ~8 ~-125 ~-104 ~8 ~-122 minecraft:smooth_stone
fill ~-105 ~2 ~-126 ~-105 ~3 ~-126 minecraft:gray_stained_glass
fill ~-105 ~2 ~-121 ~-105 ~3 ~-121 minecraft:light_gray_stained_glass
fill ~-105 ~6 ~-126 ~-105 ~7 ~-126 minecraft:gray_stained_glass
fill ~-105 ~6 ~-121 ~-105 ~7 ~-121 minecraft:light_gray_stained_glass
fill ~-106 ~0 ~-126 ~-104 ~3 ~-126 doomsday_decoration:ironsheetwall_2
setblock ~-105 ~1 ~-126 minecraft:iron_door[half=lower,facing=north]
setblock ~-105 ~2 ~-126 minecraft:iron_door[half=upper,facing=north]
fill ~-107 ~11 ~-126 ~-103 ~11 ~-121 minecraft:smooth_stone_slab
# 203 mixed_use -37,-3 -31,3 h=20
fill ~-37 ~-3 ~-3 ~-31 ~-1 ~3 minecraft:stone
fill ~-37 ~0 ~-3 ~-31 ~20 ~3 minecraft:white_terracotta
fill ~-36 ~1 ~-2 ~-32 ~19 ~2 minecraft:air
fill ~-36 ~4 ~-2 ~-32 ~4 ~2 minecraft:smooth_stone
fill ~-36 ~8 ~-2 ~-32 ~8 ~2 minecraft:smooth_stone
fill ~-36 ~12 ~-2 ~-32 ~12 ~2 minecraft:smooth_stone
fill ~-36 ~16 ~-2 ~-32 ~16 ~2 minecraft:smooth_stone
fill ~-35 ~2 ~-3 ~-33 ~3 ~-3 minecraft:gray_stained_glass
fill ~-35 ~2 ~3 ~-33 ~3 ~3 minecraft:light_gray_stained_glass
fill ~-35 ~6 ~-3 ~-33 ~7 ~-3 minecraft:gray_stained_glass
fill ~-35 ~6 ~3 ~-33 ~7 ~3 minecraft:light_gray_stained_glass
fill ~-35 ~10 ~-3 ~-33 ~11 ~-3 minecraft:gray_stained_glass
fill ~-35 ~10 ~3 ~-33 ~11 ~3 minecraft:light_gray_stained_glass
fill ~-35 ~14 ~-3 ~-33 ~15 ~-3 minecraft:gray_stained_glass
fill ~-35 ~14 ~3 ~-33 ~15 ~3 minecraft:light_gray_stained_glass
fill ~-35 ~18 ~-3 ~-33 ~19 ~-3 minecraft:gray_stained_glass
fill ~-35 ~18 ~3 ~-33 ~19 ~3 minecraft:light_gray_stained_glass
fill ~-36 ~0 ~-3 ~-33 ~3 ~-3 minecraft:gray_concrete
setblock ~-35 ~1 ~-3 minecraft:iron_door[half=lower,facing=north]
setblock ~-35 ~2 ~-3 minecraft:iron_door[half=upper,facing=north]
fill ~-37 ~21 ~-3 ~-31 ~21 ~3 minecraft:stone_brick_slab
# 204 office -84,-90 -77,-82 h=6
fill ~-84 ~-3 ~-90 ~-77 ~-1 ~-82 minecraft:stone
fill ~-84 ~0 ~-90 ~-77 ~6 ~-82 minecraft:stone_bricks
fill ~-83 ~1 ~-89 ~-78 ~5 ~-83 minecraft:air
fill ~-83 ~4 ~-89 ~-78 ~4 ~-83 minecraft:smooth_stone
fill ~-84 ~2 ~-88 ~-84 ~3 ~-84 minecraft:gray_stained_glass
fill ~-77 ~2 ~-88 ~-77 ~3 ~-84 minecraft:light_gray_stained_glass
fill ~-83 ~0 ~-90 ~-80 ~3 ~-90 doomsday_decoration:ironsheetwall_2
setblock ~-82 ~1 ~-90 minecraft:iron_door[half=lower,facing=north]
setblock ~-82 ~2 ~-90 minecraft:iron_door[half=upper,facing=north]
fill ~-84 ~7 ~-90 ~-77 ~7 ~-82 minecraft:smooth_stone_slab
# 205 detached_house -11,118 -6,123 h=9
fill ~-11 ~-3 ~118 ~-6 ~-1 ~123 minecraft:stone
fill ~-11 ~0 ~118 ~-6 ~9 ~123 minecraft:calcite
fill ~-10 ~1 ~119 ~-7 ~8 ~122 minecraft:air
fill ~-10 ~4 ~119 ~-7 ~4 ~122 minecraft:smooth_stone
fill ~-10 ~8 ~119 ~-7 ~8 ~122 minecraft:smooth_stone
fill ~-9 ~2 ~118 ~-8 ~3 ~118 minecraft:gray_stained_glass
fill ~-9 ~2 ~123 ~-8 ~3 ~123 minecraft:light_gray_stained_glass
fill ~-9 ~6 ~118 ~-8 ~7 ~118 minecraft:gray_stained_glass
fill ~-9 ~6 ~123 ~-8 ~7 ~123 minecraft:light_gray_stained_glass
fill ~-10 ~0 ~118 ~-7 ~3 ~118 minecraft:gray_concrete
setblock ~-9 ~1 ~118 minecraft:iron_door[half=lower,facing=north]
setblock ~-9 ~2 ~118 minecraft:iron_door[half=upper,facing=north]
fill ~-11 ~10 ~118 ~-6 ~10 ~123 minecraft:stone_brick_slab
# 206 community -116,-21 -112,-14 h=9
fill ~-116 ~-3 ~-21 ~-112 ~-1 ~-14 minecraft:stone
fill ~-116 ~0 ~-21 ~-112 ~9 ~-14 minecraft:mud_bricks
fill ~-115 ~1 ~-20 ~-113 ~8 ~-15 minecraft:air
fill ~-115 ~4 ~-20 ~-113 ~4 ~-15 minecraft:smooth_stone
fill ~-115 ~8 ~-20 ~-113 ~8 ~-15 minecraft:smooth_stone
fill ~-116 ~2 ~-19 ~-116 ~3 ~-16 minecraft:gray_stained_glass
fill ~-112 ~2 ~-19 ~-112 ~3 ~-16 minecraft:light_gray_stained_glass
fill ~-116 ~6 ~-19 ~-116 ~7 ~-16 minecraft:gray_stained_glass
fill ~-112 ~6 ~-19 ~-112 ~7 ~-16 minecraft:light_gray_stained_glass
fill ~-115 ~0 ~-21 ~-113 ~3 ~-21 minecraft:spruce_planks
setblock ~-114 ~1 ~-21 minecraft:iron_door[half=lower,facing=north]
setblock ~-114 ~2 ~-21 minecraft:iron_door[half=upper,facing=north]
fill ~-116 ~10 ~-21 ~-112 ~10 ~-14 minecraft:deepslate_tile_slab
# 207 garage 89,117 96,122 h=10
fill ~89 ~-3 ~117 ~96 ~-1 ~122 minecraft:stone
fill ~89 ~0 ~117 ~96 ~10 ~122 minecraft:gray_concrete
fill ~90 ~1 ~118 ~95 ~9 ~121 minecraft:air
fill ~90 ~4 ~118 ~95 ~4 ~121 minecraft:smooth_stone
fill ~90 ~8 ~118 ~95 ~8 ~121 minecraft:smooth_stone
fill ~91 ~2 ~117 ~94 ~3 ~117 minecraft:gray_stained_glass
fill ~91 ~2 ~122 ~94 ~3 ~122 minecraft:light_gray_stained_glass
fill ~91 ~6 ~117 ~94 ~7 ~117 minecraft:gray_stained_glass
fill ~91 ~6 ~122 ~94 ~7 ~122 minecraft:light_gray_stained_glass
fill ~90 ~0 ~117 ~93 ~3 ~117 doomsday_decoration:ironsheetwall_1
setblock ~91 ~1 ~117 minecraft:iron_door[half=lower,facing=north]
setblock ~91 ~2 ~117 minecraft:iron_door[half=upper,facing=north]
fill ~89 ~11 ~117 ~96 ~11 ~122 minecraft:smooth_stone_slab
# 208 mixed_use -43,-41 -37,-36 h=12
fill ~-43 ~-3 ~-41 ~-37 ~-1 ~-36 minecraft:stone
fill ~-43 ~0 ~-41 ~-37 ~12 ~-36 minecraft:bricks
fill ~-42 ~1 ~-40 ~-38 ~11 ~-37 minecraft:air
fill ~-42 ~4 ~-40 ~-38 ~4 ~-37 minecraft:smooth_stone
fill ~-42 ~8 ~-40 ~-38 ~8 ~-37 minecraft:smooth_stone
fill ~-41 ~2 ~-41 ~-39 ~3 ~-41 minecraft:gray_stained_glass
fill ~-41 ~2 ~-36 ~-39 ~3 ~-36 minecraft:light_gray_stained_glass
fill ~-41 ~6 ~-41 ~-39 ~7 ~-41 minecraft:gray_stained_glass
fill ~-41 ~6 ~-36 ~-39 ~7 ~-36 minecraft:light_gray_stained_glass
fill ~-41 ~10 ~-41 ~-39 ~11 ~-41 minecraft:gray_stained_glass
fill ~-41 ~10 ~-36 ~-39 ~11 ~-36 minecraft:light_gray_stained_glass
fill ~-42 ~0 ~-41 ~-39 ~3 ~-41 doomsday_decoration:redbrick
setblock ~-41 ~1 ~-41 minecraft:iron_door[half=lower,facing=north]
setblock ~-41 ~2 ~-41 minecraft:iron_door[half=upper,facing=north]
fill ~-43 ~13 ~-41 ~-37 ~13 ~-36 minecraft:deepslate_tile_slab
# 209 lowrise_housing 47,-21 54,-15 h=5
fill ~47 ~-3 ~-21 ~54 ~-1 ~-15 minecraft:stone
fill ~47 ~0 ~-21 ~54 ~5 ~-15 minecraft:bricks
fill ~48 ~1 ~-20 ~53 ~4 ~-16 minecraft:air
fill ~48 ~4 ~-20 ~53 ~4 ~-16 minecraft:smooth_stone
fill ~47 ~2 ~-19 ~47 ~3 ~-17 minecraft:gray_stained_glass
fill ~54 ~2 ~-19 ~54 ~3 ~-17 minecraft:light_gray_stained_glass
fill ~48 ~0 ~-21 ~51 ~3 ~-21 doomsday_decoration:hollowbrick
setblock ~49 ~1 ~-21 minecraft:iron_door[half=lower,facing=north]
setblock ~49 ~2 ~-21 minecraft:iron_door[half=upper,facing=north]
fill ~47 ~6 ~-21 ~54 ~6 ~-15 minecraft:deepslate_tile_slab
# 210 garage -123,-92 -115,-86 h=6
fill ~-123 ~-3 ~-92 ~-115 ~-1 ~-86 minecraft:stone
fill ~-123 ~0 ~-92 ~-115 ~6 ~-86 minecraft:stone_bricks
fill ~-122 ~1 ~-91 ~-116 ~5 ~-87 minecraft:air
fill ~-122 ~4 ~-91 ~-116 ~4 ~-87 minecraft:smooth_stone
fill ~-123 ~2 ~-90 ~-123 ~3 ~-88 minecraft:gray_stained_glass
fill ~-115 ~2 ~-90 ~-115 ~3 ~-88 minecraft:light_gray_stained_glass
fill ~-122 ~0 ~-92 ~-119 ~3 ~-92 doomsday_decoration:ironsheetwall_2
setblock ~-121 ~1 ~-92 minecraft:iron_door[half=lower,facing=north]
setblock ~-121 ~2 ~-92 minecraft:iron_door[half=upper,facing=north]
fill ~-123 ~7 ~-92 ~-115 ~7 ~-86 minecraft:smooth_stone_slab
# 211 office 63,-126 70,-121 h=6
fill ~63 ~-3 ~-126 ~70 ~-1 ~-121 minecraft:stone
fill ~63 ~0 ~-126 ~70 ~6 ~-121 minecraft:bricks
fill ~64 ~1 ~-125 ~69 ~5 ~-122 minecraft:air
fill ~64 ~4 ~-125 ~69 ~4 ~-122 minecraft:smooth_stone
fill ~65 ~2 ~-126 ~68 ~3 ~-126 minecraft:gray_stained_glass
fill ~65 ~2 ~-121 ~68 ~3 ~-121 minecraft:light_gray_stained_glass
fill ~64 ~0 ~-126 ~67 ~3 ~-126 minecraft:gray_concrete
setblock ~65 ~1 ~-126 minecraft:iron_door[half=lower,facing=north]
setblock ~65 ~2 ~-126 minecraft:iron_door[half=upper,facing=north]
fill ~63 ~7 ~-126 ~70 ~7 ~-121 minecraft:deepslate_tile_slab
# 212 community -53,120 -48,125 h=9
fill ~-53 ~-3 ~120 ~-48 ~-1 ~125 minecraft:stone
fill ~-53 ~0 ~120 ~-48 ~9 ~125 minecraft:mud_bricks
fill ~-52 ~1 ~121 ~-49 ~8 ~124 minecraft:air
fill ~-52 ~4 ~121 ~-49 ~4 ~124 minecraft:smooth_stone
fill ~-52 ~8 ~121 ~-49 ~8 ~124 minecraft:smooth_stone
fill ~-53 ~2 ~122 ~-53 ~3 ~123 minecraft:gray_stained_glass
fill ~-48 ~2 ~122 ~-48 ~3 ~123 minecraft:light_gray_stained_glass
fill ~-53 ~6 ~122 ~-53 ~7 ~123 minecraft:gray_stained_glass
fill ~-48 ~6 ~122 ~-48 ~7 ~123 minecraft:light_gray_stained_glass
fill ~-52 ~0 ~120 ~-49 ~3 ~120 minecraft:spruce_planks
setblock ~-51 ~1 ~120 minecraft:iron_door[half=lower,facing=north]
setblock ~-51 ~2 ~120 minecraft:iron_door[half=upper,facing=north]
fill ~-53 ~10 ~120 ~-48 ~10 ~125 minecraft:deepslate_tile_slab
# 213 detached_house -65,118 -61,124 h=7
fill ~-65 ~-3 ~118 ~-61 ~-1 ~124 minecraft:stone
fill ~-65 ~0 ~118 ~-61 ~7 ~124 minecraft:calcite
fill ~-64 ~1 ~119 ~-62 ~6 ~123 minecraft:air
fill ~-64 ~4 ~119 ~-62 ~4 ~123 minecraft:smooth_stone
fill ~-63 ~2 ~118 ~-63 ~3 ~118 minecraft:gray_stained_glass
fill ~-63 ~2 ~124 ~-63 ~3 ~124 minecraft:light_gray_stained_glass
fill ~-64 ~0 ~118 ~-62 ~3 ~118 minecraft:gray_concrete
setblock ~-63 ~1 ~118 minecraft:iron_door[half=lower,facing=north]
setblock ~-63 ~2 ~118 minecraft:iron_door[half=upper,facing=north]
fill ~-65 ~8 ~118 ~-61 ~8 ~124 minecraft:stone_brick_slab
# 214 detached_house -71,118 -66,123 h=11
fill ~-71 ~-3 ~118 ~-66 ~-1 ~123 minecraft:stone
fill ~-71 ~0 ~118 ~-66 ~11 ~123 minecraft:calcite
fill ~-70 ~1 ~119 ~-67 ~10 ~122 minecraft:air
fill ~-70 ~4 ~119 ~-67 ~4 ~122 minecraft:smooth_stone
fill ~-70 ~8 ~119 ~-67 ~8 ~122 minecraft:smooth_stone
fill ~-69 ~2 ~118 ~-68 ~3 ~118 minecraft:gray_stained_glass
fill ~-69 ~2 ~123 ~-68 ~3 ~123 minecraft:light_gray_stained_glass
fill ~-69 ~6 ~118 ~-68 ~7 ~118 minecraft:gray_stained_glass
fill ~-69 ~6 ~123 ~-68 ~7 ~123 minecraft:light_gray_stained_glass
fill ~-70 ~0 ~118 ~-67 ~3 ~118 minecraft:gray_concrete
setblock ~-69 ~1 ~118 minecraft:iron_door[half=lower,facing=north]
setblock ~-69 ~2 ~118 minecraft:iron_door[half=upper,facing=north]
fill ~-71 ~12 ~118 ~-66 ~12 ~123 minecraft:stone_brick_slab
# 215 row_house -111,120 -104,125 h=9
fill ~-111 ~-3 ~120 ~-104 ~-1 ~125 minecraft:stone
fill ~-111 ~0 ~120 ~-104 ~9 ~125 minecraft:mud_bricks
fill ~-110 ~1 ~121 ~-105 ~8 ~124 minecraft:air
fill ~-110 ~4 ~121 ~-105 ~4 ~124 minecraft:smooth_stone
fill ~-110 ~8 ~121 ~-105 ~8 ~124 minecraft:smooth_stone
fill ~-111 ~2 ~122 ~-111 ~3 ~123 minecraft:gray_stained_glass
fill ~-104 ~2 ~122 ~-104 ~3 ~123 minecraft:light_gray_stained_glass
fill ~-111 ~6 ~122 ~-111 ~7 ~123 minecraft:gray_stained_glass
fill ~-104 ~6 ~122 ~-104 ~7 ~123 minecraft:light_gray_stained_glass
fill ~-110 ~0 ~120 ~-107 ~3 ~120 minecraft:spruce_planks
setblock ~-109 ~1 ~120 minecraft:iron_door[half=lower,facing=north]
setblock ~-109 ~2 ~120 minecraft:iron_door[half=upper,facing=north]
fill ~-111 ~10 ~120 ~-104 ~10 ~125 minecraft:deepslate_tile_slab
# 216 restaurant 48,8 52,13 h=9
fill ~48 ~-3 ~8 ~52 ~-1 ~13 minecraft:stone
fill ~48 ~0 ~8 ~52 ~9 ~13 minecraft:smooth_sandstone
fill ~49 ~1 ~9 ~51 ~8 ~12 minecraft:air
fill ~49 ~4 ~9 ~51 ~4 ~12 minecraft:smooth_stone
fill ~49 ~8 ~9 ~51 ~8 ~12 minecraft:smooth_stone
fill ~50 ~2 ~8 ~50 ~3 ~8 minecraft:gray_stained_glass
fill ~50 ~2 ~13 ~50 ~3 ~13 minecraft:light_gray_stained_glass
fill ~50 ~6 ~8 ~50 ~7 ~8 minecraft:gray_stained_glass
fill ~50 ~6 ~13 ~50 ~7 ~13 minecraft:light_gray_stained_glass
fill ~49 ~0 ~8 ~51 ~3 ~8 minecraft:brown_terracotta
setblock ~50 ~1 ~8 minecraft:iron_door[half=lower,facing=north]
setblock ~50 ~2 ~8 minecraft:iron_door[half=upper,facing=north]
fill ~48 ~10 ~8 ~52 ~10 ~13 minecraft:stone_brick_slab
# 217 row_house -3,101 1,106 h=7
fill ~-3 ~-3 ~101 ~1 ~-1 ~106 minecraft:stone
fill ~-3 ~0 ~101 ~1 ~7 ~106 minecraft:calcite
fill ~-2 ~1 ~102 ~0 ~6 ~105 minecraft:air
fill ~-2 ~4 ~102 ~0 ~4 ~105 minecraft:smooth_stone
fill ~-3 ~2 ~103 ~-3 ~3 ~104 minecraft:gray_stained_glass
fill ~1 ~2 ~103 ~1 ~3 ~104 minecraft:light_gray_stained_glass
fill ~-2 ~0 ~101 ~0 ~3 ~101 minecraft:gray_concrete
setblock ~-1 ~1 ~101 minecraft:iron_door[half=lower,facing=north]
setblock ~-1 ~2 ~101 minecraft:iron_door[half=upper,facing=north]
fill ~-3 ~8 ~101 ~1 ~8 ~106 minecraft:stone_brick_slab
# 218 workshop -71,-14 -67,-8 h=5
fill ~-71 ~-3 ~-14 ~-67 ~-1 ~-8 minecraft:stone
fill ~-71 ~0 ~-14 ~-67 ~5 ~-8 minecraft:smooth_sandstone
fill ~-70 ~1 ~-13 ~-68 ~4 ~-9 minecraft:air
fill ~-70 ~4 ~-13 ~-68 ~4 ~-9 minecraft:smooth_stone
fill ~-69 ~2 ~-14 ~-69 ~3 ~-14 minecraft:gray_stained_glass
fill ~-69 ~2 ~-8 ~-69 ~3 ~-8 minecraft:light_gray_stained_glass
fill ~-70 ~0 ~-14 ~-68 ~3 ~-14 minecraft:brown_terracotta
setblock ~-69 ~1 ~-14 minecraft:iron_door[half=lower,facing=north]
setblock ~-69 ~2 ~-14 minecraft:iron_door[half=upper,facing=north]
fill ~-71 ~6 ~-14 ~-67 ~6 ~-8 minecraft:stone_brick_slab
# 219 warehouse -60,-115 -56,-109 h=8
fill ~-60 ~-3 ~-115 ~-56 ~-1 ~-109 minecraft:stone
fill ~-60 ~0 ~-115 ~-56 ~8 ~-109 minecraft:stone_bricks
fill ~-59 ~1 ~-114 ~-57 ~7 ~-110 minecraft:air
fill ~-59 ~4 ~-114 ~-57 ~4 ~-110 minecraft:smooth_stone
fill ~-60 ~2 ~-113 ~-60 ~3 ~-111 minecraft:gray_stained_glass
fill ~-56 ~2 ~-113 ~-56 ~3 ~-111 minecraft:light_gray_stained_glass
fill ~-60 ~6 ~-113 ~-60 ~7 ~-111 minecraft:gray_stained_glass
fill ~-56 ~6 ~-113 ~-56 ~7 ~-111 minecraft:light_gray_stained_glass
fill ~-59 ~0 ~-115 ~-57 ~3 ~-115 doomsday_decoration:ironsheetwall_2
setblock ~-58 ~1 ~-115 minecraft:iron_door[half=lower,facing=north]
setblock ~-58 ~2 ~-115 minecraft:iron_door[half=upper,facing=north]
fill ~-60 ~9 ~-115 ~-56 ~9 ~-109 minecraft:smooth_stone_slab
# 220 factory 51,119 55,125 h=8
fill ~51 ~-3 ~119 ~55 ~-1 ~125 minecraft:stone
fill ~51 ~0 ~119 ~55 ~8 ~125 minecraft:deepslate_bricks
fill ~52 ~1 ~120 ~54 ~7 ~124 minecraft:air
fill ~52 ~4 ~120 ~54 ~4 ~124 minecraft:smooth_stone
fill ~53 ~2 ~119 ~53 ~3 ~119 minecraft:gray_stained_glass
fill ~53 ~2 ~125 ~53 ~3 ~125 minecraft:light_gray_stained_glass
fill ~53 ~6 ~119 ~53 ~7 ~119 minecraft:gray_stained_glass
fill ~53 ~6 ~125 ~53 ~7 ~125 minecraft:light_gray_stained_glass
fill ~52 ~0 ~119 ~54 ~3 ~119 minecraft:oxidized_cut_copper
setblock ~53 ~1 ~119 minecraft:iron_door[half=lower,facing=north]
setblock ~53 ~2 ~119 minecraft:iron_door[half=upper,facing=north]
fill ~51 ~9 ~119 ~55 ~9 ~125 minecraft:deepslate_tile_slab
# 221 warehouse 40,-114 44,-109 h=10
fill ~40 ~-3 ~-114 ~44 ~-1 ~-109 minecraft:stone
fill ~40 ~0 ~-114 ~44 ~10 ~-109 minecraft:stone_bricks
fill ~41 ~1 ~-113 ~43 ~9 ~-110 minecraft:air
fill ~41 ~4 ~-113 ~43 ~4 ~-110 minecraft:smooth_stone
fill ~41 ~8 ~-113 ~43 ~8 ~-110 minecraft:smooth_stone
fill ~40 ~2 ~-112 ~40 ~3 ~-111 minecraft:gray_stained_glass
fill ~44 ~2 ~-112 ~44 ~3 ~-111 minecraft:light_gray_stained_glass
fill ~40 ~6 ~-112 ~40 ~7 ~-111 minecraft:gray_stained_glass
fill ~44 ~6 ~-112 ~44 ~7 ~-111 minecraft:light_gray_stained_glass
fill ~41 ~0 ~-114 ~43 ~3 ~-114 doomsday_decoration:ironsheetwall_2
setblock ~42 ~1 ~-114 minecraft:iron_door[half=lower,facing=north]
setblock ~42 ~2 ~-114 minecraft:iron_door[half=upper,facing=north]
fill ~40 ~11 ~-114 ~44 ~11 ~-109 minecraft:smooth_stone_slab
# 222 logistics 47,67 51,72 h=6
fill ~47 ~-3 ~67 ~51 ~-1 ~72 minecraft:stone
fill ~47 ~0 ~67 ~51 ~6 ~72 minecraft:deepslate_bricks
fill ~48 ~1 ~68 ~50 ~5 ~71 minecraft:air
fill ~48 ~4 ~68 ~50 ~4 ~71 minecraft:smooth_stone
fill ~47 ~2 ~69 ~47 ~3 ~70 minecraft:gray_stained_glass
fill ~51 ~2 ~69 ~51 ~3 ~70 minecraft:light_gray_stained_glass
fill ~48 ~0 ~67 ~50 ~3 ~67 minecraft:oxidized_cut_copper
setblock ~49 ~1 ~67 minecraft:iron_door[half=lower,facing=north]
setblock ~49 ~2 ~67 minecraft:iron_door[half=upper,facing=north]
fill ~47 ~7 ~67 ~51 ~7 ~72 minecraft:deepslate_tile_slab
# 223 community -76,103 -70,108 h=11
fill ~-76 ~-3 ~103 ~-70 ~-1 ~108 minecraft:stone
fill ~-76 ~0 ~103 ~-70 ~11 ~108 minecraft:white_terracotta
fill ~-75 ~1 ~104 ~-71 ~10 ~107 minecraft:air
fill ~-75 ~4 ~104 ~-71 ~4 ~107 minecraft:smooth_stone
fill ~-75 ~8 ~104 ~-71 ~8 ~107 minecraft:smooth_stone
fill ~-76 ~2 ~105 ~-76 ~3 ~106 minecraft:gray_stained_glass
fill ~-70 ~2 ~105 ~-70 ~3 ~106 minecraft:light_gray_stained_glass
fill ~-76 ~6 ~105 ~-76 ~7 ~106 minecraft:gray_stained_glass
fill ~-70 ~6 ~105 ~-70 ~7 ~106 minecraft:light_gray_stained_glass
fill ~-75 ~0 ~103 ~-72 ~3 ~103 minecraft:dark_oak_planks
setblock ~-74 ~1 ~103 minecraft:iron_door[half=lower,facing=north]
setblock ~-74 ~2 ~103 minecraft:iron_door[half=upper,facing=north]
fill ~-76 ~12 ~103 ~-70 ~12 ~108 minecraft:dark_oak_slab
# 224 restaurant -69,-44 -65,-37 h=9
fill ~-69 ~-3 ~-44 ~-65 ~-1 ~-37 minecraft:stone
fill ~-69 ~0 ~-44 ~-65 ~9 ~-37 minecraft:light_gray_concrete
fill ~-68 ~1 ~-43 ~-66 ~8 ~-38 minecraft:air
fill ~-68 ~4 ~-43 ~-66 ~4 ~-38 minecraft:smooth_stone
fill ~-68 ~8 ~-43 ~-66 ~8 ~-38 minecraft:smooth_stone
fill ~-69 ~2 ~-42 ~-69 ~3 ~-39 minecraft:gray_stained_glass
fill ~-65 ~2 ~-42 ~-65 ~3 ~-39 minecraft:light_gray_stained_glass
fill ~-69 ~6 ~-42 ~-69 ~7 ~-39 minecraft:gray_stained_glass
fill ~-65 ~6 ~-42 ~-65 ~7 ~-39 minecraft:light_gray_stained_glass
fill ~-68 ~0 ~-44 ~-66 ~3 ~-44 doomsday_decoration:porcelainbrickwall
setblock ~-67 ~1 ~-44 minecraft:iron_door[half=lower,facing=north]
setblock ~-67 ~2 ~-44 minecraft:iron_door[half=upper,facing=north]
fill ~-69 ~10 ~-44 ~-65 ~10 ~-37 minecraft:smooth_stone_slab
# 225 garage 76,51 80,56 h=10
fill ~76 ~-3 ~51 ~80 ~-1 ~56 minecraft:stone
fill ~76 ~0 ~51 ~80 ~10 ~56 minecraft:stone_bricks
fill ~77 ~1 ~52 ~79 ~9 ~55 minecraft:air
fill ~77 ~4 ~52 ~79 ~4 ~55 minecraft:smooth_stone
fill ~77 ~8 ~52 ~79 ~8 ~55 minecraft:smooth_stone
fill ~76 ~2 ~53 ~76 ~3 ~54 minecraft:gray_stained_glass
fill ~80 ~2 ~53 ~80 ~3 ~54 minecraft:light_gray_stained_glass
fill ~76 ~6 ~53 ~76 ~7 ~54 minecraft:gray_stained_glass
fill ~80 ~6 ~53 ~80 ~7 ~54 minecraft:light_gray_stained_glass
fill ~77 ~0 ~51 ~79 ~3 ~51 minecraft:orange_terracotta
setblock ~78 ~1 ~51 minecraft:iron_door[half=lower,facing=north]
setblock ~78 ~2 ~51 minecraft:iron_door[half=upper,facing=north]
fill ~76 ~11 ~51 ~80 ~11 ~56 minecraft:stone_brick_slab
