# Buildings 169..176
# 169 midrise_housing style=balcony_block context=arterial_front facing=north
fill ~-41 ~-3 ~-53 ~-34 ~-1 ~-48 minecraft:stone
fill ~-41 ~0 ~-53 ~-34 ~7 ~-48 minecraft:light_gray_concrete
fill ~-40 ~1 ~-52 ~-35 ~6 ~-49 minecraft:air
fill ~-40 ~4 ~-52 ~-35 ~4 ~-49 minecraft:smooth_stone
fill ~-39 ~2 ~-53 ~-39 ~3 ~-53 minecraft:gray_stained_glass
fill ~-39 ~2 ~-48 ~-39 ~3 ~-48 minecraft:light_gray_stained_glass
fill ~-36 ~2 ~-53 ~-36 ~3 ~-53 minecraft:gray_stained_glass
fill ~-36 ~2 ~-48 ~-36 ~3 ~-48 minecraft:light_gray_stained_glass
fill ~-41 ~2 ~-51 ~-41 ~3 ~-51 minecraft:gray_stained_glass
fill ~-34 ~2 ~-51 ~-34 ~3 ~-51 minecraft:light_gray_stained_glass
setblock ~-38 ~1 ~-53 minecraft:iron_door[half=lower,facing=north]
setblock ~-38 ~2 ~-53 minecraft:iron_door[half=upper,facing=north]
fill ~-39 ~4 ~-54 ~-36 ~4 ~-54 minecraft:smooth_stone_slab
fill ~-41 ~8 ~-53 ~-34 ~8 ~-48 minecraft:smooth_stone_slab
# 170 warehouse style=sawtooth context=collector_front facing=north
fill ~78 ~-3 ~75 ~82 ~-1 ~80 minecraft:stone
fill ~78 ~0 ~75 ~82 ~10 ~80 minecraft:gray_concrete
fill ~79 ~1 ~76 ~81 ~9 ~79 minecraft:air
fill ~79 ~4 ~76 ~81 ~4 ~79 minecraft:smooth_stone
fill ~79 ~8 ~76 ~81 ~8 ~79 minecraft:smooth_stone
fill ~80 ~2 ~75 ~80 ~3 ~75 minecraft:gray_stained_glass
fill ~80 ~2 ~80 ~80 ~3 ~80 minecraft:light_gray_stained_glass
fill ~78 ~2 ~77 ~78 ~3 ~77 minecraft:gray_stained_glass
fill ~82 ~2 ~77 ~82 ~3 ~77 minecraft:light_gray_stained_glass
fill ~80 ~6 ~75 ~80 ~7 ~75 minecraft:gray_stained_glass
fill ~80 ~6 ~80 ~80 ~7 ~80 minecraft:light_gray_stained_glass
fill ~78 ~6 ~77 ~78 ~7 ~77 minecraft:gray_stained_glass
fill ~82 ~6 ~77 ~82 ~7 ~77 minecraft:light_gray_stained_glass
setblock ~80 ~1 ~75 minecraft:iron_door[half=lower,facing=north]
setblock ~80 ~2 ~75 minecraft:iron_door[half=upper,facing=north]
fill ~80 ~1 ~75 ~80 ~4 ~75 minecraft:polished_blackstone
fill ~80 ~5 ~75 ~80 ~5 ~75 minecraft:light_blue_stained_glass
fill ~80 ~12 ~77 ~81 ~13 ~79 minecraft:iron_block
fill ~78 ~11 ~75 ~82 ~11 ~80 minecraft:smooth_stone_slab
# 171 mixed_use style=mixed_facade context=arterial_front facing=west
fill ~50 ~-3 ~119 ~54 ~-1 ~125 minecraft:stone
fill ~50 ~0 ~119 ~54 ~6 ~125 minecraft:stone_bricks
fill ~51 ~1 ~120 ~53 ~5 ~124 minecraft:air
fill ~51 ~4 ~120 ~53 ~4 ~124 minecraft:smooth_stone
fill ~52 ~2 ~119 ~52 ~3 ~119 minecraft:gray_stained_glass
fill ~52 ~2 ~125 ~52 ~3 ~125 minecraft:light_gray_stained_glass
fill ~50 ~2 ~121 ~50 ~3 ~121 minecraft:gray_stained_glass
fill ~54 ~2 ~121 ~54 ~3 ~121 minecraft:light_gray_stained_glass
setblock ~50 ~1 ~122 minecraft:iron_door[half=lower,facing=west]
setblock ~50 ~2 ~122 minecraft:iron_door[half=upper,facing=west]
fill ~50 ~7 ~119 ~54 ~7 ~125 minecraft:stone_brick_slab
# 172 midrise_housing style=mixed_facade context=collector_front facing=east
fill ~46 ~-3 ~-29 ~50 ~-1 ~-24 minecraft:stone
fill ~46 ~0 ~-29 ~50 ~5 ~-24 minecraft:light_gray_concrete
fill ~47 ~1 ~-28 ~49 ~4 ~-25 minecraft:air
fill ~47 ~4 ~-28 ~49 ~4 ~-25 minecraft:smooth_stone
fill ~48 ~2 ~-29 ~48 ~3 ~-29 minecraft:gray_stained_glass
fill ~48 ~2 ~-24 ~48 ~3 ~-24 minecraft:light_gray_stained_glass
fill ~46 ~2 ~-27 ~46 ~3 ~-27 minecraft:gray_stained_glass
fill ~50 ~2 ~-27 ~50 ~3 ~-27 minecraft:light_gray_stained_glass
setblock ~50 ~1 ~-27 minecraft:iron_door[half=lower,facing=east]
setblock ~50 ~2 ~-27 minecraft:iron_door[half=upper,facing=east]
fill ~46 ~6 ~-29 ~50 ~6 ~-24 minecraft:smooth_stone_slab
# 173 workshop style=industrial_shed context=back_block facing=east
fill ~-8 ~-3 ~119 ~-4 ~-1 ~124 minecraft:stone
fill ~-8 ~0 ~119 ~-4 ~11 ~124 minecraft:calcite
fill ~-7 ~1 ~120 ~-5 ~10 ~123 minecraft:air
fill ~-7 ~4 ~120 ~-5 ~4 ~123 minecraft:smooth_stone
fill ~-7 ~8 ~120 ~-5 ~8 ~123 minecraft:smooth_stone
fill ~-6 ~2 ~119 ~-6 ~3 ~119 minecraft:gray_stained_glass
fill ~-6 ~2 ~124 ~-6 ~3 ~124 minecraft:light_gray_stained_glass
fill ~-8 ~2 ~121 ~-8 ~3 ~121 minecraft:gray_stained_glass
fill ~-4 ~2 ~121 ~-4 ~3 ~121 minecraft:light_gray_stained_glass
fill ~-6 ~6 ~119 ~-6 ~7 ~119 minecraft:gray_stained_glass
fill ~-6 ~6 ~124 ~-6 ~7 ~124 minecraft:light_gray_stained_glass
fill ~-8 ~6 ~121 ~-8 ~7 ~121 minecraft:gray_stained_glass
fill ~-4 ~6 ~121 ~-4 ~7 ~121 minecraft:light_gray_stained_glass
setblock ~-4 ~1 ~121 minecraft:iron_door[half=lower,facing=east]
setblock ~-4 ~2 ~121 minecraft:iron_door[half=upper,facing=east]
fill ~-4 ~1 ~121 ~-4 ~4 ~122 minecraft:polished_blackstone
fill ~-4 ~5 ~121 ~-4 ~5 ~122 minecraft:light_blue_stained_glass
fill ~-6 ~13 ~121 ~-5 ~14 ~123 minecraft:iron_block
fill ~-8 ~12 ~119 ~-4 ~12 ~124 minecraft:stone_brick_slab
# 174 garage style=loading_bay context=collector_front facing=east
fill ~43 ~-3 ~-125 ~47 ~-1 ~-117 minecraft:stone
fill ~43 ~0 ~-125 ~47 ~10 ~-117 minecraft:bricks
fill ~44 ~1 ~-124 ~46 ~9 ~-118 minecraft:air
fill ~44 ~4 ~-124 ~46 ~4 ~-118 minecraft:smooth_stone
fill ~44 ~8 ~-124 ~46 ~8 ~-118 minecraft:smooth_stone
fill ~45 ~2 ~-125 ~45 ~3 ~-125 minecraft:gray_stained_glass
fill ~45 ~2 ~-117 ~45 ~3 ~-117 minecraft:light_gray_stained_glass
fill ~43 ~2 ~-123 ~43 ~3 ~-123 minecraft:gray_stained_glass
fill ~47 ~2 ~-123 ~47 ~3 ~-123 minecraft:light_gray_stained_glass
fill ~43 ~2 ~-120 ~43 ~3 ~-120 minecraft:gray_stained_glass
fill ~47 ~2 ~-120 ~47 ~3 ~-120 minecraft:light_gray_stained_glass
fill ~45 ~6 ~-125 ~45 ~7 ~-125 minecraft:gray_stained_glass
fill ~45 ~6 ~-117 ~45 ~7 ~-117 minecraft:light_gray_stained_glass
fill ~43 ~6 ~-123 ~43 ~7 ~-123 minecraft:gray_stained_glass
fill ~47 ~6 ~-123 ~47 ~7 ~-123 minecraft:light_gray_stained_glass
fill ~43 ~6 ~-120 ~43 ~7 ~-120 minecraft:gray_stained_glass
fill ~47 ~6 ~-120 ~47 ~7 ~-120 minecraft:light_gray_stained_glass
setblock ~47 ~1 ~-121 minecraft:iron_door[half=lower,facing=east]
setblock ~47 ~2 ~-121 minecraft:iron_door[half=upper,facing=east]
fill ~47 ~1 ~-123 ~47 ~4 ~-119 minecraft:polished_blackstone
fill ~47 ~5 ~-123 ~47 ~5 ~-119 minecraft:light_blue_stained_glass
fill ~45 ~12 ~-123 ~46 ~13 ~-121 minecraft:iron_block
fill ~43 ~11 ~-125 ~47 ~11 ~-117 minecraft:deepslate_tile_slab
fill ~45 ~12 ~-123 ~46 ~13 ~-121 minecraft:light_gray_concrete
setblock ~46 ~12 ~-122 minecraft:lightning_rod
# 175 factory style=industrial_shed context=local_front facing=west
fill ~48 ~-3 ~63 ~52 ~-1 ~68 minecraft:stone
fill ~48 ~0 ~63 ~52 ~10 ~68 minecraft:deepslate_bricks
fill ~49 ~1 ~64 ~51 ~9 ~67 minecraft:air
fill ~49 ~4 ~64 ~51 ~4 ~67 minecraft:smooth_stone
fill ~49 ~8 ~64 ~51 ~8 ~67 minecraft:smooth_stone
fill ~50 ~2 ~63 ~50 ~3 ~63 minecraft:gray_stained_glass
fill ~50 ~2 ~68 ~50 ~3 ~68 minecraft:light_gray_stained_glass
fill ~48 ~2 ~65 ~48 ~3 ~65 minecraft:gray_stained_glass
fill ~52 ~2 ~65 ~52 ~3 ~65 minecraft:light_gray_stained_glass
fill ~50 ~6 ~63 ~50 ~7 ~63 minecraft:gray_stained_glass
fill ~50 ~6 ~68 ~50 ~7 ~68 minecraft:light_gray_stained_glass
fill ~48 ~6 ~65 ~48 ~7 ~65 minecraft:gray_stained_glass
fill ~52 ~6 ~65 ~52 ~7 ~65 minecraft:light_gray_stained_glass
setblock ~48 ~1 ~65 minecraft:iron_door[half=lower,facing=west]
setblock ~48 ~2 ~65 minecraft:iron_door[half=upper,facing=west]
fill ~48 ~1 ~65 ~48 ~4 ~66 minecraft:polished_blackstone
fill ~48 ~5 ~65 ~48 ~5 ~66 minecraft:light_blue_stained_glass
fill ~50 ~12 ~65 ~51 ~13 ~67 minecraft:iron_block
fill ~48 ~11 ~63 ~52 ~11 ~68 minecraft:deepslate_tile_slab
# 176 factory style=sawtooth context=collector_front facing=east
fill ~82 ~-3 ~41 ~86 ~-1 ~51 minecraft:stone
fill ~82 ~0 ~41 ~86 ~8 ~51 minecraft:deepslate_bricks
fill ~83 ~1 ~42 ~85 ~7 ~50 minecraft:air
fill ~83 ~4 ~42 ~85 ~4 ~50 minecraft:smooth_stone
fill ~84 ~2 ~41 ~84 ~3 ~41 minecraft:gray_stained_glass
fill ~84 ~2 ~51 ~84 ~3 ~51 minecraft:light_gray_stained_glass
fill ~82 ~2 ~43 ~82 ~3 ~43 minecraft:gray_stained_glass
fill ~86 ~2 ~43 ~86 ~3 ~43 minecraft:light_gray_stained_glass
fill ~82 ~2 ~46 ~82 ~3 ~46 minecraft:gray_stained_glass
fill ~86 ~2 ~46 ~86 ~3 ~46 minecraft:light_gray_stained_glass
fill ~82 ~2 ~49 ~82 ~3 ~49 minecraft:gray_stained_glass
fill ~86 ~2 ~49 ~86 ~3 ~49 minecraft:light_gray_stained_glass
fill ~84 ~6 ~41 ~84 ~7 ~41 minecraft:gray_stained_glass
fill ~84 ~6 ~51 ~84 ~7 ~51 minecraft:light_gray_stained_glass
fill ~82 ~6 ~43 ~82 ~7 ~43 minecraft:gray_stained_glass
fill ~86 ~6 ~43 ~86 ~7 ~43 minecraft:light_gray_stained_glass
fill ~82 ~6 ~46 ~82 ~7 ~46 minecraft:gray_stained_glass
fill ~86 ~6 ~46 ~86 ~7 ~46 minecraft:light_gray_stained_glass
fill ~82 ~6 ~49 ~82 ~7 ~49 minecraft:gray_stained_glass
fill ~86 ~6 ~49 ~86 ~7 ~49 minecraft:light_gray_stained_glass
setblock ~86 ~1 ~46 minecraft:iron_door[half=lower,facing=east]
setblock ~86 ~2 ~46 minecraft:iron_door[half=upper,facing=east]
fill ~86 ~1 ~43 ~86 ~4 ~49 minecraft:polished_blackstone
fill ~86 ~5 ~43 ~86 ~5 ~49 minecraft:light_blue_stained_glass
fill ~84 ~10 ~43 ~85 ~11 ~45 minecraft:iron_block
fill ~82 ~9 ~41 ~86 ~9 ~51 minecraft:deepslate_tile_slab
