setblock ~80 ~15 ~-101 minecraft:gray_stained_glass_pane
setblock ~86 ~15 ~-101 minecraft:gray_stained_glass_pane
setblock ~83 ~2 ~-98 minecraft:dark_oak_door[half=lower]
setblock ~83 ~3 ~-98 minecraft:dark_oak_door[half=upper]
fill ~-98 ~1 ~71 ~-92 ~16 ~80 minecraft:mud_bricks
fill ~-97 ~2 ~72 ~-93 ~15 ~79 minecraft:air
fill ~-97 ~4 ~72 ~-93 ~4 ~79 minecraft:smooth_stone
fill ~-97 ~8 ~72 ~-93 ~8 ~79 minecraft:smooth_stone
fill ~-97 ~12 ~72 ~-93 ~12 ~79 minecraft:smooth_stone
fill ~-98 ~17 ~71 ~-92 ~17 ~80 minecraft:dark_oak_planks
setblock ~-96 ~3 ~71 minecraft:gray_stained_glass_pane
setblock ~-96 ~3 ~80 minecraft:gray_stained_glass_pane
setblock ~-98 ~3 ~73 minecraft:gray_stained_glass_pane
setblock ~-92 ~3 ~73 minecraft:gray_stained_glass_pane
setblock ~-98 ~3 ~76 minecraft:gray_stained_glass_pane
setblock ~-92 ~3 ~76 minecraft:gray_stained_glass_pane
setblock ~-96 ~7 ~71 minecraft:gray_stained_glass_pane
setblock ~-96 ~7 ~80 minecraft:gray_stained_glass_pane
setblock ~-98 ~7 ~73 minecraft:gray_stained_glass_pane
setblock ~-92 ~7 ~73 minecraft:gray_stained_glass_pane
setblock ~-98 ~7 ~76 minecraft:gray_stained_glass_pane
setblock ~-92 ~7 ~76 minecraft:gray_stained_glass_pane
setblock ~-96 ~11 ~71 minecraft:gray_stained_glass_pane
setblock ~-96 ~11 ~80 minecraft:gray_stained_glass_pane
setblock ~-98 ~11 ~73 minecraft:gray_stained_glass_pane
setblock ~-92 ~11 ~73 minecraft:gray_stained_glass_pane
setblock ~-98 ~11 ~76 minecraft:gray_stained_glass_pane
setblock ~-92 ~11 ~76 minecraft:gray_stained_glass_pane
setblock ~-96 ~15 ~71 minecraft:gray_stained_glass_pane
setblock ~-96 ~15 ~80 minecraft:gray_stained_glass_pane
setblock ~-98 ~15 ~73 minecraft:gray_stained_glass_pane
setblock ~-92 ~15 ~73 minecraft:gray_stained_glass_pane
setblock ~-98 ~15 ~76 minecraft:gray_stained_glass_pane
setblock ~-92 ~15 ~76 minecraft:gray_stained_glass_pane
setblock ~-98 ~2 ~76 minecraft:dark_oak_door[half=lower]
setblock ~-98 ~3 ~76 minecraft:dark_oak_door[half=upper]
fill ~27 ~1 ~8 ~36 ~16 ~16 minecraft:mud_bricks
fill ~28 ~2 ~9 ~35 ~15 ~15 minecraft:air
fill ~28 ~4 ~9 ~35 ~4 ~15 minecraft:smooth_stone
fill ~28 ~8 ~9 ~35 ~8 ~15 minecraft:smooth_stone
fill ~28 ~12 ~9 ~35 ~12 ~15 minecraft:smooth_stone
fill ~27 ~17 ~8 ~36 ~17 ~16 minecraft:dark_oak_planks
fill ~27 ~1 ~17 ~32 ~12 ~24 minecraft:mud_bricks
fill ~28 ~2 ~18 ~31 ~11 ~23 minecraft:air
fill ~28 ~4 ~18 ~31 ~4 ~23 minecraft:smooth_stone
fill ~28 ~8 ~18 ~31 ~8 ~23 minecraft:smooth_stone
fill ~27 ~13 ~17 ~32 ~13 ~24 minecraft:dark_oak_planks
setblock ~29 ~3 ~8 minecraft:gray_stained_glass_pane
setblock ~29 ~3 ~24 minecraft:gray_stained_glass_pane
setblock ~32 ~3 ~8 minecraft:gray_stained_glass_pane
setblock ~32 ~3 ~24 minecraft:gray_stained_glass_pane
setblock ~27 ~3 ~10 minecraft:gray_stained_glass_pane
setblock ~36 ~3 ~10 minecraft:gray_stained_glass_pane
setblock ~27 ~3 ~13 minecraft:gray_stained_glass_pane
setblock ~36 ~3 ~13 minecraft:gray_stained_glass_pane
setblock ~27 ~3 ~16 minecraft:gray_stained_glass_pane
setblock ~36 ~3 ~16 minecraft:gray_stained_glass_pane
setblock ~27 ~3 ~19 minecraft:gray_stained_glass_pane
setblock ~36 ~3 ~19 minecraft:gray_stained_glass_pane
setblock ~27 ~3 ~22 minecraft:gray_stained_glass_pane
setblock ~36 ~3 ~22 minecraft:gray_stained_glass_pane
setblock ~29 ~7 ~8 minecraft:gray_stained_glass_pane
setblock ~29 ~7 ~24 minecraft:gray_stained_glass_pane
setblock ~32 ~7 ~8 minecraft:gray_stained_glass_pane
setblock ~32 ~7 ~24 minecraft:gray_stained_glass_pane
setblock ~27 ~7 ~10 minecraft:gray_stained_glass_pane
setblock ~36 ~7 ~10 minecraft:gray_stained_glass_pane
setblock ~27 ~7 ~13 minecraft:gray_stained_glass_pane
setblock ~36 ~7 ~13 minecraft:gray_stained_glass_pane
setblock ~27 ~7 ~16 minecraft:gray_stained_glass_pane
setblock ~36 ~7 ~16 minecraft:gray_stained_glass_pane
setblock ~27 ~7 ~19 minecraft:gray_stained_glass_pane
setblock ~36 ~7 ~19 minecraft:gray_stained_glass_pane
setblock ~27 ~7 ~22 minecraft:gray_stained_glass_pane
setblock ~36 ~7 ~22 minecraft:gray_stained_glass_pane
setblock ~29 ~11 ~8 minecraft:gray_stained_glass_pane
setblock ~29 ~11 ~24 minecraft:gray_stained_glass_pane
setblock ~32 ~11 ~8 minecraft:gray_stained_glass_pane
setblock ~32 ~11 ~24 minecraft:gray_stained_glass_pane
setblock ~27 ~11 ~10 minecraft:gray_stained_glass_pane
setblock ~36 ~11 ~10 minecraft:gray_stained_glass_pane
setblock ~27 ~11 ~13 minecraft:gray_stained_glass_pane
setblock ~36 ~11 ~13 minecraft:gray_stained_glass_pane
setblock ~27 ~11 ~16 minecraft:gray_stained_glass_pane
setblock ~36 ~11 ~16 minecraft:gray_stained_glass_pane
setblock ~27 ~11 ~19 minecraft:gray_stained_glass_pane
setblock ~36 ~11 ~19 minecraft:gray_stained_glass_pane
setblock ~27 ~11 ~22 minecraft:gray_stained_glass_pane
setblock ~36 ~11 ~22 minecraft:gray_stained_glass_pane
setblock ~29 ~15 ~8 minecraft:gray_stained_glass_pane
setblock ~29 ~15 ~24 minecraft:gray_stained_glass_pane
setblock ~32 ~15 ~8 minecraft:gray_stained_glass_pane
setblock ~32 ~15 ~24 minecraft:gray_stained_glass_pane
setblock ~27 ~15 ~10 minecraft:gray_stained_glass_pane
setblock ~36 ~15 ~10 minecraft:gray_stained_glass_pane
setblock ~27 ~15 ~13 minecraft:gray_stained_glass_pane
setblock ~36 ~15 ~13 minecraft:gray_stained_glass_pane
setblock ~27 ~15 ~16 minecraft:gray_stained_glass_pane
setblock ~36 ~15 ~16 minecraft:gray_stained_glass_pane
setblock ~27 ~15 ~19 minecraft:gray_stained_glass_pane
setblock ~36 ~15 ~19 minecraft:gray_stained_glass_pane
setblock ~27 ~15 ~22 minecraft:gray_stained_glass_pane
setblock ~36 ~15 ~22 minecraft:gray_stained_glass_pane
setblock ~27 ~2 ~16 minecraft:dark_oak_door[half=lower]
setblock ~27 ~3 ~16 minecraft:dark_oak_door[half=upper]
setblock ~27 ~2 ~9 minecraft:cyan_stained_glass
setblock ~27 ~2 ~11 minecraft:cyan_stained_glass
setblock ~27 ~2 ~13 minecraft:cyan_stained_glass
setblock ~27 ~2 ~15 minecraft:cyan_stained_glass
setblock ~27 ~2 ~17 minecraft:cyan_stained_glass
setblock ~27 ~2 ~19 minecraft:cyan_stained_glass
setblock ~27 ~2 ~21 minecraft:cyan_stained_glass
setblock ~27 ~2 ~23 minecraft:cyan_stained_glass
fill ~-96 ~1 ~-124 ~-90 ~16 ~-118 minecraft:calcite
fill ~-95 ~2 ~-123 ~-91 ~15 ~-119 minecraft:air
fill ~-95 ~4 ~-123 ~-91 ~4 ~-119 minecraft:smooth_stone
fill ~-95 ~8 ~-123 ~-91 ~8 ~-119 minecraft:smooth_stone
fill ~-95 ~12 ~-123 ~-91 ~12 ~-119 minecraft:smooth_stone
fill ~-96 ~17 ~-124 ~-90 ~17 ~-118 minecraft:cyan_terracotta
setblock ~-94 ~3 ~-124 minecraft:gray_stained_glass_pane
setblock ~-94 ~3 ~-118 minecraft:gray_stained_glass_pane
setblock ~-96 ~3 ~-122 minecraft:gray_stained_glass_pane
setblock ~-90 ~3 ~-122 minecraft:gray_stained_glass_pane
setblock ~-94 ~7 ~-124 minecraft:gray_stained_glass_pane
setblock ~-94 ~7 ~-118 minecraft:gray_stained_glass_pane
setblock ~-96 ~7 ~-122 minecraft:gray_stained_glass_pane
setblock ~-90 ~7 ~-122 minecraft:gray_stained_glass_pane
setblock ~-94 ~11 ~-124 minecraft:gray_stained_glass_pane
setblock ~-94 ~11 ~-118 minecraft:gray_stained_glass_pane
setblock ~-96 ~11 ~-122 minecraft:gray_stained_glass_pane
setblock ~-90 ~11 ~-122 minecraft:gray_stained_glass_pane
setblock ~-94 ~15 ~-124 minecraft:gray_stained_glass_pane
setblock ~-94 ~15 ~-118 minecraft:gray_stained_glass_pane
setblock ~-96 ~15 ~-122 minecraft:gray_stained_glass_pane
setblock ~-90 ~15 ~-122 minecraft:gray_stained_glass_pane
setblock ~-93 ~2 ~-118 minecraft:dark_oak_door[half=lower]
setblock ~-93 ~3 ~-118 minecraft:dark_oak_door[half=upper]
fill ~-58 ~1 ~-124 ~-51 ~12 ~-118 minecraft:bricks
fill ~-57 ~2 ~-123 ~-52 ~11 ~-119 minecraft:air
fill ~-57 ~4 ~-123 ~-52 ~4 ~-119 minecraft:smooth_stone
fill ~-57 ~8 ~-123 ~-52 ~8 ~-119 minecraft:smooth_stone
fill ~-58 ~13 ~-124 ~-51 ~13 ~-118 minecraft:polished_andesite
setblock ~-56 ~3 ~-124 minecraft:gray_stained_glass_pane
setblock ~-56 ~3 ~-118 minecraft:gray_stained_glass_pane
setblock ~-53 ~3 ~-124 minecraft:gray_stained_glass_pane
setblock ~-53 ~3 ~-118 minecraft:gray_stained_glass_pane
setblock ~-58 ~3 ~-122 minecraft:gray_stained_glass_pane
setblock ~-51 ~3 ~-122 minecraft:gray_stained_glass_pane
setblock ~-56 ~7 ~-124 minecraft:gray_stained_glass_pane
setblock ~-56 ~7 ~-118 minecraft:gray_stained_glass_pane
setblock ~-53 ~7 ~-124 minecraft:gray_stained_glass_pane
setblock ~-53 ~7 ~-118 minecraft:gray_stained_glass_pane
setblock ~-58 ~7 ~-122 minecraft:gray_stained_glass_pane
setblock ~-51 ~7 ~-122 minecraft:gray_stained_glass_pane
setblock ~-56 ~11 ~-124 minecraft:gray_stained_glass_pane
setblock ~-56 ~11 ~-118 minecraft:gray_stained_glass_pane
setblock ~-53 ~11 ~-124 minecraft:gray_stained_glass_pane
setblock ~-53 ~11 ~-118 minecraft:gray_stained_glass_pane
setblock ~-58 ~11 ~-122 minecraft:gray_stained_glass_pane
setblock ~-51 ~11 ~-122 minecraft:gray_stained_glass_pane
setblock ~-54 ~2 ~-118 minecraft:dark_oak_door[half=lower]
setblock ~-54 ~3 ~-118 minecraft:dark_oak_door[half=upper]
setblock ~-57 ~2 ~-118 minecraft:cyan_stained_glass
setblock ~-55 ~2 ~-118 minecraft:cyan_stained_glass
setblock ~-53 ~2 ~-118 minecraft:cyan_stained_glass
fill ~-82 ~1 ~109 ~-76 ~12 ~115 minecraft:stone_bricks
fill ~-81 ~2 ~110 ~-77 ~11 ~114 minecraft:air
fill ~-81 ~4 ~110 ~-77 ~4 ~114 minecraft:smooth_stone
fill ~-81 ~8 ~110 ~-77 ~8 ~114 minecraft:smooth_stone
fill ~-82 ~13 ~109 ~-76 ~13 ~115 minecraft:deepslate_bricks
setblock ~-80 ~3 ~109 minecraft:gray_stained_glass_pane
setblock ~-80 ~3 ~115 minecraft:gray_stained_glass_pane
setblock ~-82 ~3 ~111 minecraft:gray_stained_glass_pane
setblock ~-76 ~3 ~111 minecraft:gray_stained_glass_pane
setblock ~-80 ~7 ~109 minecraft:gray_stained_glass_pane
setblock ~-80 ~7 ~115 minecraft:gray_stained_glass_pane
setblock ~-82 ~7 ~111 minecraft:gray_stained_glass_pane
setblock ~-76 ~7 ~111 minecraft:gray_stained_glass_pane
setblock ~-80 ~11 ~109 minecraft:gray_stained_glass_pane
setblock ~-80 ~11 ~115 minecraft:gray_stained_glass_pane
setblock ~-82 ~11 ~111 minecraft:gray_stained_glass_pane
setblock ~-76 ~11 ~111 minecraft:gray_stained_glass_pane
setblock ~-79 ~2 ~109 minecraft:dark_oak_door[half=lower]
setblock ~-79 ~3 ~109 minecraft:dark_oak_door[half=upper]
setblock ~-81 ~2 ~109 minecraft:cyan_stained_glass
setblock ~-79 ~2 ~109 minecraft:cyan_stained_glass
setblock ~-77 ~2 ~109 minecraft:cyan_stained_glass
fill ~-82 ~14 ~109 ~-76 ~14 ~115 minecraft:deepslate_tile_slab
fill ~-81 ~15 ~110 ~-77 ~15 ~114 minecraft:deepslate_tile_slab
fill ~-114 ~1 ~109 ~-107 ~16 ~116 minecraft:mud_bricks
fill ~-113 ~2 ~110 ~-108 ~15 ~115 minecraft:air
fill ~-113 ~4 ~110 ~-108 ~4 ~115 minecraft:smooth_stone
fill ~-113 ~8 ~110 ~-108 ~8 ~115 minecraft:smooth_stone
fill ~-113 ~12 ~110 ~-108 ~12 ~115 minecraft:smooth_stone
fill ~-114 ~17 ~109 ~-107 ~17 ~116 minecraft:dark_oak_planks
setblock ~-112 ~3 ~109 minecraft:gray_stained_glass_pane
setblock ~-112 ~3 ~116 minecraft:gray_stained_glass_pane
setblock ~-109 ~3 ~109 minecraft:gray_stained_glass_pane
setblock ~-109 ~3 ~116 minecraft:gray_stained_glass_pane
setblock ~-114 ~3 ~111 minecraft:gray_stained_glass_pane
setblock ~-107 ~3 ~111 minecraft:gray_stained_glass_pane
setblock ~-114 ~3 ~114 minecraft:gray_stained_glass_pane
setblock ~-107 ~3 ~114 minecraft:gray_stained_glass_pane
setblock ~-112 ~7 ~109 minecraft:gray_stained_glass_pane
setblock ~-112 ~7 ~116 minecraft:gray_stained_glass_pane
setblock ~-109 ~7 ~109 minecraft:gray_stained_glass_pane
setblock ~-109 ~7 ~116 minecraft:gray_stained_glass_pane
setblock ~-114 ~7 ~111 minecraft:gray_stained_glass_pane
setblock ~-107 ~7 ~111 minecraft:gray_stained_glass_pane
setblock ~-114 ~7 ~114 minecraft:gray_stained_glass_pane
setblock ~-107 ~7 ~114 minecraft:gray_stained_glass_pane
setblock ~-112 ~11 ~109 minecraft:gray_stained_glass_pane
setblock ~-112 ~11 ~116 minecraft:gray_stained_glass_pane
setblock ~-109 ~11 ~109 minecraft:gray_stained_glass_pane
setblock ~-109 ~11 ~116 minecraft:gray_stained_glass_pane
setblock ~-114 ~11 ~111 minecraft:gray_stained_glass_pane
setblock ~-107 ~11 ~111 minecraft:gray_stained_glass_pane
setblock ~-114 ~11 ~114 minecraft:gray_stained_glass_pane
setblock ~-107 ~11 ~114 minecraft:gray_stained_glass_pane
setblock ~-112 ~15 ~109 minecraft:gray_stained_glass_pane
setblock ~-112 ~15 ~116 minecraft:gray_stained_glass_pane
setblock ~-109 ~15 ~109 minecraft:gray_stained_glass_pane
setblock ~-109 ~15 ~116 minecraft:gray_stained_glass_pane
setblock ~-114 ~15 ~111 minecraft:gray_stained_glass_pane
setblock ~-107 ~15 ~111 minecraft:gray_stained_glass_pane
setblock ~-114 ~15 ~114 minecraft:gray_stained_glass_pane
setblock ~-107 ~15 ~114 minecraft:gray_stained_glass_pane
setblock ~-110 ~2 ~109 minecraft:dark_oak_door[half=lower]
setblock ~-110 ~3 ~109 minecraft:dark_oak_door[half=upper]
fill ~43 ~1 ~-29 ~54 ~28 ~-17 minecraft:mud_bricks
fill ~44 ~2 ~-28 ~53 ~27 ~-18 minecraft:air
fill ~44 ~4 ~-28 ~53 ~4 ~-18 minecraft:smooth_stone
fill ~44 ~8 ~-28 ~53 ~8 ~-18 minecraft:smooth_stone
fill ~44 ~12 ~-28 ~53 ~12 ~-18 minecraft:smooth_stone
fill ~44 ~16 ~-28 ~53 ~16 ~-18 minecraft:smooth_stone
fill ~44 ~20 ~-28 ~53 ~20 ~-18 minecraft:smooth_stone
fill ~44 ~24 ~-28 ~53 ~24 ~-18 minecraft:smooth_stone
fill ~43 ~29 ~-29 ~54 ~29 ~-17 minecraft:dark_oak_planks
setblock ~45 ~3 ~-29 minecraft:gray_stained_glass_pane
setblock ~45 ~3 ~-17 minecraft:gray_stained_glass_pane
setblock ~48 ~3 ~-29 minecraft:gray_stained_glass_pane
setblock ~48 ~3 ~-17 minecraft:gray_stained_glass_pane
setblock ~51 ~3 ~-29 minecraft:gray_stained_glass_pane
setblock ~51 ~3 ~-17 minecraft:gray_stained_glass_pane
setblock ~43 ~3 ~-27 minecraft:gray_stained_glass_pane
setblock ~54 ~3 ~-27 minecraft:gray_stained_glass_pane
setblock ~43 ~3 ~-24 minecraft:gray_stained_glass_pane
setblock ~54 ~3 ~-24 minecraft:gray_stained_glass_pane
setblock ~43 ~3 ~-21 minecraft:gray_stained_glass_pane
setblock ~54 ~3 ~-21 minecraft:gray_stained_glass_pane
setblock ~45 ~7 ~-29 minecraft:gray_stained_glass_pane
setblock ~45 ~7 ~-17 minecraft:gray_stained_glass_pane
setblock ~48 ~7 ~-29 minecraft:gray_stained_glass_pane
setblock ~48 ~7 ~-17 minecraft:gray_stained_glass_pane
setblock ~51 ~7 ~-29 minecraft:gray_stained_glass_pane
setblock ~51 ~7 ~-17 minecraft:gray_stained_glass_pane
setblock ~43 ~7 ~-27 minecraft:gray_stained_glass_pane
setblock ~54 ~7 ~-27 minecraft:gray_stained_glass_pane
setblock ~43 ~7 ~-24 minecraft:gray_stained_glass_pane
setblock ~54 ~7 ~-24 minecraft:gray_stained_glass_pane
setblock ~43 ~7 ~-21 minecraft:gray_stained_glass_pane
setblock ~54 ~7 ~-21 minecraft:gray_stained_glass_pane
setblock ~45 ~11 ~-29 minecraft:gray_stained_glass_pane
setblock ~45 ~11 ~-17 minecraft:gray_stained_glass_pane
setblock ~48 ~11 ~-29 minecraft:gray_stained_glass_pane
setblock ~48 ~11 ~-17 minecraft:gray_stained_glass_pane
setblock ~51 ~11 ~-29 minecraft:gray_stained_glass_pane
setblock ~51 ~11 ~-17 minecraft:gray_stained_glass_pane
setblock ~43 ~11 ~-27 minecraft:gray_stained_glass_pane
setblock ~54 ~11 ~-27 minecraft:gray_stained_glass_pane
setblock ~43 ~11 ~-24 minecraft:gray_stained_glass_pane
setblock ~54 ~11 ~-24 minecraft:gray_stained_glass_pane
setblock ~43 ~11 ~-21 minecraft:gray_stained_glass_pane
setblock ~54 ~11 ~-21 minecraft:gray_stained_glass_pane
setblock ~45 ~15 ~-29 minecraft:gray_stained_glass_pane
setblock ~45 ~15 ~-17 minecraft:gray_stained_glass_pane
setblock ~48 ~15 ~-29 minecraft:gray_stained_glass_pane
setblock ~48 ~15 ~-17 minecraft:gray_stained_glass_pane
setblock ~51 ~15 ~-29 minecraft:gray_stained_glass_pane
setblock ~51 ~15 ~-17 minecraft:gray_stained_glass_pane
setblock ~43 ~15 ~-27 minecraft:gray_stained_glass_pane
setblock ~54 ~15 ~-27 minecraft:gray_stained_glass_pane
setblock ~43 ~15 ~-24 minecraft:gray_stained_glass_pane
setblock ~54 ~15 ~-24 minecraft:gray_stained_glass_pane
setblock ~43 ~15 ~-21 minecraft:gray_stained_glass_pane
setblock ~54 ~15 ~-21 minecraft:gray_stained_glass_pane
setblock ~45 ~19 ~-29 minecraft:gray_stained_glass_pane
setblock ~45 ~19 ~-17 minecraft:gray_stained_glass_pane
setblock ~48 ~19 ~-29 minecraft:gray_stained_glass_pane
setblock ~48 ~19 ~-17 minecraft:gray_stained_glass_pane
setblock ~51 ~19 ~-29 minecraft:gray_stained_glass_pane
setblock ~51 ~19 ~-17 minecraft:gray_stained_glass_pane
setblock ~43 ~19 ~-27 minecraft:gray_stained_glass_pane
setblock ~54 ~19 ~-27 minecraft:gray_stained_glass_pane
setblock ~43 ~19 ~-24 minecraft:gray_stained_glass_pane
setblock ~54 ~19 ~-24 minecraft:gray_stained_glass_pane
setblock ~43 ~19 ~-21 minecraft:gray_stained_glass_pane
setblock ~54 ~19 ~-21 minecraft:gray_stained_glass_pane
setblock ~45 ~23 ~-29 minecraft:gray_stained_glass_pane
setblock ~45 ~23 ~-17 minecraft:gray_stained_glass_pane
setblock ~48 ~23 ~-29 minecraft:gray_stained_glass_pane
setblock ~48 ~23 ~-17 minecraft:gray_stained_glass_pane
setblock ~51 ~23 ~-29 minecraft:gray_stained_glass_pane
setblock ~51 ~23 ~-17 minecraft:gray_stained_glass_pane
setblock ~43 ~23 ~-27 minecraft:gray_stained_glass_pane
setblock ~54 ~23 ~-27 minecraft:gray_stained_glass_pane
setblock ~43 ~23 ~-24 minecraft:gray_stained_glass_pane
setblock ~54 ~23 ~-24 minecraft:gray_stained_glass_pane
setblock ~43 ~23 ~-21 minecraft:gray_stained_glass_pane
setblock ~54 ~23 ~-21 minecraft:gray_stained_glass_pane
setblock ~45 ~27 ~-29 minecraft:gray_stained_glass_pane
setblock ~45 ~27 ~-17 minecraft:gray_stained_glass_pane
setblock ~48 ~27 ~-29 minecraft:gray_stained_glass_pane
setblock ~48 ~27 ~-17 minecraft:gray_stained_glass_pane
setblock ~51 ~27 ~-29 minecraft:gray_stained_glass_pane
setblock ~51 ~27 ~-17 minecraft:gray_stained_glass_pane
setblock ~43 ~27 ~-27 minecraft:gray_stained_glass_pane
setblock ~54 ~27 ~-27 minecraft:gray_stained_glass_pane
setblock ~43 ~27 ~-24 minecraft:gray_stained_glass_pane
setblock ~54 ~27 ~-24 minecraft:gray_stained_glass_pane
setblock ~43 ~27 ~-21 minecraft:gray_stained_glass_pane
setblock ~54 ~27 ~-21 minecraft:gray_stained_glass_pane
setblock ~49 ~2 ~-17 minecraft:dark_oak_door[half=lower]
setblock ~49 ~3 ~-17 minecraft:dark_oak_door[half=upper]
setblock ~44 ~2 ~-17 minecraft:cyan_stained_glass
setblock ~46 ~2 ~-17 minecraft:cyan_stained_glass
setblock ~48 ~2 ~-17 minecraft:cyan_stained_glass
setblock ~50 ~2 ~-17 minecraft:cyan_stained_glass
setblock ~52 ~2 ~-17 minecraft:cyan_stained_glass
fill ~70 ~1 ~40 ~77 ~16 ~47 minecraft:calcite
fill ~71 ~2 ~41 ~76 ~15 ~46 minecraft:air
fill ~71 ~4 ~41 ~76 ~4 ~46 minecraft:smooth_stone
fill ~71 ~8 ~41 ~76 ~8 ~46 minecraft:smooth_stone
fill ~71 ~12 ~41 ~76 ~12 ~46 minecraft:smooth_stone
fill ~70 ~17 ~40 ~77 ~17 ~47 minecraft:cyan_terracotta
setblock ~72 ~3 ~40 minecraft:gray_stained_glass_pane
setblock ~72 ~3 ~47 minecraft:gray_stained_glass_pane
setblock ~75 ~3 ~40 minecraft:gray_stained_glass_pane
setblock ~75 ~3 ~47 minecraft:gray_stained_glass_pane
setblock ~70 ~3 ~42 minecraft:gray_stained_glass_pane
setblock ~77 ~3 ~42 minecraft:gray_stained_glass_pane
setblock ~70 ~3 ~45 minecraft:gray_stained_glass_pane
setblock ~77 ~3 ~45 minecraft:gray_stained_glass_pane
setblock ~72 ~7 ~40 minecraft:gray_stained_glass_pane
setblock ~72 ~7 ~47 minecraft:gray_stained_glass_pane
setblock ~75 ~7 ~40 minecraft:gray_stained_glass_pane
setblock ~75 ~7 ~47 minecraft:gray_stained_glass_pane
setblock ~70 ~7 ~42 minecraft:gray_stained_glass_pane
setblock ~77 ~7 ~42 minecraft:gray_stained_glass_pane
setblock ~70 ~7 ~45 minecraft:gray_stained_glass_pane
setblock ~77 ~7 ~45 minecraft:gray_stained_glass_pane
setblock ~72 ~11 ~40 minecraft:gray_stained_glass_pane
setblock ~72 ~11 ~47 minecraft:gray_stained_glass_pane
setblock ~75 ~11 ~40 minecraft:gray_stained_glass_pane
setblock ~75 ~11 ~47 minecraft:gray_stained_glass_pane
setblock ~70 ~11 ~42 minecraft:gray_stained_glass_pane
setblock ~77 ~11 ~42 minecraft:gray_stained_glass_pane
setblock ~70 ~11 ~45 minecraft:gray_stained_glass_pane
setblock ~77 ~11 ~45 minecraft:gray_stained_glass_pane
setblock ~72 ~15 ~40 minecraft:gray_stained_glass_pane
setblock ~72 ~15 ~47 minecraft:gray_stained_glass_pane
setblock ~75 ~15 ~40 minecraft:gray_stained_glass_pane
setblock ~75 ~15 ~47 minecraft:gray_stained_glass_pane
setblock ~70 ~15 ~42 minecraft:gray_stained_glass_pane
setblock ~77 ~15 ~42 minecraft:gray_stained_glass_pane
setblock ~70 ~15 ~45 minecraft:gray_stained_glass_pane
setblock ~77 ~15 ~45 minecraft:gray_stained_glass_pane
setblock ~70 ~2 ~44 minecraft:dark_oak_door[half=lower]
setblock ~70 ~3 ~44 minecraft:dark_oak_door[half=upper]
setblock ~70 ~2 ~41 minecraft:cyan_stained_glass
setblock ~70 ~2 ~43 minecraft:cyan_stained_glass
setblock ~70 ~2 ~45 minecraft:cyan_stained_glass
fill ~64 ~1 ~74 ~72 ~12 ~85 minecraft:calcite
fill ~65 ~2 ~75 ~71 ~11 ~84 minecraft:air
fill ~65 ~4 ~75 ~71 ~4 ~84 minecraft:smooth_stone
fill ~65 ~8 ~75 ~71 ~8 ~84 minecraft:smooth_stone
fill ~64 ~13 ~74 ~72 ~13 ~85 minecraft:cyan_terracotta
setblock ~66 ~3 ~74 minecraft:gray_stained_glass_pane
setblock ~66 ~3 ~85 minecraft:gray_stained_glass_pane
setblock ~69 ~3 ~74 minecraft:gray_stained_glass_pane
setblock ~69 ~3 ~85 minecraft:gray_stained_glass_pane
setblock ~64 ~3 ~76 minecraft:gray_stained_glass_pane
setblock ~72 ~3 ~76 minecraft:gray_stained_glass_pane
setblock ~64 ~3 ~79 minecraft:gray_stained_glass_pane
setblock ~72 ~3 ~79 minecraft:gray_stained_glass_pane
setblock ~64 ~3 ~82 minecraft:gray_stained_glass_pane
setblock ~72 ~3 ~82 minecraft:gray_stained_glass_pane
setblock ~66 ~7 ~74 minecraft:gray_stained_glass_pane
setblock ~66 ~7 ~85 minecraft:gray_stained_glass_pane
setblock ~69 ~7 ~74 minecraft:gray_stained_glass_pane
setblock ~69 ~7 ~85 minecraft:gray_stained_glass_pane
setblock ~64 ~7 ~76 minecraft:gray_stained_glass_pane
setblock ~72 ~7 ~76 minecraft:gray_stained_glass_pane
setblock ~64 ~7 ~79 minecraft:gray_stained_glass_pane
setblock ~72 ~7 ~79 minecraft:gray_stained_glass_pane
setblock ~64 ~7 ~82 minecraft:gray_stained_glass_pane
setblock ~72 ~7 ~82 minecraft:gray_stained_glass_pane
setblock ~66 ~11 ~74 minecraft:gray_stained_glass_pane
setblock ~66 ~11 ~85 minecraft:gray_stained_glass_pane
setblock ~69 ~11 ~74 minecraft:gray_stained_glass_pane
setblock ~69 ~11 ~85 minecraft:gray_stained_glass_pane
setblock ~64 ~11 ~76 minecraft:gray_stained_glass_pane
setblock ~72 ~11 ~76 minecraft:gray_stained_glass_pane
setblock ~64 ~11 ~79 minecraft:gray_stained_glass_pane
setblock ~72 ~11 ~79 minecraft:gray_stained_glass_pane
setblock ~64 ~11 ~82 minecraft:gray_stained_glass_pane
setblock ~72 ~11 ~82 minecraft:gray_stained_glass_pane
setblock ~68 ~2 ~85 minecraft:dark_oak_door[half=lower]
setblock ~68 ~3 ~85 minecraft:dark_oak_door[half=upper]
setblock ~65 ~2 ~85 minecraft:cyan_stained_glass
setblock ~67 ~2 ~85 minecraft:cyan_stained_glass
setblock ~69 ~2 ~85 minecraft:cyan_stained_glass
setblock ~71 ~2 ~85 minecraft:cyan_stained_glass
fill ~-96 ~1 ~-106 ~-85 ~16 ~-98 minecraft:white_terracotta
fill ~-95 ~2 ~-105 ~-86 ~15 ~-99 minecraft:air
fill ~-95 ~4 ~-105 ~-86 ~4 ~-99 minecraft:smooth_stone
fill ~-95 ~8 ~-105 ~-86 ~8 ~-99 minecraft:smooth_stone
fill ~-95 ~12 ~-105 ~-86 ~12 ~-99 minecraft:smooth_stone
fill ~-96 ~17 ~-106 ~-85 ~17 ~-98 minecraft:spruce_planks
setblock ~-94 ~3 ~-106 minecraft:gray_stained_glass_pane
setblock ~-94 ~3 ~-98 minecraft:gray_stained_glass_pane
setblock ~-91 ~3 ~-106 minecraft:gray_stained_glass_pane
setblock ~-91 ~3 ~-98 minecraft:gray_stained_glass_pane
setblock ~-88 ~3 ~-106 minecraft:gray_stained_glass_pane
setblock ~-88 ~3 ~-98 minecraft:gray_stained_glass_pane
setblock ~-96 ~3 ~-104 minecraft:gray_stained_glass_pane
setblock ~-85 ~3 ~-104 minecraft:gray_stained_glass_pane
setblock ~-96 ~3 ~-101 minecraft:gray_stained_glass_pane
setblock ~-85 ~3 ~-101 minecraft:gray_stained_glass_pane
setblock ~-94 ~7 ~-106 minecraft:gray_stained_glass_pane
setblock ~-94 ~7 ~-98 minecraft:gray_stained_glass_pane
setblock ~-91 ~7 ~-106 minecraft:gray_stained_glass_pane
setblock ~-91 ~7 ~-98 minecraft:gray_stained_glass_pane
setblock ~-88 ~7 ~-106 minecraft:gray_stained_glass_pane
setblock ~-88 ~7 ~-98 minecraft:gray_stained_glass_pane
setblock ~-96 ~7 ~-104 minecraft:gray_stained_glass_pane
setblock ~-85 ~7 ~-104 minecraft:gray_stained_glass_pane
setblock ~-96 ~7 ~-101 minecraft:gray_stained_glass_pane
setblock ~-85 ~7 ~-101 minecraft:gray_stained_glass_pane
setblock ~-94 ~11 ~-106 minecraft:gray_stained_glass_pane
setblock ~-94 ~11 ~-98 minecraft:gray_stained_glass_pane
setblock ~-91 ~11 ~-106 minecraft:gray_stained_glass_pane
setblock ~-91 ~11 ~-98 minecraft:gray_stained_glass_pane
setblock ~-88 ~11 ~-106 minecraft:gray_stained_glass_pane
setblock ~-88 ~11 ~-98 minecraft:gray_stained_glass_pane
setblock ~-96 ~11 ~-104 minecraft:gray_stained_glass_pane
setblock ~-85 ~11 ~-104 minecraft:gray_stained_glass_pane
setblock ~-96 ~11 ~-101 minecraft:gray_stained_glass_pane
setblock ~-85 ~11 ~-101 minecraft:gray_stained_glass_pane
setblock ~-94 ~15 ~-106 minecraft:gray_stained_glass_pane
setblock ~-94 ~15 ~-98 minecraft:gray_stained_glass_pane
setblock ~-91 ~15 ~-106 minecraft:gray_stained_glass_pane
setblock ~-91 ~15 ~-98 minecraft:gray_stained_glass_pane
setblock ~-88 ~15 ~-106 minecraft:gray_stained_glass_pane
setblock ~-88 ~15 ~-98 minecraft:gray_stained_glass_pane
setblock ~-96 ~15 ~-104 minecraft:gray_stained_glass_pane
setblock ~-85 ~15 ~-104 minecraft:gray_stained_glass_pane
setblock ~-96 ~15 ~-101 minecraft:gray_stained_glass_pane
setblock ~-85 ~15 ~-101 minecraft:gray_stained_glass_pane
setblock ~-90 ~2 ~-106 minecraft:dark_oak_door[half=lower]
setblock ~-90 ~3 ~-106 minecraft:dark_oak_door[half=upper]
fill ~16 ~1 ~-56 ~23 ~16 ~-49 minecraft:calcite
fill ~17 ~2 ~-55 ~22 ~15 ~-50 minecraft:air
fill ~17 ~4 ~-55 ~22 ~4 ~-50 minecraft:smooth_stone
fill ~17 ~8 ~-55 ~22 ~8 ~-50 minecraft:smooth_stone
fill ~17 ~12 ~-55 ~22 ~12 ~-50 minecraft:smooth_stone
fill ~16 ~17 ~-56 ~23 ~17 ~-49 minecraft:cyan_terracotta
setblock ~18 ~3 ~-56 minecraft:gray_stained_glass_pane
setblock ~18 ~3 ~-49 minecraft:gray_stained_glass_pane
setblock ~21 ~3 ~-56 minecraft:gray_stained_glass_pane
setblock ~21 ~3 ~-49 minecraft:gray_stained_glass_pane
setblock ~16 ~3 ~-54 minecraft:gray_stained_glass_pane
setblock ~23 ~3 ~-54 minecraft:gray_stained_glass_pane
setblock ~16 ~3 ~-51 minecraft:gray_stained_glass_pane
setblock ~23 ~3 ~-51 minecraft:gray_stained_glass_pane
setblock ~18 ~7 ~-56 minecraft:gray_stained_glass_pane
setblock ~18 ~7 ~-49 minecraft:gray_stained_glass_pane
setblock ~21 ~7 ~-56 minecraft:gray_stained_glass_pane
setblock ~21 ~7 ~-49 minecraft:gray_stained_glass_pane
setblock ~16 ~7 ~-54 minecraft:gray_stained_glass_pane
setblock ~23 ~7 ~-54 minecraft:gray_stained_glass_pane
setblock ~16 ~7 ~-51 minecraft:gray_stained_glass_pane
setblock ~23 ~7 ~-51 minecraft:gray_stained_glass_pane
setblock ~18 ~11 ~-56 minecraft:gray_stained_glass_pane
setblock ~18 ~11 ~-49 minecraft:gray_stained_glass_pane
setblock ~21 ~11 ~-56 minecraft:gray_stained_glass_pane
setblock ~21 ~11 ~-49 minecraft:gray_stained_glass_pane
setblock ~16 ~11 ~-54 minecraft:gray_stained_glass_pane
setblock ~23 ~11 ~-54 minecraft:gray_stained_glass_pane
setblock ~16 ~11 ~-51 minecraft:gray_stained_glass_pane
setblock ~23 ~11 ~-51 minecraft:gray_stained_glass_pane
setblock ~18 ~15 ~-56 minecraft:gray_stained_glass_pane
setblock ~18 ~15 ~-49 minecraft:gray_stained_glass_pane
setblock ~21 ~15 ~-56 minecraft:gray_stained_glass_pane
setblock ~21 ~15 ~-49 minecraft:gray_stained_glass_pane
setblock ~16 ~15 ~-54 minecraft:gray_stained_glass_pane
setblock ~23 ~15 ~-54 minecraft:gray_stained_glass_pane
setblock ~16 ~15 ~-51 minecraft:gray_stained_glass_pane
setblock ~23 ~15 ~-51 minecraft:gray_stained_glass_pane
setblock ~20 ~2 ~-56 minecraft:dark_oak_door[half=lower]
setblock ~20 ~3 ~-56 minecraft:dark_oak_door[half=upper]
fill ~-87 ~1 ~-124 ~-78 ~12 ~-118 minecraft:stone_bricks
fill ~-86 ~2 ~-123 ~-79 ~11 ~-119 minecraft:air
fill ~-86 ~4 ~-123 ~-79 ~4 ~-119 minecraft:smooth_stone
fill ~-86 ~8 ~-123 ~-79 ~8 ~-119 minecraft:smooth_stone
fill ~-87 ~13 ~-124 ~-78 ~13 ~-118 minecraft:deepslate_bricks
setblock ~-85 ~3 ~-124 minecraft:gray_stained_glass_pane
setblock ~-85 ~3 ~-118 minecraft:gray_stained_glass_pane
setblock ~-82 ~3 ~-124 minecraft:gray_stained_glass_pane
setblock ~-82 ~3 ~-118 minecraft:gray_stained_glass_pane
setblock ~-87 ~3 ~-122 minecraft:gray_stained_glass_pane
setblock ~-78 ~3 ~-122 minecraft:gray_stained_glass_pane
setblock ~-85 ~7 ~-124 minecraft:gray_stained_glass_pane
setblock ~-85 ~7 ~-118 minecraft:gray_stained_glass_pane
setblock ~-82 ~7 ~-124 minecraft:gray_stained_glass_pane
setblock ~-82 ~7 ~-118 minecraft:gray_stained_glass_pane
setblock ~-87 ~7 ~-122 minecraft:gray_stained_glass_pane
setblock ~-78 ~7 ~-122 minecraft:gray_stained_glass_pane
setblock ~-85 ~11 ~-124 minecraft:gray_stained_glass_pane
setblock ~-85 ~11 ~-118 minecraft:gray_stained_glass_pane
setblock ~-82 ~11 ~-124 minecraft:gray_stained_glass_pane
setblock ~-82 ~11 ~-118 minecraft:gray_stained_glass_pane
setblock ~-87 ~11 ~-122 minecraft:gray_stained_glass_pane
setblock ~-78 ~11 ~-122 minecraft:gray_stained_glass_pane
setblock ~-82 ~2 ~-118 minecraft:dark_oak_door[half=lower]
setblock ~-82 ~3 ~-118 minecraft:dark_oak_door[half=upper]
fill ~-87 ~14 ~-124 ~-78 ~14 ~-118 minecraft:deepslate_tile_slab
fill ~-86 ~15 ~-123 ~-79 ~15 ~-119 minecraft:deepslate_tile_slab
fill ~-69 ~1 ~-124 ~-59 ~12 ~-118 minecraft:stone_bricks
fill ~-68 ~2 ~-123 ~-60 ~11 ~-119 minecraft:air
fill ~-68 ~4 ~-123 ~-60 ~4 ~-119 minecraft:smooth_stone
fill ~-68 ~8 ~-123 ~-60 ~8 ~-119 minecraft:smooth_stone
fill ~-69 ~13 ~-124 ~-59 ~13 ~-118 minecraft:deepslate_bricks
setblock ~-67 ~3 ~-124 minecraft:gray_stained_glass_pane
setblock ~-67 ~3 ~-118 minecraft:gray_stained_glass_pane
setblock ~-64 ~3 ~-124 minecraft:gray_stained_glass_pane
setblock ~-64 ~3 ~-118 minecraft:gray_stained_glass_pane
setblock ~-61 ~3 ~-124 minecraft:gray_stained_glass_pane
setblock ~-61 ~3 ~-118 minecraft:gray_stained_glass_pane
setblock ~-69 ~3 ~-122 minecraft:gray_stained_glass_pane
setblock ~-59 ~3 ~-122 minecraft:gray_stained_glass_pane
setblock ~-67 ~7 ~-124 minecraft:gray_stained_glass_pane
setblock ~-67 ~7 ~-118 minecraft:gray_stained_glass_pane
setblock ~-64 ~7 ~-124 minecraft:gray_stained_glass_pane
setblock ~-64 ~7 ~-118 minecraft:gray_stained_glass_pane
setblock ~-61 ~7 ~-124 minecraft:gray_stained_glass_pane
setblock ~-61 ~7 ~-118 minecraft:gray_stained_glass_pane
setblock ~-69 ~7 ~-122 minecraft:gray_stained_glass_pane
setblock ~-59 ~7 ~-122 minecraft:gray_stained_glass_pane
setblock ~-67 ~11 ~-124 minecraft:gray_stained_glass_pane
setblock ~-67 ~11 ~-118 minecraft:gray_stained_glass_pane
setblock ~-64 ~11 ~-124 minecraft:gray_stained_glass_pane
setblock ~-64 ~11 ~-118 minecraft:gray_stained_glass_pane
setblock ~-61 ~11 ~-124 minecraft:gray_stained_glass_pane
setblock ~-61 ~11 ~-118 minecraft:gray_stained_glass_pane
setblock ~-69 ~11 ~-122 minecraft:gray_stained_glass_pane
setblock ~-59 ~11 ~-122 minecraft:gray_stained_glass_pane
setblock ~-64 ~2 ~-118 minecraft:dark_oak_door[half=lower]
setblock ~-64 ~3 ~-118 minecraft:dark_oak_door[half=upper]
fill ~-69 ~14 ~-124 ~-59 ~14 ~-118 minecraft:deepslate_tile_slab
fill ~-68 ~15 ~-123 ~-60 ~15 ~-119 minecraft:deepslate_tile_slab
fill ~100 ~1 ~16 ~107 ~12 ~24 minecraft:mud_bricks
fill ~101 ~2 ~17 ~106 ~11 ~23 minecraft:air
fill ~101 ~4 ~17 ~106 ~4 ~23 minecraft:smooth_stone
fill ~101 ~8 ~17 ~106 ~8 ~23 minecraft:smooth_stone
fill ~100 ~13 ~16 ~107 ~13 ~24 minecraft:dark_oak_planks
setblock ~102 ~3 ~16 minecraft:gray_stained_glass_pane
setblock ~102 ~3 ~24 minecraft:gray_stained_glass_pane
setblock ~105 ~3 ~16 minecraft:gray_stained_glass_pane
setblock ~105 ~3 ~24 minecraft:gray_stained_glass_pane
setblock ~100 ~3 ~18 minecraft:gray_stained_glass_pane
setblock ~107 ~3 ~18 minecraft:gray_stained_glass_pane
setblock ~100 ~3 ~21 minecraft:gray_stained_glass_pane
setblock ~107 ~3 ~21 minecraft:gray_stained_glass_pane
setblock ~102 ~7 ~16 minecraft:gray_stained_glass_pane
setblock ~102 ~7 ~24 minecraft:gray_stained_glass_pane
setblock ~105 ~7 ~16 minecraft:gray_stained_glass_pane
setblock ~105 ~7 ~24 minecraft:gray_stained_glass_pane
setblock ~100 ~7 ~18 minecraft:gray_stained_glass_pane
setblock ~107 ~7 ~18 minecraft:gray_stained_glass_pane
setblock ~100 ~7 ~21 minecraft:gray_stained_glass_pane
setblock ~107 ~7 ~21 minecraft:gray_stained_glass_pane
setblock ~102 ~11 ~16 minecraft:gray_stained_glass_pane
setblock ~102 ~11 ~24 minecraft:gray_stained_glass_pane
setblock ~105 ~11 ~16 minecraft:gray_stained_glass_pane
setblock ~105 ~11 ~24 minecraft:gray_stained_glass_pane
setblock ~100 ~11 ~18 minecraft:gray_stained_glass_pane
setblock ~107 ~11 ~18 minecraft:gray_stained_glass_pane
setblock ~100 ~11 ~21 minecraft:gray_stained_glass_pane
setblock ~107 ~11 ~21 minecraft:gray_stained_glass_pane
setblock ~104 ~2 ~24 minecraft:dark_oak_door[half=lower]
setblock ~104 ~3 ~24 minecraft:dark_oak_door[half=upper]
fill ~-55 ~1 ~11 ~-48 ~16 ~21 minecraft:stone_bricks
fill ~-54 ~2 ~12 ~-49 ~15 ~20 minecraft:air
fill ~-54 ~4 ~12 ~-49 ~4 ~20 minecraft:smooth_stone
fill ~-54 ~8 ~12 ~-49 ~8 ~20 minecraft:smooth_stone
fill ~-54 ~12 ~12 ~-49 ~12 ~20 minecraft:smooth_stone
fill ~-55 ~17 ~11 ~-48 ~17 ~21 minecraft:deepslate_bricks
fill ~-57 ~1 ~13 ~-56 ~16 ~21 minecraft:stone_bricks
fill ~-56 ~4 ~14 ~-57 ~4 ~20 minecraft:smooth_stone
fill ~-56 ~8 ~14 ~-57 ~8 ~20 minecraft:smooth_stone
fill ~-56 ~12 ~14 ~-57 ~12 ~20 minecraft:smooth_stone
fill ~-57 ~17 ~13 ~-56 ~17 ~21 minecraft:deepslate_bricks
setblock ~-55 ~3 ~11 minecraft:gray_stained_glass_pane
setblock ~-55 ~3 ~21 minecraft:gray_stained_glass_pane
setblock ~-52 ~3 ~11 minecraft:gray_stained_glass_pane
setblock ~-52 ~3 ~21 minecraft:gray_stained_glass_pane
setblock ~-57 ~3 ~13 minecraft:gray_stained_glass_pane
setblock ~-48 ~3 ~13 minecraft:gray_stained_glass_pane
setblock ~-57 ~3 ~16 minecraft:gray_stained_glass_pane
setblock ~-48 ~3 ~16 minecraft:gray_stained_glass_pane
setblock ~-57 ~3 ~19 minecraft:gray_stained_glass_pane
setblock ~-48 ~3 ~19 minecraft:gray_stained_glass_pane
setblock ~-55 ~7 ~11 minecraft:gray_stained_glass_pane
setblock ~-55 ~7 ~21 minecraft:gray_stained_glass_pane
setblock ~-52 ~7 ~11 minecraft:gray_stained_glass_pane
setblock ~-52 ~7 ~21 minecraft:gray_stained_glass_pane
setblock ~-57 ~7 ~13 minecraft:gray_stained_glass_pane
setblock ~-48 ~7 ~13 minecraft:gray_stained_glass_pane
setblock ~-57 ~7 ~16 minecraft:gray_stained_glass_pane
setblock ~-48 ~7 ~16 minecraft:gray_stained_glass_pane
setblock ~-57 ~7 ~19 minecraft:gray_stained_glass_pane
setblock ~-48 ~7 ~19 minecraft:gray_stained_glass_pane
setblock ~-55 ~11 ~11 minecraft:gray_stained_glass_pane
setblock ~-55 ~11 ~21 minecraft:gray_stained_glass_pane
setblock ~-52 ~11 ~11 minecraft:gray_stained_glass_pane
setblock ~-52 ~11 ~21 minecraft:gray_stained_glass_pane
setblock ~-57 ~11 ~13 minecraft:gray_stained_glass_pane
setblock ~-48 ~11 ~13 minecraft:gray_stained_glass_pane
setblock ~-57 ~11 ~16 minecraft:gray_stained_glass_pane
setblock ~-48 ~11 ~16 minecraft:gray_stained_glass_pane
setblock ~-57 ~11 ~19 minecraft:gray_stained_glass_pane
setblock ~-48 ~11 ~19 minecraft:gray_stained_glass_pane
setblock ~-55 ~15 ~11 minecraft:gray_stained_glass_pane
setblock ~-55 ~15 ~21 minecraft:gray_stained_glass_pane
setblock ~-52 ~15 ~11 minecraft:gray_stained_glass_pane
setblock ~-52 ~15 ~21 minecraft:gray_stained_glass_pane
setblock ~-57 ~15 ~13 minecraft:gray_stained_glass_pane
setblock ~-48 ~15 ~13 minecraft:gray_stained_glass_pane
setblock ~-57 ~15 ~16 minecraft:gray_stained_glass_pane
setblock ~-48 ~15 ~16 minecraft:gray_stained_glass_pane
setblock ~-57 ~15 ~19 minecraft:gray_stained_glass_pane
setblock ~-48 ~15 ~19 minecraft:gray_stained_glass_pane
setblock ~-52 ~2 ~21 minecraft:dark_oak_door[half=lower]
setblock ~-52 ~3 ~21 minecraft:dark_oak_door[half=upper]
fill ~-76 ~1 ~-124 ~-70 ~12 ~-118 minecraft:light_gray_concrete
fill ~-75 ~2 ~-123 ~-71 ~11 ~-119 minecraft:air
fill ~-75 ~4 ~-123 ~-71 ~4 ~-119 minecraft:smooth_stone
fill ~-75 ~8 ~-123 ~-71 ~8 ~-119 minecraft:smooth_stone
fill ~-76 ~13 ~-124 ~-70 ~13 ~-118 minecraft:gray_concrete
