setblock ~6 ~3 ~100 minecraft:gray_stained_glass_pane
setblock ~-8 ~3 ~103 minecraft:gray_stained_glass_pane
setblock ~6 ~3 ~103 minecraft:gray_stained_glass_pane
setblock ~-6 ~7 ~95 minecraft:gray_stained_glass_pane
setblock ~-6 ~7 ~107 minecraft:gray_stained_glass_pane
setblock ~-3 ~7 ~95 minecraft:gray_stained_glass_pane
setblock ~-3 ~7 ~107 minecraft:gray_stained_glass_pane
setblock ~ ~7 ~95 minecraft:gray_stained_glass_pane
setblock ~ ~7 ~107 minecraft:gray_stained_glass_pane
setblock ~3 ~7 ~95 minecraft:gray_stained_glass_pane
setblock ~3 ~7 ~107 minecraft:gray_stained_glass_pane
setblock ~-8 ~7 ~97 minecraft:gray_stained_glass_pane
setblock ~6 ~7 ~97 minecraft:gray_stained_glass_pane
setblock ~-8 ~7 ~100 minecraft:gray_stained_glass_pane
setblock ~6 ~7 ~100 minecraft:gray_stained_glass_pane
setblock ~-8 ~7 ~103 minecraft:gray_stained_glass_pane
setblock ~6 ~7 ~103 minecraft:gray_stained_glass_pane
setblock ~-6 ~11 ~95 minecraft:gray_stained_glass_pane
setblock ~-6 ~11 ~107 minecraft:gray_stained_glass_pane
setblock ~-3 ~11 ~95 minecraft:gray_stained_glass_pane
setblock ~-3 ~11 ~107 minecraft:gray_stained_glass_pane
setblock ~ ~11 ~95 minecraft:gray_stained_glass_pane
setblock ~ ~11 ~107 minecraft:gray_stained_glass_pane
setblock ~3 ~11 ~95 minecraft:gray_stained_glass_pane
setblock ~3 ~11 ~107 minecraft:gray_stained_glass_pane
setblock ~-8 ~11 ~97 minecraft:gray_stained_glass_pane
setblock ~6 ~11 ~97 minecraft:gray_stained_glass_pane
setblock ~-8 ~11 ~100 minecraft:gray_stained_glass_pane
setblock ~6 ~11 ~100 minecraft:gray_stained_glass_pane
setblock ~-8 ~11 ~103 minecraft:gray_stained_glass_pane
setblock ~6 ~11 ~103 minecraft:gray_stained_glass_pane
setblock ~-6 ~15 ~95 minecraft:gray_stained_glass_pane
setblock ~-6 ~15 ~107 minecraft:gray_stained_glass_pane
setblock ~-3 ~15 ~95 minecraft:gray_stained_glass_pane
setblock ~-3 ~15 ~107 minecraft:gray_stained_glass_pane
setblock ~ ~15 ~95 minecraft:gray_stained_glass_pane
setblock ~ ~15 ~107 minecraft:gray_stained_glass_pane
setblock ~3 ~15 ~95 minecraft:gray_stained_glass_pane
setblock ~3 ~15 ~107 minecraft:gray_stained_glass_pane
setblock ~-8 ~15 ~97 minecraft:gray_stained_glass_pane
setblock ~6 ~15 ~97 minecraft:gray_stained_glass_pane
setblock ~-8 ~15 ~100 minecraft:gray_stained_glass_pane
setblock ~6 ~15 ~100 minecraft:gray_stained_glass_pane
setblock ~-8 ~15 ~103 minecraft:gray_stained_glass_pane
setblock ~6 ~15 ~103 minecraft:gray_stained_glass_pane
setblock ~-8 ~2 ~101 minecraft:dark_oak_door[half=lower]
setblock ~-8 ~3 ~101 minecraft:dark_oak_door[half=upper]
setblock ~-8 ~2 ~96 minecraft:cyan_stained_glass
setblock ~-8 ~2 ~98 minecraft:cyan_stained_glass
setblock ~-8 ~2 ~100 minecraft:cyan_stained_glass
setblock ~-8 ~2 ~102 minecraft:cyan_stained_glass
setblock ~-8 ~2 ~104 minecraft:cyan_stained_glass
setblock ~-8 ~2 ~106 minecraft:cyan_stained_glass
fill ~76 ~1 ~-29 ~91 ~12 ~-23 minecraft:white_terracotta
fill ~77 ~2 ~-28 ~90 ~11 ~-24 minecraft:air
fill ~77 ~4 ~-28 ~90 ~4 ~-24 minecraft:smooth_stone
fill ~77 ~8 ~-28 ~90 ~8 ~-24 minecraft:smooth_stone
fill ~76 ~13 ~-29 ~91 ~13 ~-23 minecraft:spruce_planks
fill ~76 ~1 ~-22 ~84 ~8 ~-17 minecraft:white_terracotta
fill ~77 ~2 ~-21 ~83 ~7 ~-18 minecraft:air
fill ~77 ~4 ~-21 ~83 ~4 ~-18 minecraft:smooth_stone
fill ~76 ~9 ~-22 ~84 ~9 ~-17 minecraft:spruce_planks
setblock ~78 ~3 ~-29 minecraft:gray_stained_glass_pane
setblock ~78 ~3 ~-17 minecraft:gray_stained_glass_pane
setblock ~81 ~3 ~-29 minecraft:gray_stained_glass_pane
setblock ~81 ~3 ~-17 minecraft:gray_stained_glass_pane
setblock ~84 ~3 ~-29 minecraft:gray_stained_glass_pane
setblock ~84 ~3 ~-17 minecraft:gray_stained_glass_pane
setblock ~87 ~3 ~-29 minecraft:gray_stained_glass_pane
setblock ~87 ~3 ~-17 minecraft:gray_stained_glass_pane
setblock ~76 ~3 ~-27 minecraft:gray_stained_glass_pane
setblock ~91 ~3 ~-27 minecraft:gray_stained_glass_pane
setblock ~76 ~3 ~-24 minecraft:gray_stained_glass_pane
setblock ~91 ~3 ~-24 minecraft:gray_stained_glass_pane
setblock ~76 ~3 ~-21 minecraft:gray_stained_glass_pane
setblock ~91 ~3 ~-21 minecraft:gray_stained_glass_pane
setblock ~78 ~7 ~-29 minecraft:gray_stained_glass_pane
setblock ~78 ~7 ~-17 minecraft:gray_stained_glass_pane
setblock ~81 ~7 ~-29 minecraft:gray_stained_glass_pane
setblock ~81 ~7 ~-17 minecraft:gray_stained_glass_pane
setblock ~84 ~7 ~-29 minecraft:gray_stained_glass_pane
setblock ~84 ~7 ~-17 minecraft:gray_stained_glass_pane
setblock ~87 ~7 ~-29 minecraft:gray_stained_glass_pane
setblock ~87 ~7 ~-17 minecraft:gray_stained_glass_pane
setblock ~76 ~7 ~-27 minecraft:gray_stained_glass_pane
setblock ~91 ~7 ~-27 minecraft:gray_stained_glass_pane
setblock ~76 ~7 ~-24 minecraft:gray_stained_glass_pane
setblock ~91 ~7 ~-24 minecraft:gray_stained_glass_pane
setblock ~76 ~7 ~-21 minecraft:gray_stained_glass_pane
setblock ~91 ~7 ~-21 minecraft:gray_stained_glass_pane
setblock ~78 ~11 ~-29 minecraft:gray_stained_glass_pane
setblock ~78 ~11 ~-17 minecraft:gray_stained_glass_pane
setblock ~81 ~11 ~-29 minecraft:gray_stained_glass_pane
setblock ~81 ~11 ~-17 minecraft:gray_stained_glass_pane
setblock ~84 ~11 ~-29 minecraft:gray_stained_glass_pane
setblock ~84 ~11 ~-17 minecraft:gray_stained_glass_pane
setblock ~87 ~11 ~-29 minecraft:gray_stained_glass_pane
setblock ~87 ~11 ~-17 minecraft:gray_stained_glass_pane
setblock ~76 ~11 ~-27 minecraft:gray_stained_glass_pane
setblock ~91 ~11 ~-27 minecraft:gray_stained_glass_pane
setblock ~76 ~11 ~-24 minecraft:gray_stained_glass_pane
setblock ~91 ~11 ~-24 minecraft:gray_stained_glass_pane
setblock ~76 ~11 ~-21 minecraft:gray_stained_glass_pane
setblock ~91 ~11 ~-21 minecraft:gray_stained_glass_pane
setblock ~84 ~2 ~-17 minecraft:dark_oak_door[half=lower]
setblock ~84 ~3 ~-17 minecraft:dark_oak_door[half=upper]
setblock ~77 ~2 ~-17 minecraft:cyan_stained_glass
setblock ~79 ~2 ~-17 minecraft:cyan_stained_glass
setblock ~81 ~2 ~-17 minecraft:cyan_stained_glass
setblock ~83 ~2 ~-17 minecraft:cyan_stained_glass
setblock ~85 ~2 ~-17 minecraft:cyan_stained_glass
setblock ~87 ~2 ~-17 minecraft:cyan_stained_glass
setblock ~89 ~2 ~-17 minecraft:cyan_stained_glass
fill ~19 ~1 ~-121 ~29 ~16 ~-112 minecraft:white_terracotta
fill ~20 ~2 ~-120 ~28 ~15 ~-113 minecraft:air
fill ~20 ~4 ~-120 ~28 ~4 ~-113 minecraft:smooth_stone
fill ~20 ~8 ~-120 ~28 ~8 ~-113 minecraft:smooth_stone
fill ~20 ~12 ~-120 ~28 ~12 ~-113 minecraft:smooth_stone
fill ~19 ~17 ~-121 ~29 ~17 ~-112 minecraft:spruce_planks
setblock ~21 ~3 ~-121 minecraft:gray_stained_glass_pane
setblock ~21 ~3 ~-112 minecraft:gray_stained_glass_pane
setblock ~24 ~3 ~-121 minecraft:gray_stained_glass_pane
setblock ~24 ~3 ~-112 minecraft:gray_stained_glass_pane
setblock ~27 ~3 ~-121 minecraft:gray_stained_glass_pane
setblock ~27 ~3 ~-112 minecraft:gray_stained_glass_pane
setblock ~19 ~3 ~-119 minecraft:gray_stained_glass_pane
setblock ~29 ~3 ~-119 minecraft:gray_stained_glass_pane
setblock ~19 ~3 ~-116 minecraft:gray_stained_glass_pane
setblock ~29 ~3 ~-116 minecraft:gray_stained_glass_pane
setblock ~21 ~7 ~-121 minecraft:gray_stained_glass_pane
setblock ~21 ~7 ~-112 minecraft:gray_stained_glass_pane
setblock ~24 ~7 ~-121 minecraft:gray_stained_glass_pane
setblock ~24 ~7 ~-112 minecraft:gray_stained_glass_pane
setblock ~27 ~7 ~-121 minecraft:gray_stained_glass_pane
setblock ~27 ~7 ~-112 minecraft:gray_stained_glass_pane
setblock ~19 ~7 ~-119 minecraft:gray_stained_glass_pane
setblock ~29 ~7 ~-119 minecraft:gray_stained_glass_pane
setblock ~19 ~7 ~-116 minecraft:gray_stained_glass_pane
setblock ~29 ~7 ~-116 minecraft:gray_stained_glass_pane
setblock ~21 ~11 ~-121 minecraft:gray_stained_glass_pane
setblock ~21 ~11 ~-112 minecraft:gray_stained_glass_pane
setblock ~24 ~11 ~-121 minecraft:gray_stained_glass_pane
setblock ~24 ~11 ~-112 minecraft:gray_stained_glass_pane
setblock ~27 ~11 ~-121 minecraft:gray_stained_glass_pane
setblock ~27 ~11 ~-112 minecraft:gray_stained_glass_pane
setblock ~19 ~11 ~-119 minecraft:gray_stained_glass_pane
setblock ~29 ~11 ~-119 minecraft:gray_stained_glass_pane
setblock ~19 ~11 ~-116 minecraft:gray_stained_glass_pane
setblock ~29 ~11 ~-116 minecraft:gray_stained_glass_pane
setblock ~21 ~15 ~-121 minecraft:gray_stained_glass_pane
setblock ~21 ~15 ~-112 minecraft:gray_stained_glass_pane
setblock ~24 ~15 ~-121 minecraft:gray_stained_glass_pane
setblock ~24 ~15 ~-112 minecraft:gray_stained_glass_pane
setblock ~27 ~15 ~-121 minecraft:gray_stained_glass_pane
setblock ~27 ~15 ~-112 minecraft:gray_stained_glass_pane
setblock ~19 ~15 ~-119 minecraft:gray_stained_glass_pane
setblock ~29 ~15 ~-119 minecraft:gray_stained_glass_pane
setblock ~19 ~15 ~-116 minecraft:gray_stained_glass_pane
setblock ~29 ~15 ~-116 minecraft:gray_stained_glass_pane
setblock ~29 ~2 ~-116 minecraft:dark_oak_door[half=lower]
setblock ~29 ~3 ~-116 minecraft:dark_oak_door[half=upper]
fill ~19 ~18 ~-121 ~29 ~18 ~-112 minecraft:deepslate_tile_slab
fill ~20 ~19 ~-120 ~28 ~19 ~-113 minecraft:deepslate_tile_slab
fill ~21 ~20 ~-119 ~27 ~20 ~-114 minecraft:deepslate_tile_slab
fill ~-5 ~1 ~1 ~8 ~16 ~11 minecraft:calcite
fill ~-4 ~2 ~2 ~7 ~15 ~10 minecraft:air
fill ~-4 ~4 ~2 ~7 ~4 ~10 minecraft:smooth_stone
fill ~-4 ~8 ~2 ~7 ~8 ~10 minecraft:smooth_stone
fill ~-4 ~12 ~2 ~7 ~12 ~10 minecraft:smooth_stone
fill ~-5 ~17 ~1 ~8 ~17 ~11 minecraft:cyan_terracotta
fill ~-3 ~1 ~3 ~6 ~20 ~9 minecraft:calcite
fill ~-2 ~2 ~4 ~5 ~19 ~8 minecraft:air
fill ~-2 ~4 ~4 ~5 ~4 ~8 minecraft:smooth_stone
fill ~-2 ~8 ~4 ~5 ~8 ~8 minecraft:smooth_stone
fill ~-2 ~12 ~4 ~5 ~12 ~8 minecraft:smooth_stone
fill ~-2 ~16 ~4 ~5 ~16 ~8 minecraft:smooth_stone
fill ~-3 ~21 ~3 ~6 ~21 ~9 minecraft:cyan_terracotta
setblock ~-3 ~3 ~1 minecraft:gray_stained_glass_pane
setblock ~-3 ~3 ~11 minecraft:gray_stained_glass_pane
setblock ~ ~3 ~1 minecraft:gray_stained_glass_pane
setblock ~ ~3 ~11 minecraft:gray_stained_glass_pane
setblock ~3 ~3 ~1 minecraft:gray_stained_glass_pane
setblock ~3 ~3 ~11 minecraft:gray_stained_glass_pane
setblock ~6 ~3 ~1 minecraft:gray_stained_glass_pane
setblock ~6 ~3 ~11 minecraft:gray_stained_glass_pane
setblock ~-5 ~3 ~3 minecraft:gray_stained_glass_pane
setblock ~8 ~3 ~3 minecraft:gray_stained_glass_pane
setblock ~-5 ~3 ~6 minecraft:gray_stained_glass_pane
setblock ~8 ~3 ~6 minecraft:gray_stained_glass_pane
setblock ~-5 ~3 ~9 minecraft:gray_stained_glass_pane
setblock ~8 ~3 ~9 minecraft:gray_stained_glass_pane
setblock ~-3 ~7 ~1 minecraft:gray_stained_glass_pane
setblock ~-3 ~7 ~11 minecraft:gray_stained_glass_pane
setblock ~ ~7 ~1 minecraft:gray_stained_glass_pane
setblock ~ ~7 ~11 minecraft:gray_stained_glass_pane
setblock ~3 ~7 ~1 minecraft:gray_stained_glass_pane
setblock ~3 ~7 ~11 minecraft:gray_stained_glass_pane
setblock ~6 ~7 ~1 minecraft:gray_stained_glass_pane
setblock ~6 ~7 ~11 minecraft:gray_stained_glass_pane
setblock ~-5 ~7 ~3 minecraft:gray_stained_glass_pane
setblock ~8 ~7 ~3 minecraft:gray_stained_glass_pane
setblock ~-5 ~7 ~6 minecraft:gray_stained_glass_pane
setblock ~8 ~7 ~6 minecraft:gray_stained_glass_pane
setblock ~-5 ~7 ~9 minecraft:gray_stained_glass_pane
setblock ~8 ~7 ~9 minecraft:gray_stained_glass_pane
setblock ~-3 ~11 ~1 minecraft:gray_stained_glass_pane
setblock ~-3 ~11 ~11 minecraft:gray_stained_glass_pane
setblock ~ ~11 ~1 minecraft:gray_stained_glass_pane
setblock ~ ~11 ~11 minecraft:gray_stained_glass_pane
setblock ~3 ~11 ~1 minecraft:gray_stained_glass_pane
setblock ~3 ~11 ~11 minecraft:gray_stained_glass_pane
setblock ~6 ~11 ~1 minecraft:gray_stained_glass_pane
setblock ~6 ~11 ~11 minecraft:gray_stained_glass_pane
setblock ~-5 ~11 ~3 minecraft:gray_stained_glass_pane
setblock ~8 ~11 ~3 minecraft:gray_stained_glass_pane
setblock ~-5 ~11 ~6 minecraft:gray_stained_glass_pane
setblock ~8 ~11 ~6 minecraft:gray_stained_glass_pane
setblock ~-5 ~11 ~9 minecraft:gray_stained_glass_pane
setblock ~8 ~11 ~9 minecraft:gray_stained_glass_pane
setblock ~-3 ~15 ~1 minecraft:gray_stained_glass_pane
setblock ~-3 ~15 ~11 minecraft:gray_stained_glass_pane
setblock ~ ~15 ~1 minecraft:gray_stained_glass_pane
setblock ~ ~15 ~11 minecraft:gray_stained_glass_pane
setblock ~3 ~15 ~1 minecraft:gray_stained_glass_pane
setblock ~3 ~15 ~11 minecraft:gray_stained_glass_pane
setblock ~6 ~15 ~1 minecraft:gray_stained_glass_pane
setblock ~6 ~15 ~11 minecraft:gray_stained_glass_pane
setblock ~-5 ~15 ~3 minecraft:gray_stained_glass_pane
setblock ~8 ~15 ~3 minecraft:gray_stained_glass_pane
setblock ~-5 ~15 ~6 minecraft:gray_stained_glass_pane
setblock ~8 ~15 ~6 minecraft:gray_stained_glass_pane
setblock ~-5 ~15 ~9 minecraft:gray_stained_glass_pane
setblock ~8 ~15 ~9 minecraft:gray_stained_glass_pane
setblock ~-3 ~19 ~1 minecraft:gray_stained_glass_pane
setblock ~-3 ~19 ~11 minecraft:gray_stained_glass_pane
setblock ~ ~19 ~1 minecraft:gray_stained_glass_pane
setblock ~ ~19 ~11 minecraft:gray_stained_glass_pane
setblock ~3 ~19 ~1 minecraft:gray_stained_glass_pane
setblock ~3 ~19 ~11 minecraft:gray_stained_glass_pane
setblock ~6 ~19 ~1 minecraft:gray_stained_glass_pane
setblock ~6 ~19 ~11 minecraft:gray_stained_glass_pane
setblock ~-5 ~19 ~3 minecraft:gray_stained_glass_pane
setblock ~8 ~19 ~3 minecraft:gray_stained_glass_pane
setblock ~-5 ~19 ~6 minecraft:gray_stained_glass_pane
setblock ~8 ~19 ~6 minecraft:gray_stained_glass_pane
setblock ~-5 ~19 ~9 minecraft:gray_stained_glass_pane
setblock ~8 ~19 ~9 minecraft:gray_stained_glass_pane
setblock ~2 ~2 ~1 minecraft:dark_oak_door[half=lower]
setblock ~2 ~3 ~1 minecraft:dark_oak_door[half=upper]
fill ~-8 ~1 ~109 ~7 ~20 ~120 minecraft:white_terracotta
fill ~-7 ~2 ~110 ~6 ~19 ~119 minecraft:air
fill ~-7 ~4 ~110 ~6 ~4 ~119 minecraft:smooth_stone
fill ~-7 ~8 ~110 ~6 ~8 ~119 minecraft:smooth_stone
fill ~-7 ~12 ~110 ~6 ~12 ~119 minecraft:smooth_stone
fill ~-7 ~16 ~110 ~6 ~16 ~119 minecraft:smooth_stone
fill ~-8 ~21 ~109 ~7 ~21 ~120 minecraft:spruce_planks
setblock ~-6 ~3 ~109 minecraft:gray_stained_glass_pane
setblock ~-6 ~3 ~120 minecraft:gray_stained_glass_pane
setblock ~-3 ~3 ~109 minecraft:gray_stained_glass_pane
setblock ~-3 ~3 ~120 minecraft:gray_stained_glass_pane
setblock ~ ~3 ~109 minecraft:gray_stained_glass_pane
setblock ~ ~3 ~120 minecraft:gray_stained_glass_pane
setblock ~3 ~3 ~109 minecraft:gray_stained_glass_pane
setblock ~3 ~3 ~120 minecraft:gray_stained_glass_pane
setblock ~-8 ~3 ~111 minecraft:gray_stained_glass_pane
setblock ~7 ~3 ~111 minecraft:gray_stained_glass_pane
setblock ~-8 ~3 ~114 minecraft:gray_stained_glass_pane
setblock ~7 ~3 ~114 minecraft:gray_stained_glass_pane
setblock ~-8 ~3 ~117 minecraft:gray_stained_glass_pane
setblock ~7 ~3 ~117 minecraft:gray_stained_glass_pane
setblock ~-6 ~7 ~109 minecraft:gray_stained_glass_pane
setblock ~-6 ~7 ~120 minecraft:gray_stained_glass_pane
setblock ~-3 ~7 ~109 minecraft:gray_stained_glass_pane
setblock ~-3 ~7 ~120 minecraft:gray_stained_glass_pane
setblock ~ ~7 ~109 minecraft:gray_stained_glass_pane
setblock ~ ~7 ~120 minecraft:gray_stained_glass_pane
setblock ~3 ~7 ~109 minecraft:gray_stained_glass_pane
setblock ~3 ~7 ~120 minecraft:gray_stained_glass_pane
setblock ~-8 ~7 ~111 minecraft:gray_stained_glass_pane
setblock ~7 ~7 ~111 minecraft:gray_stained_glass_pane
setblock ~-8 ~7 ~114 minecraft:gray_stained_glass_pane
setblock ~7 ~7 ~114 minecraft:gray_stained_glass_pane
setblock ~-8 ~7 ~117 minecraft:gray_stained_glass_pane
setblock ~7 ~7 ~117 minecraft:gray_stained_glass_pane
setblock ~-6 ~11 ~109 minecraft:gray_stained_glass_pane
setblock ~-6 ~11 ~120 minecraft:gray_stained_glass_pane
setblock ~-3 ~11 ~109 minecraft:gray_stained_glass_pane
setblock ~-3 ~11 ~120 minecraft:gray_stained_glass_pane
setblock ~ ~11 ~109 minecraft:gray_stained_glass_pane
setblock ~ ~11 ~120 minecraft:gray_stained_glass_pane
setblock ~3 ~11 ~109 minecraft:gray_stained_glass_pane
setblock ~3 ~11 ~120 minecraft:gray_stained_glass_pane
setblock ~-8 ~11 ~111 minecraft:gray_stained_glass_pane
setblock ~7 ~11 ~111 minecraft:gray_stained_glass_pane
setblock ~-8 ~11 ~114 minecraft:gray_stained_glass_pane
setblock ~7 ~11 ~114 minecraft:gray_stained_glass_pane
setblock ~-8 ~11 ~117 minecraft:gray_stained_glass_pane
setblock ~7 ~11 ~117 minecraft:gray_stained_glass_pane
setblock ~-6 ~15 ~109 minecraft:gray_stained_glass_pane
setblock ~-6 ~15 ~120 minecraft:gray_stained_glass_pane
setblock ~-3 ~15 ~109 minecraft:gray_stained_glass_pane
setblock ~-3 ~15 ~120 minecraft:gray_stained_glass_pane
setblock ~ ~15 ~109 minecraft:gray_stained_glass_pane
setblock ~ ~15 ~120 minecraft:gray_stained_glass_pane
setblock ~3 ~15 ~109 minecraft:gray_stained_glass_pane
setblock ~3 ~15 ~120 minecraft:gray_stained_glass_pane
setblock ~-8 ~15 ~111 minecraft:gray_stained_glass_pane
setblock ~7 ~15 ~111 minecraft:gray_stained_glass_pane
setblock ~-8 ~15 ~114 minecraft:gray_stained_glass_pane
setblock ~7 ~15 ~114 minecraft:gray_stained_glass_pane
setblock ~-8 ~15 ~117 minecraft:gray_stained_glass_pane
setblock ~7 ~15 ~117 minecraft:gray_stained_glass_pane
setblock ~-6 ~19 ~109 minecraft:gray_stained_glass_pane
setblock ~-6 ~19 ~120 minecraft:gray_stained_glass_pane
setblock ~-3 ~19 ~109 minecraft:gray_stained_glass_pane
setblock ~-3 ~19 ~120 minecraft:gray_stained_glass_pane
setblock ~ ~19 ~109 minecraft:gray_stained_glass_pane
setblock ~ ~19 ~120 minecraft:gray_stained_glass_pane
setblock ~3 ~19 ~109 minecraft:gray_stained_glass_pane
setblock ~3 ~19 ~120 minecraft:gray_stained_glass_pane
setblock ~-8 ~19 ~111 minecraft:gray_stained_glass_pane
setblock ~7 ~19 ~111 minecraft:gray_stained_glass_pane
setblock ~-8 ~19 ~114 minecraft:gray_stained_glass_pane
setblock ~7 ~19 ~114 minecraft:gray_stained_glass_pane
setblock ~-8 ~19 ~117 minecraft:gray_stained_glass_pane
setblock ~7 ~19 ~117 minecraft:gray_stained_glass_pane
setblock ~-8 ~2 ~115 minecraft:dark_oak_door[half=lower]
setblock ~-8 ~3 ~115 minecraft:dark_oak_door[half=upper]
setblock ~-8 ~2 ~110 minecraft:cyan_stained_glass
setblock ~-8 ~2 ~112 minecraft:cyan_stained_glass
setblock ~-8 ~2 ~114 minecraft:cyan_stained_glass
setblock ~-8 ~2 ~116 minecraft:cyan_stained_glass
setblock ~-8 ~2 ~118 minecraft:cyan_stained_glass
fill ~43 ~1 ~-118 ~50 ~16 ~-112 minecraft:calcite
fill ~44 ~2 ~-117 ~49 ~15 ~-113 minecraft:air
fill ~44 ~4 ~-117 ~49 ~4 ~-113 minecraft:smooth_stone
fill ~44 ~8 ~-117 ~49 ~8 ~-113 minecraft:smooth_stone
fill ~44 ~12 ~-117 ~49 ~12 ~-113 minecraft:smooth_stone
fill ~43 ~17 ~-118 ~50 ~17 ~-112 minecraft:cyan_terracotta
setblock ~45 ~3 ~-118 minecraft:gray_stained_glass_pane
setblock ~45 ~3 ~-112 minecraft:gray_stained_glass_pane
setblock ~48 ~3 ~-118 minecraft:gray_stained_glass_pane
setblock ~48 ~3 ~-112 minecraft:gray_stained_glass_pane
setblock ~43 ~3 ~-116 minecraft:gray_stained_glass_pane
setblock ~50 ~3 ~-116 minecraft:gray_stained_glass_pane
setblock ~45 ~7 ~-118 minecraft:gray_stained_glass_pane
setblock ~45 ~7 ~-112 minecraft:gray_stained_glass_pane
setblock ~48 ~7 ~-118 minecraft:gray_stained_glass_pane
setblock ~48 ~7 ~-112 minecraft:gray_stained_glass_pane
setblock ~43 ~7 ~-116 minecraft:gray_stained_glass_pane
setblock ~50 ~7 ~-116 minecraft:gray_stained_glass_pane
setblock ~45 ~11 ~-118 minecraft:gray_stained_glass_pane
setblock ~45 ~11 ~-112 minecraft:gray_stained_glass_pane
setblock ~48 ~11 ~-118 minecraft:gray_stained_glass_pane
setblock ~48 ~11 ~-112 minecraft:gray_stained_glass_pane
setblock ~43 ~11 ~-116 minecraft:gray_stained_glass_pane
setblock ~50 ~11 ~-116 minecraft:gray_stained_glass_pane
setblock ~45 ~15 ~-118 minecraft:gray_stained_glass_pane
setblock ~45 ~15 ~-112 minecraft:gray_stained_glass_pane
setblock ~48 ~15 ~-118 minecraft:gray_stained_glass_pane
setblock ~48 ~15 ~-112 minecraft:gray_stained_glass_pane
setblock ~43 ~15 ~-116 minecraft:gray_stained_glass_pane
setblock ~50 ~15 ~-116 minecraft:gray_stained_glass_pane
setblock ~43 ~2 ~-115 minecraft:dark_oak_door[half=lower]
setblock ~43 ~3 ~-115 minecraft:dark_oak_door[half=upper]
fill ~-69 ~1 ~36 ~-60 ~16 ~44 minecraft:stone_bricks
fill ~-68 ~2 ~37 ~-61 ~15 ~43 minecraft:air
fill ~-68 ~4 ~37 ~-61 ~4 ~43 minecraft:smooth_stone
fill ~-68 ~8 ~37 ~-61 ~8 ~43 minecraft:smooth_stone
fill ~-68 ~12 ~37 ~-61 ~12 ~43 minecraft:smooth_stone
fill ~-69 ~17 ~36 ~-60 ~17 ~44 minecraft:deepslate_bricks
fill ~-67 ~1 ~38 ~-62 ~20 ~42 minecraft:stone_bricks
fill ~-66 ~2 ~39 ~-63 ~19 ~41 minecraft:air
fill ~-66 ~4 ~39 ~-63 ~4 ~41 minecraft:smooth_stone
fill ~-66 ~8 ~39 ~-63 ~8 ~41 minecraft:smooth_stone
fill ~-66 ~12 ~39 ~-63 ~12 ~41 minecraft:smooth_stone
fill ~-66 ~16 ~39 ~-63 ~16 ~41 minecraft:smooth_stone
fill ~-67 ~21 ~38 ~-62 ~21 ~42 minecraft:deepslate_bricks
setblock ~-67 ~3 ~36 minecraft:gray_stained_glass_pane
setblock ~-67 ~3 ~44 minecraft:gray_stained_glass_pane
setblock ~-64 ~3 ~36 minecraft:gray_stained_glass_pane
setblock ~-64 ~3 ~44 minecraft:gray_stained_glass_pane
setblock ~-69 ~3 ~38 minecraft:gray_stained_glass_pane
setblock ~-60 ~3 ~38 minecraft:gray_stained_glass_pane
setblock ~-69 ~3 ~41 minecraft:gray_stained_glass_pane
setblock ~-60 ~3 ~41 minecraft:gray_stained_glass_pane
setblock ~-67 ~7 ~36 minecraft:gray_stained_glass_pane
setblock ~-67 ~7 ~44 minecraft:gray_stained_glass_pane
setblock ~-64 ~7 ~36 minecraft:gray_stained_glass_pane
setblock ~-64 ~7 ~44 minecraft:gray_stained_glass_pane
setblock ~-69 ~7 ~38 minecraft:gray_stained_glass_pane
setblock ~-60 ~7 ~38 minecraft:gray_stained_glass_pane
setblock ~-69 ~7 ~41 minecraft:gray_stained_glass_pane
setblock ~-60 ~7 ~41 minecraft:gray_stained_glass_pane
setblock ~-67 ~11 ~36 minecraft:gray_stained_glass_pane
setblock ~-67 ~11 ~44 minecraft:gray_stained_glass_pane
setblock ~-64 ~11 ~36 minecraft:gray_stained_glass_pane
setblock ~-64 ~11 ~44 minecraft:gray_stained_glass_pane
setblock ~-69 ~11 ~38 minecraft:gray_stained_glass_pane
setblock ~-60 ~11 ~38 minecraft:gray_stained_glass_pane
setblock ~-69 ~11 ~41 minecraft:gray_stained_glass_pane
setblock ~-60 ~11 ~41 minecraft:gray_stained_glass_pane
setblock ~-67 ~15 ~36 minecraft:gray_stained_glass_pane
setblock ~-67 ~15 ~44 minecraft:gray_stained_glass_pane
setblock ~-64 ~15 ~36 minecraft:gray_stained_glass_pane
setblock ~-64 ~15 ~44 minecraft:gray_stained_glass_pane
setblock ~-69 ~15 ~38 minecraft:gray_stained_glass_pane
setblock ~-60 ~15 ~38 minecraft:gray_stained_glass_pane
setblock ~-69 ~15 ~41 minecraft:gray_stained_glass_pane
setblock ~-60 ~15 ~41 minecraft:gray_stained_glass_pane
setblock ~-67 ~19 ~36 minecraft:gray_stained_glass_pane
setblock ~-67 ~19 ~44 minecraft:gray_stained_glass_pane
setblock ~-64 ~19 ~36 minecraft:gray_stained_glass_pane
setblock ~-64 ~19 ~44 minecraft:gray_stained_glass_pane
setblock ~-69 ~19 ~38 minecraft:gray_stained_glass_pane
setblock ~-60 ~19 ~38 minecraft:gray_stained_glass_pane
setblock ~-69 ~19 ~41 minecraft:gray_stained_glass_pane
setblock ~-60 ~19 ~41 minecraft:gray_stained_glass_pane
setblock ~-64 ~2 ~36 minecraft:dark_oak_door[half=lower]
setblock ~-64 ~3 ~36 minecraft:dark_oak_door[half=upper]
setblock ~-68 ~2 ~36 minecraft:cyan_stained_glass
setblock ~-66 ~2 ~36 minecraft:cyan_stained_glass
setblock ~-64 ~2 ~36 minecraft:cyan_stained_glass
setblock ~-62 ~2 ~36 minecraft:cyan_stained_glass
fill ~21 ~1 ~-108 ~27 ~16 ~-98 minecraft:light_gray_concrete
fill ~22 ~2 ~-107 ~26 ~15 ~-99 minecraft:air
fill ~22 ~4 ~-107 ~26 ~4 ~-99 minecraft:smooth_stone
fill ~22 ~8 ~-107 ~26 ~8 ~-99 minecraft:smooth_stone
fill ~22 ~12 ~-107 ~26 ~12 ~-99 minecraft:smooth_stone
fill ~21 ~17 ~-108 ~27 ~17 ~-98 minecraft:gray_concrete
setblock ~23 ~3 ~-108 minecraft:gray_stained_glass_pane
setblock ~23 ~3 ~-98 minecraft:gray_stained_glass_pane
setblock ~21 ~3 ~-106 minecraft:gray_stained_glass_pane
setblock ~27 ~3 ~-106 minecraft:gray_stained_glass_pane
setblock ~21 ~3 ~-103 minecraft:gray_stained_glass_pane
setblock ~27 ~3 ~-103 minecraft:gray_stained_glass_pane
setblock ~21 ~3 ~-100 minecraft:gray_stained_glass_pane
setblock ~27 ~3 ~-100 minecraft:gray_stained_glass_pane
setblock ~23 ~7 ~-108 minecraft:gray_stained_glass_pane
setblock ~23 ~7 ~-98 minecraft:gray_stained_glass_pane
setblock ~21 ~7 ~-106 minecraft:gray_stained_glass_pane
setblock ~27 ~7 ~-106 minecraft:gray_stained_glass_pane
setblock ~21 ~7 ~-103 minecraft:gray_stained_glass_pane
setblock ~27 ~7 ~-103 minecraft:gray_stained_glass_pane
setblock ~21 ~7 ~-100 minecraft:gray_stained_glass_pane
setblock ~27 ~7 ~-100 minecraft:gray_stained_glass_pane
setblock ~23 ~11 ~-108 minecraft:gray_stained_glass_pane
setblock ~23 ~11 ~-98 minecraft:gray_stained_glass_pane
setblock ~21 ~11 ~-106 minecraft:gray_stained_glass_pane
setblock ~27 ~11 ~-106 minecraft:gray_stained_glass_pane
setblock ~21 ~11 ~-103 minecraft:gray_stained_glass_pane
setblock ~27 ~11 ~-103 minecraft:gray_stained_glass_pane
setblock ~21 ~11 ~-100 minecraft:gray_stained_glass_pane
setblock ~27 ~11 ~-100 minecraft:gray_stained_glass_pane
setblock ~23 ~15 ~-108 minecraft:gray_stained_glass_pane
setblock ~23 ~15 ~-98 minecraft:gray_stained_glass_pane
setblock ~21 ~15 ~-106 minecraft:gray_stained_glass_pane
setblock ~27 ~15 ~-106 minecraft:gray_stained_glass_pane
setblock ~21 ~15 ~-103 minecraft:gray_stained_glass_pane
setblock ~27 ~15 ~-103 minecraft:gray_stained_glass_pane
setblock ~21 ~15 ~-100 minecraft:gray_stained_glass_pane
setblock ~27 ~15 ~-100 minecraft:gray_stained_glass_pane
setblock ~24 ~2 ~-98 minecraft:dark_oak_door[half=lower]
setblock ~24 ~3 ~-98 minecraft:dark_oak_door[half=upper]
fill ~21 ~18 ~-108 ~27 ~18 ~-98 minecraft:deepslate_tile_slab
fill ~22 ~19 ~-107 ~26 ~19 ~-99 minecraft:deepslate_tile_slab
fill ~23 ~20 ~-106 ~25 ~20 ~-100 minecraft:deepslate_tile_slab
fill ~-121 ~1 ~85 ~-114 ~8 ~96 minecraft:calcite
fill ~-120 ~2 ~86 ~-115 ~7 ~95 minecraft:air
fill ~-120 ~4 ~86 ~-115 ~4 ~95 minecraft:smooth_stone
fill ~-121 ~9 ~85 ~-114 ~9 ~96 minecraft:cyan_terracotta
setblock ~-119 ~3 ~85 minecraft:gray_stained_glass_pane
setblock ~-119 ~3 ~96 minecraft:gray_stained_glass_pane
setblock ~-116 ~3 ~85 minecraft:gray_stained_glass_pane
setblock ~-116 ~3 ~96 minecraft:gray_stained_glass_pane
setblock ~-121 ~3 ~87 minecraft:gray_stained_glass_pane
setblock ~-114 ~3 ~87 minecraft:gray_stained_glass_pane
setblock ~-121 ~3 ~90 minecraft:gray_stained_glass_pane
setblock ~-114 ~3 ~90 minecraft:gray_stained_glass_pane
setblock ~-121 ~3 ~93 minecraft:gray_stained_glass_pane
setblock ~-114 ~3 ~93 minecraft:gray_stained_glass_pane
setblock ~-119 ~7 ~85 minecraft:gray_stained_glass_pane
setblock ~-119 ~7 ~96 minecraft:gray_stained_glass_pane
setblock ~-116 ~7 ~85 minecraft:gray_stained_glass_pane
setblock ~-116 ~7 ~96 minecraft:gray_stained_glass_pane
setblock ~-121 ~7 ~87 minecraft:gray_stained_glass_pane
setblock ~-114 ~7 ~87 minecraft:gray_stained_glass_pane
setblock ~-121 ~7 ~90 minecraft:gray_stained_glass_pane
setblock ~-114 ~7 ~90 minecraft:gray_stained_glass_pane
setblock ~-121 ~7 ~93 minecraft:gray_stained_glass_pane
setblock ~-114 ~7 ~93 minecraft:gray_stained_glass_pane
setblock ~-117 ~2 ~96 minecraft:dark_oak_door[half=lower]
setblock ~-117 ~3 ~96 minecraft:dark_oak_door[half=upper]
fill ~-121 ~10 ~85 ~-114 ~10 ~96 minecraft:deepslate_tile_slab
fill ~-120 ~11 ~86 ~-115 ~11 ~95 minecraft:deepslate_tile_slab
fill ~-119 ~12 ~87 ~-116 ~12 ~94 minecraft:deepslate_tile_slab
fill ~-97 ~1 ~59 ~-85 ~12 ~69 minecraft:stone_bricks
fill ~-96 ~2 ~60 ~-86 ~11 ~68 minecraft:air
fill ~-96 ~4 ~60 ~-86 ~4 ~68 minecraft:smooth_stone
fill ~-96 ~8 ~60 ~-86 ~8 ~68 minecraft:smooth_stone
fill ~-97 ~13 ~59 ~-85 ~13 ~69 minecraft:deepslate_bricks
fill ~-99 ~1 ~61 ~-98 ~12 ~69 minecraft:stone_bricks
fill ~-98 ~4 ~62 ~-99 ~4 ~68 minecraft:smooth_stone
fill ~-98 ~8 ~62 ~-99 ~8 ~68 minecraft:smooth_stone
fill ~-99 ~13 ~61 ~-98 ~13 ~69 minecraft:deepslate_bricks
setblock ~-97 ~3 ~59 minecraft:gray_stained_glass_pane
setblock ~-97 ~3 ~69 minecraft:gray_stained_glass_pane
setblock ~-94 ~3 ~59 minecraft:gray_stained_glass_pane
setblock ~-94 ~3 ~69 minecraft:gray_stained_glass_pane
setblock ~-91 ~3 ~59 minecraft:gray_stained_glass_pane
setblock ~-91 ~3 ~69 minecraft:gray_stained_glass_pane
setblock ~-88 ~3 ~59 minecraft:gray_stained_glass_pane
setblock ~-88 ~3 ~69 minecraft:gray_stained_glass_pane
setblock ~-99 ~3 ~61 minecraft:gray_stained_glass_pane
setblock ~-85 ~3 ~61 minecraft:gray_stained_glass_pane
setblock ~-99 ~3 ~64 minecraft:gray_stained_glass_pane
setblock ~-85 ~3 ~64 minecraft:gray_stained_glass_pane
setblock ~-99 ~3 ~67 minecraft:gray_stained_glass_pane
setblock ~-85 ~3 ~67 minecraft:gray_stained_glass_pane
setblock ~-97 ~7 ~59 minecraft:gray_stained_glass_pane
setblock ~-97 ~7 ~69 minecraft:gray_stained_glass_pane
setblock ~-94 ~7 ~59 minecraft:gray_stained_glass_pane
setblock ~-94 ~7 ~69 minecraft:gray_stained_glass_pane
setblock ~-91 ~7 ~59 minecraft:gray_stained_glass_pane
setblock ~-91 ~7 ~69 minecraft:gray_stained_glass_pane
setblock ~-88 ~7 ~59 minecraft:gray_stained_glass_pane
setblock ~-88 ~7 ~69 minecraft:gray_stained_glass_pane
setblock ~-99 ~7 ~61 minecraft:gray_stained_glass_pane
setblock ~-85 ~7 ~61 minecraft:gray_stained_glass_pane
setblock ~-99 ~7 ~64 minecraft:gray_stained_glass_pane
setblock ~-85 ~7 ~64 minecraft:gray_stained_glass_pane
setblock ~-99 ~7 ~67 minecraft:gray_stained_glass_pane
setblock ~-85 ~7 ~67 minecraft:gray_stained_glass_pane
setblock ~-97 ~11 ~59 minecraft:gray_stained_glass_pane
setblock ~-97 ~11 ~69 minecraft:gray_stained_glass_pane
setblock ~-94 ~11 ~59 minecraft:gray_stained_glass_pane
setblock ~-94 ~11 ~69 minecraft:gray_stained_glass_pane
setblock ~-91 ~11 ~59 minecraft:gray_stained_glass_pane
setblock ~-91 ~11 ~69 minecraft:gray_stained_glass_pane
setblock ~-88 ~11 ~59 minecraft:gray_stained_glass_pane
setblock ~-88 ~11 ~69 minecraft:gray_stained_glass_pane
setblock ~-99 ~11 ~61 minecraft:gray_stained_glass_pane
setblock ~-85 ~11 ~61 minecraft:gray_stained_glass_pane
setblock ~-99 ~11 ~64 minecraft:gray_stained_glass_pane
setblock ~-85 ~11 ~64 minecraft:gray_stained_glass_pane
setblock ~-99 ~11 ~67 minecraft:gray_stained_glass_pane
setblock ~-85 ~11 ~67 minecraft:gray_stained_glass_pane
setblock ~-92 ~2 ~59 minecraft:dark_oak_door[half=lower]
setblock ~-92 ~3 ~59 minecraft:dark_oak_door[half=upper]
setblock ~-98 ~2 ~59 minecraft:cyan_stained_glass
setblock ~-96 ~2 ~59 minecraft:cyan_stained_glass
setblock ~-94 ~2 ~59 minecraft:cyan_stained_glass
setblock ~-92 ~2 ~59 minecraft:cyan_stained_glass
setblock ~-90 ~2 ~59 minecraft:cyan_stained_glass
setblock ~-88 ~2 ~59 minecraft:cyan_stained_glass
setblock ~-86 ~2 ~59 minecraft:cyan_stained_glass
fill ~-37 ~1 ~36 ~-27 ~20 ~45 minecraft:stone_bricks
fill ~-36 ~2 ~37 ~-28 ~19 ~44 minecraft:air
fill ~-36 ~4 ~37 ~-28 ~4 ~44 minecraft:smooth_stone
fill ~-36 ~8 ~37 ~-28 ~8 ~44 minecraft:smooth_stone
fill ~-36 ~12 ~37 ~-28 ~12 ~44 minecraft:smooth_stone
fill ~-36 ~16 ~37 ~-28 ~16 ~44 minecraft:smooth_stone
fill ~-37 ~21 ~36 ~-27 ~21 ~45 minecraft:deepslate_bricks
fill ~-35 ~1 ~38 ~-29 ~24 ~43 minecraft:stone_bricks
fill ~-34 ~2 ~39 ~-30 ~23 ~42 minecraft:air
fill ~-34 ~4 ~39 ~-30 ~4 ~42 minecraft:smooth_stone
fill ~-34 ~8 ~39 ~-30 ~8 ~42 minecraft:smooth_stone
fill ~-34 ~12 ~39 ~-30 ~12 ~42 minecraft:smooth_stone
fill ~-34 ~16 ~39 ~-30 ~16 ~42 minecraft:smooth_stone
fill ~-34 ~20 ~39 ~-30 ~20 ~42 minecraft:smooth_stone
fill ~-35 ~25 ~38 ~-29 ~25 ~43 minecraft:deepslate_bricks
setblock ~-35 ~3 ~36 minecraft:gray_stained_glass_pane
setblock ~-35 ~3 ~45 minecraft:gray_stained_glass_pane
setblock ~-32 ~3 ~36 minecraft:gray_stained_glass_pane
setblock ~-32 ~3 ~45 minecraft:gray_stained_glass_pane
setblock ~-29 ~3 ~36 minecraft:gray_stained_glass_pane
setblock ~-29 ~3 ~45 minecraft:gray_stained_glass_pane
setblock ~-37 ~3 ~38 minecraft:gray_stained_glass_pane
setblock ~-27 ~3 ~38 minecraft:gray_stained_glass_pane
setblock ~-37 ~3 ~41 minecraft:gray_stained_glass_pane
setblock ~-27 ~3 ~41 minecraft:gray_stained_glass_pane
setblock ~-35 ~7 ~36 minecraft:gray_stained_glass_pane
setblock ~-35 ~7 ~45 minecraft:gray_stained_glass_pane
setblock ~-32 ~7 ~36 minecraft:gray_stained_glass_pane
setblock ~-32 ~7 ~45 minecraft:gray_stained_glass_pane
setblock ~-29 ~7 ~36 minecraft:gray_stained_glass_pane
setblock ~-29 ~7 ~45 minecraft:gray_stained_glass_pane
setblock ~-37 ~7 ~38 minecraft:gray_stained_glass_pane
setblock ~-27 ~7 ~38 minecraft:gray_stained_glass_pane
setblock ~-37 ~7 ~41 minecraft:gray_stained_glass_pane
setblock ~-27 ~7 ~41 minecraft:gray_stained_glass_pane
setblock ~-35 ~11 ~36 minecraft:gray_stained_glass_pane
setblock ~-35 ~11 ~45 minecraft:gray_stained_glass_pane
setblock ~-32 ~11 ~36 minecraft:gray_stained_glass_pane
setblock ~-32 ~11 ~45 minecraft:gray_stained_glass_pane
setblock ~-29 ~11 ~36 minecraft:gray_stained_glass_pane
setblock ~-29 ~11 ~45 minecraft:gray_stained_glass_pane
setblock ~-37 ~11 ~38 minecraft:gray_stained_glass_pane
setblock ~-27 ~11 ~38 minecraft:gray_stained_glass_pane
setblock ~-37 ~11 ~41 minecraft:gray_stained_glass_pane
setblock ~-27 ~11 ~41 minecraft:gray_stained_glass_pane
setblock ~-35 ~15 ~36 minecraft:gray_stained_glass_pane
setblock ~-35 ~15 ~45 minecraft:gray_stained_glass_pane
setblock ~-32 ~15 ~36 minecraft:gray_stained_glass_pane
setblock ~-32 ~15 ~45 minecraft:gray_stained_glass_pane
setblock ~-29 ~15 ~36 minecraft:gray_stained_glass_pane
setblock ~-29 ~15 ~45 minecraft:gray_stained_glass_pane
setblock ~-37 ~15 ~38 minecraft:gray_stained_glass_pane
setblock ~-27 ~15 ~38 minecraft:gray_stained_glass_pane
setblock ~-37 ~15 ~41 minecraft:gray_stained_glass_pane
setblock ~-27 ~15 ~41 minecraft:gray_stained_glass_pane
setblock ~-35 ~19 ~36 minecraft:gray_stained_glass_pane
setblock ~-35 ~19 ~45 minecraft:gray_stained_glass_pane
setblock ~-32 ~19 ~36 minecraft:gray_stained_glass_pane
setblock ~-32 ~19 ~45 minecraft:gray_stained_glass_pane
setblock ~-29 ~19 ~36 minecraft:gray_stained_glass_pane
setblock ~-29 ~19 ~45 minecraft:gray_stained_glass_pane
setblock ~-37 ~19 ~38 minecraft:gray_stained_glass_pane
setblock ~-27 ~19 ~38 minecraft:gray_stained_glass_pane
setblock ~-37 ~19 ~41 minecraft:gray_stained_glass_pane
setblock ~-27 ~19 ~41 minecraft:gray_stained_glass_pane
setblock ~-35 ~23 ~36 minecraft:gray_stained_glass_pane
setblock ~-35 ~23 ~45 minecraft:gray_stained_glass_pane
setblock ~-32 ~23 ~36 minecraft:gray_stained_glass_pane
setblock ~-32 ~23 ~45 minecraft:gray_stained_glass_pane
setblock ~-29 ~23 ~36 minecraft:gray_stained_glass_pane
setblock ~-29 ~23 ~45 minecraft:gray_stained_glass_pane
setblock ~-37 ~23 ~38 minecraft:gray_stained_glass_pane
setblock ~-27 ~23 ~38 minecraft:gray_stained_glass_pane
setblock ~-37 ~23 ~41 minecraft:gray_stained_glass_pane
setblock ~-27 ~23 ~41 minecraft:gray_stained_glass_pane
setblock ~-32 ~2 ~36 minecraft:dark_oak_door[half=lower]
setblock ~-32 ~3 ~36 minecraft:dark_oak_door[half=upper]
setblock ~-36 ~2 ~36 minecraft:cyan_stained_glass
setblock ~-34 ~2 ~36 minecraft:cyan_stained_glass
setblock ~-32 ~2 ~36 minecraft:cyan_stained_glass
setblock ~-30 ~2 ~36 minecraft:cyan_stained_glass
setblock ~-28 ~2 ~36 minecraft:cyan_stained_glass
fill ~-124 ~1 ~-118 ~-118 ~16 ~-108 minecraft:light_gray_concrete
fill ~-123 ~2 ~-117 ~-119 ~15 ~-109 minecraft:air
fill ~-123 ~4 ~-117 ~-119 ~4 ~-109 minecraft:smooth_stone
fill ~-123 ~8 ~-117 ~-119 ~8 ~-109 minecraft:smooth_stone
fill ~-123 ~12 ~-117 ~-119 ~12 ~-109 minecraft:smooth_stone
fill ~-124 ~17 ~-118 ~-118 ~17 ~-108 minecraft:gray_concrete
setblock ~-122 ~3 ~-118 minecraft:gray_stained_glass_pane
setblock ~-122 ~3 ~-108 minecraft:gray_stained_glass_pane
setblock ~-124 ~3 ~-116 minecraft:gray_stained_glass_pane
setblock ~-118 ~3 ~-116 minecraft:gray_stained_glass_pane
setblock ~-124 ~3 ~-113 minecraft:gray_stained_glass_pane
setblock ~-118 ~3 ~-113 minecraft:gray_stained_glass_pane
