# Buildings 265..272
# 265 row_house style=storefront context=arterial_front facing=north
fill ~15 ~-3 ~97 ~18 ~-1 ~102 minecraft:stone
fill ~15 ~0 ~97 ~18 ~5 ~102 minecraft:calcite
fill ~16 ~1 ~98 ~17 ~4 ~101 minecraft:air
fill ~16 ~4 ~98 ~17 ~4 ~101 minecraft:smooth_stone
fill ~15 ~2 ~99 ~15 ~3 ~99 minecraft:gray_stained_glass
fill ~18 ~2 ~99 ~18 ~3 ~99 minecraft:light_gray_stained_glass
setblock ~17 ~1 ~97 minecraft:iron_door[half=lower,facing=north]
setblock ~17 ~2 ~97 minecraft:iron_door[half=upper,facing=north]
fill ~16 ~1 ~97 ~17 ~3 ~97 minecraft:cyan_stained_glass
setblock ~17 ~1 ~97 minecraft:iron_door[half=lower,facing=north]
setblock ~17 ~2 ~97 minecraft:iron_door[half=upper,facing=north]
setblock ~17 ~3 ~96 minecraft:red_wool
fill ~15 ~6 ~97 ~18 ~6 ~102 minecraft:stone_brick_slab
# 266 workshop style=rowhouse context=local_front facing=west
fill ~-46 ~-3 ~63 ~-42 ~-1 ~68 minecraft:stone
fill ~-46 ~0 ~63 ~-42 ~7 ~68 minecraft:bricks
fill ~-45 ~1 ~64 ~-43 ~6 ~67 minecraft:air
fill ~-45 ~4 ~64 ~-43 ~4 ~67 minecraft:smooth_stone
fill ~-44 ~2 ~63 ~-44 ~3 ~63 minecraft:gray_stained_glass
fill ~-44 ~2 ~68 ~-44 ~3 ~68 minecraft:light_gray_stained_glass
fill ~-46 ~2 ~65 ~-46 ~3 ~65 minecraft:gray_stained_glass
fill ~-42 ~2 ~65 ~-42 ~3 ~65 minecraft:light_gray_stained_glass
setblock ~-46 ~1 ~65 minecraft:iron_door[half=lower,facing=west]
setblock ~-46 ~2 ~65 minecraft:iron_door[half=upper,facing=west]
fill ~-46 ~8 ~63 ~-42 ~8 ~68 minecraft:deepslate_tile_slab
fill ~-45 ~9 ~64 ~-43 ~9 ~67 minecraft:deepslate_tile_slab
setblock ~-47 ~3 ~65 minecraft:dark_oak_slab[type=top]
# 267 row_house style=rowhouse context=waterfront_front facing=north
fill ~95 ~-3 ~-59 ~98 ~-1 ~-54 minecraft:stone
fill ~95 ~0 ~-59 ~98 ~7 ~-54 minecraft:bricks
fill ~96 ~1 ~-58 ~97 ~6 ~-55 minecraft:air
fill ~96 ~4 ~-58 ~97 ~4 ~-55 minecraft:smooth_stone
fill ~95 ~2 ~-57 ~95 ~3 ~-57 minecraft:gray_stained_glass
fill ~98 ~2 ~-57 ~98 ~3 ~-57 minecraft:light_gray_stained_glass
setblock ~97 ~1 ~-59 minecraft:iron_door[half=lower,facing=north]
setblock ~97 ~2 ~-59 minecraft:iron_door[half=upper,facing=north]
fill ~95 ~8 ~-59 ~98 ~8 ~-54 minecraft:deepslate_tile_slab
fill ~96 ~9 ~-58 ~97 ~9 ~-55 minecraft:deepslate_tile_slab
setblock ~97 ~3 ~-60 minecraft:dark_oak_slab[type=top]
# 268 local_shop style=rowhouse context=waterfront_front facing=west
fill ~97 ~-3 ~73 ~100 ~-1 ~78 minecraft:stone
fill ~97 ~0 ~73 ~100 ~9 ~78 minecraft:bricks
fill ~98 ~1 ~74 ~99 ~8 ~77 minecraft:air
fill ~98 ~4 ~74 ~99 ~4 ~77 minecraft:smooth_stone
fill ~98 ~8 ~74 ~99 ~8 ~77 minecraft:smooth_stone
fill ~97 ~2 ~75 ~97 ~3 ~75 minecraft:gray_stained_glass
fill ~100 ~2 ~75 ~100 ~3 ~75 minecraft:light_gray_stained_glass
fill ~97 ~6 ~75 ~97 ~7 ~75 minecraft:gray_stained_glass
fill ~100 ~6 ~75 ~100 ~7 ~75 minecraft:light_gray_stained_glass
setblock ~97 ~1 ~75 minecraft:iron_door[half=lower,facing=west]
setblock ~97 ~2 ~75 minecraft:iron_door[half=upper,facing=west]
fill ~97 ~10 ~73 ~100 ~10 ~78 minecraft:deepslate_tile_slab
fill ~98 ~11 ~74 ~99 ~11 ~77 minecraft:deepslate_tile_slab
setblock ~96 ~3 ~75 minecraft:dark_oak_slab[type=top]
# 269 small_office style=stepped_house context=arterial_front facing=west
fill ~10 ~-3 ~3 ~13 ~-1 ~8 minecraft:stone
fill ~10 ~0 ~3 ~13 ~5 ~8 minecraft:light_gray_concrete
fill ~11 ~1 ~4 ~12 ~4 ~7 minecraft:air
fill ~11 ~4 ~4 ~12 ~4 ~7 minecraft:smooth_stone
fill ~10 ~2 ~5 ~10 ~3 ~5 minecraft:gray_stained_glass
fill ~13 ~2 ~5 ~13 ~3 ~5 minecraft:light_gray_stained_glass
setblock ~10 ~1 ~5 minecraft:iron_door[half=lower,facing=west]
setblock ~10 ~2 ~5 minecraft:iron_door[half=upper,facing=west]
fill ~10 ~6 ~3 ~13 ~6 ~8 minecraft:smooth_stone_slab
fill ~11 ~7 ~4 ~12 ~7 ~7 minecraft:smooth_stone_slab
setblock ~9 ~3 ~5 minecraft:dark_oak_slab[type=top]
# 270 small_office style=stepped_house context=arterial_front facing=south
fill ~48 ~-3 ~8 ~51 ~-1 ~13 minecraft:stone
fill ~48 ~0 ~8 ~51 ~5 ~13 minecraft:light_gray_concrete
fill ~49 ~1 ~9 ~50 ~4 ~12 minecraft:air
fill ~49 ~4 ~9 ~50 ~4 ~12 minecraft:smooth_stone
fill ~48 ~2 ~10 ~48 ~3 ~10 minecraft:gray_stained_glass
fill ~51 ~2 ~10 ~51 ~3 ~10 minecraft:light_gray_stained_glass
setblock ~50 ~1 ~13 minecraft:iron_door[half=lower,facing=south]
setblock ~50 ~2 ~13 minecraft:iron_door[half=upper,facing=south]
fill ~48 ~6 ~8 ~51 ~6 ~13 minecraft:smooth_stone_slab
fill ~49 ~7 ~9 ~50 ~7 ~12 minecraft:smooth_stone_slab
setblock ~50 ~3 ~14 minecraft:dark_oak_slab[type=top]
# 271 workshop style=stepped_house context=arterial_front facing=west
fill ~3 ~-3 ~-11 ~6 ~-1 ~-6 minecraft:stone
fill ~3 ~0 ~-11 ~6 ~5 ~-6 minecraft:light_gray_concrete
fill ~4 ~1 ~-10 ~5 ~4 ~-7 minecraft:air
fill ~4 ~4 ~-10 ~5 ~4 ~-7 minecraft:smooth_stone
fill ~3 ~2 ~-9 ~3 ~3 ~-9 minecraft:gray_stained_glass
fill ~6 ~2 ~-9 ~6 ~3 ~-9 minecraft:light_gray_stained_glass
setblock ~3 ~1 ~-9 minecraft:iron_door[half=lower,facing=west]
setblock ~3 ~2 ~-9 minecraft:iron_door[half=upper,facing=west]
fill ~3 ~6 ~-11 ~6 ~6 ~-6 minecraft:smooth_stone_slab
fill ~4 ~7 ~-10 ~5 ~7 ~-7 minecraft:smooth_stone_slab
setblock ~2 ~3 ~-9 minecraft:dark_oak_slab[type=top]
# 272 local_shop style=stepped_house context=back_block facing=north
fill ~-73 ~-3 ~23 ~-70 ~-1 ~28 minecraft:stone
fill ~-73 ~0 ~23 ~-70 ~9 ~28 minecraft:light_gray_concrete
fill ~-72 ~1 ~24 ~-71 ~8 ~27 minecraft:air
fill ~-72 ~4 ~24 ~-71 ~4 ~27 minecraft:smooth_stone
fill ~-72 ~8 ~24 ~-71 ~8 ~27 minecraft:smooth_stone
fill ~-73 ~2 ~25 ~-73 ~3 ~25 minecraft:gray_stained_glass
fill ~-70 ~2 ~25 ~-70 ~3 ~25 minecraft:light_gray_stained_glass
fill ~-73 ~6 ~25 ~-73 ~7 ~25 minecraft:gray_stained_glass
fill ~-70 ~6 ~25 ~-70 ~7 ~25 minecraft:light_gray_stained_glass
setblock ~-71 ~1 ~23 minecraft:iron_door[half=lower,facing=north]
setblock ~-71 ~2 ~23 minecraft:iron_door[half=upper,facing=north]
fill ~-73 ~10 ~23 ~-70 ~10 ~28 minecraft:smooth_stone_slab
fill ~-72 ~11 ~24 ~-71 ~11 ~27 minecraft:smooth_stone_slab
setblock ~-71 ~3 ~22 minecraft:dark_oak_slab[type=top]
