# Buildings 273..280
# 273 row_house style=rowhouse context=local_front facing=north
fill ~-28 ~-3 ~-38 ~-25 ~-1 ~-33 minecraft:stone
fill ~-28 ~0 ~-38 ~-25 ~5 ~-33 minecraft:white_terracotta
fill ~-27 ~1 ~-37 ~-26 ~4 ~-34 minecraft:air
fill ~-27 ~4 ~-37 ~-26 ~4 ~-34 minecraft:smooth_stone
fill ~-28 ~2 ~-36 ~-28 ~3 ~-36 minecraft:gray_stained_glass
fill ~-25 ~2 ~-36 ~-25 ~3 ~-36 minecraft:light_gray_stained_glass
setblock ~-26 ~1 ~-38 minecraft:iron_door[half=lower,facing=north]
setblock ~-26 ~2 ~-38 minecraft:iron_door[half=upper,facing=north]
fill ~-28 ~6 ~-38 ~-25 ~6 ~-33 minecraft:stone_brick_slab
fill ~-27 ~7 ~-37 ~-26 ~7 ~-34 minecraft:stone_brick_slab
setblock ~-26 ~3 ~-39 minecraft:dark_oak_slab[type=top]
# 274 local_shop style=corner_store context=collector_front facing=east
fill ~-99 ~-3 ~99 ~-94 ~-1 ~102 minecraft:stone
fill ~-99 ~0 ~99 ~-94 ~11 ~102 minecraft:mud_bricks
fill ~-98 ~1 ~100 ~-95 ~10 ~101 minecraft:air
fill ~-98 ~4 ~100 ~-95 ~4 ~101 minecraft:smooth_stone
fill ~-98 ~8 ~100 ~-95 ~8 ~101 minecraft:smooth_stone
fill ~-97 ~2 ~99 ~-97 ~3 ~99 minecraft:gray_stained_glass
fill ~-97 ~2 ~102 ~-97 ~3 ~102 minecraft:light_gray_stained_glass
fill ~-97 ~6 ~99 ~-97 ~7 ~99 minecraft:gray_stained_glass
fill ~-97 ~6 ~102 ~-97 ~7 ~102 minecraft:light_gray_stained_glass
setblock ~-94 ~1 ~101 minecraft:iron_door[half=lower,facing=east]
setblock ~-94 ~2 ~101 minecraft:iron_door[half=upper,facing=east]
fill ~-94 ~1 ~100 ~-94 ~3 ~101 minecraft:cyan_stained_glass
setblock ~-94 ~1 ~101 minecraft:iron_door[half=lower,facing=east]
setblock ~-94 ~2 ~101 minecraft:iron_door[half=upper,facing=east]
setblock ~-93 ~3 ~101 minecraft:red_wool
fill ~-99 ~12 ~99 ~-94 ~12 ~102 minecraft:deepslate_tile_slab
# 275 small_office style=bay_office context=local_front facing=north
fill ~-10 ~-3 ~110 ~-7 ~-1 ~115 minecraft:stone
fill ~-10 ~0 ~110 ~-7 ~7 ~115 minecraft:white_terracotta
fill ~-9 ~1 ~111 ~-8 ~6 ~114 minecraft:air
fill ~-9 ~4 ~111 ~-8 ~4 ~114 minecraft:smooth_stone
fill ~-10 ~2 ~112 ~-10 ~3 ~112 minecraft:gray_stained_glass
fill ~-7 ~2 ~112 ~-7 ~3 ~112 minecraft:light_gray_stained_glass
setblock ~-8 ~1 ~110 minecraft:iron_door[half=lower,facing=north]
setblock ~-8 ~2 ~110 minecraft:iron_door[half=upper,facing=north]
# 276 workshop style=sawtooth context=local_front facing=south
fill ~101 ~-3 ~-122 ~105 ~-1 ~-116 minecraft:stone
fill ~101 ~0 ~-122 ~105 ~5 ~-116 minecraft:bricks
fill ~102 ~1 ~-121 ~104 ~4 ~-117 minecraft:air
fill ~102 ~4 ~-121 ~104 ~4 ~-117 minecraft:smooth_stone
fill ~103 ~2 ~-122 ~103 ~3 ~-122 minecraft:gray_stained_glass
fill ~103 ~2 ~-116 ~103 ~3 ~-116 minecraft:light_gray_stained_glass
fill ~101 ~2 ~-120 ~101 ~3 ~-120 minecraft:gray_stained_glass
fill ~105 ~2 ~-120 ~105 ~3 ~-120 minecraft:light_gray_stained_glass
setblock ~103 ~1 ~-116 minecraft:iron_door[half=lower,facing=south]
setblock ~103 ~2 ~-116 minecraft:iron_door[half=upper,facing=south]
fill ~103 ~1 ~-116 ~103 ~4 ~-116 minecraft:polished_blackstone
fill ~103 ~4 ~-116 ~103 ~4 ~-116 minecraft:light_blue_stained_glass
fill ~103 ~7 ~-120 ~104 ~8 ~-118 minecraft:iron_block
fill ~101 ~6 ~-122 ~105 ~6 ~-116 minecraft:deepslate_tile_slab
# 277 small_office style=bay_office context=local_front facing=north
fill ~-8 ~-3 ~-38 ~-3 ~-1 ~-31 minecraft:stone
fill ~-8 ~0 ~-38 ~-3 ~11 ~-31 minecraft:light_gray_concrete
fill ~-7 ~1 ~-37 ~-4 ~10 ~-32 minecraft:air
fill ~-7 ~4 ~-37 ~-4 ~4 ~-32 minecraft:smooth_stone
fill ~-7 ~8 ~-37 ~-4 ~8 ~-32 minecraft:smooth_stone
fill ~-6 ~2 ~-38 ~-6 ~3 ~-38 minecraft:gray_stained_glass
fill ~-6 ~2 ~-31 ~-6 ~3 ~-31 minecraft:light_gray_stained_glass
fill ~-8 ~2 ~-36 ~-8 ~3 ~-36 minecraft:gray_stained_glass
fill ~-3 ~2 ~-36 ~-3 ~3 ~-36 minecraft:light_gray_stained_glass
fill ~-8 ~2 ~-33 ~-8 ~3 ~-33 minecraft:gray_stained_glass
fill ~-3 ~2 ~-33 ~-3 ~3 ~-33 minecraft:light_gray_stained_glass
fill ~-6 ~6 ~-38 ~-6 ~7 ~-38 minecraft:gray_stained_glass
fill ~-6 ~6 ~-31 ~-6 ~7 ~-31 minecraft:light_gray_stained_glass
fill ~-8 ~6 ~-36 ~-8 ~7 ~-36 minecraft:gray_stained_glass
fill ~-3 ~6 ~-36 ~-3 ~7 ~-36 minecraft:light_gray_stained_glass
fill ~-8 ~6 ~-33 ~-8 ~7 ~-33 minecraft:gray_stained_glass
fill ~-3 ~6 ~-33 ~-3 ~7 ~-33 minecraft:light_gray_stained_glass
setblock ~-6 ~1 ~-38 minecraft:iron_door[half=lower,facing=north]
setblock ~-6 ~2 ~-38 minecraft:iron_door[half=upper,facing=north]
fill ~-8 ~7 ~-38 ~-3 ~11 ~-31 minecraft:air
fill ~-7 ~7 ~-37 ~-4 ~11 ~-32 minecraft:light_gray_concrete
fill ~-6 ~8 ~-36 ~-5 ~10 ~-33 minecraft:air
fill ~-7 ~12 ~-37 ~-4 ~12 ~-32 minecraft:smooth_stone_slab
fill ~-6 ~2 ~-38 ~-5 ~7 ~-38 minecraft:blue_stained_glass
fill ~-7 ~1 ~-38 ~-7 ~7 ~-38 doomsday_decoration:cementwall
# 278 small_office style=civic_modern context=local_front facing=north
fill ~-124 ~-3 ~25 ~-121 ~-1 ~30 minecraft:stone
fill ~-124 ~0 ~25 ~-121 ~11 ~30 minecraft:mud_bricks
fill ~-123 ~1 ~26 ~-122 ~10 ~29 minecraft:air
fill ~-123 ~4 ~26 ~-122 ~4 ~29 minecraft:smooth_stone
fill ~-123 ~8 ~26 ~-122 ~8 ~29 minecraft:smooth_stone
fill ~-124 ~2 ~27 ~-124 ~3 ~27 minecraft:gray_stained_glass
fill ~-121 ~2 ~27 ~-121 ~3 ~27 minecraft:light_gray_stained_glass
fill ~-124 ~6 ~27 ~-124 ~7 ~27 minecraft:gray_stained_glass
fill ~-121 ~6 ~27 ~-121 ~7 ~27 minecraft:light_gray_stained_glass
setblock ~-122 ~1 ~25 minecraft:iron_door[half=lower,facing=north]
setblock ~-122 ~2 ~25 minecraft:iron_door[half=upper,facing=north]
fill ~-124 ~7 ~25 ~-121 ~11 ~30 minecraft:air
fill ~-123 ~7 ~26 ~-122 ~11 ~29 minecraft:mud_bricks
fill ~-122 ~8 ~27 ~-123 ~10 ~28 minecraft:air
fill ~-123 ~12 ~26 ~-122 ~12 ~29 minecraft:deepslate_tile_slab
# 279 shop_house style=corner_store context=collector_front facing=east
fill ~52 ~-3 ~45 ~57 ~-1 ~48 minecraft:stone
fill ~52 ~0 ~45 ~57 ~7 ~48 minecraft:gray_concrete
fill ~53 ~1 ~46 ~56 ~6 ~47 minecraft:air
fill ~53 ~4 ~46 ~56 ~4 ~47 minecraft:smooth_stone
fill ~54 ~2 ~45 ~54 ~3 ~45 minecraft:gray_stained_glass
fill ~54 ~2 ~48 ~54 ~3 ~48 minecraft:light_gray_stained_glass
setblock ~57 ~1 ~47 minecraft:iron_door[half=lower,facing=east]
setblock ~57 ~2 ~47 minecraft:iron_door[half=upper,facing=east]
fill ~57 ~1 ~46 ~57 ~3 ~47 minecraft:cyan_stained_glass
setblock ~57 ~1 ~47 minecraft:iron_door[half=lower,facing=east]
setblock ~57 ~2 ~47 minecraft:iron_door[half=upper,facing=east]
setblock ~58 ~3 ~47 minecraft:red_wool
fill ~52 ~8 ~45 ~57 ~8 ~48 minecraft:smooth_stone_slab
# 280 shop_house style=arcade_shop context=local_front facing=south
fill ~36 ~-3 ~-94 ~39 ~-1 ~-89 minecraft:stone
fill ~36 ~0 ~-94 ~39 ~5 ~-89 minecraft:bricks
fill ~37 ~1 ~-93 ~38 ~4 ~-90 minecraft:air
fill ~37 ~4 ~-93 ~38 ~4 ~-90 minecraft:smooth_stone
fill ~36 ~2 ~-92 ~36 ~3 ~-92 minecraft:gray_stained_glass
fill ~39 ~2 ~-92 ~39 ~3 ~-92 minecraft:light_gray_stained_glass
setblock ~38 ~1 ~-89 minecraft:iron_door[half=lower,facing=south]
setblock ~38 ~2 ~-89 minecraft:iron_door[half=upper,facing=south]
fill ~37 ~1 ~-89 ~38 ~3 ~-89 minecraft:cyan_stained_glass
setblock ~38 ~1 ~-89 minecraft:iron_door[half=lower,facing=south]
setblock ~38 ~2 ~-89 minecraft:iron_door[half=upper,facing=south]
setblock ~38 ~3 ~-88 minecraft:red_wool
fill ~37 ~4 ~-89 ~38 ~4 ~-89 minecraft:gray_concrete
fill ~36 ~6 ~-94 ~39 ~6 ~-89 minecraft:deepslate_tile_slab
