# Buildings 233..240
# 233 shop_house style=arcade_shop context=collector_front facing=east
fill ~-17 ~-3 ~36 ~-12 ~-1 ~39 minecraft:stone
fill ~-17 ~0 ~36 ~-12 ~5 ~39 minecraft:bricks
fill ~-16 ~1 ~37 ~-13 ~4 ~38 minecraft:air
fill ~-16 ~4 ~37 ~-13 ~4 ~38 minecraft:smooth_stone
fill ~-15 ~2 ~36 ~-15 ~3 ~36 minecraft:gray_stained_glass
fill ~-15 ~2 ~39 ~-15 ~3 ~39 minecraft:light_gray_stained_glass
setblock ~-12 ~1 ~38 minecraft:iron_door[half=lower,facing=east]
setblock ~-12 ~2 ~38 minecraft:iron_door[half=upper,facing=east]
fill ~-12 ~1 ~37 ~-12 ~3 ~38 minecraft:cyan_stained_glass
setblock ~-12 ~1 ~38 minecraft:iron_door[half=lower,facing=east]
setblock ~-12 ~2 ~38 minecraft:iron_door[half=upper,facing=east]
setblock ~-11 ~3 ~38 minecraft:red_wool
fill ~-12 ~4 ~37 ~-12 ~4 ~38 doomsday_decoration:redbrick
fill ~-17 ~6 ~36 ~-12 ~6 ~39 minecraft:deepslate_tile_slab
# 234 shop_house style=storefront context=local_front facing=north
fill ~6 ~-3 ~110 ~10 ~-1 ~116 minecraft:stone
fill ~6 ~0 ~110 ~10 ~5 ~116 minecraft:white_terracotta
fill ~7 ~1 ~111 ~9 ~4 ~115 minecraft:air
fill ~7 ~4 ~111 ~9 ~4 ~115 minecraft:smooth_stone
fill ~8 ~2 ~110 ~8 ~3 ~110 minecraft:gray_stained_glass
fill ~8 ~2 ~116 ~8 ~3 ~116 minecraft:light_gray_stained_glass
fill ~6 ~2 ~112 ~6 ~3 ~112 minecraft:gray_stained_glass
fill ~10 ~2 ~112 ~10 ~3 ~112 minecraft:light_gray_stained_glass
setblock ~8 ~1 ~110 minecraft:iron_door[half=lower,facing=north]
setblock ~8 ~2 ~110 minecraft:iron_door[half=upper,facing=north]
fill ~7 ~1 ~110 ~9 ~3 ~110 minecraft:cyan_stained_glass
setblock ~8 ~1 ~110 minecraft:iron_door[half=lower,facing=north]
setblock ~8 ~2 ~110 minecraft:iron_door[half=upper,facing=north]
setblock ~8 ~3 ~109 minecraft:red_wool
fill ~6 ~6 ~110 ~10 ~6 ~116 minecraft:dark_oak_slab
# 235 row_house style=stepped_house context=collector_front facing=east
fill ~-106 ~-3 ~37 ~-101 ~-1 ~40 minecraft:stone
fill ~-106 ~0 ~37 ~-101 ~11 ~40 minecraft:calcite
fill ~-105 ~1 ~38 ~-102 ~10 ~39 minecraft:air
fill ~-105 ~4 ~38 ~-102 ~4 ~39 minecraft:smooth_stone
fill ~-105 ~8 ~38 ~-102 ~8 ~39 minecraft:smooth_stone
fill ~-104 ~2 ~37 ~-104 ~3 ~37 minecraft:gray_stained_glass
fill ~-104 ~2 ~40 ~-104 ~3 ~40 minecraft:light_gray_stained_glass
fill ~-104 ~6 ~37 ~-104 ~7 ~37 minecraft:gray_stained_glass
fill ~-104 ~6 ~40 ~-104 ~7 ~40 minecraft:light_gray_stained_glass
setblock ~-101 ~1 ~39 minecraft:iron_door[half=lower,facing=east]
setblock ~-101 ~2 ~39 minecraft:iron_door[half=upper,facing=east]
fill ~-106 ~12 ~37 ~-101 ~12 ~40 minecraft:stone_brick_slab
fill ~-105 ~13 ~38 ~-102 ~13 ~39 minecraft:stone_brick_slab
setblock ~-100 ~3 ~39 minecraft:dark_oak_slab[type=top]
# 236 shop_house style=storefront context=local_front facing=south
fill ~65 ~-3 ~-111 ~68 ~-1 ~-106 minecraft:stone
fill ~65 ~0 ~-111 ~68 ~7 ~-106 minecraft:stone_bricks
fill ~66 ~1 ~-110 ~67 ~6 ~-107 minecraft:air
fill ~66 ~4 ~-110 ~67 ~4 ~-107 minecraft:smooth_stone
fill ~65 ~2 ~-109 ~65 ~3 ~-109 minecraft:gray_stained_glass
fill ~68 ~2 ~-109 ~68 ~3 ~-109 minecraft:light_gray_stained_glass
setblock ~67 ~1 ~-106 minecraft:iron_door[half=lower,facing=south]
setblock ~67 ~2 ~-106 minecraft:iron_door[half=upper,facing=south]
fill ~66 ~1 ~-106 ~67 ~3 ~-106 minecraft:cyan_stained_glass
setblock ~67 ~1 ~-106 minecraft:iron_door[half=lower,facing=south]
setblock ~67 ~2 ~-106 minecraft:iron_door[half=upper,facing=south]
setblock ~67 ~3 ~-105 minecraft:red_wool
fill ~65 ~8 ~-111 ~68 ~8 ~-106 minecraft:smooth_stone_slab
# 237 local_shop style=arcade_shop context=arterial_front facing=south
fill ~-15 ~-3 ~-17 ~-10 ~-1 ~-10 minecraft:stone
fill ~-15 ~0 ~-17 ~-10 ~11 ~-10 minecraft:bricks
fill ~-14 ~1 ~-16 ~-11 ~10 ~-11 minecraft:air
fill ~-14 ~4 ~-16 ~-11 ~4 ~-11 minecraft:smooth_stone
fill ~-14 ~8 ~-16 ~-11 ~8 ~-11 minecraft:smooth_stone
fill ~-13 ~2 ~-17 ~-13 ~3 ~-17 minecraft:gray_stained_glass
fill ~-13 ~2 ~-10 ~-13 ~3 ~-10 minecraft:light_gray_stained_glass
fill ~-15 ~2 ~-15 ~-15 ~3 ~-15 minecraft:gray_stained_glass
fill ~-10 ~2 ~-15 ~-10 ~3 ~-15 minecraft:light_gray_stained_glass
fill ~-15 ~2 ~-12 ~-15 ~3 ~-12 minecraft:gray_stained_glass
fill ~-10 ~2 ~-12 ~-10 ~3 ~-12 minecraft:light_gray_stained_glass
fill ~-13 ~6 ~-17 ~-13 ~7 ~-17 minecraft:gray_stained_glass
fill ~-13 ~6 ~-10 ~-13 ~7 ~-10 minecraft:light_gray_stained_glass
fill ~-15 ~6 ~-15 ~-15 ~7 ~-15 minecraft:gray_stained_glass
fill ~-10 ~6 ~-15 ~-10 ~7 ~-15 minecraft:light_gray_stained_glass
fill ~-15 ~6 ~-12 ~-15 ~7 ~-12 minecraft:gray_stained_glass
fill ~-10 ~6 ~-12 ~-10 ~7 ~-12 minecraft:light_gray_stained_glass
setblock ~-13 ~1 ~-10 minecraft:iron_door[half=lower,facing=south]
setblock ~-13 ~2 ~-10 minecraft:iron_door[half=upper,facing=south]
fill ~-14 ~1 ~-10 ~-11 ~3 ~-10 minecraft:cyan_stained_glass
setblock ~-13 ~1 ~-10 minecraft:iron_door[half=lower,facing=south]
setblock ~-13 ~2 ~-10 minecraft:iron_door[half=upper,facing=south]
setblock ~-13 ~3 ~-9 minecraft:red_wool
fill ~-14 ~4 ~-10 ~-11 ~4 ~-10 doomsday_decoration:redbrick
fill ~-15 ~12 ~-17 ~-10 ~12 ~-10 minecraft:deepslate_tile_slab
fill ~-13 ~13 ~-15 ~-11 ~14 ~-13 minecraft:light_gray_concrete
setblock ~-11 ~13 ~-14 minecraft:lightning_rod
fill ~-14 ~1 ~-10 ~-14 ~7 ~-10 doomsday_decoration:redbrick
setblock ~-13 ~3 ~-10 minecraft:red_carpet
# 238 row_house style=stepped_house context=collector_front facing=north
fill ~-61 ~-3 ~52 ~-56 ~-1 ~59 minecraft:stone
fill ~-61 ~0 ~52 ~-56 ~5 ~59 minecraft:light_gray_concrete
fill ~-60 ~1 ~53 ~-57 ~4 ~58 minecraft:air
fill ~-60 ~4 ~53 ~-57 ~4 ~58 minecraft:smooth_stone
fill ~-59 ~2 ~52 ~-59 ~3 ~52 minecraft:gray_stained_glass
fill ~-59 ~2 ~59 ~-59 ~3 ~59 minecraft:light_gray_stained_glass
fill ~-61 ~2 ~54 ~-61 ~3 ~54 minecraft:gray_stained_glass
fill ~-56 ~2 ~54 ~-56 ~3 ~54 minecraft:light_gray_stained_glass
fill ~-61 ~2 ~57 ~-61 ~3 ~57 minecraft:gray_stained_glass
fill ~-56 ~2 ~57 ~-56 ~3 ~57 minecraft:light_gray_stained_glass
setblock ~-59 ~1 ~52 minecraft:iron_door[half=lower,facing=north]
setblock ~-59 ~2 ~52 minecraft:iron_door[half=upper,facing=north]
fill ~-61 ~6 ~52 ~-56 ~6 ~59 minecraft:smooth_stone_slab
fill ~-60 ~7 ~53 ~-57 ~7 ~58 minecraft:smooth_stone_slab
setblock ~-59 ~3 ~51 minecraft:dark_oak_slab[type=top]
fill ~-60 ~1 ~52 ~-60 ~5 ~52 doomsday_decoration:porcelainbrickwall
# 239 row_house style=japanese_house context=arterial_front facing=north
fill ~74 ~-3 ~6 ~77 ~-1 ~11 minecraft:stone
fill ~74 ~0 ~6 ~77 ~9 ~11 minecraft:bricks
fill ~75 ~1 ~7 ~76 ~8 ~10 minecraft:air
fill ~75 ~4 ~7 ~76 ~4 ~10 minecraft:smooth_stone
fill ~75 ~8 ~7 ~76 ~8 ~10 minecraft:smooth_stone
fill ~74 ~2 ~8 ~74 ~3 ~8 minecraft:gray_stained_glass
fill ~77 ~2 ~8 ~77 ~3 ~8 minecraft:light_gray_stained_glass
fill ~74 ~6 ~8 ~74 ~7 ~8 minecraft:gray_stained_glass
fill ~77 ~6 ~8 ~77 ~7 ~8 minecraft:light_gray_stained_glass
setblock ~76 ~1 ~6 minecraft:iron_door[half=lower,facing=north]
setblock ~76 ~2 ~6 minecraft:iron_door[half=upper,facing=north]
fill ~74 ~10 ~6 ~77 ~10 ~11 minecraft:deepslate_tile_slab
fill ~75 ~11 ~7 ~76 ~11 ~10 minecraft:deepslate_tile_slab
setblock ~76 ~3 ~5 minecraft:dark_oak_slab[type=top]
# 240 shop_house style=arcade_shop context=local_front facing=south
fill ~-23 ~-3 ~94 ~-19 ~-1 ~100 minecraft:stone
fill ~-23 ~0 ~94 ~-19 ~5 ~100 minecraft:white_terracotta
fill ~-22 ~1 ~95 ~-20 ~4 ~99 minecraft:air
fill ~-22 ~4 ~95 ~-20 ~4 ~99 minecraft:smooth_stone
fill ~-21 ~2 ~94 ~-21 ~3 ~94 minecraft:gray_stained_glass
fill ~-21 ~2 ~100 ~-21 ~3 ~100 minecraft:light_gray_stained_glass
fill ~-23 ~2 ~96 ~-23 ~3 ~96 minecraft:gray_stained_glass
fill ~-19 ~2 ~96 ~-19 ~3 ~96 minecraft:light_gray_stained_glass
setblock ~-21 ~1 ~100 minecraft:iron_door[half=lower,facing=south]
setblock ~-21 ~2 ~100 minecraft:iron_door[half=upper,facing=south]
fill ~-22 ~1 ~100 ~-20 ~3 ~100 minecraft:cyan_stained_glass
setblock ~-21 ~1 ~100 minecraft:iron_door[half=lower,facing=south]
setblock ~-21 ~2 ~100 minecraft:iron_door[half=upper,facing=south]
setblock ~-21 ~3 ~101 minecraft:red_wool
fill ~-22 ~4 ~100 ~-20 ~4 ~100 minecraft:dark_oak_planks
fill ~-23 ~6 ~94 ~-19 ~6 ~100 minecraft:dark_oak_slab
