# Buildings 185..192
# 185 warehouse style=sawtooth context=back_block facing=west
fill ~76 ~-3 ~116 ~80 ~-1 ~125 minecraft:stone
fill ~76 ~0 ~116 ~80 ~8 ~125 minecraft:deepslate_bricks
fill ~77 ~1 ~117 ~79 ~7 ~124 minecraft:air
fill ~77 ~4 ~117 ~79 ~4 ~124 minecraft:smooth_stone
fill ~78 ~2 ~116 ~78 ~3 ~116 minecraft:gray_stained_glass
fill ~78 ~2 ~125 ~78 ~3 ~125 minecraft:light_gray_stained_glass
fill ~76 ~2 ~118 ~76 ~3 ~118 minecraft:gray_stained_glass
fill ~80 ~2 ~118 ~80 ~3 ~118 minecraft:light_gray_stained_glass
fill ~76 ~2 ~121 ~76 ~3 ~121 minecraft:gray_stained_glass
fill ~80 ~2 ~121 ~80 ~3 ~121 minecraft:light_gray_stained_glass
fill ~78 ~6 ~116 ~78 ~7 ~116 minecraft:gray_stained_glass
fill ~78 ~6 ~125 ~78 ~7 ~125 minecraft:light_gray_stained_glass
fill ~76 ~6 ~118 ~76 ~7 ~118 minecraft:gray_stained_glass
fill ~80 ~6 ~118 ~80 ~7 ~118 minecraft:light_gray_stained_glass
fill ~76 ~6 ~121 ~76 ~7 ~121 minecraft:gray_stained_glass
fill ~80 ~6 ~121 ~80 ~7 ~121 minecraft:light_gray_stained_glass
setblock ~76 ~1 ~120 minecraft:iron_door[half=lower,facing=west]
setblock ~76 ~2 ~120 minecraft:iron_door[half=upper,facing=west]
fill ~76 ~1 ~118 ~76 ~4 ~123 minecraft:polished_blackstone
fill ~76 ~5 ~118 ~76 ~5 ~123 minecraft:light_blue_stained_glass
fill ~78 ~10 ~118 ~79 ~11 ~120 minecraft:iron_block
fill ~76 ~9 ~116 ~80 ~9 ~125 minecraft:deepslate_tile_slab
# 186 logistics style=loading_bay context=back_block facing=west
fill ~-56 ~-3 ~-115 ~-50 ~-1 ~-110 minecraft:stone
fill ~-56 ~0 ~-115 ~-50 ~10 ~-110 minecraft:bricks
fill ~-55 ~1 ~-114 ~-51 ~9 ~-111 minecraft:air
fill ~-55 ~4 ~-114 ~-51 ~4 ~-111 minecraft:smooth_stone
fill ~-55 ~8 ~-114 ~-51 ~8 ~-111 minecraft:smooth_stone
fill ~-54 ~2 ~-115 ~-54 ~3 ~-115 minecraft:gray_stained_glass
fill ~-54 ~2 ~-110 ~-54 ~3 ~-110 minecraft:light_gray_stained_glass
fill ~-56 ~2 ~-113 ~-56 ~3 ~-113 minecraft:gray_stained_glass
fill ~-50 ~2 ~-113 ~-50 ~3 ~-113 minecraft:light_gray_stained_glass
fill ~-54 ~6 ~-115 ~-54 ~7 ~-115 minecraft:gray_stained_glass
fill ~-54 ~6 ~-110 ~-54 ~7 ~-110 minecraft:light_gray_stained_glass
fill ~-56 ~6 ~-113 ~-56 ~7 ~-113 minecraft:gray_stained_glass
fill ~-50 ~6 ~-113 ~-50 ~7 ~-113 minecraft:light_gray_stained_glass
setblock ~-56 ~1 ~-113 minecraft:iron_door[half=lower,facing=west]
setblock ~-56 ~2 ~-113 minecraft:iron_door[half=upper,facing=west]
fill ~-56 ~1 ~-113 ~-56 ~4 ~-112 minecraft:polished_blackstone
fill ~-56 ~5 ~-113 ~-56 ~5 ~-112 minecraft:light_blue_stained_glass
fill ~-54 ~12 ~-113 ~-52 ~13 ~-111 minecraft:iron_block
fill ~-56 ~11 ~-115 ~-50 ~11 ~-110 minecraft:deepslate_tile_slab
fill ~-54 ~12 ~-113 ~-52 ~13 ~-111 minecraft:light_gray_concrete
setblock ~-51 ~12 ~-112 minecraft:lightning_rod
# 187 garage style=sawtooth context=back_block facing=north
fill ~64 ~-3 ~-126 ~70 ~-1 ~-121 minecraft:stone
fill ~64 ~0 ~-126 ~70 ~6 ~-121 minecraft:bricks
fill ~65 ~1 ~-125 ~69 ~5 ~-122 minecraft:air
fill ~65 ~4 ~-125 ~69 ~4 ~-122 minecraft:smooth_stone
fill ~66 ~2 ~-126 ~66 ~3 ~-126 minecraft:gray_stained_glass
fill ~66 ~2 ~-121 ~66 ~3 ~-121 minecraft:light_gray_stained_glass
fill ~64 ~2 ~-124 ~64 ~3 ~-124 minecraft:gray_stained_glass
fill ~70 ~2 ~-124 ~70 ~3 ~-124 minecraft:light_gray_stained_glass
setblock ~67 ~1 ~-126 minecraft:iron_door[half=lower,facing=north]
setblock ~67 ~2 ~-126 minecraft:iron_door[half=upper,facing=north]
fill ~66 ~1 ~-126 ~68 ~4 ~-126 minecraft:polished_blackstone
fill ~66 ~5 ~-126 ~68 ~5 ~-126 minecraft:light_blue_stained_glass
fill ~66 ~8 ~-124 ~68 ~9 ~-122 minecraft:iron_block
fill ~64 ~7 ~-126 ~70 ~7 ~-121 minecraft:deepslate_tile_slab
# 188 office style=bay_office context=arterial_front facing=north
fill ~-116 ~-3 ~-27 ~-112 ~-1 ~-19 minecraft:stone
fill ~-116 ~0 ~-27 ~-112 ~11 ~-19 minecraft:calcite
fill ~-115 ~1 ~-26 ~-113 ~10 ~-20 minecraft:air
fill ~-115 ~4 ~-26 ~-113 ~4 ~-20 minecraft:smooth_stone
fill ~-115 ~8 ~-26 ~-113 ~8 ~-20 minecraft:smooth_stone
fill ~-114 ~2 ~-27 ~-114 ~3 ~-27 minecraft:gray_stained_glass
fill ~-114 ~2 ~-19 ~-114 ~3 ~-19 minecraft:light_gray_stained_glass
fill ~-116 ~2 ~-25 ~-116 ~3 ~-25 minecraft:gray_stained_glass
fill ~-112 ~2 ~-25 ~-112 ~3 ~-25 minecraft:light_gray_stained_glass
fill ~-116 ~2 ~-22 ~-116 ~3 ~-22 minecraft:gray_stained_glass
fill ~-112 ~2 ~-22 ~-112 ~3 ~-22 minecraft:light_gray_stained_glass
fill ~-114 ~6 ~-27 ~-114 ~7 ~-27 minecraft:gray_stained_glass
fill ~-114 ~6 ~-19 ~-114 ~7 ~-19 minecraft:light_gray_stained_glass
fill ~-116 ~6 ~-25 ~-116 ~7 ~-25 minecraft:gray_stained_glass
fill ~-112 ~6 ~-25 ~-112 ~7 ~-25 minecraft:light_gray_stained_glass
fill ~-116 ~6 ~-22 ~-116 ~7 ~-22 minecraft:gray_stained_glass
fill ~-112 ~6 ~-22 ~-112 ~7 ~-22 minecraft:light_gray_stained_glass
setblock ~-114 ~1 ~-27 minecraft:iron_door[half=lower,facing=north]
setblock ~-114 ~2 ~-27 minecraft:iron_door[half=upper,facing=north]
fill ~-116 ~7 ~-27 ~-112 ~11 ~-19 minecraft:air
fill ~-115 ~7 ~-26 ~-113 ~11 ~-20 minecraft:calcite
fill ~-114 ~8 ~-25 ~-114 ~10 ~-21 minecraft:air
fill ~-115 ~12 ~-26 ~-113 ~12 ~-20 minecraft:stone_brick_slab
fill ~-114 ~2 ~-27 ~-114 ~7 ~-27 minecraft:blue_stained_glass
# 189 row_house style=japanese_house context=local_front facing=north
fill ~-55 ~-3 ~118 ~-50 ~-1 ~123 minecraft:stone
fill ~-55 ~0 ~118 ~-50 ~5 ~123 minecraft:white_terracotta
fill ~-54 ~1 ~119 ~-51 ~4 ~122 minecraft:air
fill ~-54 ~4 ~119 ~-51 ~4 ~122 minecraft:smooth_stone
fill ~-53 ~2 ~118 ~-53 ~3 ~118 minecraft:gray_stained_glass
fill ~-53 ~2 ~123 ~-53 ~3 ~123 minecraft:light_gray_stained_glass
fill ~-55 ~2 ~120 ~-55 ~3 ~120 minecraft:gray_stained_glass
fill ~-50 ~2 ~120 ~-50 ~3 ~120 minecraft:light_gray_stained_glass
setblock ~-53 ~1 ~118 minecraft:iron_door[half=lower,facing=north]
setblock ~-53 ~2 ~118 minecraft:iron_door[half=upper,facing=north]
fill ~-55 ~6 ~118 ~-50 ~6 ~123 minecraft:dark_oak_slab
fill ~-54 ~7 ~119 ~-51 ~7 ~122 minecraft:dark_oak_slab
setblock ~-53 ~3 ~117 minecraft:dark_oak_slab[type=top]
# 190 local_shop style=arcade_shop context=local_front facing=south
fill ~-54 ~-3 ~96 ~-49 ~-1 ~101 minecraft:stone
fill ~-54 ~0 ~96 ~-49 ~5 ~101 minecraft:mud_bricks
fill ~-53 ~1 ~97 ~-50 ~4 ~100 minecraft:air
fill ~-53 ~4 ~97 ~-50 ~4 ~100 minecraft:smooth_stone
fill ~-52 ~2 ~96 ~-52 ~3 ~96 minecraft:gray_stained_glass
fill ~-52 ~2 ~101 ~-52 ~3 ~101 minecraft:light_gray_stained_glass
fill ~-54 ~2 ~98 ~-54 ~3 ~98 minecraft:gray_stained_glass
fill ~-49 ~2 ~98 ~-49 ~3 ~98 minecraft:light_gray_stained_glass
setblock ~-52 ~1 ~101 minecraft:iron_door[half=lower,facing=south]
setblock ~-52 ~2 ~101 minecraft:iron_door[half=upper,facing=south]
fill ~-53 ~1 ~101 ~-50 ~3 ~101 minecraft:cyan_stained_glass
setblock ~-52 ~1 ~101 minecraft:iron_door[half=lower,facing=south]
setblock ~-52 ~2 ~101 minecraft:iron_door[half=upper,facing=south]
setblock ~-52 ~3 ~102 minecraft:red_wool
fill ~-53 ~4 ~101 ~-50 ~4 ~101 minecraft:spruce_planks
fill ~-54 ~6 ~96 ~-49 ~6 ~101 minecraft:deepslate_tile_slab
# 191 station_hotel style=civic_modern context=station_front facing=south
fill ~35 ~-3 ~-89 ~39 ~-1 ~-82 minecraft:stone
fill ~35 ~0 ~-89 ~39 ~8 ~-82 minecraft:bricks
fill ~36 ~1 ~-88 ~38 ~7 ~-83 minecraft:air
fill ~36 ~4 ~-88 ~38 ~4 ~-83 minecraft:smooth_stone
fill ~37 ~2 ~-89 ~37 ~3 ~-89 minecraft:gray_stained_glass
fill ~37 ~2 ~-82 ~37 ~3 ~-82 minecraft:light_gray_stained_glass
fill ~35 ~2 ~-87 ~35 ~3 ~-87 minecraft:gray_stained_glass
fill ~39 ~2 ~-87 ~39 ~3 ~-87 minecraft:light_gray_stained_glass
fill ~35 ~2 ~-84 ~35 ~3 ~-84 minecraft:gray_stained_glass
fill ~39 ~2 ~-84 ~39 ~3 ~-84 minecraft:light_gray_stained_glass
fill ~37 ~6 ~-89 ~37 ~7 ~-89 minecraft:gray_stained_glass
fill ~37 ~6 ~-82 ~37 ~7 ~-82 minecraft:light_gray_stained_glass
fill ~35 ~6 ~-87 ~35 ~7 ~-87 minecraft:gray_stained_glass
fill ~39 ~6 ~-87 ~39 ~7 ~-87 minecraft:light_gray_stained_glass
fill ~35 ~6 ~-84 ~35 ~7 ~-84 minecraft:gray_stained_glass
fill ~39 ~6 ~-84 ~39 ~7 ~-84 minecraft:light_gray_stained_glass
setblock ~37 ~1 ~-82 minecraft:iron_door[half=lower,facing=south]
setblock ~37 ~2 ~-82 minecraft:iron_door[half=upper,facing=south]
# 192 workshop style=sawtooth context=back_block facing=north
fill ~-36 ~-3 ~-5 ~-31 ~-1 ~2 minecraft:stone
fill ~-36 ~0 ~-5 ~-31 ~16 ~2 minecraft:light_gray_concrete
fill ~-35 ~1 ~-4 ~-32 ~15 ~1 minecraft:air
fill ~-35 ~4 ~-4 ~-32 ~4 ~1 minecraft:smooth_stone
fill ~-35 ~8 ~-4 ~-32 ~8 ~1 minecraft:smooth_stone
fill ~-35 ~12 ~-4 ~-32 ~12 ~1 minecraft:smooth_stone
fill ~-34 ~2 ~-5 ~-34 ~3 ~-5 minecraft:gray_stained_glass
fill ~-34 ~2 ~2 ~-34 ~3 ~2 minecraft:light_gray_stained_glass
fill ~-36 ~2 ~-3 ~-36 ~3 ~-3 minecraft:gray_stained_glass
fill ~-31 ~2 ~-3 ~-31 ~3 ~-3 minecraft:light_gray_stained_glass
fill ~-36 ~2 ~0 ~-36 ~3 ~0 minecraft:gray_stained_glass
fill ~-31 ~2 ~0 ~-31 ~3 ~0 minecraft:light_gray_stained_glass
fill ~-34 ~6 ~-5 ~-34 ~7 ~-5 minecraft:gray_stained_glass
fill ~-34 ~6 ~2 ~-34 ~7 ~2 minecraft:light_gray_stained_glass
fill ~-36 ~6 ~-3 ~-36 ~7 ~-3 minecraft:gray_stained_glass
fill ~-31 ~6 ~-3 ~-31 ~7 ~-3 minecraft:light_gray_stained_glass
fill ~-36 ~6 ~0 ~-36 ~7 ~0 minecraft:gray_stained_glass
fill ~-31 ~6 ~0 ~-31 ~7 ~0 minecraft:light_gray_stained_glass
fill ~-34 ~10 ~-5 ~-34 ~11 ~-5 minecraft:gray_stained_glass
fill ~-34 ~10 ~2 ~-34 ~11 ~2 minecraft:light_gray_stained_glass
fill ~-36 ~10 ~-3 ~-36 ~11 ~-3 minecraft:gray_stained_glass
fill ~-31 ~10 ~-3 ~-31 ~11 ~-3 minecraft:light_gray_stained_glass
fill ~-36 ~10 ~0 ~-36 ~11 ~0 minecraft:gray_stained_glass
fill ~-31 ~10 ~0 ~-31 ~11 ~0 minecraft:light_gray_stained_glass
fill ~-34 ~14 ~-5 ~-34 ~15 ~-5 minecraft:gray_stained_glass
fill ~-34 ~14 ~2 ~-34 ~15 ~2 minecraft:light_gray_stained_glass
fill ~-36 ~14 ~-3 ~-36 ~15 ~-3 minecraft:gray_stained_glass
fill ~-31 ~14 ~-3 ~-31 ~15 ~-3 minecraft:light_gray_stained_glass
fill ~-36 ~14 ~0 ~-36 ~15 ~0 minecraft:gray_stained_glass
fill ~-31 ~14 ~0 ~-31 ~15 ~0 minecraft:light_gray_stained_glass
setblock ~-34 ~1 ~-5 minecraft:iron_door[half=lower,facing=north]
setblock ~-34 ~2 ~-5 minecraft:iron_door[half=upper,facing=north]
fill ~-34 ~1 ~-5 ~-33 ~4 ~-5 minecraft:polished_blackstone
fill ~-34 ~5 ~-5 ~-33 ~5 ~-5 minecraft:light_blue_stained_glass
fill ~-34 ~18 ~-3 ~-32 ~19 ~-1 minecraft:iron_block
fill ~-36 ~17 ~-5 ~-31 ~17 ~2 minecraft:smooth_stone_slab
fill ~-34 ~18 ~-3 ~-32 ~19 ~-1 minecraft:light_gray_concrete
setblock ~-32 ~18 ~-2 minecraft:lightning_rod
