# Buildings 153..160
# 153 logistics style=industrial_shed context=collector_front facing=south
fill ~55 ~-3 ~77 ~71 ~-1 ~89 minecraft:stone
fill ~55 ~0 ~77 ~71 ~9 ~89 minecraft:gray_concrete
fill ~56 ~1 ~78 ~70 ~8 ~88 minecraft:air
fill ~56 ~4 ~78 ~70 ~4 ~88 minecraft:smooth_stone
fill ~56 ~8 ~78 ~70 ~8 ~88 minecraft:smooth_stone
fill ~57 ~2 ~77 ~57 ~3 ~77 minecraft:gray_stained_glass
fill ~57 ~2 ~89 ~57 ~3 ~89 minecraft:light_gray_stained_glass
fill ~60 ~2 ~77 ~60 ~3 ~77 minecraft:gray_stained_glass
fill ~60 ~2 ~89 ~60 ~3 ~89 minecraft:light_gray_stained_glass
fill ~63 ~2 ~77 ~63 ~3 ~77 minecraft:gray_stained_glass
fill ~63 ~2 ~89 ~63 ~3 ~89 minecraft:light_gray_stained_glass
fill ~66 ~2 ~77 ~66 ~3 ~77 minecraft:gray_stained_glass
fill ~66 ~2 ~89 ~66 ~3 ~89 minecraft:light_gray_stained_glass
fill ~69 ~2 ~77 ~69 ~3 ~77 minecraft:gray_stained_glass
fill ~69 ~2 ~89 ~69 ~3 ~89 minecraft:light_gray_stained_glass
fill ~55 ~2 ~79 ~55 ~3 ~79 minecraft:gray_stained_glass
fill ~71 ~2 ~79 ~71 ~3 ~79 minecraft:light_gray_stained_glass
fill ~55 ~2 ~82 ~55 ~3 ~82 minecraft:gray_stained_glass
fill ~71 ~2 ~82 ~71 ~3 ~82 minecraft:light_gray_stained_glass
fill ~55 ~2 ~85 ~55 ~3 ~85 minecraft:gray_stained_glass
fill ~71 ~2 ~85 ~71 ~3 ~85 minecraft:light_gray_stained_glass
fill ~57 ~6 ~77 ~57 ~7 ~77 minecraft:gray_stained_glass
fill ~57 ~6 ~89 ~57 ~7 ~89 minecraft:light_gray_stained_glass
fill ~60 ~6 ~77 ~60 ~7 ~77 minecraft:gray_stained_glass
fill ~60 ~6 ~89 ~60 ~7 ~89 minecraft:light_gray_stained_glass
fill ~63 ~6 ~77 ~63 ~7 ~77 minecraft:gray_stained_glass
fill ~63 ~6 ~89 ~63 ~7 ~89 minecraft:light_gray_stained_glass
fill ~66 ~6 ~77 ~66 ~7 ~77 minecraft:gray_stained_glass
fill ~66 ~6 ~89 ~66 ~7 ~89 minecraft:light_gray_stained_glass
fill ~69 ~6 ~77 ~69 ~7 ~77 minecraft:gray_stained_glass
fill ~69 ~6 ~89 ~69 ~7 ~89 minecraft:light_gray_stained_glass
fill ~55 ~6 ~79 ~55 ~7 ~79 minecraft:gray_stained_glass
fill ~71 ~6 ~79 ~71 ~7 ~79 minecraft:light_gray_stained_glass
fill ~55 ~6 ~82 ~55 ~7 ~82 minecraft:gray_stained_glass
fill ~71 ~6 ~82 ~71 ~7 ~82 minecraft:light_gray_stained_glass
fill ~55 ~6 ~85 ~55 ~7 ~85 minecraft:gray_stained_glass
fill ~71 ~6 ~85 ~71 ~7 ~85 minecraft:light_gray_stained_glass
setblock ~60 ~1 ~89 minecraft:iron_door[half=lower,facing=south]
setblock ~60 ~2 ~89 minecraft:iron_door[half=upper,facing=south]
fill ~57 ~1 ~89 ~69 ~4 ~89 minecraft:polished_blackstone
fill ~57 ~5 ~89 ~69 ~5 ~89 minecraft:light_blue_stained_glass
fill ~57 ~11 ~79 ~59 ~12 ~81 minecraft:iron_block
fill ~55 ~10 ~77 ~71 ~10 ~89 minecraft:smooth_stone_slab
fill ~57 ~11 ~79 ~59 ~12 ~81 minecraft:light_gray_concrete
setblock ~60 ~11 ~80 minecraft:lightning_rod
fill ~56 ~1 ~89 ~56 ~7 ~89 doomsday_decoration:ironsheetwall_1
fill ~60 ~1 ~89 ~60 ~7 ~89 doomsday_decoration:ironsheetwall_1
fill ~64 ~1 ~89 ~64 ~7 ~89 doomsday_decoration:ironsheetwall_1
fill ~68 ~1 ~89 ~68 ~7 ~89 doomsday_decoration:ironsheetwall_1
# 154 apartment style=mixed_facade context=waterfront_front facing=south
fill ~115 ~-3 ~-62 ~119 ~-1 ~-52 minecraft:stone
fill ~115 ~0 ~-62 ~119 ~5 ~-52 minecraft:bricks
fill ~116 ~1 ~-61 ~118 ~4 ~-53 minecraft:air
fill ~116 ~4 ~-61 ~118 ~4 ~-53 minecraft:smooth_stone
fill ~117 ~2 ~-62 ~117 ~3 ~-62 minecraft:gray_stained_glass
fill ~117 ~2 ~-52 ~117 ~3 ~-52 minecraft:light_gray_stained_glass
fill ~115 ~2 ~-60 ~115 ~3 ~-60 minecraft:gray_stained_glass
fill ~119 ~2 ~-60 ~119 ~3 ~-60 minecraft:light_gray_stained_glass
fill ~115 ~2 ~-57 ~115 ~3 ~-57 minecraft:gray_stained_glass
fill ~119 ~2 ~-57 ~119 ~3 ~-57 minecraft:light_gray_stained_glass
fill ~115 ~2 ~-54 ~115 ~3 ~-54 minecraft:gray_stained_glass
fill ~119 ~2 ~-54 ~119 ~3 ~-54 minecraft:light_gray_stained_glass
setblock ~117 ~1 ~-52 minecraft:iron_door[half=lower,facing=south]
setblock ~117 ~2 ~-52 minecraft:iron_door[half=upper,facing=south]
fill ~115 ~6 ~-62 ~119 ~6 ~-52 minecraft:deepslate_tile_slab
# 155 small_office style=setback_tower context=local_front facing=north
fill ~-63 ~-3 ~-104 ~-60 ~-1 ~-99 minecraft:stone
fill ~-63 ~0 ~-104 ~-60 ~11 ~-99 minecraft:stone_bricks
fill ~-62 ~1 ~-103 ~-61 ~10 ~-100 minecraft:air
fill ~-62 ~4 ~-103 ~-61 ~4 ~-100 minecraft:smooth_stone
fill ~-62 ~8 ~-103 ~-61 ~8 ~-100 minecraft:smooth_stone
fill ~-63 ~2 ~-102 ~-63 ~3 ~-102 minecraft:gray_stained_glass
fill ~-60 ~2 ~-102 ~-60 ~3 ~-102 minecraft:light_gray_stained_glass
fill ~-63 ~6 ~-102 ~-63 ~7 ~-102 minecraft:gray_stained_glass
fill ~-60 ~6 ~-102 ~-60 ~7 ~-102 minecraft:light_gray_stained_glass
setblock ~-61 ~1 ~-104 minecraft:iron_door[half=lower,facing=north]
setblock ~-61 ~2 ~-104 minecraft:iron_door[half=upper,facing=north]
fill ~-63 ~7 ~-104 ~-60 ~11 ~-99 minecraft:air
fill ~-62 ~7 ~-103 ~-61 ~11 ~-100 minecraft:stone_bricks
fill ~-61 ~8 ~-102 ~-62 ~10 ~-101 minecraft:air
fill ~-62 ~12 ~-103 ~-61 ~12 ~-100 minecraft:smooth_stone_slab
# 156 local_shop style=arcade_shop context=local_front facing=north
fill ~45 ~-3 ~-96 ~48 ~-1 ~-91 minecraft:stone
fill ~45 ~0 ~-96 ~48 ~5 ~-91 minecraft:bricks
fill ~46 ~1 ~-95 ~47 ~4 ~-92 minecraft:air
fill ~46 ~4 ~-95 ~47 ~4 ~-92 minecraft:smooth_stone
fill ~45 ~2 ~-94 ~45 ~3 ~-94 minecraft:gray_stained_glass
fill ~48 ~2 ~-94 ~48 ~3 ~-94 minecraft:light_gray_stained_glass
setblock ~47 ~1 ~-96 minecraft:iron_door[half=lower,facing=north]
setblock ~47 ~2 ~-96 minecraft:iron_door[half=upper,facing=north]
fill ~46 ~1 ~-96 ~47 ~3 ~-96 minecraft:cyan_stained_glass
setblock ~47 ~1 ~-96 minecraft:iron_door[half=lower,facing=north]
setblock ~47 ~2 ~-96 minecraft:iron_door[half=upper,facing=north]
setblock ~47 ~3 ~-97 minecraft:red_wool
fill ~46 ~4 ~-96 ~47 ~4 ~-96 minecraft:gray_concrete
fill ~45 ~6 ~-96 ~48 ~6 ~-91 minecraft:deepslate_tile_slab
# 157 local_shop style=arcade_shop context=collector_front facing=north
fill ~85 ~-3 ~77 ~90 ~-1 ~84 minecraft:stone
fill ~85 ~0 ~77 ~90 ~5 ~84 minecraft:gray_concrete
fill ~86 ~1 ~78 ~89 ~4 ~83 minecraft:air
fill ~86 ~4 ~78 ~89 ~4 ~83 minecraft:smooth_stone
fill ~87 ~2 ~77 ~87 ~3 ~77 minecraft:gray_stained_glass
fill ~87 ~2 ~84 ~87 ~3 ~84 minecraft:light_gray_stained_glass
fill ~85 ~2 ~79 ~85 ~3 ~79 minecraft:gray_stained_glass
fill ~90 ~2 ~79 ~90 ~3 ~79 minecraft:light_gray_stained_glass
fill ~85 ~2 ~82 ~85 ~3 ~82 minecraft:gray_stained_glass
fill ~90 ~2 ~82 ~90 ~3 ~82 minecraft:light_gray_stained_glass
setblock ~87 ~1 ~77 minecraft:iron_door[half=lower,facing=north]
setblock ~87 ~2 ~77 minecraft:iron_door[half=upper,facing=north]
fill ~86 ~1 ~77 ~89 ~3 ~77 minecraft:cyan_stained_glass
setblock ~87 ~1 ~77 minecraft:iron_door[half=lower,facing=north]
setblock ~87 ~2 ~77 minecraft:iron_door[half=upper,facing=north]
setblock ~87 ~3 ~76 minecraft:red_wool
fill ~86 ~4 ~77 ~89 ~4 ~77 doomsday_decoration:ironsheetwall_1
fill ~85 ~6 ~77 ~90 ~6 ~84 minecraft:smooth_stone_slab
fill ~86 ~1 ~77 ~86 ~5 ~77 doomsday_decoration:ironsheetwall_1
setblock ~87 ~3 ~77 minecraft:red_carpet
# 158 local_shop style=corner_store context=arterial_front facing=south
fill ~38 ~-3 ~6 ~43 ~-1 ~13 minecraft:stone
fill ~38 ~0 ~6 ~43 ~5 ~13 minecraft:white_terracotta
fill ~39 ~1 ~7 ~42 ~4 ~12 minecraft:air
fill ~39 ~4 ~7 ~42 ~4 ~12 minecraft:smooth_stone
fill ~40 ~2 ~6 ~40 ~3 ~6 minecraft:gray_stained_glass
fill ~40 ~2 ~13 ~40 ~3 ~13 minecraft:light_gray_stained_glass
fill ~38 ~2 ~8 ~38 ~3 ~8 minecraft:gray_stained_glass
fill ~43 ~2 ~8 ~43 ~3 ~8 minecraft:light_gray_stained_glass
fill ~38 ~2 ~11 ~38 ~3 ~11 minecraft:gray_stained_glass
fill ~43 ~2 ~11 ~43 ~3 ~11 minecraft:light_gray_stained_glass
setblock ~40 ~1 ~13 minecraft:iron_door[half=lower,facing=south]
setblock ~40 ~2 ~13 minecraft:iron_door[half=upper,facing=south]
fill ~39 ~1 ~13 ~42 ~3 ~13 minecraft:cyan_stained_glass
setblock ~40 ~1 ~13 minecraft:iron_door[half=lower,facing=south]
setblock ~40 ~2 ~13 minecraft:iron_door[half=upper,facing=south]
setblock ~40 ~3 ~14 minecraft:red_wool
fill ~38 ~6 ~6 ~43 ~6 ~13 minecraft:stone_brick_slab
fill ~39 ~1 ~13 ~39 ~5 ~13 minecraft:gray_concrete
setblock ~40 ~3 ~13 minecraft:red_carpet
# 159 workshop style=industrial_shed context=local_front facing=north
fill ~41 ~-3 ~-96 ~44 ~-1 ~-91 minecraft:stone
fill ~41 ~0 ~-96 ~44 ~9 ~-91 minecraft:bricks
fill ~42 ~1 ~-95 ~43 ~8 ~-92 minecraft:air
fill ~42 ~4 ~-95 ~43 ~4 ~-92 minecraft:smooth_stone
fill ~42 ~8 ~-95 ~43 ~8 ~-92 minecraft:smooth_stone
fill ~41 ~2 ~-94 ~41 ~3 ~-94 minecraft:gray_stained_glass
fill ~44 ~2 ~-94 ~44 ~3 ~-94 minecraft:light_gray_stained_glass
fill ~41 ~6 ~-94 ~41 ~7 ~-94 minecraft:gray_stained_glass
fill ~44 ~6 ~-94 ~44 ~7 ~-94 minecraft:light_gray_stained_glass
setblock ~43 ~1 ~-96 minecraft:iron_door[half=lower,facing=north]
setblock ~43 ~2 ~-96 minecraft:iron_door[half=upper,facing=north]
fill ~43 ~1 ~-96 ~42 ~4 ~-96 minecraft:polished_blackstone
fill ~43 ~5 ~-96 ~42 ~5 ~-96 minecraft:light_blue_stained_glass
fill ~43 ~11 ~-94 ~43 ~12 ~-92 minecraft:iron_block
fill ~41 ~10 ~-96 ~44 ~10 ~-91 minecraft:deepslate_tile_slab
fill ~43 ~11 ~-94 ~43 ~12 ~-92 minecraft:light_gray_concrete
setblock ~43 ~11 ~-93 minecraft:lightning_rod
# 160 shop_house style=arcade_shop context=collector_front facing=south
fill ~-87 ~-3 ~-101 ~-82 ~-1 ~-94 minecraft:stone
fill ~-87 ~0 ~-101 ~-82 ~9 ~-94 minecraft:stone_bricks
fill ~-86 ~1 ~-100 ~-83 ~8 ~-95 minecraft:air
fill ~-86 ~4 ~-100 ~-83 ~4 ~-95 minecraft:smooth_stone
fill ~-86 ~8 ~-100 ~-83 ~8 ~-95 minecraft:smooth_stone
fill ~-85 ~2 ~-101 ~-85 ~3 ~-101 minecraft:gray_stained_glass
fill ~-85 ~2 ~-94 ~-85 ~3 ~-94 minecraft:light_gray_stained_glass
fill ~-87 ~2 ~-99 ~-87 ~3 ~-99 minecraft:gray_stained_glass
fill ~-82 ~2 ~-99 ~-82 ~3 ~-99 minecraft:light_gray_stained_glass
fill ~-87 ~2 ~-96 ~-87 ~3 ~-96 minecraft:gray_stained_glass
fill ~-82 ~2 ~-96 ~-82 ~3 ~-96 minecraft:light_gray_stained_glass
fill ~-85 ~6 ~-101 ~-85 ~7 ~-101 minecraft:gray_stained_glass
fill ~-85 ~6 ~-94 ~-85 ~7 ~-94 minecraft:light_gray_stained_glass
fill ~-87 ~6 ~-99 ~-87 ~7 ~-99 minecraft:gray_stained_glass
fill ~-82 ~6 ~-99 ~-82 ~7 ~-99 minecraft:light_gray_stained_glass
fill ~-87 ~6 ~-96 ~-87 ~7 ~-96 minecraft:gray_stained_glass
fill ~-82 ~6 ~-96 ~-82 ~7 ~-96 minecraft:light_gray_stained_glass
setblock ~-85 ~1 ~-94 minecraft:iron_door[half=lower,facing=south]
setblock ~-85 ~2 ~-94 minecraft:iron_door[half=upper,facing=south]
fill ~-86 ~1 ~-94 ~-83 ~3 ~-94 minecraft:cyan_stained_glass
setblock ~-85 ~1 ~-94 minecraft:iron_door[half=lower,facing=south]
setblock ~-85 ~2 ~-94 minecraft:iron_door[half=upper,facing=south]
setblock ~-85 ~3 ~-93 minecraft:red_wool
fill ~-86 ~4 ~-94 ~-83 ~4 ~-94 doomsday_decoration:ironsheetwall_2
fill ~-87 ~10 ~-101 ~-82 ~10 ~-94 minecraft:smooth_stone_slab
fill ~-86 ~1 ~-94 ~-86 ~7 ~-94 doomsday_decoration:ironsheetwall_2
setblock ~-85 ~3 ~-94 minecraft:red_carpet
