# Buildings 101..125
# 101 clinic 84,-10 93,-2 h=12
fill ~84 ~-3 ~-10 ~93 ~-1 ~-2 minecraft:stone
fill ~84 ~0 ~-10 ~93 ~12 ~-2 minecraft:light_gray_concrete
fill ~85 ~1 ~-9 ~92 ~11 ~-3 minecraft:air
fill ~85 ~4 ~-9 ~92 ~4 ~-3 minecraft:smooth_stone
fill ~85 ~8 ~-9 ~92 ~8 ~-3 minecraft:smooth_stone
fill ~84 ~2 ~-8 ~84 ~3 ~-4 minecraft:gray_stained_glass
fill ~93 ~2 ~-8 ~93 ~3 ~-4 minecraft:light_gray_stained_glass
fill ~84 ~6 ~-8 ~84 ~7 ~-4 minecraft:gray_stained_glass
fill ~93 ~6 ~-8 ~93 ~7 ~-4 minecraft:light_gray_stained_glass
fill ~84 ~10 ~-8 ~84 ~11 ~-4 minecraft:gray_stained_glass
fill ~93 ~10 ~-8 ~93 ~11 ~-4 minecraft:light_gray_stained_glass
fill ~85 ~0 ~-10 ~88 ~3 ~-10 doomsday_decoration:porcelainbrickwall
setblock ~86 ~1 ~-10 minecraft:iron_door[half=lower,facing=north]
setblock ~86 ~2 ~-10 minecraft:iron_door[half=upper,facing=north]
fill ~84 ~13 ~-10 ~93 ~13 ~-2 minecraft:smooth_stone_slab
# 102 local_shop -71,-81 -65,-74 h=7
fill ~-71 ~-3 ~-81 ~-65 ~-1 ~-74 minecraft:stone
fill ~-71 ~0 ~-81 ~-65 ~7 ~-74 minecraft:calcite
fill ~-70 ~1 ~-80 ~-66 ~6 ~-75 minecraft:air
fill ~-70 ~4 ~-80 ~-66 ~4 ~-75 minecraft:smooth_stone
fill ~-71 ~2 ~-79 ~-71 ~3 ~-76 minecraft:gray_stained_glass
fill ~-65 ~2 ~-79 ~-65 ~3 ~-76 minecraft:light_gray_stained_glass
fill ~-70 ~0 ~-81 ~-67 ~3 ~-81 minecraft:gray_concrete
setblock ~-69 ~1 ~-81 minecraft:iron_door[half=lower,facing=north]
setblock ~-69 ~2 ~-81 minecraft:iron_door[half=upper,facing=north]
fill ~-71 ~8 ~-81 ~-65 ~8 ~-74 minecraft:stone_brick_slab
# 103 local_shop -106,24 -101,32 h=7
fill ~-106 ~-3 ~24 ~-101 ~-1 ~32 minecraft:stone
fill ~-106 ~0 ~24 ~-101 ~7 ~32 minecraft:calcite
fill ~-105 ~1 ~25 ~-102 ~6 ~31 minecraft:air
fill ~-105 ~4 ~25 ~-102 ~4 ~31 minecraft:smooth_stone
fill ~-104 ~2 ~24 ~-103 ~3 ~24 minecraft:gray_stained_glass
fill ~-104 ~2 ~32 ~-103 ~3 ~32 minecraft:light_gray_stained_glass
fill ~-105 ~0 ~24 ~-102 ~3 ~24 minecraft:gray_concrete
setblock ~-104 ~1 ~24 minecraft:iron_door[half=lower,facing=north]
setblock ~-104 ~2 ~24 minecraft:iron_door[half=upper,facing=north]
fill ~-106 ~8 ~24 ~-101 ~8 ~32 minecraft:stone_brick_slab
# 104 hotel -40,33 -28,42 h=12
fill ~-40 ~-3 ~33 ~-28 ~-1 ~42 minecraft:stone
fill ~-40 ~0 ~33 ~-28 ~12 ~42 minecraft:light_gray_concrete
fill ~-39 ~1 ~34 ~-29 ~11 ~41 minecraft:air
fill ~-39 ~4 ~34 ~-29 ~4 ~41 minecraft:smooth_stone
fill ~-39 ~8 ~34 ~-29 ~8 ~41 minecraft:smooth_stone
fill ~-38 ~2 ~33 ~-30 ~3 ~33 minecraft:gray_stained_glass
fill ~-38 ~2 ~42 ~-30 ~3 ~42 minecraft:light_gray_stained_glass
fill ~-38 ~6 ~33 ~-30 ~7 ~33 minecraft:gray_stained_glass
fill ~-38 ~6 ~42 ~-30 ~7 ~42 minecraft:light_gray_stained_glass
fill ~-38 ~10 ~33 ~-30 ~11 ~33 minecraft:gray_stained_glass
fill ~-38 ~10 ~42 ~-30 ~11 ~42 minecraft:light_gray_stained_glass
fill ~-39 ~0 ~33 ~-36 ~3 ~33 doomsday_decoration:cementwall
setblock ~-38 ~1 ~33 minecraft:iron_door[half=lower,facing=north]
setblock ~-38 ~2 ~33 minecraft:iron_door[half=upper,facing=north]
fill ~-40 ~13 ~33 ~-28 ~13 ~42 minecraft:smooth_stone_slab
# 105 detached_house -34,115 -25,123 h=9
fill ~-34 ~-3 ~115 ~-25 ~-1 ~123 minecraft:stone
fill ~-34 ~0 ~115 ~-25 ~9 ~123 minecraft:calcite
fill ~-33 ~1 ~116 ~-26 ~8 ~122 minecraft:air
fill ~-33 ~4 ~116 ~-26 ~4 ~122 minecraft:smooth_stone
fill ~-33 ~8 ~116 ~-26 ~8 ~122 minecraft:smooth_stone
fill ~-34 ~2 ~117 ~-34 ~3 ~121 minecraft:gray_stained_glass
fill ~-25 ~2 ~117 ~-25 ~3 ~121 minecraft:light_gray_stained_glass
fill ~-34 ~6 ~117 ~-34 ~7 ~121 minecraft:gray_stained_glass
fill ~-25 ~6 ~117 ~-25 ~7 ~121 minecraft:light_gray_stained_glass
fill ~-33 ~0 ~115 ~-30 ~3 ~115 minecraft:gray_concrete
setblock ~-32 ~1 ~115 minecraft:iron_door[half=lower,facing=north]
setblock ~-32 ~2 ~115 minecraft:iron_door[half=upper,facing=north]
fill ~-34 ~10 ~115 ~-25 ~10 ~123 minecraft:stone_brick_slab
# 106 row_house -31,99 -26,105 h=5
fill ~-31 ~-3 ~99 ~-26 ~-1 ~105 minecraft:stone
fill ~-31 ~0 ~99 ~-26 ~5 ~105 minecraft:calcite
fill ~-30 ~1 ~100 ~-27 ~4 ~104 minecraft:air
fill ~-30 ~4 ~100 ~-27 ~4 ~104 minecraft:smooth_stone
fill ~-31 ~2 ~101 ~-31 ~3 ~103 minecraft:gray_stained_glass
fill ~-26 ~2 ~101 ~-26 ~3 ~103 minecraft:light_gray_stained_glass
fill ~-30 ~0 ~99 ~-27 ~3 ~99 minecraft:gray_concrete
setblock ~-29 ~1 ~99 minecraft:iron_door[half=lower,facing=north]
setblock ~-29 ~2 ~99 minecraft:iron_door[half=upper,facing=north]
fill ~-31 ~6 ~99 ~-26 ~6 ~105 minecraft:stone_brick_slab
# 107 row_house -110,-20 -103,-13 h=5
fill ~-110 ~-3 ~-20 ~-103 ~-1 ~-13 minecraft:stone
fill ~-110 ~0 ~-20 ~-103 ~5 ~-13 minecraft:calcite
fill ~-109 ~1 ~-19 ~-104 ~4 ~-14 minecraft:air
fill ~-109 ~4 ~-19 ~-104 ~4 ~-14 minecraft:smooth_stone
fill ~-110 ~2 ~-18 ~-110 ~3 ~-15 minecraft:gray_stained_glass
fill ~-103 ~2 ~-18 ~-103 ~3 ~-15 minecraft:light_gray_stained_glass
fill ~-109 ~0 ~-20 ~-106 ~3 ~-20 minecraft:gray_concrete
setblock ~-108 ~1 ~-20 minecraft:iron_door[half=lower,facing=north]
setblock ~-108 ~2 ~-20 minecraft:iron_door[half=upper,facing=north]
fill ~-110 ~6 ~-20 ~-103 ~6 ~-13 minecraft:stone_brick_slab
# 108 local_shop -90,-60 -84,-50 h=5
fill ~-90 ~-3 ~-60 ~-84 ~-1 ~-50 minecraft:stone
fill ~-90 ~0 ~-60 ~-84 ~5 ~-50 minecraft:calcite
fill ~-89 ~1 ~-59 ~-85 ~4 ~-51 minecraft:air
fill ~-89 ~4 ~-59 ~-85 ~4 ~-51 minecraft:smooth_stone
fill ~-88 ~2 ~-60 ~-86 ~3 ~-60 minecraft:gray_stained_glass
fill ~-88 ~2 ~-50 ~-86 ~3 ~-50 minecraft:light_gray_stained_glass
fill ~-89 ~0 ~-60 ~-86 ~3 ~-60 minecraft:gray_concrete
setblock ~-88 ~1 ~-60 minecraft:iron_door[half=lower,facing=north]
setblock ~-88 ~2 ~-60 minecraft:iron_door[half=upper,facing=north]
fill ~-90 ~6 ~-60 ~-84 ~6 ~-50 minecraft:stone_brick_slab
# 109 restaurant -77,48 -71,58 h=10
fill ~-77 ~-3 ~48 ~-71 ~-1 ~58 minecraft:stone
fill ~-77 ~0 ~48 ~-71 ~10 ~58 minecraft:smooth_sandstone
fill ~-76 ~1 ~49 ~-72 ~9 ~57 minecraft:air
fill ~-76 ~4 ~49 ~-72 ~4 ~57 minecraft:smooth_stone
fill ~-76 ~8 ~49 ~-72 ~8 ~57 minecraft:smooth_stone
fill ~-75 ~2 ~48 ~-73 ~3 ~48 minecraft:gray_stained_glass
fill ~-75 ~2 ~58 ~-73 ~3 ~58 minecraft:light_gray_stained_glass
fill ~-75 ~6 ~48 ~-73 ~7 ~48 minecraft:gray_stained_glass
fill ~-75 ~6 ~58 ~-73 ~7 ~58 minecraft:light_gray_stained_glass
fill ~-76 ~0 ~48 ~-73 ~3 ~48 minecraft:brown_terracotta
setblock ~-75 ~1 ~48 minecraft:iron_door[half=lower,facing=north]
setblock ~-75 ~2 ~48 minecraft:iron_door[half=upper,facing=north]
fill ~-77 ~11 ~48 ~-71 ~11 ~58 minecraft:stone_brick_slab
# 110 shop_house -80,-19 -74,-8 h=8
fill ~-80 ~-3 ~-19 ~-74 ~-1 ~-8 minecraft:stone
fill ~-80 ~0 ~-19 ~-74 ~8 ~-8 minecraft:bricks
fill ~-79 ~1 ~-18 ~-75 ~7 ~-9 minecraft:air
fill ~-79 ~4 ~-18 ~-75 ~4 ~-9 minecraft:smooth_stone
fill ~-78 ~2 ~-19 ~-76 ~3 ~-19 minecraft:gray_stained_glass
fill ~-78 ~2 ~-8 ~-76 ~3 ~-8 minecraft:light_gray_stained_glass
fill ~-78 ~6 ~-19 ~-76 ~7 ~-19 minecraft:gray_stained_glass
fill ~-78 ~6 ~-8 ~-76 ~7 ~-8 minecraft:light_gray_stained_glass
fill ~-79 ~0 ~-19 ~-76 ~3 ~-19 doomsday_decoration:hollowbrick
setblock ~-78 ~1 ~-19 minecraft:iron_door[half=lower,facing=north]
setblock ~-78 ~2 ~-19 minecraft:iron_door[half=upper,facing=north]
fill ~-80 ~9 ~-19 ~-74 ~9 ~-8 minecraft:deepslate_tile_slab
# 111 restaurant 94,31 100,38 h=7
fill ~94 ~-3 ~31 ~100 ~-1 ~38 minecraft:stone
fill ~94 ~0 ~31 ~100 ~7 ~38 minecraft:white_concrete
fill ~95 ~1 ~32 ~99 ~6 ~37 minecraft:air
fill ~95 ~4 ~32 ~99 ~4 ~37 minecraft:smooth_stone
fill ~94 ~2 ~33 ~94 ~3 ~36 minecraft:gray_stained_glass
fill ~100 ~2 ~33 ~100 ~3 ~36 minecraft:light_gray_stained_glass
fill ~95 ~0 ~31 ~98 ~3 ~31 minecraft:cyan_terracotta
setblock ~96 ~1 ~31 minecraft:iron_door[half=lower,facing=north]
setblock ~96 ~2 ~31 minecraft:iron_door[half=upper,facing=north]
fill ~94 ~8 ~31 ~100 ~8 ~38 minecraft:smooth_stone_slab
# 112 mixed_use 12,-36 21,-28 h=20
fill ~12 ~-3 ~-36 ~21 ~-1 ~-28 minecraft:stone
fill ~12 ~0 ~-36 ~21 ~20 ~-28 minecraft:light_gray_concrete
fill ~13 ~1 ~-35 ~20 ~19 ~-29 minecraft:air
fill ~13 ~4 ~-35 ~20 ~4 ~-29 minecraft:smooth_stone
fill ~13 ~8 ~-35 ~20 ~8 ~-29 minecraft:smooth_stone
fill ~13 ~12 ~-35 ~20 ~12 ~-29 minecraft:smooth_stone
fill ~13 ~16 ~-35 ~20 ~16 ~-29 minecraft:smooth_stone
fill ~12 ~2 ~-34 ~12 ~3 ~-30 minecraft:gray_stained_glass
fill ~21 ~2 ~-34 ~21 ~3 ~-30 minecraft:light_gray_stained_glass
fill ~12 ~6 ~-34 ~12 ~7 ~-30 minecraft:gray_stained_glass
fill ~21 ~6 ~-34 ~21 ~7 ~-30 minecraft:light_gray_stained_glass
fill ~12 ~10 ~-34 ~12 ~11 ~-30 minecraft:gray_stained_glass
fill ~21 ~10 ~-34 ~21 ~11 ~-30 minecraft:light_gray_stained_glass
fill ~12 ~14 ~-34 ~12 ~15 ~-30 minecraft:gray_stained_glass
fill ~21 ~14 ~-34 ~21 ~15 ~-30 minecraft:light_gray_stained_glass
fill ~12 ~18 ~-34 ~12 ~19 ~-30 minecraft:gray_stained_glass
fill ~21 ~18 ~-34 ~21 ~19 ~-30 minecraft:light_gray_stained_glass
fill ~13 ~0 ~-36 ~16 ~3 ~-36 doomsday_decoration:cementwall
setblock ~14 ~1 ~-36 minecraft:iron_door[half=lower,facing=north]
setblock ~14 ~2 ~-36 minecraft:iron_door[half=upper,facing=north]
fill ~12 ~21 ~-36 ~21 ~21 ~-28 minecraft:smooth_stone_slab
# 113 detached_house -125,99 -119,111 h=7
fill ~-125 ~-3 ~99 ~-119 ~-1 ~111 minecraft:stone
fill ~-125 ~0 ~99 ~-119 ~7 ~111 minecraft:white_terracotta
fill ~-124 ~1 ~100 ~-120 ~6 ~110 minecraft:air
fill ~-124 ~4 ~100 ~-120 ~4 ~110 minecraft:smooth_stone
fill ~-125 ~2 ~101 ~-125 ~3 ~109 minecraft:gray_stained_glass
fill ~-119 ~2 ~101 ~-119 ~3 ~109 minecraft:light_gray_stained_glass
fill ~-124 ~0 ~99 ~-121 ~3 ~99 minecraft:dark_oak_planks
setblock ~-123 ~1 ~99 minecraft:iron_door[half=lower,facing=north]
setblock ~-123 ~2 ~99 minecraft:iron_door[half=upper,facing=north]
fill ~-125 ~8 ~99 ~-119 ~8 ~111 minecraft:dark_oak_slab
# 114 row_house -125,57 -120,63 h=7
fill ~-125 ~-3 ~57 ~-120 ~-1 ~63 minecraft:stone
fill ~-125 ~0 ~57 ~-120 ~7 ~63 minecraft:mud_bricks
fill ~-124 ~1 ~58 ~-121 ~6 ~62 minecraft:air
fill ~-124 ~4 ~58 ~-121 ~4 ~62 minecraft:smooth_stone
fill ~-125 ~2 ~59 ~-125 ~3 ~61 minecraft:gray_stained_glass
fill ~-120 ~2 ~59 ~-120 ~3 ~61 minecraft:light_gray_stained_glass
fill ~-124 ~0 ~57 ~-121 ~3 ~57 minecraft:spruce_planks
setblock ~-123 ~1 ~57 minecraft:iron_door[half=lower,facing=north]
setblock ~-123 ~2 ~57 minecraft:iron_door[half=upper,facing=north]
fill ~-125 ~8 ~57 ~-120 ~8 ~63 minecraft:deepslate_tile_slab
# 115 workshop 5,-59 15,-50 h=16
fill ~5 ~-3 ~-59 ~15 ~-1 ~-50 minecraft:stone
fill ~5 ~0 ~-59 ~15 ~16 ~-50 minecraft:light_gray_concrete
fill ~6 ~1 ~-58 ~14 ~15 ~-51 minecraft:air
fill ~6 ~4 ~-58 ~14 ~4 ~-51 minecraft:smooth_stone
fill ~6 ~8 ~-58 ~14 ~8 ~-51 minecraft:smooth_stone
fill ~6 ~12 ~-58 ~14 ~12 ~-51 minecraft:smooth_stone
fill ~5 ~2 ~-57 ~5 ~3 ~-52 minecraft:gray_stained_glass
fill ~15 ~2 ~-57 ~15 ~3 ~-52 minecraft:light_gray_stained_glass
fill ~5 ~6 ~-57 ~5 ~7 ~-52 minecraft:gray_stained_glass
fill ~15 ~6 ~-57 ~15 ~7 ~-52 minecraft:light_gray_stained_glass
fill ~5 ~10 ~-57 ~5 ~11 ~-52 minecraft:gray_stained_glass
fill ~15 ~10 ~-57 ~15 ~11 ~-52 minecraft:light_gray_stained_glass
fill ~5 ~14 ~-57 ~5 ~15 ~-52 minecraft:gray_stained_glass
fill ~15 ~14 ~-57 ~15 ~15 ~-52 minecraft:light_gray_stained_glass
fill ~6 ~0 ~-59 ~9 ~3 ~-59 doomsday_decoration:porcelainbrickwall
setblock ~7 ~1 ~-59 minecraft:iron_door[half=lower,facing=north]
setblock ~7 ~2 ~-59 minecraft:iron_door[half=upper,facing=north]
fill ~5 ~17 ~-59 ~15 ~17 ~-50 minecraft:smooth_stone_slab
# 116 local_shop -123,46 -118,53 h=11
fill ~-123 ~-3 ~46 ~-118 ~-1 ~53 minecraft:stone
fill ~-123 ~0 ~46 ~-118 ~11 ~53 minecraft:white_terracotta
fill ~-122 ~1 ~47 ~-119 ~10 ~52 minecraft:air
fill ~-122 ~4 ~47 ~-119 ~4 ~52 minecraft:smooth_stone
fill ~-122 ~8 ~47 ~-119 ~8 ~52 minecraft:smooth_stone
fill ~-121 ~2 ~46 ~-120 ~3 ~46 minecraft:gray_stained_glass
fill ~-121 ~2 ~53 ~-120 ~3 ~53 minecraft:light_gray_stained_glass
fill ~-121 ~6 ~46 ~-120 ~7 ~46 minecraft:gray_stained_glass
fill ~-121 ~6 ~53 ~-120 ~7 ~53 minecraft:light_gray_stained_glass
fill ~-122 ~0 ~46 ~-119 ~3 ~46 minecraft:dark_oak_planks
setblock ~-121 ~1 ~46 minecraft:iron_door[half=lower,facing=north]
setblock ~-121 ~2 ~46 minecraft:iron_door[half=upper,facing=north]
fill ~-123 ~12 ~46 ~-118 ~12 ~53 minecraft:dark_oak_slab
# 117 garage 60,-120 69,-109 h=10
fill ~60 ~-3 ~-120 ~69 ~-1 ~-109 minecraft:stone
fill ~60 ~0 ~-120 ~69 ~10 ~-109 minecraft:stone_bricks
fill ~61 ~1 ~-119 ~68 ~9 ~-110 minecraft:air
fill ~61 ~4 ~-119 ~68 ~4 ~-110 minecraft:smooth_stone
fill ~61 ~8 ~-119 ~68 ~8 ~-110 minecraft:smooth_stone
fill ~60 ~2 ~-118 ~60 ~3 ~-111 minecraft:gray_stained_glass
fill ~69 ~2 ~-118 ~69 ~3 ~-111 minecraft:light_gray_stained_glass
fill ~60 ~6 ~-118 ~60 ~7 ~-111 minecraft:gray_stained_glass
fill ~69 ~6 ~-118 ~69 ~7 ~-111 minecraft:light_gray_stained_glass
fill ~61 ~0 ~-120 ~64 ~3 ~-120 doomsday_decoration:ironsheetwall_2
setblock ~62 ~1 ~-120 minecraft:iron_door[half=lower,facing=north]
setblock ~62 ~2 ~-120 minecraft:iron_door[half=upper,facing=north]
fill ~60 ~11 ~-120 ~69 ~11 ~-109 minecraft:smooth_stone_slab
fill ~67 ~8 ~-111 ~69 ~11 ~-109 minecraft:air
setblock ~67 ~8 ~-111 minecraft:cobweb
# 118 detached_house -2,114 6,122 h=7
fill ~-2 ~-3 ~114 ~6 ~-1 ~122 minecraft:stone
fill ~-2 ~0 ~114 ~6 ~7 ~122 minecraft:white_terracotta
fill ~-1 ~1 ~115 ~5 ~6 ~121 minecraft:air
fill ~-1 ~4 ~115 ~5 ~4 ~121 minecraft:smooth_stone
fill ~-2 ~2 ~116 ~-2 ~3 ~120 minecraft:gray_stained_glass
fill ~6 ~2 ~116 ~6 ~3 ~120 minecraft:light_gray_stained_glass
fill ~-1 ~0 ~114 ~2 ~3 ~114 minecraft:dark_oak_planks
setblock ~0 ~1 ~114 minecraft:iron_door[half=lower,facing=north]
setblock ~0 ~2 ~114 minecraft:iron_door[half=upper,facing=north]
fill ~-2 ~8 ~114 ~6 ~8 ~122 minecraft:dark_oak_slab
# 119 garage 48,107 57,118 h=6
fill ~48 ~-3 ~107 ~57 ~-1 ~118 minecraft:stone
fill ~48 ~0 ~107 ~57 ~6 ~118 minecraft:stone_bricks
fill ~49 ~1 ~108 ~56 ~5 ~117 minecraft:air
fill ~49 ~4 ~108 ~56 ~4 ~117 minecraft:smooth_stone
fill ~50 ~2 ~107 ~55 ~3 ~107 minecraft:gray_stained_glass
fill ~50 ~2 ~118 ~55 ~3 ~118 minecraft:light_gray_stained_glass
fill ~49 ~0 ~107 ~52 ~3 ~107 minecraft:orange_terracotta
setblock ~50 ~1 ~107 minecraft:iron_door[half=lower,facing=north]
setblock ~50 ~2 ~107 minecraft:iron_door[half=upper,facing=north]
fill ~48 ~7 ~107 ~57 ~7 ~118 minecraft:stone_brick_slab
# 120 shop_house 40,-48 46,-34 h=8
fill ~40 ~-3 ~-48 ~46 ~-1 ~-34 minecraft:stone
fill ~40 ~0 ~-48 ~46 ~8 ~-34 minecraft:smooth_sandstone
fill ~41 ~1 ~-47 ~45 ~7 ~-35 minecraft:air
fill ~41 ~4 ~-47 ~45 ~4 ~-35 minecraft:smooth_stone
fill ~40 ~2 ~-46 ~40 ~3 ~-36 minecraft:gray_stained_glass
fill ~46 ~2 ~-46 ~46 ~3 ~-36 minecraft:light_gray_stained_glass
fill ~40 ~6 ~-46 ~40 ~7 ~-36 minecraft:gray_stained_glass
fill ~46 ~6 ~-46 ~46 ~7 ~-36 minecraft:light_gray_stained_glass
fill ~41 ~0 ~-48 ~44 ~3 ~-48 minecraft:brown_terracotta
setblock ~42 ~1 ~-48 minecraft:iron_door[half=lower,facing=north]
setblock ~42 ~2 ~-48 minecraft:iron_door[half=upper,facing=north]
fill ~40 ~9 ~-48 ~46 ~9 ~-34 minecraft:stone_brick_slab
# 121 restaurant 96,-42 103,-36 h=7
fill ~96 ~-3 ~-42 ~103 ~-1 ~-36 minecraft:stone
fill ~96 ~0 ~-42 ~103 ~7 ~-36 minecraft:bricks
fill ~97 ~1 ~-41 ~102 ~6 ~-37 minecraft:air
fill ~97 ~4 ~-41 ~102 ~4 ~-37 minecraft:smooth_stone
fill ~96 ~2 ~-40 ~96 ~3 ~-38 minecraft:gray_stained_glass
fill ~103 ~2 ~-40 ~103 ~3 ~-38 minecraft:light_gray_stained_glass
fill ~97 ~0 ~-42 ~100 ~3 ~-42 minecraft:weathered_cut_copper
setblock ~98 ~1 ~-42 minecraft:iron_door[half=lower,facing=north]
setblock ~98 ~2 ~-42 minecraft:iron_door[half=upper,facing=north]
fill ~96 ~8 ~-42 ~103 ~8 ~-36 minecraft:deepslate_tile_slab
# 122 restaurant 102,25 108,35 h=11
fill ~102 ~-3 ~25 ~108 ~-1 ~35 minecraft:stone
fill ~102 ~0 ~25 ~108 ~11 ~35 minecraft:bricks
fill ~103 ~1 ~26 ~107 ~10 ~34 minecraft:air
fill ~103 ~4 ~26 ~107 ~4 ~34 minecraft:smooth_stone
fill ~103 ~8 ~26 ~107 ~8 ~34 minecraft:smooth_stone
fill ~104 ~2 ~25 ~106 ~3 ~25 minecraft:gray_stained_glass
fill ~104 ~2 ~35 ~106 ~3 ~35 minecraft:light_gray_stained_glass
fill ~104 ~6 ~25 ~106 ~7 ~25 minecraft:gray_stained_glass
fill ~104 ~6 ~35 ~106 ~7 ~35 minecraft:light_gray_stained_glass
fill ~103 ~0 ~25 ~106 ~3 ~25 minecraft:weathered_cut_copper
setblock ~104 ~1 ~25 minecraft:iron_door[half=lower,facing=north]
setblock ~104 ~2 ~25 minecraft:iron_door[half=upper,facing=north]
fill ~102 ~12 ~25 ~108 ~12 ~35 minecraft:deepslate_tile_slab
# 123 shop_house 27,59 33,70 h=8
fill ~27 ~-3 ~59 ~33 ~-1 ~70 minecraft:stone
fill ~27 ~0 ~59 ~33 ~8 ~70 minecraft:smooth_sandstone
fill ~28 ~1 ~60 ~32 ~7 ~69 minecraft:air
fill ~28 ~4 ~60 ~32 ~4 ~69 minecraft:smooth_stone
fill ~29 ~2 ~59 ~31 ~3 ~59 minecraft:gray_stained_glass
fill ~29 ~2 ~70 ~31 ~3 ~70 minecraft:light_gray_stained_glass
fill ~29 ~6 ~59 ~31 ~7 ~59 minecraft:gray_stained_glass
fill ~29 ~6 ~70 ~31 ~7 ~70 minecraft:light_gray_stained_glass
fill ~28 ~0 ~59 ~31 ~3 ~59 minecraft:brown_terracotta
setblock ~29 ~1 ~59 minecraft:iron_door[half=lower,facing=north]
setblock ~29 ~2 ~59 minecraft:iron_door[half=upper,facing=north]
fill ~27 ~9 ~59 ~33 ~9 ~70 minecraft:stone_brick_slab
# 124 logistics 52,91 62,100 h=12
fill ~52 ~-3 ~91 ~62 ~-1 ~100 minecraft:stone
fill ~52 ~0 ~91 ~62 ~12 ~100 minecraft:stone_bricks
fill ~53 ~1 ~92 ~61 ~11 ~99 minecraft:air
fill ~53 ~4 ~92 ~61 ~4 ~99 minecraft:smooth_stone
fill ~53 ~8 ~92 ~61 ~8 ~99 minecraft:smooth_stone
fill ~54 ~2 ~91 ~60 ~3 ~91 minecraft:gray_stained_glass
fill ~54 ~2 ~100 ~60 ~3 ~100 minecraft:light_gray_stained_glass
fill ~54 ~6 ~91 ~60 ~7 ~91 minecraft:gray_stained_glass
fill ~54 ~6 ~100 ~60 ~7 ~100 minecraft:light_gray_stained_glass
fill ~54 ~10 ~91 ~60 ~11 ~91 minecraft:gray_stained_glass
fill ~54 ~10 ~100 ~60 ~11 ~100 minecraft:light_gray_stained_glass
fill ~53 ~0 ~91 ~56 ~3 ~91 minecraft:orange_terracotta
setblock ~54 ~1 ~91 minecraft:iron_door[half=lower,facing=north]
setblock ~54 ~2 ~91 minecraft:iron_door[half=upper,facing=north]
fill ~52 ~13 ~91 ~62 ~13 ~100 minecraft:stone_brick_slab
# 125 small_office 7,-8 13,0 h=12
fill ~7 ~-3 ~-8 ~13 ~-1 ~0 minecraft:stone
fill ~7 ~0 ~-8 ~13 ~12 ~0 minecraft:white_terracotta
fill ~8 ~1 ~-7 ~12 ~11 ~-1 minecraft:air
fill ~8 ~4 ~-7 ~12 ~4 ~-1 minecraft:smooth_stone
fill ~8 ~8 ~-7 ~12 ~8 ~-1 minecraft:smooth_stone
fill ~7 ~2 ~-6 ~7 ~3 ~-2 minecraft:gray_stained_glass
fill ~13 ~2 ~-6 ~13 ~3 ~-2 minecraft:light_gray_stained_glass
fill ~7 ~6 ~-6 ~7 ~7 ~-2 minecraft:gray_stained_glass
fill ~13 ~6 ~-6 ~13 ~7 ~-2 minecraft:light_gray_stained_glass
fill ~7 ~10 ~-6 ~7 ~11 ~-2 minecraft:gray_stained_glass
fill ~13 ~10 ~-6 ~13 ~11 ~-2 minecraft:light_gray_stained_glass
fill ~8 ~0 ~-8 ~11 ~3 ~-8 minecraft:gray_concrete
setblock ~9 ~1 ~-8 minecraft:iron_door[half=lower,facing=north]
setblock ~9 ~2 ~-8 minecraft:iron_door[half=upper,facing=north]
fill ~7 ~13 ~-8 ~13 ~13 ~0 minecraft:stone_brick_slab
