# Buildings 201..208
# 201 workshop style=loading_bay context=collector_front facing=east
fill ~-110 ~-3 ~-80 ~-104 ~-1 ~-76 minecraft:stone
fill ~-110 ~0 ~-80 ~-104 ~9 ~-76 minecraft:mud_bricks
fill ~-109 ~1 ~-79 ~-105 ~8 ~-77 minecraft:air
fill ~-109 ~4 ~-79 ~-105 ~4 ~-77 minecraft:smooth_stone
fill ~-109 ~8 ~-79 ~-105 ~8 ~-77 minecraft:smooth_stone
fill ~-108 ~2 ~-80 ~-108 ~3 ~-80 minecraft:gray_stained_glass
fill ~-108 ~2 ~-76 ~-108 ~3 ~-76 minecraft:light_gray_stained_glass
fill ~-110 ~2 ~-78 ~-110 ~3 ~-78 minecraft:gray_stained_glass
fill ~-104 ~2 ~-78 ~-104 ~3 ~-78 minecraft:light_gray_stained_glass
fill ~-108 ~6 ~-80 ~-108 ~7 ~-80 minecraft:gray_stained_glass
fill ~-108 ~6 ~-76 ~-108 ~7 ~-76 minecraft:light_gray_stained_glass
fill ~-110 ~6 ~-78 ~-110 ~7 ~-78 minecraft:gray_stained_glass
fill ~-104 ~6 ~-78 ~-104 ~7 ~-78 minecraft:light_gray_stained_glass
setblock ~-104 ~1 ~-78 minecraft:iron_door[half=lower,facing=east]
setblock ~-104 ~2 ~-78 minecraft:iron_door[half=upper,facing=east]
fill ~-104 ~1 ~-78 ~-104 ~4 ~-78 minecraft:polished_blackstone
fill ~-104 ~5 ~-78 ~-104 ~5 ~-78 minecraft:light_blue_stained_glass
fill ~-108 ~11 ~-78 ~-106 ~12 ~-77 minecraft:iron_block
fill ~-110 ~10 ~-80 ~-104 ~10 ~-76 minecraft:deepslate_tile_slab
fill ~-108 ~11 ~-78 ~-106 ~12 ~-77 minecraft:light_gray_concrete
setblock ~-105 ~11 ~-77 minecraft:lightning_rod
# 202 local_shop style=arcade_shop context=arterial_front facing=north
fill ~87 ~-3 ~6 ~92 ~-1 ~13 minecraft:stone
fill ~87 ~0 ~6 ~92 ~5 ~13 minecraft:smooth_sandstone
fill ~88 ~1 ~7 ~91 ~4 ~12 minecraft:air
fill ~88 ~4 ~7 ~91 ~4 ~12 minecraft:smooth_stone
fill ~89 ~2 ~6 ~89 ~3 ~6 minecraft:gray_stained_glass
fill ~89 ~2 ~13 ~89 ~3 ~13 minecraft:light_gray_stained_glass
fill ~87 ~2 ~8 ~87 ~3 ~8 minecraft:gray_stained_glass
fill ~92 ~2 ~8 ~92 ~3 ~8 minecraft:light_gray_stained_glass
fill ~87 ~2 ~11 ~87 ~3 ~11 minecraft:gray_stained_glass
fill ~92 ~2 ~11 ~92 ~3 ~11 minecraft:light_gray_stained_glass
setblock ~89 ~1 ~6 minecraft:iron_door[half=lower,facing=north]
setblock ~89 ~2 ~6 minecraft:iron_door[half=upper,facing=north]
fill ~88 ~1 ~6 ~91 ~3 ~6 minecraft:cyan_stained_glass
setblock ~89 ~1 ~6 minecraft:iron_door[half=lower,facing=north]
setblock ~89 ~2 ~6 minecraft:iron_door[half=upper,facing=north]
setblock ~89 ~3 ~5 minecraft:red_wool
fill ~88 ~4 ~6 ~91 ~4 ~6 minecraft:brown_terracotta
fill ~87 ~6 ~6 ~92 ~6 ~13 minecraft:stone_brick_slab
fill ~88 ~1 ~6 ~88 ~5 ~6 minecraft:brown_terracotta
setblock ~89 ~3 ~6 minecraft:red_carpet
# 203 row_house style=rowhouse context=local_front facing=north
fill ~-15 ~-3 ~-104 ~-11 ~-1 ~-98 minecraft:stone
fill ~-15 ~0 ~-104 ~-11 ~9 ~-98 minecraft:bricks
fill ~-14 ~1 ~-103 ~-12 ~8 ~-99 minecraft:air
fill ~-14 ~4 ~-103 ~-12 ~4 ~-99 minecraft:smooth_stone
fill ~-14 ~8 ~-103 ~-12 ~8 ~-99 minecraft:smooth_stone
fill ~-13 ~2 ~-104 ~-13 ~3 ~-104 minecraft:gray_stained_glass
fill ~-13 ~2 ~-98 ~-13 ~3 ~-98 minecraft:light_gray_stained_glass
fill ~-15 ~2 ~-102 ~-15 ~3 ~-102 minecraft:gray_stained_glass
fill ~-11 ~2 ~-102 ~-11 ~3 ~-102 minecraft:light_gray_stained_glass
fill ~-13 ~6 ~-104 ~-13 ~7 ~-104 minecraft:gray_stained_glass
fill ~-13 ~6 ~-98 ~-13 ~7 ~-98 minecraft:light_gray_stained_glass
fill ~-15 ~6 ~-102 ~-15 ~7 ~-102 minecraft:gray_stained_glass
fill ~-11 ~6 ~-102 ~-11 ~7 ~-102 minecraft:light_gray_stained_glass
setblock ~-13 ~1 ~-104 minecraft:iron_door[half=lower,facing=north]
setblock ~-13 ~2 ~-104 minecraft:iron_door[half=upper,facing=north]
fill ~-15 ~10 ~-104 ~-11 ~10 ~-98 minecraft:deepslate_tile_slab
fill ~-14 ~11 ~-103 ~-12 ~11 ~-99 minecraft:deepslate_tile_slab
setblock ~-13 ~3 ~-105 minecraft:dark_oak_slab[type=top]
# 204 local_shop style=storefront context=collector_front facing=west
fill ~91 ~-3 ~-64 ~97 ~-1 ~-60 minecraft:stone
fill ~91 ~0 ~-64 ~97 ~11 ~-60 minecraft:mud_bricks
fill ~92 ~1 ~-63 ~96 ~10 ~-61 minecraft:air
fill ~92 ~4 ~-63 ~96 ~4 ~-61 minecraft:smooth_stone
fill ~92 ~8 ~-63 ~96 ~8 ~-61 minecraft:smooth_stone
fill ~93 ~2 ~-64 ~93 ~3 ~-64 minecraft:gray_stained_glass
fill ~93 ~2 ~-60 ~93 ~3 ~-60 minecraft:light_gray_stained_glass
fill ~91 ~2 ~-62 ~91 ~3 ~-62 minecraft:gray_stained_glass
fill ~97 ~2 ~-62 ~97 ~3 ~-62 minecraft:light_gray_stained_glass
fill ~93 ~6 ~-64 ~93 ~7 ~-64 minecraft:gray_stained_glass
fill ~93 ~6 ~-60 ~93 ~7 ~-60 minecraft:light_gray_stained_glass
fill ~91 ~6 ~-62 ~91 ~7 ~-62 minecraft:gray_stained_glass
fill ~97 ~6 ~-62 ~97 ~7 ~-62 minecraft:light_gray_stained_glass
setblock ~91 ~1 ~-62 minecraft:iron_door[half=lower,facing=west]
setblock ~91 ~2 ~-62 minecraft:iron_door[half=upper,facing=west]
fill ~91 ~1 ~-63 ~91 ~3 ~-61 minecraft:cyan_stained_glass
setblock ~91 ~1 ~-62 minecraft:iron_door[half=lower,facing=west]
setblock ~91 ~2 ~-62 minecraft:iron_door[half=upper,facing=west]
setblock ~90 ~3 ~-62 minecraft:red_wool
fill ~91 ~12 ~-64 ~97 ~12 ~-60 minecraft:deepslate_tile_slab
fill ~93 ~13 ~-62 ~95 ~14 ~-61 minecraft:light_gray_concrete
setblock ~96 ~13 ~-61 minecraft:lightning_rod
# 205 shop_house style=arcade_shop context=local_front facing=west
fill ~-62 ~-3 ~63 ~-57 ~-1 ~66 minecraft:stone
fill ~-62 ~0 ~63 ~-57 ~11 ~66 minecraft:light_gray_concrete
fill ~-61 ~1 ~64 ~-58 ~10 ~65 minecraft:air
fill ~-61 ~4 ~64 ~-58 ~4 ~65 minecraft:smooth_stone
fill ~-61 ~8 ~64 ~-58 ~8 ~65 minecraft:smooth_stone
fill ~-60 ~2 ~63 ~-60 ~3 ~63 minecraft:gray_stained_glass
fill ~-60 ~2 ~66 ~-60 ~3 ~66 minecraft:light_gray_stained_glass
fill ~-60 ~6 ~63 ~-60 ~7 ~63 minecraft:gray_stained_glass
fill ~-60 ~6 ~66 ~-60 ~7 ~66 minecraft:light_gray_stained_glass
setblock ~-62 ~1 ~65 minecraft:iron_door[half=lower,facing=west]
setblock ~-62 ~2 ~65 minecraft:iron_door[half=upper,facing=west]
fill ~-62 ~1 ~64 ~-62 ~3 ~65 minecraft:cyan_stained_glass
setblock ~-62 ~1 ~65 minecraft:iron_door[half=lower,facing=west]
setblock ~-62 ~2 ~65 minecraft:iron_door[half=upper,facing=west]
setblock ~-63 ~3 ~65 minecraft:red_wool
fill ~-62 ~4 ~64 ~-62 ~4 ~65 doomsday_decoration:porcelainbrickwall
fill ~-62 ~12 ~63 ~-57 ~12 ~66 minecraft:smooth_stone_slab
# 206 workshop style=sawtooth context=collector_front facing=east
fill ~12 ~-3 ~-123 ~17 ~-1 ~-120 minecraft:stone
fill ~12 ~0 ~-123 ~17 ~5 ~-120 minecraft:bricks
fill ~13 ~1 ~-122 ~16 ~4 ~-121 minecraft:air
fill ~13 ~4 ~-122 ~16 ~4 ~-121 minecraft:smooth_stone
fill ~14 ~2 ~-123 ~14 ~3 ~-123 minecraft:gray_stained_glass
fill ~14 ~2 ~-120 ~14 ~3 ~-120 minecraft:light_gray_stained_glass
setblock ~17 ~1 ~-121 minecraft:iron_door[half=lower,facing=east]
setblock ~17 ~2 ~-121 minecraft:iron_door[half=upper,facing=east]
fill ~17 ~1 ~-121 ~17 ~4 ~-122 minecraft:polished_blackstone
fill ~17 ~4 ~-121 ~17 ~4 ~-122 minecraft:light_blue_stained_glass
fill ~14 ~7 ~-121 ~16 ~8 ~-121 minecraft:iron_block
fill ~12 ~6 ~-123 ~17 ~6 ~-120 minecraft:deepslate_tile_slab
# 207 shop_house style=corner_store context=local_front facing=north
fill ~-24 ~-3 ~110 ~-21 ~-1 ~115 minecraft:stone
fill ~-24 ~0 ~110 ~-21 ~11 ~115 minecraft:white_terracotta
fill ~-23 ~1 ~111 ~-22 ~10 ~114 minecraft:air
fill ~-23 ~4 ~111 ~-22 ~4 ~114 minecraft:smooth_stone
fill ~-23 ~8 ~111 ~-22 ~8 ~114 minecraft:smooth_stone
fill ~-24 ~2 ~112 ~-24 ~3 ~112 minecraft:gray_stained_glass
fill ~-21 ~2 ~112 ~-21 ~3 ~112 minecraft:light_gray_stained_glass
fill ~-24 ~6 ~112 ~-24 ~7 ~112 minecraft:gray_stained_glass
fill ~-21 ~6 ~112 ~-21 ~7 ~112 minecraft:light_gray_stained_glass
setblock ~-22 ~1 ~110 minecraft:iron_door[half=lower,facing=north]
setblock ~-22 ~2 ~110 minecraft:iron_door[half=upper,facing=north]
fill ~-23 ~1 ~110 ~-22 ~3 ~110 minecraft:cyan_stained_glass
setblock ~-22 ~1 ~110 minecraft:iron_door[half=lower,facing=north]
setblock ~-22 ~2 ~110 minecraft:iron_door[half=upper,facing=north]
setblock ~-22 ~3 ~109 minecraft:red_wool
fill ~-24 ~12 ~110 ~-21 ~12 ~115 minecraft:dark_oak_slab
fill ~-22 ~13 ~112 ~-22 ~14 ~114 minecraft:light_gray_concrete
setblock ~-22 ~13 ~113 minecraft:lightning_rod
# 208 workshop style=sawtooth context=local_front facing=south
fill ~-70 ~-3 ~-121 ~-65 ~-1 ~-114 minecraft:stone
fill ~-70 ~0 ~-121 ~-65 ~7 ~-114 minecraft:bricks
fill ~-69 ~1 ~-120 ~-66 ~6 ~-115 minecraft:air
fill ~-69 ~4 ~-120 ~-66 ~4 ~-115 minecraft:smooth_stone
fill ~-68 ~2 ~-121 ~-68 ~3 ~-121 minecraft:gray_stained_glass
fill ~-68 ~2 ~-114 ~-68 ~3 ~-114 minecraft:light_gray_stained_glass
fill ~-70 ~2 ~-119 ~-70 ~3 ~-119 minecraft:gray_stained_glass
fill ~-65 ~2 ~-119 ~-65 ~3 ~-119 minecraft:light_gray_stained_glass
fill ~-70 ~2 ~-116 ~-70 ~3 ~-116 minecraft:gray_stained_glass
fill ~-65 ~2 ~-116 ~-65 ~3 ~-116 minecraft:light_gray_stained_glass
setblock ~-68 ~1 ~-114 minecraft:iron_door[half=lower,facing=south]
setblock ~-68 ~2 ~-114 minecraft:iron_door[half=upper,facing=south]
fill ~-68 ~1 ~-114 ~-67 ~4 ~-114 minecraft:polished_blackstone
fill ~-68 ~5 ~-114 ~-67 ~5 ~-114 minecraft:light_blue_stained_glass
fill ~-68 ~9 ~-119 ~-66 ~10 ~-117 minecraft:iron_block
fill ~-70 ~8 ~-121 ~-65 ~8 ~-114 minecraft:deepslate_tile_slab
fill ~-69 ~1 ~-114 ~-69 ~7 ~-114 minecraft:gray_concrete
