# Buildings 145..152
# 145 warehouse style=industrial_shed context=local_front facing=east
fill ~74 ~-3 ~-118 ~85 ~-1 ~-107 minecraft:stone
fill ~74 ~0 ~-118 ~85 ~9 ~-107 minecraft:bricks
fill ~75 ~1 ~-117 ~84 ~8 ~-108 minecraft:air
fill ~75 ~4 ~-117 ~84 ~4 ~-108 minecraft:smooth_stone
fill ~75 ~8 ~-117 ~84 ~8 ~-108 minecraft:smooth_stone
fill ~76 ~2 ~-118 ~76 ~3 ~-118 minecraft:gray_stained_glass
fill ~76 ~2 ~-107 ~76 ~3 ~-107 minecraft:light_gray_stained_glass
fill ~79 ~2 ~-118 ~79 ~3 ~-118 minecraft:gray_stained_glass
fill ~79 ~2 ~-107 ~79 ~3 ~-107 minecraft:light_gray_stained_glass
fill ~82 ~2 ~-118 ~82 ~3 ~-118 minecraft:gray_stained_glass
fill ~82 ~2 ~-107 ~82 ~3 ~-107 minecraft:light_gray_stained_glass
fill ~74 ~2 ~-116 ~74 ~3 ~-116 minecraft:gray_stained_glass
fill ~85 ~2 ~-116 ~85 ~3 ~-116 minecraft:light_gray_stained_glass
fill ~74 ~2 ~-113 ~74 ~3 ~-113 minecraft:gray_stained_glass
fill ~85 ~2 ~-113 ~85 ~3 ~-113 minecraft:light_gray_stained_glass
fill ~74 ~2 ~-110 ~74 ~3 ~-110 minecraft:gray_stained_glass
fill ~85 ~2 ~-110 ~85 ~3 ~-110 minecraft:light_gray_stained_glass
fill ~76 ~6 ~-118 ~76 ~7 ~-118 minecraft:gray_stained_glass
fill ~76 ~6 ~-107 ~76 ~7 ~-107 minecraft:light_gray_stained_glass
fill ~79 ~6 ~-118 ~79 ~7 ~-118 minecraft:gray_stained_glass
fill ~79 ~6 ~-107 ~79 ~7 ~-107 minecraft:light_gray_stained_glass
fill ~82 ~6 ~-118 ~82 ~7 ~-118 minecraft:gray_stained_glass
fill ~82 ~6 ~-107 ~82 ~7 ~-107 minecraft:light_gray_stained_glass
fill ~74 ~6 ~-116 ~74 ~7 ~-116 minecraft:gray_stained_glass
fill ~85 ~6 ~-116 ~85 ~7 ~-116 minecraft:light_gray_stained_glass
fill ~74 ~6 ~-113 ~74 ~7 ~-113 minecraft:gray_stained_glass
fill ~85 ~6 ~-113 ~85 ~7 ~-113 minecraft:light_gray_stained_glass
fill ~74 ~6 ~-110 ~74 ~7 ~-110 minecraft:gray_stained_glass
fill ~85 ~6 ~-110 ~85 ~7 ~-110 minecraft:light_gray_stained_glass
setblock ~85 ~1 ~-113 minecraft:iron_door[half=lower,facing=east]
setblock ~85 ~2 ~-113 minecraft:iron_door[half=upper,facing=east]
fill ~85 ~1 ~-116 ~85 ~4 ~-109 minecraft:polished_blackstone
fill ~85 ~5 ~-116 ~85 ~5 ~-109 minecraft:light_blue_stained_glass
fill ~76 ~11 ~-116 ~78 ~12 ~-114 minecraft:iron_block
fill ~74 ~10 ~-118 ~85 ~10 ~-107 minecraft:deepslate_tile_slab
fill ~85 ~1 ~-117 ~85 ~7 ~-117 minecraft:gray_concrete
fill ~85 ~1 ~-113 ~85 ~7 ~-113 minecraft:gray_concrete
fill ~85 ~1 ~-109 ~85 ~7 ~-109 minecraft:gray_concrete
# 146 restaurant style=storefront context=collector_front facing=west
fill ~104 ~-3 ~45 ~110 ~-1 ~50 minecraft:stone
fill ~104 ~0 ~45 ~110 ~5 ~50 minecraft:bricks
fill ~105 ~1 ~46 ~109 ~4 ~49 minecraft:air
fill ~105 ~4 ~46 ~109 ~4 ~49 minecraft:smooth_stone
fill ~106 ~2 ~45 ~106 ~3 ~45 minecraft:gray_stained_glass
fill ~106 ~2 ~50 ~106 ~3 ~50 minecraft:light_gray_stained_glass
fill ~104 ~2 ~47 ~104 ~3 ~47 minecraft:gray_stained_glass
fill ~110 ~2 ~47 ~110 ~3 ~47 minecraft:light_gray_stained_glass
setblock ~104 ~1 ~47 minecraft:iron_door[half=lower,facing=west]
setblock ~104 ~2 ~47 minecraft:iron_door[half=upper,facing=west]
fill ~104 ~1 ~46 ~104 ~3 ~49 minecraft:cyan_stained_glass
setblock ~104 ~1 ~47 minecraft:iron_door[half=lower,facing=west]
setblock ~104 ~2 ~47 minecraft:iron_door[half=upper,facing=west]
setblock ~103 ~3 ~47 minecraft:red_wool
fill ~104 ~6 ~45 ~110 ~6 ~50 minecraft:deepslate_tile_slab
fill ~104 ~1 ~46 ~104 ~5 ~46 minecraft:weathered_cut_copper
setblock ~104 ~3 ~47 minecraft:red_carpet
# 147 supermarket style=storefront context=collector_front facing=west
fill ~-92 ~-3 ~-71 ~-86 ~-1 ~-62 minecraft:stone
fill ~-92 ~0 ~-71 ~-86 ~9 ~-62 minecraft:mud_bricks
fill ~-91 ~1 ~-70 ~-87 ~8 ~-63 minecraft:air
fill ~-91 ~4 ~-70 ~-87 ~4 ~-63 minecraft:smooth_stone
fill ~-91 ~8 ~-70 ~-87 ~8 ~-63 minecraft:smooth_stone
fill ~-90 ~2 ~-71 ~-90 ~3 ~-71 minecraft:gray_stained_glass
fill ~-90 ~2 ~-62 ~-90 ~3 ~-62 minecraft:light_gray_stained_glass
fill ~-92 ~2 ~-69 ~-92 ~3 ~-69 minecraft:gray_stained_glass
fill ~-86 ~2 ~-69 ~-86 ~3 ~-69 minecraft:light_gray_stained_glass
fill ~-92 ~2 ~-66 ~-92 ~3 ~-66 minecraft:gray_stained_glass
fill ~-86 ~2 ~-66 ~-86 ~3 ~-66 minecraft:light_gray_stained_glass
fill ~-90 ~6 ~-71 ~-90 ~7 ~-71 minecraft:gray_stained_glass
fill ~-90 ~6 ~-62 ~-90 ~7 ~-62 minecraft:light_gray_stained_glass
fill ~-92 ~6 ~-69 ~-92 ~7 ~-69 minecraft:gray_stained_glass
fill ~-86 ~6 ~-69 ~-86 ~7 ~-69 minecraft:light_gray_stained_glass
fill ~-92 ~6 ~-66 ~-92 ~7 ~-66 minecraft:gray_stained_glass
fill ~-86 ~6 ~-66 ~-86 ~7 ~-66 minecraft:light_gray_stained_glass
setblock ~-92 ~1 ~-67 minecraft:iron_door[half=lower,facing=west]
setblock ~-92 ~2 ~-67 minecraft:iron_door[half=upper,facing=west]
fill ~-92 ~1 ~-70 ~-92 ~3 ~-63 minecraft:cyan_stained_glass
setblock ~-92 ~1 ~-67 minecraft:iron_door[half=lower,facing=west]
setblock ~-92 ~2 ~-67 minecraft:iron_door[half=upper,facing=west]
setblock ~-93 ~3 ~-67 minecraft:red_wool
fill ~-92 ~10 ~-71 ~-86 ~10 ~-62 minecraft:deepslate_tile_slab
fill ~-90 ~11 ~-69 ~-88 ~12 ~-67 minecraft:light_gray_concrete
setblock ~-87 ~11 ~-68 minecraft:lightning_rod
fill ~-92 ~1 ~-70 ~-92 ~7 ~-70 minecraft:spruce_planks
fill ~-92 ~1 ~-66 ~-92 ~7 ~-66 minecraft:spruce_planks
# 148 shop_house style=corner_store context=collector_front facing=south
fill ~2 ~-3 ~32 ~11 ~-1 ~40 minecraft:stone
fill ~2 ~0 ~32 ~11 ~28 ~40 minecraft:light_gray_concrete
fill ~3 ~1 ~33 ~10 ~27 ~39 minecraft:air
fill ~3 ~4 ~33 ~10 ~4 ~39 minecraft:smooth_stone
fill ~3 ~8 ~33 ~10 ~8 ~39 minecraft:smooth_stone
fill ~3 ~12 ~33 ~10 ~12 ~39 minecraft:smooth_stone
fill ~3 ~16 ~33 ~10 ~16 ~39 minecraft:smooth_stone
fill ~3 ~20 ~33 ~10 ~20 ~39 minecraft:smooth_stone
fill ~3 ~24 ~33 ~10 ~24 ~39 minecraft:smooth_stone
fill ~4 ~2 ~32 ~4 ~3 ~32 minecraft:gray_stained_glass
fill ~4 ~2 ~40 ~4 ~3 ~40 minecraft:light_gray_stained_glass
fill ~7 ~2 ~32 ~7 ~3 ~32 minecraft:gray_stained_glass
fill ~7 ~2 ~40 ~7 ~3 ~40 minecraft:light_gray_stained_glass
fill ~2 ~2 ~34 ~2 ~3 ~34 minecraft:gray_stained_glass
fill ~11 ~2 ~34 ~11 ~3 ~34 minecraft:light_gray_stained_glass
fill ~2 ~2 ~37 ~2 ~3 ~37 minecraft:gray_stained_glass
fill ~11 ~2 ~37 ~11 ~3 ~37 minecraft:light_gray_stained_glass
fill ~4 ~6 ~32 ~4 ~7 ~32 minecraft:gray_stained_glass
fill ~4 ~6 ~40 ~4 ~7 ~40 minecraft:light_gray_stained_glass
fill ~7 ~6 ~32 ~7 ~7 ~32 minecraft:gray_stained_glass
fill ~7 ~6 ~40 ~7 ~7 ~40 minecraft:light_gray_stained_glass
fill ~2 ~6 ~34 ~2 ~7 ~34 minecraft:gray_stained_glass
fill ~11 ~6 ~34 ~11 ~7 ~34 minecraft:light_gray_stained_glass
fill ~2 ~6 ~37 ~2 ~7 ~37 minecraft:gray_stained_glass
fill ~11 ~6 ~37 ~11 ~7 ~37 minecraft:light_gray_stained_glass
fill ~4 ~10 ~32 ~4 ~11 ~32 minecraft:gray_stained_glass
fill ~4 ~10 ~40 ~4 ~11 ~40 minecraft:light_gray_stained_glass
fill ~7 ~10 ~32 ~7 ~11 ~32 minecraft:gray_stained_glass
fill ~7 ~10 ~40 ~7 ~11 ~40 minecraft:light_gray_stained_glass
fill ~2 ~10 ~34 ~2 ~11 ~34 minecraft:gray_stained_glass
fill ~11 ~10 ~34 ~11 ~11 ~34 minecraft:light_gray_stained_glass
fill ~2 ~10 ~37 ~2 ~11 ~37 minecraft:gray_stained_glass
fill ~11 ~10 ~37 ~11 ~11 ~37 minecraft:light_gray_stained_glass
fill ~4 ~14 ~32 ~4 ~15 ~32 minecraft:gray_stained_glass
fill ~4 ~14 ~40 ~4 ~15 ~40 minecraft:light_gray_stained_glass
fill ~7 ~14 ~32 ~7 ~15 ~32 minecraft:gray_stained_glass
fill ~7 ~14 ~40 ~7 ~15 ~40 minecraft:light_gray_stained_glass
fill ~2 ~14 ~34 ~2 ~15 ~34 minecraft:gray_stained_glass
fill ~11 ~14 ~34 ~11 ~15 ~34 minecraft:light_gray_stained_glass
fill ~2 ~14 ~37 ~2 ~15 ~37 minecraft:gray_stained_glass
fill ~11 ~14 ~37 ~11 ~15 ~37 minecraft:light_gray_stained_glass
fill ~4 ~18 ~32 ~4 ~19 ~32 minecraft:gray_stained_glass
fill ~4 ~18 ~40 ~4 ~19 ~40 minecraft:light_gray_stained_glass
fill ~7 ~18 ~32 ~7 ~19 ~32 minecraft:gray_stained_glass
fill ~7 ~18 ~40 ~7 ~19 ~40 minecraft:light_gray_stained_glass
fill ~2 ~18 ~34 ~2 ~19 ~34 minecraft:gray_stained_glass
fill ~11 ~18 ~34 ~11 ~19 ~34 minecraft:light_gray_stained_glass
fill ~2 ~18 ~37 ~2 ~19 ~37 minecraft:gray_stained_glass
fill ~11 ~18 ~37 ~11 ~19 ~37 minecraft:light_gray_stained_glass
fill ~4 ~22 ~32 ~4 ~23 ~32 minecraft:gray_stained_glass
fill ~4 ~22 ~40 ~4 ~23 ~40 minecraft:light_gray_stained_glass
fill ~7 ~22 ~32 ~7 ~23 ~32 minecraft:gray_stained_glass
fill ~7 ~22 ~40 ~7 ~23 ~40 minecraft:light_gray_stained_glass
fill ~2 ~22 ~34 ~2 ~23 ~34 minecraft:gray_stained_glass
fill ~11 ~22 ~34 ~11 ~23 ~34 minecraft:light_gray_stained_glass
fill ~2 ~22 ~37 ~2 ~23 ~37 minecraft:gray_stained_glass
fill ~11 ~22 ~37 ~11 ~23 ~37 minecraft:light_gray_stained_glass
fill ~4 ~26 ~32 ~4 ~27 ~32 minecraft:gray_stained_glass
fill ~4 ~26 ~40 ~4 ~27 ~40 minecraft:light_gray_stained_glass
fill ~7 ~26 ~32 ~7 ~27 ~32 minecraft:gray_stained_glass
fill ~7 ~26 ~40 ~7 ~27 ~40 minecraft:light_gray_stained_glass
fill ~2 ~26 ~34 ~2 ~27 ~34 minecraft:gray_stained_glass
fill ~11 ~26 ~34 ~11 ~27 ~34 minecraft:light_gray_stained_glass
fill ~2 ~26 ~37 ~2 ~27 ~37 minecraft:gray_stained_glass
fill ~11 ~26 ~37 ~11 ~27 ~37 minecraft:light_gray_stained_glass
setblock ~6 ~1 ~40 minecraft:iron_door[half=lower,facing=south]
setblock ~6 ~2 ~40 minecraft:iron_door[half=upper,facing=south]
fill ~3 ~1 ~40 ~10 ~3 ~40 minecraft:cyan_stained_glass
setblock ~6 ~1 ~40 minecraft:iron_door[half=lower,facing=south]
setblock ~6 ~2 ~40 minecraft:iron_door[half=upper,facing=south]
setblock ~6 ~3 ~41 minecraft:red_wool
fill ~2 ~29 ~32 ~11 ~29 ~40 minecraft:smooth_stone_slab
fill ~3 ~1 ~40 ~3 ~7 ~40 doomsday_decoration:cementwall
fill ~7 ~1 ~40 ~7 ~7 ~40 doomsday_decoration:cementwall
fill ~3 ~6 ~33 ~10 ~28 ~39 minecraft:light_gray_concrete
fill ~4 ~7 ~34 ~9 ~27 ~38 minecraft:air
setblock ~4 ~3 ~40 minecraft:red_carpet
setblock ~9 ~3 ~40 minecraft:red_carpet
# 149 detached_house style=stepped_house context=local_front facing=north
fill ~-71 ~-3 ~97 ~-67 ~-1 ~104 minecraft:stone
fill ~-71 ~0 ~97 ~-67 ~11 ~104 minecraft:mud_bricks
fill ~-70 ~1 ~98 ~-68 ~10 ~103 minecraft:air
fill ~-70 ~4 ~98 ~-68 ~4 ~103 minecraft:smooth_stone
fill ~-70 ~8 ~98 ~-68 ~8 ~103 minecraft:smooth_stone
fill ~-69 ~2 ~97 ~-69 ~3 ~97 minecraft:gray_stained_glass
fill ~-69 ~2 ~104 ~-69 ~3 ~104 minecraft:light_gray_stained_glass
fill ~-71 ~2 ~99 ~-71 ~3 ~99 minecraft:gray_stained_glass
fill ~-67 ~2 ~99 ~-67 ~3 ~99 minecraft:light_gray_stained_glass
fill ~-71 ~2 ~102 ~-71 ~3 ~102 minecraft:gray_stained_glass
fill ~-67 ~2 ~102 ~-67 ~3 ~102 minecraft:light_gray_stained_glass
fill ~-69 ~6 ~97 ~-69 ~7 ~97 minecraft:gray_stained_glass
fill ~-69 ~6 ~104 ~-69 ~7 ~104 minecraft:light_gray_stained_glass
fill ~-71 ~6 ~99 ~-71 ~7 ~99 minecraft:gray_stained_glass
fill ~-67 ~6 ~99 ~-67 ~7 ~99 minecraft:light_gray_stained_glass
fill ~-71 ~6 ~102 ~-71 ~7 ~102 minecraft:gray_stained_glass
fill ~-67 ~6 ~102 ~-67 ~7 ~102 minecraft:light_gray_stained_glass
setblock ~-69 ~1 ~97 minecraft:iron_door[half=lower,facing=north]
setblock ~-69 ~2 ~97 minecraft:iron_door[half=upper,facing=north]
fill ~-71 ~12 ~97 ~-67 ~12 ~104 minecraft:deepslate_tile_slab
fill ~-70 ~13 ~98 ~-68 ~13 ~103 minecraft:deepslate_tile_slab
setblock ~-69 ~3 ~96 minecraft:dark_oak_slab[type=top]
# 150 restaurant style=corner_store context=collector_front facing=east
fill ~-114 ~-3 ~-55 ~-104 ~-1 ~-49 minecraft:stone
fill ~-114 ~0 ~-55 ~-104 ~5 ~-49 minecraft:white_terracotta
fill ~-113 ~1 ~-54 ~-105 ~4 ~-50 minecraft:air
fill ~-113 ~4 ~-54 ~-105 ~4 ~-50 minecraft:smooth_stone
fill ~-112 ~2 ~-55 ~-112 ~3 ~-55 minecraft:gray_stained_glass
fill ~-112 ~2 ~-49 ~-112 ~3 ~-49 minecraft:light_gray_stained_glass
fill ~-109 ~2 ~-55 ~-109 ~3 ~-55 minecraft:gray_stained_glass
fill ~-109 ~2 ~-49 ~-109 ~3 ~-49 minecraft:light_gray_stained_glass
fill ~-106 ~2 ~-55 ~-106 ~3 ~-55 minecraft:gray_stained_glass
fill ~-106 ~2 ~-49 ~-106 ~3 ~-49 minecraft:light_gray_stained_glass
fill ~-114 ~2 ~-53 ~-114 ~3 ~-53 minecraft:gray_stained_glass
fill ~-104 ~2 ~-53 ~-104 ~3 ~-53 minecraft:light_gray_stained_glass
setblock ~-104 ~1 ~-52 minecraft:iron_door[half=lower,facing=east]
setblock ~-104 ~2 ~-52 minecraft:iron_door[half=upper,facing=east]
fill ~-104 ~1 ~-54 ~-104 ~3 ~-50 minecraft:cyan_stained_glass
setblock ~-104 ~1 ~-52 minecraft:iron_door[half=lower,facing=east]
setblock ~-104 ~2 ~-52 minecraft:iron_door[half=upper,facing=east]
setblock ~-103 ~3 ~-52 minecraft:red_wool
fill ~-114 ~6 ~-55 ~-104 ~6 ~-49 minecraft:dark_oak_slab
fill ~-104 ~1 ~-54 ~-104 ~5 ~-54 minecraft:dark_oak_planks
fill ~-104 ~1 ~-50 ~-104 ~5 ~-50 minecraft:dark_oak_planks
setblock ~-104 ~3 ~-53 minecraft:red_carpet
# 151 workshop style=industrial_shed context=local_front facing=south
fill ~-73 ~-3 ~-62 ~-66 ~-1 ~-55 minecraft:stone
fill ~-73 ~0 ~-62 ~-66 ~10 ~-55 minecraft:light_gray_concrete
fill ~-72 ~1 ~-61 ~-67 ~9 ~-56 minecraft:air
fill ~-72 ~4 ~-61 ~-67 ~4 ~-56 minecraft:smooth_stone
fill ~-72 ~8 ~-61 ~-67 ~8 ~-56 minecraft:smooth_stone
fill ~-71 ~2 ~-62 ~-71 ~3 ~-62 minecraft:gray_stained_glass
fill ~-71 ~2 ~-55 ~-71 ~3 ~-55 minecraft:light_gray_stained_glass
fill ~-68 ~2 ~-62 ~-68 ~3 ~-62 minecraft:gray_stained_glass
fill ~-68 ~2 ~-55 ~-68 ~3 ~-55 minecraft:light_gray_stained_glass
fill ~-73 ~2 ~-60 ~-73 ~3 ~-60 minecraft:gray_stained_glass
fill ~-66 ~2 ~-60 ~-66 ~3 ~-60 minecraft:light_gray_stained_glass
fill ~-73 ~2 ~-57 ~-73 ~3 ~-57 minecraft:gray_stained_glass
fill ~-66 ~2 ~-57 ~-66 ~3 ~-57 minecraft:light_gray_stained_glass
fill ~-71 ~6 ~-62 ~-71 ~7 ~-62 minecraft:gray_stained_glass
fill ~-71 ~6 ~-55 ~-71 ~7 ~-55 minecraft:light_gray_stained_glass
fill ~-68 ~6 ~-62 ~-68 ~7 ~-62 minecraft:gray_stained_glass
fill ~-68 ~6 ~-55 ~-68 ~7 ~-55 minecraft:light_gray_stained_glass
fill ~-73 ~6 ~-60 ~-73 ~7 ~-60 minecraft:gray_stained_glass
fill ~-66 ~6 ~-60 ~-66 ~7 ~-60 minecraft:light_gray_stained_glass
fill ~-73 ~6 ~-57 ~-73 ~7 ~-57 minecraft:gray_stained_glass
fill ~-66 ~6 ~-57 ~-66 ~7 ~-57 minecraft:light_gray_stained_glass
setblock ~-70 ~1 ~-55 minecraft:iron_door[half=lower,facing=south]
setblock ~-70 ~2 ~-55 minecraft:iron_door[half=upper,facing=south]
fill ~-71 ~1 ~-55 ~-68 ~4 ~-55 minecraft:polished_blackstone
fill ~-71 ~5 ~-55 ~-68 ~5 ~-55 minecraft:light_blue_stained_glass
fill ~-71 ~12 ~-60 ~-69 ~13 ~-58 minecraft:iron_block
fill ~-73 ~11 ~-62 ~-66 ~11 ~-55 minecraft:smooth_stone_slab
fill ~-72 ~1 ~-55 ~-72 ~7 ~-55 doomsday_decoration:porcelainbrickwall
fill ~-68 ~1 ~-55 ~-68 ~7 ~-55 doomsday_decoration:porcelainbrickwall
# 152 medical_center style=setback_tower context=station_front facing=north
fill ~-85 ~-3 ~-45 ~-74 ~-1 ~-37 minecraft:stone
fill ~-85 ~0 ~-45 ~-74 ~10 ~-37 minecraft:bricks
fill ~-84 ~1 ~-44 ~-75 ~9 ~-38 minecraft:air
fill ~-84 ~4 ~-44 ~-75 ~4 ~-38 minecraft:smooth_stone
fill ~-84 ~8 ~-44 ~-75 ~8 ~-38 minecraft:smooth_stone
fill ~-83 ~2 ~-45 ~-83 ~3 ~-45 minecraft:gray_stained_glass
fill ~-83 ~2 ~-37 ~-83 ~3 ~-37 minecraft:light_gray_stained_glass
fill ~-80 ~2 ~-45 ~-80 ~3 ~-45 minecraft:gray_stained_glass
fill ~-80 ~2 ~-37 ~-80 ~3 ~-37 minecraft:light_gray_stained_glass
fill ~-77 ~2 ~-45 ~-77 ~3 ~-45 minecraft:gray_stained_glass
fill ~-77 ~2 ~-37 ~-77 ~3 ~-37 minecraft:light_gray_stained_glass
fill ~-85 ~2 ~-43 ~-85 ~3 ~-43 minecraft:gray_stained_glass
fill ~-74 ~2 ~-43 ~-74 ~3 ~-43 minecraft:light_gray_stained_glass
fill ~-85 ~2 ~-40 ~-85 ~3 ~-40 minecraft:gray_stained_glass
fill ~-74 ~2 ~-40 ~-74 ~3 ~-40 minecraft:light_gray_stained_glass
fill ~-83 ~6 ~-45 ~-83 ~7 ~-45 minecraft:gray_stained_glass
fill ~-83 ~6 ~-37 ~-83 ~7 ~-37 minecraft:light_gray_stained_glass
fill ~-80 ~6 ~-45 ~-80 ~7 ~-45 minecraft:gray_stained_glass
fill ~-80 ~6 ~-37 ~-80 ~7 ~-37 minecraft:light_gray_stained_glass
fill ~-77 ~6 ~-45 ~-77 ~7 ~-45 minecraft:gray_stained_glass
fill ~-77 ~6 ~-37 ~-77 ~7 ~-37 minecraft:light_gray_stained_glass
fill ~-85 ~6 ~-43 ~-85 ~7 ~-43 minecraft:gray_stained_glass
fill ~-74 ~6 ~-43 ~-74 ~7 ~-43 minecraft:light_gray_stained_glass
fill ~-85 ~6 ~-40 ~-85 ~7 ~-40 minecraft:gray_stained_glass
fill ~-74 ~6 ~-40 ~-74 ~7 ~-40 minecraft:light_gray_stained_glass
setblock ~-80 ~1 ~-45 minecraft:iron_door[half=lower,facing=north]
setblock ~-80 ~2 ~-45 minecraft:iron_door[half=upper,facing=north]
fill ~-85 ~7 ~-45 ~-74 ~10 ~-37 minecraft:air
fill ~-84 ~7 ~-44 ~-75 ~10 ~-38 minecraft:bricks
fill ~-83 ~8 ~-43 ~-76 ~9 ~-39 minecraft:air
fill ~-84 ~11 ~-44 ~-75 ~11 ~-38 minecraft:deepslate_tile_slab
fill ~-84 ~1 ~-45 ~-84 ~7 ~-45 doomsday_decoration:hollowbrick
fill ~-80 ~1 ~-45 ~-80 ~7 ~-45 doomsday_decoration:hollowbrick
fill ~-76 ~1 ~-45 ~-76 ~7 ~-45 doomsday_decoration:hollowbrick
