# Buildings 57..64
# 057 shop_house style=arcade_shop context=collector_front facing=west
fill ~67 ~-3 ~-38 ~77 ~-1 ~-30 minecraft:stone
fill ~67 ~0 ~-38 ~77 ~12 ~-30 minecraft:smooth_sandstone
fill ~68 ~1 ~-37 ~76 ~11 ~-31 minecraft:air
fill ~68 ~4 ~-37 ~76 ~4 ~-31 minecraft:smooth_stone
fill ~68 ~8 ~-37 ~76 ~8 ~-31 minecraft:smooth_stone
fill ~69 ~2 ~-38 ~69 ~3 ~-38 minecraft:gray_stained_glass
fill ~69 ~2 ~-30 ~69 ~3 ~-30 minecraft:light_gray_stained_glass
fill ~72 ~2 ~-38 ~72 ~3 ~-38 minecraft:gray_stained_glass
fill ~72 ~2 ~-30 ~72 ~3 ~-30 minecraft:light_gray_stained_glass
fill ~75 ~2 ~-38 ~75 ~3 ~-38 minecraft:gray_stained_glass
fill ~75 ~2 ~-30 ~75 ~3 ~-30 minecraft:light_gray_stained_glass
fill ~67 ~2 ~-36 ~67 ~3 ~-36 minecraft:gray_stained_glass
fill ~77 ~2 ~-36 ~77 ~3 ~-36 minecraft:light_gray_stained_glass
fill ~67 ~2 ~-33 ~67 ~3 ~-33 minecraft:gray_stained_glass
fill ~77 ~2 ~-33 ~77 ~3 ~-33 minecraft:light_gray_stained_glass
fill ~69 ~6 ~-38 ~69 ~7 ~-38 minecraft:gray_stained_glass
fill ~69 ~6 ~-30 ~69 ~7 ~-30 minecraft:light_gray_stained_glass
fill ~72 ~6 ~-38 ~72 ~7 ~-38 minecraft:gray_stained_glass
fill ~72 ~6 ~-30 ~72 ~7 ~-30 minecraft:light_gray_stained_glass
fill ~75 ~6 ~-38 ~75 ~7 ~-38 minecraft:gray_stained_glass
fill ~75 ~6 ~-30 ~75 ~7 ~-30 minecraft:light_gray_stained_glass
fill ~67 ~6 ~-36 ~67 ~7 ~-36 minecraft:gray_stained_glass
fill ~77 ~6 ~-36 ~77 ~7 ~-36 minecraft:light_gray_stained_glass
fill ~67 ~6 ~-33 ~67 ~7 ~-33 minecraft:gray_stained_glass
fill ~77 ~6 ~-33 ~77 ~7 ~-33 minecraft:light_gray_stained_glass
fill ~69 ~10 ~-38 ~69 ~11 ~-38 minecraft:gray_stained_glass
fill ~69 ~10 ~-30 ~69 ~11 ~-30 minecraft:light_gray_stained_glass
fill ~72 ~10 ~-38 ~72 ~11 ~-38 minecraft:gray_stained_glass
fill ~72 ~10 ~-30 ~72 ~11 ~-30 minecraft:light_gray_stained_glass
fill ~75 ~10 ~-38 ~75 ~11 ~-38 minecraft:gray_stained_glass
fill ~75 ~10 ~-30 ~75 ~11 ~-30 minecraft:light_gray_stained_glass
fill ~67 ~10 ~-36 ~67 ~11 ~-36 minecraft:gray_stained_glass
fill ~77 ~10 ~-36 ~77 ~11 ~-36 minecraft:light_gray_stained_glass
fill ~67 ~10 ~-33 ~67 ~11 ~-33 minecraft:gray_stained_glass
fill ~77 ~10 ~-33 ~77 ~11 ~-33 minecraft:light_gray_stained_glass
setblock ~67 ~1 ~-34 minecraft:iron_door[half=lower,facing=west]
setblock ~67 ~2 ~-34 minecraft:iron_door[half=upper,facing=west]
fill ~67 ~1 ~-37 ~67 ~3 ~-31 minecraft:cyan_stained_glass
setblock ~67 ~1 ~-34 minecraft:iron_door[half=lower,facing=west]
setblock ~67 ~2 ~-34 minecraft:iron_door[half=upper,facing=west]
setblock ~66 ~3 ~-34 minecraft:red_wool
fill ~67 ~4 ~-37 ~67 ~4 ~-31 minecraft:brown_terracotta
fill ~67 ~13 ~-38 ~77 ~13 ~-30 minecraft:stone_brick_slab
fill ~69 ~14 ~-36 ~71 ~15 ~-34 minecraft:light_gray_concrete
setblock ~72 ~14 ~-35 minecraft:lightning_rod
# 058 mixed_use style=mixed_facade context=arterial_front facing=north
fill ~16 ~-3 ~-6 ~24 ~-1 ~2 minecraft:stone
fill ~16 ~0 ~-6 ~24 ~16 ~2 minecraft:bricks
fill ~17 ~1 ~-5 ~23 ~15 ~1 minecraft:air
fill ~17 ~4 ~-5 ~23 ~4 ~1 minecraft:smooth_stone
fill ~17 ~8 ~-5 ~23 ~8 ~1 minecraft:smooth_stone
fill ~17 ~12 ~-5 ~23 ~12 ~1 minecraft:smooth_stone
fill ~18 ~2 ~-6 ~18 ~3 ~-6 minecraft:gray_stained_glass
fill ~18 ~2 ~2 ~18 ~3 ~2 minecraft:light_gray_stained_glass
fill ~21 ~2 ~-6 ~21 ~3 ~-6 minecraft:gray_stained_glass
fill ~21 ~2 ~2 ~21 ~3 ~2 minecraft:light_gray_stained_glass
fill ~16 ~2 ~-4 ~16 ~3 ~-4 minecraft:gray_stained_glass
fill ~24 ~2 ~-4 ~24 ~3 ~-4 minecraft:light_gray_stained_glass
fill ~16 ~2 ~-1 ~16 ~3 ~-1 minecraft:gray_stained_glass
fill ~24 ~2 ~-1 ~24 ~3 ~-1 minecraft:light_gray_stained_glass
fill ~18 ~6 ~-6 ~18 ~7 ~-6 minecraft:gray_stained_glass
fill ~18 ~6 ~2 ~18 ~7 ~2 minecraft:light_gray_stained_glass
fill ~21 ~6 ~-6 ~21 ~7 ~-6 minecraft:gray_stained_glass
fill ~21 ~6 ~2 ~21 ~7 ~2 minecraft:light_gray_stained_glass
fill ~16 ~6 ~-4 ~16 ~7 ~-4 minecraft:gray_stained_glass
fill ~24 ~6 ~-4 ~24 ~7 ~-4 minecraft:light_gray_stained_glass
fill ~16 ~6 ~-1 ~16 ~7 ~-1 minecraft:gray_stained_glass
fill ~24 ~6 ~-1 ~24 ~7 ~-1 minecraft:light_gray_stained_glass
fill ~18 ~10 ~-6 ~18 ~11 ~-6 minecraft:gray_stained_glass
fill ~18 ~10 ~2 ~18 ~11 ~2 minecraft:light_gray_stained_glass
fill ~21 ~10 ~-6 ~21 ~11 ~-6 minecraft:gray_stained_glass
fill ~21 ~10 ~2 ~21 ~11 ~2 minecraft:light_gray_stained_glass
fill ~16 ~10 ~-4 ~16 ~11 ~-4 minecraft:gray_stained_glass
fill ~24 ~10 ~-4 ~24 ~11 ~-4 minecraft:light_gray_stained_glass
fill ~16 ~10 ~-1 ~16 ~11 ~-1 minecraft:gray_stained_glass
fill ~24 ~10 ~-1 ~24 ~11 ~-1 minecraft:light_gray_stained_glass
fill ~18 ~14 ~-6 ~18 ~15 ~-6 minecraft:gray_stained_glass
fill ~18 ~14 ~2 ~18 ~15 ~2 minecraft:light_gray_stained_glass
fill ~21 ~14 ~-6 ~21 ~15 ~-6 minecraft:gray_stained_glass
fill ~21 ~14 ~2 ~21 ~15 ~2 minecraft:light_gray_stained_glass
fill ~16 ~14 ~-4 ~16 ~15 ~-4 minecraft:gray_stained_glass
fill ~24 ~14 ~-4 ~24 ~15 ~-4 minecraft:light_gray_stained_glass
fill ~16 ~14 ~-1 ~16 ~15 ~-1 minecraft:gray_stained_glass
fill ~24 ~14 ~-1 ~24 ~15 ~-1 minecraft:light_gray_stained_glass
setblock ~20 ~1 ~-6 minecraft:iron_door[half=lower,facing=north]
setblock ~20 ~2 ~-6 minecraft:iron_door[half=upper,facing=north]
fill ~16 ~17 ~-6 ~24 ~17 ~2 minecraft:deepslate_tile_slab
# 059 mixed_use style=balcony_block context=arterial_front facing=east
fill ~-18 ~-3 ~11 ~-9 ~-1 ~20 minecraft:stone
fill ~-18 ~0 ~11 ~-9 ~24 ~20 minecraft:bricks
fill ~-17 ~1 ~12 ~-10 ~23 ~19 minecraft:air
fill ~-17 ~4 ~12 ~-10 ~4 ~19 minecraft:smooth_stone
fill ~-17 ~8 ~12 ~-10 ~8 ~19 minecraft:smooth_stone
fill ~-17 ~12 ~12 ~-10 ~12 ~19 minecraft:smooth_stone
fill ~-17 ~16 ~12 ~-10 ~16 ~19 minecraft:smooth_stone
fill ~-17 ~20 ~12 ~-10 ~20 ~19 minecraft:smooth_stone
fill ~-16 ~2 ~11 ~-16 ~3 ~11 minecraft:gray_stained_glass
fill ~-16 ~2 ~20 ~-16 ~3 ~20 minecraft:light_gray_stained_glass
fill ~-13 ~2 ~11 ~-13 ~3 ~11 minecraft:gray_stained_glass
fill ~-13 ~2 ~20 ~-13 ~3 ~20 minecraft:light_gray_stained_glass
fill ~-18 ~2 ~13 ~-18 ~3 ~13 minecraft:gray_stained_glass
fill ~-9 ~2 ~13 ~-9 ~3 ~13 minecraft:light_gray_stained_glass
fill ~-18 ~2 ~16 ~-18 ~3 ~16 minecraft:gray_stained_glass
fill ~-9 ~2 ~16 ~-9 ~3 ~16 minecraft:light_gray_stained_glass
fill ~-16 ~6 ~11 ~-16 ~7 ~11 minecraft:gray_stained_glass
fill ~-16 ~6 ~20 ~-16 ~7 ~20 minecraft:light_gray_stained_glass
fill ~-13 ~6 ~11 ~-13 ~7 ~11 minecraft:gray_stained_glass
fill ~-13 ~6 ~20 ~-13 ~7 ~20 minecraft:light_gray_stained_glass
fill ~-18 ~6 ~13 ~-18 ~7 ~13 minecraft:gray_stained_glass
fill ~-9 ~6 ~13 ~-9 ~7 ~13 minecraft:light_gray_stained_glass
fill ~-18 ~6 ~16 ~-18 ~7 ~16 minecraft:gray_stained_glass
fill ~-9 ~6 ~16 ~-9 ~7 ~16 minecraft:light_gray_stained_glass
fill ~-16 ~10 ~11 ~-16 ~11 ~11 minecraft:gray_stained_glass
fill ~-16 ~10 ~20 ~-16 ~11 ~20 minecraft:light_gray_stained_glass
fill ~-13 ~10 ~11 ~-13 ~11 ~11 minecraft:gray_stained_glass
fill ~-13 ~10 ~20 ~-13 ~11 ~20 minecraft:light_gray_stained_glass
fill ~-18 ~10 ~13 ~-18 ~11 ~13 minecraft:gray_stained_glass
fill ~-9 ~10 ~13 ~-9 ~11 ~13 minecraft:light_gray_stained_glass
fill ~-18 ~10 ~16 ~-18 ~11 ~16 minecraft:gray_stained_glass
fill ~-9 ~10 ~16 ~-9 ~11 ~16 minecraft:light_gray_stained_glass
fill ~-16 ~14 ~11 ~-16 ~15 ~11 minecraft:gray_stained_glass
fill ~-16 ~14 ~20 ~-16 ~15 ~20 minecraft:light_gray_stained_glass
fill ~-13 ~14 ~11 ~-13 ~15 ~11 minecraft:gray_stained_glass
fill ~-13 ~14 ~20 ~-13 ~15 ~20 minecraft:light_gray_stained_glass
fill ~-18 ~14 ~13 ~-18 ~15 ~13 minecraft:gray_stained_glass
fill ~-9 ~14 ~13 ~-9 ~15 ~13 minecraft:light_gray_stained_glass
fill ~-18 ~14 ~16 ~-18 ~15 ~16 minecraft:gray_stained_glass
fill ~-9 ~14 ~16 ~-9 ~15 ~16 minecraft:light_gray_stained_glass
fill ~-16 ~18 ~11 ~-16 ~19 ~11 minecraft:gray_stained_glass
fill ~-16 ~18 ~20 ~-16 ~19 ~20 minecraft:light_gray_stained_glass
fill ~-13 ~18 ~11 ~-13 ~19 ~11 minecraft:gray_stained_glass
fill ~-13 ~18 ~20 ~-13 ~19 ~20 minecraft:light_gray_stained_glass
fill ~-18 ~18 ~13 ~-18 ~19 ~13 minecraft:gray_stained_glass
fill ~-9 ~18 ~13 ~-9 ~19 ~13 minecraft:light_gray_stained_glass
fill ~-18 ~18 ~16 ~-18 ~19 ~16 minecraft:gray_stained_glass
fill ~-9 ~18 ~16 ~-9 ~19 ~16 minecraft:light_gray_stained_glass
fill ~-16 ~22 ~11 ~-16 ~23 ~11 minecraft:gray_stained_glass
fill ~-16 ~22 ~20 ~-16 ~23 ~20 minecraft:light_gray_stained_glass
fill ~-13 ~22 ~11 ~-13 ~23 ~11 minecraft:gray_stained_glass
fill ~-13 ~22 ~20 ~-13 ~23 ~20 minecraft:light_gray_stained_glass
fill ~-18 ~22 ~13 ~-18 ~23 ~13 minecraft:gray_stained_glass
fill ~-9 ~22 ~13 ~-9 ~23 ~13 minecraft:light_gray_stained_glass
fill ~-18 ~22 ~16 ~-18 ~23 ~16 minecraft:gray_stained_glass
fill ~-9 ~22 ~16 ~-9 ~23 ~16 minecraft:light_gray_stained_glass
setblock ~-9 ~1 ~15 minecraft:iron_door[half=lower,facing=east]
setblock ~-9 ~2 ~15 minecraft:iron_door[half=upper,facing=east]
fill ~-8 ~4 ~13 ~-8 ~4 ~18 minecraft:smooth_stone_slab
fill ~-8 ~8 ~13 ~-8 ~8 ~18 minecraft:smooth_stone_slab
fill ~-8 ~12 ~13 ~-8 ~12 ~18 minecraft:smooth_stone_slab
fill ~-8 ~16 ~13 ~-8 ~16 ~18 minecraft:smooth_stone_slab
fill ~-8 ~20 ~13 ~-8 ~20 ~18 minecraft:smooth_stone_slab
fill ~-18 ~25 ~11 ~-9 ~25 ~20 minecraft:deepslate_tile_slab
# 060 detached_house style=japanese_house context=back_block facing=north
fill ~-99 ~-3 ~-63 ~-91 ~-1 ~-50 minecraft:stone
fill ~-99 ~0 ~-63 ~-91 ~9 ~-50 minecraft:calcite
fill ~-98 ~1 ~-62 ~-92 ~8 ~-51 minecraft:air
fill ~-98 ~4 ~-62 ~-92 ~4 ~-51 minecraft:smooth_stone
fill ~-98 ~8 ~-62 ~-92 ~8 ~-51 minecraft:smooth_stone
fill ~-97 ~2 ~-63 ~-97 ~3 ~-63 minecraft:gray_stained_glass
fill ~-97 ~2 ~-50 ~-97 ~3 ~-50 minecraft:light_gray_stained_glass
fill ~-94 ~2 ~-63 ~-94 ~3 ~-63 minecraft:gray_stained_glass
fill ~-94 ~2 ~-50 ~-94 ~3 ~-50 minecraft:light_gray_stained_glass
fill ~-99 ~2 ~-61 ~-99 ~3 ~-61 minecraft:gray_stained_glass
fill ~-91 ~2 ~-61 ~-91 ~3 ~-61 minecraft:light_gray_stained_glass
fill ~-99 ~2 ~-58 ~-99 ~3 ~-58 minecraft:gray_stained_glass
fill ~-91 ~2 ~-58 ~-91 ~3 ~-58 minecraft:light_gray_stained_glass
fill ~-99 ~2 ~-55 ~-99 ~3 ~-55 minecraft:gray_stained_glass
fill ~-91 ~2 ~-55 ~-91 ~3 ~-55 minecraft:light_gray_stained_glass
fill ~-99 ~2 ~-52 ~-99 ~3 ~-52 minecraft:gray_stained_glass
fill ~-91 ~2 ~-52 ~-91 ~3 ~-52 minecraft:light_gray_stained_glass
fill ~-97 ~6 ~-63 ~-97 ~7 ~-63 minecraft:gray_stained_glass
fill ~-97 ~6 ~-50 ~-97 ~7 ~-50 minecraft:light_gray_stained_glass
fill ~-94 ~6 ~-63 ~-94 ~7 ~-63 minecraft:gray_stained_glass
fill ~-94 ~6 ~-50 ~-94 ~7 ~-50 minecraft:light_gray_stained_glass
fill ~-99 ~6 ~-61 ~-99 ~7 ~-61 minecraft:gray_stained_glass
fill ~-91 ~6 ~-61 ~-91 ~7 ~-61 minecraft:light_gray_stained_glass
fill ~-99 ~6 ~-58 ~-99 ~7 ~-58 minecraft:gray_stained_glass
fill ~-91 ~6 ~-58 ~-91 ~7 ~-58 minecraft:light_gray_stained_glass
fill ~-99 ~6 ~-55 ~-99 ~7 ~-55 minecraft:gray_stained_glass
fill ~-91 ~6 ~-55 ~-91 ~7 ~-55 minecraft:light_gray_stained_glass
fill ~-99 ~6 ~-52 ~-99 ~7 ~-52 minecraft:gray_stained_glass
fill ~-91 ~6 ~-52 ~-91 ~7 ~-52 minecraft:light_gray_stained_glass
setblock ~-95 ~1 ~-63 minecraft:iron_door[half=lower,facing=north]
setblock ~-95 ~2 ~-63 minecraft:iron_door[half=upper,facing=north]
fill ~-99 ~10 ~-63 ~-91 ~10 ~-50 minecraft:stone_brick_slab
fill ~-98 ~11 ~-62 ~-92 ~11 ~-51 minecraft:stone_brick_slab
setblock ~-95 ~3 ~-64 minecraft:dark_oak_slab[type=top]
fill ~-97 ~11 ~-61 ~-95 ~12 ~-59 minecraft:light_gray_concrete
setblock ~-94 ~11 ~-60 minecraft:lightning_rod
# 061 midrise_housing style=mixed_facade context=arterial_front facing=east
fill ~-39 ~-3 ~-44 ~-33 ~-1 ~-36 minecraft:stone
fill ~-39 ~0 ~-44 ~-33 ~16 ~-36 minecraft:bricks
fill ~-38 ~1 ~-43 ~-34 ~15 ~-37 minecraft:air
fill ~-38 ~4 ~-43 ~-34 ~4 ~-37 minecraft:smooth_stone
fill ~-38 ~8 ~-43 ~-34 ~8 ~-37 minecraft:smooth_stone
fill ~-38 ~12 ~-43 ~-34 ~12 ~-37 minecraft:smooth_stone
fill ~-37 ~2 ~-44 ~-37 ~3 ~-44 minecraft:gray_stained_glass
fill ~-37 ~2 ~-36 ~-37 ~3 ~-36 minecraft:light_gray_stained_glass
fill ~-39 ~2 ~-42 ~-39 ~3 ~-42 minecraft:gray_stained_glass
fill ~-33 ~2 ~-42 ~-33 ~3 ~-42 minecraft:light_gray_stained_glass
fill ~-39 ~2 ~-39 ~-39 ~3 ~-39 minecraft:gray_stained_glass
fill ~-33 ~2 ~-39 ~-33 ~3 ~-39 minecraft:light_gray_stained_glass
fill ~-37 ~6 ~-44 ~-37 ~7 ~-44 minecraft:gray_stained_glass
fill ~-37 ~6 ~-36 ~-37 ~7 ~-36 minecraft:light_gray_stained_glass
fill ~-39 ~6 ~-42 ~-39 ~7 ~-42 minecraft:gray_stained_glass
fill ~-33 ~6 ~-42 ~-33 ~7 ~-42 minecraft:light_gray_stained_glass
fill ~-39 ~6 ~-39 ~-39 ~7 ~-39 minecraft:gray_stained_glass
fill ~-33 ~6 ~-39 ~-33 ~7 ~-39 minecraft:light_gray_stained_glass
fill ~-37 ~10 ~-44 ~-37 ~11 ~-44 minecraft:gray_stained_glass
fill ~-37 ~10 ~-36 ~-37 ~11 ~-36 minecraft:light_gray_stained_glass
fill ~-39 ~10 ~-42 ~-39 ~11 ~-42 minecraft:gray_stained_glass
fill ~-33 ~10 ~-42 ~-33 ~11 ~-42 minecraft:light_gray_stained_glass
fill ~-39 ~10 ~-39 ~-39 ~11 ~-39 minecraft:gray_stained_glass
fill ~-33 ~10 ~-39 ~-33 ~11 ~-39 minecraft:light_gray_stained_glass
fill ~-37 ~14 ~-44 ~-37 ~15 ~-44 minecraft:gray_stained_glass
fill ~-37 ~14 ~-36 ~-37 ~15 ~-36 minecraft:light_gray_stained_glass
fill ~-39 ~14 ~-42 ~-39 ~15 ~-42 minecraft:gray_stained_glass
fill ~-33 ~14 ~-42 ~-33 ~15 ~-42 minecraft:light_gray_stained_glass
fill ~-39 ~14 ~-39 ~-39 ~15 ~-39 minecraft:gray_stained_glass
fill ~-33 ~14 ~-39 ~-33 ~15 ~-39 minecraft:light_gray_stained_glass
setblock ~-33 ~1 ~-40 minecraft:iron_door[half=lower,facing=east]
setblock ~-33 ~2 ~-40 minecraft:iron_door[half=upper,facing=east]
fill ~-39 ~17 ~-44 ~-33 ~17 ~-36 minecraft:deepslate_tile_slab
# 062 detached_house style=rowhouse context=local_front facing=east
fill ~-69 ~-3 ~25 ~-61 ~-1 ~36 minecraft:stone
fill ~-69 ~0 ~25 ~-61 ~16 ~36 minecraft:light_gray_concrete
fill ~-68 ~1 ~26 ~-62 ~15 ~35 minecraft:air
fill ~-68 ~4 ~26 ~-62 ~4 ~35 minecraft:smooth_stone
fill ~-68 ~8 ~26 ~-62 ~8 ~35 minecraft:smooth_stone
fill ~-68 ~12 ~26 ~-62 ~12 ~35 minecraft:smooth_stone
fill ~-67 ~2 ~25 ~-67 ~3 ~25 minecraft:gray_stained_glass
fill ~-67 ~2 ~36 ~-67 ~3 ~36 minecraft:light_gray_stained_glass
fill ~-64 ~2 ~25 ~-64 ~3 ~25 minecraft:gray_stained_glass
fill ~-64 ~2 ~36 ~-64 ~3 ~36 minecraft:light_gray_stained_glass
fill ~-69 ~2 ~27 ~-69 ~3 ~27 minecraft:gray_stained_glass
fill ~-61 ~2 ~27 ~-61 ~3 ~27 minecraft:light_gray_stained_glass
fill ~-69 ~2 ~30 ~-69 ~3 ~30 minecraft:gray_stained_glass
fill ~-61 ~2 ~30 ~-61 ~3 ~30 minecraft:light_gray_stained_glass
fill ~-69 ~2 ~33 ~-69 ~3 ~33 minecraft:gray_stained_glass
fill ~-61 ~2 ~33 ~-61 ~3 ~33 minecraft:light_gray_stained_glass
fill ~-67 ~6 ~25 ~-67 ~7 ~25 minecraft:gray_stained_glass
fill ~-67 ~6 ~36 ~-67 ~7 ~36 minecraft:light_gray_stained_glass
fill ~-64 ~6 ~25 ~-64 ~7 ~25 minecraft:gray_stained_glass
fill ~-64 ~6 ~36 ~-64 ~7 ~36 minecraft:light_gray_stained_glass
fill ~-69 ~6 ~27 ~-69 ~7 ~27 minecraft:gray_stained_glass
fill ~-61 ~6 ~27 ~-61 ~7 ~27 minecraft:light_gray_stained_glass
fill ~-69 ~6 ~30 ~-69 ~7 ~30 minecraft:gray_stained_glass
fill ~-61 ~6 ~30 ~-61 ~7 ~30 minecraft:light_gray_stained_glass
fill ~-69 ~6 ~33 ~-69 ~7 ~33 minecraft:gray_stained_glass
fill ~-61 ~6 ~33 ~-61 ~7 ~33 minecraft:light_gray_stained_glass
fill ~-67 ~10 ~25 ~-67 ~11 ~25 minecraft:gray_stained_glass
fill ~-67 ~10 ~36 ~-67 ~11 ~36 minecraft:light_gray_stained_glass
fill ~-64 ~10 ~25 ~-64 ~11 ~25 minecraft:gray_stained_glass
fill ~-64 ~10 ~36 ~-64 ~11 ~36 minecraft:light_gray_stained_glass
fill ~-69 ~10 ~27 ~-69 ~11 ~27 minecraft:gray_stained_glass
fill ~-61 ~10 ~27 ~-61 ~11 ~27 minecraft:light_gray_stained_glass
fill ~-69 ~10 ~30 ~-69 ~11 ~30 minecraft:gray_stained_glass
fill ~-61 ~10 ~30 ~-61 ~11 ~30 minecraft:light_gray_stained_glass
fill ~-69 ~10 ~33 ~-69 ~11 ~33 minecraft:gray_stained_glass
fill ~-61 ~10 ~33 ~-61 ~11 ~33 minecraft:light_gray_stained_glass
fill ~-67 ~14 ~25 ~-67 ~15 ~25 minecraft:gray_stained_glass
fill ~-67 ~14 ~36 ~-67 ~15 ~36 minecraft:light_gray_stained_glass
fill ~-64 ~14 ~25 ~-64 ~15 ~25 minecraft:gray_stained_glass
fill ~-64 ~14 ~36 ~-64 ~15 ~36 minecraft:light_gray_stained_glass
fill ~-69 ~14 ~27 ~-69 ~15 ~27 minecraft:gray_stained_glass
fill ~-61 ~14 ~27 ~-61 ~15 ~27 minecraft:light_gray_stained_glass
fill ~-69 ~14 ~30 ~-69 ~15 ~30 minecraft:gray_stained_glass
fill ~-61 ~14 ~30 ~-61 ~15 ~30 minecraft:light_gray_stained_glass
fill ~-69 ~14 ~33 ~-69 ~15 ~33 minecraft:gray_stained_glass
fill ~-61 ~14 ~33 ~-61 ~15 ~33 minecraft:light_gray_stained_glass
setblock ~-61 ~1 ~30 minecraft:iron_door[half=lower,facing=east]
setblock ~-61 ~2 ~30 minecraft:iron_door[half=upper,facing=east]
fill ~-69 ~17 ~25 ~-61 ~17 ~36 minecraft:smooth_stone_slab
fill ~-68 ~18 ~26 ~-62 ~18 ~35 minecraft:smooth_stone_slab
setblock ~-60 ~3 ~30 minecraft:dark_oak_slab[type=top]
# 063 large_retail style=arcade_shop context=arterial_front facing=east
fill ~-6 ~-3 ~46 ~7 ~-1 ~59 minecraft:stone
fill ~-6 ~0 ~46 ~7 ~24 ~59 minecraft:bricks
fill ~-5 ~1 ~47 ~6 ~23 ~58 minecraft:air
fill ~-5 ~4 ~47 ~6 ~4 ~58 minecraft:smooth_stone
fill ~-5 ~8 ~47 ~6 ~8 ~58 minecraft:smooth_stone
fill ~-5 ~12 ~47 ~6 ~12 ~58 minecraft:smooth_stone
fill ~-5 ~16 ~47 ~6 ~16 ~58 minecraft:smooth_stone
fill ~-5 ~20 ~47 ~6 ~20 ~58 minecraft:smooth_stone
fill ~-4 ~2 ~46 ~-4 ~3 ~46 minecraft:gray_stained_glass
fill ~-4 ~2 ~59 ~-4 ~3 ~59 minecraft:light_gray_stained_glass
fill ~-1 ~2 ~46 ~-1 ~3 ~46 minecraft:gray_stained_glass
fill ~-1 ~2 ~59 ~-1 ~3 ~59 minecraft:light_gray_stained_glass
fill ~2 ~2 ~46 ~2 ~3 ~46 minecraft:gray_stained_glass
fill ~2 ~2 ~59 ~2 ~3 ~59 minecraft:light_gray_stained_glass
fill ~5 ~2 ~46 ~5 ~3 ~46 minecraft:gray_stained_glass
fill ~5 ~2 ~59 ~5 ~3 ~59 minecraft:light_gray_stained_glass
fill ~-6 ~2 ~48 ~-6 ~3 ~48 minecraft:gray_stained_glass
fill ~7 ~2 ~48 ~7 ~3 ~48 minecraft:light_gray_stained_glass
fill ~-6 ~2 ~51 ~-6 ~3 ~51 minecraft:gray_stained_glass
fill ~7 ~2 ~51 ~7 ~3 ~51 minecraft:light_gray_stained_glass
fill ~-6 ~2 ~54 ~-6 ~3 ~54 minecraft:gray_stained_glass
fill ~7 ~2 ~54 ~7 ~3 ~54 minecraft:light_gray_stained_glass
fill ~-6 ~2 ~57 ~-6 ~3 ~57 minecraft:gray_stained_glass
fill ~7 ~2 ~57 ~7 ~3 ~57 minecraft:light_gray_stained_glass
fill ~-4 ~6 ~46 ~-4 ~7 ~46 minecraft:gray_stained_glass
fill ~-4 ~6 ~59 ~-4 ~7 ~59 minecraft:light_gray_stained_glass
fill ~-1 ~6 ~46 ~-1 ~7 ~46 minecraft:gray_stained_glass
fill ~-1 ~6 ~59 ~-1 ~7 ~59 minecraft:light_gray_stained_glass
fill ~2 ~6 ~46 ~2 ~7 ~46 minecraft:gray_stained_glass
fill ~2 ~6 ~59 ~2 ~7 ~59 minecraft:light_gray_stained_glass
fill ~5 ~6 ~46 ~5 ~7 ~46 minecraft:gray_stained_glass
fill ~5 ~6 ~59 ~5 ~7 ~59 minecraft:light_gray_stained_glass
fill ~-6 ~6 ~48 ~-6 ~7 ~48 minecraft:gray_stained_glass
fill ~7 ~6 ~48 ~7 ~7 ~48 minecraft:light_gray_stained_glass
fill ~-6 ~6 ~51 ~-6 ~7 ~51 minecraft:gray_stained_glass
fill ~7 ~6 ~51 ~7 ~7 ~51 minecraft:light_gray_stained_glass
fill ~-6 ~6 ~54 ~-6 ~7 ~54 minecraft:gray_stained_glass
fill ~7 ~6 ~54 ~7 ~7 ~54 minecraft:light_gray_stained_glass
fill ~-6 ~6 ~57 ~-6 ~7 ~57 minecraft:gray_stained_glass
fill ~7 ~6 ~57 ~7 ~7 ~57 minecraft:light_gray_stained_glass
fill ~-4 ~10 ~46 ~-4 ~11 ~46 minecraft:gray_stained_glass
fill ~-4 ~10 ~59 ~-4 ~11 ~59 minecraft:light_gray_stained_glass
fill ~-1 ~10 ~46 ~-1 ~11 ~46 minecraft:gray_stained_glass
fill ~-1 ~10 ~59 ~-1 ~11 ~59 minecraft:light_gray_stained_glass
fill ~2 ~10 ~46 ~2 ~11 ~46 minecraft:gray_stained_glass
fill ~2 ~10 ~59 ~2 ~11 ~59 minecraft:light_gray_stained_glass
fill ~5 ~10 ~46 ~5 ~11 ~46 minecraft:gray_stained_glass
fill ~5 ~10 ~59 ~5 ~11 ~59 minecraft:light_gray_stained_glass
fill ~-6 ~10 ~48 ~-6 ~11 ~48 minecraft:gray_stained_glass
fill ~7 ~10 ~48 ~7 ~11 ~48 minecraft:light_gray_stained_glass
fill ~-6 ~10 ~51 ~-6 ~11 ~51 minecraft:gray_stained_glass
fill ~7 ~10 ~51 ~7 ~11 ~51 minecraft:light_gray_stained_glass
fill ~-6 ~10 ~54 ~-6 ~11 ~54 minecraft:gray_stained_glass
fill ~7 ~10 ~54 ~7 ~11 ~54 minecraft:light_gray_stained_glass
fill ~-6 ~10 ~57 ~-6 ~11 ~57 minecraft:gray_stained_glass
fill ~7 ~10 ~57 ~7 ~11 ~57 minecraft:light_gray_stained_glass
fill ~-4 ~14 ~46 ~-4 ~15 ~46 minecraft:gray_stained_glass
fill ~-4 ~14 ~59 ~-4 ~15 ~59 minecraft:light_gray_stained_glass
fill ~-1 ~14 ~46 ~-1 ~15 ~46 minecraft:gray_stained_glass
fill ~-1 ~14 ~59 ~-1 ~15 ~59 minecraft:light_gray_stained_glass
fill ~2 ~14 ~46 ~2 ~15 ~46 minecraft:gray_stained_glass
fill ~2 ~14 ~59 ~2 ~15 ~59 minecraft:light_gray_stained_glass
fill ~5 ~14 ~46 ~5 ~15 ~46 minecraft:gray_stained_glass
fill ~5 ~14 ~59 ~5 ~15 ~59 minecraft:light_gray_stained_glass
fill ~-6 ~14 ~48 ~-6 ~15 ~48 minecraft:gray_stained_glass
fill ~7 ~14 ~48 ~7 ~15 ~48 minecraft:light_gray_stained_glass
fill ~-6 ~14 ~51 ~-6 ~15 ~51 minecraft:gray_stained_glass
fill ~7 ~14 ~51 ~7 ~15 ~51 minecraft:light_gray_stained_glass
fill ~-6 ~14 ~54 ~-6 ~15 ~54 minecraft:gray_stained_glass
fill ~7 ~14 ~54 ~7 ~15 ~54 minecraft:light_gray_stained_glass
fill ~-6 ~14 ~57 ~-6 ~15 ~57 minecraft:gray_stained_glass
fill ~7 ~14 ~57 ~7 ~15 ~57 minecraft:light_gray_stained_glass
fill ~-4 ~18 ~46 ~-4 ~19 ~46 minecraft:gray_stained_glass
fill ~-4 ~18 ~59 ~-4 ~19 ~59 minecraft:light_gray_stained_glass
fill ~-1 ~18 ~46 ~-1 ~19 ~46 minecraft:gray_stained_glass
fill ~-1 ~18 ~59 ~-1 ~19 ~59 minecraft:light_gray_stained_glass
fill ~2 ~18 ~46 ~2 ~19 ~46 minecraft:gray_stained_glass
fill ~2 ~18 ~59 ~2 ~19 ~59 minecraft:light_gray_stained_glass
fill ~5 ~18 ~46 ~5 ~19 ~46 minecraft:gray_stained_glass
fill ~5 ~18 ~59 ~5 ~19 ~59 minecraft:light_gray_stained_glass
fill ~-6 ~18 ~48 ~-6 ~19 ~48 minecraft:gray_stained_glass
fill ~7 ~18 ~48 ~7 ~19 ~48 minecraft:light_gray_stained_glass
fill ~-6 ~18 ~51 ~-6 ~19 ~51 minecraft:gray_stained_glass
fill ~7 ~18 ~51 ~7 ~19 ~51 minecraft:light_gray_stained_glass
fill ~-6 ~18 ~54 ~-6 ~19 ~54 minecraft:gray_stained_glass
fill ~7 ~18 ~54 ~7 ~19 ~54 minecraft:light_gray_stained_glass
fill ~-6 ~18 ~57 ~-6 ~19 ~57 minecraft:gray_stained_glass
fill ~7 ~18 ~57 ~7 ~19 ~57 minecraft:light_gray_stained_glass
fill ~-4 ~22 ~46 ~-4 ~23 ~46 minecraft:gray_stained_glass
fill ~-4 ~22 ~59 ~-4 ~23 ~59 minecraft:light_gray_stained_glass
fill ~-1 ~22 ~46 ~-1 ~23 ~46 minecraft:gray_stained_glass
fill ~-1 ~22 ~59 ~-1 ~23 ~59 minecraft:light_gray_stained_glass
fill ~2 ~22 ~46 ~2 ~23 ~46 minecraft:gray_stained_glass
fill ~2 ~22 ~59 ~2 ~23 ~59 minecraft:light_gray_stained_glass
fill ~5 ~22 ~46 ~5 ~23 ~46 minecraft:gray_stained_glass
fill ~5 ~22 ~59 ~5 ~23 ~59 minecraft:light_gray_stained_glass
fill ~-6 ~22 ~48 ~-6 ~23 ~48 minecraft:gray_stained_glass
fill ~7 ~22 ~48 ~7 ~23 ~48 minecraft:light_gray_stained_glass
fill ~-6 ~22 ~51 ~-6 ~23 ~51 minecraft:gray_stained_glass
fill ~7 ~22 ~51 ~7 ~23 ~51 minecraft:light_gray_stained_glass
fill ~-6 ~22 ~54 ~-6 ~23 ~54 minecraft:gray_stained_glass
fill ~7 ~22 ~54 ~7 ~23 ~54 minecraft:light_gray_stained_glass
fill ~-6 ~22 ~57 ~-6 ~23 ~57 minecraft:gray_stained_glass
fill ~7 ~22 ~57 ~7 ~23 ~57 minecraft:light_gray_stained_glass
setblock ~7 ~1 ~51 minecraft:iron_door[half=lower,facing=east]
setblock ~7 ~2 ~51 minecraft:iron_door[half=upper,facing=east]
fill ~7 ~1 ~47 ~7 ~3 ~58 minecraft:cyan_stained_glass
setblock ~7 ~1 ~51 minecraft:iron_door[half=lower,facing=east]
setblock ~7 ~2 ~51 minecraft:iron_door[half=upper,facing=east]
setblock ~8 ~3 ~51 minecraft:red_wool
fill ~7 ~4 ~47 ~7 ~4 ~58 doomsday_decoration:redbrick
fill ~-6 ~25 ~46 ~7 ~25 ~59 minecraft:deepslate_tile_slab
fill ~-4 ~26 ~48 ~-2 ~27 ~50 minecraft:light_gray_concrete
setblock ~-1 ~26 ~49 minecraft:lightning_rod
# 064 factory style=sawtooth context=waterfront_front facing=north
fill ~86 ~-3 ~70 ~96 ~-1 ~82 minecraft:stone
fill ~86 ~0 ~70 ~96 ~10 ~82 minecraft:gray_concrete
fill ~87 ~1 ~71 ~95 ~9 ~81 minecraft:air
fill ~87 ~4 ~71 ~95 ~4 ~81 minecraft:smooth_stone
fill ~87 ~8 ~71 ~95 ~8 ~81 minecraft:smooth_stone
fill ~88 ~2 ~70 ~88 ~3 ~70 minecraft:gray_stained_glass
fill ~88 ~2 ~82 ~88 ~3 ~82 minecraft:light_gray_stained_glass
fill ~91 ~2 ~70 ~91 ~3 ~70 minecraft:gray_stained_glass
fill ~91 ~2 ~82 ~91 ~3 ~82 minecraft:light_gray_stained_glass
fill ~94 ~2 ~70 ~94 ~3 ~70 minecraft:gray_stained_glass
fill ~94 ~2 ~82 ~94 ~3 ~82 minecraft:light_gray_stained_glass
fill ~86 ~2 ~72 ~86 ~3 ~72 minecraft:gray_stained_glass
fill ~96 ~2 ~72 ~96 ~3 ~72 minecraft:light_gray_stained_glass
fill ~86 ~2 ~75 ~86 ~3 ~75 minecraft:gray_stained_glass
fill ~96 ~2 ~75 ~96 ~3 ~75 minecraft:light_gray_stained_glass
fill ~86 ~2 ~78 ~86 ~3 ~78 minecraft:gray_stained_glass
fill ~96 ~2 ~78 ~96 ~3 ~78 minecraft:light_gray_stained_glass
fill ~88 ~6 ~70 ~88 ~7 ~70 minecraft:gray_stained_glass
fill ~88 ~6 ~82 ~88 ~7 ~82 minecraft:light_gray_stained_glass
fill ~91 ~6 ~70 ~91 ~7 ~70 minecraft:gray_stained_glass
fill ~91 ~6 ~82 ~91 ~7 ~82 minecraft:light_gray_stained_glass
fill ~94 ~6 ~70 ~94 ~7 ~70 minecraft:gray_stained_glass
fill ~94 ~6 ~82 ~94 ~7 ~82 minecraft:light_gray_stained_glass
fill ~86 ~6 ~72 ~86 ~7 ~72 minecraft:gray_stained_glass
fill ~96 ~6 ~72 ~96 ~7 ~72 minecraft:light_gray_stained_glass
fill ~86 ~6 ~75 ~86 ~7 ~75 minecraft:gray_stained_glass
fill ~96 ~6 ~75 ~96 ~7 ~75 minecraft:light_gray_stained_glass
fill ~86 ~6 ~78 ~86 ~7 ~78 minecraft:gray_stained_glass
fill ~96 ~6 ~78 ~96 ~7 ~78 minecraft:light_gray_stained_glass
setblock ~91 ~1 ~70 minecraft:iron_door[half=lower,facing=north]
setblock ~91 ~2 ~70 minecraft:iron_door[half=upper,facing=north]
fill ~88 ~1 ~70 ~94 ~4 ~70 minecraft:polished_blackstone
fill ~88 ~5 ~70 ~94 ~5 ~70 minecraft:light_blue_stained_glass
fill ~88 ~12 ~72 ~90 ~13 ~74 minecraft:iron_block
fill ~86 ~11 ~70 ~96 ~11 ~82 minecraft:smooth_stone_slab
fill ~94 ~8 ~80 ~96 ~12 ~82 minecraft:air
setblock ~94 ~8 ~80 minecraft:cobweb
