setblock ~-8 ~2 ~76 minecraft:dark_oak_door[half=lower]
setblock ~-8 ~3 ~76 minecraft:dark_oak_door[half=upper]
fill ~105 ~1 ~-35 ~113 ~20 ~-22 minecraft:mud_bricks
fill ~106 ~2 ~-34 ~112 ~19 ~-23 minecraft:air
fill ~106 ~4 ~-34 ~112 ~4 ~-23 minecraft:smooth_stone
fill ~106 ~8 ~-34 ~112 ~8 ~-23 minecraft:smooth_stone
fill ~106 ~12 ~-34 ~112 ~12 ~-23 minecraft:smooth_stone
fill ~106 ~16 ~-34 ~112 ~16 ~-23 minecraft:smooth_stone
fill ~105 ~21 ~-35 ~113 ~21 ~-22 minecraft:dark_oak_planks
fill ~103 ~1 ~-33 ~104 ~20 ~-22 minecraft:mud_bricks
fill ~104 ~4 ~-32 ~103 ~4 ~-23 minecraft:smooth_stone
fill ~104 ~8 ~-32 ~103 ~8 ~-23 minecraft:smooth_stone
fill ~104 ~12 ~-32 ~103 ~12 ~-23 minecraft:smooth_stone
fill ~104 ~16 ~-32 ~103 ~16 ~-23 minecraft:smooth_stone
fill ~103 ~21 ~-33 ~104 ~21 ~-22 minecraft:dark_oak_planks
setblock ~105 ~3 ~-35 minecraft:gray_stained_glass_pane
setblock ~105 ~3 ~-22 minecraft:gray_stained_glass_pane
setblock ~108 ~3 ~-35 minecraft:gray_stained_glass_pane
setblock ~108 ~3 ~-22 minecraft:gray_stained_glass_pane
setblock ~111 ~3 ~-35 minecraft:gray_stained_glass_pane
setblock ~111 ~3 ~-22 minecraft:gray_stained_glass_pane
setblock ~103 ~3 ~-33 minecraft:gray_stained_glass_pane
setblock ~113 ~3 ~-33 minecraft:gray_stained_glass_pane
setblock ~103 ~3 ~-30 minecraft:gray_stained_glass_pane
setblock ~113 ~3 ~-30 minecraft:gray_stained_glass_pane
setblock ~103 ~3 ~-27 minecraft:gray_stained_glass_pane
setblock ~113 ~3 ~-27 minecraft:gray_stained_glass_pane
setblock ~103 ~3 ~-24 minecraft:gray_stained_glass_pane
setblock ~113 ~3 ~-24 minecraft:gray_stained_glass_pane
setblock ~105 ~7 ~-35 minecraft:gray_stained_glass_pane
setblock ~105 ~7 ~-22 minecraft:gray_stained_glass_pane
setblock ~108 ~7 ~-35 minecraft:gray_stained_glass_pane
setblock ~108 ~7 ~-22 minecraft:gray_stained_glass_pane
setblock ~111 ~7 ~-35 minecraft:gray_stained_glass_pane
setblock ~111 ~7 ~-22 minecraft:gray_stained_glass_pane
setblock ~103 ~7 ~-33 minecraft:gray_stained_glass_pane
setblock ~113 ~7 ~-33 minecraft:gray_stained_glass_pane
setblock ~103 ~7 ~-30 minecraft:gray_stained_glass_pane
setblock ~113 ~7 ~-30 minecraft:gray_stained_glass_pane
setblock ~103 ~7 ~-27 minecraft:gray_stained_glass_pane
setblock ~113 ~7 ~-27 minecraft:gray_stained_glass_pane
setblock ~103 ~7 ~-24 minecraft:gray_stained_glass_pane
setblock ~113 ~7 ~-24 minecraft:gray_stained_glass_pane
setblock ~105 ~11 ~-35 minecraft:gray_stained_glass_pane
setblock ~105 ~11 ~-22 minecraft:gray_stained_glass_pane
setblock ~108 ~11 ~-35 minecraft:gray_stained_glass_pane
setblock ~108 ~11 ~-22 minecraft:gray_stained_glass_pane
setblock ~111 ~11 ~-35 minecraft:gray_stained_glass_pane
setblock ~111 ~11 ~-22 minecraft:gray_stained_glass_pane
setblock ~103 ~11 ~-33 minecraft:gray_stained_glass_pane
setblock ~113 ~11 ~-33 minecraft:gray_stained_glass_pane
setblock ~103 ~11 ~-30 minecraft:gray_stained_glass_pane
setblock ~113 ~11 ~-30 minecraft:gray_stained_glass_pane
setblock ~103 ~11 ~-27 minecraft:gray_stained_glass_pane
setblock ~113 ~11 ~-27 minecraft:gray_stained_glass_pane
setblock ~103 ~11 ~-24 minecraft:gray_stained_glass_pane
setblock ~113 ~11 ~-24 minecraft:gray_stained_glass_pane
setblock ~105 ~15 ~-35 minecraft:gray_stained_glass_pane
setblock ~105 ~15 ~-22 minecraft:gray_stained_glass_pane
setblock ~108 ~15 ~-35 minecraft:gray_stained_glass_pane
setblock ~108 ~15 ~-22 minecraft:gray_stained_glass_pane
setblock ~111 ~15 ~-35 minecraft:gray_stained_glass_pane
setblock ~111 ~15 ~-22 minecraft:gray_stained_glass_pane
setblock ~103 ~15 ~-33 minecraft:gray_stained_glass_pane
setblock ~113 ~15 ~-33 minecraft:gray_stained_glass_pane
setblock ~103 ~15 ~-30 minecraft:gray_stained_glass_pane
setblock ~113 ~15 ~-30 minecraft:gray_stained_glass_pane
setblock ~103 ~15 ~-27 minecraft:gray_stained_glass_pane
setblock ~113 ~15 ~-27 minecraft:gray_stained_glass_pane
setblock ~103 ~15 ~-24 minecraft:gray_stained_glass_pane
setblock ~113 ~15 ~-24 minecraft:gray_stained_glass_pane
setblock ~105 ~19 ~-35 minecraft:gray_stained_glass_pane
setblock ~105 ~19 ~-22 minecraft:gray_stained_glass_pane
setblock ~108 ~19 ~-35 minecraft:gray_stained_glass_pane
setblock ~108 ~19 ~-22 minecraft:gray_stained_glass_pane
setblock ~111 ~19 ~-35 minecraft:gray_stained_glass_pane
setblock ~111 ~19 ~-22 minecraft:gray_stained_glass_pane
setblock ~103 ~19 ~-33 minecraft:gray_stained_glass_pane
setblock ~113 ~19 ~-33 minecraft:gray_stained_glass_pane
setblock ~103 ~19 ~-30 minecraft:gray_stained_glass_pane
setblock ~113 ~19 ~-30 minecraft:gray_stained_glass_pane
setblock ~103 ~19 ~-27 minecraft:gray_stained_glass_pane
setblock ~113 ~19 ~-27 minecraft:gray_stained_glass_pane
setblock ~103 ~19 ~-24 minecraft:gray_stained_glass_pane
setblock ~113 ~19 ~-24 minecraft:gray_stained_glass_pane
setblock ~108 ~2 ~-35 minecraft:dark_oak_door[half=lower]
setblock ~108 ~3 ~-35 minecraft:dark_oak_door[half=upper]
setblock ~104 ~2 ~-35 minecraft:cyan_stained_glass
setblock ~106 ~2 ~-35 minecraft:cyan_stained_glass
setblock ~108 ~2 ~-35 minecraft:cyan_stained_glass
setblock ~110 ~2 ~-35 minecraft:cyan_stained_glass
setblock ~112 ~2 ~-35 minecraft:cyan_stained_glass
fill ~28 ~1 ~-83 ~36 ~8 ~-72 minecraft:mud_bricks
fill ~29 ~2 ~-82 ~35 ~7 ~-73 minecraft:air
fill ~29 ~4 ~-82 ~35 ~4 ~-73 minecraft:smooth_stone
fill ~28 ~9 ~-83 ~36 ~9 ~-72 minecraft:dark_oak_planks
setblock ~30 ~3 ~-83 minecraft:gray_stained_glass_pane
setblock ~30 ~3 ~-72 minecraft:gray_stained_glass_pane
setblock ~33 ~3 ~-83 minecraft:gray_stained_glass_pane
setblock ~33 ~3 ~-72 minecraft:gray_stained_glass_pane
setblock ~28 ~3 ~-81 minecraft:gray_stained_glass_pane
setblock ~36 ~3 ~-81 minecraft:gray_stained_glass_pane
setblock ~28 ~3 ~-78 minecraft:gray_stained_glass_pane
setblock ~36 ~3 ~-78 minecraft:gray_stained_glass_pane
setblock ~28 ~3 ~-75 minecraft:gray_stained_glass_pane
setblock ~36 ~3 ~-75 minecraft:gray_stained_glass_pane
setblock ~30 ~7 ~-83 minecraft:gray_stained_glass_pane
setblock ~30 ~7 ~-72 minecraft:gray_stained_glass_pane
setblock ~33 ~7 ~-83 minecraft:gray_stained_glass_pane
setblock ~33 ~7 ~-72 minecraft:gray_stained_glass_pane
setblock ~28 ~7 ~-81 minecraft:gray_stained_glass_pane
setblock ~36 ~7 ~-81 minecraft:gray_stained_glass_pane
setblock ~28 ~7 ~-78 minecraft:gray_stained_glass_pane
setblock ~36 ~7 ~-78 minecraft:gray_stained_glass_pane
setblock ~28 ~7 ~-75 minecraft:gray_stained_glass_pane
setblock ~36 ~7 ~-75 minecraft:gray_stained_glass_pane
setblock ~32 ~2 ~-83 minecraft:dark_oak_door[half=lower]
setblock ~32 ~3 ~-83 minecraft:dark_oak_door[half=upper]
fill ~28 ~10 ~-83 ~36 ~10 ~-72 minecraft:deepslate_tile_slab
fill ~29 ~11 ~-82 ~35 ~11 ~-73 minecraft:deepslate_tile_slab
fill ~30 ~12 ~-81 ~34 ~12 ~-74 minecraft:deepslate_tile_slab
fill ~-123 ~1 ~76 ~-111 ~16 ~82 minecraft:bricks
fill ~-122 ~2 ~77 ~-112 ~15 ~81 minecraft:air
fill ~-122 ~4 ~77 ~-112 ~4 ~81 minecraft:smooth_stone
fill ~-122 ~8 ~77 ~-112 ~8 ~81 minecraft:smooth_stone
fill ~-122 ~12 ~77 ~-112 ~12 ~81 minecraft:smooth_stone
fill ~-123 ~17 ~76 ~-111 ~17 ~82 minecraft:polished_andesite
setblock ~-121 ~3 ~76 minecraft:gray_stained_glass_pane
setblock ~-121 ~3 ~82 minecraft:gray_stained_glass_pane
setblock ~-118 ~3 ~76 minecraft:gray_stained_glass_pane
setblock ~-118 ~3 ~82 minecraft:gray_stained_glass_pane
setblock ~-115 ~3 ~76 minecraft:gray_stained_glass_pane
setblock ~-115 ~3 ~82 minecraft:gray_stained_glass_pane
setblock ~-123 ~3 ~78 minecraft:gray_stained_glass_pane
setblock ~-111 ~3 ~78 minecraft:gray_stained_glass_pane
setblock ~-121 ~7 ~76 minecraft:gray_stained_glass_pane
setblock ~-121 ~7 ~82 minecraft:gray_stained_glass_pane
setblock ~-118 ~7 ~76 minecraft:gray_stained_glass_pane
setblock ~-118 ~7 ~82 minecraft:gray_stained_glass_pane
setblock ~-115 ~7 ~76 minecraft:gray_stained_glass_pane
setblock ~-115 ~7 ~82 minecraft:gray_stained_glass_pane
setblock ~-123 ~7 ~78 minecraft:gray_stained_glass_pane
setblock ~-111 ~7 ~78 minecraft:gray_stained_glass_pane
setblock ~-121 ~11 ~76 minecraft:gray_stained_glass_pane
setblock ~-121 ~11 ~82 minecraft:gray_stained_glass_pane
setblock ~-118 ~11 ~76 minecraft:gray_stained_glass_pane
setblock ~-118 ~11 ~82 minecraft:gray_stained_glass_pane
setblock ~-115 ~11 ~76 minecraft:gray_stained_glass_pane
setblock ~-115 ~11 ~82 minecraft:gray_stained_glass_pane
setblock ~-123 ~11 ~78 minecraft:gray_stained_glass_pane
setblock ~-111 ~11 ~78 minecraft:gray_stained_glass_pane
setblock ~-121 ~15 ~76 minecraft:gray_stained_glass_pane
setblock ~-121 ~15 ~82 minecraft:gray_stained_glass_pane
setblock ~-118 ~15 ~76 minecraft:gray_stained_glass_pane
setblock ~-118 ~15 ~82 minecraft:gray_stained_glass_pane
setblock ~-115 ~15 ~76 minecraft:gray_stained_glass_pane
setblock ~-115 ~15 ~82 minecraft:gray_stained_glass_pane
setblock ~-123 ~15 ~78 minecraft:gray_stained_glass_pane
setblock ~-111 ~15 ~78 minecraft:gray_stained_glass_pane
setblock ~-111 ~2 ~79 minecraft:dark_oak_door[half=lower]
setblock ~-111 ~3 ~79 minecraft:dark_oak_door[half=upper]
fill ~-123 ~18 ~76 ~-111 ~18 ~82 minecraft:deepslate_tile_slab
fill ~-122 ~19 ~77 ~-112 ~19 ~81 minecraft:deepslate_tile_slab
fill ~91 ~1 ~-85 ~97 ~8 ~-78 minecraft:light_gray_concrete
fill ~92 ~2 ~-84 ~96 ~7 ~-79 minecraft:air
fill ~92 ~4 ~-84 ~96 ~4 ~-79 minecraft:smooth_stone
fill ~91 ~9 ~-85 ~97 ~9 ~-78 minecraft:gray_concrete
setblock ~93 ~3 ~-85 minecraft:gray_stained_glass_pane
setblock ~93 ~3 ~-78 minecraft:gray_stained_glass_pane
setblock ~91 ~3 ~-83 minecraft:gray_stained_glass_pane
setblock ~97 ~3 ~-83 minecraft:gray_stained_glass_pane
setblock ~91 ~3 ~-80 minecraft:gray_stained_glass_pane
setblock ~97 ~3 ~-80 minecraft:gray_stained_glass_pane
setblock ~93 ~7 ~-85 minecraft:gray_stained_glass_pane
setblock ~93 ~7 ~-78 minecraft:gray_stained_glass_pane
setblock ~91 ~7 ~-83 minecraft:gray_stained_glass_pane
setblock ~97 ~7 ~-83 minecraft:gray_stained_glass_pane
setblock ~91 ~7 ~-80 minecraft:gray_stained_glass_pane
setblock ~97 ~7 ~-80 minecraft:gray_stained_glass_pane
setblock ~94 ~2 ~-85 minecraft:dark_oak_door[half=lower]
setblock ~94 ~3 ~-85 minecraft:dark_oak_door[half=upper]
setblock ~92 ~2 ~-85 minecraft:cyan_stained_glass
setblock ~94 ~2 ~-85 minecraft:cyan_stained_glass
setblock ~96 ~2 ~-85 minecraft:cyan_stained_glass
fill ~91 ~10 ~-85 ~97 ~10 ~-78 minecraft:deepslate_tile_slab
fill ~92 ~11 ~-84 ~96 ~11 ~-79 minecraft:deepslate_tile_slab
fill ~93 ~12 ~-83 ~95 ~12 ~-80 minecraft:deepslate_tile_slab
fill ~-108 ~1 ~-124 ~-99 ~16 ~-118 minecraft:white_terracotta
fill ~-107 ~2 ~-123 ~-100 ~15 ~-119 minecraft:air
fill ~-107 ~4 ~-123 ~-100 ~4 ~-119 minecraft:smooth_stone
fill ~-107 ~8 ~-123 ~-100 ~8 ~-119 minecraft:smooth_stone
fill ~-107 ~12 ~-123 ~-100 ~12 ~-119 minecraft:smooth_stone
fill ~-108 ~17 ~-124 ~-99 ~17 ~-118 minecraft:spruce_planks
setblock ~-106 ~3 ~-124 minecraft:gray_stained_glass_pane
setblock ~-106 ~3 ~-118 minecraft:gray_stained_glass_pane
setblock ~-103 ~3 ~-124 minecraft:gray_stained_glass_pane
setblock ~-103 ~3 ~-118 minecraft:gray_stained_glass_pane
setblock ~-108 ~3 ~-122 minecraft:gray_stained_glass_pane
setblock ~-99 ~3 ~-122 minecraft:gray_stained_glass_pane
setblock ~-106 ~7 ~-124 minecraft:gray_stained_glass_pane
setblock ~-106 ~7 ~-118 minecraft:gray_stained_glass_pane
setblock ~-103 ~7 ~-124 minecraft:gray_stained_glass_pane
setblock ~-103 ~7 ~-118 minecraft:gray_stained_glass_pane
setblock ~-108 ~7 ~-122 minecraft:gray_stained_glass_pane
setblock ~-99 ~7 ~-122 minecraft:gray_stained_glass_pane
setblock ~-106 ~11 ~-124 minecraft:gray_stained_glass_pane
setblock ~-106 ~11 ~-118 minecraft:gray_stained_glass_pane
setblock ~-103 ~11 ~-124 minecraft:gray_stained_glass_pane
setblock ~-103 ~11 ~-118 minecraft:gray_stained_glass_pane
setblock ~-108 ~11 ~-122 minecraft:gray_stained_glass_pane
setblock ~-99 ~11 ~-122 minecraft:gray_stained_glass_pane
setblock ~-106 ~15 ~-124 minecraft:gray_stained_glass_pane
setblock ~-106 ~15 ~-118 minecraft:gray_stained_glass_pane
setblock ~-103 ~15 ~-124 minecraft:gray_stained_glass_pane
setblock ~-103 ~15 ~-118 minecraft:gray_stained_glass_pane
setblock ~-108 ~15 ~-122 minecraft:gray_stained_glass_pane
setblock ~-99 ~15 ~-122 minecraft:gray_stained_glass_pane
setblock ~-103 ~2 ~-118 minecraft:dark_oak_door[half=lower]
setblock ~-103 ~3 ~-118 minecraft:dark_oak_door[half=upper]
fill ~-108 ~18 ~-124 ~-99 ~18 ~-118 minecraft:deepslate_tile_slab
fill ~-107 ~19 ~-123 ~-100 ~19 ~-119 minecraft:deepslate_tile_slab
fill ~-91 ~1 ~91 ~-83 ~12 ~97 minecraft:white_terracotta
fill ~-90 ~2 ~92 ~-84 ~11 ~96 minecraft:air
fill ~-90 ~4 ~92 ~-84 ~4 ~96 minecraft:smooth_stone
fill ~-90 ~8 ~92 ~-84 ~8 ~96 minecraft:smooth_stone
fill ~-91 ~13 ~91 ~-83 ~13 ~97 minecraft:spruce_planks
setblock ~-89 ~3 ~91 minecraft:gray_stained_glass_pane
setblock ~-89 ~3 ~97 minecraft:gray_stained_glass_pane
setblock ~-86 ~3 ~91 minecraft:gray_stained_glass_pane
setblock ~-86 ~3 ~97 minecraft:gray_stained_glass_pane
setblock ~-91 ~3 ~93 minecraft:gray_stained_glass_pane
setblock ~-83 ~3 ~93 minecraft:gray_stained_glass_pane
setblock ~-89 ~7 ~91 minecraft:gray_stained_glass_pane
setblock ~-89 ~7 ~97 minecraft:gray_stained_glass_pane
setblock ~-86 ~7 ~91 minecraft:gray_stained_glass_pane
setblock ~-86 ~7 ~97 minecraft:gray_stained_glass_pane
setblock ~-91 ~7 ~93 minecraft:gray_stained_glass_pane
setblock ~-83 ~7 ~93 minecraft:gray_stained_glass_pane
setblock ~-89 ~11 ~91 minecraft:gray_stained_glass_pane
setblock ~-89 ~11 ~97 minecraft:gray_stained_glass_pane
setblock ~-86 ~11 ~91 minecraft:gray_stained_glass_pane
setblock ~-86 ~11 ~97 minecraft:gray_stained_glass_pane
setblock ~-91 ~11 ~93 minecraft:gray_stained_glass_pane
setblock ~-83 ~11 ~93 minecraft:gray_stained_glass_pane
setblock ~-87 ~2 ~97 minecraft:dark_oak_door[half=lower]
setblock ~-87 ~3 ~97 minecraft:dark_oak_door[half=upper]
fill ~-53 ~1 ~110 ~-45 ~20 ~119 minecraft:mud_bricks
fill ~-52 ~2 ~111 ~-46 ~19 ~118 minecraft:air
fill ~-52 ~4 ~111 ~-46 ~4 ~118 minecraft:smooth_stone
fill ~-52 ~8 ~111 ~-46 ~8 ~118 minecraft:smooth_stone
fill ~-52 ~12 ~111 ~-46 ~12 ~118 minecraft:smooth_stone
fill ~-52 ~16 ~111 ~-46 ~16 ~118 minecraft:smooth_stone
fill ~-53 ~21 ~110 ~-45 ~21 ~119 minecraft:dark_oak_planks
fill ~-55 ~1 ~112 ~-54 ~20 ~119 minecraft:mud_bricks
fill ~-54 ~4 ~113 ~-55 ~4 ~118 minecraft:smooth_stone
fill ~-54 ~8 ~113 ~-55 ~8 ~118 minecraft:smooth_stone
fill ~-54 ~12 ~113 ~-55 ~12 ~118 minecraft:smooth_stone
fill ~-54 ~16 ~113 ~-55 ~16 ~118 minecraft:smooth_stone
fill ~-55 ~21 ~112 ~-54 ~21 ~119 minecraft:dark_oak_planks
setblock ~-53 ~3 ~110 minecraft:gray_stained_glass_pane
setblock ~-53 ~3 ~119 minecraft:gray_stained_glass_pane
setblock ~-50 ~3 ~110 minecraft:gray_stained_glass_pane
setblock ~-50 ~3 ~119 minecraft:gray_stained_glass_pane
setblock ~-47 ~3 ~110 minecraft:gray_stained_glass_pane
setblock ~-47 ~3 ~119 minecraft:gray_stained_glass_pane
setblock ~-55 ~3 ~112 minecraft:gray_stained_glass_pane
setblock ~-45 ~3 ~112 minecraft:gray_stained_glass_pane
setblock ~-55 ~3 ~115 minecraft:gray_stained_glass_pane
setblock ~-45 ~3 ~115 minecraft:gray_stained_glass_pane
setblock ~-53 ~7 ~110 minecraft:gray_stained_glass_pane
setblock ~-53 ~7 ~119 minecraft:gray_stained_glass_pane
setblock ~-50 ~7 ~110 minecraft:gray_stained_glass_pane
setblock ~-50 ~7 ~119 minecraft:gray_stained_glass_pane
setblock ~-47 ~7 ~110 minecraft:gray_stained_glass_pane
setblock ~-47 ~7 ~119 minecraft:gray_stained_glass_pane
setblock ~-55 ~7 ~112 minecraft:gray_stained_glass_pane
setblock ~-45 ~7 ~112 minecraft:gray_stained_glass_pane
setblock ~-55 ~7 ~115 minecraft:gray_stained_glass_pane
setblock ~-45 ~7 ~115 minecraft:gray_stained_glass_pane
setblock ~-53 ~11 ~110 minecraft:gray_stained_glass_pane
setblock ~-53 ~11 ~119 minecraft:gray_stained_glass_pane
setblock ~-50 ~11 ~110 minecraft:gray_stained_glass_pane
setblock ~-50 ~11 ~119 minecraft:gray_stained_glass_pane
setblock ~-47 ~11 ~110 minecraft:gray_stained_glass_pane
setblock ~-47 ~11 ~119 minecraft:gray_stained_glass_pane
setblock ~-55 ~11 ~112 minecraft:gray_stained_glass_pane
setblock ~-45 ~11 ~112 minecraft:gray_stained_glass_pane
setblock ~-55 ~11 ~115 minecraft:gray_stained_glass_pane
setblock ~-45 ~11 ~115 minecraft:gray_stained_glass_pane
setblock ~-53 ~15 ~110 minecraft:gray_stained_glass_pane
setblock ~-53 ~15 ~119 minecraft:gray_stained_glass_pane
setblock ~-50 ~15 ~110 minecraft:gray_stained_glass_pane
setblock ~-50 ~15 ~119 minecraft:gray_stained_glass_pane
setblock ~-47 ~15 ~110 minecraft:gray_stained_glass_pane
setblock ~-47 ~15 ~119 minecraft:gray_stained_glass_pane
setblock ~-55 ~15 ~112 minecraft:gray_stained_glass_pane
setblock ~-45 ~15 ~112 minecraft:gray_stained_glass_pane
setblock ~-55 ~15 ~115 minecraft:gray_stained_glass_pane
setblock ~-45 ~15 ~115 minecraft:gray_stained_glass_pane
setblock ~-53 ~19 ~110 minecraft:gray_stained_glass_pane
setblock ~-53 ~19 ~119 minecraft:gray_stained_glass_pane
setblock ~-50 ~19 ~110 minecraft:gray_stained_glass_pane
setblock ~-50 ~19 ~119 minecraft:gray_stained_glass_pane
setblock ~-47 ~19 ~110 minecraft:gray_stained_glass_pane
setblock ~-47 ~19 ~119 minecraft:gray_stained_glass_pane
setblock ~-55 ~19 ~112 minecraft:gray_stained_glass_pane
setblock ~-45 ~19 ~112 minecraft:gray_stained_glass_pane
setblock ~-55 ~19 ~115 minecraft:gray_stained_glass_pane
setblock ~-45 ~19 ~115 minecraft:gray_stained_glass_pane
setblock ~-50 ~2 ~110 minecraft:dark_oak_door[half=lower]
setblock ~-50 ~3 ~110 minecraft:dark_oak_door[half=upper]
fill ~55 ~1 ~1 ~62 ~20 ~8 minecraft:white_terracotta
fill ~56 ~2 ~2 ~61 ~19 ~7 minecraft:air
fill ~56 ~4 ~2 ~61 ~4 ~7 minecraft:smooth_stone
fill ~56 ~8 ~2 ~61 ~8 ~7 minecraft:smooth_stone
fill ~56 ~12 ~2 ~61 ~12 ~7 minecraft:smooth_stone
fill ~56 ~16 ~2 ~61 ~16 ~7 minecraft:smooth_stone
fill ~55 ~21 ~1 ~62 ~21 ~8 minecraft:spruce_planks
setblock ~57 ~3 ~1 minecraft:gray_stained_glass_pane
setblock ~57 ~3 ~8 minecraft:gray_stained_glass_pane
setblock ~60 ~3 ~1 minecraft:gray_stained_glass_pane
setblock ~60 ~3 ~8 minecraft:gray_stained_glass_pane
setblock ~55 ~3 ~3 minecraft:gray_stained_glass_pane
setblock ~62 ~3 ~3 minecraft:gray_stained_glass_pane
setblock ~55 ~3 ~6 minecraft:gray_stained_glass_pane
setblock ~62 ~3 ~6 minecraft:gray_stained_glass_pane
setblock ~57 ~7 ~1 minecraft:gray_stained_glass_pane
setblock ~57 ~7 ~8 minecraft:gray_stained_glass_pane
setblock ~60 ~7 ~1 minecraft:gray_stained_glass_pane
setblock ~60 ~7 ~8 minecraft:gray_stained_glass_pane
setblock ~55 ~7 ~3 minecraft:gray_stained_glass_pane
setblock ~62 ~7 ~3 minecraft:gray_stained_glass_pane
setblock ~55 ~7 ~6 minecraft:gray_stained_glass_pane
setblock ~62 ~7 ~6 minecraft:gray_stained_glass_pane
setblock ~57 ~11 ~1 minecraft:gray_stained_glass_pane
setblock ~57 ~11 ~8 minecraft:gray_stained_glass_pane
setblock ~60 ~11 ~1 minecraft:gray_stained_glass_pane
setblock ~60 ~11 ~8 minecraft:gray_stained_glass_pane
setblock ~55 ~11 ~3 minecraft:gray_stained_glass_pane
setblock ~62 ~11 ~3 minecraft:gray_stained_glass_pane
setblock ~55 ~11 ~6 minecraft:gray_stained_glass_pane
setblock ~62 ~11 ~6 minecraft:gray_stained_glass_pane
setblock ~57 ~15 ~1 minecraft:gray_stained_glass_pane
setblock ~57 ~15 ~8 minecraft:gray_stained_glass_pane
setblock ~60 ~15 ~1 minecraft:gray_stained_glass_pane
setblock ~60 ~15 ~8 minecraft:gray_stained_glass_pane
setblock ~55 ~15 ~3 minecraft:gray_stained_glass_pane
setblock ~62 ~15 ~3 minecraft:gray_stained_glass_pane
setblock ~55 ~15 ~6 minecraft:gray_stained_glass_pane
setblock ~62 ~15 ~6 minecraft:gray_stained_glass_pane
setblock ~57 ~19 ~1 minecraft:gray_stained_glass_pane
setblock ~57 ~19 ~8 minecraft:gray_stained_glass_pane
setblock ~60 ~19 ~1 minecraft:gray_stained_glass_pane
setblock ~60 ~19 ~8 minecraft:gray_stained_glass_pane
setblock ~55 ~19 ~3 minecraft:gray_stained_glass_pane
setblock ~62 ~19 ~3 minecraft:gray_stained_glass_pane
setblock ~55 ~19 ~6 minecraft:gray_stained_glass_pane
setblock ~62 ~19 ~6 minecraft:gray_stained_glass_pane
setblock ~59 ~2 ~8 minecraft:dark_oak_door[half=lower]
setblock ~59 ~3 ~8 minecraft:dark_oak_door[half=upper]
fill ~91 ~1 ~38 ~98 ~20 ~47 minecraft:bricks
fill ~92 ~2 ~39 ~97 ~19 ~46 minecraft:air
fill ~92 ~4 ~39 ~97 ~4 ~46 minecraft:smooth_stone
fill ~92 ~8 ~39 ~97 ~8 ~46 minecraft:smooth_stone
fill ~92 ~12 ~39 ~97 ~12 ~46 minecraft:smooth_stone
fill ~92 ~16 ~39 ~97 ~16 ~46 minecraft:smooth_stone
fill ~91 ~21 ~38 ~98 ~21 ~47 minecraft:polished_andesite
setblock ~93 ~3 ~38 minecraft:gray_stained_glass_pane
setblock ~93 ~3 ~47 minecraft:gray_stained_glass_pane
setblock ~96 ~3 ~38 minecraft:gray_stained_glass_pane
setblock ~96 ~3 ~47 minecraft:gray_stained_glass_pane
setblock ~91 ~3 ~40 minecraft:gray_stained_glass_pane
setblock ~98 ~3 ~40 minecraft:gray_stained_glass_pane
setblock ~91 ~3 ~43 minecraft:gray_stained_glass_pane
setblock ~98 ~3 ~43 minecraft:gray_stained_glass_pane
setblock ~93 ~7 ~38 minecraft:gray_stained_glass_pane
setblock ~93 ~7 ~47 minecraft:gray_stained_glass_pane
setblock ~96 ~7 ~38 minecraft:gray_stained_glass_pane
setblock ~96 ~7 ~47 minecraft:gray_stained_glass_pane
setblock ~91 ~7 ~40 minecraft:gray_stained_glass_pane
setblock ~98 ~7 ~40 minecraft:gray_stained_glass_pane
setblock ~91 ~7 ~43 minecraft:gray_stained_glass_pane
setblock ~98 ~7 ~43 minecraft:gray_stained_glass_pane
setblock ~93 ~11 ~38 minecraft:gray_stained_glass_pane
setblock ~93 ~11 ~47 minecraft:gray_stained_glass_pane
setblock ~96 ~11 ~38 minecraft:gray_stained_glass_pane
setblock ~96 ~11 ~47 minecraft:gray_stained_glass_pane
setblock ~91 ~11 ~40 minecraft:gray_stained_glass_pane
setblock ~98 ~11 ~40 minecraft:gray_stained_glass_pane
setblock ~91 ~11 ~43 minecraft:gray_stained_glass_pane
setblock ~98 ~11 ~43 minecraft:gray_stained_glass_pane
setblock ~93 ~15 ~38 minecraft:gray_stained_glass_pane
setblock ~93 ~15 ~47 minecraft:gray_stained_glass_pane
setblock ~96 ~15 ~38 minecraft:gray_stained_glass_pane
setblock ~96 ~15 ~47 minecraft:gray_stained_glass_pane
setblock ~91 ~15 ~40 minecraft:gray_stained_glass_pane
setblock ~98 ~15 ~40 minecraft:gray_stained_glass_pane
setblock ~91 ~15 ~43 minecraft:gray_stained_glass_pane
setblock ~98 ~15 ~43 minecraft:gray_stained_glass_pane
setblock ~93 ~19 ~38 minecraft:gray_stained_glass_pane
setblock ~93 ~19 ~47 minecraft:gray_stained_glass_pane
setblock ~96 ~19 ~38 minecraft:gray_stained_glass_pane
setblock ~96 ~19 ~47 minecraft:gray_stained_glass_pane
setblock ~91 ~19 ~40 minecraft:gray_stained_glass_pane
setblock ~98 ~19 ~40 minecraft:gray_stained_glass_pane
setblock ~91 ~19 ~43 minecraft:gray_stained_glass_pane
setblock ~98 ~19 ~43 minecraft:gray_stained_glass_pane
setblock ~95 ~2 ~38 minecraft:dark_oak_door[half=lower]
setblock ~95 ~3 ~38 minecraft:dark_oak_door[half=upper]
setblock ~92 ~2 ~38 minecraft:cyan_stained_glass
setblock ~94 ~2 ~38 minecraft:cyan_stained_glass
setblock ~96 ~2 ~38 minecraft:cyan_stained_glass
fill ~92 ~1 ~1 ~101 ~16 ~11 minecraft:mud_bricks
fill ~93 ~2 ~2 ~100 ~15 ~10 minecraft:air
fill ~93 ~4 ~2 ~100 ~4 ~10 minecraft:smooth_stone
fill ~93 ~8 ~2 ~100 ~8 ~10 minecraft:smooth_stone
fill ~93 ~12 ~2 ~100 ~12 ~10 minecraft:smooth_stone
fill ~92 ~17 ~1 ~101 ~17 ~11 minecraft:dark_oak_planks
fill ~94 ~1 ~3 ~99 ~20 ~9 minecraft:mud_bricks
fill ~95 ~2 ~4 ~98 ~19 ~8 minecraft:air
fill ~95 ~4 ~4 ~98 ~4 ~8 minecraft:smooth_stone
fill ~95 ~8 ~4 ~98 ~8 ~8 minecraft:smooth_stone
fill ~95 ~12 ~4 ~98 ~12 ~8 minecraft:smooth_stone
fill ~95 ~16 ~4 ~98 ~16 ~8 minecraft:smooth_stone
fill ~94 ~21 ~3 ~99 ~21 ~9 minecraft:dark_oak_planks
setblock ~94 ~3 ~1 minecraft:gray_stained_glass_pane
setblock ~94 ~3 ~11 minecraft:gray_stained_glass_pane
setblock ~97 ~3 ~1 minecraft:gray_stained_glass_pane
setblock ~97 ~3 ~11 minecraft:gray_stained_glass_pane
setblock ~92 ~3 ~3 minecraft:gray_stained_glass_pane
setblock ~101 ~3 ~3 minecraft:gray_stained_glass_pane
setblock ~92 ~3 ~6 minecraft:gray_stained_glass_pane
setblock ~101 ~3 ~6 minecraft:gray_stained_glass_pane
setblock ~92 ~3 ~9 minecraft:gray_stained_glass_pane
setblock ~101 ~3 ~9 minecraft:gray_stained_glass_pane
setblock ~94 ~7 ~1 minecraft:gray_stained_glass_pane
setblock ~94 ~7 ~11 minecraft:gray_stained_glass_pane
setblock ~97 ~7 ~1 minecraft:gray_stained_glass_pane
setblock ~97 ~7 ~11 minecraft:gray_stained_glass_pane
setblock ~92 ~7 ~3 minecraft:gray_stained_glass_pane
setblock ~101 ~7 ~3 minecraft:gray_stained_glass_pane
setblock ~92 ~7 ~6 minecraft:gray_stained_glass_pane
setblock ~101 ~7 ~6 minecraft:gray_stained_glass_pane
setblock ~92 ~7 ~9 minecraft:gray_stained_glass_pane
setblock ~101 ~7 ~9 minecraft:gray_stained_glass_pane
setblock ~94 ~11 ~1 minecraft:gray_stained_glass_pane
setblock ~94 ~11 ~11 minecraft:gray_stained_glass_pane
setblock ~97 ~11 ~1 minecraft:gray_stained_glass_pane
setblock ~97 ~11 ~11 minecraft:gray_stained_glass_pane
setblock ~92 ~11 ~3 minecraft:gray_stained_glass_pane
setblock ~101 ~11 ~3 minecraft:gray_stained_glass_pane
setblock ~92 ~11 ~6 minecraft:gray_stained_glass_pane
setblock ~101 ~11 ~6 minecraft:gray_stained_glass_pane
setblock ~92 ~11 ~9 minecraft:gray_stained_glass_pane
setblock ~101 ~11 ~9 minecraft:gray_stained_glass_pane
setblock ~94 ~15 ~1 minecraft:gray_stained_glass_pane
setblock ~94 ~15 ~11 minecraft:gray_stained_glass_pane
setblock ~97 ~15 ~1 minecraft:gray_stained_glass_pane
setblock ~97 ~15 ~11 minecraft:gray_stained_glass_pane
setblock ~92 ~15 ~3 minecraft:gray_stained_glass_pane
setblock ~101 ~15 ~3 minecraft:gray_stained_glass_pane
setblock ~92 ~15 ~6 minecraft:gray_stained_glass_pane
setblock ~101 ~15 ~6 minecraft:gray_stained_glass_pane
setblock ~92 ~15 ~9 minecraft:gray_stained_glass_pane
setblock ~101 ~15 ~9 minecraft:gray_stained_glass_pane
setblock ~94 ~19 ~1 minecraft:gray_stained_glass_pane
setblock ~94 ~19 ~11 minecraft:gray_stained_glass_pane
setblock ~97 ~19 ~1 minecraft:gray_stained_glass_pane
setblock ~97 ~19 ~11 minecraft:gray_stained_glass_pane
setblock ~92 ~19 ~3 minecraft:gray_stained_glass_pane
setblock ~101 ~19 ~3 minecraft:gray_stained_glass_pane
setblock ~92 ~19 ~6 minecraft:gray_stained_glass_pane
setblock ~101 ~19 ~6 minecraft:gray_stained_glass_pane
setblock ~92 ~19 ~9 minecraft:gray_stained_glass_pane
setblock ~101 ~19 ~9 minecraft:gray_stained_glass_pane
setblock ~97 ~2 ~1 minecraft:dark_oak_door[half=lower]
setblock ~97 ~3 ~1 minecraft:dark_oak_door[half=upper]
fill ~5 ~1 ~-91 ~15 ~12 ~-85 minecraft:light_gray_concrete
fill ~6 ~2 ~-90 ~14 ~11 ~-86 minecraft:air
fill ~6 ~4 ~-90 ~14 ~4 ~-86 minecraft:smooth_stone
fill ~6 ~8 ~-90 ~14 ~8 ~-86 minecraft:smooth_stone
fill ~5 ~13 ~-91 ~15 ~13 ~-85 minecraft:gray_concrete
setblock ~7 ~3 ~-91 minecraft:gray_stained_glass_pane
setblock ~7 ~3 ~-85 minecraft:gray_stained_glass_pane
setblock ~10 ~3 ~-91 minecraft:gray_stained_glass_pane
setblock ~10 ~3 ~-85 minecraft:gray_stained_glass_pane
setblock ~13 ~3 ~-91 minecraft:gray_stained_glass_pane
setblock ~13 ~3 ~-85 minecraft:gray_stained_glass_pane
setblock ~5 ~3 ~-89 minecraft:gray_stained_glass_pane
setblock ~15 ~3 ~-89 minecraft:gray_stained_glass_pane
setblock ~7 ~7 ~-91 minecraft:gray_stained_glass_pane
setblock ~7 ~7 ~-85 minecraft:gray_stained_glass_pane
setblock ~10 ~7 ~-91 minecraft:gray_stained_glass_pane
setblock ~10 ~7 ~-85 minecraft:gray_stained_glass_pane
setblock ~13 ~7 ~-91 minecraft:gray_stained_glass_pane
setblock ~13 ~7 ~-85 minecraft:gray_stained_glass_pane
setblock ~5 ~7 ~-89 minecraft:gray_stained_glass_pane
setblock ~15 ~7 ~-89 minecraft:gray_stained_glass_pane
setblock ~7 ~11 ~-91 minecraft:gray_stained_glass_pane
setblock ~7 ~11 ~-85 minecraft:gray_stained_glass_pane
setblock ~10 ~11 ~-91 minecraft:gray_stained_glass_pane
setblock ~10 ~11 ~-85 minecraft:gray_stained_glass_pane
setblock ~13 ~11 ~-91 minecraft:gray_stained_glass_pane
setblock ~13 ~11 ~-85 minecraft:gray_stained_glass_pane
setblock ~5 ~11 ~-89 minecraft:gray_stained_glass_pane
setblock ~15 ~11 ~-89 minecraft:gray_stained_glass_pane
setblock ~15 ~2 ~-88 minecraft:dark_oak_door[half=lower]
setblock ~15 ~3 ~-88 minecraft:dark_oak_door[half=upper]
setblock ~15 ~2 ~-90 minecraft:cyan_stained_glass
setblock ~15 ~2 ~-88 minecraft:cyan_stained_glass
setblock ~15 ~2 ~-86 minecraft:cyan_stained_glass
fill ~5 ~14 ~-91 ~15 ~14 ~-85 minecraft:deepslate_tile_slab
fill ~6 ~15 ~-90 ~14 ~15 ~-86 minecraft:deepslate_tile_slab
fill ~42 ~1 ~-108 ~49 ~16 ~-102 minecraft:light_gray_concrete
fill ~43 ~2 ~-107 ~48 ~15 ~-103 minecraft:air
fill ~43 ~4 ~-107 ~48 ~4 ~-103 minecraft:smooth_stone
fill ~43 ~8 ~-107 ~48 ~8 ~-103 minecraft:smooth_stone
fill ~43 ~12 ~-107 ~48 ~12 ~-103 minecraft:smooth_stone
fill ~42 ~17 ~-108 ~49 ~17 ~-102 minecraft:gray_concrete
setblock ~44 ~3 ~-108 minecraft:gray_stained_glass_pane
setblock ~44 ~3 ~-102 minecraft:gray_stained_glass_pane
setblock ~47 ~3 ~-108 minecraft:gray_stained_glass_pane
setblock ~47 ~3 ~-102 minecraft:gray_stained_glass_pane
setblock ~42 ~3 ~-106 minecraft:gray_stained_glass_pane
setblock ~49 ~3 ~-106 minecraft:gray_stained_glass_pane
setblock ~44 ~7 ~-108 minecraft:gray_stained_glass_pane
setblock ~44 ~7 ~-102 minecraft:gray_stained_glass_pane
setblock ~47 ~7 ~-108 minecraft:gray_stained_glass_pane
setblock ~47 ~7 ~-102 minecraft:gray_stained_glass_pane
setblock ~42 ~7 ~-106 minecraft:gray_stained_glass_pane
setblock ~49 ~7 ~-106 minecraft:gray_stained_glass_pane
setblock ~44 ~11 ~-108 minecraft:gray_stained_glass_pane
setblock ~44 ~11 ~-102 minecraft:gray_stained_glass_pane
setblock ~47 ~11 ~-108 minecraft:gray_stained_glass_pane
setblock ~47 ~11 ~-102 minecraft:gray_stained_glass_pane
setblock ~42 ~11 ~-106 minecraft:gray_stained_glass_pane
setblock ~49 ~11 ~-106 minecraft:gray_stained_glass_pane
setblock ~44 ~15 ~-108 minecraft:gray_stained_glass_pane
setblock ~44 ~15 ~-102 minecraft:gray_stained_glass_pane
setblock ~47 ~15 ~-108 minecraft:gray_stained_glass_pane
setblock ~47 ~15 ~-102 minecraft:gray_stained_glass_pane
setblock ~42 ~15 ~-106 minecraft:gray_stained_glass_pane
setblock ~49 ~15 ~-106 minecraft:gray_stained_glass_pane
setblock ~42 ~2 ~-105 minecraft:dark_oak_door[half=lower]
setblock ~42 ~3 ~-105 minecraft:dark_oak_door[half=upper]
fill ~-38 ~1 ~-75 ~-31 ~16 ~-69 minecraft:stone_bricks
fill ~-37 ~2 ~-74 ~-32 ~15 ~-70 minecraft:air
fill ~-37 ~4 ~-74 ~-32 ~4 ~-70 minecraft:smooth_stone
fill ~-37 ~8 ~-74 ~-32 ~8 ~-70 minecraft:smooth_stone
fill ~-37 ~12 ~-74 ~-32 ~12 ~-70 minecraft:smooth_stone
fill ~-38 ~17 ~-75 ~-31 ~17 ~-69 minecraft:deepslate_bricks
setblock ~-36 ~3 ~-75 minecraft:gray_stained_glass_pane
setblock ~-36 ~3 ~-69 minecraft:gray_stained_glass_pane
setblock ~-33 ~3 ~-75 minecraft:gray_stained_glass_pane
setblock ~-33 ~3 ~-69 minecraft:gray_stained_glass_pane
setblock ~-38 ~3 ~-73 minecraft:gray_stained_glass_pane
setblock ~-31 ~3 ~-73 minecraft:gray_stained_glass_pane
setblock ~-36 ~7 ~-75 minecraft:gray_stained_glass_pane
setblock ~-36 ~7 ~-69 minecraft:gray_stained_glass_pane
setblock ~-33 ~7 ~-75 minecraft:gray_stained_glass_pane
setblock ~-33 ~7 ~-69 minecraft:gray_stained_glass_pane
setblock ~-38 ~7 ~-73 minecraft:gray_stained_glass_pane
setblock ~-31 ~7 ~-73 minecraft:gray_stained_glass_pane
setblock ~-36 ~11 ~-75 minecraft:gray_stained_glass_pane
setblock ~-36 ~11 ~-69 minecraft:gray_stained_glass_pane
setblock ~-33 ~11 ~-75 minecraft:gray_stained_glass_pane
setblock ~-33 ~11 ~-69 minecraft:gray_stained_glass_pane
setblock ~-38 ~11 ~-73 minecraft:gray_stained_glass_pane
setblock ~-31 ~11 ~-73 minecraft:gray_stained_glass_pane
setblock ~-36 ~15 ~-75 minecraft:gray_stained_glass_pane
setblock ~-36 ~15 ~-69 minecraft:gray_stained_glass_pane
setblock ~-33 ~15 ~-75 minecraft:gray_stained_glass_pane
setblock ~-33 ~15 ~-69 minecraft:gray_stained_glass_pane
setblock ~-38 ~15 ~-73 minecraft:gray_stained_glass_pane
setblock ~-31 ~15 ~-73 minecraft:gray_stained_glass_pane
setblock ~-34 ~2 ~-75 minecraft:dark_oak_door[half=lower]
setblock ~-34 ~3 ~-75 minecraft:dark_oak_door[half=upper]
setblock ~-37 ~2 ~-75 minecraft:cyan_stained_glass
setblock ~-35 ~2 ~-75 minecraft:cyan_stained_glass
setblock ~-33 ~2 ~-75 minecraft:cyan_stained_glass
fill ~-36 ~1 ~-124 ~-29 ~12 ~-117 minecraft:bricks
fill ~-35 ~2 ~-123 ~-30 ~11 ~-118 minecraft:air
fill ~-35 ~4 ~-123 ~-30 ~4 ~-118 minecraft:smooth_stone
fill ~-35 ~8 ~-123 ~-30 ~8 ~-118 minecraft:smooth_stone
fill ~-36 ~13 ~-124 ~-29 ~13 ~-117 minecraft:polished_andesite
setblock ~-34 ~3 ~-124 minecraft:gray_stained_glass_pane
setblock ~-34 ~3 ~-117 minecraft:gray_stained_glass_pane
setblock ~-31 ~3 ~-124 minecraft:gray_stained_glass_pane
setblock ~-31 ~3 ~-117 minecraft:gray_stained_glass_pane
setblock ~-36 ~3 ~-122 minecraft:gray_stained_glass_pane
setblock ~-29 ~3 ~-122 minecraft:gray_stained_glass_pane
setblock ~-36 ~3 ~-119 minecraft:gray_stained_glass_pane
setblock ~-29 ~3 ~-119 minecraft:gray_stained_glass_pane
setblock ~-34 ~7 ~-124 minecraft:gray_stained_glass_pane
setblock ~-34 ~7 ~-117 minecraft:gray_stained_glass_pane
setblock ~-31 ~7 ~-124 minecraft:gray_stained_glass_pane
setblock ~-31 ~7 ~-117 minecraft:gray_stained_glass_pane
setblock ~-36 ~7 ~-122 minecraft:gray_stained_glass_pane
setblock ~-29 ~7 ~-122 minecraft:gray_stained_glass_pane
setblock ~-36 ~7 ~-119 minecraft:gray_stained_glass_pane
setblock ~-29 ~7 ~-119 minecraft:gray_stained_glass_pane
setblock ~-34 ~11 ~-124 minecraft:gray_stained_glass_pane
setblock ~-34 ~11 ~-117 minecraft:gray_stained_glass_pane
setblock ~-31 ~11 ~-124 minecraft:gray_stained_glass_pane
setblock ~-31 ~11 ~-117 minecraft:gray_stained_glass_pane
setblock ~-36 ~11 ~-122 minecraft:gray_stained_glass_pane
setblock ~-29 ~11 ~-122 minecraft:gray_stained_glass_pane
setblock ~-36 ~11 ~-119 minecraft:gray_stained_glass_pane
setblock ~-29 ~11 ~-119 minecraft:gray_stained_glass_pane
setblock ~-29 ~2 ~-120 minecraft:dark_oak_door[half=lower]
setblock ~-29 ~3 ~-120 minecraft:dark_oak_door[half=upper]
setblock ~-29 ~2 ~-123 minecraft:cyan_stained_glass
setblock ~-29 ~2 ~-121 minecraft:cyan_stained_glass
setblock ~-29 ~2 ~-119 minecraft:cyan_stained_glass
fill ~80 ~1 ~-109 ~86 ~16 ~-98 minecraft:bricks
fill ~81 ~2 ~-108 ~85 ~15 ~-99 minecraft:air
fill ~81 ~4 ~-108 ~85 ~4 ~-99 minecraft:smooth_stone
fill ~81 ~8 ~-108 ~85 ~8 ~-99 minecraft:smooth_stone
fill ~81 ~12 ~-108 ~85 ~12 ~-99 minecraft:smooth_stone
fill ~80 ~17 ~-109 ~86 ~17 ~-98 minecraft:polished_andesite
setblock ~82 ~3 ~-109 minecraft:gray_stained_glass_pane
setblock ~82 ~3 ~-98 minecraft:gray_stained_glass_pane
setblock ~80 ~3 ~-107 minecraft:gray_stained_glass_pane
setblock ~86 ~3 ~-107 minecraft:gray_stained_glass_pane
setblock ~80 ~3 ~-104 minecraft:gray_stained_glass_pane
setblock ~86 ~3 ~-104 minecraft:gray_stained_glass_pane
setblock ~80 ~3 ~-101 minecraft:gray_stained_glass_pane
setblock ~86 ~3 ~-101 minecraft:gray_stained_glass_pane
setblock ~82 ~7 ~-109 minecraft:gray_stained_glass_pane
setblock ~82 ~7 ~-98 minecraft:gray_stained_glass_pane
setblock ~80 ~7 ~-107 minecraft:gray_stained_glass_pane
setblock ~86 ~7 ~-107 minecraft:gray_stained_glass_pane
setblock ~80 ~7 ~-104 minecraft:gray_stained_glass_pane
setblock ~86 ~7 ~-104 minecraft:gray_stained_glass_pane
setblock ~80 ~7 ~-101 minecraft:gray_stained_glass_pane
setblock ~86 ~7 ~-101 minecraft:gray_stained_glass_pane
setblock ~82 ~11 ~-109 minecraft:gray_stained_glass_pane
setblock ~82 ~11 ~-98 minecraft:gray_stained_glass_pane
setblock ~80 ~11 ~-107 minecraft:gray_stained_glass_pane
setblock ~86 ~11 ~-107 minecraft:gray_stained_glass_pane
setblock ~80 ~11 ~-104 minecraft:gray_stained_glass_pane
setblock ~86 ~11 ~-104 minecraft:gray_stained_glass_pane
setblock ~80 ~11 ~-101 minecraft:gray_stained_glass_pane
setblock ~86 ~11 ~-101 minecraft:gray_stained_glass_pane
setblock ~82 ~15 ~-109 minecraft:gray_stained_glass_pane
setblock ~82 ~15 ~-98 minecraft:gray_stained_glass_pane
setblock ~80 ~15 ~-107 minecraft:gray_stained_glass_pane
setblock ~86 ~15 ~-107 minecraft:gray_stained_glass_pane
setblock ~80 ~15 ~-104 minecraft:gray_stained_glass_pane
setblock ~86 ~15 ~-104 minecraft:gray_stained_glass_pane
