# Buildings 145..152
# 145 midrise_housing style=setback_block context=collector_front facing=south
fill ~-70 ~-3 ~57 ~-62 ~-1 ~64 minecraft:stone
fill ~-70 ~0 ~57 ~-62 ~10 ~64 minecraft:light_gray_concrete
fill ~-69 ~1 ~58 ~-63 ~9 ~63 minecraft:air
fill ~-69 ~4 ~58 ~-63 ~4 ~63 minecraft:smooth_stone
fill ~-69 ~8 ~58 ~-63 ~8 ~63 minecraft:smooth_stone
fill ~-68 ~2 ~57 ~-68 ~3 ~57 minecraft:gray_stained_glass
fill ~-68 ~2 ~64 ~-68 ~3 ~64 minecraft:light_gray_stained_glass
fill ~-65 ~2 ~57 ~-65 ~3 ~57 minecraft:gray_stained_glass
fill ~-65 ~2 ~64 ~-65 ~3 ~64 minecraft:light_gray_stained_glass
fill ~-70 ~2 ~59 ~-70 ~3 ~59 minecraft:gray_stained_glass
fill ~-62 ~2 ~59 ~-62 ~3 ~59 minecraft:light_gray_stained_glass
fill ~-70 ~2 ~62 ~-70 ~3 ~62 minecraft:gray_stained_glass
fill ~-62 ~2 ~62 ~-62 ~3 ~62 minecraft:light_gray_stained_glass
fill ~-68 ~6 ~57 ~-68 ~7 ~57 minecraft:gray_stained_glass
fill ~-68 ~6 ~64 ~-68 ~7 ~64 minecraft:light_gray_stained_glass
fill ~-65 ~6 ~57 ~-65 ~7 ~57 minecraft:gray_stained_glass
fill ~-65 ~6 ~64 ~-65 ~7 ~64 minecraft:light_gray_stained_glass
fill ~-70 ~6 ~59 ~-70 ~7 ~59 minecraft:gray_stained_glass
fill ~-62 ~6 ~59 ~-62 ~7 ~59 minecraft:light_gray_stained_glass
fill ~-70 ~6 ~62 ~-70 ~7 ~62 minecraft:gray_stained_glass
fill ~-62 ~6 ~62 ~-62 ~7 ~62 minecraft:light_gray_stained_glass
setblock ~-66 ~1 ~64 minecraft:iron_door[half=lower,facing=south]
setblock ~-66 ~2 ~64 minecraft:iron_door[half=upper,facing=south]
fill ~-70 ~7 ~57 ~-62 ~10 ~64 minecraft:air
fill ~-69 ~7 ~58 ~-63 ~10 ~63 minecraft:light_gray_concrete
fill ~-68 ~8 ~59 ~-64 ~9 ~62 minecraft:air
fill ~-69 ~11 ~58 ~-63 ~11 ~63 minecraft:smooth_stone_slab
# 146 lowrise_housing style=rowhouse context=local_front facing=east
fill ~-64 ~-3 ~109 ~-59 ~-1 ~122 minecraft:stone
fill ~-64 ~0 ~109 ~-59 ~5 ~122 minecraft:mud_bricks
fill ~-63 ~1 ~110 ~-60 ~4 ~121 minecraft:air
fill ~-63 ~4 ~110 ~-60 ~4 ~121 minecraft:smooth_stone
fill ~-62 ~2 ~109 ~-62 ~3 ~109 minecraft:gray_stained_glass
fill ~-62 ~2 ~122 ~-62 ~3 ~122 minecraft:light_gray_stained_glass
fill ~-64 ~2 ~111 ~-64 ~3 ~111 minecraft:gray_stained_glass
fill ~-59 ~2 ~111 ~-59 ~3 ~111 minecraft:light_gray_stained_glass
fill ~-64 ~2 ~114 ~-64 ~3 ~114 minecraft:gray_stained_glass
fill ~-59 ~2 ~114 ~-59 ~3 ~114 minecraft:light_gray_stained_glass
fill ~-64 ~2 ~117 ~-64 ~3 ~117 minecraft:gray_stained_glass
fill ~-59 ~2 ~117 ~-59 ~3 ~117 minecraft:light_gray_stained_glass
fill ~-64 ~2 ~120 ~-64 ~3 ~120 minecraft:gray_stained_glass
fill ~-59 ~2 ~120 ~-59 ~3 ~120 minecraft:light_gray_stained_glass
setblock ~-59 ~1 ~114 minecraft:iron_door[half=lower,facing=east]
setblock ~-59 ~2 ~114 minecraft:iron_door[half=upper,facing=east]
fill ~-64 ~6 ~109 ~-59 ~6 ~122 minecraft:deepslate_tile_slab
fill ~-63 ~7 ~110 ~-60 ~7 ~121 minecraft:deepslate_tile_slab
setblock ~-58 ~3 ~114 minecraft:dark_oak_slab[type=top]
# 147 detached_house style=rowhouse context=local_front facing=north
fill ~-43 ~-3 ~115 ~-38 ~-1 ~123 minecraft:stone
fill ~-43 ~0 ~115 ~-38 ~5 ~123 minecraft:white_terracotta
fill ~-42 ~1 ~116 ~-39 ~4 ~122 minecraft:air
fill ~-42 ~4 ~116 ~-39 ~4 ~122 minecraft:smooth_stone
fill ~-41 ~2 ~115 ~-41 ~3 ~115 minecraft:gray_stained_glass
fill ~-41 ~2 ~123 ~-41 ~3 ~123 minecraft:light_gray_stained_glass
fill ~-43 ~2 ~117 ~-43 ~3 ~117 minecraft:gray_stained_glass
fill ~-38 ~2 ~117 ~-38 ~3 ~117 minecraft:light_gray_stained_glass
fill ~-43 ~2 ~120 ~-43 ~3 ~120 minecraft:gray_stained_glass
fill ~-38 ~2 ~120 ~-38 ~3 ~120 minecraft:light_gray_stained_glass
setblock ~-41 ~1 ~115 minecraft:iron_door[half=lower,facing=north]
setblock ~-41 ~2 ~115 minecraft:iron_door[half=upper,facing=north]
fill ~-43 ~6 ~115 ~-38 ~6 ~123 minecraft:dark_oak_slab
fill ~-42 ~7 ~116 ~-39 ~7 ~122 minecraft:dark_oak_slab
setblock ~-41 ~3 ~114 minecraft:dark_oak_slab[type=top]
# 148 apartment style=setback_block context=waterfront_front facing=west
fill ~96 ~-3 ~-36 ~102 ~-1 ~-29 minecraft:stone
fill ~96 ~0 ~-36 ~102 ~5 ~-29 minecraft:white_concrete
fill ~97 ~1 ~-35 ~101 ~4 ~-30 minecraft:air
fill ~97 ~4 ~-35 ~101 ~4 ~-30 minecraft:smooth_stone
fill ~98 ~2 ~-36 ~98 ~3 ~-36 minecraft:gray_stained_glass
fill ~98 ~2 ~-29 ~98 ~3 ~-29 minecraft:light_gray_stained_glass
fill ~96 ~2 ~-34 ~96 ~3 ~-34 minecraft:gray_stained_glass
fill ~102 ~2 ~-34 ~102 ~3 ~-34 minecraft:light_gray_stained_glass
fill ~96 ~2 ~-31 ~96 ~3 ~-31 minecraft:gray_stained_glass
fill ~102 ~2 ~-31 ~102 ~3 ~-31 minecraft:light_gray_stained_glass
setblock ~96 ~1 ~-33 minecraft:iron_door[half=lower,facing=west]
setblock ~96 ~2 ~-33 minecraft:iron_door[half=upper,facing=west]
# 149 clinic style=setback_block context=collector_front facing=north
fill ~-76 ~-3 ~77 ~-69 ~-1 ~83 minecraft:stone
fill ~-76 ~0 ~77 ~-69 ~7 ~83 minecraft:white_terracotta
fill ~-75 ~1 ~78 ~-70 ~6 ~82 minecraft:air
fill ~-75 ~4 ~78 ~-70 ~4 ~82 minecraft:smooth_stone
fill ~-74 ~2 ~77 ~-74 ~3 ~77 minecraft:gray_stained_glass
fill ~-74 ~2 ~83 ~-74 ~3 ~83 minecraft:light_gray_stained_glass
fill ~-71 ~2 ~77 ~-71 ~3 ~77 minecraft:gray_stained_glass
fill ~-71 ~2 ~83 ~-71 ~3 ~83 minecraft:light_gray_stained_glass
fill ~-76 ~2 ~79 ~-76 ~3 ~79 minecraft:gray_stained_glass
fill ~-69 ~2 ~79 ~-69 ~3 ~79 minecraft:light_gray_stained_glass
setblock ~-73 ~1 ~77 minecraft:iron_door[half=lower,facing=north]
setblock ~-73 ~2 ~77 minecraft:iron_door[half=upper,facing=north]
# 150 large_retail style=arcade_shop context=arterial_front facing=north
fill ~-6 ~-3 ~38 ~3 ~-1 ~45 minecraft:stone
fill ~-6 ~0 ~38 ~3 ~20 ~45 minecraft:white_terracotta
fill ~-5 ~1 ~39 ~2 ~19 ~44 minecraft:air
fill ~-5 ~4 ~39 ~2 ~4 ~44 minecraft:smooth_stone
fill ~-5 ~8 ~39 ~2 ~8 ~44 minecraft:smooth_stone
fill ~-5 ~12 ~39 ~2 ~12 ~44 minecraft:smooth_stone
fill ~-5 ~16 ~39 ~2 ~16 ~44 minecraft:smooth_stone
fill ~-4 ~2 ~38 ~-4 ~3 ~38 minecraft:gray_stained_glass
fill ~-4 ~2 ~45 ~-4 ~3 ~45 minecraft:light_gray_stained_glass
fill ~-1 ~2 ~38 ~-1 ~3 ~38 minecraft:gray_stained_glass
fill ~-1 ~2 ~45 ~-1 ~3 ~45 minecraft:light_gray_stained_glass
fill ~-6 ~2 ~40 ~-6 ~3 ~40 minecraft:gray_stained_glass
fill ~3 ~2 ~40 ~3 ~3 ~40 minecraft:light_gray_stained_glass
fill ~-6 ~2 ~43 ~-6 ~3 ~43 minecraft:gray_stained_glass
fill ~3 ~2 ~43 ~3 ~3 ~43 minecraft:light_gray_stained_glass
fill ~-4 ~6 ~38 ~-4 ~7 ~38 minecraft:gray_stained_glass
fill ~-4 ~6 ~45 ~-4 ~7 ~45 minecraft:light_gray_stained_glass
fill ~-1 ~6 ~38 ~-1 ~7 ~38 minecraft:gray_stained_glass
fill ~-1 ~6 ~45 ~-1 ~7 ~45 minecraft:light_gray_stained_glass
fill ~-6 ~6 ~40 ~-6 ~7 ~40 minecraft:gray_stained_glass
fill ~3 ~6 ~40 ~3 ~7 ~40 minecraft:light_gray_stained_glass
fill ~-6 ~6 ~43 ~-6 ~7 ~43 minecraft:gray_stained_glass
fill ~3 ~6 ~43 ~3 ~7 ~43 minecraft:light_gray_stained_glass
fill ~-4 ~10 ~38 ~-4 ~11 ~38 minecraft:gray_stained_glass
fill ~-4 ~10 ~45 ~-4 ~11 ~45 minecraft:light_gray_stained_glass
fill ~-1 ~10 ~38 ~-1 ~11 ~38 minecraft:gray_stained_glass
fill ~-1 ~10 ~45 ~-1 ~11 ~45 minecraft:light_gray_stained_glass
fill ~-6 ~10 ~40 ~-6 ~11 ~40 minecraft:gray_stained_glass
fill ~3 ~10 ~40 ~3 ~11 ~40 minecraft:light_gray_stained_glass
fill ~-6 ~10 ~43 ~-6 ~11 ~43 minecraft:gray_stained_glass
fill ~3 ~10 ~43 ~3 ~11 ~43 minecraft:light_gray_stained_glass
fill ~-4 ~14 ~38 ~-4 ~15 ~38 minecraft:gray_stained_glass
fill ~-4 ~14 ~45 ~-4 ~15 ~45 minecraft:light_gray_stained_glass
fill ~-1 ~14 ~38 ~-1 ~15 ~38 minecraft:gray_stained_glass
fill ~-1 ~14 ~45 ~-1 ~15 ~45 minecraft:light_gray_stained_glass
fill ~-6 ~14 ~40 ~-6 ~15 ~40 minecraft:gray_stained_glass
fill ~3 ~14 ~40 ~3 ~15 ~40 minecraft:light_gray_stained_glass
fill ~-6 ~14 ~43 ~-6 ~15 ~43 minecraft:gray_stained_glass
fill ~3 ~14 ~43 ~3 ~15 ~43 minecraft:light_gray_stained_glass
fill ~-4 ~18 ~38 ~-4 ~19 ~38 minecraft:gray_stained_glass
fill ~-4 ~18 ~45 ~-4 ~19 ~45 minecraft:light_gray_stained_glass
fill ~-1 ~18 ~38 ~-1 ~19 ~38 minecraft:gray_stained_glass
fill ~-1 ~18 ~45 ~-1 ~19 ~45 minecraft:light_gray_stained_glass
fill ~-6 ~18 ~40 ~-6 ~19 ~40 minecraft:gray_stained_glass
fill ~3 ~18 ~40 ~3 ~19 ~40 minecraft:light_gray_stained_glass
fill ~-6 ~18 ~43 ~-6 ~19 ~43 minecraft:gray_stained_glass
fill ~3 ~18 ~43 ~3 ~19 ~43 minecraft:light_gray_stained_glass
setblock ~-2 ~1 ~38 minecraft:iron_door[half=lower,facing=north]
setblock ~-2 ~2 ~38 minecraft:iron_door[half=upper,facing=north]
fill ~-5 ~1 ~38 ~2 ~3 ~38 minecraft:cyan_stained_glass
setblock ~-2 ~1 ~38 minecraft:iron_door[half=lower,facing=north]
setblock ~-2 ~2 ~38 minecraft:iron_door[half=upper,facing=north]
setblock ~-2 ~3 ~37 minecraft:red_wool
fill ~-5 ~4 ~38 ~2 ~4 ~38 minecraft:gray_concrete
fill ~-6 ~21 ~38 ~3 ~21 ~45 minecraft:stone_brick_slab
fill ~-4 ~22 ~40 ~-2 ~23 ~42 minecraft:light_gray_concrete
setblock ~-1 ~22 ~41 minecraft:lightning_rod
# 151 medical_center style=civic_modern context=arterial_front facing=north
fill ~41 ~-3 ~6 ~47 ~-1 ~13 minecraft:stone
fill ~41 ~0 ~6 ~47 ~16 ~13 minecraft:white_terracotta
fill ~42 ~1 ~7 ~46 ~15 ~12 minecraft:air
fill ~42 ~4 ~7 ~46 ~4 ~12 minecraft:smooth_stone
fill ~42 ~8 ~7 ~46 ~8 ~12 minecraft:smooth_stone
fill ~42 ~12 ~7 ~46 ~12 ~12 minecraft:smooth_stone
fill ~43 ~2 ~6 ~43 ~3 ~6 minecraft:gray_stained_glass
fill ~43 ~2 ~13 ~43 ~3 ~13 minecraft:light_gray_stained_glass
fill ~41 ~2 ~8 ~41 ~3 ~8 minecraft:gray_stained_glass
fill ~47 ~2 ~8 ~47 ~3 ~8 minecraft:light_gray_stained_glass
fill ~41 ~2 ~11 ~41 ~3 ~11 minecraft:gray_stained_glass
fill ~47 ~2 ~11 ~47 ~3 ~11 minecraft:light_gray_stained_glass
fill ~43 ~6 ~6 ~43 ~7 ~6 minecraft:gray_stained_glass
fill ~43 ~6 ~13 ~43 ~7 ~13 minecraft:light_gray_stained_glass
fill ~41 ~6 ~8 ~41 ~7 ~8 minecraft:gray_stained_glass
fill ~47 ~6 ~8 ~47 ~7 ~8 minecraft:light_gray_stained_glass
fill ~41 ~6 ~11 ~41 ~7 ~11 minecraft:gray_stained_glass
fill ~47 ~6 ~11 ~47 ~7 ~11 minecraft:light_gray_stained_glass
fill ~43 ~10 ~6 ~43 ~11 ~6 minecraft:gray_stained_glass
fill ~43 ~10 ~13 ~43 ~11 ~13 minecraft:light_gray_stained_glass
fill ~41 ~10 ~8 ~41 ~11 ~8 minecraft:gray_stained_glass
fill ~47 ~10 ~8 ~47 ~11 ~8 minecraft:light_gray_stained_glass
fill ~41 ~10 ~11 ~41 ~11 ~11 minecraft:gray_stained_glass
fill ~47 ~10 ~11 ~47 ~11 ~11 minecraft:light_gray_stained_glass
fill ~43 ~14 ~6 ~43 ~15 ~6 minecraft:gray_stained_glass
fill ~43 ~14 ~13 ~43 ~15 ~13 minecraft:light_gray_stained_glass
fill ~41 ~14 ~8 ~41 ~15 ~8 minecraft:gray_stained_glass
fill ~47 ~14 ~8 ~47 ~15 ~8 minecraft:light_gray_stained_glass
fill ~41 ~14 ~11 ~41 ~15 ~11 minecraft:gray_stained_glass
fill ~47 ~14 ~11 ~47 ~15 ~11 minecraft:light_gray_stained_glass
setblock ~44 ~1 ~6 minecraft:iron_door[half=lower,facing=north]
setblock ~44 ~2 ~6 minecraft:iron_door[half=upper,facing=north]
fill ~41 ~11 ~6 ~47 ~16 ~13 minecraft:air
fill ~42 ~11 ~7 ~46 ~16 ~12 minecraft:white_terracotta
fill ~43 ~12 ~8 ~45 ~15 ~11 minecraft:air
fill ~42 ~17 ~7 ~46 ~17 ~12 minecraft:stone_brick_slab
# 152 local_shop style=arcade_shop context=local_front facing=east
fill ~14 ~-3 ~-44 ~26 ~-1 ~-37 minecraft:stone
fill ~14 ~0 ~-44 ~26 ~12 ~-37 minecraft:light_gray_concrete
fill ~15 ~1 ~-43 ~25 ~11 ~-38 minecraft:air
fill ~15 ~4 ~-43 ~25 ~4 ~-38 minecraft:smooth_stone
fill ~15 ~8 ~-43 ~25 ~8 ~-38 minecraft:smooth_stone
fill ~16 ~2 ~-44 ~16 ~3 ~-44 minecraft:gray_stained_glass
fill ~16 ~2 ~-37 ~16 ~3 ~-37 minecraft:light_gray_stained_glass
fill ~19 ~2 ~-44 ~19 ~3 ~-44 minecraft:gray_stained_glass
fill ~19 ~2 ~-37 ~19 ~3 ~-37 minecraft:light_gray_stained_glass
fill ~22 ~2 ~-44 ~22 ~3 ~-44 minecraft:gray_stained_glass
fill ~22 ~2 ~-37 ~22 ~3 ~-37 minecraft:light_gray_stained_glass
fill ~14 ~2 ~-42 ~14 ~3 ~-42 minecraft:gray_stained_glass
fill ~26 ~2 ~-42 ~26 ~3 ~-42 minecraft:light_gray_stained_glass
fill ~14 ~2 ~-39 ~14 ~3 ~-39 minecraft:gray_stained_glass
fill ~26 ~2 ~-39 ~26 ~3 ~-39 minecraft:light_gray_stained_glass
fill ~16 ~6 ~-44 ~16 ~7 ~-44 minecraft:gray_stained_glass
fill ~16 ~6 ~-37 ~16 ~7 ~-37 minecraft:light_gray_stained_glass
fill ~19 ~6 ~-44 ~19 ~7 ~-44 minecraft:gray_stained_glass
fill ~19 ~6 ~-37 ~19 ~7 ~-37 minecraft:light_gray_stained_glass
fill ~22 ~6 ~-44 ~22 ~7 ~-44 minecraft:gray_stained_glass
fill ~22 ~6 ~-37 ~22 ~7 ~-37 minecraft:light_gray_stained_glass
fill ~14 ~6 ~-42 ~14 ~7 ~-42 minecraft:gray_stained_glass
fill ~26 ~6 ~-42 ~26 ~7 ~-42 minecraft:light_gray_stained_glass
fill ~14 ~6 ~-39 ~14 ~7 ~-39 minecraft:gray_stained_glass
fill ~26 ~6 ~-39 ~26 ~7 ~-39 minecraft:light_gray_stained_glass
fill ~16 ~10 ~-44 ~16 ~11 ~-44 minecraft:gray_stained_glass
fill ~16 ~10 ~-37 ~16 ~11 ~-37 minecraft:light_gray_stained_glass
fill ~19 ~10 ~-44 ~19 ~11 ~-44 minecraft:gray_stained_glass
fill ~19 ~10 ~-37 ~19 ~11 ~-37 minecraft:light_gray_stained_glass
fill ~22 ~10 ~-44 ~22 ~11 ~-44 minecraft:gray_stained_glass
fill ~22 ~10 ~-37 ~22 ~11 ~-37 minecraft:light_gray_stained_glass
fill ~14 ~10 ~-42 ~14 ~11 ~-42 minecraft:gray_stained_glass
fill ~26 ~10 ~-42 ~26 ~11 ~-42 minecraft:light_gray_stained_glass
fill ~14 ~10 ~-39 ~14 ~11 ~-39 minecraft:gray_stained_glass
fill ~26 ~10 ~-39 ~26 ~11 ~-39 minecraft:light_gray_stained_glass
setblock ~26 ~1 ~-41 minecraft:iron_door[half=lower,facing=east]
setblock ~26 ~2 ~-41 minecraft:iron_door[half=upper,facing=east]
fill ~26 ~1 ~-43 ~26 ~3 ~-38 minecraft:cyan_stained_glass
setblock ~26 ~1 ~-41 minecraft:iron_door[half=lower,facing=east]
setblock ~26 ~2 ~-41 minecraft:iron_door[half=upper,facing=east]
setblock ~27 ~3 ~-41 minecraft:red_wool
fill ~26 ~4 ~-43 ~26 ~4 ~-38 doomsday_decoration:cementwall
fill ~14 ~13 ~-44 ~26 ~13 ~-37 minecraft:smooth_stone_slab
