fill ~-118 ~2 ~39 ~-112 ~11 ~45 minecraft:air
fill ~-118 ~4 ~39 ~-112 ~4 ~45 minecraft:smooth_stone
fill ~-118 ~8 ~39 ~-112 ~8 ~45 minecraft:smooth_stone
fill ~-119 ~13 ~38 ~-111 ~13 ~46 minecraft:deepslate_bricks
setblock ~-117 ~3 ~38 minecraft:gray_stained_glass_pane
setblock ~-117 ~3 ~46 minecraft:gray_stained_glass_pane
setblock ~-114 ~3 ~38 minecraft:gray_stained_glass_pane
setblock ~-114 ~3 ~46 minecraft:gray_stained_glass_pane
setblock ~-119 ~3 ~40 minecraft:gray_stained_glass_pane
setblock ~-111 ~3 ~40 minecraft:gray_stained_glass_pane
setblock ~-119 ~3 ~43 minecraft:gray_stained_glass_pane
setblock ~-111 ~3 ~43 minecraft:gray_stained_glass_pane
setblock ~-117 ~7 ~38 minecraft:gray_stained_glass_pane
setblock ~-117 ~7 ~46 minecraft:gray_stained_glass_pane
setblock ~-114 ~7 ~38 minecraft:gray_stained_glass_pane
setblock ~-114 ~7 ~46 minecraft:gray_stained_glass_pane
setblock ~-119 ~7 ~40 minecraft:gray_stained_glass_pane
setblock ~-111 ~7 ~40 minecraft:gray_stained_glass_pane
setblock ~-119 ~7 ~43 minecraft:gray_stained_glass_pane
setblock ~-111 ~7 ~43 minecraft:gray_stained_glass_pane
setblock ~-117 ~11 ~38 minecraft:gray_stained_glass_pane
setblock ~-117 ~11 ~46 minecraft:gray_stained_glass_pane
setblock ~-114 ~11 ~38 minecraft:gray_stained_glass_pane
setblock ~-114 ~11 ~46 minecraft:gray_stained_glass_pane
setblock ~-119 ~11 ~40 minecraft:gray_stained_glass_pane
setblock ~-111 ~11 ~40 minecraft:gray_stained_glass_pane
setblock ~-119 ~11 ~43 minecraft:gray_stained_glass_pane
setblock ~-111 ~11 ~43 minecraft:gray_stained_glass_pane
setblock ~-115 ~2 ~46 minecraft:dark_oak_door[half=lower]
setblock ~-115 ~3 ~46 minecraft:dark_oak_door[half=upper]
fill ~-17 ~1 ~-29 ~-7 ~24 ~-23 minecraft:light_gray_concrete
fill ~-16 ~2 ~-28 ~-8 ~23 ~-24 minecraft:air
fill ~-16 ~4 ~-28 ~-8 ~4 ~-24 minecraft:smooth_stone
fill ~-16 ~8 ~-28 ~-8 ~8 ~-24 minecraft:smooth_stone
fill ~-16 ~12 ~-28 ~-8 ~12 ~-24 minecraft:smooth_stone
fill ~-16 ~16 ~-28 ~-8 ~16 ~-24 minecraft:smooth_stone
fill ~-16 ~20 ~-28 ~-8 ~20 ~-24 minecraft:smooth_stone
fill ~-17 ~25 ~-29 ~-7 ~25 ~-23 minecraft:gray_concrete
fill ~-17 ~1 ~-22 ~-12 ~20 ~-18 minecraft:light_gray_concrete
fill ~-16 ~2 ~-21 ~-13 ~19 ~-19 minecraft:air
fill ~-16 ~4 ~-21 ~-13 ~4 ~-19 minecraft:smooth_stone
fill ~-16 ~8 ~-21 ~-13 ~8 ~-19 minecraft:smooth_stone
fill ~-16 ~12 ~-21 ~-13 ~12 ~-19 minecraft:smooth_stone
fill ~-16 ~16 ~-21 ~-13 ~16 ~-19 minecraft:smooth_stone
fill ~-17 ~21 ~-22 ~-12 ~21 ~-18 minecraft:gray_concrete
setblock ~-15 ~3 ~-29 minecraft:gray_stained_glass_pane
setblock ~-15 ~3 ~-18 minecraft:gray_stained_glass_pane
setblock ~-12 ~3 ~-29 minecraft:gray_stained_glass_pane
setblock ~-12 ~3 ~-18 minecraft:gray_stained_glass_pane
setblock ~-9 ~3 ~-29 minecraft:gray_stained_glass_pane
setblock ~-9 ~3 ~-18 minecraft:gray_stained_glass_pane
setblock ~-17 ~3 ~-27 minecraft:gray_stained_glass_pane
setblock ~-7 ~3 ~-27 minecraft:gray_stained_glass_pane
setblock ~-17 ~3 ~-24 minecraft:gray_stained_glass_pane
setblock ~-7 ~3 ~-24 minecraft:gray_stained_glass_pane
setblock ~-17 ~3 ~-21 minecraft:gray_stained_glass_pane
setblock ~-7 ~3 ~-21 minecraft:gray_stained_glass_pane
setblock ~-15 ~7 ~-29 minecraft:gray_stained_glass_pane
setblock ~-15 ~7 ~-18 minecraft:gray_stained_glass_pane
setblock ~-12 ~7 ~-29 minecraft:gray_stained_glass_pane
setblock ~-12 ~7 ~-18 minecraft:gray_stained_glass_pane
setblock ~-9 ~7 ~-29 minecraft:gray_stained_glass_pane
setblock ~-9 ~7 ~-18 minecraft:gray_stained_glass_pane
setblock ~-17 ~7 ~-27 minecraft:gray_stained_glass_pane
setblock ~-7 ~7 ~-27 minecraft:gray_stained_glass_pane
setblock ~-17 ~7 ~-24 minecraft:gray_stained_glass_pane
setblock ~-7 ~7 ~-24 minecraft:gray_stained_glass_pane
setblock ~-17 ~7 ~-21 minecraft:gray_stained_glass_pane
setblock ~-7 ~7 ~-21 minecraft:gray_stained_glass_pane
setblock ~-15 ~11 ~-29 minecraft:gray_stained_glass_pane
setblock ~-15 ~11 ~-18 minecraft:gray_stained_glass_pane
setblock ~-12 ~11 ~-29 minecraft:gray_stained_glass_pane
setblock ~-12 ~11 ~-18 minecraft:gray_stained_glass_pane
setblock ~-9 ~11 ~-29 minecraft:gray_stained_glass_pane
setblock ~-9 ~11 ~-18 minecraft:gray_stained_glass_pane
setblock ~-17 ~11 ~-27 minecraft:gray_stained_glass_pane
setblock ~-7 ~11 ~-27 minecraft:gray_stained_glass_pane
setblock ~-17 ~11 ~-24 minecraft:gray_stained_glass_pane
setblock ~-7 ~11 ~-24 minecraft:gray_stained_glass_pane
setblock ~-17 ~11 ~-21 minecraft:gray_stained_glass_pane
setblock ~-7 ~11 ~-21 minecraft:gray_stained_glass_pane
setblock ~-15 ~15 ~-29 minecraft:gray_stained_glass_pane
setblock ~-15 ~15 ~-18 minecraft:gray_stained_glass_pane
setblock ~-12 ~15 ~-29 minecraft:gray_stained_glass_pane
setblock ~-12 ~15 ~-18 minecraft:gray_stained_glass_pane
setblock ~-9 ~15 ~-29 minecraft:gray_stained_glass_pane
setblock ~-9 ~15 ~-18 minecraft:gray_stained_glass_pane
setblock ~-17 ~15 ~-27 minecraft:gray_stained_glass_pane
setblock ~-7 ~15 ~-27 minecraft:gray_stained_glass_pane
setblock ~-17 ~15 ~-24 minecraft:gray_stained_glass_pane
setblock ~-7 ~15 ~-24 minecraft:gray_stained_glass_pane
setblock ~-17 ~15 ~-21 minecraft:gray_stained_glass_pane
setblock ~-7 ~15 ~-21 minecraft:gray_stained_glass_pane
setblock ~-15 ~19 ~-29 minecraft:gray_stained_glass_pane
setblock ~-15 ~19 ~-18 minecraft:gray_stained_glass_pane
setblock ~-12 ~19 ~-29 minecraft:gray_stained_glass_pane
setblock ~-12 ~19 ~-18 minecraft:gray_stained_glass_pane
setblock ~-9 ~19 ~-29 minecraft:gray_stained_glass_pane
setblock ~-9 ~19 ~-18 minecraft:gray_stained_glass_pane
setblock ~-17 ~19 ~-27 minecraft:gray_stained_glass_pane
setblock ~-7 ~19 ~-27 minecraft:gray_stained_glass_pane
setblock ~-17 ~19 ~-24 minecraft:gray_stained_glass_pane
setblock ~-7 ~19 ~-24 minecraft:gray_stained_glass_pane
setblock ~-17 ~19 ~-21 minecraft:gray_stained_glass_pane
setblock ~-7 ~19 ~-21 minecraft:gray_stained_glass_pane
setblock ~-15 ~23 ~-29 minecraft:gray_stained_glass_pane
setblock ~-15 ~23 ~-18 minecraft:gray_stained_glass_pane
setblock ~-12 ~23 ~-29 minecraft:gray_stained_glass_pane
setblock ~-12 ~23 ~-18 minecraft:gray_stained_glass_pane
setblock ~-9 ~23 ~-29 minecraft:gray_stained_glass_pane
setblock ~-9 ~23 ~-18 minecraft:gray_stained_glass_pane
setblock ~-17 ~23 ~-27 minecraft:gray_stained_glass_pane
setblock ~-7 ~23 ~-27 minecraft:gray_stained_glass_pane
setblock ~-17 ~23 ~-24 minecraft:gray_stained_glass_pane
setblock ~-7 ~23 ~-24 minecraft:gray_stained_glass_pane
setblock ~-17 ~23 ~-21 minecraft:gray_stained_glass_pane
setblock ~-7 ~23 ~-21 minecraft:gray_stained_glass_pane
setblock ~-12 ~2 ~-29 minecraft:dark_oak_door[half=lower]
setblock ~-12 ~3 ~-29 minecraft:dark_oak_door[half=upper]
setblock ~-16 ~2 ~-29 minecraft:cyan_stained_glass
setblock ~-14 ~2 ~-29 minecraft:cyan_stained_glass
setblock ~-12 ~2 ~-29 minecraft:cyan_stained_glass
setblock ~-10 ~2 ~-29 minecraft:cyan_stained_glass
setblock ~-8 ~2 ~-29 minecraft:cyan_stained_glass
fill ~-10 ~1 ~-122 ~-3 ~16 ~-114 minecraft:calcite
fill ~-9 ~2 ~-121 ~-4 ~15 ~-115 minecraft:air
fill ~-9 ~4 ~-121 ~-4 ~4 ~-115 minecraft:smooth_stone
fill ~-9 ~8 ~-121 ~-4 ~8 ~-115 minecraft:smooth_stone
fill ~-9 ~12 ~-121 ~-4 ~12 ~-115 minecraft:smooth_stone
fill ~-10 ~17 ~-122 ~-3 ~17 ~-114 minecraft:cyan_terracotta
setblock ~-8 ~3 ~-122 minecraft:gray_stained_glass_pane
setblock ~-8 ~3 ~-114 minecraft:gray_stained_glass_pane
setblock ~-5 ~3 ~-122 minecraft:gray_stained_glass_pane
setblock ~-5 ~3 ~-114 minecraft:gray_stained_glass_pane
setblock ~-10 ~3 ~-120 minecraft:gray_stained_glass_pane
setblock ~-3 ~3 ~-120 minecraft:gray_stained_glass_pane
setblock ~-10 ~3 ~-117 minecraft:gray_stained_glass_pane
setblock ~-3 ~3 ~-117 minecraft:gray_stained_glass_pane
setblock ~-8 ~7 ~-122 minecraft:gray_stained_glass_pane
setblock ~-8 ~7 ~-114 minecraft:gray_stained_glass_pane
setblock ~-5 ~7 ~-122 minecraft:gray_stained_glass_pane
setblock ~-5 ~7 ~-114 minecraft:gray_stained_glass_pane
setblock ~-10 ~7 ~-120 minecraft:gray_stained_glass_pane
setblock ~-3 ~7 ~-120 minecraft:gray_stained_glass_pane
setblock ~-10 ~7 ~-117 minecraft:gray_stained_glass_pane
setblock ~-3 ~7 ~-117 minecraft:gray_stained_glass_pane
setblock ~-8 ~11 ~-122 minecraft:gray_stained_glass_pane
setblock ~-8 ~11 ~-114 minecraft:gray_stained_glass_pane
setblock ~-5 ~11 ~-122 minecraft:gray_stained_glass_pane
setblock ~-5 ~11 ~-114 minecraft:gray_stained_glass_pane
setblock ~-10 ~11 ~-120 minecraft:gray_stained_glass_pane
setblock ~-3 ~11 ~-120 minecraft:gray_stained_glass_pane
setblock ~-10 ~11 ~-117 minecraft:gray_stained_glass_pane
setblock ~-3 ~11 ~-117 minecraft:gray_stained_glass_pane
setblock ~-8 ~15 ~-122 minecraft:gray_stained_glass_pane
setblock ~-8 ~15 ~-114 minecraft:gray_stained_glass_pane
setblock ~-5 ~15 ~-122 minecraft:gray_stained_glass_pane
setblock ~-5 ~15 ~-114 minecraft:gray_stained_glass_pane
setblock ~-10 ~15 ~-120 minecraft:gray_stained_glass_pane
setblock ~-3 ~15 ~-120 minecraft:gray_stained_glass_pane
setblock ~-10 ~15 ~-117 minecraft:gray_stained_glass_pane
setblock ~-3 ~15 ~-117 minecraft:gray_stained_glass_pane
setblock ~-10 ~2 ~-118 minecraft:dark_oak_door[half=lower]
setblock ~-10 ~3 ~-118 minecraft:dark_oak_door[half=upper]
setblock ~-10 ~2 ~-121 minecraft:cyan_stained_glass
setblock ~-10 ~2 ~-119 minecraft:cyan_stained_glass
setblock ~-10 ~2 ~-117 minecraft:cyan_stained_glass
setblock ~-10 ~2 ~-115 minecraft:cyan_stained_glass
fill ~-10 ~18 ~-122 ~-3 ~18 ~-114 minecraft:deepslate_tile_slab
fill ~-9 ~19 ~-121 ~-4 ~19 ~-115 minecraft:deepslate_tile_slab
fill ~-8 ~20 ~-120 ~-5 ~20 ~-116 minecraft:deepslate_tile_slab
fill ~30 ~1 ~-34 ~41 ~20 ~-26 minecraft:stone_bricks
fill ~31 ~2 ~-33 ~40 ~19 ~-27 minecraft:air
fill ~31 ~4 ~-33 ~40 ~4 ~-27 minecraft:smooth_stone
fill ~31 ~8 ~-33 ~40 ~8 ~-27 minecraft:smooth_stone
fill ~31 ~12 ~-33 ~40 ~12 ~-27 minecraft:smooth_stone
fill ~31 ~16 ~-33 ~40 ~16 ~-27 minecraft:smooth_stone
fill ~30 ~21 ~-34 ~41 ~21 ~-26 minecraft:deepslate_bricks
fill ~30 ~1 ~-25 ~36 ~16 ~-18 minecraft:stone_bricks
fill ~31 ~2 ~-24 ~35 ~15 ~-19 minecraft:air
fill ~31 ~4 ~-24 ~35 ~4 ~-19 minecraft:smooth_stone
fill ~31 ~8 ~-24 ~35 ~8 ~-19 minecraft:smooth_stone
fill ~31 ~12 ~-24 ~35 ~12 ~-19 minecraft:smooth_stone
fill ~30 ~17 ~-25 ~36 ~17 ~-18 minecraft:deepslate_bricks
setblock ~32 ~3 ~-34 minecraft:gray_stained_glass_pane
setblock ~32 ~3 ~-18 minecraft:gray_stained_glass_pane
setblock ~35 ~3 ~-34 minecraft:gray_stained_glass_pane
setblock ~35 ~3 ~-18 minecraft:gray_stained_glass_pane
setblock ~38 ~3 ~-34 minecraft:gray_stained_glass_pane
setblock ~38 ~3 ~-18 minecraft:gray_stained_glass_pane
setblock ~30 ~3 ~-32 minecraft:gray_stained_glass_pane
setblock ~41 ~3 ~-32 minecraft:gray_stained_glass_pane
setblock ~30 ~3 ~-29 minecraft:gray_stained_glass_pane
setblock ~41 ~3 ~-29 minecraft:gray_stained_glass_pane
setblock ~30 ~3 ~-26 minecraft:gray_stained_glass_pane
setblock ~41 ~3 ~-26 minecraft:gray_stained_glass_pane
setblock ~30 ~3 ~-23 minecraft:gray_stained_glass_pane
setblock ~41 ~3 ~-23 minecraft:gray_stained_glass_pane
setblock ~30 ~3 ~-20 minecraft:gray_stained_glass_pane
setblock ~41 ~3 ~-20 minecraft:gray_stained_glass_pane
setblock ~32 ~7 ~-34 minecraft:gray_stained_glass_pane
setblock ~32 ~7 ~-18 minecraft:gray_stained_glass_pane
setblock ~35 ~7 ~-34 minecraft:gray_stained_glass_pane
setblock ~35 ~7 ~-18 minecraft:gray_stained_glass_pane
setblock ~38 ~7 ~-34 minecraft:gray_stained_glass_pane
setblock ~38 ~7 ~-18 minecraft:gray_stained_glass_pane
setblock ~30 ~7 ~-32 minecraft:gray_stained_glass_pane
setblock ~41 ~7 ~-32 minecraft:gray_stained_glass_pane
setblock ~30 ~7 ~-29 minecraft:gray_stained_glass_pane
setblock ~41 ~7 ~-29 minecraft:gray_stained_glass_pane
setblock ~30 ~7 ~-26 minecraft:gray_stained_glass_pane
setblock ~41 ~7 ~-26 minecraft:gray_stained_glass_pane
setblock ~30 ~7 ~-23 minecraft:gray_stained_glass_pane
setblock ~41 ~7 ~-23 minecraft:gray_stained_glass_pane
setblock ~30 ~7 ~-20 minecraft:gray_stained_glass_pane
setblock ~41 ~7 ~-20 minecraft:gray_stained_glass_pane
setblock ~32 ~11 ~-34 minecraft:gray_stained_glass_pane
setblock ~32 ~11 ~-18 minecraft:gray_stained_glass_pane
setblock ~35 ~11 ~-34 minecraft:gray_stained_glass_pane
setblock ~35 ~11 ~-18 minecraft:gray_stained_glass_pane
setblock ~38 ~11 ~-34 minecraft:gray_stained_glass_pane
setblock ~38 ~11 ~-18 minecraft:gray_stained_glass_pane
setblock ~30 ~11 ~-32 minecraft:gray_stained_glass_pane
setblock ~41 ~11 ~-32 minecraft:gray_stained_glass_pane
setblock ~30 ~11 ~-29 minecraft:gray_stained_glass_pane
setblock ~41 ~11 ~-29 minecraft:gray_stained_glass_pane
setblock ~30 ~11 ~-26 minecraft:gray_stained_glass_pane
setblock ~41 ~11 ~-26 minecraft:gray_stained_glass_pane
setblock ~30 ~11 ~-23 minecraft:gray_stained_glass_pane
setblock ~41 ~11 ~-23 minecraft:gray_stained_glass_pane
setblock ~30 ~11 ~-20 minecraft:gray_stained_glass_pane
setblock ~41 ~11 ~-20 minecraft:gray_stained_glass_pane
setblock ~32 ~15 ~-34 minecraft:gray_stained_glass_pane
setblock ~32 ~15 ~-18 minecraft:gray_stained_glass_pane
setblock ~35 ~15 ~-34 minecraft:gray_stained_glass_pane
setblock ~35 ~15 ~-18 minecraft:gray_stained_glass_pane
setblock ~38 ~15 ~-34 minecraft:gray_stained_glass_pane
setblock ~38 ~15 ~-18 minecraft:gray_stained_glass_pane
setblock ~30 ~15 ~-32 minecraft:gray_stained_glass_pane
setblock ~41 ~15 ~-32 minecraft:gray_stained_glass_pane
setblock ~30 ~15 ~-29 minecraft:gray_stained_glass_pane
setblock ~41 ~15 ~-29 minecraft:gray_stained_glass_pane
setblock ~30 ~15 ~-26 minecraft:gray_stained_glass_pane
setblock ~41 ~15 ~-26 minecraft:gray_stained_glass_pane
setblock ~30 ~15 ~-23 minecraft:gray_stained_glass_pane
setblock ~41 ~15 ~-23 minecraft:gray_stained_glass_pane
setblock ~30 ~15 ~-20 minecraft:gray_stained_glass_pane
setblock ~41 ~15 ~-20 minecraft:gray_stained_glass_pane
setblock ~32 ~19 ~-34 minecraft:gray_stained_glass_pane
setblock ~32 ~19 ~-18 minecraft:gray_stained_glass_pane
setblock ~35 ~19 ~-34 minecraft:gray_stained_glass_pane
setblock ~35 ~19 ~-18 minecraft:gray_stained_glass_pane
setblock ~38 ~19 ~-34 minecraft:gray_stained_glass_pane
setblock ~38 ~19 ~-18 minecraft:gray_stained_glass_pane
setblock ~30 ~19 ~-32 minecraft:gray_stained_glass_pane
setblock ~41 ~19 ~-32 minecraft:gray_stained_glass_pane
setblock ~30 ~19 ~-29 minecraft:gray_stained_glass_pane
setblock ~41 ~19 ~-29 minecraft:gray_stained_glass_pane
setblock ~30 ~19 ~-26 minecraft:gray_stained_glass_pane
setblock ~41 ~19 ~-26 minecraft:gray_stained_glass_pane
setblock ~30 ~19 ~-23 minecraft:gray_stained_glass_pane
setblock ~41 ~19 ~-23 minecraft:gray_stained_glass_pane
setblock ~30 ~19 ~-20 minecraft:gray_stained_glass_pane
setblock ~41 ~19 ~-20 minecraft:gray_stained_glass_pane
setblock ~36 ~2 ~-34 minecraft:dark_oak_door[half=lower]
setblock ~36 ~3 ~-34 minecraft:dark_oak_door[half=upper]
fill ~-3 ~1 ~64 ~6 ~24 ~71 minecraft:white_terracotta
fill ~-2 ~2 ~65 ~5 ~23 ~70 minecraft:air
fill ~-2 ~4 ~65 ~5 ~4 ~70 minecraft:smooth_stone
fill ~-2 ~8 ~65 ~5 ~8 ~70 minecraft:smooth_stone
fill ~-2 ~12 ~65 ~5 ~12 ~70 minecraft:smooth_stone
fill ~-2 ~16 ~65 ~5 ~16 ~70 minecraft:smooth_stone
fill ~-2 ~20 ~65 ~5 ~20 ~70 minecraft:smooth_stone
fill ~-3 ~25 ~64 ~6 ~25 ~71 minecraft:spruce_planks
setblock ~-1 ~3 ~64 minecraft:gray_stained_glass_pane
setblock ~-1 ~3 ~71 minecraft:gray_stained_glass_pane
setblock ~2 ~3 ~64 minecraft:gray_stained_glass_pane
setblock ~2 ~3 ~71 minecraft:gray_stained_glass_pane
setblock ~-3 ~3 ~66 minecraft:gray_stained_glass_pane
setblock ~6 ~3 ~66 minecraft:gray_stained_glass_pane
setblock ~-3 ~3 ~69 minecraft:gray_stained_glass_pane
setblock ~6 ~3 ~69 minecraft:gray_stained_glass_pane
setblock ~-1 ~7 ~64 minecraft:gray_stained_glass_pane
setblock ~-1 ~7 ~71 minecraft:gray_stained_glass_pane
setblock ~2 ~7 ~64 minecraft:gray_stained_glass_pane
setblock ~2 ~7 ~71 minecraft:gray_stained_glass_pane
setblock ~-3 ~7 ~66 minecraft:gray_stained_glass_pane
setblock ~6 ~7 ~66 minecraft:gray_stained_glass_pane
setblock ~-3 ~7 ~69 minecraft:gray_stained_glass_pane
setblock ~6 ~7 ~69 minecraft:gray_stained_glass_pane
setblock ~-1 ~11 ~64 minecraft:gray_stained_glass_pane
setblock ~-1 ~11 ~71 minecraft:gray_stained_glass_pane
setblock ~2 ~11 ~64 minecraft:gray_stained_glass_pane
setblock ~2 ~11 ~71 minecraft:gray_stained_glass_pane
setblock ~-3 ~11 ~66 minecraft:gray_stained_glass_pane
setblock ~6 ~11 ~66 minecraft:gray_stained_glass_pane
setblock ~-3 ~11 ~69 minecraft:gray_stained_glass_pane
setblock ~6 ~11 ~69 minecraft:gray_stained_glass_pane
setblock ~-1 ~15 ~64 minecraft:gray_stained_glass_pane
setblock ~-1 ~15 ~71 minecraft:gray_stained_glass_pane
setblock ~2 ~15 ~64 minecraft:gray_stained_glass_pane
setblock ~2 ~15 ~71 minecraft:gray_stained_glass_pane
setblock ~-3 ~15 ~66 minecraft:gray_stained_glass_pane
setblock ~6 ~15 ~66 minecraft:gray_stained_glass_pane
setblock ~-3 ~15 ~69 minecraft:gray_stained_glass_pane
setblock ~6 ~15 ~69 minecraft:gray_stained_glass_pane
setblock ~-1 ~19 ~64 minecraft:gray_stained_glass_pane
setblock ~-1 ~19 ~71 minecraft:gray_stained_glass_pane
setblock ~2 ~19 ~64 minecraft:gray_stained_glass_pane
setblock ~2 ~19 ~71 minecraft:gray_stained_glass_pane
setblock ~-3 ~19 ~66 minecraft:gray_stained_glass_pane
setblock ~6 ~19 ~66 minecraft:gray_stained_glass_pane
setblock ~-3 ~19 ~69 minecraft:gray_stained_glass_pane
setblock ~6 ~19 ~69 minecraft:gray_stained_glass_pane
setblock ~-1 ~23 ~64 minecraft:gray_stained_glass_pane
setblock ~-1 ~23 ~71 minecraft:gray_stained_glass_pane
setblock ~2 ~23 ~64 minecraft:gray_stained_glass_pane
setblock ~2 ~23 ~71 minecraft:gray_stained_glass_pane
setblock ~-3 ~23 ~66 minecraft:gray_stained_glass_pane
setblock ~6 ~23 ~66 minecraft:gray_stained_glass_pane
setblock ~-3 ~23 ~69 minecraft:gray_stained_glass_pane
setblock ~6 ~23 ~69 minecraft:gray_stained_glass_pane
setblock ~2 ~2 ~64 minecraft:dark_oak_door[half=lower]
setblock ~2 ~3 ~64 minecraft:dark_oak_door[half=upper]
fill ~-8 ~1 ~35 ~1 ~24 ~47 minecraft:bricks
fill ~-7 ~2 ~36 ~ ~23 ~46 minecraft:air
fill ~-7 ~4 ~36 ~ ~4 ~46 minecraft:smooth_stone
fill ~-7 ~8 ~36 ~ ~8 ~46 minecraft:smooth_stone
fill ~-7 ~12 ~36 ~ ~12 ~46 minecraft:smooth_stone
fill ~-7 ~16 ~36 ~ ~16 ~46 minecraft:smooth_stone
fill ~-7 ~20 ~36 ~ ~20 ~46 minecraft:smooth_stone
fill ~-8 ~25 ~35 ~1 ~25 ~47 minecraft:polished_andesite
fill ~-6 ~1 ~37 ~-1 ~28 ~45 minecraft:bricks
fill ~-5 ~2 ~38 ~-2 ~27 ~44 minecraft:air
fill ~-5 ~4 ~38 ~-2 ~4 ~44 minecraft:smooth_stone
fill ~-5 ~8 ~38 ~-2 ~8 ~44 minecraft:smooth_stone
fill ~-5 ~12 ~38 ~-2 ~12 ~44 minecraft:smooth_stone
fill ~-5 ~16 ~38 ~-2 ~16 ~44 minecraft:smooth_stone
fill ~-5 ~20 ~38 ~-2 ~20 ~44 minecraft:smooth_stone
fill ~-5 ~24 ~38 ~-2 ~24 ~44 minecraft:smooth_stone
fill ~-6 ~29 ~37 ~-1 ~29 ~45 minecraft:polished_andesite
setblock ~-6 ~3 ~35 minecraft:gray_stained_glass_pane
setblock ~-6 ~3 ~47 minecraft:gray_stained_glass_pane
setblock ~-3 ~3 ~35 minecraft:gray_stained_glass_pane
setblock ~-3 ~3 ~47 minecraft:gray_stained_glass_pane
setblock ~-8 ~3 ~37 minecraft:gray_stained_glass_pane
setblock ~1 ~3 ~37 minecraft:gray_stained_glass_pane
setblock ~-8 ~3 ~40 minecraft:gray_stained_glass_pane
setblock ~1 ~3 ~40 minecraft:gray_stained_glass_pane
setblock ~-8 ~3 ~43 minecraft:gray_stained_glass_pane
setblock ~1 ~3 ~43 minecraft:gray_stained_glass_pane
setblock ~-6 ~7 ~35 minecraft:gray_stained_glass_pane
setblock ~-6 ~7 ~47 minecraft:gray_stained_glass_pane
setblock ~-3 ~7 ~35 minecraft:gray_stained_glass_pane
setblock ~-3 ~7 ~47 minecraft:gray_stained_glass_pane
setblock ~-8 ~7 ~37 minecraft:gray_stained_glass_pane
setblock ~1 ~7 ~37 minecraft:gray_stained_glass_pane
setblock ~-8 ~7 ~40 minecraft:gray_stained_glass_pane
setblock ~1 ~7 ~40 minecraft:gray_stained_glass_pane
setblock ~-8 ~7 ~43 minecraft:gray_stained_glass_pane
setblock ~1 ~7 ~43 minecraft:gray_stained_glass_pane
setblock ~-6 ~11 ~35 minecraft:gray_stained_glass_pane
setblock ~-6 ~11 ~47 minecraft:gray_stained_glass_pane
setblock ~-3 ~11 ~35 minecraft:gray_stained_glass_pane
setblock ~-3 ~11 ~47 minecraft:gray_stained_glass_pane
setblock ~-8 ~11 ~37 minecraft:gray_stained_glass_pane
setblock ~1 ~11 ~37 minecraft:gray_stained_glass_pane
setblock ~-8 ~11 ~40 minecraft:gray_stained_glass_pane
setblock ~1 ~11 ~40 minecraft:gray_stained_glass_pane
setblock ~-8 ~11 ~43 minecraft:gray_stained_glass_pane
setblock ~1 ~11 ~43 minecraft:gray_stained_glass_pane
setblock ~-6 ~15 ~35 minecraft:gray_stained_glass_pane
setblock ~-6 ~15 ~47 minecraft:gray_stained_glass_pane
setblock ~-3 ~15 ~35 minecraft:gray_stained_glass_pane
setblock ~-3 ~15 ~47 minecraft:gray_stained_glass_pane
setblock ~-8 ~15 ~37 minecraft:gray_stained_glass_pane
setblock ~1 ~15 ~37 minecraft:gray_stained_glass_pane
setblock ~-8 ~15 ~40 minecraft:gray_stained_glass_pane
setblock ~1 ~15 ~40 minecraft:gray_stained_glass_pane
setblock ~-8 ~15 ~43 minecraft:gray_stained_glass_pane
setblock ~1 ~15 ~43 minecraft:gray_stained_glass_pane
setblock ~-6 ~19 ~35 minecraft:gray_stained_glass_pane
setblock ~-6 ~19 ~47 minecraft:gray_stained_glass_pane
setblock ~-3 ~19 ~35 minecraft:gray_stained_glass_pane
setblock ~-3 ~19 ~47 minecraft:gray_stained_glass_pane
setblock ~-8 ~19 ~37 minecraft:gray_stained_glass_pane
setblock ~1 ~19 ~37 minecraft:gray_stained_glass_pane
setblock ~-8 ~19 ~40 minecraft:gray_stained_glass_pane
setblock ~1 ~19 ~40 minecraft:gray_stained_glass_pane
setblock ~-8 ~19 ~43 minecraft:gray_stained_glass_pane
setblock ~1 ~19 ~43 minecraft:gray_stained_glass_pane
setblock ~-6 ~23 ~35 minecraft:gray_stained_glass_pane
setblock ~-6 ~23 ~47 minecraft:gray_stained_glass_pane
setblock ~-3 ~23 ~35 minecraft:gray_stained_glass_pane
setblock ~-3 ~23 ~47 minecraft:gray_stained_glass_pane
setblock ~-8 ~23 ~37 minecraft:gray_stained_glass_pane
setblock ~1 ~23 ~37 minecraft:gray_stained_glass_pane
setblock ~-8 ~23 ~40 minecraft:gray_stained_glass_pane
setblock ~1 ~23 ~40 minecraft:gray_stained_glass_pane
setblock ~-8 ~23 ~43 minecraft:gray_stained_glass_pane
setblock ~1 ~23 ~43 minecraft:gray_stained_glass_pane
setblock ~-6 ~27 ~35 minecraft:gray_stained_glass_pane
setblock ~-6 ~27 ~47 minecraft:gray_stained_glass_pane
setblock ~-3 ~27 ~35 minecraft:gray_stained_glass_pane
setblock ~-3 ~27 ~47 minecraft:gray_stained_glass_pane
setblock ~-8 ~27 ~37 minecraft:gray_stained_glass_pane
setblock ~1 ~27 ~37 minecraft:gray_stained_glass_pane
setblock ~-8 ~27 ~40 minecraft:gray_stained_glass_pane
setblock ~1 ~27 ~40 minecraft:gray_stained_glass_pane
setblock ~-8 ~27 ~43 minecraft:gray_stained_glass_pane
setblock ~1 ~27 ~43 minecraft:gray_stained_glass_pane
setblock ~-3 ~2 ~47 minecraft:dark_oak_door[half=lower]
setblock ~-3 ~3 ~47 minecraft:dark_oak_door[half=upper]
setblock ~-7 ~2 ~47 minecraft:cyan_stained_glass
setblock ~-5 ~2 ~47 minecraft:cyan_stained_glass
setblock ~-3 ~2 ~47 minecraft:cyan_stained_glass
setblock ~-1 ~2 ~47 minecraft:cyan_stained_glass
fill ~55 ~1 ~-34 ~64 ~20 ~-29 minecraft:stone_bricks
fill ~56 ~2 ~-33 ~63 ~19 ~-30 minecraft:air
fill ~56 ~4 ~-33 ~63 ~4 ~-30 minecraft:smooth_stone
fill ~56 ~8 ~-33 ~63 ~8 ~-30 minecraft:smooth_stone
fill ~56 ~12 ~-33 ~63 ~12 ~-30 minecraft:smooth_stone
fill ~56 ~16 ~-33 ~63 ~16 ~-30 minecraft:smooth_stone
fill ~55 ~21 ~-34 ~64 ~21 ~-29 minecraft:deepslate_bricks
fill ~55 ~1 ~-28 ~60 ~16 ~-24 minecraft:stone_bricks
fill ~56 ~2 ~-27 ~59 ~15 ~-25 minecraft:air
fill ~56 ~4 ~-27 ~59 ~4 ~-25 minecraft:smooth_stone
fill ~56 ~8 ~-27 ~59 ~8 ~-25 minecraft:smooth_stone
fill ~56 ~12 ~-27 ~59 ~12 ~-25 minecraft:smooth_stone
fill ~55 ~17 ~-28 ~60 ~17 ~-24 minecraft:deepslate_bricks
setblock ~57 ~3 ~-34 minecraft:gray_stained_glass_pane
setblock ~57 ~3 ~-24 minecraft:gray_stained_glass_pane
setblock ~60 ~3 ~-34 minecraft:gray_stained_glass_pane
setblock ~60 ~3 ~-24 minecraft:gray_stained_glass_pane
setblock ~55 ~3 ~-32 minecraft:gray_stained_glass_pane
setblock ~64 ~3 ~-32 minecraft:gray_stained_glass_pane
setblock ~55 ~3 ~-29 minecraft:gray_stained_glass_pane
setblock ~64 ~3 ~-29 minecraft:gray_stained_glass_pane
setblock ~55 ~3 ~-26 minecraft:gray_stained_glass_pane
setblock ~64 ~3 ~-26 minecraft:gray_stained_glass_pane
setblock ~57 ~7 ~-34 minecraft:gray_stained_glass_pane
setblock ~57 ~7 ~-24 minecraft:gray_stained_glass_pane
setblock ~60 ~7 ~-34 minecraft:gray_stained_glass_pane
setblock ~60 ~7 ~-24 minecraft:gray_stained_glass_pane
setblock ~55 ~7 ~-32 minecraft:gray_stained_glass_pane
setblock ~64 ~7 ~-32 minecraft:gray_stained_glass_pane
setblock ~55 ~7 ~-29 minecraft:gray_stained_glass_pane
setblock ~64 ~7 ~-29 minecraft:gray_stained_glass_pane
setblock ~55 ~7 ~-26 minecraft:gray_stained_glass_pane
setblock ~64 ~7 ~-26 minecraft:gray_stained_glass_pane
setblock ~57 ~11 ~-34 minecraft:gray_stained_glass_pane
setblock ~57 ~11 ~-24 minecraft:gray_stained_glass_pane
setblock ~60 ~11 ~-34 minecraft:gray_stained_glass_pane
setblock ~60 ~11 ~-24 minecraft:gray_stained_glass_pane
setblock ~55 ~11 ~-32 minecraft:gray_stained_glass_pane
setblock ~64 ~11 ~-32 minecraft:gray_stained_glass_pane
setblock ~55 ~11 ~-29 minecraft:gray_stained_glass_pane
setblock ~64 ~11 ~-29 minecraft:gray_stained_glass_pane
setblock ~55 ~11 ~-26 minecraft:gray_stained_glass_pane
setblock ~64 ~11 ~-26 minecraft:gray_stained_glass_pane
setblock ~57 ~15 ~-34 minecraft:gray_stained_glass_pane
setblock ~57 ~15 ~-24 minecraft:gray_stained_glass_pane
setblock ~60 ~15 ~-34 minecraft:gray_stained_glass_pane
setblock ~60 ~15 ~-24 minecraft:gray_stained_glass_pane
setblock ~55 ~15 ~-32 minecraft:gray_stained_glass_pane
setblock ~64 ~15 ~-32 minecraft:gray_stained_glass_pane
setblock ~55 ~15 ~-29 minecraft:gray_stained_glass_pane
setblock ~64 ~15 ~-29 minecraft:gray_stained_glass_pane
setblock ~55 ~15 ~-26 minecraft:gray_stained_glass_pane
setblock ~64 ~15 ~-26 minecraft:gray_stained_glass_pane
setblock ~57 ~19 ~-34 minecraft:gray_stained_glass_pane
setblock ~57 ~19 ~-24 minecraft:gray_stained_glass_pane
setblock ~60 ~19 ~-34 minecraft:gray_stained_glass_pane
setblock ~60 ~19 ~-24 minecraft:gray_stained_glass_pane
setblock ~55 ~19 ~-32 minecraft:gray_stained_glass_pane
setblock ~64 ~19 ~-32 minecraft:gray_stained_glass_pane
setblock ~55 ~19 ~-29 minecraft:gray_stained_glass_pane
setblock ~64 ~19 ~-29 minecraft:gray_stained_glass_pane
setblock ~55 ~19 ~-26 minecraft:gray_stained_glass_pane
setblock ~64 ~19 ~-26 minecraft:gray_stained_glass_pane
setblock ~60 ~2 ~-34 minecraft:dark_oak_door[half=lower]
setblock ~60 ~3 ~-34 minecraft:dark_oak_door[half=upper]
fill ~24 ~1 ~-54 ~33 ~20 ~-49 minecraft:white_terracotta
fill ~25 ~2 ~-53 ~32 ~19 ~-50 minecraft:air
fill ~25 ~4 ~-53 ~32 ~4 ~-50 minecraft:smooth_stone
fill ~25 ~8 ~-53 ~32 ~8 ~-50 minecraft:smooth_stone
fill ~25 ~12 ~-53 ~32 ~12 ~-50 minecraft:smooth_stone
fill ~25 ~16 ~-53 ~32 ~16 ~-50 minecraft:smooth_stone
fill ~24 ~21 ~-54 ~33 ~21 ~-49 minecraft:spruce_planks
fill ~24 ~1 ~-48 ~29 ~16 ~-45 minecraft:white_terracotta
fill ~25 ~2 ~-47 ~28 ~15 ~-46 minecraft:air
fill ~25 ~4 ~-47 ~28 ~4 ~-46 minecraft:smooth_stone
fill ~25 ~8 ~-47 ~28 ~8 ~-46 minecraft:smooth_stone
fill ~25 ~12 ~-47 ~28 ~12 ~-46 minecraft:smooth_stone
fill ~24 ~17 ~-48 ~29 ~17 ~-45 minecraft:spruce_planks
setblock ~26 ~3 ~-54 minecraft:gray_stained_glass_pane
setblock ~26 ~3 ~-45 minecraft:gray_stained_glass_pane
setblock ~29 ~3 ~-54 minecraft:gray_stained_glass_pane
setblock ~29 ~3 ~-45 minecraft:gray_stained_glass_pane
setblock ~24 ~3 ~-52 minecraft:gray_stained_glass_pane
setblock ~33 ~3 ~-52 minecraft:gray_stained_glass_pane
setblock ~24 ~3 ~-49 minecraft:gray_stained_glass_pane
setblock ~33 ~3 ~-49 minecraft:gray_stained_glass_pane
setblock ~26 ~7 ~-54 minecraft:gray_stained_glass_pane
setblock ~26 ~7 ~-45 minecraft:gray_stained_glass_pane
setblock ~29 ~7 ~-54 minecraft:gray_stained_glass_pane
setblock ~29 ~7 ~-45 minecraft:gray_stained_glass_pane
setblock ~24 ~7 ~-52 minecraft:gray_stained_glass_pane
setblock ~33 ~7 ~-52 minecraft:gray_stained_glass_pane
setblock ~24 ~7 ~-49 minecraft:gray_stained_glass_pane
setblock ~33 ~7 ~-49 minecraft:gray_stained_glass_pane
setblock ~26 ~11 ~-54 minecraft:gray_stained_glass_pane
setblock ~26 ~11 ~-45 minecraft:gray_stained_glass_pane
setblock ~29 ~11 ~-54 minecraft:gray_stained_glass_pane
setblock ~29 ~11 ~-45 minecraft:gray_stained_glass_pane
setblock ~24 ~11 ~-52 minecraft:gray_stained_glass_pane
setblock ~33 ~11 ~-52 minecraft:gray_stained_glass_pane
setblock ~24 ~11 ~-49 minecraft:gray_stained_glass_pane
setblock ~33 ~11 ~-49 minecraft:gray_stained_glass_pane
setblock ~26 ~15 ~-54 minecraft:gray_stained_glass_pane
setblock ~26 ~15 ~-45 minecraft:gray_stained_glass_pane
setblock ~29 ~15 ~-54 minecraft:gray_stained_glass_pane
setblock ~29 ~15 ~-45 minecraft:gray_stained_glass_pane
setblock ~24 ~15 ~-52 minecraft:gray_stained_glass_pane
setblock ~33 ~15 ~-52 minecraft:gray_stained_glass_pane
setblock ~24 ~15 ~-49 minecraft:gray_stained_glass_pane
setblock ~33 ~15 ~-49 minecraft:gray_stained_glass_pane
setblock ~26 ~19 ~-54 minecraft:gray_stained_glass_pane
setblock ~26 ~19 ~-45 minecraft:gray_stained_glass_pane
setblock ~29 ~19 ~-54 minecraft:gray_stained_glass_pane
setblock ~29 ~19 ~-45 minecraft:gray_stained_glass_pane
setblock ~24 ~19 ~-52 minecraft:gray_stained_glass_pane
setblock ~33 ~19 ~-52 minecraft:gray_stained_glass_pane
setblock ~24 ~19 ~-49 minecraft:gray_stained_glass_pane
setblock ~33 ~19 ~-49 minecraft:gray_stained_glass_pane
setblock ~33 ~2 ~-49 minecraft:dark_oak_door[half=lower]
setblock ~33 ~3 ~-49 minecraft:dark_oak_door[half=upper]
fill ~32 ~1 ~39 ~49 ~28 ~49 minecraft:stone_bricks
fill ~33 ~2 ~40 ~48 ~27 ~48 minecraft:air
fill ~33 ~4 ~40 ~48 ~4 ~48 minecraft:smooth_stone
fill ~33 ~8 ~40 ~48 ~8 ~48 minecraft:smooth_stone
fill ~33 ~12 ~40 ~48 ~12 ~48 minecraft:smooth_stone
fill ~33 ~16 ~40 ~48 ~16 ~48 minecraft:smooth_stone
fill ~33 ~20 ~40 ~48 ~20 ~48 minecraft:smooth_stone
fill ~33 ~24 ~40 ~48 ~24 ~48 minecraft:smooth_stone
fill ~32 ~29 ~39 ~49 ~29 ~49 minecraft:deepslate_bricks
setblock ~34 ~3 ~39 minecraft:gray_stained_glass_pane
setblock ~34 ~3 ~49 minecraft:gray_stained_glass_pane
setblock ~37 ~3 ~39 minecraft:gray_stained_glass_pane
setblock ~37 ~3 ~49 minecraft:gray_stained_glass_pane
setblock ~40 ~3 ~39 minecraft:gray_stained_glass_pane
setblock ~40 ~3 ~49 minecraft:gray_stained_glass_pane
setblock ~43 ~3 ~39 minecraft:gray_stained_glass_pane
setblock ~43 ~3 ~49 minecraft:gray_stained_glass_pane
setblock ~46 ~3 ~39 minecraft:gray_stained_glass_pane
setblock ~46 ~3 ~49 minecraft:gray_stained_glass_pane
setblock ~32 ~3 ~41 minecraft:gray_stained_glass_pane
setblock ~49 ~3 ~41 minecraft:gray_stained_glass_pane
setblock ~32 ~3 ~44 minecraft:gray_stained_glass_pane
setblock ~49 ~3 ~44 minecraft:gray_stained_glass_pane
setblock ~32 ~3 ~47 minecraft:gray_stained_glass_pane
setblock ~49 ~3 ~47 minecraft:gray_stained_glass_pane
setblock ~34 ~7 ~39 minecraft:gray_stained_glass_pane
setblock ~34 ~7 ~49 minecraft:gray_stained_glass_pane
setblock ~37 ~7 ~39 minecraft:gray_stained_glass_pane
setblock ~37 ~7 ~49 minecraft:gray_stained_glass_pane
setblock ~40 ~7 ~39 minecraft:gray_stained_glass_pane
setblock ~40 ~7 ~49 minecraft:gray_stained_glass_pane
setblock ~43 ~7 ~39 minecraft:gray_stained_glass_pane
setblock ~43 ~7 ~49 minecraft:gray_stained_glass_pane
setblock ~46 ~7 ~39 minecraft:gray_stained_glass_pane
setblock ~46 ~7 ~49 minecraft:gray_stained_glass_pane
setblock ~32 ~7 ~41 minecraft:gray_stained_glass_pane
setblock ~49 ~7 ~41 minecraft:gray_stained_glass_pane
setblock ~32 ~7 ~44 minecraft:gray_stained_glass_pane
setblock ~49 ~7 ~44 minecraft:gray_stained_glass_pane
setblock ~32 ~7 ~47 minecraft:gray_stained_glass_pane
setblock ~49 ~7 ~47 minecraft:gray_stained_glass_pane
setblock ~34 ~11 ~39 minecraft:gray_stained_glass_pane
setblock ~34 ~11 ~49 minecraft:gray_stained_glass_pane
setblock ~37 ~11 ~39 minecraft:gray_stained_glass_pane
setblock ~37 ~11 ~49 minecraft:gray_stained_glass_pane
setblock ~40 ~11 ~39 minecraft:gray_stained_glass_pane
setblock ~40 ~11 ~49 minecraft:gray_stained_glass_pane
setblock ~43 ~11 ~39 minecraft:gray_stained_glass_pane
setblock ~43 ~11 ~49 minecraft:gray_stained_glass_pane
setblock ~46 ~11 ~39 minecraft:gray_stained_glass_pane
setblock ~46 ~11 ~49 minecraft:gray_stained_glass_pane
setblock ~32 ~11 ~41 minecraft:gray_stained_glass_pane
setblock ~49 ~11 ~41 minecraft:gray_stained_glass_pane
setblock ~32 ~11 ~44 minecraft:gray_stained_glass_pane
setblock ~49 ~11 ~44 minecraft:gray_stained_glass_pane
setblock ~32 ~11 ~47 minecraft:gray_stained_glass_pane
setblock ~49 ~11 ~47 minecraft:gray_stained_glass_pane
setblock ~34 ~15 ~39 minecraft:gray_stained_glass_pane
setblock ~34 ~15 ~49 minecraft:gray_stained_glass_pane
setblock ~37 ~15 ~39 minecraft:gray_stained_glass_pane
setblock ~37 ~15 ~49 minecraft:gray_stained_glass_pane
setblock ~40 ~15 ~39 minecraft:gray_stained_glass_pane
setblock ~40 ~15 ~49 minecraft:gray_stained_glass_pane
setblock ~43 ~15 ~39 minecraft:gray_stained_glass_pane
setblock ~43 ~15 ~49 minecraft:gray_stained_glass_pane
setblock ~46 ~15 ~39 minecraft:gray_stained_glass_pane
setblock ~46 ~15 ~49 minecraft:gray_stained_glass_pane
setblock ~32 ~15 ~41 minecraft:gray_stained_glass_pane
setblock ~49 ~15 ~41 minecraft:gray_stained_glass_pane
setblock ~32 ~15 ~44 minecraft:gray_stained_glass_pane
setblock ~49 ~15 ~44 minecraft:gray_stained_glass_pane
setblock ~32 ~15 ~47 minecraft:gray_stained_glass_pane
setblock ~49 ~15 ~47 minecraft:gray_stained_glass_pane
setblock ~34 ~19 ~39 minecraft:gray_stained_glass_pane
setblock ~34 ~19 ~49 minecraft:gray_stained_glass_pane
setblock ~37 ~19 ~39 minecraft:gray_stained_glass_pane
setblock ~37 ~19 ~49 minecraft:gray_stained_glass_pane
setblock ~40 ~19 ~39 minecraft:gray_stained_glass_pane
setblock ~40 ~19 ~49 minecraft:gray_stained_glass_pane
setblock ~43 ~19 ~39 minecraft:gray_stained_glass_pane
setblock ~43 ~19 ~49 minecraft:gray_stained_glass_pane
setblock ~46 ~19 ~39 minecraft:gray_stained_glass_pane
setblock ~46 ~19 ~49 minecraft:gray_stained_glass_pane
setblock ~32 ~19 ~41 minecraft:gray_stained_glass_pane
setblock ~49 ~19 ~41 minecraft:gray_stained_glass_pane
setblock ~32 ~19 ~44 minecraft:gray_stained_glass_pane
setblock ~49 ~19 ~44 minecraft:gray_stained_glass_pane
setblock ~32 ~19 ~47 minecraft:gray_stained_glass_pane
setblock ~49 ~19 ~47 minecraft:gray_stained_glass_pane
setblock ~34 ~23 ~39 minecraft:gray_stained_glass_pane
setblock ~34 ~23 ~49 minecraft:gray_stained_glass_pane
setblock ~37 ~23 ~39 minecraft:gray_stained_glass_pane
setblock ~37 ~23 ~49 minecraft:gray_stained_glass_pane
setblock ~40 ~23 ~39 minecraft:gray_stained_glass_pane
setblock ~40 ~23 ~49 minecraft:gray_stained_glass_pane
setblock ~43 ~23 ~39 minecraft:gray_stained_glass_pane
setblock ~43 ~23 ~49 minecraft:gray_stained_glass_pane
setblock ~46 ~23 ~39 minecraft:gray_stained_glass_pane
setblock ~46 ~23 ~49 minecraft:gray_stained_glass_pane
setblock ~32 ~23 ~41 minecraft:gray_stained_glass_pane
setblock ~49 ~23 ~41 minecraft:gray_stained_glass_pane
setblock ~32 ~23 ~44 minecraft:gray_stained_glass_pane
setblock ~49 ~23 ~44 minecraft:gray_stained_glass_pane
setblock ~32 ~23 ~47 minecraft:gray_stained_glass_pane
setblock ~49 ~23 ~47 minecraft:gray_stained_glass_pane
setblock ~34 ~27 ~39 minecraft:gray_stained_glass_pane
setblock ~34 ~27 ~49 minecraft:gray_stained_glass_pane
setblock ~37 ~27 ~39 minecraft:gray_stained_glass_pane
setblock ~37 ~27 ~49 minecraft:gray_stained_glass_pane
setblock ~40 ~27 ~39 minecraft:gray_stained_glass_pane
setblock ~40 ~27 ~49 minecraft:gray_stained_glass_pane
setblock ~43 ~27 ~39 minecraft:gray_stained_glass_pane
setblock ~43 ~27 ~49 minecraft:gray_stained_glass_pane
