# Buildings 113..120
# 113 supermarket style=storefront context=collector_front facing=east
fill ~84 ~-3 ~40 ~92 ~-1 ~49 minecraft:stone
fill ~84 ~0 ~40 ~92 ~5 ~49 minecraft:bricks
fill ~85 ~1 ~41 ~91 ~4 ~48 minecraft:air
fill ~85 ~4 ~41 ~91 ~4 ~48 minecraft:smooth_stone
fill ~86 ~2 ~40 ~86 ~3 ~40 minecraft:gray_stained_glass
fill ~86 ~2 ~49 ~86 ~3 ~49 minecraft:light_gray_stained_glass
fill ~89 ~2 ~40 ~89 ~3 ~40 minecraft:gray_stained_glass
fill ~89 ~2 ~49 ~89 ~3 ~49 minecraft:light_gray_stained_glass
fill ~84 ~2 ~42 ~84 ~3 ~42 minecraft:gray_stained_glass
fill ~92 ~2 ~42 ~92 ~3 ~42 minecraft:light_gray_stained_glass
fill ~84 ~2 ~45 ~84 ~3 ~45 minecraft:gray_stained_glass
fill ~92 ~2 ~45 ~92 ~3 ~45 minecraft:light_gray_stained_glass
setblock ~92 ~1 ~44 minecraft:iron_door[half=lower,facing=east]
setblock ~92 ~2 ~44 minecraft:iron_door[half=upper,facing=east]
fill ~92 ~1 ~41 ~92 ~3 ~48 minecraft:cyan_stained_glass
setblock ~92 ~1 ~44 minecraft:iron_door[half=lower,facing=east]
setblock ~92 ~2 ~44 minecraft:iron_door[half=upper,facing=east]
setblock ~93 ~3 ~44 minecraft:red_wool
fill ~84 ~6 ~40 ~92 ~6 ~49 minecraft:deepslate_tile_slab
fill ~92 ~1 ~41 ~92 ~5 ~41 minecraft:weathered_cut_copper
fill ~92 ~1 ~45 ~92 ~5 ~45 minecraft:weathered_cut_copper
# 114 warehouse style=loading_bay context=local_front facing=south
fill ~-2 ~-3 ~-126 ~11 ~-1 ~-114 minecraft:stone
fill ~-2 ~0 ~-126 ~11 ~7 ~-114 minecraft:stone_bricks
fill ~-1 ~1 ~-125 ~10 ~6 ~-115 minecraft:air
fill ~-1 ~4 ~-125 ~10 ~4 ~-115 minecraft:smooth_stone
fill ~0 ~2 ~-126 ~0 ~3 ~-126 minecraft:gray_stained_glass
fill ~0 ~2 ~-114 ~0 ~3 ~-114 minecraft:light_gray_stained_glass
fill ~3 ~2 ~-126 ~3 ~3 ~-126 minecraft:gray_stained_glass
fill ~3 ~2 ~-114 ~3 ~3 ~-114 minecraft:light_gray_stained_glass
fill ~6 ~2 ~-126 ~6 ~3 ~-126 minecraft:gray_stained_glass
fill ~6 ~2 ~-114 ~6 ~3 ~-114 minecraft:light_gray_stained_glass
fill ~9 ~2 ~-126 ~9 ~3 ~-126 minecraft:gray_stained_glass
fill ~9 ~2 ~-114 ~9 ~3 ~-114 minecraft:light_gray_stained_glass
fill ~-2 ~2 ~-124 ~-2 ~3 ~-124 minecraft:gray_stained_glass
fill ~11 ~2 ~-124 ~11 ~3 ~-124 minecraft:light_gray_stained_glass
fill ~-2 ~2 ~-121 ~-2 ~3 ~-121 minecraft:gray_stained_glass
fill ~11 ~2 ~-121 ~11 ~3 ~-121 minecraft:light_gray_stained_glass
fill ~-2 ~2 ~-118 ~-2 ~3 ~-118 minecraft:gray_stained_glass
fill ~11 ~2 ~-118 ~11 ~3 ~-118 minecraft:light_gray_stained_glass
setblock ~3 ~1 ~-114 minecraft:iron_door[half=lower,facing=south]
setblock ~3 ~2 ~-114 minecraft:iron_door[half=upper,facing=south]
fill ~0 ~1 ~-114 ~9 ~4 ~-114 minecraft:polished_blackstone
fill ~0 ~5 ~-114 ~9 ~5 ~-114 minecraft:light_blue_stained_glass
fill ~0 ~9 ~-124 ~2 ~10 ~-122 minecraft:iron_block
fill ~-2 ~8 ~-126 ~11 ~8 ~-114 minecraft:smooth_stone_slab
fill ~9 ~5 ~-116 ~11 ~9 ~-114 minecraft:air
setblock ~9 ~5 ~-116 minecraft:cobweb
fill ~-1 ~1 ~-114 ~-1 ~7 ~-114 doomsday_decoration:ironsheetwall_2
fill ~3 ~1 ~-114 ~3 ~7 ~-114 doomsday_decoration:ironsheetwall_2
fill ~7 ~1 ~-114 ~7 ~7 ~-114 doomsday_decoration:ironsheetwall_2
# 115 detached_house style=rowhouse context=local_front facing=south
fill ~2 ~-3 ~63 ~11 ~-1 ~71 minecraft:stone
fill ~2 ~0 ~63 ~11 ~16 ~71 minecraft:smooth_sandstone
fill ~3 ~1 ~64 ~10 ~15 ~70 minecraft:air
fill ~3 ~4 ~64 ~10 ~4 ~70 minecraft:smooth_stone
fill ~3 ~8 ~64 ~10 ~8 ~70 minecraft:smooth_stone
fill ~3 ~12 ~64 ~10 ~12 ~70 minecraft:smooth_stone
fill ~4 ~2 ~63 ~4 ~3 ~63 minecraft:gray_stained_glass
fill ~4 ~2 ~71 ~4 ~3 ~71 minecraft:light_gray_stained_glass
fill ~7 ~2 ~63 ~7 ~3 ~63 minecraft:gray_stained_glass
fill ~7 ~2 ~71 ~7 ~3 ~71 minecraft:light_gray_stained_glass
fill ~2 ~2 ~65 ~2 ~3 ~65 minecraft:gray_stained_glass
fill ~11 ~2 ~65 ~11 ~3 ~65 minecraft:light_gray_stained_glass
fill ~2 ~2 ~68 ~2 ~3 ~68 minecraft:gray_stained_glass
fill ~11 ~2 ~68 ~11 ~3 ~68 minecraft:light_gray_stained_glass
fill ~4 ~6 ~63 ~4 ~7 ~63 minecraft:gray_stained_glass
fill ~4 ~6 ~71 ~4 ~7 ~71 minecraft:light_gray_stained_glass
fill ~7 ~6 ~63 ~7 ~7 ~63 minecraft:gray_stained_glass
fill ~7 ~6 ~71 ~7 ~7 ~71 minecraft:light_gray_stained_glass
fill ~2 ~6 ~65 ~2 ~7 ~65 minecraft:gray_stained_glass
fill ~11 ~6 ~65 ~11 ~7 ~65 minecraft:light_gray_stained_glass
fill ~2 ~6 ~68 ~2 ~7 ~68 minecraft:gray_stained_glass
fill ~11 ~6 ~68 ~11 ~7 ~68 minecraft:light_gray_stained_glass
fill ~4 ~10 ~63 ~4 ~11 ~63 minecraft:gray_stained_glass
fill ~4 ~10 ~71 ~4 ~11 ~71 minecraft:light_gray_stained_glass
fill ~7 ~10 ~63 ~7 ~11 ~63 minecraft:gray_stained_glass
fill ~7 ~10 ~71 ~7 ~11 ~71 minecraft:light_gray_stained_glass
fill ~2 ~10 ~65 ~2 ~11 ~65 minecraft:gray_stained_glass
fill ~11 ~10 ~65 ~11 ~11 ~65 minecraft:light_gray_stained_glass
fill ~2 ~10 ~68 ~2 ~11 ~68 minecraft:gray_stained_glass
fill ~11 ~10 ~68 ~11 ~11 ~68 minecraft:light_gray_stained_glass
fill ~4 ~14 ~63 ~4 ~15 ~63 minecraft:gray_stained_glass
fill ~4 ~14 ~71 ~4 ~15 ~71 minecraft:light_gray_stained_glass
fill ~7 ~14 ~63 ~7 ~15 ~63 minecraft:gray_stained_glass
fill ~7 ~14 ~71 ~7 ~15 ~71 minecraft:light_gray_stained_glass
fill ~2 ~14 ~65 ~2 ~15 ~65 minecraft:gray_stained_glass
fill ~11 ~14 ~65 ~11 ~15 ~65 minecraft:light_gray_stained_glass
fill ~2 ~14 ~68 ~2 ~15 ~68 minecraft:gray_stained_glass
fill ~11 ~14 ~68 ~11 ~15 ~68 minecraft:light_gray_stained_glass
setblock ~6 ~1 ~71 minecraft:iron_door[half=lower,facing=south]
setblock ~6 ~2 ~71 minecraft:iron_door[half=upper,facing=south]
fill ~2 ~17 ~63 ~11 ~17 ~71 minecraft:stone_brick_slab
fill ~3 ~18 ~64 ~10 ~18 ~70 minecraft:stone_brick_slab
setblock ~6 ~3 ~72 minecraft:dark_oak_slab[type=top]
fill ~3 ~1 ~71 ~3 ~7 ~71 minecraft:brown_terracotta
fill ~7 ~1 ~71 ~7 ~7 ~71 minecraft:brown_terracotta
# 116 workshop style=sawtooth context=local_front facing=south
fill ~-18 ~-3 ~93 ~-12 ~-1 ~100 minecraft:stone
fill ~-18 ~0 ~93 ~-12 ~9 ~100 minecraft:calcite
fill ~-17 ~1 ~94 ~-13 ~8 ~99 minecraft:air
fill ~-17 ~4 ~94 ~-13 ~4 ~99 minecraft:smooth_stone
fill ~-17 ~8 ~94 ~-13 ~8 ~99 minecraft:smooth_stone
fill ~-16 ~2 ~93 ~-16 ~3 ~93 minecraft:gray_stained_glass
fill ~-16 ~2 ~100 ~-16 ~3 ~100 minecraft:light_gray_stained_glass
fill ~-18 ~2 ~95 ~-18 ~3 ~95 minecraft:gray_stained_glass
fill ~-12 ~2 ~95 ~-12 ~3 ~95 minecraft:light_gray_stained_glass
fill ~-18 ~2 ~98 ~-18 ~3 ~98 minecraft:gray_stained_glass
fill ~-12 ~2 ~98 ~-12 ~3 ~98 minecraft:light_gray_stained_glass
fill ~-16 ~6 ~93 ~-16 ~7 ~93 minecraft:gray_stained_glass
fill ~-16 ~6 ~100 ~-16 ~7 ~100 minecraft:light_gray_stained_glass
fill ~-18 ~6 ~95 ~-18 ~7 ~95 minecraft:gray_stained_glass
fill ~-12 ~6 ~95 ~-12 ~7 ~95 minecraft:light_gray_stained_glass
fill ~-18 ~6 ~98 ~-18 ~7 ~98 minecraft:gray_stained_glass
fill ~-12 ~6 ~98 ~-12 ~7 ~98 minecraft:light_gray_stained_glass
setblock ~-15 ~1 ~100 minecraft:iron_door[half=lower,facing=south]
setblock ~-15 ~2 ~100 minecraft:iron_door[half=upper,facing=south]
fill ~-16 ~1 ~100 ~-14 ~4 ~100 minecraft:polished_blackstone
fill ~-16 ~5 ~100 ~-14 ~5 ~100 minecraft:light_blue_stained_glass
fill ~-16 ~11 ~95 ~-14 ~12 ~97 minecraft:iron_block
fill ~-18 ~10 ~93 ~-12 ~10 ~100 minecraft:stone_brick_slab
fill ~-17 ~1 ~100 ~-17 ~7 ~100 minecraft:gray_concrete
fill ~-13 ~1 ~100 ~-13 ~7 ~100 minecraft:gray_concrete
# 117 detached_house style=japanese_house context=local_front facing=north
fill ~11 ~-3 ~110 ~19 ~-1 ~118 minecraft:stone
fill ~11 ~0 ~110 ~19 ~5 ~118 minecraft:calcite
fill ~12 ~1 ~111 ~18 ~4 ~117 minecraft:air
fill ~12 ~4 ~111 ~18 ~4 ~117 minecraft:smooth_stone
fill ~13 ~2 ~110 ~13 ~3 ~110 minecraft:gray_stained_glass
fill ~13 ~2 ~118 ~13 ~3 ~118 minecraft:light_gray_stained_glass
fill ~16 ~2 ~110 ~16 ~3 ~110 minecraft:gray_stained_glass
fill ~16 ~2 ~118 ~16 ~3 ~118 minecraft:light_gray_stained_glass
fill ~11 ~2 ~112 ~11 ~3 ~112 minecraft:gray_stained_glass
fill ~19 ~2 ~112 ~19 ~3 ~112 minecraft:light_gray_stained_glass
fill ~11 ~2 ~115 ~11 ~3 ~115 minecraft:gray_stained_glass
fill ~19 ~2 ~115 ~19 ~3 ~115 minecraft:light_gray_stained_glass
setblock ~15 ~1 ~110 minecraft:iron_door[half=lower,facing=north]
setblock ~15 ~2 ~110 minecraft:iron_door[half=upper,facing=north]
fill ~11 ~6 ~110 ~19 ~6 ~118 minecraft:stone_brick_slab
fill ~12 ~7 ~111 ~18 ~7 ~117 minecraft:stone_brick_slab
setblock ~15 ~3 ~109 minecraft:dark_oak_slab[type=top]
fill ~12 ~1 ~110 ~12 ~5 ~110 minecraft:gray_concrete
fill ~16 ~1 ~110 ~16 ~5 ~110 minecraft:gray_concrete
# 118 apartment style=setback_block context=waterfront_front facing=north
fill ~110 ~-3 ~-42 ~117 ~-1 ~-31 minecraft:stone
fill ~110 ~0 ~-42 ~117 ~11 ~-31 minecraft:bricks
fill ~111 ~1 ~-41 ~116 ~10 ~-32 minecraft:air
fill ~111 ~4 ~-41 ~116 ~4 ~-32 minecraft:smooth_stone
fill ~111 ~8 ~-41 ~116 ~8 ~-32 minecraft:smooth_stone
fill ~112 ~2 ~-42 ~112 ~3 ~-42 minecraft:gray_stained_glass
fill ~112 ~2 ~-31 ~112 ~3 ~-31 minecraft:light_gray_stained_glass
fill ~115 ~2 ~-42 ~115 ~3 ~-42 minecraft:gray_stained_glass
fill ~115 ~2 ~-31 ~115 ~3 ~-31 minecraft:light_gray_stained_glass
fill ~110 ~2 ~-40 ~110 ~3 ~-40 minecraft:gray_stained_glass
fill ~117 ~2 ~-40 ~117 ~3 ~-40 minecraft:light_gray_stained_glass
fill ~110 ~2 ~-37 ~110 ~3 ~-37 minecraft:gray_stained_glass
fill ~117 ~2 ~-37 ~117 ~3 ~-37 minecraft:light_gray_stained_glass
fill ~110 ~2 ~-34 ~110 ~3 ~-34 minecraft:gray_stained_glass
fill ~117 ~2 ~-34 ~117 ~3 ~-34 minecraft:light_gray_stained_glass
fill ~112 ~6 ~-42 ~112 ~7 ~-42 minecraft:gray_stained_glass
fill ~112 ~6 ~-31 ~112 ~7 ~-31 minecraft:light_gray_stained_glass
fill ~115 ~6 ~-42 ~115 ~7 ~-42 minecraft:gray_stained_glass
fill ~115 ~6 ~-31 ~115 ~7 ~-31 minecraft:light_gray_stained_glass
fill ~110 ~6 ~-40 ~110 ~7 ~-40 minecraft:gray_stained_glass
fill ~117 ~6 ~-40 ~117 ~7 ~-40 minecraft:light_gray_stained_glass
fill ~110 ~6 ~-37 ~110 ~7 ~-37 minecraft:gray_stained_glass
fill ~117 ~6 ~-37 ~117 ~7 ~-37 minecraft:light_gray_stained_glass
fill ~110 ~6 ~-34 ~110 ~7 ~-34 minecraft:gray_stained_glass
fill ~117 ~6 ~-34 ~117 ~7 ~-34 minecraft:light_gray_stained_glass
setblock ~113 ~1 ~-42 minecraft:iron_door[half=lower,facing=north]
setblock ~113 ~2 ~-42 minecraft:iron_door[half=upper,facing=north]
fill ~110 ~7 ~-42 ~117 ~11 ~-31 minecraft:air
fill ~111 ~7 ~-41 ~116 ~11 ~-32 minecraft:bricks
fill ~112 ~8 ~-40 ~115 ~10 ~-33 minecraft:air
fill ~111 ~12 ~-41 ~116 ~12 ~-32 minecraft:deepslate_tile_slab
fill ~111 ~1 ~-42 ~111 ~7 ~-42 minecraft:weathered_cut_copper
fill ~115 ~1 ~-42 ~115 ~7 ~-42 minecraft:weathered_cut_copper
# 119 mixed_use style=mixed_facade context=arterial_front facing=south
fill ~-9 ~-3 ~-19 ~6 ~-1 ~-10 minecraft:stone
fill ~-9 ~0 ~-19 ~6 ~24 ~-10 minecraft:bricks
fill ~-8 ~1 ~-18 ~5 ~23 ~-11 minecraft:air
fill ~-8 ~4 ~-18 ~5 ~4 ~-11 minecraft:smooth_stone
fill ~-8 ~8 ~-18 ~5 ~8 ~-11 minecraft:smooth_stone
fill ~-8 ~12 ~-18 ~5 ~12 ~-11 minecraft:smooth_stone
fill ~-8 ~16 ~-18 ~5 ~16 ~-11 minecraft:smooth_stone
fill ~-8 ~20 ~-18 ~5 ~20 ~-11 minecraft:smooth_stone
fill ~-7 ~2 ~-19 ~-7 ~3 ~-19 minecraft:gray_stained_glass
fill ~-7 ~2 ~-10 ~-7 ~3 ~-10 minecraft:light_gray_stained_glass
fill ~-4 ~2 ~-19 ~-4 ~3 ~-19 minecraft:gray_stained_glass
fill ~-4 ~2 ~-10 ~-4 ~3 ~-10 minecraft:light_gray_stained_glass
fill ~-1 ~2 ~-19 ~-1 ~3 ~-19 minecraft:gray_stained_glass
fill ~-1 ~2 ~-10 ~-1 ~3 ~-10 minecraft:light_gray_stained_glass
fill ~2 ~2 ~-19 ~2 ~3 ~-19 minecraft:gray_stained_glass
fill ~2 ~2 ~-10 ~2 ~3 ~-10 minecraft:light_gray_stained_glass
fill ~-9 ~2 ~-17 ~-9 ~3 ~-17 minecraft:gray_stained_glass
fill ~6 ~2 ~-17 ~6 ~3 ~-17 minecraft:light_gray_stained_glass
fill ~-9 ~2 ~-14 ~-9 ~3 ~-14 minecraft:gray_stained_glass
fill ~6 ~2 ~-14 ~6 ~3 ~-14 minecraft:light_gray_stained_glass
fill ~-7 ~6 ~-19 ~-7 ~7 ~-19 minecraft:gray_stained_glass
fill ~-7 ~6 ~-10 ~-7 ~7 ~-10 minecraft:light_gray_stained_glass
fill ~-4 ~6 ~-19 ~-4 ~7 ~-19 minecraft:gray_stained_glass
fill ~-4 ~6 ~-10 ~-4 ~7 ~-10 minecraft:light_gray_stained_glass
fill ~-1 ~6 ~-19 ~-1 ~7 ~-19 minecraft:gray_stained_glass
fill ~-1 ~6 ~-10 ~-1 ~7 ~-10 minecraft:light_gray_stained_glass
fill ~2 ~6 ~-19 ~2 ~7 ~-19 minecraft:gray_stained_glass
fill ~2 ~6 ~-10 ~2 ~7 ~-10 minecraft:light_gray_stained_glass
fill ~-9 ~6 ~-17 ~-9 ~7 ~-17 minecraft:gray_stained_glass
fill ~6 ~6 ~-17 ~6 ~7 ~-17 minecraft:light_gray_stained_glass
fill ~-9 ~6 ~-14 ~-9 ~7 ~-14 minecraft:gray_stained_glass
fill ~6 ~6 ~-14 ~6 ~7 ~-14 minecraft:light_gray_stained_glass
fill ~-7 ~10 ~-19 ~-7 ~11 ~-19 minecraft:gray_stained_glass
fill ~-7 ~10 ~-10 ~-7 ~11 ~-10 minecraft:light_gray_stained_glass
fill ~-4 ~10 ~-19 ~-4 ~11 ~-19 minecraft:gray_stained_glass
fill ~-4 ~10 ~-10 ~-4 ~11 ~-10 minecraft:light_gray_stained_glass
fill ~-1 ~10 ~-19 ~-1 ~11 ~-19 minecraft:gray_stained_glass
fill ~-1 ~10 ~-10 ~-1 ~11 ~-10 minecraft:light_gray_stained_glass
fill ~2 ~10 ~-19 ~2 ~11 ~-19 minecraft:gray_stained_glass
fill ~2 ~10 ~-10 ~2 ~11 ~-10 minecraft:light_gray_stained_glass
fill ~-9 ~10 ~-17 ~-9 ~11 ~-17 minecraft:gray_stained_glass
fill ~6 ~10 ~-17 ~6 ~11 ~-17 minecraft:light_gray_stained_glass
fill ~-9 ~10 ~-14 ~-9 ~11 ~-14 minecraft:gray_stained_glass
fill ~6 ~10 ~-14 ~6 ~11 ~-14 minecraft:light_gray_stained_glass
fill ~-7 ~14 ~-19 ~-7 ~15 ~-19 minecraft:gray_stained_glass
fill ~-7 ~14 ~-10 ~-7 ~15 ~-10 minecraft:light_gray_stained_glass
fill ~-4 ~14 ~-19 ~-4 ~15 ~-19 minecraft:gray_stained_glass
fill ~-4 ~14 ~-10 ~-4 ~15 ~-10 minecraft:light_gray_stained_glass
fill ~-1 ~14 ~-19 ~-1 ~15 ~-19 minecraft:gray_stained_glass
fill ~-1 ~14 ~-10 ~-1 ~15 ~-10 minecraft:light_gray_stained_glass
fill ~2 ~14 ~-19 ~2 ~15 ~-19 minecraft:gray_stained_glass
fill ~2 ~14 ~-10 ~2 ~15 ~-10 minecraft:light_gray_stained_glass
fill ~-9 ~14 ~-17 ~-9 ~15 ~-17 minecraft:gray_stained_glass
fill ~6 ~14 ~-17 ~6 ~15 ~-17 minecraft:light_gray_stained_glass
fill ~-9 ~14 ~-14 ~-9 ~15 ~-14 minecraft:gray_stained_glass
fill ~6 ~14 ~-14 ~6 ~15 ~-14 minecraft:light_gray_stained_glass
fill ~-7 ~18 ~-19 ~-7 ~19 ~-19 minecraft:gray_stained_glass
fill ~-7 ~18 ~-10 ~-7 ~19 ~-10 minecraft:light_gray_stained_glass
fill ~-4 ~18 ~-19 ~-4 ~19 ~-19 minecraft:gray_stained_glass
fill ~-4 ~18 ~-10 ~-4 ~19 ~-10 minecraft:light_gray_stained_glass
fill ~-1 ~18 ~-19 ~-1 ~19 ~-19 minecraft:gray_stained_glass
fill ~-1 ~18 ~-10 ~-1 ~19 ~-10 minecraft:light_gray_stained_glass
fill ~2 ~18 ~-19 ~2 ~19 ~-19 minecraft:gray_stained_glass
fill ~2 ~18 ~-10 ~2 ~19 ~-10 minecraft:light_gray_stained_glass
fill ~-9 ~18 ~-17 ~-9 ~19 ~-17 minecraft:gray_stained_glass
fill ~6 ~18 ~-17 ~6 ~19 ~-17 minecraft:light_gray_stained_glass
fill ~-9 ~18 ~-14 ~-9 ~19 ~-14 minecraft:gray_stained_glass
fill ~6 ~18 ~-14 ~6 ~19 ~-14 minecraft:light_gray_stained_glass
fill ~-7 ~22 ~-19 ~-7 ~23 ~-19 minecraft:gray_stained_glass
fill ~-7 ~22 ~-10 ~-7 ~23 ~-10 minecraft:light_gray_stained_glass
fill ~-4 ~22 ~-19 ~-4 ~23 ~-19 minecraft:gray_stained_glass
fill ~-4 ~22 ~-10 ~-4 ~23 ~-10 minecraft:light_gray_stained_glass
fill ~-1 ~22 ~-19 ~-1 ~23 ~-19 minecraft:gray_stained_glass
fill ~-1 ~22 ~-10 ~-1 ~23 ~-10 minecraft:light_gray_stained_glass
fill ~2 ~22 ~-19 ~2 ~23 ~-19 minecraft:gray_stained_glass
fill ~2 ~22 ~-10 ~2 ~23 ~-10 minecraft:light_gray_stained_glass
fill ~-9 ~22 ~-17 ~-9 ~23 ~-17 minecraft:gray_stained_glass
fill ~6 ~22 ~-17 ~6 ~23 ~-17 minecraft:light_gray_stained_glass
fill ~-9 ~22 ~-14 ~-9 ~23 ~-14 minecraft:gray_stained_glass
fill ~6 ~22 ~-14 ~6 ~23 ~-14 minecraft:light_gray_stained_glass
setblock ~-4 ~1 ~-10 minecraft:iron_door[half=lower,facing=south]
setblock ~-4 ~2 ~-10 minecraft:iron_door[half=upper,facing=south]
fill ~-9 ~25 ~-19 ~6 ~25 ~-10 minecraft:deepslate_tile_slab
fill ~-8 ~1 ~-10 ~-8 ~7 ~-10 doomsday_decoration:redbrick
fill ~-4 ~1 ~-10 ~-4 ~7 ~-10 doomsday_decoration:redbrick
fill ~0 ~1 ~-10 ~0 ~7 ~-10 doomsday_decoration:redbrick
fill ~4 ~1 ~-10 ~4 ~7 ~-10 doomsday_decoration:redbrick
fill ~-8 ~6 ~-18 ~5 ~24 ~-11 minecraft:bricks
fill ~-7 ~7 ~-17 ~4 ~23 ~-12 minecraft:air
setblock ~-7 ~3 ~-10 minecraft:red_carpet
setblock ~-2 ~3 ~-10 minecraft:red_carpet
setblock ~3 ~3 ~-10 minecraft:red_carpet
# 120 supermarket style=corner_store context=collector_front facing=north
fill ~-94 ~-3 ~114 ~-88 ~-1 ~125 minecraft:stone
fill ~-94 ~0 ~114 ~-88 ~5 ~125 minecraft:mud_bricks
fill ~-93 ~1 ~115 ~-89 ~4 ~124 minecraft:air
fill ~-93 ~4 ~115 ~-89 ~4 ~124 minecraft:smooth_stone
fill ~-92 ~2 ~114 ~-92 ~3 ~114 minecraft:gray_stained_glass
fill ~-92 ~2 ~125 ~-92 ~3 ~125 minecraft:light_gray_stained_glass
fill ~-94 ~2 ~116 ~-94 ~3 ~116 minecraft:gray_stained_glass
fill ~-88 ~2 ~116 ~-88 ~3 ~116 minecraft:light_gray_stained_glass
fill ~-94 ~2 ~119 ~-94 ~3 ~119 minecraft:gray_stained_glass
fill ~-88 ~2 ~119 ~-88 ~3 ~119 minecraft:light_gray_stained_glass
fill ~-94 ~2 ~122 ~-94 ~3 ~122 minecraft:gray_stained_glass
fill ~-88 ~2 ~122 ~-88 ~3 ~122 minecraft:light_gray_stained_glass
setblock ~-91 ~1 ~114 minecraft:iron_door[half=lower,facing=north]
setblock ~-91 ~2 ~114 minecraft:iron_door[half=upper,facing=north]
fill ~-93 ~1 ~114 ~-89 ~3 ~114 minecraft:cyan_stained_glass
setblock ~-91 ~1 ~114 minecraft:iron_door[half=lower,facing=north]
setblock ~-91 ~2 ~114 minecraft:iron_door[half=upper,facing=north]
setblock ~-91 ~3 ~113 minecraft:red_wool
fill ~-94 ~6 ~114 ~-88 ~6 ~125 minecraft:deepslate_tile_slab
fill ~-93 ~1 ~114 ~-93 ~5 ~114 minecraft:spruce_planks
fill ~-89 ~1 ~114 ~-89 ~5 ~114 minecraft:spruce_planks
