# Buildings 153..160
# 153 supermarket style=arcade_shop context=collector_front facing=east
fill ~-125 ~-3 ~67 ~-118 ~-1 ~73 minecraft:stone
fill ~-125 ~0 ~67 ~-118 ~11 ~73 minecraft:mud_bricks
fill ~-124 ~1 ~68 ~-119 ~10 ~72 minecraft:air
fill ~-124 ~4 ~68 ~-119 ~4 ~72 minecraft:smooth_stone
fill ~-124 ~8 ~68 ~-119 ~8 ~72 minecraft:smooth_stone
fill ~-123 ~2 ~67 ~-123 ~3 ~67 minecraft:gray_stained_glass
fill ~-123 ~2 ~73 ~-123 ~3 ~73 minecraft:light_gray_stained_glass
fill ~-120 ~2 ~67 ~-120 ~3 ~67 minecraft:gray_stained_glass
fill ~-120 ~2 ~73 ~-120 ~3 ~73 minecraft:light_gray_stained_glass
fill ~-125 ~2 ~69 ~-125 ~3 ~69 minecraft:gray_stained_glass
fill ~-118 ~2 ~69 ~-118 ~3 ~69 minecraft:light_gray_stained_glass
fill ~-123 ~6 ~67 ~-123 ~7 ~67 minecraft:gray_stained_glass
fill ~-123 ~6 ~73 ~-123 ~7 ~73 minecraft:light_gray_stained_glass
fill ~-120 ~6 ~67 ~-120 ~7 ~67 minecraft:gray_stained_glass
fill ~-120 ~6 ~73 ~-120 ~7 ~73 minecraft:light_gray_stained_glass
fill ~-125 ~6 ~69 ~-125 ~7 ~69 minecraft:gray_stained_glass
fill ~-118 ~6 ~69 ~-118 ~7 ~69 minecraft:light_gray_stained_glass
setblock ~-118 ~1 ~70 minecraft:iron_door[half=lower,facing=east]
setblock ~-118 ~2 ~70 minecraft:iron_door[half=upper,facing=east]
fill ~-118 ~1 ~68 ~-118 ~3 ~72 minecraft:cyan_stained_glass
setblock ~-118 ~1 ~70 minecraft:iron_door[half=lower,facing=east]
setblock ~-118 ~2 ~70 minecraft:iron_door[half=upper,facing=east]
setblock ~-117 ~3 ~70 minecraft:red_wool
fill ~-118 ~4 ~68 ~-118 ~4 ~72 minecraft:spruce_planks
fill ~-125 ~12 ~67 ~-118 ~12 ~73 minecraft:deepslate_tile_slab
fill ~-123 ~13 ~69 ~-121 ~14 ~71 minecraft:light_gray_concrete
setblock ~-120 ~13 ~70 minecraft:lightning_rod
# 154 factory style=sawtooth context=collector_front facing=east
fill ~-105 ~-3 ~-91 ~-96 ~-1 ~-82 minecraft:stone
fill ~-105 ~0 ~-91 ~-96 ~8 ~-82 minecraft:bricks
fill ~-104 ~1 ~-90 ~-97 ~7 ~-83 minecraft:air
fill ~-104 ~4 ~-90 ~-97 ~4 ~-83 minecraft:smooth_stone
fill ~-103 ~2 ~-91 ~-103 ~3 ~-91 minecraft:gray_stained_glass
fill ~-103 ~2 ~-82 ~-103 ~3 ~-82 minecraft:light_gray_stained_glass
fill ~-100 ~2 ~-91 ~-100 ~3 ~-91 minecraft:gray_stained_glass
fill ~-100 ~2 ~-82 ~-100 ~3 ~-82 minecraft:light_gray_stained_glass
fill ~-105 ~2 ~-89 ~-105 ~3 ~-89 minecraft:gray_stained_glass
fill ~-96 ~2 ~-89 ~-96 ~3 ~-89 minecraft:light_gray_stained_glass
fill ~-105 ~2 ~-86 ~-105 ~3 ~-86 minecraft:gray_stained_glass
fill ~-96 ~2 ~-86 ~-96 ~3 ~-86 minecraft:light_gray_stained_glass
fill ~-103 ~6 ~-91 ~-103 ~7 ~-91 minecraft:gray_stained_glass
fill ~-103 ~6 ~-82 ~-103 ~7 ~-82 minecraft:light_gray_stained_glass
fill ~-100 ~6 ~-91 ~-100 ~7 ~-91 minecraft:gray_stained_glass
fill ~-100 ~6 ~-82 ~-100 ~7 ~-82 minecraft:light_gray_stained_glass
fill ~-105 ~6 ~-89 ~-105 ~7 ~-89 minecraft:gray_stained_glass
fill ~-96 ~6 ~-89 ~-96 ~7 ~-89 minecraft:light_gray_stained_glass
fill ~-105 ~6 ~-86 ~-105 ~7 ~-86 minecraft:gray_stained_glass
fill ~-96 ~6 ~-86 ~-96 ~7 ~-86 minecraft:light_gray_stained_glass
setblock ~-96 ~1 ~-87 minecraft:iron_door[half=lower,facing=east]
setblock ~-96 ~2 ~-87 minecraft:iron_door[half=upper,facing=east]
fill ~-96 ~1 ~-89 ~-96 ~4 ~-84 minecraft:polished_blackstone
fill ~-96 ~5 ~-89 ~-96 ~5 ~-84 minecraft:light_blue_stained_glass
fill ~-103 ~10 ~-89 ~-101 ~11 ~-87 minecraft:iron_block
fill ~-105 ~9 ~-91 ~-96 ~9 ~-82 minecraft:deepslate_tile_slab
# 155 shop_house style=storefront context=collector_front facing=south
fill ~-110 ~-3 ~3 ~-105 ~-1 ~9 minecraft:stone
fill ~-110 ~0 ~3 ~-105 ~5 ~9 minecraft:mud_bricks
fill ~-109 ~1 ~4 ~-106 ~4 ~8 minecraft:air
fill ~-109 ~4 ~4 ~-106 ~4 ~8 minecraft:smooth_stone
fill ~-108 ~2 ~3 ~-108 ~3 ~3 minecraft:gray_stained_glass
fill ~-108 ~2 ~9 ~-108 ~3 ~9 minecraft:light_gray_stained_glass
fill ~-110 ~2 ~5 ~-110 ~3 ~5 minecraft:gray_stained_glass
fill ~-105 ~2 ~5 ~-105 ~3 ~5 minecraft:light_gray_stained_glass
setblock ~-108 ~1 ~9 minecraft:iron_door[half=lower,facing=south]
setblock ~-108 ~2 ~9 minecraft:iron_door[half=upper,facing=south]
fill ~-109 ~1 ~9 ~-106 ~3 ~9 minecraft:cyan_stained_glass
setblock ~-108 ~1 ~9 minecraft:iron_door[half=lower,facing=south]
setblock ~-108 ~2 ~9 minecraft:iron_door[half=upper,facing=south]
setblock ~-108 ~3 ~10 minecraft:red_wool
fill ~-110 ~6 ~3 ~-105 ~6 ~9 minecraft:deepslate_tile_slab
# 156 clinic style=balcony_block context=collector_front facing=north
fill ~-57 ~-3 ~26 ~-51 ~-1 ~33 minecraft:stone
fill ~-57 ~0 ~26 ~-51 ~16 ~33 minecraft:light_gray_concrete
fill ~-56 ~1 ~27 ~-52 ~15 ~32 minecraft:air
fill ~-56 ~4 ~27 ~-52 ~4 ~32 minecraft:smooth_stone
fill ~-56 ~8 ~27 ~-52 ~8 ~32 minecraft:smooth_stone
fill ~-56 ~12 ~27 ~-52 ~12 ~32 minecraft:smooth_stone
fill ~-55 ~2 ~26 ~-55 ~3 ~26 minecraft:gray_stained_glass
fill ~-55 ~2 ~33 ~-55 ~3 ~33 minecraft:light_gray_stained_glass
fill ~-57 ~2 ~28 ~-57 ~3 ~28 minecraft:gray_stained_glass
fill ~-51 ~2 ~28 ~-51 ~3 ~28 minecraft:light_gray_stained_glass
fill ~-57 ~2 ~31 ~-57 ~3 ~31 minecraft:gray_stained_glass
fill ~-51 ~2 ~31 ~-51 ~3 ~31 minecraft:light_gray_stained_glass
fill ~-55 ~6 ~26 ~-55 ~7 ~26 minecraft:gray_stained_glass
fill ~-55 ~6 ~33 ~-55 ~7 ~33 minecraft:light_gray_stained_glass
fill ~-57 ~6 ~28 ~-57 ~7 ~28 minecraft:gray_stained_glass
fill ~-51 ~6 ~28 ~-51 ~7 ~28 minecraft:light_gray_stained_glass
fill ~-57 ~6 ~31 ~-57 ~7 ~31 minecraft:gray_stained_glass
fill ~-51 ~6 ~31 ~-51 ~7 ~31 minecraft:light_gray_stained_glass
fill ~-55 ~10 ~26 ~-55 ~11 ~26 minecraft:gray_stained_glass
fill ~-55 ~10 ~33 ~-55 ~11 ~33 minecraft:light_gray_stained_glass
fill ~-57 ~10 ~28 ~-57 ~11 ~28 minecraft:gray_stained_glass
fill ~-51 ~10 ~28 ~-51 ~11 ~28 minecraft:light_gray_stained_glass
fill ~-57 ~10 ~31 ~-57 ~11 ~31 minecraft:gray_stained_glass
fill ~-51 ~10 ~31 ~-51 ~11 ~31 minecraft:light_gray_stained_glass
fill ~-55 ~14 ~26 ~-55 ~15 ~26 minecraft:gray_stained_glass
fill ~-55 ~14 ~33 ~-55 ~15 ~33 minecraft:light_gray_stained_glass
fill ~-57 ~14 ~28 ~-57 ~15 ~28 minecraft:gray_stained_glass
fill ~-51 ~14 ~28 ~-51 ~15 ~28 minecraft:light_gray_stained_glass
fill ~-57 ~14 ~31 ~-57 ~15 ~31 minecraft:gray_stained_glass
fill ~-51 ~14 ~31 ~-51 ~15 ~31 minecraft:light_gray_stained_glass
setblock ~-54 ~1 ~26 minecraft:iron_door[half=lower,facing=north]
setblock ~-54 ~2 ~26 minecraft:iron_door[half=upper,facing=north]
fill ~-55 ~4 ~25 ~-53 ~4 ~25 minecraft:smooth_stone_slab
fill ~-55 ~8 ~25 ~-53 ~8 ~25 minecraft:smooth_stone_slab
fill ~-55 ~12 ~25 ~-53 ~12 ~25 minecraft:smooth_stone_slab
fill ~-57 ~17 ~26 ~-51 ~17 ~33 minecraft:smooth_stone_slab
fill ~-55 ~18 ~28 ~-53 ~19 ~30 minecraft:light_gray_concrete
setblock ~-52 ~18 ~29 minecraft:lightning_rod
# 157 restaurant style=storefront context=collector_front facing=north
fill ~-11 ~-3 ~98 ~-5 ~-1 ~104 minecraft:stone
fill ~-11 ~0 ~98 ~-5 ~5 ~104 minecraft:white_terracotta
fill ~-10 ~1 ~99 ~-6 ~4 ~103 minecraft:air
fill ~-10 ~4 ~99 ~-6 ~4 ~103 minecraft:smooth_stone
fill ~-9 ~2 ~98 ~-9 ~3 ~98 minecraft:gray_stained_glass
fill ~-9 ~2 ~104 ~-9 ~3 ~104 minecraft:light_gray_stained_glass
fill ~-11 ~2 ~100 ~-11 ~3 ~100 minecraft:gray_stained_glass
fill ~-5 ~2 ~100 ~-5 ~3 ~100 minecraft:light_gray_stained_glass
setblock ~-8 ~1 ~98 minecraft:iron_door[half=lower,facing=north]
setblock ~-8 ~2 ~98 minecraft:iron_door[half=upper,facing=north]
fill ~-10 ~1 ~98 ~-6 ~3 ~98 minecraft:cyan_stained_glass
setblock ~-8 ~1 ~98 minecraft:iron_door[half=lower,facing=north]
setblock ~-8 ~2 ~98 minecraft:iron_door[half=upper,facing=north]
setblock ~-8 ~3 ~97 minecraft:red_wool
fill ~-11 ~6 ~98 ~-5 ~6 ~104 minecraft:dark_oak_slab
# 158 restaurant style=arcade_shop context=waterfront_front facing=north
fill ~100 ~-3 ~52 ~105 ~-1 ~58 minecraft:stone
fill ~100 ~0 ~52 ~105 ~7 ~58 minecraft:white_concrete
fill ~101 ~1 ~53 ~104 ~6 ~57 minecraft:air
fill ~101 ~4 ~53 ~104 ~4 ~57 minecraft:smooth_stone
fill ~102 ~2 ~52 ~102 ~3 ~52 minecraft:gray_stained_glass
fill ~102 ~2 ~58 ~102 ~3 ~58 minecraft:light_gray_stained_glass
fill ~100 ~2 ~54 ~100 ~3 ~54 minecraft:gray_stained_glass
fill ~105 ~2 ~54 ~105 ~3 ~54 minecraft:light_gray_stained_glass
setblock ~102 ~1 ~52 minecraft:iron_door[half=lower,facing=north]
setblock ~102 ~2 ~52 minecraft:iron_door[half=upper,facing=north]
fill ~101 ~1 ~52 ~104 ~3 ~52 minecraft:cyan_stained_glass
setblock ~102 ~1 ~52 minecraft:iron_door[half=lower,facing=north]
setblock ~102 ~2 ~52 minecraft:iron_door[half=upper,facing=north]
setblock ~102 ~3 ~51 minecraft:red_wool
fill ~101 ~4 ~52 ~104 ~4 ~52 minecraft:cyan_terracotta
fill ~100 ~8 ~52 ~105 ~8 ~58 minecraft:smooth_stone_slab
# 159 restaurant style=storefront context=collector_front facing=north
fill ~-124 ~-3 ~24 ~-116 ~-1 ~30 minecraft:stone
fill ~-124 ~0 ~24 ~-116 ~9 ~30 minecraft:calcite
fill ~-123 ~1 ~25 ~-117 ~8 ~29 minecraft:air
fill ~-123 ~4 ~25 ~-117 ~4 ~29 minecraft:smooth_stone
fill ~-123 ~8 ~25 ~-117 ~8 ~29 minecraft:smooth_stone
fill ~-122 ~2 ~24 ~-122 ~3 ~24 minecraft:gray_stained_glass
fill ~-122 ~2 ~30 ~-122 ~3 ~30 minecraft:light_gray_stained_glass
fill ~-119 ~2 ~24 ~-119 ~3 ~24 minecraft:gray_stained_glass
fill ~-119 ~2 ~30 ~-119 ~3 ~30 minecraft:light_gray_stained_glass
fill ~-124 ~2 ~26 ~-124 ~3 ~26 minecraft:gray_stained_glass
fill ~-116 ~2 ~26 ~-116 ~3 ~26 minecraft:light_gray_stained_glass
fill ~-122 ~6 ~24 ~-122 ~7 ~24 minecraft:gray_stained_glass
fill ~-122 ~6 ~30 ~-122 ~7 ~30 minecraft:light_gray_stained_glass
fill ~-119 ~6 ~24 ~-119 ~7 ~24 minecraft:gray_stained_glass
fill ~-119 ~6 ~30 ~-119 ~7 ~30 minecraft:light_gray_stained_glass
fill ~-124 ~6 ~26 ~-124 ~7 ~26 minecraft:gray_stained_glass
fill ~-116 ~6 ~26 ~-116 ~7 ~26 minecraft:light_gray_stained_glass
setblock ~-120 ~1 ~24 minecraft:iron_door[half=lower,facing=north]
setblock ~-120 ~2 ~24 minecraft:iron_door[half=upper,facing=north]
fill ~-123 ~1 ~24 ~-117 ~3 ~24 minecraft:cyan_stained_glass
setblock ~-120 ~1 ~24 minecraft:iron_door[half=lower,facing=north]
setblock ~-120 ~2 ~24 minecraft:iron_door[half=upper,facing=north]
setblock ~-120 ~3 ~23 minecraft:red_wool
fill ~-124 ~10 ~24 ~-116 ~10 ~30 minecraft:stone_brick_slab
fill ~-122 ~11 ~26 ~-120 ~12 ~28 minecraft:light_gray_concrete
setblock ~-119 ~11 ~27 minecraft:lightning_rod
# 160 waterfront_hotel style=setback_tower context=waterfront_front facing=west
fill ~103 ~-3 ~37 ~108 ~-1 ~44 minecraft:stone
fill ~103 ~0 ~37 ~108 ~11 ~44 minecraft:bricks
fill ~104 ~1 ~38 ~107 ~10 ~43 minecraft:air
fill ~104 ~4 ~38 ~107 ~4 ~43 minecraft:smooth_stone
fill ~104 ~8 ~38 ~107 ~8 ~43 minecraft:smooth_stone
fill ~105 ~2 ~37 ~105 ~3 ~37 minecraft:gray_stained_glass
fill ~105 ~2 ~44 ~105 ~3 ~44 minecraft:light_gray_stained_glass
fill ~103 ~2 ~39 ~103 ~3 ~39 minecraft:gray_stained_glass
fill ~108 ~2 ~39 ~108 ~3 ~39 minecraft:light_gray_stained_glass
fill ~103 ~2 ~42 ~103 ~3 ~42 minecraft:gray_stained_glass
fill ~108 ~2 ~42 ~108 ~3 ~42 minecraft:light_gray_stained_glass
fill ~105 ~6 ~37 ~105 ~7 ~37 minecraft:gray_stained_glass
fill ~105 ~6 ~44 ~105 ~7 ~44 minecraft:light_gray_stained_glass
fill ~103 ~6 ~39 ~103 ~7 ~39 minecraft:gray_stained_glass
fill ~108 ~6 ~39 ~108 ~7 ~39 minecraft:light_gray_stained_glass
fill ~103 ~6 ~42 ~103 ~7 ~42 minecraft:gray_stained_glass
fill ~108 ~6 ~42 ~108 ~7 ~42 minecraft:light_gray_stained_glass
setblock ~103 ~1 ~40 minecraft:iron_door[half=lower,facing=west]
setblock ~103 ~2 ~40 minecraft:iron_door[half=upper,facing=west]
fill ~103 ~7 ~37 ~108 ~11 ~44 minecraft:air
fill ~104 ~7 ~38 ~107 ~11 ~43 minecraft:bricks
fill ~105 ~8 ~39 ~106 ~10 ~42 minecraft:air
fill ~104 ~12 ~38 ~107 ~12 ~43 minecraft:deepslate_tile_slab
