# Buildings 65..72
# 065 detached_house style=rowhouse context=local_front facing=south
fill ~33 ~-3 ~90 ~38 ~-1 ~100 minecraft:stone
fill ~33 ~0 ~90 ~38 ~9 ~100 minecraft:calcite
fill ~34 ~1 ~91 ~37 ~8 ~99 minecraft:air
fill ~34 ~4 ~91 ~37 ~4 ~99 minecraft:smooth_stone
fill ~34 ~8 ~91 ~37 ~8 ~99 minecraft:smooth_stone
fill ~35 ~2 ~90 ~35 ~3 ~90 minecraft:gray_stained_glass
fill ~35 ~2 ~100 ~35 ~3 ~100 minecraft:light_gray_stained_glass
fill ~33 ~2 ~92 ~33 ~3 ~92 minecraft:gray_stained_glass
fill ~38 ~2 ~92 ~38 ~3 ~92 minecraft:light_gray_stained_glass
fill ~33 ~2 ~95 ~33 ~3 ~95 minecraft:gray_stained_glass
fill ~38 ~2 ~95 ~38 ~3 ~95 minecraft:light_gray_stained_glass
fill ~33 ~2 ~98 ~33 ~3 ~98 minecraft:gray_stained_glass
fill ~38 ~2 ~98 ~38 ~3 ~98 minecraft:light_gray_stained_glass
fill ~35 ~6 ~90 ~35 ~7 ~90 minecraft:gray_stained_glass
fill ~35 ~6 ~100 ~35 ~7 ~100 minecraft:light_gray_stained_glass
fill ~33 ~6 ~92 ~33 ~7 ~92 minecraft:gray_stained_glass
fill ~38 ~6 ~92 ~38 ~7 ~92 minecraft:light_gray_stained_glass
fill ~33 ~6 ~95 ~33 ~7 ~95 minecraft:gray_stained_glass
fill ~38 ~6 ~95 ~38 ~7 ~95 minecraft:light_gray_stained_glass
fill ~33 ~6 ~98 ~33 ~7 ~98 minecraft:gray_stained_glass
fill ~38 ~6 ~98 ~38 ~7 ~98 minecraft:light_gray_stained_glass
setblock ~35 ~1 ~100 minecraft:iron_door[half=lower,facing=south]
setblock ~35 ~2 ~100 minecraft:iron_door[half=upper,facing=south]
fill ~33 ~10 ~90 ~38 ~10 ~100 minecraft:stone_brick_slab
fill ~34 ~11 ~91 ~37 ~11 ~99 minecraft:stone_brick_slab
setblock ~35 ~3 ~101 minecraft:dark_oak_slab[type=top]
fill ~34 ~1 ~100 ~34 ~7 ~100 minecraft:gray_concrete
# 066 supermarket style=corner_store context=collector_front facing=south
fill ~-109 ~-3 ~8 ~-101 ~-1 ~15 minecraft:stone
fill ~-109 ~0 ~8 ~-101 ~11 ~15 minecraft:mud_bricks
fill ~-108 ~1 ~9 ~-102 ~10 ~14 minecraft:air
fill ~-108 ~4 ~9 ~-102 ~4 ~14 minecraft:smooth_stone
fill ~-108 ~8 ~9 ~-102 ~8 ~14 minecraft:smooth_stone
fill ~-107 ~2 ~8 ~-107 ~3 ~8 minecraft:gray_stained_glass
fill ~-107 ~2 ~15 ~-107 ~3 ~15 minecraft:light_gray_stained_glass
fill ~-104 ~2 ~8 ~-104 ~3 ~8 minecraft:gray_stained_glass
fill ~-104 ~2 ~15 ~-104 ~3 ~15 minecraft:light_gray_stained_glass
fill ~-109 ~2 ~10 ~-109 ~3 ~10 minecraft:gray_stained_glass
fill ~-101 ~2 ~10 ~-101 ~3 ~10 minecraft:light_gray_stained_glass
fill ~-109 ~2 ~13 ~-109 ~3 ~13 minecraft:gray_stained_glass
fill ~-101 ~2 ~13 ~-101 ~3 ~13 minecraft:light_gray_stained_glass
fill ~-107 ~6 ~8 ~-107 ~7 ~8 minecraft:gray_stained_glass
fill ~-107 ~6 ~15 ~-107 ~7 ~15 minecraft:light_gray_stained_glass
fill ~-104 ~6 ~8 ~-104 ~7 ~8 minecraft:gray_stained_glass
fill ~-104 ~6 ~15 ~-104 ~7 ~15 minecraft:light_gray_stained_glass
fill ~-109 ~6 ~10 ~-109 ~7 ~10 minecraft:gray_stained_glass
fill ~-101 ~6 ~10 ~-101 ~7 ~10 minecraft:light_gray_stained_glass
fill ~-109 ~6 ~13 ~-109 ~7 ~13 minecraft:gray_stained_glass
fill ~-101 ~6 ~13 ~-101 ~7 ~13 minecraft:light_gray_stained_glass
setblock ~-105 ~1 ~15 minecraft:iron_door[half=lower,facing=south]
setblock ~-105 ~2 ~15 minecraft:iron_door[half=upper,facing=south]
fill ~-108 ~1 ~15 ~-102 ~3 ~15 minecraft:cyan_stained_glass
setblock ~-105 ~1 ~15 minecraft:iron_door[half=lower,facing=south]
setblock ~-105 ~2 ~15 minecraft:iron_door[half=upper,facing=south]
setblock ~-105 ~3 ~16 minecraft:red_wool
fill ~-109 ~12 ~8 ~-101 ~12 ~15 minecraft:deepslate_tile_slab
fill ~-107 ~13 ~10 ~-105 ~14 ~12 minecraft:light_gray_concrete
setblock ~-104 ~13 ~11 minecraft:lightning_rod
fill ~-108 ~1 ~15 ~-108 ~7 ~15 minecraft:spruce_planks
fill ~-104 ~1 ~15 ~-104 ~7 ~15 minecraft:spruce_planks
# 067 shop_house style=corner_store context=collector_front facing=east
fill ~-114 ~-3 ~-74 ~-104 ~-1 ~-67 minecraft:stone
fill ~-114 ~0 ~-74 ~-104 ~5 ~-67 minecraft:mud_bricks
fill ~-113 ~1 ~-73 ~-105 ~4 ~-68 minecraft:air
fill ~-113 ~4 ~-73 ~-105 ~4 ~-68 minecraft:smooth_stone
fill ~-112 ~2 ~-74 ~-112 ~3 ~-74 minecraft:gray_stained_glass
fill ~-112 ~2 ~-67 ~-112 ~3 ~-67 minecraft:light_gray_stained_glass
fill ~-109 ~2 ~-74 ~-109 ~3 ~-74 minecraft:gray_stained_glass
fill ~-109 ~2 ~-67 ~-109 ~3 ~-67 minecraft:light_gray_stained_glass
fill ~-106 ~2 ~-74 ~-106 ~3 ~-74 minecraft:gray_stained_glass
fill ~-106 ~2 ~-67 ~-106 ~3 ~-67 minecraft:light_gray_stained_glass
fill ~-114 ~2 ~-72 ~-114 ~3 ~-72 minecraft:gray_stained_glass
fill ~-104 ~2 ~-72 ~-104 ~3 ~-72 minecraft:light_gray_stained_glass
fill ~-114 ~2 ~-69 ~-114 ~3 ~-69 minecraft:gray_stained_glass
fill ~-104 ~2 ~-69 ~-104 ~3 ~-69 minecraft:light_gray_stained_glass
setblock ~-104 ~1 ~-71 minecraft:iron_door[half=lower,facing=east]
setblock ~-104 ~2 ~-71 minecraft:iron_door[half=upper,facing=east]
fill ~-104 ~1 ~-73 ~-104 ~3 ~-68 minecraft:cyan_stained_glass
setblock ~-104 ~1 ~-71 minecraft:iron_door[half=lower,facing=east]
setblock ~-104 ~2 ~-71 minecraft:iron_door[half=upper,facing=east]
setblock ~-103 ~3 ~-71 minecraft:red_wool
fill ~-114 ~6 ~-74 ~-104 ~6 ~-67 minecraft:deepslate_tile_slab
fill ~-104 ~1 ~-73 ~-104 ~5 ~-73 minecraft:spruce_planks
fill ~-104 ~1 ~-69 ~-104 ~5 ~-69 minecraft:spruce_planks
setblock ~-104 ~3 ~-72 minecraft:red_carpet
# 068 detached_house style=rowhouse context=local_front facing=north
fill ~92 ~-3 ~-106 ~102 ~-1 ~-95 minecraft:stone
fill ~92 ~0 ~-106 ~102 ~11 ~-95 minecraft:white_concrete
fill ~93 ~1 ~-105 ~101 ~10 ~-96 minecraft:air
fill ~93 ~4 ~-105 ~101 ~4 ~-96 minecraft:smooth_stone
fill ~93 ~8 ~-105 ~101 ~8 ~-96 minecraft:smooth_stone
fill ~94 ~2 ~-106 ~94 ~3 ~-106 minecraft:gray_stained_glass
fill ~94 ~2 ~-95 ~94 ~3 ~-95 minecraft:light_gray_stained_glass
fill ~97 ~2 ~-106 ~97 ~3 ~-106 minecraft:gray_stained_glass
fill ~97 ~2 ~-95 ~97 ~3 ~-95 minecraft:light_gray_stained_glass
fill ~100 ~2 ~-106 ~100 ~3 ~-106 minecraft:gray_stained_glass
fill ~100 ~2 ~-95 ~100 ~3 ~-95 minecraft:light_gray_stained_glass
fill ~92 ~2 ~-104 ~92 ~3 ~-104 minecraft:gray_stained_glass
fill ~102 ~2 ~-104 ~102 ~3 ~-104 minecraft:light_gray_stained_glass
fill ~92 ~2 ~-101 ~92 ~3 ~-101 minecraft:gray_stained_glass
fill ~102 ~2 ~-101 ~102 ~3 ~-101 minecraft:light_gray_stained_glass
fill ~92 ~2 ~-98 ~92 ~3 ~-98 minecraft:gray_stained_glass
fill ~102 ~2 ~-98 ~102 ~3 ~-98 minecraft:light_gray_stained_glass
fill ~94 ~6 ~-106 ~94 ~7 ~-106 minecraft:gray_stained_glass
fill ~94 ~6 ~-95 ~94 ~7 ~-95 minecraft:light_gray_stained_glass
fill ~97 ~6 ~-106 ~97 ~7 ~-106 minecraft:gray_stained_glass
fill ~97 ~6 ~-95 ~97 ~7 ~-95 minecraft:light_gray_stained_glass
fill ~100 ~6 ~-106 ~100 ~7 ~-106 minecraft:gray_stained_glass
fill ~100 ~6 ~-95 ~100 ~7 ~-95 minecraft:light_gray_stained_glass
fill ~92 ~6 ~-104 ~92 ~7 ~-104 minecraft:gray_stained_glass
fill ~102 ~6 ~-104 ~102 ~7 ~-104 minecraft:light_gray_stained_glass
fill ~92 ~6 ~-101 ~92 ~7 ~-101 minecraft:gray_stained_glass
fill ~102 ~6 ~-101 ~102 ~7 ~-101 minecraft:light_gray_stained_glass
fill ~92 ~6 ~-98 ~92 ~7 ~-98 minecraft:gray_stained_glass
fill ~102 ~6 ~-98 ~102 ~7 ~-98 minecraft:light_gray_stained_glass
setblock ~97 ~1 ~-106 minecraft:iron_door[half=lower,facing=north]
setblock ~97 ~2 ~-106 minecraft:iron_door[half=upper,facing=north]
fill ~92 ~12 ~-106 ~102 ~12 ~-95 minecraft:smooth_stone_slab
fill ~93 ~13 ~-105 ~101 ~13 ~-96 minecraft:smooth_stone_slab
setblock ~97 ~3 ~-107 minecraft:dark_oak_slab[type=top]
fill ~100 ~9 ~-97 ~102 ~13 ~-95 minecraft:air
setblock ~100 ~9 ~-97 minecraft:cobweb
fill ~93 ~1 ~-106 ~93 ~7 ~-106 minecraft:cyan_terracotta
fill ~97 ~1 ~-106 ~97 ~7 ~-106 minecraft:cyan_terracotta
fill ~101 ~1 ~-106 ~101 ~7 ~-106 minecraft:cyan_terracotta
# 069 row_house style=rowhouse context=local_front facing=north
fill ~106 ~-3 ~116 ~112 ~-1 ~124 minecraft:stone
fill ~106 ~0 ~116 ~112 ~7 ~124 minecraft:bricks
fill ~107 ~1 ~117 ~111 ~6 ~123 minecraft:air
fill ~107 ~4 ~117 ~111 ~4 ~123 minecraft:smooth_stone
fill ~108 ~2 ~116 ~108 ~3 ~116 minecraft:gray_stained_glass
fill ~108 ~2 ~124 ~108 ~3 ~124 minecraft:light_gray_stained_glass
fill ~106 ~2 ~118 ~106 ~3 ~118 minecraft:gray_stained_glass
fill ~112 ~2 ~118 ~112 ~3 ~118 minecraft:light_gray_stained_glass
fill ~106 ~2 ~121 ~106 ~3 ~121 minecraft:gray_stained_glass
fill ~112 ~2 ~121 ~112 ~3 ~121 minecraft:light_gray_stained_glass
setblock ~109 ~1 ~116 minecraft:iron_door[half=lower,facing=north]
setblock ~109 ~2 ~116 minecraft:iron_door[half=upper,facing=north]
fill ~106 ~8 ~116 ~112 ~8 ~124 minecraft:deepslate_tile_slab
fill ~107 ~9 ~117 ~111 ~9 ~123 minecraft:deepslate_tile_slab
setblock ~109 ~3 ~115 minecraft:dark_oak_slab[type=top]
fill ~107 ~1 ~116 ~107 ~7 ~116 minecraft:weathered_cut_copper
fill ~111 ~1 ~116 ~111 ~7 ~116 minecraft:weathered_cut_copper
# 070 factory style=industrial_shed context=collector_front facing=west
fill ~67 ~-3 ~45 ~82 ~-1 ~64 minecraft:stone
fill ~67 ~0 ~45 ~82 ~7 ~64 minecraft:stone_bricks
fill ~68 ~1 ~46 ~81 ~6 ~63 minecraft:air
fill ~68 ~4 ~46 ~81 ~4 ~63 minecraft:smooth_stone
fill ~69 ~2 ~45 ~69 ~3 ~45 minecraft:gray_stained_glass
fill ~69 ~2 ~64 ~69 ~3 ~64 minecraft:light_gray_stained_glass
fill ~72 ~2 ~45 ~72 ~3 ~45 minecraft:gray_stained_glass
fill ~72 ~2 ~64 ~72 ~3 ~64 minecraft:light_gray_stained_glass
fill ~75 ~2 ~45 ~75 ~3 ~45 minecraft:gray_stained_glass
fill ~75 ~2 ~64 ~75 ~3 ~64 minecraft:light_gray_stained_glass
fill ~78 ~2 ~45 ~78 ~3 ~45 minecraft:gray_stained_glass
fill ~78 ~2 ~64 ~78 ~3 ~64 minecraft:light_gray_stained_glass
fill ~67 ~2 ~47 ~67 ~3 ~47 minecraft:gray_stained_glass
fill ~82 ~2 ~47 ~82 ~3 ~47 minecraft:light_gray_stained_glass
fill ~67 ~2 ~50 ~67 ~3 ~50 minecraft:gray_stained_glass
fill ~82 ~2 ~50 ~82 ~3 ~50 minecraft:light_gray_stained_glass
fill ~67 ~2 ~53 ~67 ~3 ~53 minecraft:gray_stained_glass
fill ~82 ~2 ~53 ~82 ~3 ~53 minecraft:light_gray_stained_glass
fill ~67 ~2 ~56 ~67 ~3 ~56 minecraft:gray_stained_glass
fill ~82 ~2 ~56 ~82 ~3 ~56 minecraft:light_gray_stained_glass
fill ~67 ~2 ~59 ~67 ~3 ~59 minecraft:gray_stained_glass
fill ~82 ~2 ~59 ~82 ~3 ~59 minecraft:light_gray_stained_glass
fill ~67 ~2 ~62 ~67 ~3 ~62 minecraft:gray_stained_glass
fill ~82 ~2 ~62 ~82 ~3 ~62 minecraft:light_gray_stained_glass
setblock ~67 ~1 ~50 minecraft:iron_door[half=lower,facing=west]
setblock ~67 ~2 ~50 minecraft:iron_door[half=upper,facing=west]
fill ~67 ~1 ~47 ~67 ~4 ~62 minecraft:polished_blackstone
fill ~67 ~5 ~47 ~67 ~5 ~62 minecraft:light_blue_stained_glass
fill ~69 ~9 ~47 ~71 ~10 ~49 minecraft:iron_block
fill ~67 ~8 ~45 ~82 ~8 ~64 minecraft:stone_brick_slab
fill ~67 ~1 ~46 ~67 ~7 ~46 minecraft:orange_terracotta
fill ~67 ~1 ~50 ~67 ~7 ~50 minecraft:orange_terracotta
fill ~67 ~1 ~54 ~67 ~7 ~54 minecraft:orange_terracotta
fill ~67 ~1 ~58 ~67 ~7 ~58 minecraft:orange_terracotta
fill ~67 ~1 ~62 ~67 ~7 ~62 minecraft:orange_terracotta
# 071 midrise_housing style=mixed_facade context=arterial_front facing=south
fill ~40 ~-3 ~-19 ~48 ~-1 ~-10 minecraft:stone
fill ~40 ~0 ~-19 ~48 ~28 ~-10 minecraft:bricks
fill ~41 ~1 ~-18 ~47 ~27 ~-11 minecraft:air
fill ~41 ~4 ~-18 ~47 ~4 ~-11 minecraft:smooth_stone
fill ~41 ~8 ~-18 ~47 ~8 ~-11 minecraft:smooth_stone
fill ~41 ~12 ~-18 ~47 ~12 ~-11 minecraft:smooth_stone
fill ~41 ~16 ~-18 ~47 ~16 ~-11 minecraft:smooth_stone
fill ~41 ~20 ~-18 ~47 ~20 ~-11 minecraft:smooth_stone
fill ~41 ~24 ~-18 ~47 ~24 ~-11 minecraft:smooth_stone
fill ~42 ~2 ~-19 ~42 ~3 ~-19 minecraft:gray_stained_glass
fill ~42 ~2 ~-10 ~42 ~3 ~-10 minecraft:light_gray_stained_glass
fill ~45 ~2 ~-19 ~45 ~3 ~-19 minecraft:gray_stained_glass
fill ~45 ~2 ~-10 ~45 ~3 ~-10 minecraft:light_gray_stained_glass
fill ~40 ~2 ~-17 ~40 ~3 ~-17 minecraft:gray_stained_glass
fill ~48 ~2 ~-17 ~48 ~3 ~-17 minecraft:light_gray_stained_glass
fill ~40 ~2 ~-14 ~40 ~3 ~-14 minecraft:gray_stained_glass
fill ~48 ~2 ~-14 ~48 ~3 ~-14 minecraft:light_gray_stained_glass
fill ~42 ~6 ~-19 ~42 ~7 ~-19 minecraft:gray_stained_glass
fill ~42 ~6 ~-10 ~42 ~7 ~-10 minecraft:light_gray_stained_glass
fill ~45 ~6 ~-19 ~45 ~7 ~-19 minecraft:gray_stained_glass
fill ~45 ~6 ~-10 ~45 ~7 ~-10 minecraft:light_gray_stained_glass
fill ~40 ~6 ~-17 ~40 ~7 ~-17 minecraft:gray_stained_glass
fill ~48 ~6 ~-17 ~48 ~7 ~-17 minecraft:light_gray_stained_glass
fill ~40 ~6 ~-14 ~40 ~7 ~-14 minecraft:gray_stained_glass
fill ~48 ~6 ~-14 ~48 ~7 ~-14 minecraft:light_gray_stained_glass
fill ~42 ~10 ~-19 ~42 ~11 ~-19 minecraft:gray_stained_glass
fill ~42 ~10 ~-10 ~42 ~11 ~-10 minecraft:light_gray_stained_glass
fill ~45 ~10 ~-19 ~45 ~11 ~-19 minecraft:gray_stained_glass
fill ~45 ~10 ~-10 ~45 ~11 ~-10 minecraft:light_gray_stained_glass
fill ~40 ~10 ~-17 ~40 ~11 ~-17 minecraft:gray_stained_glass
fill ~48 ~10 ~-17 ~48 ~11 ~-17 minecraft:light_gray_stained_glass
fill ~40 ~10 ~-14 ~40 ~11 ~-14 minecraft:gray_stained_glass
fill ~48 ~10 ~-14 ~48 ~11 ~-14 minecraft:light_gray_stained_glass
fill ~42 ~14 ~-19 ~42 ~15 ~-19 minecraft:gray_stained_glass
fill ~42 ~14 ~-10 ~42 ~15 ~-10 minecraft:light_gray_stained_glass
fill ~45 ~14 ~-19 ~45 ~15 ~-19 minecraft:gray_stained_glass
fill ~45 ~14 ~-10 ~45 ~15 ~-10 minecraft:light_gray_stained_glass
fill ~40 ~14 ~-17 ~40 ~15 ~-17 minecraft:gray_stained_glass
fill ~48 ~14 ~-17 ~48 ~15 ~-17 minecraft:light_gray_stained_glass
fill ~40 ~14 ~-14 ~40 ~15 ~-14 minecraft:gray_stained_glass
fill ~48 ~14 ~-14 ~48 ~15 ~-14 minecraft:light_gray_stained_glass
fill ~42 ~18 ~-19 ~42 ~19 ~-19 minecraft:gray_stained_glass
fill ~42 ~18 ~-10 ~42 ~19 ~-10 minecraft:light_gray_stained_glass
fill ~45 ~18 ~-19 ~45 ~19 ~-19 minecraft:gray_stained_glass
fill ~45 ~18 ~-10 ~45 ~19 ~-10 minecraft:light_gray_stained_glass
fill ~40 ~18 ~-17 ~40 ~19 ~-17 minecraft:gray_stained_glass
fill ~48 ~18 ~-17 ~48 ~19 ~-17 minecraft:light_gray_stained_glass
fill ~40 ~18 ~-14 ~40 ~19 ~-14 minecraft:gray_stained_glass
fill ~48 ~18 ~-14 ~48 ~19 ~-14 minecraft:light_gray_stained_glass
fill ~42 ~22 ~-19 ~42 ~23 ~-19 minecraft:gray_stained_glass
fill ~42 ~22 ~-10 ~42 ~23 ~-10 minecraft:light_gray_stained_glass
fill ~45 ~22 ~-19 ~45 ~23 ~-19 minecraft:gray_stained_glass
fill ~45 ~22 ~-10 ~45 ~23 ~-10 minecraft:light_gray_stained_glass
fill ~40 ~22 ~-17 ~40 ~23 ~-17 minecraft:gray_stained_glass
fill ~48 ~22 ~-17 ~48 ~23 ~-17 minecraft:light_gray_stained_glass
fill ~40 ~22 ~-14 ~40 ~23 ~-14 minecraft:gray_stained_glass
fill ~48 ~22 ~-14 ~48 ~23 ~-14 minecraft:light_gray_stained_glass
fill ~42 ~26 ~-19 ~42 ~27 ~-19 minecraft:gray_stained_glass
fill ~42 ~26 ~-10 ~42 ~27 ~-10 minecraft:light_gray_stained_glass
fill ~45 ~26 ~-19 ~45 ~27 ~-19 minecraft:gray_stained_glass
fill ~45 ~26 ~-10 ~45 ~27 ~-10 minecraft:light_gray_stained_glass
fill ~40 ~26 ~-17 ~40 ~27 ~-17 minecraft:gray_stained_glass
fill ~48 ~26 ~-17 ~48 ~27 ~-17 minecraft:light_gray_stained_glass
fill ~40 ~26 ~-14 ~40 ~27 ~-14 minecraft:gray_stained_glass
fill ~48 ~26 ~-14 ~48 ~27 ~-14 minecraft:light_gray_stained_glass
setblock ~44 ~1 ~-10 minecraft:iron_door[half=lower,facing=south]
setblock ~44 ~2 ~-10 minecraft:iron_door[half=upper,facing=south]
fill ~40 ~29 ~-19 ~48 ~29 ~-10 minecraft:deepslate_tile_slab
fill ~41 ~1 ~-10 ~41 ~7 ~-10 doomsday_decoration:redbrick
fill ~45 ~1 ~-10 ~45 ~7 ~-10 doomsday_decoration:redbrick
fill ~42 ~30 ~-17 ~45 ~32 ~-14 minecraft:light_gray_concrete
setblock ~46 ~30 ~-12 minecraft:lightning_rod
# 072 restaurant style=corner_store context=collector_front facing=south
fill ~105 ~-3 ~54 ~111 ~-1 ~65 minecraft:stone
fill ~105 ~0 ~54 ~111 ~7 ~65 minecraft:bricks
fill ~106 ~1 ~55 ~110 ~6 ~64 minecraft:air
fill ~106 ~4 ~55 ~110 ~4 ~64 minecraft:smooth_stone
fill ~107 ~2 ~54 ~107 ~3 ~54 minecraft:gray_stained_glass
fill ~107 ~2 ~65 ~107 ~3 ~65 minecraft:light_gray_stained_glass
fill ~105 ~2 ~56 ~105 ~3 ~56 minecraft:gray_stained_glass
fill ~111 ~2 ~56 ~111 ~3 ~56 minecraft:light_gray_stained_glass
fill ~105 ~2 ~59 ~105 ~3 ~59 minecraft:gray_stained_glass
fill ~111 ~2 ~59 ~111 ~3 ~59 minecraft:light_gray_stained_glass
fill ~105 ~2 ~62 ~105 ~3 ~62 minecraft:gray_stained_glass
fill ~111 ~2 ~62 ~111 ~3 ~62 minecraft:light_gray_stained_glass
setblock ~108 ~1 ~65 minecraft:iron_door[half=lower,facing=south]
setblock ~108 ~2 ~65 minecraft:iron_door[half=upper,facing=south]
fill ~106 ~1 ~65 ~110 ~3 ~65 minecraft:cyan_stained_glass
setblock ~108 ~1 ~65 minecraft:iron_door[half=lower,facing=south]
setblock ~108 ~2 ~65 minecraft:iron_door[half=upper,facing=south]
setblock ~108 ~3 ~66 minecraft:red_wool
fill ~105 ~8 ~54 ~111 ~8 ~65 minecraft:deepslate_tile_slab
fill ~106 ~1 ~65 ~106 ~7 ~65 minecraft:weathered_cut_copper
fill ~110 ~1 ~65 ~110 ~7 ~65 minecraft:weathered_cut_copper
setblock ~107 ~3 ~65 minecraft:red_carpet
