# Buildings 176..200
# 176 clinic -101,-19 -97,-9 h=7
fill ~-101 ~-3 ~-19 ~-97 ~-1 ~-9 minecraft:stone
fill ~-101 ~0 ~-19 ~-97 ~7 ~-9 minecraft:smooth_sandstone
fill ~-100 ~1 ~-18 ~-98 ~6 ~-10 minecraft:air
fill ~-100 ~4 ~-18 ~-98 ~4 ~-10 minecraft:smooth_stone
fill ~-101 ~2 ~-17 ~-101 ~3 ~-11 minecraft:gray_stained_glass
fill ~-97 ~2 ~-17 ~-97 ~3 ~-11 minecraft:light_gray_stained_glass
fill ~-100 ~0 ~-19 ~-98 ~3 ~-19 minecraft:brown_terracotta
setblock ~-99 ~1 ~-19 minecraft:iron_door[half=lower,facing=north]
setblock ~-99 ~2 ~-19 minecraft:iron_door[half=upper,facing=north]
fill ~-101 ~8 ~-19 ~-97 ~8 ~-9 minecraft:stone_brick_slab
# 177 warehouse -79,-125 -75,-117 h=8
fill ~-79 ~-3 ~-125 ~-75 ~-1 ~-117 minecraft:stone
fill ~-79 ~0 ~-125 ~-75 ~8 ~-117 minecraft:bricks
fill ~-78 ~1 ~-124 ~-76 ~7 ~-118 minecraft:air
fill ~-78 ~4 ~-124 ~-76 ~4 ~-118 minecraft:smooth_stone
fill ~-77 ~2 ~-125 ~-77 ~3 ~-125 minecraft:gray_stained_glass
fill ~-77 ~2 ~-117 ~-77 ~3 ~-117 minecraft:light_gray_stained_glass
fill ~-77 ~6 ~-125 ~-77 ~7 ~-125 minecraft:gray_stained_glass
fill ~-77 ~6 ~-117 ~-77 ~7 ~-117 minecraft:light_gray_stained_glass
fill ~-78 ~0 ~-125 ~-76 ~3 ~-125 minecraft:gray_concrete
setblock ~-77 ~1 ~-125 minecraft:iron_door[half=lower,facing=north]
setblock ~-77 ~2 ~-125 minecraft:iron_door[half=upper,facing=north]
fill ~-79 ~9 ~-125 ~-75 ~9 ~-117 minecraft:deepslate_tile_slab
# 178 warehouse 59,119 63,125 h=10
fill ~59 ~-3 ~119 ~63 ~-1 ~125 minecraft:stone
fill ~59 ~0 ~119 ~63 ~10 ~125 minecraft:gray_concrete
fill ~60 ~1 ~120 ~62 ~9 ~124 minecraft:air
fill ~60 ~4 ~120 ~62 ~4 ~124 minecraft:smooth_stone
fill ~60 ~8 ~120 ~62 ~8 ~124 minecraft:smooth_stone
fill ~59 ~2 ~121 ~59 ~3 ~123 minecraft:gray_stained_glass
fill ~63 ~2 ~121 ~63 ~3 ~123 minecraft:light_gray_stained_glass
fill ~59 ~6 ~121 ~59 ~7 ~123 minecraft:gray_stained_glass
fill ~63 ~6 ~121 ~63 ~7 ~123 minecraft:light_gray_stained_glass
fill ~60 ~0 ~119 ~62 ~3 ~119 doomsday_decoration:ironsheetwall_1
setblock ~61 ~1 ~119 minecraft:iron_door[half=lower,facing=north]
setblock ~61 ~2 ~119 minecraft:iron_door[half=upper,facing=north]
fill ~59 ~11 ~119 ~63 ~11 ~125 minecraft:smooth_stone_slab
# 179 warehouse 52,66 57,71 h=10
fill ~52 ~-3 ~66 ~57 ~-1 ~71 minecraft:stone
fill ~52 ~0 ~66 ~57 ~10 ~71 minecraft:stone_bricks
fill ~53 ~1 ~67 ~56 ~9 ~70 minecraft:air
fill ~53 ~4 ~67 ~56 ~4 ~70 minecraft:smooth_stone
fill ~53 ~8 ~67 ~56 ~8 ~70 minecraft:smooth_stone
fill ~54 ~2 ~66 ~55 ~3 ~66 minecraft:gray_stained_glass
fill ~54 ~2 ~71 ~55 ~3 ~71 minecraft:light_gray_stained_glass
fill ~54 ~6 ~66 ~55 ~7 ~66 minecraft:gray_stained_glass
fill ~54 ~6 ~71 ~55 ~7 ~71 minecraft:light_gray_stained_glass
fill ~53 ~0 ~66 ~56 ~3 ~66 minecraft:orange_terracotta
setblock ~54 ~1 ~66 minecraft:iron_door[half=lower,facing=north]
setblock ~54 ~2 ~66 minecraft:iron_door[half=upper,facing=north]
fill ~52 ~11 ~66 ~57 ~11 ~71 minecraft:stone_brick_slab
# 180 local_shop -59,117 -54,124 h=9
fill ~-59 ~-3 ~117 ~-54 ~-1 ~124 minecraft:stone
fill ~-59 ~0 ~117 ~-54 ~9 ~124 minecraft:calcite
fill ~-58 ~1 ~118 ~-55 ~8 ~123 minecraft:air
fill ~-58 ~4 ~118 ~-55 ~4 ~123 minecraft:smooth_stone
fill ~-58 ~8 ~118 ~-55 ~8 ~123 minecraft:smooth_stone
fill ~-59 ~2 ~119 ~-59 ~3 ~122 minecraft:gray_stained_glass
fill ~-54 ~2 ~119 ~-54 ~3 ~122 minecraft:light_gray_stained_glass
fill ~-59 ~6 ~119 ~-59 ~7 ~122 minecraft:gray_stained_glass
fill ~-54 ~6 ~119 ~-54 ~7 ~122 minecraft:light_gray_stained_glass
fill ~-58 ~0 ~117 ~-55 ~3 ~117 minecraft:gray_concrete
setblock ~-57 ~1 ~117 minecraft:iron_door[half=lower,facing=north]
setblock ~-57 ~2 ~117 minecraft:iron_door[half=upper,facing=north]
fill ~-59 ~10 ~117 ~-54 ~10 ~124 minecraft:stone_brick_slab
# 181 midrise_housing -18,-3 -14,4 h=16
fill ~-18 ~-3 ~-3 ~-14 ~-1 ~4 minecraft:stone
fill ~-18 ~0 ~-3 ~-14 ~16 ~4 minecraft:bricks
fill ~-17 ~1 ~-2 ~-15 ~15 ~3 minecraft:air
fill ~-17 ~4 ~-2 ~-15 ~4 ~3 minecraft:smooth_stone
fill ~-17 ~8 ~-2 ~-15 ~8 ~3 minecraft:smooth_stone
fill ~-17 ~12 ~-2 ~-15 ~12 ~3 minecraft:smooth_stone
fill ~-16 ~2 ~-3 ~-16 ~3 ~-3 minecraft:gray_stained_glass
fill ~-16 ~2 ~4 ~-16 ~3 ~4 minecraft:light_gray_stained_glass
fill ~-16 ~6 ~-3 ~-16 ~7 ~-3 minecraft:gray_stained_glass
fill ~-16 ~6 ~4 ~-16 ~7 ~4 minecraft:light_gray_stained_glass
fill ~-16 ~10 ~-3 ~-16 ~11 ~-3 minecraft:gray_stained_glass
fill ~-16 ~10 ~4 ~-16 ~11 ~4 minecraft:light_gray_stained_glass
fill ~-16 ~14 ~-3 ~-16 ~15 ~-3 minecraft:gray_stained_glass
fill ~-16 ~14 ~4 ~-16 ~15 ~4 minecraft:light_gray_stained_glass
fill ~-17 ~0 ~-3 ~-15 ~3 ~-3 doomsday_decoration:redbrick
setblock ~-16 ~1 ~-3 minecraft:iron_door[half=lower,facing=north]
setblock ~-16 ~2 ~-3 minecraft:iron_door[half=upper,facing=north]
fill ~-18 ~17 ~-3 ~-14 ~17 ~4 minecraft:deepslate_tile_slab
# 182 garage -125,-115 -120,-110 h=6
fill ~-125 ~-3 ~-115 ~-120 ~-1 ~-110 minecraft:stone
fill ~-125 ~0 ~-115 ~-120 ~6 ~-110 minecraft:bricks
fill ~-124 ~1 ~-114 ~-121 ~5 ~-111 minecraft:air
fill ~-124 ~4 ~-114 ~-121 ~4 ~-111 minecraft:smooth_stone
fill ~-125 ~2 ~-113 ~-125 ~3 ~-112 minecraft:gray_stained_glass
fill ~-120 ~2 ~-113 ~-120 ~3 ~-112 minecraft:light_gray_stained_glass
fill ~-124 ~0 ~-115 ~-121 ~3 ~-115 minecraft:gray_concrete
setblock ~-123 ~1 ~-115 minecraft:iron_door[half=lower,facing=north]
setblock ~-123 ~2 ~-115 minecraft:iron_door[half=upper,facing=north]
fill ~-125 ~7 ~-115 ~-120 ~7 ~-110 minecraft:deepslate_tile_slab
# 183 community -126,4 -122,9 h=11
fill ~-126 ~-3 ~4 ~-122 ~-1 ~9 minecraft:stone
fill ~-126 ~0 ~4 ~-122 ~11 ~9 minecraft:white_terracotta
fill ~-125 ~1 ~5 ~-123 ~10 ~8 minecraft:air
fill ~-125 ~4 ~5 ~-123 ~4 ~8 minecraft:smooth_stone
fill ~-125 ~8 ~5 ~-123 ~8 ~8 minecraft:smooth_stone
fill ~-126 ~2 ~6 ~-126 ~3 ~7 minecraft:gray_stained_glass
fill ~-122 ~2 ~6 ~-122 ~3 ~7 minecraft:light_gray_stained_glass
fill ~-126 ~6 ~6 ~-126 ~7 ~7 minecraft:gray_stained_glass
fill ~-122 ~6 ~6 ~-122 ~7 ~7 minecraft:light_gray_stained_glass
fill ~-125 ~0 ~4 ~-123 ~3 ~4 minecraft:dark_oak_planks
setblock ~-124 ~1 ~4 minecraft:iron_door[half=lower,facing=north]
setblock ~-124 ~2 ~4 minecraft:iron_door[half=upper,facing=north]
fill ~-126 ~12 ~4 ~-122 ~12 ~9 minecraft:dark_oak_slab
# 184 garage 79,40 85,49 h=6
fill ~79 ~-3 ~40 ~85 ~-1 ~49 minecraft:stone
fill ~79 ~0 ~40 ~85 ~6 ~49 minecraft:deepslate_bricks
fill ~80 ~1 ~41 ~84 ~5 ~48 minecraft:air
fill ~80 ~4 ~41 ~84 ~4 ~48 minecraft:smooth_stone
fill ~79 ~2 ~42 ~79 ~3 ~47 minecraft:gray_stained_glass
fill ~85 ~2 ~42 ~85 ~3 ~47 minecraft:light_gray_stained_glass
fill ~80 ~0 ~40 ~83 ~3 ~40 minecraft:oxidized_cut_copper
setblock ~81 ~1 ~40 minecraft:iron_door[half=lower,facing=north]
setblock ~81 ~2 ~40 minecraft:iron_door[half=upper,facing=north]
fill ~79 ~7 ~40 ~85 ~7 ~49 minecraft:deepslate_tile_slab
# 185 warehouse 50,44 54,50 h=8
fill ~50 ~-3 ~44 ~54 ~-1 ~50 minecraft:stone
fill ~50 ~0 ~44 ~54 ~8 ~50 minecraft:deepslate_bricks
fill ~51 ~1 ~45 ~53 ~7 ~49 minecraft:air
fill ~51 ~4 ~45 ~53 ~4 ~49 minecraft:smooth_stone
fill ~50 ~2 ~46 ~50 ~3 ~48 minecraft:gray_stained_glass
fill ~54 ~2 ~46 ~54 ~3 ~48 minecraft:light_gray_stained_glass
fill ~50 ~6 ~46 ~50 ~7 ~48 minecraft:gray_stained_glass
fill ~54 ~6 ~46 ~54 ~7 ~48 minecraft:light_gray_stained_glass
fill ~51 ~0 ~44 ~53 ~3 ~44 minecraft:oxidized_cut_copper
setblock ~52 ~1 ~44 minecraft:iron_door[half=lower,facing=north]
setblock ~52 ~2 ~44 minecraft:iron_door[half=upper,facing=north]
fill ~50 ~9 ~44 ~54 ~9 ~50 minecraft:deepslate_tile_slab
# 186 office -48,-114 -42,-108 h=8
fill ~-48 ~-3 ~-114 ~-42 ~-1 ~-108 minecraft:stone
fill ~-48 ~0 ~-114 ~-42 ~8 ~-108 minecraft:stone_bricks
fill ~-47 ~1 ~-113 ~-43 ~7 ~-109 minecraft:air
fill ~-47 ~4 ~-113 ~-43 ~4 ~-109 minecraft:smooth_stone
fill ~-46 ~2 ~-114 ~-44 ~3 ~-114 minecraft:gray_stained_glass
fill ~-46 ~2 ~-108 ~-44 ~3 ~-108 minecraft:light_gray_stained_glass
fill ~-46 ~6 ~-114 ~-44 ~7 ~-114 minecraft:gray_stained_glass
fill ~-46 ~6 ~-108 ~-44 ~7 ~-108 minecraft:light_gray_stained_glass
fill ~-47 ~0 ~-114 ~-44 ~3 ~-114 doomsday_decoration:ironsheetwall_2
setblock ~-46 ~1 ~-114 minecraft:iron_door[half=lower,facing=north]
setblock ~-46 ~2 ~-114 minecraft:iron_door[half=upper,facing=north]
fill ~-48 ~9 ~-114 ~-42 ~9 ~-108 minecraft:smooth_stone_slab
# 187 warehouse 56,101 60,106 h=10
fill ~56 ~-3 ~101 ~60 ~-1 ~106 minecraft:stone
fill ~56 ~0 ~101 ~60 ~10 ~106 minecraft:stone_bricks
fill ~57 ~1 ~102 ~59 ~9 ~105 minecraft:air
fill ~57 ~4 ~102 ~59 ~4 ~105 minecraft:smooth_stone
fill ~57 ~8 ~102 ~59 ~8 ~105 minecraft:smooth_stone
fill ~56 ~2 ~103 ~56 ~3 ~104 minecraft:gray_stained_glass
fill ~60 ~2 ~103 ~60 ~3 ~104 minecraft:light_gray_stained_glass
fill ~56 ~6 ~103 ~56 ~7 ~104 minecraft:gray_stained_glass
fill ~60 ~6 ~103 ~60 ~7 ~104 minecraft:light_gray_stained_glass
fill ~57 ~0 ~101 ~59 ~3 ~101 minecraft:orange_terracotta
setblock ~58 ~1 ~101 minecraft:iron_door[half=lower,facing=north]
setblock ~58 ~2 ~101 minecraft:iron_door[half=upper,facing=north]
fill ~56 ~11 ~101 ~60 ~11 ~106 minecraft:stone_brick_slab
# 188 utility 90,109 95,114 h=8
fill ~90 ~-3 ~109 ~95 ~-1 ~114 minecraft:stone
fill ~90 ~0 ~109 ~95 ~8 ~114 minecraft:deepslate_bricks
fill ~91 ~1 ~110 ~94 ~7 ~113 minecraft:air
fill ~91 ~4 ~110 ~94 ~4 ~113 minecraft:smooth_stone
fill ~92 ~2 ~109 ~93 ~3 ~109 minecraft:gray_stained_glass
fill ~92 ~2 ~114 ~93 ~3 ~114 minecraft:light_gray_stained_glass
fill ~92 ~6 ~109 ~93 ~7 ~109 minecraft:gray_stained_glass
fill ~92 ~6 ~114 ~93 ~7 ~114 minecraft:light_gray_stained_glass
fill ~91 ~0 ~109 ~94 ~3 ~109 minecraft:oxidized_cut_copper
setblock ~92 ~1 ~109 minecraft:iron_door[half=lower,facing=north]
setblock ~92 ~2 ~109 minecraft:iron_door[half=upper,facing=north]
fill ~90 ~9 ~109 ~95 ~9 ~114 minecraft:deepslate_tile_slab
# 189 shop_house -81,-4 -77,2 h=5
fill ~-81 ~-3 ~-4 ~-77 ~-1 ~2 minecraft:stone
fill ~-81 ~0 ~-4 ~-77 ~5 ~2 minecraft:bricks
fill ~-80 ~1 ~-3 ~-78 ~4 ~1 minecraft:air
fill ~-80 ~4 ~-3 ~-78 ~4 ~1 minecraft:smooth_stone
fill ~-81 ~2 ~-2 ~-81 ~3 ~0 minecraft:gray_stained_glass
fill ~-77 ~2 ~-2 ~-77 ~3 ~0 minecraft:light_gray_stained_glass
fill ~-80 ~0 ~-4 ~-78 ~3 ~-4 doomsday_decoration:hollowbrick
setblock ~-79 ~1 ~-4 minecraft:iron_door[half=lower,facing=north]
setblock ~-79 ~2 ~-4 minecraft:iron_door[half=upper,facing=north]
fill ~-81 ~6 ~-4 ~-77 ~6 ~2 minecraft:deepslate_tile_slab
# 190 warehouse 38,-90 42,-83 h=8
fill ~38 ~-3 ~-90 ~42 ~-1 ~-83 minecraft:stone
fill ~38 ~0 ~-90 ~42 ~8 ~-83 minecraft:bricks
fill ~39 ~1 ~-89 ~41 ~7 ~-84 minecraft:air
fill ~39 ~4 ~-89 ~41 ~4 ~-84 minecraft:smooth_stone
fill ~40 ~2 ~-90 ~40 ~3 ~-90 minecraft:gray_stained_glass
fill ~40 ~2 ~-83 ~40 ~3 ~-83 minecraft:light_gray_stained_glass
fill ~40 ~6 ~-90 ~40 ~7 ~-90 minecraft:gray_stained_glass
fill ~40 ~6 ~-83 ~40 ~7 ~-83 minecraft:light_gray_stained_glass
fill ~39 ~0 ~-90 ~41 ~3 ~-90 minecraft:gray_concrete
setblock ~40 ~1 ~-90 minecraft:iron_door[half=lower,facing=north]
setblock ~40 ~2 ~-90 minecraft:iron_door[half=upper,facing=north]
fill ~38 ~9 ~-90 ~42 ~9 ~-83 minecraft:deepslate_tile_slab
# 191 station_shop -79,-115 -75,-108 h=8
fill ~-79 ~-3 ~-115 ~-75 ~-1 ~-108 minecraft:stone
fill ~-79 ~0 ~-115 ~-75 ~8 ~-108 minecraft:stone_bricks
fill ~-78 ~1 ~-114 ~-76 ~7 ~-109 minecraft:air
fill ~-78 ~4 ~-114 ~-76 ~4 ~-109 minecraft:smooth_stone
fill ~-79 ~2 ~-113 ~-79 ~3 ~-110 minecraft:gray_stained_glass
fill ~-75 ~2 ~-113 ~-75 ~3 ~-110 minecraft:light_gray_stained_glass
fill ~-79 ~6 ~-113 ~-79 ~7 ~-110 minecraft:gray_stained_glass
fill ~-75 ~6 ~-113 ~-75 ~7 ~-110 minecraft:light_gray_stained_glass
fill ~-78 ~0 ~-115 ~-76 ~3 ~-115 doomsday_decoration:ironsheetwall_2
setblock ~-77 ~1 ~-115 minecraft:iron_door[half=lower,facing=north]
setblock ~-77 ~2 ~-115 minecraft:iron_door[half=upper,facing=north]
fill ~-79 ~9 ~-115 ~-75 ~9 ~-108 minecraft:smooth_stone_slab
# 192 shop_house -35,-75 -31,-67 h=7
fill ~-35 ~-3 ~-75 ~-31 ~-1 ~-67 minecraft:stone
fill ~-35 ~0 ~-75 ~-31 ~7 ~-67 minecraft:bricks
fill ~-34 ~1 ~-74 ~-32 ~6 ~-68 minecraft:air
fill ~-34 ~4 ~-74 ~-32 ~4 ~-68 minecraft:smooth_stone
fill ~-35 ~2 ~-73 ~-35 ~3 ~-69 minecraft:gray_stained_glass
fill ~-31 ~2 ~-73 ~-31 ~3 ~-69 minecraft:light_gray_stained_glass
fill ~-34 ~0 ~-75 ~-32 ~3 ~-75 doomsday_decoration:hollowbrick
setblock ~-33 ~1 ~-75 minecraft:iron_door[half=lower,facing=north]
setblock ~-33 ~2 ~-75 minecraft:iron_door[half=upper,facing=north]
fill ~-35 ~8 ~-75 ~-31 ~8 ~-67 minecraft:deepslate_tile_slab
# 193 shop_house 46,-29 51,-24 h=5
fill ~46 ~-3 ~-29 ~51 ~-1 ~-24 minecraft:stone
fill ~46 ~0 ~-29 ~51 ~5 ~-24 minecraft:bricks
fill ~47 ~1 ~-28 ~50 ~4 ~-25 minecraft:air
fill ~47 ~4 ~-28 ~50 ~4 ~-25 minecraft:smooth_stone
fill ~48 ~2 ~-29 ~49 ~3 ~-29 minecraft:gray_stained_glass
fill ~48 ~2 ~-24 ~49 ~3 ~-24 minecraft:light_gray_stained_glass
fill ~47 ~0 ~-29 ~50 ~3 ~-29 doomsday_decoration:hollowbrick
setblock ~48 ~1 ~-29 minecraft:iron_door[half=lower,facing=north]
setblock ~48 ~2 ~-29 minecraft:iron_door[half=upper,facing=north]
fill ~46 ~6 ~-29 ~51 ~6 ~-24 minecraft:deepslate_tile_slab
# 194 workshop 65,-62 70,-57 h=5
fill ~65 ~-3 ~-62 ~70 ~-1 ~-57 minecraft:stone
fill ~65 ~0 ~-62 ~70 ~5 ~-57 minecraft:bricks
fill ~66 ~1 ~-61 ~69 ~4 ~-58 minecraft:air
fill ~66 ~4 ~-61 ~69 ~4 ~-58 minecraft:smooth_stone
fill ~65 ~2 ~-60 ~65 ~3 ~-59 minecraft:gray_stained_glass
fill ~70 ~2 ~-60 ~70 ~3 ~-59 minecraft:light_gray_stained_glass
fill ~66 ~0 ~-62 ~69 ~3 ~-62 doomsday_decoration:hollowbrick
setblock ~67 ~1 ~-62 minecraft:iron_door[half=lower,facing=north]
setblock ~67 ~2 ~-62 minecraft:iron_door[half=upper,facing=north]
fill ~65 ~6 ~-62 ~70 ~6 ~-57 minecraft:deepslate_tile_slab
# 195 market 106,15 110,22 h=11
fill ~106 ~-3 ~15 ~110 ~-1 ~22 minecraft:stone
fill ~106 ~0 ~15 ~110 ~11 ~22 minecraft:bricks
fill ~107 ~1 ~16 ~109 ~10 ~21 minecraft:air
fill ~107 ~4 ~16 ~109 ~4 ~21 minecraft:smooth_stone
fill ~107 ~8 ~16 ~109 ~8 ~21 minecraft:smooth_stone
fill ~108 ~2 ~15 ~108 ~3 ~15 minecraft:gray_stained_glass
fill ~108 ~2 ~22 ~108 ~3 ~22 minecraft:light_gray_stained_glass
fill ~108 ~6 ~15 ~108 ~7 ~15 minecraft:gray_stained_glass
fill ~108 ~6 ~22 ~108 ~7 ~22 minecraft:light_gray_stained_glass
fill ~107 ~0 ~15 ~109 ~3 ~15 minecraft:weathered_cut_copper
setblock ~108 ~1 ~15 minecraft:iron_door[half=lower,facing=north]
setblock ~108 ~2 ~15 minecraft:iron_door[half=upper,facing=north]
fill ~106 ~12 ~15 ~110 ~12 ~22 minecraft:deepslate_tile_slab
# 196 station_shop -54,-114 -50,-108 h=10
fill ~-54 ~-3 ~-114 ~-50 ~-1 ~-108 minecraft:stone
fill ~-54 ~0 ~-114 ~-50 ~10 ~-108 minecraft:stone_bricks
fill ~-53 ~1 ~-113 ~-51 ~9 ~-109 minecraft:air
fill ~-53 ~4 ~-113 ~-51 ~4 ~-109 minecraft:smooth_stone
fill ~-53 ~8 ~-113 ~-51 ~8 ~-109 minecraft:smooth_stone
fill ~-54 ~2 ~-112 ~-54 ~3 ~-110 minecraft:gray_stained_glass
fill ~-50 ~2 ~-112 ~-50 ~3 ~-110 minecraft:light_gray_stained_glass
fill ~-54 ~6 ~-112 ~-54 ~7 ~-110 minecraft:gray_stained_glass
fill ~-50 ~6 ~-112 ~-50 ~7 ~-110 minecraft:light_gray_stained_glass
fill ~-53 ~0 ~-114 ~-51 ~3 ~-114 doomsday_decoration:ironsheetwall_2
setblock ~-52 ~1 ~-114 minecraft:iron_door[half=lower,facing=north]
setblock ~-52 ~2 ~-114 minecraft:iron_door[half=upper,facing=north]
fill ~-54 ~11 ~-114 ~-50 ~11 ~-108 minecraft:smooth_stone_slab
# 197 warehouse -113,-92 -108,-86 h=10
fill ~-113 ~-3 ~-92 ~-108 ~-1 ~-86 minecraft:stone
fill ~-113 ~0 ~-92 ~-108 ~10 ~-86 minecraft:stone_bricks
fill ~-112 ~1 ~-91 ~-109 ~9 ~-87 minecraft:air
fill ~-112 ~4 ~-91 ~-109 ~4 ~-87 minecraft:smooth_stone
fill ~-112 ~8 ~-91 ~-109 ~8 ~-87 minecraft:smooth_stone
fill ~-111 ~2 ~-92 ~-110 ~3 ~-92 minecraft:gray_stained_glass
fill ~-111 ~2 ~-86 ~-110 ~3 ~-86 minecraft:light_gray_stained_glass
fill ~-111 ~6 ~-92 ~-110 ~7 ~-92 minecraft:gray_stained_glass
fill ~-111 ~6 ~-86 ~-110 ~7 ~-86 minecraft:light_gray_stained_glass
fill ~-112 ~0 ~-92 ~-109 ~3 ~-92 doomsday_decoration:ironsheetwall_2
setblock ~-111 ~1 ~-92 minecraft:iron_door[half=lower,facing=north]
setblock ~-111 ~2 ~-92 minecraft:iron_door[half=upper,facing=north]
fill ~-113 ~11 ~-92 ~-108 ~11 ~-86 minecraft:smooth_stone_slab
# 198 community -99,120 -91,125 h=9
fill ~-99 ~-3 ~120 ~-91 ~-1 ~125 minecraft:stone
fill ~-99 ~0 ~120 ~-91 ~9 ~125 minecraft:calcite
fill ~-98 ~1 ~121 ~-92 ~8 ~124 minecraft:air
fill ~-98 ~4 ~121 ~-92 ~4 ~124 minecraft:smooth_stone
fill ~-98 ~8 ~121 ~-92 ~8 ~124 minecraft:smooth_stone
fill ~-97 ~2 ~120 ~-93 ~3 ~120 minecraft:gray_stained_glass
fill ~-97 ~2 ~125 ~-93 ~3 ~125 minecraft:light_gray_stained_glass
fill ~-97 ~6 ~120 ~-93 ~7 ~120 minecraft:gray_stained_glass
fill ~-97 ~6 ~125 ~-93 ~7 ~125 minecraft:light_gray_stained_glass
fill ~-98 ~0 ~120 ~-95 ~3 ~120 minecraft:gray_concrete
setblock ~-97 ~1 ~120 minecraft:iron_door[half=lower,facing=north]
setblock ~-97 ~2 ~120 minecraft:iron_door[half=upper,facing=north]
fill ~-99 ~10 ~120 ~-91 ~10 ~125 minecraft:stone_brick_slab
# 199 warehouse 90,-88 94,-83 h=10
fill ~90 ~-3 ~-88 ~94 ~-1 ~-83 minecraft:stone
fill ~90 ~0 ~-88 ~94 ~10 ~-83 minecraft:stone_bricks
fill ~91 ~1 ~-87 ~93 ~9 ~-84 minecraft:air
fill ~91 ~4 ~-87 ~93 ~4 ~-84 minecraft:smooth_stone
fill ~91 ~8 ~-87 ~93 ~8 ~-84 minecraft:smooth_stone
fill ~92 ~2 ~-88 ~92 ~3 ~-88 minecraft:gray_stained_glass
fill ~92 ~2 ~-83 ~92 ~3 ~-83 minecraft:light_gray_stained_glass
fill ~92 ~6 ~-88 ~92 ~7 ~-88 minecraft:gray_stained_glass
fill ~92 ~6 ~-83 ~92 ~7 ~-83 minecraft:light_gray_stained_glass
fill ~91 ~0 ~-88 ~93 ~3 ~-88 doomsday_decoration:ironsheetwall_2
setblock ~92 ~1 ~-88 minecraft:iron_door[half=lower,facing=north]
setblock ~92 ~2 ~-88 minecraft:iron_door[half=upper,facing=north]
fill ~90 ~11 ~-88 ~94 ~11 ~-83 minecraft:smooth_stone_slab
# 200 utility 67,119 71,125 h=6
fill ~67 ~-3 ~119 ~71 ~-1 ~125 minecraft:stone
fill ~67 ~0 ~119 ~71 ~6 ~125 minecraft:gray_concrete
fill ~68 ~1 ~120 ~70 ~5 ~124 minecraft:air
fill ~68 ~4 ~120 ~70 ~4 ~124 minecraft:smooth_stone
fill ~67 ~2 ~121 ~67 ~3 ~123 minecraft:gray_stained_glass
fill ~71 ~2 ~121 ~71 ~3 ~123 minecraft:light_gray_stained_glass
fill ~68 ~0 ~119 ~70 ~3 ~119 doomsday_decoration:ironsheetwall_1
setblock ~69 ~1 ~119 minecraft:iron_door[half=lower,facing=north]
setblock ~69 ~2 ~119 minecraft:iron_door[half=upper,facing=north]
fill ~67 ~7 ~119 ~71 ~7 ~125 minecraft:smooth_stone_slab
