# Buildings 201..208
# 201 logistics style=sawtooth context=local_front facing=west
fill ~45 ~-3 ~45 ~49 ~-1 ~50 minecraft:stone
fill ~45 ~0 ~45 ~49 ~8 ~50 minecraft:gray_concrete
fill ~46 ~1 ~46 ~48 ~7 ~49 minecraft:air
fill ~46 ~4 ~46 ~48 ~4 ~49 minecraft:smooth_stone
fill ~47 ~2 ~45 ~47 ~3 ~45 minecraft:gray_stained_glass
fill ~47 ~2 ~50 ~47 ~3 ~50 minecraft:light_gray_stained_glass
fill ~45 ~2 ~47 ~45 ~3 ~47 minecraft:gray_stained_glass
fill ~49 ~2 ~47 ~49 ~3 ~47 minecraft:light_gray_stained_glass
fill ~47 ~6 ~45 ~47 ~7 ~45 minecraft:gray_stained_glass
fill ~47 ~6 ~50 ~47 ~7 ~50 minecraft:light_gray_stained_glass
fill ~45 ~6 ~47 ~45 ~7 ~47 minecraft:gray_stained_glass
fill ~49 ~6 ~47 ~49 ~7 ~47 minecraft:light_gray_stained_glass
setblock ~45 ~1 ~47 minecraft:iron_door[half=lower,facing=west]
setblock ~45 ~2 ~47 minecraft:iron_door[half=upper,facing=west]
fill ~45 ~1 ~47 ~45 ~4 ~48 minecraft:polished_blackstone
fill ~45 ~5 ~47 ~45 ~5 ~48 minecraft:light_blue_stained_glass
fill ~47 ~10 ~47 ~48 ~11 ~49 minecraft:iron_block
fill ~45 ~9 ~45 ~49 ~9 ~50 minecraft:smooth_stone_slab
fill ~47 ~10 ~47 ~48 ~11 ~49 minecraft:light_gray_concrete
setblock ~48 ~10 ~48 minecraft:lightning_rod
# 202 logistics style=sawtooth context=local_front facing=north
fill ~58 ~-3 ~119 ~62 ~-1 ~125 minecraft:stone
fill ~58 ~0 ~119 ~62 ~10 ~125 minecraft:stone_bricks
fill ~59 ~1 ~120 ~61 ~9 ~124 minecraft:air
fill ~59 ~4 ~120 ~61 ~4 ~124 minecraft:smooth_stone
fill ~59 ~8 ~120 ~61 ~8 ~124 minecraft:smooth_stone
fill ~60 ~2 ~119 ~60 ~3 ~119 minecraft:gray_stained_glass
fill ~60 ~2 ~125 ~60 ~3 ~125 minecraft:light_gray_stained_glass
fill ~58 ~2 ~121 ~58 ~3 ~121 minecraft:gray_stained_glass
fill ~62 ~2 ~121 ~62 ~3 ~121 minecraft:light_gray_stained_glass
fill ~60 ~6 ~119 ~60 ~7 ~119 minecraft:gray_stained_glass
fill ~60 ~6 ~125 ~60 ~7 ~125 minecraft:light_gray_stained_glass
fill ~58 ~6 ~121 ~58 ~7 ~121 minecraft:gray_stained_glass
fill ~62 ~6 ~121 ~62 ~7 ~121 minecraft:light_gray_stained_glass
setblock ~60 ~1 ~119 minecraft:iron_door[half=lower,facing=north]
setblock ~60 ~2 ~119 minecraft:iron_door[half=upper,facing=north]
fill ~60 ~1 ~119 ~60 ~4 ~119 minecraft:polished_blackstone
fill ~60 ~5 ~119 ~60 ~5 ~119 minecraft:light_blue_stained_glass
fill ~60 ~12 ~121 ~61 ~13 ~123 minecraft:iron_block
fill ~58 ~11 ~119 ~62 ~11 ~125 minecraft:stone_brick_slab
# 203 utility style=loading_bay context=back_block facing=south
fill ~74 ~-3 ~-114 ~81 ~-1 ~-109 minecraft:stone
fill ~74 ~0 ~-114 ~81 ~8 ~-109 minecraft:stone_bricks
fill ~75 ~1 ~-113 ~80 ~7 ~-110 minecraft:air
fill ~75 ~4 ~-113 ~80 ~4 ~-110 minecraft:smooth_stone
fill ~76 ~2 ~-114 ~76 ~3 ~-114 minecraft:gray_stained_glass
fill ~76 ~2 ~-109 ~76 ~3 ~-109 minecraft:light_gray_stained_glass
fill ~79 ~2 ~-114 ~79 ~3 ~-114 minecraft:gray_stained_glass
fill ~79 ~2 ~-109 ~79 ~3 ~-109 minecraft:light_gray_stained_glass
fill ~74 ~2 ~-112 ~74 ~3 ~-112 minecraft:gray_stained_glass
fill ~81 ~2 ~-112 ~81 ~3 ~-112 minecraft:light_gray_stained_glass
fill ~76 ~6 ~-114 ~76 ~7 ~-114 minecraft:gray_stained_glass
fill ~76 ~6 ~-109 ~76 ~7 ~-109 minecraft:light_gray_stained_glass
fill ~79 ~6 ~-114 ~79 ~7 ~-114 minecraft:gray_stained_glass
fill ~79 ~6 ~-109 ~79 ~7 ~-109 minecraft:light_gray_stained_glass
fill ~74 ~6 ~-112 ~74 ~7 ~-112 minecraft:gray_stained_glass
fill ~81 ~6 ~-112 ~81 ~7 ~-112 minecraft:light_gray_stained_glass
setblock ~77 ~1 ~-109 minecraft:iron_door[half=lower,facing=south]
setblock ~77 ~2 ~-109 minecraft:iron_door[half=upper,facing=south]
fill ~76 ~1 ~-109 ~79 ~4 ~-109 minecraft:polished_blackstone
fill ~76 ~5 ~-109 ~79 ~5 ~-109 minecraft:light_blue_stained_glass
fill ~76 ~10 ~-112 ~78 ~11 ~-110 minecraft:iron_block
fill ~74 ~9 ~-114 ~81 ~9 ~-109 minecraft:smooth_stone_slab
# 204 supermarket style=storefront context=collector_front facing=east
fill ~-96 ~-3 ~55 ~-92 ~-1 ~63 minecraft:stone
fill ~-96 ~0 ~55 ~-92 ~11 ~63 minecraft:white_terracotta
fill ~-95 ~1 ~56 ~-93 ~10 ~62 minecraft:air
fill ~-95 ~4 ~56 ~-93 ~4 ~62 minecraft:smooth_stone
fill ~-95 ~8 ~56 ~-93 ~8 ~62 minecraft:smooth_stone
fill ~-94 ~2 ~55 ~-94 ~3 ~55 minecraft:gray_stained_glass
fill ~-94 ~2 ~63 ~-94 ~3 ~63 minecraft:light_gray_stained_glass
fill ~-96 ~2 ~57 ~-96 ~3 ~57 minecraft:gray_stained_glass
fill ~-92 ~2 ~57 ~-92 ~3 ~57 minecraft:light_gray_stained_glass
fill ~-96 ~2 ~60 ~-96 ~3 ~60 minecraft:gray_stained_glass
fill ~-92 ~2 ~60 ~-92 ~3 ~60 minecraft:light_gray_stained_glass
fill ~-94 ~6 ~55 ~-94 ~7 ~55 minecraft:gray_stained_glass
fill ~-94 ~6 ~63 ~-94 ~7 ~63 minecraft:light_gray_stained_glass
fill ~-96 ~6 ~57 ~-96 ~7 ~57 minecraft:gray_stained_glass
fill ~-92 ~6 ~57 ~-92 ~7 ~57 minecraft:light_gray_stained_glass
fill ~-96 ~6 ~60 ~-96 ~7 ~60 minecraft:gray_stained_glass
fill ~-92 ~6 ~60 ~-92 ~7 ~60 minecraft:light_gray_stained_glass
setblock ~-92 ~1 ~59 minecraft:iron_door[half=lower,facing=east]
setblock ~-92 ~2 ~59 minecraft:iron_door[half=upper,facing=east]
fill ~-92 ~1 ~56 ~-92 ~3 ~62 minecraft:cyan_stained_glass
setblock ~-92 ~1 ~59 minecraft:iron_door[half=lower,facing=east]
setblock ~-92 ~2 ~59 minecraft:iron_door[half=upper,facing=east]
setblock ~-91 ~3 ~59 minecraft:red_wool
fill ~-96 ~12 ~55 ~-92 ~12 ~63 minecraft:dark_oak_slab
fill ~-94 ~13 ~57 ~-93 ~14 ~59 minecraft:light_gray_concrete
setblock ~-93 ~13 ~58 minecraft:lightning_rod
# 205 logistics style=sawtooth context=back_block facing=north
fill ~69 ~-3 ~120 ~74 ~-1 ~125 minecraft:stone
fill ~69 ~0 ~120 ~74 ~8 ~125 minecraft:gray_concrete
fill ~70 ~1 ~121 ~73 ~7 ~124 minecraft:air
fill ~70 ~4 ~121 ~73 ~4 ~124 minecraft:smooth_stone
fill ~71 ~2 ~120 ~71 ~3 ~120 minecraft:gray_stained_glass
fill ~71 ~2 ~125 ~71 ~3 ~125 minecraft:light_gray_stained_glass
fill ~69 ~2 ~122 ~69 ~3 ~122 minecraft:gray_stained_glass
fill ~74 ~2 ~122 ~74 ~3 ~122 minecraft:light_gray_stained_glass
fill ~71 ~6 ~120 ~71 ~7 ~120 minecraft:gray_stained_glass
fill ~71 ~6 ~125 ~71 ~7 ~125 minecraft:light_gray_stained_glass
fill ~69 ~6 ~122 ~69 ~7 ~122 minecraft:gray_stained_glass
fill ~74 ~6 ~122 ~74 ~7 ~122 minecraft:light_gray_stained_glass
setblock ~71 ~1 ~120 minecraft:iron_door[half=lower,facing=north]
setblock ~71 ~2 ~120 minecraft:iron_door[half=upper,facing=north]
fill ~71 ~1 ~120 ~72 ~4 ~120 minecraft:polished_blackstone
fill ~71 ~5 ~120 ~72 ~5 ~120 minecraft:light_blue_stained_glass
fill ~71 ~10 ~122 ~73 ~11 ~124 minecraft:iron_block
fill ~69 ~9 ~120 ~74 ~9 ~125 minecraft:smooth_stone_slab
# 206 lowrise_housing style=rowhouse context=back_block facing=north
fill ~-69 ~-3 ~119 ~-65 ~-1 ~124 minecraft:stone
fill ~-69 ~0 ~119 ~-65 ~11 ~124 minecraft:mud_bricks
fill ~-68 ~1 ~120 ~-66 ~10 ~123 minecraft:air
fill ~-68 ~4 ~120 ~-66 ~4 ~123 minecraft:smooth_stone
fill ~-68 ~8 ~120 ~-66 ~8 ~123 minecraft:smooth_stone
fill ~-67 ~2 ~119 ~-67 ~3 ~119 minecraft:gray_stained_glass
fill ~-67 ~2 ~124 ~-67 ~3 ~124 minecraft:light_gray_stained_glass
fill ~-69 ~2 ~121 ~-69 ~3 ~121 minecraft:gray_stained_glass
fill ~-65 ~2 ~121 ~-65 ~3 ~121 minecraft:light_gray_stained_glass
fill ~-67 ~6 ~119 ~-67 ~7 ~119 minecraft:gray_stained_glass
fill ~-67 ~6 ~124 ~-67 ~7 ~124 minecraft:light_gray_stained_glass
fill ~-69 ~6 ~121 ~-69 ~7 ~121 minecraft:gray_stained_glass
fill ~-65 ~6 ~121 ~-65 ~7 ~121 minecraft:light_gray_stained_glass
setblock ~-67 ~1 ~119 minecraft:iron_door[half=lower,facing=north]
setblock ~-67 ~2 ~119 minecraft:iron_door[half=upper,facing=north]
fill ~-69 ~12 ~119 ~-65 ~12 ~124 minecraft:deepslate_tile_slab
fill ~-68 ~13 ~120 ~-66 ~13 ~123 minecraft:deepslate_tile_slab
setblock ~-67 ~3 ~118 minecraft:dark_oak_slab[type=top]
# 207 warehouse style=industrial_shed context=local_front facing=west
fill ~75 ~-3 ~106 ~79 ~-1 ~115 minecraft:stone
fill ~75 ~0 ~106 ~79 ~10 ~115 minecraft:gray_concrete
fill ~76 ~1 ~107 ~78 ~9 ~114 minecraft:air
fill ~76 ~4 ~107 ~78 ~4 ~114 minecraft:smooth_stone
fill ~76 ~8 ~107 ~78 ~8 ~114 minecraft:smooth_stone
fill ~77 ~2 ~106 ~77 ~3 ~106 minecraft:gray_stained_glass
fill ~77 ~2 ~115 ~77 ~3 ~115 minecraft:light_gray_stained_glass
fill ~75 ~2 ~108 ~75 ~3 ~108 minecraft:gray_stained_glass
fill ~79 ~2 ~108 ~79 ~3 ~108 minecraft:light_gray_stained_glass
fill ~75 ~2 ~111 ~75 ~3 ~111 minecraft:gray_stained_glass
fill ~79 ~2 ~111 ~79 ~3 ~111 minecraft:light_gray_stained_glass
fill ~77 ~6 ~106 ~77 ~7 ~106 minecraft:gray_stained_glass
fill ~77 ~6 ~115 ~77 ~7 ~115 minecraft:light_gray_stained_glass
fill ~75 ~6 ~108 ~75 ~7 ~108 minecraft:gray_stained_glass
fill ~79 ~6 ~108 ~79 ~7 ~108 minecraft:light_gray_stained_glass
fill ~75 ~6 ~111 ~75 ~7 ~111 minecraft:gray_stained_glass
fill ~79 ~6 ~111 ~79 ~7 ~111 minecraft:light_gray_stained_glass
setblock ~75 ~1 ~110 minecraft:iron_door[half=lower,facing=west]
setblock ~75 ~2 ~110 minecraft:iron_door[half=upper,facing=west]
fill ~75 ~1 ~108 ~75 ~4 ~113 minecraft:polished_blackstone
fill ~75 ~5 ~108 ~75 ~5 ~113 minecraft:light_blue_stained_glass
fill ~77 ~12 ~108 ~78 ~13 ~110 minecraft:iron_block
fill ~75 ~11 ~106 ~79 ~11 ~115 minecraft:smooth_stone_slab
fill ~77 ~12 ~108 ~78 ~13 ~110 minecraft:light_gray_concrete
setblock ~78 ~12 ~109 minecraft:lightning_rod
# 208 small_office style=setback_tower context=back_block facing=north
fill ~-37 ~-3 ~117 ~-32 ~-1 ~122 minecraft:stone
fill ~-37 ~0 ~117 ~-32 ~11 ~122 minecraft:mud_bricks
fill ~-36 ~1 ~118 ~-33 ~10 ~121 minecraft:air
fill ~-36 ~4 ~118 ~-33 ~4 ~121 minecraft:smooth_stone
fill ~-36 ~8 ~118 ~-33 ~8 ~121 minecraft:smooth_stone
fill ~-35 ~2 ~117 ~-35 ~3 ~117 minecraft:gray_stained_glass
fill ~-35 ~2 ~122 ~-35 ~3 ~122 minecraft:light_gray_stained_glass
fill ~-37 ~2 ~119 ~-37 ~3 ~119 minecraft:gray_stained_glass
fill ~-32 ~2 ~119 ~-32 ~3 ~119 minecraft:light_gray_stained_glass
fill ~-35 ~6 ~117 ~-35 ~7 ~117 minecraft:gray_stained_glass
fill ~-35 ~6 ~122 ~-35 ~7 ~122 minecraft:light_gray_stained_glass
fill ~-37 ~6 ~119 ~-37 ~7 ~119 minecraft:gray_stained_glass
fill ~-32 ~6 ~119 ~-32 ~7 ~119 minecraft:light_gray_stained_glass
setblock ~-35 ~1 ~117 minecraft:iron_door[half=lower,facing=north]
setblock ~-35 ~2 ~117 minecraft:iron_door[half=upper,facing=north]
fill ~-37 ~7 ~117 ~-32 ~11 ~122 minecraft:air
fill ~-36 ~7 ~118 ~-33 ~11 ~121 minecraft:mud_bricks
fill ~-35 ~8 ~119 ~-34 ~10 ~120 minecraft:air
fill ~-36 ~12 ~118 ~-33 ~12 ~121 minecraft:deepslate_tile_slab
