# Buildings 121..128
# 121 row_house style=japanese_house context=local_front facing=east
fill ~-124 ~-3 ~-11 ~-117 ~-1 ~-5 minecraft:stone
fill ~-124 ~0 ~-11 ~-117 ~11 ~-5 minecraft:mud_bricks
fill ~-123 ~1 ~-10 ~-118 ~10 ~-6 minecraft:air
fill ~-123 ~4 ~-10 ~-118 ~4 ~-6 minecraft:smooth_stone
fill ~-123 ~8 ~-10 ~-118 ~8 ~-6 minecraft:smooth_stone
fill ~-122 ~2 ~-11 ~-122 ~3 ~-11 minecraft:gray_stained_glass
fill ~-122 ~2 ~-5 ~-122 ~3 ~-5 minecraft:light_gray_stained_glass
fill ~-119 ~2 ~-11 ~-119 ~3 ~-11 minecraft:gray_stained_glass
fill ~-119 ~2 ~-5 ~-119 ~3 ~-5 minecraft:light_gray_stained_glass
fill ~-124 ~2 ~-9 ~-124 ~3 ~-9 minecraft:gray_stained_glass
fill ~-117 ~2 ~-9 ~-117 ~3 ~-9 minecraft:light_gray_stained_glass
fill ~-122 ~6 ~-11 ~-122 ~7 ~-11 minecraft:gray_stained_glass
fill ~-122 ~6 ~-5 ~-122 ~7 ~-5 minecraft:light_gray_stained_glass
fill ~-119 ~6 ~-11 ~-119 ~7 ~-11 minecraft:gray_stained_glass
fill ~-119 ~6 ~-5 ~-119 ~7 ~-5 minecraft:light_gray_stained_glass
fill ~-124 ~6 ~-9 ~-124 ~7 ~-9 minecraft:gray_stained_glass
fill ~-117 ~6 ~-9 ~-117 ~7 ~-9 minecraft:light_gray_stained_glass
setblock ~-117 ~1 ~-8 minecraft:iron_door[half=lower,facing=east]
setblock ~-117 ~2 ~-8 minecraft:iron_door[half=upper,facing=east]
fill ~-124 ~12 ~-11 ~-117 ~12 ~-5 minecraft:deepslate_tile_slab
fill ~-123 ~13 ~-10 ~-118 ~13 ~-6 minecraft:deepslate_tile_slab
setblock ~-116 ~3 ~-8 minecraft:dark_oak_slab[type=top]
# 122 logistics style=loading_bay context=local_front facing=east
fill ~52 ~-3 ~91 ~62 ~-1 ~100 minecraft:stone
fill ~52 ~0 ~91 ~62 ~12 ~100 minecraft:stone_bricks
fill ~53 ~1 ~92 ~61 ~11 ~99 minecraft:air
fill ~53 ~4 ~92 ~61 ~4 ~99 minecraft:smooth_stone
fill ~53 ~8 ~92 ~61 ~8 ~99 minecraft:smooth_stone
fill ~54 ~2 ~91 ~54 ~3 ~91 minecraft:gray_stained_glass
fill ~54 ~2 ~100 ~54 ~3 ~100 minecraft:light_gray_stained_glass
fill ~57 ~2 ~91 ~57 ~3 ~91 minecraft:gray_stained_glass
fill ~57 ~2 ~100 ~57 ~3 ~100 minecraft:light_gray_stained_glass
fill ~60 ~2 ~91 ~60 ~3 ~91 minecraft:gray_stained_glass
fill ~60 ~2 ~100 ~60 ~3 ~100 minecraft:light_gray_stained_glass
fill ~52 ~2 ~93 ~52 ~3 ~93 minecraft:gray_stained_glass
fill ~62 ~2 ~93 ~62 ~3 ~93 minecraft:light_gray_stained_glass
fill ~52 ~2 ~96 ~52 ~3 ~96 minecraft:gray_stained_glass
fill ~62 ~2 ~96 ~62 ~3 ~96 minecraft:light_gray_stained_glass
fill ~54 ~6 ~91 ~54 ~7 ~91 minecraft:gray_stained_glass
fill ~54 ~6 ~100 ~54 ~7 ~100 minecraft:light_gray_stained_glass
fill ~57 ~6 ~91 ~57 ~7 ~91 minecraft:gray_stained_glass
fill ~57 ~6 ~100 ~57 ~7 ~100 minecraft:light_gray_stained_glass
fill ~60 ~6 ~91 ~60 ~7 ~91 minecraft:gray_stained_glass
fill ~60 ~6 ~100 ~60 ~7 ~100 minecraft:light_gray_stained_glass
fill ~52 ~6 ~93 ~52 ~7 ~93 minecraft:gray_stained_glass
fill ~62 ~6 ~93 ~62 ~7 ~93 minecraft:light_gray_stained_glass
fill ~52 ~6 ~96 ~52 ~7 ~96 minecraft:gray_stained_glass
fill ~62 ~6 ~96 ~62 ~7 ~96 minecraft:light_gray_stained_glass
fill ~54 ~10 ~91 ~54 ~11 ~91 minecraft:gray_stained_glass
fill ~54 ~10 ~100 ~54 ~11 ~100 minecraft:light_gray_stained_glass
fill ~57 ~10 ~91 ~57 ~11 ~91 minecraft:gray_stained_glass
fill ~57 ~10 ~100 ~57 ~11 ~100 minecraft:light_gray_stained_glass
fill ~60 ~10 ~91 ~60 ~11 ~91 minecraft:gray_stained_glass
fill ~60 ~10 ~100 ~60 ~11 ~100 minecraft:light_gray_stained_glass
fill ~52 ~10 ~93 ~52 ~11 ~93 minecraft:gray_stained_glass
fill ~62 ~10 ~93 ~62 ~11 ~93 minecraft:light_gray_stained_glass
fill ~52 ~10 ~96 ~52 ~11 ~96 minecraft:gray_stained_glass
fill ~62 ~10 ~96 ~62 ~11 ~96 minecraft:light_gray_stained_glass
setblock ~62 ~1 ~95 minecraft:iron_door[half=lower,facing=east]
setblock ~62 ~2 ~95 minecraft:iron_door[half=upper,facing=east]
fill ~62 ~1 ~93 ~62 ~4 ~98 minecraft:polished_blackstone
fill ~62 ~5 ~93 ~62 ~5 ~98 minecraft:light_blue_stained_glass
fill ~54 ~14 ~93 ~56 ~15 ~95 minecraft:iron_block
fill ~52 ~13 ~91 ~62 ~13 ~100 minecraft:stone_brick_slab
# 123 shop_house style=corner_store context=collector_front facing=south
fill ~-33 ~-3 ~70 ~-26 ~-1 ~77 minecraft:stone
fill ~-33 ~0 ~70 ~-26 ~16 ~77 minecraft:smooth_sandstone
fill ~-32 ~1 ~71 ~-27 ~15 ~76 minecraft:air
fill ~-32 ~4 ~71 ~-27 ~4 ~76 minecraft:smooth_stone
fill ~-32 ~8 ~71 ~-27 ~8 ~76 minecraft:smooth_stone
fill ~-32 ~12 ~71 ~-27 ~12 ~76 minecraft:smooth_stone
fill ~-31 ~2 ~70 ~-31 ~3 ~70 minecraft:gray_stained_glass
fill ~-31 ~2 ~77 ~-31 ~3 ~77 minecraft:light_gray_stained_glass
fill ~-28 ~2 ~70 ~-28 ~3 ~70 minecraft:gray_stained_glass
fill ~-28 ~2 ~77 ~-28 ~3 ~77 minecraft:light_gray_stained_glass
fill ~-33 ~2 ~72 ~-33 ~3 ~72 minecraft:gray_stained_glass
fill ~-26 ~2 ~72 ~-26 ~3 ~72 minecraft:light_gray_stained_glass
fill ~-33 ~2 ~75 ~-33 ~3 ~75 minecraft:gray_stained_glass
fill ~-26 ~2 ~75 ~-26 ~3 ~75 minecraft:light_gray_stained_glass
fill ~-31 ~6 ~70 ~-31 ~7 ~70 minecraft:gray_stained_glass
fill ~-31 ~6 ~77 ~-31 ~7 ~77 minecraft:light_gray_stained_glass
fill ~-28 ~6 ~70 ~-28 ~7 ~70 minecraft:gray_stained_glass
fill ~-28 ~6 ~77 ~-28 ~7 ~77 minecraft:light_gray_stained_glass
fill ~-33 ~6 ~72 ~-33 ~7 ~72 minecraft:gray_stained_glass
fill ~-26 ~6 ~72 ~-26 ~7 ~72 minecraft:light_gray_stained_glass
fill ~-33 ~6 ~75 ~-33 ~7 ~75 minecraft:gray_stained_glass
fill ~-26 ~6 ~75 ~-26 ~7 ~75 minecraft:light_gray_stained_glass
fill ~-31 ~10 ~70 ~-31 ~11 ~70 minecraft:gray_stained_glass
fill ~-31 ~10 ~77 ~-31 ~11 ~77 minecraft:light_gray_stained_glass
fill ~-28 ~10 ~70 ~-28 ~11 ~70 minecraft:gray_stained_glass
fill ~-28 ~10 ~77 ~-28 ~11 ~77 minecraft:light_gray_stained_glass
fill ~-33 ~10 ~72 ~-33 ~11 ~72 minecraft:gray_stained_glass
fill ~-26 ~10 ~72 ~-26 ~11 ~72 minecraft:light_gray_stained_glass
fill ~-33 ~10 ~75 ~-33 ~11 ~75 minecraft:gray_stained_glass
fill ~-26 ~10 ~75 ~-26 ~11 ~75 minecraft:light_gray_stained_glass
fill ~-31 ~14 ~70 ~-31 ~15 ~70 minecraft:gray_stained_glass
fill ~-31 ~14 ~77 ~-31 ~15 ~77 minecraft:light_gray_stained_glass
fill ~-28 ~14 ~70 ~-28 ~15 ~70 minecraft:gray_stained_glass
fill ~-28 ~14 ~77 ~-28 ~15 ~77 minecraft:light_gray_stained_glass
fill ~-33 ~14 ~72 ~-33 ~15 ~72 minecraft:gray_stained_glass
fill ~-26 ~14 ~72 ~-26 ~15 ~72 minecraft:light_gray_stained_glass
fill ~-33 ~14 ~75 ~-33 ~15 ~75 minecraft:gray_stained_glass
fill ~-26 ~14 ~75 ~-26 ~15 ~75 minecraft:light_gray_stained_glass
setblock ~-30 ~1 ~77 minecraft:iron_door[half=lower,facing=south]
setblock ~-30 ~2 ~77 minecraft:iron_door[half=upper,facing=south]
fill ~-32 ~1 ~77 ~-27 ~3 ~77 minecraft:cyan_stained_glass
setblock ~-30 ~1 ~77 minecraft:iron_door[half=lower,facing=south]
setblock ~-30 ~2 ~77 minecraft:iron_door[half=upper,facing=south]
setblock ~-30 ~3 ~78 minecraft:red_wool
fill ~-33 ~17 ~70 ~-26 ~17 ~77 minecraft:stone_brick_slab
fill ~-31 ~18 ~72 ~-29 ~19 ~74 minecraft:light_gray_concrete
setblock ~-28 ~18 ~73 minecraft:lightning_rod
# 124 community style=balcony_block context=collector_front facing=south
fill ~-106 ~-3 ~85 ~-101 ~-1 ~91 minecraft:stone
fill ~-106 ~0 ~85 ~-101 ~7 ~91 minecraft:calcite
fill ~-105 ~1 ~86 ~-102 ~6 ~90 minecraft:air
fill ~-105 ~4 ~86 ~-102 ~4 ~90 minecraft:smooth_stone
fill ~-104 ~2 ~85 ~-104 ~3 ~85 minecraft:gray_stained_glass
fill ~-104 ~2 ~91 ~-104 ~3 ~91 minecraft:light_gray_stained_glass
fill ~-106 ~2 ~87 ~-106 ~3 ~87 minecraft:gray_stained_glass
fill ~-101 ~2 ~87 ~-101 ~3 ~87 minecraft:light_gray_stained_glass
setblock ~-104 ~1 ~91 minecraft:iron_door[half=lower,facing=south]
setblock ~-104 ~2 ~91 minecraft:iron_door[half=upper,facing=south]
fill ~-104 ~4 ~92 ~-103 ~4 ~92 minecraft:smooth_stone_slab
fill ~-106 ~8 ~85 ~-101 ~8 ~91 minecraft:stone_brick_slab
# 125 mixed_use style=balcony_block context=arterial_front facing=north
fill ~7 ~-3 ~-8 ~13 ~-1 ~0 minecraft:stone
fill ~7 ~0 ~-8 ~13 ~12 ~0 minecraft:white_terracotta
fill ~8 ~1 ~-7 ~12 ~11 ~-1 minecraft:air
fill ~8 ~4 ~-7 ~12 ~4 ~-1 minecraft:smooth_stone
fill ~8 ~8 ~-7 ~12 ~8 ~-1 minecraft:smooth_stone
fill ~9 ~2 ~-8 ~9 ~3 ~-8 minecraft:gray_stained_glass
fill ~9 ~2 ~0 ~9 ~3 ~0 minecraft:light_gray_stained_glass
fill ~7 ~2 ~-6 ~7 ~3 ~-6 minecraft:gray_stained_glass
fill ~13 ~2 ~-6 ~13 ~3 ~-6 minecraft:light_gray_stained_glass
fill ~7 ~2 ~-3 ~7 ~3 ~-3 minecraft:gray_stained_glass
fill ~13 ~2 ~-3 ~13 ~3 ~-3 minecraft:light_gray_stained_glass
fill ~9 ~6 ~-8 ~9 ~7 ~-8 minecraft:gray_stained_glass
fill ~9 ~6 ~0 ~9 ~7 ~0 minecraft:light_gray_stained_glass
fill ~7 ~6 ~-6 ~7 ~7 ~-6 minecraft:gray_stained_glass
fill ~13 ~6 ~-6 ~13 ~7 ~-6 minecraft:light_gray_stained_glass
fill ~7 ~6 ~-3 ~7 ~7 ~-3 minecraft:gray_stained_glass
fill ~13 ~6 ~-3 ~13 ~7 ~-3 minecraft:light_gray_stained_glass
fill ~9 ~10 ~-8 ~9 ~11 ~-8 minecraft:gray_stained_glass
fill ~9 ~10 ~0 ~9 ~11 ~0 minecraft:light_gray_stained_glass
fill ~7 ~10 ~-6 ~7 ~11 ~-6 minecraft:gray_stained_glass
fill ~13 ~10 ~-6 ~13 ~11 ~-6 minecraft:light_gray_stained_glass
fill ~7 ~10 ~-3 ~7 ~11 ~-3 minecraft:gray_stained_glass
fill ~13 ~10 ~-3 ~13 ~11 ~-3 minecraft:light_gray_stained_glass
setblock ~10 ~1 ~-8 minecraft:iron_door[half=lower,facing=north]
setblock ~10 ~2 ~-8 minecraft:iron_door[half=upper,facing=north]
fill ~9 ~4 ~-9 ~11 ~4 ~-9 minecraft:smooth_stone_slab
fill ~9 ~8 ~-9 ~11 ~8 ~-9 minecraft:smooth_stone_slab
fill ~7 ~13 ~-8 ~13 ~13 ~0 minecraft:stone_brick_slab
# 126 detached_house style=rowhouse context=local_front facing=east
fill ~-124 ~-3 ~44 ~-119 ~-1 ~54 minecraft:stone
fill ~-124 ~0 ~44 ~-119 ~9 ~54 minecraft:white_terracotta
fill ~-123 ~1 ~45 ~-120 ~8 ~53 minecraft:air
fill ~-123 ~4 ~45 ~-120 ~4 ~53 minecraft:smooth_stone
fill ~-123 ~8 ~45 ~-120 ~8 ~53 minecraft:smooth_stone
fill ~-122 ~2 ~44 ~-122 ~3 ~44 minecraft:gray_stained_glass
fill ~-122 ~2 ~54 ~-122 ~3 ~54 minecraft:light_gray_stained_glass
fill ~-124 ~2 ~46 ~-124 ~3 ~46 minecraft:gray_stained_glass
fill ~-119 ~2 ~46 ~-119 ~3 ~46 minecraft:light_gray_stained_glass
fill ~-124 ~2 ~49 ~-124 ~3 ~49 minecraft:gray_stained_glass
fill ~-119 ~2 ~49 ~-119 ~3 ~49 minecraft:light_gray_stained_glass
fill ~-124 ~2 ~52 ~-124 ~3 ~52 minecraft:gray_stained_glass
fill ~-119 ~2 ~52 ~-119 ~3 ~52 minecraft:light_gray_stained_glass
fill ~-122 ~6 ~44 ~-122 ~7 ~44 minecraft:gray_stained_glass
fill ~-122 ~6 ~54 ~-122 ~7 ~54 minecraft:light_gray_stained_glass
fill ~-124 ~6 ~46 ~-124 ~7 ~46 minecraft:gray_stained_glass
fill ~-119 ~6 ~46 ~-119 ~7 ~46 minecraft:light_gray_stained_glass
fill ~-124 ~6 ~49 ~-124 ~7 ~49 minecraft:gray_stained_glass
fill ~-119 ~6 ~49 ~-119 ~7 ~49 minecraft:light_gray_stained_glass
fill ~-124 ~6 ~52 ~-124 ~7 ~52 minecraft:gray_stained_glass
fill ~-119 ~6 ~52 ~-119 ~7 ~52 minecraft:light_gray_stained_glass
setblock ~-119 ~1 ~49 minecraft:iron_door[half=lower,facing=east]
setblock ~-119 ~2 ~49 minecraft:iron_door[half=upper,facing=east]
fill ~-124 ~10 ~44 ~-119 ~10 ~54 minecraft:dark_oak_slab
fill ~-123 ~11 ~45 ~-120 ~11 ~53 minecraft:dark_oak_slab
setblock ~-118 ~3 ~49 minecraft:dark_oak_slab[type=top]
fill ~-122 ~11 ~46 ~-120 ~12 ~48 minecraft:light_gray_concrete
setblock ~-120 ~11 ~47 minecraft:lightning_rod
# 127 large_retail style=corner_store context=arterial_front facing=south
fill ~-42 ~-3 ~-35 ~-30 ~-1 ~-26 minecraft:stone
fill ~-42 ~0 ~-35 ~-30 ~24 ~-26 minecraft:bricks
fill ~-41 ~1 ~-34 ~-31 ~23 ~-27 minecraft:air
fill ~-41 ~4 ~-34 ~-31 ~4 ~-27 minecraft:smooth_stone
fill ~-41 ~8 ~-34 ~-31 ~8 ~-27 minecraft:smooth_stone
fill ~-41 ~12 ~-34 ~-31 ~12 ~-27 minecraft:smooth_stone
fill ~-41 ~16 ~-34 ~-31 ~16 ~-27 minecraft:smooth_stone
fill ~-41 ~20 ~-34 ~-31 ~20 ~-27 minecraft:smooth_stone
fill ~-40 ~2 ~-35 ~-40 ~3 ~-35 minecraft:gray_stained_glass
fill ~-40 ~2 ~-26 ~-40 ~3 ~-26 minecraft:light_gray_stained_glass
fill ~-37 ~2 ~-35 ~-37 ~3 ~-35 minecraft:gray_stained_glass
fill ~-37 ~2 ~-26 ~-37 ~3 ~-26 minecraft:light_gray_stained_glass
fill ~-34 ~2 ~-35 ~-34 ~3 ~-35 minecraft:gray_stained_glass
fill ~-34 ~2 ~-26 ~-34 ~3 ~-26 minecraft:light_gray_stained_glass
fill ~-42 ~2 ~-33 ~-42 ~3 ~-33 minecraft:gray_stained_glass
fill ~-30 ~2 ~-33 ~-30 ~3 ~-33 minecraft:light_gray_stained_glass
fill ~-42 ~2 ~-30 ~-42 ~3 ~-30 minecraft:gray_stained_glass
fill ~-30 ~2 ~-30 ~-30 ~3 ~-30 minecraft:light_gray_stained_glass
fill ~-40 ~6 ~-35 ~-40 ~7 ~-35 minecraft:gray_stained_glass
fill ~-40 ~6 ~-26 ~-40 ~7 ~-26 minecraft:light_gray_stained_glass
fill ~-37 ~6 ~-35 ~-37 ~7 ~-35 minecraft:gray_stained_glass
fill ~-37 ~6 ~-26 ~-37 ~7 ~-26 minecraft:light_gray_stained_glass
fill ~-34 ~6 ~-35 ~-34 ~7 ~-35 minecraft:gray_stained_glass
fill ~-34 ~6 ~-26 ~-34 ~7 ~-26 minecraft:light_gray_stained_glass
fill ~-42 ~6 ~-33 ~-42 ~7 ~-33 minecraft:gray_stained_glass
fill ~-30 ~6 ~-33 ~-30 ~7 ~-33 minecraft:light_gray_stained_glass
fill ~-42 ~6 ~-30 ~-42 ~7 ~-30 minecraft:gray_stained_glass
fill ~-30 ~6 ~-30 ~-30 ~7 ~-30 minecraft:light_gray_stained_glass
fill ~-40 ~10 ~-35 ~-40 ~11 ~-35 minecraft:gray_stained_glass
fill ~-40 ~10 ~-26 ~-40 ~11 ~-26 minecraft:light_gray_stained_glass
fill ~-37 ~10 ~-35 ~-37 ~11 ~-35 minecraft:gray_stained_glass
fill ~-37 ~10 ~-26 ~-37 ~11 ~-26 minecraft:light_gray_stained_glass
fill ~-34 ~10 ~-35 ~-34 ~11 ~-35 minecraft:gray_stained_glass
fill ~-34 ~10 ~-26 ~-34 ~11 ~-26 minecraft:light_gray_stained_glass
fill ~-42 ~10 ~-33 ~-42 ~11 ~-33 minecraft:gray_stained_glass
fill ~-30 ~10 ~-33 ~-30 ~11 ~-33 minecraft:light_gray_stained_glass
fill ~-42 ~10 ~-30 ~-42 ~11 ~-30 minecraft:gray_stained_glass
fill ~-30 ~10 ~-30 ~-30 ~11 ~-30 minecraft:light_gray_stained_glass
fill ~-40 ~14 ~-35 ~-40 ~15 ~-35 minecraft:gray_stained_glass
fill ~-40 ~14 ~-26 ~-40 ~15 ~-26 minecraft:light_gray_stained_glass
fill ~-37 ~14 ~-35 ~-37 ~15 ~-35 minecraft:gray_stained_glass
fill ~-37 ~14 ~-26 ~-37 ~15 ~-26 minecraft:light_gray_stained_glass
fill ~-34 ~14 ~-35 ~-34 ~15 ~-35 minecraft:gray_stained_glass
fill ~-34 ~14 ~-26 ~-34 ~15 ~-26 minecraft:light_gray_stained_glass
fill ~-42 ~14 ~-33 ~-42 ~15 ~-33 minecraft:gray_stained_glass
fill ~-30 ~14 ~-33 ~-30 ~15 ~-33 minecraft:light_gray_stained_glass
fill ~-42 ~14 ~-30 ~-42 ~15 ~-30 minecraft:gray_stained_glass
fill ~-30 ~14 ~-30 ~-30 ~15 ~-30 minecraft:light_gray_stained_glass
fill ~-40 ~18 ~-35 ~-40 ~19 ~-35 minecraft:gray_stained_glass
fill ~-40 ~18 ~-26 ~-40 ~19 ~-26 minecraft:light_gray_stained_glass
fill ~-37 ~18 ~-35 ~-37 ~19 ~-35 minecraft:gray_stained_glass
fill ~-37 ~18 ~-26 ~-37 ~19 ~-26 minecraft:light_gray_stained_glass
fill ~-34 ~18 ~-35 ~-34 ~19 ~-35 minecraft:gray_stained_glass
fill ~-34 ~18 ~-26 ~-34 ~19 ~-26 minecraft:light_gray_stained_glass
fill ~-42 ~18 ~-33 ~-42 ~19 ~-33 minecraft:gray_stained_glass
fill ~-30 ~18 ~-33 ~-30 ~19 ~-33 minecraft:light_gray_stained_glass
fill ~-42 ~18 ~-30 ~-42 ~19 ~-30 minecraft:gray_stained_glass
fill ~-30 ~18 ~-30 ~-30 ~19 ~-30 minecraft:light_gray_stained_glass
fill ~-40 ~22 ~-35 ~-40 ~23 ~-35 minecraft:gray_stained_glass
fill ~-40 ~22 ~-26 ~-40 ~23 ~-26 minecraft:light_gray_stained_glass
fill ~-37 ~22 ~-35 ~-37 ~23 ~-35 minecraft:gray_stained_glass
fill ~-37 ~22 ~-26 ~-37 ~23 ~-26 minecraft:light_gray_stained_glass
fill ~-34 ~22 ~-35 ~-34 ~23 ~-35 minecraft:gray_stained_glass
fill ~-34 ~22 ~-26 ~-34 ~23 ~-26 minecraft:light_gray_stained_glass
fill ~-42 ~22 ~-33 ~-42 ~23 ~-33 minecraft:gray_stained_glass
fill ~-30 ~22 ~-33 ~-30 ~23 ~-33 minecraft:light_gray_stained_glass
fill ~-42 ~22 ~-30 ~-42 ~23 ~-30 minecraft:gray_stained_glass
fill ~-30 ~22 ~-30 ~-30 ~23 ~-30 minecraft:light_gray_stained_glass
setblock ~-37 ~1 ~-26 minecraft:iron_door[half=lower,facing=south]
setblock ~-37 ~2 ~-26 minecraft:iron_door[half=upper,facing=south]
fill ~-41 ~1 ~-26 ~-31 ~3 ~-26 minecraft:cyan_stained_glass
setblock ~-37 ~1 ~-26 minecraft:iron_door[half=lower,facing=south]
setblock ~-37 ~2 ~-26 minecraft:iron_door[half=upper,facing=south]
setblock ~-37 ~3 ~-25 minecraft:red_wool
fill ~-42 ~25 ~-35 ~-30 ~25 ~-26 minecraft:deepslate_tile_slab
fill ~-32 ~22 ~-28 ~-30 ~26 ~-26 minecraft:air
setblock ~-32 ~22 ~-28 minecraft:cobweb
# 128 community style=mixed_facade context=collector_front facing=north
fill ~66 ~-3 ~-63 ~79 ~-1 ~-55 minecraft:stone
fill ~66 ~0 ~-63 ~79 ~12 ~-55 minecraft:smooth_sandstone
fill ~67 ~1 ~-62 ~78 ~11 ~-56 minecraft:air
fill ~67 ~4 ~-62 ~78 ~4 ~-56 minecraft:smooth_stone
fill ~67 ~8 ~-62 ~78 ~8 ~-56 minecraft:smooth_stone
fill ~68 ~2 ~-63 ~68 ~3 ~-63 minecraft:gray_stained_glass
fill ~68 ~2 ~-55 ~68 ~3 ~-55 minecraft:light_gray_stained_glass
fill ~71 ~2 ~-63 ~71 ~3 ~-63 minecraft:gray_stained_glass
fill ~71 ~2 ~-55 ~71 ~3 ~-55 minecraft:light_gray_stained_glass
fill ~74 ~2 ~-63 ~74 ~3 ~-63 minecraft:gray_stained_glass
fill ~74 ~2 ~-55 ~74 ~3 ~-55 minecraft:light_gray_stained_glass
fill ~77 ~2 ~-63 ~77 ~3 ~-63 minecraft:gray_stained_glass
fill ~77 ~2 ~-55 ~77 ~3 ~-55 minecraft:light_gray_stained_glass
fill ~66 ~2 ~-61 ~66 ~3 ~-61 minecraft:gray_stained_glass
fill ~79 ~2 ~-61 ~79 ~3 ~-61 minecraft:light_gray_stained_glass
fill ~66 ~2 ~-58 ~66 ~3 ~-58 minecraft:gray_stained_glass
fill ~79 ~2 ~-58 ~79 ~3 ~-58 minecraft:light_gray_stained_glass
fill ~68 ~6 ~-63 ~68 ~7 ~-63 minecraft:gray_stained_glass
fill ~68 ~6 ~-55 ~68 ~7 ~-55 minecraft:light_gray_stained_glass
fill ~71 ~6 ~-63 ~71 ~7 ~-63 minecraft:gray_stained_glass
fill ~71 ~6 ~-55 ~71 ~7 ~-55 minecraft:light_gray_stained_glass
fill ~74 ~6 ~-63 ~74 ~7 ~-63 minecraft:gray_stained_glass
fill ~74 ~6 ~-55 ~74 ~7 ~-55 minecraft:light_gray_stained_glass
fill ~77 ~6 ~-63 ~77 ~7 ~-63 minecraft:gray_stained_glass
fill ~77 ~6 ~-55 ~77 ~7 ~-55 minecraft:light_gray_stained_glass
fill ~66 ~6 ~-61 ~66 ~7 ~-61 minecraft:gray_stained_glass
fill ~79 ~6 ~-61 ~79 ~7 ~-61 minecraft:light_gray_stained_glass
fill ~66 ~6 ~-58 ~66 ~7 ~-58 minecraft:gray_stained_glass
fill ~79 ~6 ~-58 ~79 ~7 ~-58 minecraft:light_gray_stained_glass
fill ~68 ~10 ~-63 ~68 ~11 ~-63 minecraft:gray_stained_glass
fill ~68 ~10 ~-55 ~68 ~11 ~-55 minecraft:light_gray_stained_glass
fill ~71 ~10 ~-63 ~71 ~11 ~-63 minecraft:gray_stained_glass
fill ~71 ~10 ~-55 ~71 ~11 ~-55 minecraft:light_gray_stained_glass
fill ~74 ~10 ~-63 ~74 ~11 ~-63 minecraft:gray_stained_glass
fill ~74 ~10 ~-55 ~74 ~11 ~-55 minecraft:light_gray_stained_glass
fill ~77 ~10 ~-63 ~77 ~11 ~-63 minecraft:gray_stained_glass
fill ~77 ~10 ~-55 ~77 ~11 ~-55 minecraft:light_gray_stained_glass
fill ~66 ~10 ~-61 ~66 ~11 ~-61 minecraft:gray_stained_glass
fill ~79 ~10 ~-61 ~79 ~11 ~-61 minecraft:light_gray_stained_glass
fill ~66 ~10 ~-58 ~66 ~11 ~-58 minecraft:gray_stained_glass
fill ~79 ~10 ~-58 ~79 ~11 ~-58 minecraft:light_gray_stained_glass
setblock ~71 ~1 ~-63 minecraft:iron_door[half=lower,facing=north]
setblock ~71 ~2 ~-63 minecraft:iron_door[half=upper,facing=north]
fill ~66 ~13 ~-63 ~79 ~13 ~-55 minecraft:stone_brick_slab
