# Buildings 25..32
# 025 community style=setback_block context=collector_front facing=north
fill ~1 ~-3 ~52 ~10 ~-1 ~61 minecraft:stone
fill ~1 ~0 ~52 ~10 ~16 ~61 minecraft:smooth_sandstone
fill ~2 ~1 ~53 ~9 ~15 ~60 minecraft:air
fill ~2 ~4 ~53 ~9 ~4 ~60 minecraft:smooth_stone
fill ~2 ~8 ~53 ~9 ~8 ~60 minecraft:smooth_stone
fill ~2 ~12 ~53 ~9 ~12 ~60 minecraft:smooth_stone
fill ~3 ~2 ~52 ~3 ~3 ~52 minecraft:gray_stained_glass
fill ~3 ~2 ~61 ~3 ~3 ~61 minecraft:light_gray_stained_glass
fill ~6 ~2 ~52 ~6 ~3 ~52 minecraft:gray_stained_glass
fill ~6 ~2 ~61 ~6 ~3 ~61 minecraft:light_gray_stained_glass
fill ~1 ~2 ~54 ~1 ~3 ~54 minecraft:gray_stained_glass
fill ~10 ~2 ~54 ~10 ~3 ~54 minecraft:light_gray_stained_glass
fill ~1 ~2 ~57 ~1 ~3 ~57 minecraft:gray_stained_glass
fill ~10 ~2 ~57 ~10 ~3 ~57 minecraft:light_gray_stained_glass
fill ~3 ~6 ~52 ~3 ~7 ~52 minecraft:gray_stained_glass
fill ~3 ~6 ~61 ~3 ~7 ~61 minecraft:light_gray_stained_glass
fill ~6 ~6 ~52 ~6 ~7 ~52 minecraft:gray_stained_glass
fill ~6 ~6 ~61 ~6 ~7 ~61 minecraft:light_gray_stained_glass
fill ~1 ~6 ~54 ~1 ~7 ~54 minecraft:gray_stained_glass
fill ~10 ~6 ~54 ~10 ~7 ~54 minecraft:light_gray_stained_glass
fill ~1 ~6 ~57 ~1 ~7 ~57 minecraft:gray_stained_glass
fill ~10 ~6 ~57 ~10 ~7 ~57 minecraft:light_gray_stained_glass
fill ~3 ~10 ~52 ~3 ~11 ~52 minecraft:gray_stained_glass
fill ~3 ~10 ~61 ~3 ~11 ~61 minecraft:light_gray_stained_glass
fill ~6 ~10 ~52 ~6 ~11 ~52 minecraft:gray_stained_glass
fill ~6 ~10 ~61 ~6 ~11 ~61 minecraft:light_gray_stained_glass
fill ~1 ~10 ~54 ~1 ~11 ~54 minecraft:gray_stained_glass
fill ~10 ~10 ~54 ~10 ~11 ~54 minecraft:light_gray_stained_glass
fill ~1 ~10 ~57 ~1 ~11 ~57 minecraft:gray_stained_glass
fill ~10 ~10 ~57 ~10 ~11 ~57 minecraft:light_gray_stained_glass
fill ~3 ~14 ~52 ~3 ~15 ~52 minecraft:gray_stained_glass
fill ~3 ~14 ~61 ~3 ~15 ~61 minecraft:light_gray_stained_glass
fill ~6 ~14 ~52 ~6 ~15 ~52 minecraft:gray_stained_glass
fill ~6 ~14 ~61 ~6 ~15 ~61 minecraft:light_gray_stained_glass
fill ~1 ~14 ~54 ~1 ~15 ~54 minecraft:gray_stained_glass
fill ~10 ~14 ~54 ~10 ~15 ~54 minecraft:light_gray_stained_glass
fill ~1 ~14 ~57 ~1 ~15 ~57 minecraft:gray_stained_glass
fill ~10 ~14 ~57 ~10 ~15 ~57 minecraft:light_gray_stained_glass
setblock ~5 ~1 ~52 minecraft:iron_door[half=lower,facing=north]
setblock ~5 ~2 ~52 minecraft:iron_door[half=upper,facing=north]
fill ~1 ~11 ~52 ~10 ~16 ~61 minecraft:air
fill ~2 ~11 ~53 ~9 ~16 ~60 minecraft:smooth_sandstone
fill ~3 ~12 ~54 ~8 ~15 ~59 minecraft:air
fill ~2 ~17 ~53 ~9 ~17 ~60 minecraft:stone_brick_slab
fill ~2 ~1 ~52 ~2 ~7 ~52 minecraft:brown_terracotta
fill ~6 ~1 ~52 ~6 ~7 ~52 minecraft:brown_terracotta
# 026 mixed_use style=mixed_facade context=arterial_front facing=north
fill ~48 ~-3 ~6 ~57 ~-1 ~13 minecraft:stone
fill ~48 ~0 ~6 ~57 ~16 ~13 minecraft:smooth_sandstone
fill ~49 ~1 ~7 ~56 ~15 ~12 minecraft:air
fill ~49 ~4 ~7 ~56 ~4 ~12 minecraft:smooth_stone
fill ~49 ~8 ~7 ~56 ~8 ~12 minecraft:smooth_stone
fill ~49 ~12 ~7 ~56 ~12 ~12 minecraft:smooth_stone
fill ~50 ~2 ~6 ~50 ~3 ~6 minecraft:gray_stained_glass
fill ~50 ~2 ~13 ~50 ~3 ~13 minecraft:light_gray_stained_glass
fill ~53 ~2 ~6 ~53 ~3 ~6 minecraft:gray_stained_glass
fill ~53 ~2 ~13 ~53 ~3 ~13 minecraft:light_gray_stained_glass
fill ~48 ~2 ~8 ~48 ~3 ~8 minecraft:gray_stained_glass
fill ~57 ~2 ~8 ~57 ~3 ~8 minecraft:light_gray_stained_glass
fill ~48 ~2 ~11 ~48 ~3 ~11 minecraft:gray_stained_glass
fill ~57 ~2 ~11 ~57 ~3 ~11 minecraft:light_gray_stained_glass
fill ~50 ~6 ~6 ~50 ~7 ~6 minecraft:gray_stained_glass
fill ~50 ~6 ~13 ~50 ~7 ~13 minecraft:light_gray_stained_glass
fill ~53 ~6 ~6 ~53 ~7 ~6 minecraft:gray_stained_glass
fill ~53 ~6 ~13 ~53 ~7 ~13 minecraft:light_gray_stained_glass
fill ~48 ~6 ~8 ~48 ~7 ~8 minecraft:gray_stained_glass
fill ~57 ~6 ~8 ~57 ~7 ~8 minecraft:light_gray_stained_glass
fill ~48 ~6 ~11 ~48 ~7 ~11 minecraft:gray_stained_glass
fill ~57 ~6 ~11 ~57 ~7 ~11 minecraft:light_gray_stained_glass
fill ~50 ~10 ~6 ~50 ~11 ~6 minecraft:gray_stained_glass
fill ~50 ~10 ~13 ~50 ~11 ~13 minecraft:light_gray_stained_glass
fill ~53 ~10 ~6 ~53 ~11 ~6 minecraft:gray_stained_glass
fill ~53 ~10 ~13 ~53 ~11 ~13 minecraft:light_gray_stained_glass
fill ~48 ~10 ~8 ~48 ~11 ~8 minecraft:gray_stained_glass
fill ~57 ~10 ~8 ~57 ~11 ~8 minecraft:light_gray_stained_glass
fill ~48 ~10 ~11 ~48 ~11 ~11 minecraft:gray_stained_glass
fill ~57 ~10 ~11 ~57 ~11 ~11 minecraft:light_gray_stained_glass
fill ~50 ~14 ~6 ~50 ~15 ~6 minecraft:gray_stained_glass
fill ~50 ~14 ~13 ~50 ~15 ~13 minecraft:light_gray_stained_glass
fill ~53 ~14 ~6 ~53 ~15 ~6 minecraft:gray_stained_glass
fill ~53 ~14 ~13 ~53 ~15 ~13 minecraft:light_gray_stained_glass
fill ~48 ~14 ~8 ~48 ~15 ~8 minecraft:gray_stained_glass
fill ~57 ~14 ~8 ~57 ~15 ~8 minecraft:light_gray_stained_glass
fill ~48 ~14 ~11 ~48 ~15 ~11 minecraft:gray_stained_glass
fill ~57 ~14 ~11 ~57 ~15 ~11 minecraft:light_gray_stained_glass
setblock ~52 ~1 ~6 minecraft:iron_door[half=lower,facing=north]
setblock ~52 ~2 ~6 minecraft:iron_door[half=upper,facing=north]
fill ~48 ~17 ~6 ~57 ~17 ~13 minecraft:stone_brick_slab
fill ~49 ~1 ~6 ~49 ~7 ~6 minecraft:brown_terracotta
fill ~53 ~1 ~6 ~53 ~7 ~6 minecraft:brown_terracotta
fill ~49 ~6 ~7 ~56 ~16 ~12 minecraft:smooth_sandstone
fill ~50 ~7 ~8 ~55 ~15 ~11 minecraft:air
setblock ~50 ~3 ~6 minecraft:red_carpet
setblock ~55 ~3 ~6 minecraft:red_carpet
# 027 community style=balcony_block context=collector_front facing=south
fill ~-7 ~-3 ~-90 ~4 ~-1 ~-76 minecraft:stone
fill ~-7 ~0 ~-90 ~4 ~8 ~-76 minecraft:smooth_sandstone
fill ~-6 ~1 ~-89 ~3 ~7 ~-77 minecraft:air
fill ~-6 ~4 ~-89 ~3 ~4 ~-77 minecraft:smooth_stone
fill ~-5 ~2 ~-90 ~-5 ~3 ~-90 minecraft:gray_stained_glass
fill ~-5 ~2 ~-76 ~-5 ~3 ~-76 minecraft:light_gray_stained_glass
fill ~-2 ~2 ~-90 ~-2 ~3 ~-90 minecraft:gray_stained_glass
fill ~-2 ~2 ~-76 ~-2 ~3 ~-76 minecraft:light_gray_stained_glass
fill ~1 ~2 ~-90 ~1 ~3 ~-90 minecraft:gray_stained_glass
fill ~1 ~2 ~-76 ~1 ~3 ~-76 minecraft:light_gray_stained_glass
fill ~-7 ~2 ~-88 ~-7 ~3 ~-88 minecraft:gray_stained_glass
fill ~4 ~2 ~-88 ~4 ~3 ~-88 minecraft:light_gray_stained_glass
fill ~-7 ~2 ~-85 ~-7 ~3 ~-85 minecraft:gray_stained_glass
fill ~4 ~2 ~-85 ~4 ~3 ~-85 minecraft:light_gray_stained_glass
fill ~-7 ~2 ~-82 ~-7 ~3 ~-82 minecraft:gray_stained_glass
fill ~4 ~2 ~-82 ~4 ~3 ~-82 minecraft:light_gray_stained_glass
fill ~-7 ~2 ~-79 ~-7 ~3 ~-79 minecraft:gray_stained_glass
fill ~4 ~2 ~-79 ~4 ~3 ~-79 minecraft:light_gray_stained_glass
fill ~-5 ~6 ~-90 ~-5 ~7 ~-90 minecraft:gray_stained_glass
fill ~-5 ~6 ~-76 ~-5 ~7 ~-76 minecraft:light_gray_stained_glass
fill ~-2 ~6 ~-90 ~-2 ~7 ~-90 minecraft:gray_stained_glass
fill ~-2 ~6 ~-76 ~-2 ~7 ~-76 minecraft:light_gray_stained_glass
fill ~1 ~6 ~-90 ~1 ~7 ~-90 minecraft:gray_stained_glass
fill ~1 ~6 ~-76 ~1 ~7 ~-76 minecraft:light_gray_stained_glass
fill ~-7 ~6 ~-88 ~-7 ~7 ~-88 minecraft:gray_stained_glass
fill ~4 ~6 ~-88 ~4 ~7 ~-88 minecraft:light_gray_stained_glass
fill ~-7 ~6 ~-85 ~-7 ~7 ~-85 minecraft:gray_stained_glass
fill ~4 ~6 ~-85 ~4 ~7 ~-85 minecraft:light_gray_stained_glass
fill ~-7 ~6 ~-82 ~-7 ~7 ~-82 minecraft:gray_stained_glass
fill ~4 ~6 ~-82 ~4 ~7 ~-82 minecraft:light_gray_stained_glass
fill ~-7 ~6 ~-79 ~-7 ~7 ~-79 minecraft:gray_stained_glass
fill ~4 ~6 ~-79 ~4 ~7 ~-79 minecraft:light_gray_stained_glass
setblock ~-2 ~1 ~-76 minecraft:iron_door[half=lower,facing=south]
setblock ~-2 ~2 ~-76 minecraft:iron_door[half=upper,facing=south]
fill ~-5 ~4 ~-75 ~2 ~4 ~-75 minecraft:smooth_stone_slab
fill ~-7 ~9 ~-90 ~4 ~9 ~-76 minecraft:stone_brick_slab
fill ~-5 ~10 ~-88 ~-3 ~11 ~-86 minecraft:light_gray_concrete
setblock ~-2 ~10 ~-87 minecraft:lightning_rod
fill ~-6 ~1 ~-76 ~-6 ~7 ~-76 minecraft:brown_terracotta
fill ~-2 ~1 ~-76 ~-2 ~7 ~-76 minecraft:brown_terracotta
fill ~2 ~1 ~-76 ~2 ~7 ~-76 minecraft:brown_terracotta
# 028 row_house style=rowhouse context=local_front facing=north
fill ~-120 ~-3 ~25 ~-111 ~-1 ~36 minecraft:stone
fill ~-120 ~0 ~25 ~-111 ~9 ~36 minecraft:mud_bricks
fill ~-119 ~1 ~26 ~-112 ~8 ~35 minecraft:air
fill ~-119 ~4 ~26 ~-112 ~4 ~35 minecraft:smooth_stone
fill ~-119 ~8 ~26 ~-112 ~8 ~35 minecraft:smooth_stone
fill ~-118 ~2 ~25 ~-118 ~3 ~25 minecraft:gray_stained_glass
fill ~-118 ~2 ~36 ~-118 ~3 ~36 minecraft:light_gray_stained_glass
fill ~-115 ~2 ~25 ~-115 ~3 ~25 minecraft:gray_stained_glass
fill ~-115 ~2 ~36 ~-115 ~3 ~36 minecraft:light_gray_stained_glass
fill ~-120 ~2 ~27 ~-120 ~3 ~27 minecraft:gray_stained_glass
fill ~-111 ~2 ~27 ~-111 ~3 ~27 minecraft:light_gray_stained_glass
fill ~-120 ~2 ~30 ~-120 ~3 ~30 minecraft:gray_stained_glass
fill ~-111 ~2 ~30 ~-111 ~3 ~30 minecraft:light_gray_stained_glass
fill ~-120 ~2 ~33 ~-120 ~3 ~33 minecraft:gray_stained_glass
fill ~-111 ~2 ~33 ~-111 ~3 ~33 minecraft:light_gray_stained_glass
fill ~-118 ~6 ~25 ~-118 ~7 ~25 minecraft:gray_stained_glass
fill ~-118 ~6 ~36 ~-118 ~7 ~36 minecraft:light_gray_stained_glass
fill ~-115 ~6 ~25 ~-115 ~7 ~25 minecraft:gray_stained_glass
fill ~-115 ~6 ~36 ~-115 ~7 ~36 minecraft:light_gray_stained_glass
fill ~-120 ~6 ~27 ~-120 ~7 ~27 minecraft:gray_stained_glass
fill ~-111 ~6 ~27 ~-111 ~7 ~27 minecraft:light_gray_stained_glass
fill ~-120 ~6 ~30 ~-120 ~7 ~30 minecraft:gray_stained_glass
fill ~-111 ~6 ~30 ~-111 ~7 ~30 minecraft:light_gray_stained_glass
fill ~-120 ~6 ~33 ~-120 ~7 ~33 minecraft:gray_stained_glass
fill ~-111 ~6 ~33 ~-111 ~7 ~33 minecraft:light_gray_stained_glass
setblock ~-116 ~1 ~25 minecraft:iron_door[half=lower,facing=north]
setblock ~-116 ~2 ~25 minecraft:iron_door[half=upper,facing=north]
fill ~-120 ~10 ~25 ~-111 ~10 ~36 minecraft:deepslate_tile_slab
fill ~-119 ~11 ~26 ~-112 ~11 ~35 minecraft:deepslate_tile_slab
setblock ~-116 ~3 ~24 minecraft:dark_oak_slab[type=top]
fill ~-113 ~7 ~34 ~-111 ~11 ~36 minecraft:air
setblock ~-113 ~7 ~34 minecraft:cobweb
fill ~-119 ~1 ~25 ~-119 ~7 ~25 minecraft:spruce_planks
fill ~-115 ~1 ~25 ~-115 ~7 ~25 minecraft:spruce_planks
# 029 mixed_use style=balcony_block context=arterial_front facing=north
fill ~-11 ~-3 ~6 ~4 ~-1 ~14 minecraft:stone
fill ~-11 ~0 ~6 ~4 ~24 ~14 minecraft:light_gray_concrete
fill ~-10 ~1 ~7 ~3 ~23 ~13 minecraft:air
fill ~-10 ~4 ~7 ~3 ~4 ~13 minecraft:smooth_stone
fill ~-10 ~8 ~7 ~3 ~8 ~13 minecraft:smooth_stone
fill ~-10 ~12 ~7 ~3 ~12 ~13 minecraft:smooth_stone
fill ~-10 ~16 ~7 ~3 ~16 ~13 minecraft:smooth_stone
fill ~-10 ~20 ~7 ~3 ~20 ~13 minecraft:smooth_stone
fill ~-9 ~2 ~6 ~-9 ~3 ~6 minecraft:gray_stained_glass
fill ~-9 ~2 ~14 ~-9 ~3 ~14 minecraft:light_gray_stained_glass
fill ~-6 ~2 ~6 ~-6 ~3 ~6 minecraft:gray_stained_glass
fill ~-6 ~2 ~14 ~-6 ~3 ~14 minecraft:light_gray_stained_glass
fill ~-3 ~2 ~6 ~-3 ~3 ~6 minecraft:gray_stained_glass
fill ~-3 ~2 ~14 ~-3 ~3 ~14 minecraft:light_gray_stained_glass
fill ~0 ~2 ~6 ~0 ~3 ~6 minecraft:gray_stained_glass
fill ~0 ~2 ~14 ~0 ~3 ~14 minecraft:light_gray_stained_glass
fill ~-11 ~2 ~8 ~-11 ~3 ~8 minecraft:gray_stained_glass
fill ~4 ~2 ~8 ~4 ~3 ~8 minecraft:light_gray_stained_glass
fill ~-11 ~2 ~11 ~-11 ~3 ~11 minecraft:gray_stained_glass
fill ~4 ~2 ~11 ~4 ~3 ~11 minecraft:light_gray_stained_glass
fill ~-9 ~6 ~6 ~-9 ~7 ~6 minecraft:gray_stained_glass
fill ~-9 ~6 ~14 ~-9 ~7 ~14 minecraft:light_gray_stained_glass
fill ~-6 ~6 ~6 ~-6 ~7 ~6 minecraft:gray_stained_glass
fill ~-6 ~6 ~14 ~-6 ~7 ~14 minecraft:light_gray_stained_glass
fill ~-3 ~6 ~6 ~-3 ~7 ~6 minecraft:gray_stained_glass
fill ~-3 ~6 ~14 ~-3 ~7 ~14 minecraft:light_gray_stained_glass
fill ~0 ~6 ~6 ~0 ~7 ~6 minecraft:gray_stained_glass
fill ~0 ~6 ~14 ~0 ~7 ~14 minecraft:light_gray_stained_glass
fill ~-11 ~6 ~8 ~-11 ~7 ~8 minecraft:gray_stained_glass
fill ~4 ~6 ~8 ~4 ~7 ~8 minecraft:light_gray_stained_glass
fill ~-11 ~6 ~11 ~-11 ~7 ~11 minecraft:gray_stained_glass
fill ~4 ~6 ~11 ~4 ~7 ~11 minecraft:light_gray_stained_glass
fill ~-9 ~10 ~6 ~-9 ~11 ~6 minecraft:gray_stained_glass
fill ~-9 ~10 ~14 ~-9 ~11 ~14 minecraft:light_gray_stained_glass
fill ~-6 ~10 ~6 ~-6 ~11 ~6 minecraft:gray_stained_glass
fill ~-6 ~10 ~14 ~-6 ~11 ~14 minecraft:light_gray_stained_glass
fill ~-3 ~10 ~6 ~-3 ~11 ~6 minecraft:gray_stained_glass
fill ~-3 ~10 ~14 ~-3 ~11 ~14 minecraft:light_gray_stained_glass
fill ~0 ~10 ~6 ~0 ~11 ~6 minecraft:gray_stained_glass
fill ~0 ~10 ~14 ~0 ~11 ~14 minecraft:light_gray_stained_glass
fill ~-11 ~10 ~8 ~-11 ~11 ~8 minecraft:gray_stained_glass
fill ~4 ~10 ~8 ~4 ~11 ~8 minecraft:light_gray_stained_glass
fill ~-11 ~10 ~11 ~-11 ~11 ~11 minecraft:gray_stained_glass
fill ~4 ~10 ~11 ~4 ~11 ~11 minecraft:light_gray_stained_glass
fill ~-9 ~14 ~6 ~-9 ~15 ~6 minecraft:gray_stained_glass
fill ~-9 ~14 ~14 ~-9 ~15 ~14 minecraft:light_gray_stained_glass
fill ~-6 ~14 ~6 ~-6 ~15 ~6 minecraft:gray_stained_glass
fill ~-6 ~14 ~14 ~-6 ~15 ~14 minecraft:light_gray_stained_glass
fill ~-3 ~14 ~6 ~-3 ~15 ~6 minecraft:gray_stained_glass
fill ~-3 ~14 ~14 ~-3 ~15 ~14 minecraft:light_gray_stained_glass
fill ~0 ~14 ~6 ~0 ~15 ~6 minecraft:gray_stained_glass
fill ~0 ~14 ~14 ~0 ~15 ~14 minecraft:light_gray_stained_glass
fill ~-11 ~14 ~8 ~-11 ~15 ~8 minecraft:gray_stained_glass
fill ~4 ~14 ~8 ~4 ~15 ~8 minecraft:light_gray_stained_glass
fill ~-11 ~14 ~11 ~-11 ~15 ~11 minecraft:gray_stained_glass
fill ~4 ~14 ~11 ~4 ~15 ~11 minecraft:light_gray_stained_glass
fill ~-9 ~18 ~6 ~-9 ~19 ~6 minecraft:gray_stained_glass
fill ~-9 ~18 ~14 ~-9 ~19 ~14 minecraft:light_gray_stained_glass
fill ~-6 ~18 ~6 ~-6 ~19 ~6 minecraft:gray_stained_glass
fill ~-6 ~18 ~14 ~-6 ~19 ~14 minecraft:light_gray_stained_glass
fill ~-3 ~18 ~6 ~-3 ~19 ~6 minecraft:gray_stained_glass
fill ~-3 ~18 ~14 ~-3 ~19 ~14 minecraft:light_gray_stained_glass
fill ~0 ~18 ~6 ~0 ~19 ~6 minecraft:gray_stained_glass
fill ~0 ~18 ~14 ~0 ~19 ~14 minecraft:light_gray_stained_glass
fill ~-11 ~18 ~8 ~-11 ~19 ~8 minecraft:gray_stained_glass
fill ~4 ~18 ~8 ~4 ~19 ~8 minecraft:light_gray_stained_glass
fill ~-11 ~18 ~11 ~-11 ~19 ~11 minecraft:gray_stained_glass
fill ~4 ~18 ~11 ~4 ~19 ~11 minecraft:light_gray_stained_glass
fill ~-9 ~22 ~6 ~-9 ~23 ~6 minecraft:gray_stained_glass
fill ~-9 ~22 ~14 ~-9 ~23 ~14 minecraft:light_gray_stained_glass
fill ~-6 ~22 ~6 ~-6 ~23 ~6 minecraft:gray_stained_glass
fill ~-6 ~22 ~14 ~-6 ~23 ~14 minecraft:light_gray_stained_glass
fill ~-3 ~22 ~6 ~-3 ~23 ~6 minecraft:gray_stained_glass
fill ~-3 ~22 ~14 ~-3 ~23 ~14 minecraft:light_gray_stained_glass
fill ~0 ~22 ~6 ~0 ~23 ~6 minecraft:gray_stained_glass
fill ~0 ~22 ~14 ~0 ~23 ~14 minecraft:light_gray_stained_glass
fill ~-11 ~22 ~8 ~-11 ~23 ~8 minecraft:gray_stained_glass
fill ~4 ~22 ~8 ~4 ~23 ~8 minecraft:light_gray_stained_glass
fill ~-11 ~22 ~11 ~-11 ~23 ~11 minecraft:gray_stained_glass
fill ~4 ~22 ~11 ~4 ~23 ~11 minecraft:light_gray_stained_glass
setblock ~-6 ~1 ~6 minecraft:iron_door[half=lower,facing=north]
setblock ~-6 ~2 ~6 minecraft:iron_door[half=upper,facing=north]
fill ~-9 ~4 ~5 ~2 ~4 ~5 minecraft:smooth_stone_slab
fill ~-9 ~8 ~5 ~2 ~8 ~5 minecraft:smooth_stone_slab
fill ~-9 ~12 ~5 ~2 ~12 ~5 minecraft:smooth_stone_slab
fill ~-9 ~16 ~5 ~2 ~16 ~5 minecraft:smooth_stone_slab
fill ~-9 ~20 ~5 ~2 ~20 ~5 minecraft:smooth_stone_slab
fill ~-11 ~25 ~6 ~4 ~25 ~14 minecraft:smooth_stone_slab
fill ~-10 ~1 ~6 ~-10 ~7 ~6 doomsday_decoration:cementwall
fill ~-6 ~1 ~6 ~-6 ~7 ~6 doomsday_decoration:cementwall
fill ~-2 ~1 ~6 ~-2 ~7 ~6 doomsday_decoration:cementwall
fill ~2 ~1 ~6 ~2 ~7 ~6 doomsday_decoration:cementwall
fill ~-10 ~6 ~7 ~3 ~24 ~13 minecraft:light_gray_concrete
fill ~-9 ~7 ~8 ~2 ~23 ~12 minecraft:air
setblock ~-9 ~3 ~6 minecraft:red_carpet
setblock ~-4 ~3 ~6 minecraft:red_carpet
setblock ~1 ~3 ~6 minecraft:red_carpet
# 030 row_house style=rowhouse context=local_front facing=north
fill ~91 ~-3 ~99 ~96 ~-1 ~110 minecraft:stone
fill ~91 ~0 ~99 ~96 ~7 ~110 minecraft:white_concrete
fill ~92 ~1 ~100 ~95 ~6 ~109 minecraft:air
fill ~92 ~4 ~100 ~95 ~4 ~109 minecraft:smooth_stone
fill ~93 ~2 ~99 ~93 ~3 ~99 minecraft:gray_stained_glass
fill ~93 ~2 ~110 ~93 ~3 ~110 minecraft:light_gray_stained_glass
fill ~91 ~2 ~101 ~91 ~3 ~101 minecraft:gray_stained_glass
fill ~96 ~2 ~101 ~96 ~3 ~101 minecraft:light_gray_stained_glass
fill ~91 ~2 ~104 ~91 ~3 ~104 minecraft:gray_stained_glass
fill ~96 ~2 ~104 ~96 ~3 ~104 minecraft:light_gray_stained_glass
fill ~91 ~2 ~107 ~91 ~3 ~107 minecraft:gray_stained_glass
fill ~96 ~2 ~107 ~96 ~3 ~107 minecraft:light_gray_stained_glass
setblock ~93 ~1 ~99 minecraft:iron_door[half=lower,facing=north]
setblock ~93 ~2 ~99 minecraft:iron_door[half=upper,facing=north]
fill ~91 ~8 ~99 ~96 ~8 ~110 minecraft:smooth_stone_slab
fill ~92 ~9 ~100 ~95 ~9 ~109 minecraft:smooth_stone_slab
setblock ~93 ~3 ~98 minecraft:dark_oak_slab[type=top]
fill ~92 ~1 ~99 ~92 ~7 ~99 minecraft:cyan_terracotta
# 031 workshop style=sawtooth context=local_front facing=east
fill ~-80 ~-3 ~84 ~-72 ~-1 ~93 minecraft:stone
fill ~-80 ~0 ~84 ~-72 ~7 ~93 minecraft:white_terracotta
fill ~-79 ~1 ~85 ~-73 ~6 ~92 minecraft:air
fill ~-79 ~4 ~85 ~-73 ~4 ~92 minecraft:smooth_stone
fill ~-78 ~2 ~84 ~-78 ~3 ~84 minecraft:gray_stained_glass
fill ~-78 ~2 ~93 ~-78 ~3 ~93 minecraft:light_gray_stained_glass
fill ~-75 ~2 ~84 ~-75 ~3 ~84 minecraft:gray_stained_glass
fill ~-75 ~2 ~93 ~-75 ~3 ~93 minecraft:light_gray_stained_glass
fill ~-80 ~2 ~86 ~-80 ~3 ~86 minecraft:gray_stained_glass
fill ~-72 ~2 ~86 ~-72 ~3 ~86 minecraft:light_gray_stained_glass
fill ~-80 ~2 ~89 ~-80 ~3 ~89 minecraft:gray_stained_glass
fill ~-72 ~2 ~89 ~-72 ~3 ~89 minecraft:light_gray_stained_glass
setblock ~-72 ~1 ~88 minecraft:iron_door[half=lower,facing=east]
setblock ~-72 ~2 ~88 minecraft:iron_door[half=upper,facing=east]
fill ~-72 ~1 ~86 ~-72 ~4 ~91 minecraft:polished_blackstone
fill ~-72 ~5 ~86 ~-72 ~5 ~91 minecraft:light_blue_stained_glass
fill ~-78 ~9 ~86 ~-76 ~10 ~88 minecraft:iron_block
fill ~-80 ~8 ~84 ~-72 ~8 ~93 minecraft:dark_oak_slab
fill ~-72 ~1 ~85 ~-72 ~7 ~85 minecraft:dark_oak_planks
fill ~-72 ~1 ~89 ~-72 ~7 ~89 minecraft:dark_oak_planks
# 032 community style=setback_block context=collector_front facing=west
fill ~91 ~-3 ~-32 ~103 ~-1 ~-27 minecraft:stone
fill ~91 ~0 ~-32 ~103 ~9 ~-27 minecraft:white_terracotta
fill ~92 ~1 ~-31 ~102 ~8 ~-28 minecraft:air
fill ~92 ~4 ~-31 ~102 ~4 ~-28 minecraft:smooth_stone
fill ~92 ~8 ~-31 ~102 ~8 ~-28 minecraft:smooth_stone
fill ~93 ~2 ~-32 ~93 ~3 ~-32 minecraft:gray_stained_glass
fill ~93 ~2 ~-27 ~93 ~3 ~-27 minecraft:light_gray_stained_glass
fill ~96 ~2 ~-32 ~96 ~3 ~-32 minecraft:gray_stained_glass
fill ~96 ~2 ~-27 ~96 ~3 ~-27 minecraft:light_gray_stained_glass
fill ~99 ~2 ~-32 ~99 ~3 ~-32 minecraft:gray_stained_glass
fill ~99 ~2 ~-27 ~99 ~3 ~-27 minecraft:light_gray_stained_glass
fill ~91 ~2 ~-30 ~91 ~3 ~-30 minecraft:gray_stained_glass
fill ~103 ~2 ~-30 ~103 ~3 ~-30 minecraft:light_gray_stained_glass
fill ~93 ~6 ~-32 ~93 ~7 ~-32 minecraft:gray_stained_glass
fill ~93 ~6 ~-27 ~93 ~7 ~-27 minecraft:light_gray_stained_glass
fill ~96 ~6 ~-32 ~96 ~7 ~-32 minecraft:gray_stained_glass
fill ~96 ~6 ~-27 ~96 ~7 ~-27 minecraft:light_gray_stained_glass
fill ~99 ~6 ~-32 ~99 ~7 ~-32 minecraft:gray_stained_glass
fill ~99 ~6 ~-27 ~99 ~7 ~-27 minecraft:light_gray_stained_glass
fill ~91 ~6 ~-30 ~91 ~7 ~-30 minecraft:gray_stained_glass
fill ~103 ~6 ~-30 ~103 ~7 ~-30 minecraft:light_gray_stained_glass
setblock ~91 ~1 ~-30 minecraft:iron_door[half=lower,facing=west]
setblock ~91 ~2 ~-30 minecraft:iron_door[half=upper,facing=west]
fill ~91 ~1 ~-31 ~91 ~7 ~-31 minecraft:dark_oak_planks
