# Buildings 241..248
# 241 shop_house style=arcade_shop context=collector_front facing=north
fill ~75 ~-3 ~-64 ~79 ~-1 ~-58 minecraft:stone
fill ~75 ~0 ~-64 ~79 ~5 ~-58 minecraft:calcite
fill ~76 ~1 ~-63 ~78 ~4 ~-59 minecraft:air
fill ~76 ~4 ~-63 ~78 ~4 ~-59 minecraft:smooth_stone
fill ~77 ~2 ~-64 ~77 ~3 ~-64 minecraft:gray_stained_glass
fill ~77 ~2 ~-58 ~77 ~3 ~-58 minecraft:light_gray_stained_glass
fill ~75 ~2 ~-62 ~75 ~3 ~-62 minecraft:gray_stained_glass
fill ~79 ~2 ~-62 ~79 ~3 ~-62 minecraft:light_gray_stained_glass
setblock ~77 ~1 ~-64 minecraft:iron_door[half=lower,facing=north]
setblock ~77 ~2 ~-64 minecraft:iron_door[half=upper,facing=north]
fill ~76 ~1 ~-64 ~78 ~3 ~-64 minecraft:cyan_stained_glass
setblock ~77 ~1 ~-64 minecraft:iron_door[half=lower,facing=north]
setblock ~77 ~2 ~-64 minecraft:iron_door[half=upper,facing=north]
setblock ~77 ~3 ~-65 minecraft:red_wool
fill ~76 ~4 ~-64 ~78 ~4 ~-64 minecraft:gray_concrete
fill ~75 ~6 ~-64 ~79 ~6 ~-58 minecraft:stone_brick_slab
# 242 small_office style=civic_modern context=collector_front facing=west
fill ~40 ~-3 ~-24 ~46 ~-1 ~-20 minecraft:stone
fill ~40 ~0 ~-24 ~46 ~11 ~-20 minecraft:light_gray_concrete
fill ~41 ~1 ~-23 ~45 ~10 ~-21 minecraft:air
fill ~41 ~4 ~-23 ~45 ~4 ~-21 minecraft:smooth_stone
fill ~41 ~8 ~-23 ~45 ~8 ~-21 minecraft:smooth_stone
fill ~42 ~2 ~-24 ~42 ~3 ~-24 minecraft:gray_stained_glass
fill ~42 ~2 ~-20 ~42 ~3 ~-20 minecraft:light_gray_stained_glass
fill ~40 ~2 ~-22 ~40 ~3 ~-22 minecraft:gray_stained_glass
fill ~46 ~2 ~-22 ~46 ~3 ~-22 minecraft:light_gray_stained_glass
fill ~42 ~6 ~-24 ~42 ~7 ~-24 minecraft:gray_stained_glass
fill ~42 ~6 ~-20 ~42 ~7 ~-20 minecraft:light_gray_stained_glass
fill ~40 ~6 ~-22 ~40 ~7 ~-22 minecraft:gray_stained_glass
fill ~46 ~6 ~-22 ~46 ~7 ~-22 minecraft:light_gray_stained_glass
setblock ~40 ~1 ~-22 minecraft:iron_door[half=lower,facing=west]
setblock ~40 ~2 ~-22 minecraft:iron_door[half=upper,facing=west]
fill ~40 ~7 ~-24 ~46 ~11 ~-20 minecraft:air
fill ~41 ~7 ~-23 ~45 ~11 ~-21 minecraft:light_gray_concrete
fill ~42 ~8 ~-22 ~44 ~10 ~-22 minecraft:air
fill ~41 ~12 ~-23 ~45 ~12 ~-21 minecraft:smooth_stone_slab
# 243 shop_house style=arcade_shop context=collector_front facing=west
fill ~52 ~-3 ~107 ~58 ~-1 ~111 minecraft:stone
fill ~52 ~0 ~107 ~58 ~7 ~111 minecraft:stone_bricks
fill ~53 ~1 ~108 ~57 ~6 ~110 minecraft:air
fill ~53 ~4 ~108 ~57 ~4 ~110 minecraft:smooth_stone
fill ~54 ~2 ~107 ~54 ~3 ~107 minecraft:gray_stained_glass
fill ~54 ~2 ~111 ~54 ~3 ~111 minecraft:light_gray_stained_glass
fill ~52 ~2 ~109 ~52 ~3 ~109 minecraft:gray_stained_glass
fill ~58 ~2 ~109 ~58 ~3 ~109 minecraft:light_gray_stained_glass
setblock ~52 ~1 ~109 minecraft:iron_door[half=lower,facing=west]
setblock ~52 ~2 ~109 minecraft:iron_door[half=upper,facing=west]
fill ~52 ~1 ~108 ~52 ~3 ~110 minecraft:cyan_stained_glass
setblock ~52 ~1 ~109 minecraft:iron_door[half=lower,facing=west]
setblock ~52 ~2 ~109 minecraft:iron_door[half=upper,facing=west]
setblock ~51 ~3 ~109 minecraft:red_wool
fill ~52 ~4 ~108 ~52 ~4 ~110 minecraft:orange_terracotta
fill ~52 ~8 ~107 ~58 ~8 ~111 minecraft:stone_brick_slab
# 244 workshop style=industrial_shed context=local_front facing=north
fill ~11 ~-3 ~-38 ~16 ~-1 ~-31 minecraft:stone
fill ~11 ~0 ~-38 ~16 ~5 ~-31 minecraft:white_terracotta
fill ~12 ~1 ~-37 ~15 ~4 ~-32 minecraft:air
fill ~12 ~4 ~-37 ~15 ~4 ~-32 minecraft:smooth_stone
fill ~13 ~2 ~-38 ~13 ~3 ~-38 minecraft:gray_stained_glass
fill ~13 ~2 ~-31 ~13 ~3 ~-31 minecraft:light_gray_stained_glass
fill ~11 ~2 ~-36 ~11 ~3 ~-36 minecraft:gray_stained_glass
fill ~16 ~2 ~-36 ~16 ~3 ~-36 minecraft:light_gray_stained_glass
fill ~11 ~2 ~-33 ~11 ~3 ~-33 minecraft:gray_stained_glass
fill ~16 ~2 ~-33 ~16 ~3 ~-33 minecraft:light_gray_stained_glass
setblock ~13 ~1 ~-38 minecraft:iron_door[half=lower,facing=north]
setblock ~13 ~2 ~-38 minecraft:iron_door[half=upper,facing=north]
fill ~13 ~1 ~-38 ~14 ~4 ~-38 minecraft:polished_blackstone
fill ~13 ~4 ~-38 ~14 ~4 ~-38 minecraft:light_blue_stained_glass
fill ~13 ~7 ~-36 ~15 ~8 ~-34 minecraft:iron_block
fill ~11 ~6 ~-38 ~16 ~6 ~-31 minecraft:stone_brick_slab
fill ~12 ~1 ~-38 ~12 ~5 ~-38 minecraft:gray_concrete
# 245 local_shop style=arcade_shop context=local_front facing=north
fill ~65 ~-3 ~-32 ~68 ~-1 ~-27 minecraft:stone
fill ~65 ~0 ~-32 ~68 ~11 ~-27 minecraft:light_gray_concrete
fill ~66 ~1 ~-31 ~67 ~10 ~-28 minecraft:air
fill ~66 ~4 ~-31 ~67 ~4 ~-28 minecraft:smooth_stone
fill ~66 ~8 ~-31 ~67 ~8 ~-28 minecraft:smooth_stone
fill ~65 ~2 ~-30 ~65 ~3 ~-30 minecraft:gray_stained_glass
fill ~68 ~2 ~-30 ~68 ~3 ~-30 minecraft:light_gray_stained_glass
fill ~65 ~6 ~-30 ~65 ~7 ~-30 minecraft:gray_stained_glass
fill ~68 ~6 ~-30 ~68 ~7 ~-30 minecraft:light_gray_stained_glass
setblock ~67 ~1 ~-32 minecraft:iron_door[half=lower,facing=north]
setblock ~67 ~2 ~-32 minecraft:iron_door[half=upper,facing=north]
fill ~66 ~1 ~-32 ~67 ~3 ~-32 minecraft:cyan_stained_glass
setblock ~67 ~1 ~-32 minecraft:iron_door[half=lower,facing=north]
setblock ~67 ~2 ~-32 minecraft:iron_door[half=upper,facing=north]
setblock ~67 ~3 ~-33 minecraft:red_wool
fill ~66 ~4 ~-32 ~67 ~4 ~-32 doomsday_decoration:porcelainbrickwall
fill ~65 ~12 ~-32 ~68 ~12 ~-27 minecraft:smooth_stone_slab
# 246 small_office style=civic_modern context=collector_front facing=east
fill ~12 ~-3 ~-117 ~17 ~-1 ~-114 minecraft:stone
fill ~12 ~0 ~-117 ~17 ~11 ~-114 minecraft:stone_bricks
fill ~13 ~1 ~-116 ~16 ~10 ~-115 minecraft:air
fill ~13 ~4 ~-116 ~16 ~4 ~-115 minecraft:smooth_stone
fill ~13 ~8 ~-116 ~16 ~8 ~-115 minecraft:smooth_stone
fill ~14 ~2 ~-117 ~14 ~3 ~-117 minecraft:gray_stained_glass
fill ~14 ~2 ~-114 ~14 ~3 ~-114 minecraft:light_gray_stained_glass
fill ~14 ~6 ~-117 ~14 ~7 ~-117 minecraft:gray_stained_glass
fill ~14 ~6 ~-114 ~14 ~7 ~-114 minecraft:light_gray_stained_glass
setblock ~17 ~1 ~-115 minecraft:iron_door[half=lower,facing=east]
setblock ~17 ~2 ~-115 minecraft:iron_door[half=upper,facing=east]
fill ~12 ~7 ~-117 ~17 ~11 ~-114 minecraft:air
fill ~13 ~7 ~-116 ~16 ~11 ~-115 minecraft:stone_bricks
fill ~14 ~8 ~-115 ~15 ~10 ~-116 minecraft:air
fill ~13 ~12 ~-116 ~16 ~12 ~-115 minecraft:smooth_stone_slab
fill ~14 ~13 ~-115 ~16 ~14 ~-115 minecraft:light_gray_concrete
setblock ~16 ~13 ~-115 minecraft:lightning_rod
# 247 shop_house style=storefront context=waterfront_front facing=north
fill ~115 ~-3 ~116 ~118 ~-1 ~121 minecraft:stone
fill ~115 ~0 ~116 ~118 ~11 ~121 minecraft:bricks
fill ~116 ~1 ~117 ~117 ~10 ~120 minecraft:air
fill ~116 ~4 ~117 ~117 ~4 ~120 minecraft:smooth_stone
fill ~116 ~8 ~117 ~117 ~8 ~120 minecraft:smooth_stone
fill ~115 ~2 ~118 ~115 ~3 ~118 minecraft:gray_stained_glass
fill ~118 ~2 ~118 ~118 ~3 ~118 minecraft:light_gray_stained_glass
fill ~115 ~6 ~118 ~115 ~7 ~118 minecraft:gray_stained_glass
fill ~118 ~6 ~118 ~118 ~7 ~118 minecraft:light_gray_stained_glass
setblock ~117 ~1 ~116 minecraft:iron_door[half=lower,facing=north]
setblock ~117 ~2 ~116 minecraft:iron_door[half=upper,facing=north]
fill ~116 ~1 ~116 ~117 ~3 ~116 minecraft:cyan_stained_glass
setblock ~117 ~1 ~116 minecraft:iron_door[half=lower,facing=north]
setblock ~117 ~2 ~116 minecraft:iron_door[half=upper,facing=north]
setblock ~117 ~3 ~115 minecraft:red_wool
fill ~115 ~12 ~116 ~118 ~12 ~121 minecraft:deepslate_tile_slab
# 248 workshop style=industrial_shed context=waterfront_front facing=south
fill ~114 ~-3 ~60 ~117 ~-1 ~65 minecraft:stone
fill ~114 ~0 ~60 ~117 ~9 ~65 minecraft:white_concrete
fill ~115 ~1 ~61 ~116 ~8 ~64 minecraft:air
fill ~115 ~4 ~61 ~116 ~4 ~64 minecraft:smooth_stone
fill ~115 ~8 ~61 ~116 ~8 ~64 minecraft:smooth_stone
fill ~114 ~2 ~62 ~114 ~3 ~62 minecraft:gray_stained_glass
fill ~117 ~2 ~62 ~117 ~3 ~62 minecraft:light_gray_stained_glass
fill ~114 ~6 ~62 ~114 ~7 ~62 minecraft:gray_stained_glass
fill ~117 ~6 ~62 ~117 ~7 ~62 minecraft:light_gray_stained_glass
setblock ~116 ~1 ~65 minecraft:iron_door[half=lower,facing=south]
setblock ~116 ~2 ~65 minecraft:iron_door[half=upper,facing=south]
fill ~116 ~1 ~65 ~115 ~4 ~65 minecraft:polished_blackstone
fill ~116 ~5 ~65 ~115 ~5 ~65 minecraft:light_blue_stained_glass
fill ~116 ~11 ~62 ~116 ~12 ~64 minecraft:iron_block
fill ~114 ~10 ~60 ~117 ~10 ~65 minecraft:smooth_stone_slab
