# Buildings 41..48
# 041 factory style=industrial_shed context=waterfront_front facing=west
fill ~89 ~-3 ~85 ~98 ~-1 ~96 minecraft:stone
fill ~89 ~0 ~85 ~98 ~6 ~96 minecraft:stone_bricks
fill ~90 ~1 ~86 ~97 ~5 ~95 minecraft:air
fill ~90 ~4 ~86 ~97 ~4 ~95 minecraft:smooth_stone
fill ~91 ~2 ~85 ~91 ~3 ~85 minecraft:gray_stained_glass
fill ~91 ~2 ~96 ~91 ~3 ~96 minecraft:light_gray_stained_glass
fill ~94 ~2 ~85 ~94 ~3 ~85 minecraft:gray_stained_glass
fill ~94 ~2 ~96 ~94 ~3 ~96 minecraft:light_gray_stained_glass
fill ~89 ~2 ~87 ~89 ~3 ~87 minecraft:gray_stained_glass
fill ~98 ~2 ~87 ~98 ~3 ~87 minecraft:light_gray_stained_glass
fill ~89 ~2 ~90 ~89 ~3 ~90 minecraft:gray_stained_glass
fill ~98 ~2 ~90 ~98 ~3 ~90 minecraft:light_gray_stained_glass
fill ~89 ~2 ~93 ~89 ~3 ~93 minecraft:gray_stained_glass
fill ~98 ~2 ~93 ~98 ~3 ~93 minecraft:light_gray_stained_glass
setblock ~89 ~1 ~90 minecraft:iron_door[half=lower,facing=west]
setblock ~89 ~2 ~90 minecraft:iron_door[half=upper,facing=west]
fill ~89 ~1 ~87 ~89 ~4 ~94 minecraft:polished_blackstone
fill ~89 ~5 ~87 ~89 ~5 ~94 minecraft:light_blue_stained_glass
fill ~91 ~8 ~87 ~93 ~9 ~89 minecraft:iron_block
fill ~89 ~7 ~85 ~98 ~7 ~96 minecraft:stone_brick_slab
# 042 workshop style=sawtooth context=back_block facing=west
fill ~-75 ~-3 ~84 ~-70 ~-1 ~94 minecraft:stone
fill ~-75 ~0 ~84 ~-70 ~7 ~94 minecraft:calcite
fill ~-74 ~1 ~85 ~-71 ~6 ~93 minecraft:air
fill ~-74 ~4 ~85 ~-71 ~4 ~93 minecraft:smooth_stone
fill ~-73 ~2 ~84 ~-73 ~3 ~84 minecraft:gray_stained_glass
fill ~-73 ~2 ~94 ~-73 ~3 ~94 minecraft:light_gray_stained_glass
fill ~-75 ~2 ~86 ~-75 ~3 ~86 minecraft:gray_stained_glass
fill ~-70 ~2 ~86 ~-70 ~3 ~86 minecraft:light_gray_stained_glass
fill ~-75 ~2 ~89 ~-75 ~3 ~89 minecraft:gray_stained_glass
fill ~-70 ~2 ~89 ~-70 ~3 ~89 minecraft:light_gray_stained_glass
fill ~-75 ~2 ~92 ~-75 ~3 ~92 minecraft:gray_stained_glass
fill ~-70 ~2 ~92 ~-70 ~3 ~92 minecraft:light_gray_stained_glass
setblock ~-75 ~1 ~89 minecraft:iron_door[half=lower,facing=west]
setblock ~-75 ~2 ~89 minecraft:iron_door[half=upper,facing=west]
fill ~-75 ~1 ~86 ~-75 ~4 ~92 minecraft:polished_blackstone
fill ~-75 ~5 ~86 ~-75 ~5 ~92 minecraft:light_blue_stained_glass
fill ~-73 ~9 ~86 ~-71 ~10 ~88 minecraft:iron_block
fill ~-75 ~8 ~84 ~-70 ~8 ~94 minecraft:stone_brick_slab
# 043 detached_house style=japanese_house context=back_block facing=north
fill ~-64 ~-3 ~88 ~-53 ~-1 ~95 minecraft:stone
fill ~-64 ~0 ~88 ~-53 ~5 ~95 minecraft:mud_bricks
fill ~-63 ~1 ~89 ~-54 ~4 ~94 minecraft:air
fill ~-63 ~4 ~89 ~-54 ~4 ~94 minecraft:smooth_stone
fill ~-62 ~2 ~88 ~-62 ~3 ~88 minecraft:gray_stained_glass
fill ~-62 ~2 ~95 ~-62 ~3 ~95 minecraft:light_gray_stained_glass
fill ~-59 ~2 ~88 ~-59 ~3 ~88 minecraft:gray_stained_glass
fill ~-59 ~2 ~95 ~-59 ~3 ~95 minecraft:light_gray_stained_glass
fill ~-56 ~2 ~88 ~-56 ~3 ~88 minecraft:gray_stained_glass
fill ~-56 ~2 ~95 ~-56 ~3 ~95 minecraft:light_gray_stained_glass
fill ~-64 ~2 ~90 ~-64 ~3 ~90 minecraft:gray_stained_glass
fill ~-53 ~2 ~90 ~-53 ~3 ~90 minecraft:light_gray_stained_glass
fill ~-64 ~2 ~93 ~-64 ~3 ~93 minecraft:gray_stained_glass
fill ~-53 ~2 ~93 ~-53 ~3 ~93 minecraft:light_gray_stained_glass
setblock ~-59 ~1 ~88 minecraft:iron_door[half=lower,facing=north]
setblock ~-59 ~2 ~88 minecraft:iron_door[half=upper,facing=north]
fill ~-64 ~6 ~88 ~-53 ~6 ~95 minecraft:deepslate_tile_slab
fill ~-63 ~7 ~89 ~-54 ~7 ~94 minecraft:deepslate_tile_slab
setblock ~-59 ~3 ~87 minecraft:dark_oak_slab[type=top]
# 044 supermarket style=corner_store context=collector_front facing=north
fill ~-10 ~-3 ~-57 ~1 ~-1 ~-50 minecraft:stone
fill ~-10 ~0 ~-57 ~1 ~12 ~-50 minecraft:light_gray_concrete
fill ~-9 ~1 ~-56 ~0 ~11 ~-51 minecraft:air
fill ~-9 ~4 ~-56 ~0 ~4 ~-51 minecraft:smooth_stone
fill ~-9 ~8 ~-56 ~0 ~8 ~-51 minecraft:smooth_stone
fill ~-8 ~2 ~-57 ~-8 ~3 ~-57 minecraft:gray_stained_glass
fill ~-8 ~2 ~-50 ~-8 ~3 ~-50 minecraft:light_gray_stained_glass
fill ~-5 ~2 ~-57 ~-5 ~3 ~-57 minecraft:gray_stained_glass
fill ~-5 ~2 ~-50 ~-5 ~3 ~-50 minecraft:light_gray_stained_glass
fill ~-2 ~2 ~-57 ~-2 ~3 ~-57 minecraft:gray_stained_glass
fill ~-2 ~2 ~-50 ~-2 ~3 ~-50 minecraft:light_gray_stained_glass
fill ~-10 ~2 ~-55 ~-10 ~3 ~-55 minecraft:gray_stained_glass
fill ~1 ~2 ~-55 ~1 ~3 ~-55 minecraft:light_gray_stained_glass
fill ~-10 ~2 ~-52 ~-10 ~3 ~-52 minecraft:gray_stained_glass
fill ~1 ~2 ~-52 ~1 ~3 ~-52 minecraft:light_gray_stained_glass
fill ~-8 ~6 ~-57 ~-8 ~7 ~-57 minecraft:gray_stained_glass
fill ~-8 ~6 ~-50 ~-8 ~7 ~-50 minecraft:light_gray_stained_glass
fill ~-5 ~6 ~-57 ~-5 ~7 ~-57 minecraft:gray_stained_glass
fill ~-5 ~6 ~-50 ~-5 ~7 ~-50 minecraft:light_gray_stained_glass
fill ~-2 ~6 ~-57 ~-2 ~7 ~-57 minecraft:gray_stained_glass
fill ~-2 ~6 ~-50 ~-2 ~7 ~-50 minecraft:light_gray_stained_glass
fill ~-10 ~6 ~-55 ~-10 ~7 ~-55 minecraft:gray_stained_glass
fill ~1 ~6 ~-55 ~1 ~7 ~-55 minecraft:light_gray_stained_glass
fill ~-10 ~6 ~-52 ~-10 ~7 ~-52 minecraft:gray_stained_glass
fill ~1 ~6 ~-52 ~1 ~7 ~-52 minecraft:light_gray_stained_glass
fill ~-8 ~10 ~-57 ~-8 ~11 ~-57 minecraft:gray_stained_glass
fill ~-8 ~10 ~-50 ~-8 ~11 ~-50 minecraft:light_gray_stained_glass
fill ~-5 ~10 ~-57 ~-5 ~11 ~-57 minecraft:gray_stained_glass
fill ~-5 ~10 ~-50 ~-5 ~11 ~-50 minecraft:light_gray_stained_glass
fill ~-2 ~10 ~-57 ~-2 ~11 ~-57 minecraft:gray_stained_glass
fill ~-2 ~10 ~-50 ~-2 ~11 ~-50 minecraft:light_gray_stained_glass
fill ~-10 ~10 ~-55 ~-10 ~11 ~-55 minecraft:gray_stained_glass
fill ~1 ~10 ~-55 ~1 ~11 ~-55 minecraft:light_gray_stained_glass
fill ~-10 ~10 ~-52 ~-10 ~11 ~-52 minecraft:gray_stained_glass
fill ~1 ~10 ~-52 ~1 ~11 ~-52 minecraft:light_gray_stained_glass
setblock ~-5 ~1 ~-57 minecraft:iron_door[half=lower,facing=north]
setblock ~-5 ~2 ~-57 minecraft:iron_door[half=upper,facing=north]
fill ~-9 ~1 ~-57 ~0 ~3 ~-57 minecraft:cyan_stained_glass
setblock ~-5 ~1 ~-57 minecraft:iron_door[half=lower,facing=north]
setblock ~-5 ~2 ~-57 minecraft:iron_door[half=upper,facing=north]
setblock ~-5 ~3 ~-58 minecraft:red_wool
fill ~-10 ~13 ~-57 ~1 ~13 ~-50 minecraft:smooth_stone_slab
# 045 office style=setback_tower context=arterial_front facing=south
fill ~14 ~-3 ~12 ~23 ~-1 ~20 minecraft:stone
fill ~14 ~0 ~12 ~23 ~12 ~20 minecraft:light_gray_concrete
fill ~15 ~1 ~13 ~22 ~11 ~19 minecraft:air
fill ~15 ~4 ~13 ~22 ~4 ~19 minecraft:smooth_stone
fill ~15 ~8 ~13 ~22 ~8 ~19 minecraft:smooth_stone
fill ~16 ~2 ~12 ~16 ~3 ~12 minecraft:gray_stained_glass
fill ~16 ~2 ~20 ~16 ~3 ~20 minecraft:light_gray_stained_glass
fill ~19 ~2 ~12 ~19 ~3 ~12 minecraft:gray_stained_glass
fill ~19 ~2 ~20 ~19 ~3 ~20 minecraft:light_gray_stained_glass
fill ~14 ~2 ~14 ~14 ~3 ~14 minecraft:gray_stained_glass
fill ~23 ~2 ~14 ~23 ~3 ~14 minecraft:light_gray_stained_glass
fill ~14 ~2 ~17 ~14 ~3 ~17 minecraft:gray_stained_glass
fill ~23 ~2 ~17 ~23 ~3 ~17 minecraft:light_gray_stained_glass
fill ~16 ~6 ~12 ~16 ~7 ~12 minecraft:gray_stained_glass
fill ~16 ~6 ~20 ~16 ~7 ~20 minecraft:light_gray_stained_glass
fill ~19 ~6 ~12 ~19 ~7 ~12 minecraft:gray_stained_glass
fill ~19 ~6 ~20 ~19 ~7 ~20 minecraft:light_gray_stained_glass
fill ~14 ~6 ~14 ~14 ~7 ~14 minecraft:gray_stained_glass
fill ~23 ~6 ~14 ~23 ~7 ~14 minecraft:light_gray_stained_glass
fill ~14 ~6 ~17 ~14 ~7 ~17 minecraft:gray_stained_glass
fill ~23 ~6 ~17 ~23 ~7 ~17 minecraft:light_gray_stained_glass
fill ~16 ~10 ~12 ~16 ~11 ~12 minecraft:gray_stained_glass
fill ~16 ~10 ~20 ~16 ~11 ~20 minecraft:light_gray_stained_glass
fill ~19 ~10 ~12 ~19 ~11 ~12 minecraft:gray_stained_glass
fill ~19 ~10 ~20 ~19 ~11 ~20 minecraft:light_gray_stained_glass
fill ~14 ~10 ~14 ~14 ~11 ~14 minecraft:gray_stained_glass
fill ~23 ~10 ~14 ~23 ~11 ~14 minecraft:light_gray_stained_glass
fill ~14 ~10 ~17 ~14 ~11 ~17 minecraft:gray_stained_glass
fill ~23 ~10 ~17 ~23 ~11 ~17 minecraft:light_gray_stained_glass
setblock ~18 ~1 ~20 minecraft:iron_door[half=lower,facing=south]
setblock ~18 ~2 ~20 minecraft:iron_door[half=upper,facing=south]
fill ~14 ~7 ~12 ~23 ~12 ~20 minecraft:air
fill ~15 ~7 ~13 ~22 ~12 ~19 minecraft:light_gray_concrete
fill ~16 ~8 ~14 ~21 ~11 ~18 minecraft:air
fill ~15 ~13 ~13 ~22 ~13 ~19 minecraft:smooth_stone_slab
fill ~16 ~14 ~14 ~18 ~15 ~16 minecraft:light_gray_concrete
setblock ~19 ~14 ~15 minecraft:lightning_rod
# 046 detached_house style=rowhouse context=local_front facing=north
fill ~-118 ~-3 ~55 ~-107 ~-1 ~66 minecraft:stone
fill ~-118 ~0 ~55 ~-107 ~9 ~66 minecraft:white_terracotta
fill ~-117 ~1 ~56 ~-108 ~8 ~65 minecraft:air
fill ~-117 ~4 ~56 ~-108 ~4 ~65 minecraft:smooth_stone
fill ~-117 ~8 ~56 ~-108 ~8 ~65 minecraft:smooth_stone
fill ~-116 ~2 ~55 ~-116 ~3 ~55 minecraft:gray_stained_glass
fill ~-116 ~2 ~66 ~-116 ~3 ~66 minecraft:light_gray_stained_glass
fill ~-113 ~2 ~55 ~-113 ~3 ~55 minecraft:gray_stained_glass
fill ~-113 ~2 ~66 ~-113 ~3 ~66 minecraft:light_gray_stained_glass
fill ~-110 ~2 ~55 ~-110 ~3 ~55 minecraft:gray_stained_glass
fill ~-110 ~2 ~66 ~-110 ~3 ~66 minecraft:light_gray_stained_glass
fill ~-118 ~2 ~57 ~-118 ~3 ~57 minecraft:gray_stained_glass
fill ~-107 ~2 ~57 ~-107 ~3 ~57 minecraft:light_gray_stained_glass
fill ~-118 ~2 ~60 ~-118 ~3 ~60 minecraft:gray_stained_glass
fill ~-107 ~2 ~60 ~-107 ~3 ~60 minecraft:light_gray_stained_glass
fill ~-118 ~2 ~63 ~-118 ~3 ~63 minecraft:gray_stained_glass
fill ~-107 ~2 ~63 ~-107 ~3 ~63 minecraft:light_gray_stained_glass
fill ~-116 ~6 ~55 ~-116 ~7 ~55 minecraft:gray_stained_glass
fill ~-116 ~6 ~66 ~-116 ~7 ~66 minecraft:light_gray_stained_glass
fill ~-113 ~6 ~55 ~-113 ~7 ~55 minecraft:gray_stained_glass
fill ~-113 ~6 ~66 ~-113 ~7 ~66 minecraft:light_gray_stained_glass
fill ~-110 ~6 ~55 ~-110 ~7 ~55 minecraft:gray_stained_glass
fill ~-110 ~6 ~66 ~-110 ~7 ~66 minecraft:light_gray_stained_glass
fill ~-118 ~6 ~57 ~-118 ~7 ~57 minecraft:gray_stained_glass
fill ~-107 ~6 ~57 ~-107 ~7 ~57 minecraft:light_gray_stained_glass
fill ~-118 ~6 ~60 ~-118 ~7 ~60 minecraft:gray_stained_glass
fill ~-107 ~6 ~60 ~-107 ~7 ~60 minecraft:light_gray_stained_glass
fill ~-118 ~6 ~63 ~-118 ~7 ~63 minecraft:gray_stained_glass
fill ~-107 ~6 ~63 ~-107 ~7 ~63 minecraft:light_gray_stained_glass
setblock ~-113 ~1 ~55 minecraft:iron_door[half=lower,facing=north]
setblock ~-113 ~2 ~55 minecraft:iron_door[half=upper,facing=north]
fill ~-118 ~10 ~55 ~-107 ~10 ~66 minecraft:dark_oak_slab
fill ~-117 ~11 ~56 ~-108 ~11 ~65 minecraft:dark_oak_slab
setblock ~-113 ~3 ~54 minecraft:dark_oak_slab[type=top]
# 047 medical_center style=bay_office context=arterial_front facing=north
fill ~-111 ~-3 ~-28 ~-100 ~-1 ~-21 minecraft:stone
fill ~-111 ~0 ~-28 ~-100 ~5 ~-21 minecraft:calcite
fill ~-110 ~1 ~-27 ~-101 ~4 ~-22 minecraft:air
fill ~-110 ~4 ~-27 ~-101 ~4 ~-22 minecraft:smooth_stone
fill ~-109 ~2 ~-28 ~-109 ~3 ~-28 minecraft:gray_stained_glass
fill ~-109 ~2 ~-21 ~-109 ~3 ~-21 minecraft:light_gray_stained_glass
fill ~-106 ~2 ~-28 ~-106 ~3 ~-28 minecraft:gray_stained_glass
fill ~-106 ~2 ~-21 ~-106 ~3 ~-21 minecraft:light_gray_stained_glass
fill ~-103 ~2 ~-28 ~-103 ~3 ~-28 minecraft:gray_stained_glass
fill ~-103 ~2 ~-21 ~-103 ~3 ~-21 minecraft:light_gray_stained_glass
fill ~-111 ~2 ~-26 ~-111 ~3 ~-26 minecraft:gray_stained_glass
fill ~-100 ~2 ~-26 ~-100 ~3 ~-26 minecraft:light_gray_stained_glass
fill ~-111 ~2 ~-23 ~-111 ~3 ~-23 minecraft:gray_stained_glass
fill ~-100 ~2 ~-23 ~-100 ~3 ~-23 minecraft:light_gray_stained_glass
setblock ~-106 ~1 ~-28 minecraft:iron_door[half=lower,facing=north]
setblock ~-106 ~2 ~-28 minecraft:iron_door[half=upper,facing=north]
# 048 hotel style=civic_modern context=arterial_front facing=west
fill ~100 ~-3 ~10 ~105 ~-1 ~22 minecraft:stone
fill ~100 ~0 ~10 ~105 ~7 ~22 minecraft:bricks
fill ~101 ~1 ~11 ~104 ~6 ~21 minecraft:air
fill ~101 ~4 ~11 ~104 ~4 ~21 minecraft:smooth_stone
fill ~102 ~2 ~10 ~102 ~3 ~10 minecraft:gray_stained_glass
fill ~102 ~2 ~22 ~102 ~3 ~22 minecraft:light_gray_stained_glass
fill ~100 ~2 ~12 ~100 ~3 ~12 minecraft:gray_stained_glass
fill ~105 ~2 ~12 ~105 ~3 ~12 minecraft:light_gray_stained_glass
fill ~100 ~2 ~15 ~100 ~3 ~15 minecraft:gray_stained_glass
fill ~105 ~2 ~15 ~105 ~3 ~15 minecraft:light_gray_stained_glass
fill ~100 ~2 ~18 ~100 ~3 ~18 minecraft:gray_stained_glass
fill ~105 ~2 ~18 ~105 ~3 ~18 minecraft:light_gray_stained_glass
setblock ~100 ~1 ~15 minecraft:iron_door[half=lower,facing=west]
setblock ~100 ~2 ~15 minecraft:iron_door[half=upper,facing=west]
