# Buildings 137..144
# 137 medical_center style=bay_office context=arterial_front facing=south
fill ~4 ~-3 ~-36 ~10 ~-1 ~-29 minecraft:stone
fill ~4 ~0 ~-36 ~10 ~12 ~-29 minecraft:bricks
fill ~5 ~1 ~-35 ~9 ~11 ~-30 minecraft:air
fill ~5 ~4 ~-35 ~9 ~4 ~-30 minecraft:smooth_stone
fill ~5 ~8 ~-35 ~9 ~8 ~-30 minecraft:smooth_stone
fill ~6 ~2 ~-36 ~6 ~3 ~-36 minecraft:gray_stained_glass
fill ~6 ~2 ~-29 ~6 ~3 ~-29 minecraft:light_gray_stained_glass
fill ~4 ~2 ~-34 ~4 ~3 ~-34 minecraft:gray_stained_glass
fill ~10 ~2 ~-34 ~10 ~3 ~-34 minecraft:light_gray_stained_glass
fill ~4 ~2 ~-31 ~4 ~3 ~-31 minecraft:gray_stained_glass
fill ~10 ~2 ~-31 ~10 ~3 ~-31 minecraft:light_gray_stained_glass
fill ~6 ~6 ~-36 ~6 ~7 ~-36 minecraft:gray_stained_glass
fill ~6 ~6 ~-29 ~6 ~7 ~-29 minecraft:light_gray_stained_glass
fill ~4 ~6 ~-34 ~4 ~7 ~-34 minecraft:gray_stained_glass
fill ~10 ~6 ~-34 ~10 ~7 ~-34 minecraft:light_gray_stained_glass
fill ~4 ~6 ~-31 ~4 ~7 ~-31 minecraft:gray_stained_glass
fill ~10 ~6 ~-31 ~10 ~7 ~-31 minecraft:light_gray_stained_glass
fill ~6 ~10 ~-36 ~6 ~11 ~-36 minecraft:gray_stained_glass
fill ~6 ~10 ~-29 ~6 ~11 ~-29 minecraft:light_gray_stained_glass
fill ~4 ~10 ~-34 ~4 ~11 ~-34 minecraft:gray_stained_glass
fill ~10 ~10 ~-34 ~10 ~11 ~-34 minecraft:light_gray_stained_glass
fill ~4 ~10 ~-31 ~4 ~11 ~-31 minecraft:gray_stained_glass
fill ~10 ~10 ~-31 ~10 ~11 ~-31 minecraft:light_gray_stained_glass
setblock ~7 ~1 ~-29 minecraft:iron_door[half=lower,facing=south]
setblock ~7 ~2 ~-29 minecraft:iron_door[half=upper,facing=south]
fill ~4 ~7 ~-36 ~10 ~12 ~-29 minecraft:air
fill ~5 ~7 ~-35 ~9 ~12 ~-30 minecraft:bricks
fill ~6 ~8 ~-34 ~8 ~11 ~-31 minecraft:air
fill ~5 ~13 ~-35 ~9 ~13 ~-30 minecraft:deepslate_tile_slab
fill ~6 ~2 ~-29 ~8 ~7 ~-29 minecraft:blue_stained_glass
# 138 logistics style=industrial_shed context=local_front facing=east
fill ~-76 ~-3 ~-92 ~-67 ~-1 ~-82 minecraft:stone
fill ~-76 ~0 ~-92 ~-67 ~6 ~-82 minecraft:bricks
fill ~-75 ~1 ~-91 ~-68 ~5 ~-83 minecraft:air
fill ~-75 ~4 ~-91 ~-68 ~4 ~-83 minecraft:smooth_stone
fill ~-74 ~2 ~-92 ~-74 ~3 ~-92 minecraft:gray_stained_glass
fill ~-74 ~2 ~-82 ~-74 ~3 ~-82 minecraft:light_gray_stained_glass
fill ~-71 ~2 ~-92 ~-71 ~3 ~-92 minecraft:gray_stained_glass
fill ~-71 ~2 ~-82 ~-71 ~3 ~-82 minecraft:light_gray_stained_glass
fill ~-76 ~2 ~-90 ~-76 ~3 ~-90 minecraft:gray_stained_glass
fill ~-67 ~2 ~-90 ~-67 ~3 ~-90 minecraft:light_gray_stained_glass
fill ~-76 ~2 ~-87 ~-76 ~3 ~-87 minecraft:gray_stained_glass
fill ~-67 ~2 ~-87 ~-67 ~3 ~-87 minecraft:light_gray_stained_glass
fill ~-76 ~2 ~-84 ~-76 ~3 ~-84 minecraft:gray_stained_glass
fill ~-67 ~2 ~-84 ~-67 ~3 ~-84 minecraft:light_gray_stained_glass
setblock ~-67 ~1 ~-87 minecraft:iron_door[half=lower,facing=east]
setblock ~-67 ~2 ~-87 minecraft:iron_door[half=upper,facing=east]
fill ~-67 ~1 ~-90 ~-67 ~4 ~-84 minecraft:polished_blackstone
fill ~-67 ~5 ~-90 ~-67 ~5 ~-84 minecraft:light_blue_stained_glass
fill ~-74 ~8 ~-90 ~-72 ~9 ~-88 minecraft:iron_block
fill ~-76 ~7 ~-92 ~-67 ~7 ~-82 minecraft:deepslate_tile_slab
fill ~-69 ~4 ~-84 ~-67 ~8 ~-82 minecraft:air
setblock ~-69 ~4 ~-84 minecraft:cobweb
# 139 community style=setback_block context=collector_front facing=west
fill ~60 ~-3 ~-50 ~67 ~-1 ~-42 minecraft:stone
fill ~60 ~0 ~-50 ~67 ~10 ~-42 minecraft:light_gray_concrete
fill ~61 ~1 ~-49 ~66 ~9 ~-43 minecraft:air
fill ~61 ~4 ~-49 ~66 ~4 ~-43 minecraft:smooth_stone
fill ~61 ~8 ~-49 ~66 ~8 ~-43 minecraft:smooth_stone
fill ~62 ~2 ~-50 ~62 ~3 ~-50 minecraft:gray_stained_glass
fill ~62 ~2 ~-42 ~62 ~3 ~-42 minecraft:light_gray_stained_glass
fill ~65 ~2 ~-50 ~65 ~3 ~-50 minecraft:gray_stained_glass
fill ~65 ~2 ~-42 ~65 ~3 ~-42 minecraft:light_gray_stained_glass
fill ~60 ~2 ~-48 ~60 ~3 ~-48 minecraft:gray_stained_glass
fill ~67 ~2 ~-48 ~67 ~3 ~-48 minecraft:light_gray_stained_glass
fill ~60 ~2 ~-45 ~60 ~3 ~-45 minecraft:gray_stained_glass
fill ~67 ~2 ~-45 ~67 ~3 ~-45 minecraft:light_gray_stained_glass
fill ~62 ~6 ~-50 ~62 ~7 ~-50 minecraft:gray_stained_glass
fill ~62 ~6 ~-42 ~62 ~7 ~-42 minecraft:light_gray_stained_glass
fill ~65 ~6 ~-50 ~65 ~7 ~-50 minecraft:gray_stained_glass
fill ~65 ~6 ~-42 ~65 ~7 ~-42 minecraft:light_gray_stained_glass
fill ~60 ~6 ~-48 ~60 ~7 ~-48 minecraft:gray_stained_glass
fill ~67 ~6 ~-48 ~67 ~7 ~-48 minecraft:light_gray_stained_glass
fill ~60 ~6 ~-45 ~60 ~7 ~-45 minecraft:gray_stained_glass
fill ~67 ~6 ~-45 ~67 ~7 ~-45 minecraft:light_gray_stained_glass
setblock ~60 ~1 ~-46 minecraft:iron_door[half=lower,facing=west]
setblock ~60 ~2 ~-46 minecraft:iron_door[half=upper,facing=west]
fill ~60 ~7 ~-50 ~67 ~10 ~-42 minecraft:air
fill ~61 ~7 ~-49 ~66 ~10 ~-43 minecraft:light_gray_concrete
fill ~62 ~8 ~-48 ~65 ~9 ~-44 minecraft:air
fill ~61 ~11 ~-49 ~66 ~11 ~-43 minecraft:smooth_stone_slab
# 140 supermarket style=corner_store context=collector_front facing=east
fill ~-124 ~-3 ~74 ~-118 ~-1 ~80 minecraft:stone
fill ~-124 ~0 ~74 ~-118 ~7 ~80 minecraft:white_terracotta
fill ~-123 ~1 ~75 ~-119 ~6 ~79 minecraft:air
fill ~-123 ~4 ~75 ~-119 ~4 ~79 minecraft:smooth_stone
fill ~-122 ~2 ~74 ~-122 ~3 ~74 minecraft:gray_stained_glass
fill ~-122 ~2 ~80 ~-122 ~3 ~80 minecraft:light_gray_stained_glass
fill ~-124 ~2 ~76 ~-124 ~3 ~76 minecraft:gray_stained_glass
fill ~-118 ~2 ~76 ~-118 ~3 ~76 minecraft:light_gray_stained_glass
setblock ~-118 ~1 ~77 minecraft:iron_door[half=lower,facing=east]
setblock ~-118 ~2 ~77 minecraft:iron_door[half=upper,facing=east]
fill ~-118 ~1 ~75 ~-118 ~3 ~79 minecraft:cyan_stained_glass
setblock ~-118 ~1 ~77 minecraft:iron_door[half=lower,facing=east]
setblock ~-118 ~2 ~77 minecraft:iron_door[half=upper,facing=east]
setblock ~-117 ~3 ~77 minecraft:red_wool
fill ~-124 ~8 ~74 ~-118 ~8 ~80 minecraft:dark_oak_slab
# 141 shop_house style=arcade_shop context=collector_front facing=west
fill ~95 ~-3 ~23 ~101 ~-1 ~29 minecraft:stone
fill ~95 ~0 ~23 ~101 ~5 ~29 minecraft:bricks
fill ~96 ~1 ~24 ~100 ~4 ~28 minecraft:air
fill ~96 ~4 ~24 ~100 ~4 ~28 minecraft:smooth_stone
fill ~97 ~2 ~23 ~97 ~3 ~23 minecraft:gray_stained_glass
fill ~97 ~2 ~29 ~97 ~3 ~29 minecraft:light_gray_stained_glass
fill ~95 ~2 ~25 ~95 ~3 ~25 minecraft:gray_stained_glass
fill ~101 ~2 ~25 ~101 ~3 ~25 minecraft:light_gray_stained_glass
setblock ~95 ~1 ~26 minecraft:iron_door[half=lower,facing=west]
setblock ~95 ~2 ~26 minecraft:iron_door[half=upper,facing=west]
fill ~95 ~1 ~24 ~95 ~3 ~28 minecraft:cyan_stained_glass
setblock ~95 ~1 ~26 minecraft:iron_door[half=lower,facing=west]
setblock ~95 ~2 ~26 minecraft:iron_door[half=upper,facing=west]
setblock ~94 ~3 ~26 minecraft:red_wool
fill ~95 ~4 ~24 ~95 ~4 ~28 minecraft:weathered_cut_copper
fill ~95 ~6 ~23 ~101 ~6 ~29 minecraft:deepslate_tile_slab
# 142 supermarket style=arcade_shop context=collector_front facing=south
fill ~-48 ~-3 ~89 ~-43 ~-1 ~95 minecraft:stone
fill ~-48 ~0 ~89 ~-43 ~7 ~95 minecraft:white_terracotta
fill ~-47 ~1 ~90 ~-44 ~6 ~94 minecraft:air
fill ~-47 ~4 ~90 ~-44 ~4 ~94 minecraft:smooth_stone
fill ~-46 ~2 ~89 ~-46 ~3 ~89 minecraft:gray_stained_glass
fill ~-46 ~2 ~95 ~-46 ~3 ~95 minecraft:light_gray_stained_glass
fill ~-48 ~2 ~91 ~-48 ~3 ~91 minecraft:gray_stained_glass
fill ~-43 ~2 ~91 ~-43 ~3 ~91 minecraft:light_gray_stained_glass
setblock ~-46 ~1 ~95 minecraft:iron_door[half=lower,facing=south]
setblock ~-46 ~2 ~95 minecraft:iron_door[half=upper,facing=south]
fill ~-47 ~1 ~95 ~-44 ~3 ~95 minecraft:cyan_stained_glass
setblock ~-46 ~1 ~95 minecraft:iron_door[half=lower,facing=south]
setblock ~-46 ~2 ~95 minecraft:iron_door[half=upper,facing=south]
setblock ~-46 ~3 ~96 minecraft:red_wool
fill ~-47 ~4 ~95 ~-44 ~4 ~95 minecraft:dark_oak_planks
fill ~-48 ~8 ~89 ~-43 ~8 ~95 minecraft:dark_oak_slab
# 143 lowrise_housing style=stepped_house context=local_front facing=west
fill ~91 ~-3 ~-23 ~97 ~-1 ~-16 minecraft:stone
fill ~91 ~0 ~-23 ~97 ~9 ~-16 minecraft:white_terracotta
fill ~92 ~1 ~-22 ~96 ~8 ~-17 minecraft:air
fill ~92 ~4 ~-22 ~96 ~4 ~-17 minecraft:smooth_stone
fill ~92 ~8 ~-22 ~96 ~8 ~-17 minecraft:smooth_stone
fill ~93 ~2 ~-23 ~93 ~3 ~-23 minecraft:gray_stained_glass
fill ~93 ~2 ~-16 ~93 ~3 ~-16 minecraft:light_gray_stained_glass
fill ~91 ~2 ~-21 ~91 ~3 ~-21 minecraft:gray_stained_glass
fill ~97 ~2 ~-21 ~97 ~3 ~-21 minecraft:light_gray_stained_glass
fill ~91 ~2 ~-18 ~91 ~3 ~-18 minecraft:gray_stained_glass
fill ~97 ~2 ~-18 ~97 ~3 ~-18 minecraft:light_gray_stained_glass
fill ~93 ~6 ~-23 ~93 ~7 ~-23 minecraft:gray_stained_glass
fill ~93 ~6 ~-16 ~93 ~7 ~-16 minecraft:light_gray_stained_glass
fill ~91 ~6 ~-21 ~91 ~7 ~-21 minecraft:gray_stained_glass
fill ~97 ~6 ~-21 ~97 ~7 ~-21 minecraft:light_gray_stained_glass
fill ~91 ~6 ~-18 ~91 ~7 ~-18 minecraft:gray_stained_glass
fill ~97 ~6 ~-18 ~97 ~7 ~-18 minecraft:light_gray_stained_glass
setblock ~91 ~1 ~-20 minecraft:iron_door[half=lower,facing=west]
setblock ~91 ~2 ~-20 minecraft:iron_door[half=upper,facing=west]
fill ~91 ~10 ~-23 ~97 ~10 ~-16 minecraft:dark_oak_slab
fill ~92 ~11 ~-22 ~96 ~11 ~-17 minecraft:dark_oak_slab
setblock ~90 ~3 ~-20 minecraft:dark_oak_slab[type=top]
# 144 lowrise_housing style=rowhouse context=local_front facing=east
fill ~78 ~-3 ~-41 ~84 ~-1 ~-33 minecraft:stone
fill ~78 ~0 ~-41 ~84 ~12 ~-33 minecraft:bricks
fill ~79 ~1 ~-40 ~83 ~11 ~-34 minecraft:air
fill ~79 ~4 ~-40 ~83 ~4 ~-34 minecraft:smooth_stone
fill ~79 ~8 ~-40 ~83 ~8 ~-34 minecraft:smooth_stone
fill ~80 ~2 ~-41 ~80 ~3 ~-41 minecraft:gray_stained_glass
fill ~80 ~2 ~-33 ~80 ~3 ~-33 minecraft:light_gray_stained_glass
fill ~78 ~2 ~-39 ~78 ~3 ~-39 minecraft:gray_stained_glass
fill ~84 ~2 ~-39 ~84 ~3 ~-39 minecraft:light_gray_stained_glass
fill ~78 ~2 ~-36 ~78 ~3 ~-36 minecraft:gray_stained_glass
fill ~84 ~2 ~-36 ~84 ~3 ~-36 minecraft:light_gray_stained_glass
fill ~80 ~6 ~-41 ~80 ~7 ~-41 minecraft:gray_stained_glass
fill ~80 ~6 ~-33 ~80 ~7 ~-33 minecraft:light_gray_stained_glass
fill ~78 ~6 ~-39 ~78 ~7 ~-39 minecraft:gray_stained_glass
fill ~84 ~6 ~-39 ~84 ~7 ~-39 minecraft:light_gray_stained_glass
fill ~78 ~6 ~-36 ~78 ~7 ~-36 minecraft:gray_stained_glass
fill ~84 ~6 ~-36 ~84 ~7 ~-36 minecraft:light_gray_stained_glass
fill ~80 ~10 ~-41 ~80 ~11 ~-41 minecraft:gray_stained_glass
fill ~80 ~10 ~-33 ~80 ~11 ~-33 minecraft:light_gray_stained_glass
fill ~78 ~10 ~-39 ~78 ~11 ~-39 minecraft:gray_stained_glass
fill ~84 ~10 ~-39 ~84 ~11 ~-39 minecraft:light_gray_stained_glass
fill ~78 ~10 ~-36 ~78 ~11 ~-36 minecraft:gray_stained_glass
fill ~84 ~10 ~-36 ~84 ~11 ~-36 minecraft:light_gray_stained_glass
setblock ~84 ~1 ~-37 minecraft:iron_door[half=lower,facing=east]
setblock ~84 ~2 ~-37 minecraft:iron_door[half=upper,facing=east]
fill ~78 ~13 ~-41 ~84 ~13 ~-33 minecraft:deepslate_tile_slab
fill ~79 ~14 ~-40 ~83 ~14 ~-34 minecraft:deepslate_tile_slab
setblock ~85 ~3 ~-37 minecraft:dark_oak_slab[type=top]
fill ~80 ~14 ~-39 ~82 ~15 ~-37 minecraft:light_gray_concrete
setblock ~83 ~14 ~-38 minecraft:lightning_rod
