# Buildings 105..112
# 105 row_house style=stepped_house context=back_block facing=north
fill ~-90 ~-3 ~-60 ~-84 ~-1 ~-50 minecraft:stone
fill ~-90 ~0 ~-60 ~-84 ~5 ~-50 minecraft:calcite
fill ~-89 ~1 ~-59 ~-85 ~4 ~-51 minecraft:air
fill ~-89 ~4 ~-59 ~-85 ~4 ~-51 minecraft:smooth_stone
fill ~-88 ~2 ~-60 ~-88 ~3 ~-60 minecraft:gray_stained_glass
fill ~-88 ~2 ~-50 ~-88 ~3 ~-50 minecraft:light_gray_stained_glass
fill ~-90 ~2 ~-58 ~-90 ~3 ~-58 minecraft:gray_stained_glass
fill ~-84 ~2 ~-58 ~-84 ~3 ~-58 minecraft:light_gray_stained_glass
fill ~-90 ~2 ~-55 ~-90 ~3 ~-55 minecraft:gray_stained_glass
fill ~-84 ~2 ~-55 ~-84 ~3 ~-55 minecraft:light_gray_stained_glass
fill ~-90 ~2 ~-52 ~-90 ~3 ~-52 minecraft:gray_stained_glass
fill ~-84 ~2 ~-52 ~-84 ~3 ~-52 minecraft:light_gray_stained_glass
setblock ~-87 ~1 ~-60 minecraft:iron_door[half=lower,facing=north]
setblock ~-87 ~2 ~-60 minecraft:iron_door[half=upper,facing=north]
fill ~-90 ~6 ~-60 ~-84 ~6 ~-50 minecraft:stone_brick_slab
fill ~-89 ~7 ~-59 ~-85 ~7 ~-51 minecraft:stone_brick_slab
setblock ~-87 ~3 ~-61 minecraft:dark_oak_slab[type=top]
# 106 supermarket style=arcade_shop context=collector_front facing=west
fill ~-77 ~-3 ~48 ~-71 ~-1 ~58 minecraft:stone
fill ~-77 ~0 ~48 ~-71 ~10 ~58 minecraft:smooth_sandstone
fill ~-76 ~1 ~49 ~-72 ~9 ~57 minecraft:air
fill ~-76 ~4 ~49 ~-72 ~4 ~57 minecraft:smooth_stone
fill ~-76 ~8 ~49 ~-72 ~8 ~57 minecraft:smooth_stone
fill ~-75 ~2 ~48 ~-75 ~3 ~48 minecraft:gray_stained_glass
fill ~-75 ~2 ~58 ~-75 ~3 ~58 minecraft:light_gray_stained_glass
fill ~-77 ~2 ~50 ~-77 ~3 ~50 minecraft:gray_stained_glass
fill ~-71 ~2 ~50 ~-71 ~3 ~50 minecraft:light_gray_stained_glass
fill ~-77 ~2 ~53 ~-77 ~3 ~53 minecraft:gray_stained_glass
fill ~-71 ~2 ~53 ~-71 ~3 ~53 minecraft:light_gray_stained_glass
fill ~-77 ~2 ~56 ~-77 ~3 ~56 minecraft:gray_stained_glass
fill ~-71 ~2 ~56 ~-71 ~3 ~56 minecraft:light_gray_stained_glass
fill ~-75 ~6 ~48 ~-75 ~7 ~48 minecraft:gray_stained_glass
fill ~-75 ~6 ~58 ~-75 ~7 ~58 minecraft:light_gray_stained_glass
fill ~-77 ~6 ~50 ~-77 ~7 ~50 minecraft:gray_stained_glass
fill ~-71 ~6 ~50 ~-71 ~7 ~50 minecraft:light_gray_stained_glass
fill ~-77 ~6 ~53 ~-77 ~7 ~53 minecraft:gray_stained_glass
fill ~-71 ~6 ~53 ~-71 ~7 ~53 minecraft:light_gray_stained_glass
fill ~-77 ~6 ~56 ~-77 ~7 ~56 minecraft:gray_stained_glass
fill ~-71 ~6 ~56 ~-71 ~7 ~56 minecraft:light_gray_stained_glass
setblock ~-77 ~1 ~53 minecraft:iron_door[half=lower,facing=west]
setblock ~-77 ~2 ~53 minecraft:iron_door[half=upper,facing=west]
fill ~-77 ~1 ~49 ~-77 ~3 ~57 minecraft:cyan_stained_glass
setblock ~-77 ~1 ~53 minecraft:iron_door[half=lower,facing=west]
setblock ~-77 ~2 ~53 minecraft:iron_door[half=upper,facing=west]
setblock ~-78 ~3 ~53 minecraft:red_wool
fill ~-77 ~4 ~49 ~-77 ~4 ~57 minecraft:brown_terracotta
fill ~-77 ~11 ~48 ~-71 ~11 ~58 minecraft:stone_brick_slab
# 107 restaurant style=storefront context=collector_front facing=south
fill ~94 ~-3 ~31 ~100 ~-1 ~38 minecraft:stone
fill ~94 ~0 ~31 ~100 ~7 ~38 minecraft:white_concrete
fill ~95 ~1 ~32 ~99 ~6 ~37 minecraft:air
fill ~95 ~4 ~32 ~99 ~4 ~37 minecraft:smooth_stone
fill ~96 ~2 ~31 ~96 ~3 ~31 minecraft:gray_stained_glass
fill ~96 ~2 ~38 ~96 ~3 ~38 minecraft:light_gray_stained_glass
fill ~94 ~2 ~33 ~94 ~3 ~33 minecraft:gray_stained_glass
fill ~100 ~2 ~33 ~100 ~3 ~33 minecraft:light_gray_stained_glass
fill ~94 ~2 ~36 ~94 ~3 ~36 minecraft:gray_stained_glass
fill ~100 ~2 ~36 ~100 ~3 ~36 minecraft:light_gray_stained_glass
setblock ~97 ~1 ~38 minecraft:iron_door[half=lower,facing=south]
setblock ~97 ~2 ~38 minecraft:iron_door[half=upper,facing=south]
fill ~95 ~1 ~38 ~99 ~3 ~38 minecraft:cyan_stained_glass
setblock ~97 ~1 ~38 minecraft:iron_door[half=lower,facing=south]
setblock ~97 ~2 ~38 minecraft:iron_door[half=upper,facing=south]
setblock ~97 ~3 ~39 minecraft:red_wool
fill ~94 ~8 ~31 ~100 ~8 ~38 minecraft:smooth_stone_slab
# 108 medical_center style=setback_tower context=arterial_front facing=south
fill ~12 ~-3 ~-36 ~21 ~-1 ~-28 minecraft:stone
fill ~12 ~0 ~-36 ~21 ~20 ~-28 minecraft:light_gray_concrete
fill ~13 ~1 ~-35 ~20 ~19 ~-29 minecraft:air
fill ~13 ~4 ~-35 ~20 ~4 ~-29 minecraft:smooth_stone
fill ~13 ~8 ~-35 ~20 ~8 ~-29 minecraft:smooth_stone
fill ~13 ~12 ~-35 ~20 ~12 ~-29 minecraft:smooth_stone
fill ~13 ~16 ~-35 ~20 ~16 ~-29 minecraft:smooth_stone
fill ~14 ~2 ~-36 ~14 ~3 ~-36 minecraft:gray_stained_glass
fill ~14 ~2 ~-28 ~14 ~3 ~-28 minecraft:light_gray_stained_glass
fill ~17 ~2 ~-36 ~17 ~3 ~-36 minecraft:gray_stained_glass
fill ~17 ~2 ~-28 ~17 ~3 ~-28 minecraft:light_gray_stained_glass
fill ~12 ~2 ~-34 ~12 ~3 ~-34 minecraft:gray_stained_glass
fill ~21 ~2 ~-34 ~21 ~3 ~-34 minecraft:light_gray_stained_glass
fill ~12 ~2 ~-31 ~12 ~3 ~-31 minecraft:gray_stained_glass
fill ~21 ~2 ~-31 ~21 ~3 ~-31 minecraft:light_gray_stained_glass
fill ~14 ~6 ~-36 ~14 ~7 ~-36 minecraft:gray_stained_glass
fill ~14 ~6 ~-28 ~14 ~7 ~-28 minecraft:light_gray_stained_glass
fill ~17 ~6 ~-36 ~17 ~7 ~-36 minecraft:gray_stained_glass
fill ~17 ~6 ~-28 ~17 ~7 ~-28 minecraft:light_gray_stained_glass
fill ~12 ~6 ~-34 ~12 ~7 ~-34 minecraft:gray_stained_glass
fill ~21 ~6 ~-34 ~21 ~7 ~-34 minecraft:light_gray_stained_glass
fill ~12 ~6 ~-31 ~12 ~7 ~-31 minecraft:gray_stained_glass
fill ~21 ~6 ~-31 ~21 ~7 ~-31 minecraft:light_gray_stained_glass
fill ~14 ~10 ~-36 ~14 ~11 ~-36 minecraft:gray_stained_glass
fill ~14 ~10 ~-28 ~14 ~11 ~-28 minecraft:light_gray_stained_glass
fill ~17 ~10 ~-36 ~17 ~11 ~-36 minecraft:gray_stained_glass
fill ~17 ~10 ~-28 ~17 ~11 ~-28 minecraft:light_gray_stained_glass
fill ~12 ~10 ~-34 ~12 ~11 ~-34 minecraft:gray_stained_glass
fill ~21 ~10 ~-34 ~21 ~11 ~-34 minecraft:light_gray_stained_glass
fill ~12 ~10 ~-31 ~12 ~11 ~-31 minecraft:gray_stained_glass
fill ~21 ~10 ~-31 ~21 ~11 ~-31 minecraft:light_gray_stained_glass
fill ~14 ~14 ~-36 ~14 ~15 ~-36 minecraft:gray_stained_glass
fill ~14 ~14 ~-28 ~14 ~15 ~-28 minecraft:light_gray_stained_glass
fill ~17 ~14 ~-36 ~17 ~15 ~-36 minecraft:gray_stained_glass
fill ~17 ~14 ~-28 ~17 ~15 ~-28 minecraft:light_gray_stained_glass
fill ~12 ~14 ~-34 ~12 ~15 ~-34 minecraft:gray_stained_glass
fill ~21 ~14 ~-34 ~21 ~15 ~-34 minecraft:light_gray_stained_glass
fill ~12 ~14 ~-31 ~12 ~15 ~-31 minecraft:gray_stained_glass
fill ~21 ~14 ~-31 ~21 ~15 ~-31 minecraft:light_gray_stained_glass
fill ~14 ~18 ~-36 ~14 ~19 ~-36 minecraft:gray_stained_glass
fill ~14 ~18 ~-28 ~14 ~19 ~-28 minecraft:light_gray_stained_glass
fill ~17 ~18 ~-36 ~17 ~19 ~-36 minecraft:gray_stained_glass
fill ~17 ~18 ~-28 ~17 ~19 ~-28 minecraft:light_gray_stained_glass
fill ~12 ~18 ~-34 ~12 ~19 ~-34 minecraft:gray_stained_glass
fill ~21 ~18 ~-34 ~21 ~19 ~-34 minecraft:light_gray_stained_glass
fill ~12 ~18 ~-31 ~12 ~19 ~-31 minecraft:gray_stained_glass
fill ~21 ~18 ~-31 ~21 ~19 ~-31 minecraft:light_gray_stained_glass
setblock ~16 ~1 ~-28 minecraft:iron_door[half=lower,facing=south]
setblock ~16 ~2 ~-28 minecraft:iron_door[half=upper,facing=south]
fill ~12 ~15 ~-36 ~21 ~20 ~-28 minecraft:air
fill ~13 ~15 ~-35 ~20 ~20 ~-29 minecraft:light_gray_concrete
fill ~14 ~16 ~-34 ~19 ~19 ~-30 minecraft:air
fill ~13 ~21 ~-35 ~20 ~21 ~-29 minecraft:smooth_stone_slab
fill ~14 ~22 ~-34 ~16 ~23 ~-32 minecraft:light_gray_concrete
setblock ~17 ~22 ~-33 minecraft:lightning_rod
# 109 shop_house style=arcade_shop context=collector_front facing=east
fill ~-122 ~-3 ~83 ~-116 ~-1 ~91 minecraft:stone
fill ~-122 ~0 ~83 ~-116 ~7 ~91 minecraft:calcite
fill ~-121 ~1 ~84 ~-117 ~6 ~90 minecraft:air
fill ~-121 ~4 ~84 ~-117 ~4 ~90 minecraft:smooth_stone
fill ~-120 ~2 ~83 ~-120 ~3 ~83 minecraft:gray_stained_glass
fill ~-120 ~2 ~91 ~-120 ~3 ~91 minecraft:light_gray_stained_glass
fill ~-122 ~2 ~85 ~-122 ~3 ~85 minecraft:gray_stained_glass
fill ~-116 ~2 ~85 ~-116 ~3 ~85 minecraft:light_gray_stained_glass
fill ~-122 ~2 ~88 ~-122 ~3 ~88 minecraft:gray_stained_glass
fill ~-116 ~2 ~88 ~-116 ~3 ~88 minecraft:light_gray_stained_glass
setblock ~-116 ~1 ~87 minecraft:iron_door[half=lower,facing=east]
setblock ~-116 ~2 ~87 minecraft:iron_door[half=upper,facing=east]
fill ~-116 ~1 ~84 ~-116 ~3 ~90 minecraft:cyan_stained_glass
setblock ~-116 ~1 ~87 minecraft:iron_door[half=lower,facing=east]
setblock ~-116 ~2 ~87 minecraft:iron_door[half=upper,facing=east]
setblock ~-115 ~3 ~87 minecraft:red_wool
fill ~-116 ~4 ~84 ~-116 ~4 ~90 minecraft:gray_concrete
fill ~-122 ~8 ~83 ~-116 ~8 ~91 minecraft:stone_brick_slab
# 110 shop_house style=storefront context=collector_front facing=north
fill ~-80 ~-3 ~21 ~-74 ~-1 ~28 minecraft:stone
fill ~-80 ~0 ~21 ~-74 ~16 ~28 minecraft:light_gray_concrete
fill ~-79 ~1 ~22 ~-75 ~15 ~27 minecraft:air
fill ~-79 ~4 ~22 ~-75 ~4 ~27 minecraft:smooth_stone
fill ~-79 ~8 ~22 ~-75 ~8 ~27 minecraft:smooth_stone
fill ~-79 ~12 ~22 ~-75 ~12 ~27 minecraft:smooth_stone
fill ~-78 ~2 ~21 ~-78 ~3 ~21 minecraft:gray_stained_glass
fill ~-78 ~2 ~28 ~-78 ~3 ~28 minecraft:light_gray_stained_glass
fill ~-80 ~2 ~23 ~-80 ~3 ~23 minecraft:gray_stained_glass
fill ~-74 ~2 ~23 ~-74 ~3 ~23 minecraft:light_gray_stained_glass
fill ~-80 ~2 ~26 ~-80 ~3 ~26 minecraft:gray_stained_glass
fill ~-74 ~2 ~26 ~-74 ~3 ~26 minecraft:light_gray_stained_glass
fill ~-78 ~6 ~21 ~-78 ~7 ~21 minecraft:gray_stained_glass
fill ~-78 ~6 ~28 ~-78 ~7 ~28 minecraft:light_gray_stained_glass
fill ~-80 ~6 ~23 ~-80 ~7 ~23 minecraft:gray_stained_glass
fill ~-74 ~6 ~23 ~-74 ~7 ~23 minecraft:light_gray_stained_glass
fill ~-80 ~6 ~26 ~-80 ~7 ~26 minecraft:gray_stained_glass
fill ~-74 ~6 ~26 ~-74 ~7 ~26 minecraft:light_gray_stained_glass
fill ~-78 ~10 ~21 ~-78 ~11 ~21 minecraft:gray_stained_glass
fill ~-78 ~10 ~28 ~-78 ~11 ~28 minecraft:light_gray_stained_glass
fill ~-80 ~10 ~23 ~-80 ~11 ~23 minecraft:gray_stained_glass
fill ~-74 ~10 ~23 ~-74 ~11 ~23 minecraft:light_gray_stained_glass
fill ~-80 ~10 ~26 ~-80 ~11 ~26 minecraft:gray_stained_glass
fill ~-74 ~10 ~26 ~-74 ~11 ~26 minecraft:light_gray_stained_glass
fill ~-78 ~14 ~21 ~-78 ~15 ~21 minecraft:gray_stained_glass
fill ~-78 ~14 ~28 ~-78 ~15 ~28 minecraft:light_gray_stained_glass
fill ~-80 ~14 ~23 ~-80 ~15 ~23 minecraft:gray_stained_glass
fill ~-74 ~14 ~23 ~-74 ~15 ~23 minecraft:light_gray_stained_glass
fill ~-80 ~14 ~26 ~-80 ~15 ~26 minecraft:gray_stained_glass
fill ~-74 ~14 ~26 ~-74 ~15 ~26 minecraft:light_gray_stained_glass
setblock ~-77 ~1 ~21 minecraft:iron_door[half=lower,facing=north]
setblock ~-77 ~2 ~21 minecraft:iron_door[half=upper,facing=north]
fill ~-79 ~1 ~21 ~-75 ~3 ~21 minecraft:cyan_stained_glass
setblock ~-77 ~1 ~21 minecraft:iron_door[half=lower,facing=north]
setblock ~-77 ~2 ~21 minecraft:iron_door[half=upper,facing=north]
setblock ~-77 ~3 ~20 minecraft:red_wool
fill ~-80 ~17 ~21 ~-74 ~17 ~28 minecraft:smooth_stone_slab
# 111 fish_market style=balcony_block context=waterfront_front facing=west
fill ~97 ~-3 ~60 ~103 ~-1 ~72 minecraft:stone
fill ~97 ~0 ~60 ~103 ~9 ~72 minecraft:bricks
fill ~98 ~1 ~61 ~102 ~8 ~71 minecraft:air
fill ~98 ~4 ~61 ~102 ~4 ~71 minecraft:smooth_stone
fill ~98 ~8 ~61 ~102 ~8 ~71 minecraft:smooth_stone
fill ~99 ~2 ~60 ~99 ~3 ~60 minecraft:gray_stained_glass
fill ~99 ~2 ~72 ~99 ~3 ~72 minecraft:light_gray_stained_glass
fill ~97 ~2 ~62 ~97 ~3 ~62 minecraft:gray_stained_glass
fill ~103 ~2 ~62 ~103 ~3 ~62 minecraft:light_gray_stained_glass
fill ~97 ~2 ~65 ~97 ~3 ~65 minecraft:gray_stained_glass
fill ~103 ~2 ~65 ~103 ~3 ~65 minecraft:light_gray_stained_glass
fill ~97 ~2 ~68 ~97 ~3 ~68 minecraft:gray_stained_glass
fill ~103 ~2 ~68 ~103 ~3 ~68 minecraft:light_gray_stained_glass
fill ~99 ~6 ~60 ~99 ~7 ~60 minecraft:gray_stained_glass
fill ~99 ~6 ~72 ~99 ~7 ~72 minecraft:light_gray_stained_glass
fill ~97 ~6 ~62 ~97 ~7 ~62 minecraft:gray_stained_glass
fill ~103 ~6 ~62 ~103 ~7 ~62 minecraft:light_gray_stained_glass
fill ~97 ~6 ~65 ~97 ~7 ~65 minecraft:gray_stained_glass
fill ~103 ~6 ~65 ~103 ~7 ~65 minecraft:light_gray_stained_glass
fill ~97 ~6 ~68 ~97 ~7 ~68 minecraft:gray_stained_glass
fill ~103 ~6 ~68 ~103 ~7 ~68 minecraft:light_gray_stained_glass
setblock ~97 ~1 ~65 minecraft:iron_door[half=lower,facing=west]
setblock ~97 ~2 ~65 minecraft:iron_door[half=upper,facing=west]
fill ~96 ~4 ~62 ~96 ~4 ~70 minecraft:smooth_stone_slab
fill ~96 ~8 ~62 ~96 ~8 ~70 minecraft:smooth_stone_slab
fill ~97 ~10 ~60 ~103 ~10 ~72 minecraft:deepslate_tile_slab
fill ~99 ~11 ~62 ~101 ~12 ~64 minecraft:light_gray_concrete
setblock ~102 ~11 ~63 minecraft:lightning_rod
# 112 lowrise_housing style=japanese_house context=back_block facing=north
fill ~-125 ~-3 ~57 ~-120 ~-1 ~63 minecraft:stone
fill ~-125 ~0 ~57 ~-120 ~7 ~63 minecraft:mud_bricks
fill ~-124 ~1 ~58 ~-121 ~6 ~62 minecraft:air
fill ~-124 ~4 ~58 ~-121 ~4 ~62 minecraft:smooth_stone
fill ~-123 ~2 ~57 ~-123 ~3 ~57 minecraft:gray_stained_glass
fill ~-123 ~2 ~63 ~-123 ~3 ~63 minecraft:light_gray_stained_glass
fill ~-125 ~2 ~59 ~-125 ~3 ~59 minecraft:gray_stained_glass
fill ~-120 ~2 ~59 ~-120 ~3 ~59 minecraft:light_gray_stained_glass
setblock ~-123 ~1 ~57 minecraft:iron_door[half=lower,facing=north]
setblock ~-123 ~2 ~57 minecraft:iron_door[half=upper,facing=north]
fill ~-125 ~8 ~57 ~-120 ~8 ~63 minecraft:deepslate_tile_slab
fill ~-124 ~9 ~58 ~-121 ~9 ~62 minecraft:deepslate_tile_slab
setblock ~-123 ~3 ~56 minecraft:dark_oak_slab[type=top]
