# Buildings 105..112
# 105 supermarket style=arcade_shop context=collector_front facing=east
fill ~31 ~-3 ~47 ~40 ~-1 ~54 minecraft:stone
fill ~31 ~0 ~47 ~40 ~16 ~54 minecraft:bricks
fill ~32 ~1 ~48 ~39 ~15 ~53 minecraft:air
fill ~32 ~4 ~48 ~39 ~4 ~53 minecraft:smooth_stone
fill ~32 ~8 ~48 ~39 ~8 ~53 minecraft:smooth_stone
fill ~32 ~12 ~48 ~39 ~12 ~53 minecraft:smooth_stone
fill ~33 ~2 ~47 ~33 ~3 ~47 minecraft:gray_stained_glass
fill ~33 ~2 ~54 ~33 ~3 ~54 minecraft:light_gray_stained_glass
fill ~36 ~2 ~47 ~36 ~3 ~47 minecraft:gray_stained_glass
fill ~36 ~2 ~54 ~36 ~3 ~54 minecraft:light_gray_stained_glass
fill ~31 ~2 ~49 ~31 ~3 ~49 minecraft:gray_stained_glass
fill ~40 ~2 ~49 ~40 ~3 ~49 minecraft:light_gray_stained_glass
fill ~31 ~2 ~52 ~31 ~3 ~52 minecraft:gray_stained_glass
fill ~40 ~2 ~52 ~40 ~3 ~52 minecraft:light_gray_stained_glass
fill ~33 ~6 ~47 ~33 ~7 ~47 minecraft:gray_stained_glass
fill ~33 ~6 ~54 ~33 ~7 ~54 minecraft:light_gray_stained_glass
fill ~36 ~6 ~47 ~36 ~7 ~47 minecraft:gray_stained_glass
fill ~36 ~6 ~54 ~36 ~7 ~54 minecraft:light_gray_stained_glass
fill ~31 ~6 ~49 ~31 ~7 ~49 minecraft:gray_stained_glass
fill ~40 ~6 ~49 ~40 ~7 ~49 minecraft:light_gray_stained_glass
fill ~31 ~6 ~52 ~31 ~7 ~52 minecraft:gray_stained_glass
fill ~40 ~6 ~52 ~40 ~7 ~52 minecraft:light_gray_stained_glass
fill ~33 ~10 ~47 ~33 ~11 ~47 minecraft:gray_stained_glass
fill ~33 ~10 ~54 ~33 ~11 ~54 minecraft:light_gray_stained_glass
fill ~36 ~10 ~47 ~36 ~11 ~47 minecraft:gray_stained_glass
fill ~36 ~10 ~54 ~36 ~11 ~54 minecraft:light_gray_stained_glass
fill ~31 ~10 ~49 ~31 ~11 ~49 minecraft:gray_stained_glass
fill ~40 ~10 ~49 ~40 ~11 ~49 minecraft:light_gray_stained_glass
fill ~31 ~10 ~52 ~31 ~11 ~52 minecraft:gray_stained_glass
fill ~40 ~10 ~52 ~40 ~11 ~52 minecraft:light_gray_stained_glass
fill ~33 ~14 ~47 ~33 ~15 ~47 minecraft:gray_stained_glass
fill ~33 ~14 ~54 ~33 ~15 ~54 minecraft:light_gray_stained_glass
fill ~36 ~14 ~47 ~36 ~15 ~47 minecraft:gray_stained_glass
fill ~36 ~14 ~54 ~36 ~15 ~54 minecraft:light_gray_stained_glass
fill ~31 ~14 ~49 ~31 ~15 ~49 minecraft:gray_stained_glass
fill ~40 ~14 ~49 ~40 ~15 ~49 minecraft:light_gray_stained_glass
fill ~31 ~14 ~52 ~31 ~15 ~52 minecraft:gray_stained_glass
fill ~40 ~14 ~52 ~40 ~15 ~52 minecraft:light_gray_stained_glass
setblock ~40 ~1 ~50 minecraft:iron_door[half=lower,facing=east]
setblock ~40 ~2 ~50 minecraft:iron_door[half=upper,facing=east]
fill ~40 ~1 ~48 ~40 ~3 ~53 minecraft:cyan_stained_glass
setblock ~40 ~1 ~50 minecraft:iron_door[half=lower,facing=east]
setblock ~40 ~2 ~50 minecraft:iron_door[half=upper,facing=east]
setblock ~41 ~3 ~50 minecraft:red_wool
fill ~40 ~4 ~48 ~40 ~4 ~53 doomsday_decoration:hollowbrick
fill ~31 ~17 ~47 ~40 ~17 ~54 minecraft:deepslate_tile_slab
fill ~33 ~18 ~49 ~35 ~19 ~51 minecraft:light_gray_concrete
setblock ~36 ~18 ~50 minecraft:lightning_rod
fill ~40 ~1 ~48 ~40 ~7 ~48 doomsday_decoration:hollowbrick
fill ~40 ~1 ~52 ~40 ~7 ~52 doomsday_decoration:hollowbrick
# 106 hotel style=civic_modern context=arterial_front facing=west
fill ~-31 ~-3 ~111 ~-25 ~-1 ~116 minecraft:stone
fill ~-31 ~0 ~111 ~-25 ~11 ~116 minecraft:white_terracotta
fill ~-30 ~1 ~112 ~-26 ~10 ~115 minecraft:air
fill ~-30 ~4 ~112 ~-26 ~4 ~115 minecraft:smooth_stone
fill ~-30 ~8 ~112 ~-26 ~8 ~115 minecraft:smooth_stone
fill ~-29 ~2 ~111 ~-29 ~3 ~111 minecraft:gray_stained_glass
fill ~-29 ~2 ~116 ~-29 ~3 ~116 minecraft:light_gray_stained_glass
fill ~-31 ~2 ~113 ~-31 ~3 ~113 minecraft:gray_stained_glass
fill ~-25 ~2 ~113 ~-25 ~3 ~113 minecraft:light_gray_stained_glass
fill ~-29 ~6 ~111 ~-29 ~7 ~111 minecraft:gray_stained_glass
fill ~-29 ~6 ~116 ~-29 ~7 ~116 minecraft:light_gray_stained_glass
fill ~-31 ~6 ~113 ~-31 ~7 ~113 minecraft:gray_stained_glass
fill ~-25 ~6 ~113 ~-25 ~7 ~113 minecraft:light_gray_stained_glass
setblock ~-31 ~1 ~113 minecraft:iron_door[half=lower,facing=west]
setblock ~-31 ~2 ~113 minecraft:iron_door[half=upper,facing=west]
fill ~-31 ~7 ~111 ~-25 ~11 ~116 minecraft:air
fill ~-30 ~7 ~112 ~-26 ~11 ~115 minecraft:white_terracotta
fill ~-29 ~8 ~113 ~-27 ~10 ~114 minecraft:air
fill ~-30 ~12 ~112 ~-26 ~12 ~115 minecraft:dark_oak_slab
fill ~-31 ~1 ~112 ~-31 ~7 ~112 minecraft:dark_oak_planks
# 107 local_shop style=storefront context=local_front facing=west
fill ~98 ~-3 ~89 ~106 ~-1 ~95 minecraft:stone
fill ~98 ~0 ~89 ~106 ~9 ~95 minecraft:white_concrete
fill ~99 ~1 ~90 ~105 ~8 ~94 minecraft:air
fill ~99 ~4 ~90 ~105 ~4 ~94 minecraft:smooth_stone
fill ~99 ~8 ~90 ~105 ~8 ~94 minecraft:smooth_stone
fill ~100 ~2 ~89 ~100 ~3 ~89 minecraft:gray_stained_glass
fill ~100 ~2 ~95 ~100 ~3 ~95 minecraft:light_gray_stained_glass
fill ~103 ~2 ~89 ~103 ~3 ~89 minecraft:gray_stained_glass
fill ~103 ~2 ~95 ~103 ~3 ~95 minecraft:light_gray_stained_glass
fill ~98 ~2 ~91 ~98 ~3 ~91 minecraft:gray_stained_glass
fill ~106 ~2 ~91 ~106 ~3 ~91 minecraft:light_gray_stained_glass
fill ~100 ~6 ~89 ~100 ~7 ~89 minecraft:gray_stained_glass
fill ~100 ~6 ~95 ~100 ~7 ~95 minecraft:light_gray_stained_glass
fill ~103 ~6 ~89 ~103 ~7 ~89 minecraft:gray_stained_glass
fill ~103 ~6 ~95 ~103 ~7 ~95 minecraft:light_gray_stained_glass
fill ~98 ~6 ~91 ~98 ~7 ~91 minecraft:gray_stained_glass
fill ~106 ~6 ~91 ~106 ~7 ~91 minecraft:light_gray_stained_glass
setblock ~98 ~1 ~92 minecraft:iron_door[half=lower,facing=west]
setblock ~98 ~2 ~92 minecraft:iron_door[half=upper,facing=west]
fill ~98 ~1 ~90 ~98 ~3 ~94 minecraft:cyan_stained_glass
setblock ~98 ~1 ~92 minecraft:iron_door[half=lower,facing=west]
setblock ~98 ~2 ~92 minecraft:iron_door[half=upper,facing=west]
setblock ~97 ~3 ~92 minecraft:red_wool
fill ~98 ~10 ~89 ~106 ~10 ~95 minecraft:smooth_stone_slab
fill ~98 ~1 ~90 ~98 ~7 ~90 minecraft:cyan_terracotta
fill ~98 ~1 ~94 ~98 ~7 ~94 minecraft:cyan_terracotta
setblock ~98 ~3 ~91 minecraft:red_carpet
# 108 workshop style=industrial_shed context=local_front facing=south
fill ~107 ~-3 ~-126 ~111 ~-1 ~-116 minecraft:stone
fill ~107 ~0 ~-126 ~111 ~9 ~-116 minecraft:white_concrete
fill ~108 ~1 ~-125 ~110 ~8 ~-117 minecraft:air
fill ~108 ~4 ~-125 ~110 ~4 ~-117 minecraft:smooth_stone
fill ~108 ~8 ~-125 ~110 ~8 ~-117 minecraft:smooth_stone
fill ~109 ~2 ~-126 ~109 ~3 ~-126 minecraft:gray_stained_glass
fill ~109 ~2 ~-116 ~109 ~3 ~-116 minecraft:light_gray_stained_glass
fill ~107 ~2 ~-124 ~107 ~3 ~-124 minecraft:gray_stained_glass
fill ~111 ~2 ~-124 ~111 ~3 ~-124 minecraft:light_gray_stained_glass
fill ~107 ~2 ~-121 ~107 ~3 ~-121 minecraft:gray_stained_glass
fill ~111 ~2 ~-121 ~111 ~3 ~-121 minecraft:light_gray_stained_glass
fill ~107 ~2 ~-118 ~107 ~3 ~-118 minecraft:gray_stained_glass
fill ~111 ~2 ~-118 ~111 ~3 ~-118 minecraft:light_gray_stained_glass
fill ~109 ~6 ~-126 ~109 ~7 ~-126 minecraft:gray_stained_glass
fill ~109 ~6 ~-116 ~109 ~7 ~-116 minecraft:light_gray_stained_glass
fill ~107 ~6 ~-124 ~107 ~7 ~-124 minecraft:gray_stained_glass
fill ~111 ~6 ~-124 ~111 ~7 ~-124 minecraft:light_gray_stained_glass
fill ~107 ~6 ~-121 ~107 ~7 ~-121 minecraft:gray_stained_glass
fill ~111 ~6 ~-121 ~111 ~7 ~-121 minecraft:light_gray_stained_glass
fill ~107 ~6 ~-118 ~107 ~7 ~-118 minecraft:gray_stained_glass
fill ~111 ~6 ~-118 ~111 ~7 ~-118 minecraft:light_gray_stained_glass
setblock ~109 ~1 ~-116 minecraft:iron_door[half=lower,facing=south]
setblock ~109 ~2 ~-116 minecraft:iron_door[half=upper,facing=south]
fill ~109 ~1 ~-116 ~109 ~4 ~-116 minecraft:polished_blackstone
fill ~109 ~5 ~-116 ~109 ~5 ~-116 minecraft:light_blue_stained_glass
fill ~109 ~11 ~-124 ~110 ~12 ~-122 minecraft:iron_block
fill ~107 ~10 ~-126 ~111 ~10 ~-116 minecraft:smooth_stone_slab
fill ~109 ~11 ~-124 ~110 ~12 ~-122 minecraft:light_gray_concrete
setblock ~110 ~11 ~-123 minecraft:lightning_rod
# 109 midrise_housing style=balcony_block context=arterial_front facing=west
fill ~-31 ~-3 ~53 ~-24 ~-1 ~61 minecraft:stone
fill ~-31 ~0 ~53 ~-24 ~10 ~61 minecraft:bricks
fill ~-30 ~1 ~54 ~-25 ~9 ~60 minecraft:air
fill ~-30 ~4 ~54 ~-25 ~4 ~60 minecraft:smooth_stone
fill ~-30 ~8 ~54 ~-25 ~8 ~60 minecraft:smooth_stone
fill ~-29 ~2 ~53 ~-29 ~3 ~53 minecraft:gray_stained_glass
fill ~-29 ~2 ~61 ~-29 ~3 ~61 minecraft:light_gray_stained_glass
fill ~-26 ~2 ~53 ~-26 ~3 ~53 minecraft:gray_stained_glass
fill ~-26 ~2 ~61 ~-26 ~3 ~61 minecraft:light_gray_stained_glass
fill ~-31 ~2 ~55 ~-31 ~3 ~55 minecraft:gray_stained_glass
fill ~-24 ~2 ~55 ~-24 ~3 ~55 minecraft:light_gray_stained_glass
fill ~-31 ~2 ~58 ~-31 ~3 ~58 minecraft:gray_stained_glass
fill ~-24 ~2 ~58 ~-24 ~3 ~58 minecraft:light_gray_stained_glass
fill ~-29 ~6 ~53 ~-29 ~7 ~53 minecraft:gray_stained_glass
fill ~-29 ~6 ~61 ~-29 ~7 ~61 minecraft:light_gray_stained_glass
fill ~-26 ~6 ~53 ~-26 ~7 ~53 minecraft:gray_stained_glass
fill ~-26 ~6 ~61 ~-26 ~7 ~61 minecraft:light_gray_stained_glass
fill ~-31 ~6 ~55 ~-31 ~7 ~55 minecraft:gray_stained_glass
fill ~-24 ~6 ~55 ~-24 ~7 ~55 minecraft:light_gray_stained_glass
fill ~-31 ~6 ~58 ~-31 ~7 ~58 minecraft:gray_stained_glass
fill ~-24 ~6 ~58 ~-24 ~7 ~58 minecraft:light_gray_stained_glass
setblock ~-31 ~1 ~57 minecraft:iron_door[half=lower,facing=west]
setblock ~-31 ~2 ~57 minecraft:iron_door[half=upper,facing=west]
fill ~-32 ~4 ~55 ~-32 ~4 ~59 minecraft:smooth_stone_slab
fill ~-32 ~8 ~55 ~-32 ~8 ~59 minecraft:smooth_stone_slab
fill ~-31 ~11 ~53 ~-24 ~11 ~61 minecraft:deepslate_tile_slab
fill ~-31 ~1 ~54 ~-31 ~7 ~54 doomsday_decoration:hollowbrick
fill ~-31 ~1 ~58 ~-31 ~7 ~58 doomsday_decoration:hollowbrick
# 110 restaurant style=arcade_shop context=collector_front facing=north
fill ~18 ~-3 ~-38 ~27 ~-1 ~-29 minecraft:stone
fill ~18 ~0 ~-38 ~27 ~20 ~-29 minecraft:white_terracotta
fill ~19 ~1 ~-37 ~26 ~19 ~-30 minecraft:air
fill ~19 ~4 ~-37 ~26 ~4 ~-30 minecraft:smooth_stone
fill ~19 ~8 ~-37 ~26 ~8 ~-30 minecraft:smooth_stone
fill ~19 ~12 ~-37 ~26 ~12 ~-30 minecraft:smooth_stone
fill ~19 ~16 ~-37 ~26 ~16 ~-30 minecraft:smooth_stone
fill ~20 ~2 ~-38 ~20 ~3 ~-38 minecraft:gray_stained_glass
fill ~20 ~2 ~-29 ~20 ~3 ~-29 minecraft:light_gray_stained_glass
fill ~23 ~2 ~-38 ~23 ~3 ~-38 minecraft:gray_stained_glass
fill ~23 ~2 ~-29 ~23 ~3 ~-29 minecraft:light_gray_stained_glass
fill ~18 ~2 ~-36 ~18 ~3 ~-36 minecraft:gray_stained_glass
fill ~27 ~2 ~-36 ~27 ~3 ~-36 minecraft:light_gray_stained_glass
fill ~18 ~2 ~-33 ~18 ~3 ~-33 minecraft:gray_stained_glass
fill ~27 ~2 ~-33 ~27 ~3 ~-33 minecraft:light_gray_stained_glass
fill ~20 ~6 ~-38 ~20 ~7 ~-38 minecraft:gray_stained_glass
fill ~20 ~6 ~-29 ~20 ~7 ~-29 minecraft:light_gray_stained_glass
fill ~23 ~6 ~-38 ~23 ~7 ~-38 minecraft:gray_stained_glass
fill ~23 ~6 ~-29 ~23 ~7 ~-29 minecraft:light_gray_stained_glass
fill ~18 ~6 ~-36 ~18 ~7 ~-36 minecraft:gray_stained_glass
fill ~27 ~6 ~-36 ~27 ~7 ~-36 minecraft:light_gray_stained_glass
fill ~18 ~6 ~-33 ~18 ~7 ~-33 minecraft:gray_stained_glass
fill ~27 ~6 ~-33 ~27 ~7 ~-33 minecraft:light_gray_stained_glass
fill ~20 ~10 ~-38 ~20 ~11 ~-38 minecraft:gray_stained_glass
fill ~20 ~10 ~-29 ~20 ~11 ~-29 minecraft:light_gray_stained_glass
fill ~23 ~10 ~-38 ~23 ~11 ~-38 minecraft:gray_stained_glass
fill ~23 ~10 ~-29 ~23 ~11 ~-29 minecraft:light_gray_stained_glass
fill ~18 ~10 ~-36 ~18 ~11 ~-36 minecraft:gray_stained_glass
fill ~27 ~10 ~-36 ~27 ~11 ~-36 minecraft:light_gray_stained_glass
fill ~18 ~10 ~-33 ~18 ~11 ~-33 minecraft:gray_stained_glass
fill ~27 ~10 ~-33 ~27 ~11 ~-33 minecraft:light_gray_stained_glass
fill ~20 ~14 ~-38 ~20 ~15 ~-38 minecraft:gray_stained_glass
fill ~20 ~14 ~-29 ~20 ~15 ~-29 minecraft:light_gray_stained_glass
fill ~23 ~14 ~-38 ~23 ~15 ~-38 minecraft:gray_stained_glass
fill ~23 ~14 ~-29 ~23 ~15 ~-29 minecraft:light_gray_stained_glass
fill ~18 ~14 ~-36 ~18 ~15 ~-36 minecraft:gray_stained_glass
fill ~27 ~14 ~-36 ~27 ~15 ~-36 minecraft:light_gray_stained_glass
fill ~18 ~14 ~-33 ~18 ~15 ~-33 minecraft:gray_stained_glass
fill ~27 ~14 ~-33 ~27 ~15 ~-33 minecraft:light_gray_stained_glass
fill ~20 ~18 ~-38 ~20 ~19 ~-38 minecraft:gray_stained_glass
fill ~20 ~18 ~-29 ~20 ~19 ~-29 minecraft:light_gray_stained_glass
fill ~23 ~18 ~-38 ~23 ~19 ~-38 minecraft:gray_stained_glass
fill ~23 ~18 ~-29 ~23 ~19 ~-29 minecraft:light_gray_stained_glass
fill ~18 ~18 ~-36 ~18 ~19 ~-36 minecraft:gray_stained_glass
fill ~27 ~18 ~-36 ~27 ~19 ~-36 minecraft:light_gray_stained_glass
fill ~18 ~18 ~-33 ~18 ~19 ~-33 minecraft:gray_stained_glass
fill ~27 ~18 ~-33 ~27 ~19 ~-33 minecraft:light_gray_stained_glass
setblock ~22 ~1 ~-38 minecraft:iron_door[half=lower,facing=north]
setblock ~22 ~2 ~-38 minecraft:iron_door[half=upper,facing=north]
fill ~19 ~1 ~-38 ~26 ~3 ~-38 minecraft:cyan_stained_glass
setblock ~22 ~1 ~-38 minecraft:iron_door[half=lower,facing=north]
setblock ~22 ~2 ~-38 minecraft:iron_door[half=upper,facing=north]
setblock ~22 ~3 ~-39 minecraft:red_wool
fill ~19 ~4 ~-38 ~26 ~4 ~-38 minecraft:gray_concrete
fill ~18 ~21 ~-38 ~27 ~21 ~-29 minecraft:stone_brick_slab
fill ~19 ~1 ~-38 ~19 ~7 ~-38 minecraft:gray_concrete
fill ~23 ~1 ~-38 ~23 ~7 ~-38 minecraft:gray_concrete
fill ~19 ~6 ~-37 ~26 ~20 ~-30 minecraft:white_terracotta
fill ~20 ~7 ~-36 ~25 ~19 ~-31 minecraft:air
setblock ~20 ~3 ~-38 minecraft:red_carpet
setblock ~25 ~3 ~-38 minecraft:red_carpet
# 111 midrise_housing style=mixed_facade context=arterial_front facing=north
fill ~79 ~-3 ~6 ~86 ~-1 ~13 minecraft:stone
fill ~79 ~0 ~6 ~86 ~10 ~13 minecraft:bricks
fill ~80 ~1 ~7 ~85 ~9 ~12 minecraft:air
fill ~80 ~4 ~7 ~85 ~4 ~12 minecraft:smooth_stone
fill ~80 ~8 ~7 ~85 ~8 ~12 minecraft:smooth_stone
fill ~81 ~2 ~6 ~81 ~3 ~6 minecraft:gray_stained_glass
fill ~81 ~2 ~13 ~81 ~3 ~13 minecraft:light_gray_stained_glass
fill ~84 ~2 ~6 ~84 ~3 ~6 minecraft:gray_stained_glass
fill ~84 ~2 ~13 ~84 ~3 ~13 minecraft:light_gray_stained_glass
fill ~79 ~2 ~8 ~79 ~3 ~8 minecraft:gray_stained_glass
fill ~86 ~2 ~8 ~86 ~3 ~8 minecraft:light_gray_stained_glass
fill ~79 ~2 ~11 ~79 ~3 ~11 minecraft:gray_stained_glass
fill ~86 ~2 ~11 ~86 ~3 ~11 minecraft:light_gray_stained_glass
fill ~81 ~6 ~6 ~81 ~7 ~6 minecraft:gray_stained_glass
fill ~81 ~6 ~13 ~81 ~7 ~13 minecraft:light_gray_stained_glass
fill ~84 ~6 ~6 ~84 ~7 ~6 minecraft:gray_stained_glass
fill ~84 ~6 ~13 ~84 ~7 ~13 minecraft:light_gray_stained_glass
fill ~79 ~6 ~8 ~79 ~7 ~8 minecraft:gray_stained_glass
fill ~86 ~6 ~8 ~86 ~7 ~8 minecraft:light_gray_stained_glass
fill ~79 ~6 ~11 ~79 ~7 ~11 minecraft:gray_stained_glass
fill ~86 ~6 ~11 ~86 ~7 ~11 minecraft:light_gray_stained_glass
setblock ~82 ~1 ~6 minecraft:iron_door[half=lower,facing=north]
setblock ~82 ~2 ~6 minecraft:iron_door[half=upper,facing=north]
fill ~79 ~11 ~6 ~86 ~11 ~13 minecraft:deepslate_tile_slab
fill ~81 ~12 ~8 ~83 ~13 ~10 minecraft:light_gray_concrete
setblock ~84 ~12 ~9 minecraft:lightning_rod
fill ~80 ~1 ~6 ~80 ~7 ~6 doomsday_decoration:hollowbrick
fill ~84 ~1 ~6 ~84 ~7 ~6 doomsday_decoration:hollowbrick
# 112 shop_house style=storefront context=collector_front facing=west
fill ~91 ~-3 ~-38 ~102 ~-1 ~-34 minecraft:stone
fill ~91 ~0 ~-38 ~102 ~5 ~-34 minecraft:calcite
fill ~92 ~1 ~-37 ~101 ~4 ~-35 minecraft:air
fill ~92 ~4 ~-37 ~101 ~4 ~-35 minecraft:smooth_stone
fill ~93 ~2 ~-38 ~93 ~3 ~-38 minecraft:gray_stained_glass
fill ~93 ~2 ~-34 ~93 ~3 ~-34 minecraft:light_gray_stained_glass
fill ~96 ~2 ~-38 ~96 ~3 ~-38 minecraft:gray_stained_glass
fill ~96 ~2 ~-34 ~96 ~3 ~-34 minecraft:light_gray_stained_glass
fill ~99 ~2 ~-38 ~99 ~3 ~-38 minecraft:gray_stained_glass
fill ~99 ~2 ~-34 ~99 ~3 ~-34 minecraft:light_gray_stained_glass
fill ~91 ~2 ~-36 ~91 ~3 ~-36 minecraft:gray_stained_glass
fill ~102 ~2 ~-36 ~102 ~3 ~-36 minecraft:light_gray_stained_glass
setblock ~91 ~1 ~-36 minecraft:iron_door[half=lower,facing=west]
setblock ~91 ~2 ~-36 minecraft:iron_door[half=upper,facing=west]
fill ~91 ~1 ~-37 ~91 ~3 ~-35 minecraft:cyan_stained_glass
setblock ~91 ~1 ~-36 minecraft:iron_door[half=lower,facing=west]
setblock ~91 ~2 ~-36 minecraft:iron_door[half=upper,facing=west]
setblock ~90 ~3 ~-36 minecraft:red_wool
fill ~91 ~6 ~-38 ~102 ~6 ~-34 minecraft:stone_brick_slab
