# Buildings 1..25
# 001 detached_house -118,108 -113,116 h=9
fill ~-118 ~-3 ~108 ~-113 ~-1 ~116 minecraft:stone
fill ~-118 ~0 ~108 ~-113 ~9 ~116 minecraft:mud_bricks
fill ~-117 ~1 ~109 ~-114 ~8 ~115 minecraft:air
fill ~-117 ~4 ~109 ~-114 ~4 ~115 minecraft:smooth_stone
fill ~-117 ~8 ~109 ~-114 ~8 ~115 minecraft:smooth_stone
fill ~-118 ~2 ~110 ~-118 ~3 ~114 minecraft:gray_stained_glass
fill ~-113 ~2 ~110 ~-113 ~3 ~114 minecraft:light_gray_stained_glass
fill ~-118 ~6 ~110 ~-118 ~7 ~114 minecraft:gray_stained_glass
fill ~-113 ~6 ~110 ~-113 ~7 ~114 minecraft:light_gray_stained_glass
fill ~-117 ~0 ~108 ~-114 ~3 ~108 minecraft:spruce_planks
setblock ~-116 ~1 ~108 minecraft:iron_door[half=lower,facing=north]
setblock ~-116 ~2 ~108 minecraft:iron_door[half=upper,facing=north]
fill ~-118 ~10 ~108 ~-113 ~10 ~116 minecraft:deepslate_tile_slab
# 002 mixed_use -17,39 -7,48 h=20
fill ~-17 ~-3 ~39 ~-7 ~-1 ~48 minecraft:stone
fill ~-17 ~0 ~39 ~-7 ~20 ~48 minecraft:bricks
fill ~-16 ~1 ~40 ~-8 ~19 ~47 minecraft:air
fill ~-16 ~4 ~40 ~-8 ~4 ~47 minecraft:smooth_stone
fill ~-16 ~8 ~40 ~-8 ~8 ~47 minecraft:smooth_stone
fill ~-16 ~12 ~40 ~-8 ~12 ~47 minecraft:smooth_stone
fill ~-16 ~16 ~40 ~-8 ~16 ~47 minecraft:smooth_stone
fill ~-17 ~2 ~41 ~-17 ~3 ~46 minecraft:gray_stained_glass
fill ~-7 ~2 ~41 ~-7 ~3 ~46 minecraft:light_gray_stained_glass
fill ~-17 ~6 ~41 ~-17 ~7 ~46 minecraft:gray_stained_glass
fill ~-7 ~6 ~41 ~-7 ~7 ~46 minecraft:light_gray_stained_glass
fill ~-17 ~10 ~41 ~-17 ~11 ~46 minecraft:gray_stained_glass
fill ~-7 ~10 ~41 ~-7 ~11 ~46 minecraft:light_gray_stained_glass
fill ~-17 ~14 ~41 ~-17 ~15 ~46 minecraft:gray_stained_glass
fill ~-7 ~14 ~41 ~-7 ~15 ~46 minecraft:light_gray_stained_glass
fill ~-17 ~18 ~41 ~-17 ~19 ~46 minecraft:gray_stained_glass
fill ~-7 ~18 ~41 ~-7 ~19 ~46 minecraft:light_gray_stained_glass
fill ~-16 ~0 ~39 ~-13 ~3 ~39 doomsday_decoration:redbrick
setblock ~-15 ~1 ~39 minecraft:iron_door[half=lower,facing=north]
setblock ~-15 ~2 ~39 minecraft:iron_door[half=upper,facing=north]
fill ~-17 ~21 ~39 ~-7 ~21 ~48 minecraft:deepslate_tile_slab
# 003 mixed_use -31,5 -20,19 h=16
fill ~-31 ~-3 ~5 ~-20 ~-1 ~19 minecraft:stone
fill ~-31 ~0 ~5 ~-20 ~16 ~19 minecraft:white_terracotta
fill ~-30 ~1 ~6 ~-21 ~15 ~18 minecraft:air
fill ~-30 ~4 ~6 ~-21 ~4 ~18 minecraft:smooth_stone
fill ~-30 ~8 ~6 ~-21 ~8 ~18 minecraft:smooth_stone
fill ~-30 ~12 ~6 ~-21 ~12 ~18 minecraft:smooth_stone
fill ~-31 ~2 ~7 ~-31 ~3 ~17 minecraft:gray_stained_glass
fill ~-20 ~2 ~7 ~-20 ~3 ~17 minecraft:light_gray_stained_glass
fill ~-31 ~6 ~7 ~-31 ~7 ~17 minecraft:gray_stained_glass
fill ~-20 ~6 ~7 ~-20 ~7 ~17 minecraft:light_gray_stained_glass
fill ~-31 ~10 ~7 ~-31 ~11 ~17 minecraft:gray_stained_glass
fill ~-20 ~10 ~7 ~-20 ~11 ~17 minecraft:light_gray_stained_glass
fill ~-31 ~14 ~7 ~-31 ~15 ~17 minecraft:gray_stained_glass
fill ~-20 ~14 ~7 ~-20 ~15 ~17 minecraft:light_gray_stained_glass
fill ~-30 ~0 ~5 ~-27 ~3 ~5 minecraft:gray_concrete
setblock ~-29 ~1 ~5 minecraft:iron_door[half=lower,facing=north]
setblock ~-29 ~2 ~5 minecraft:iron_door[half=upper,facing=north]
fill ~-31 ~17 ~5 ~-20 ~17 ~19 minecraft:stone_brick_slab
# 004 local_shop -103,112 -93,119 h=5
fill ~-103 ~-3 ~112 ~-93 ~-1 ~119 minecraft:stone
fill ~-103 ~0 ~112 ~-93 ~5 ~119 minecraft:white_terracotta
fill ~-102 ~1 ~113 ~-94 ~4 ~118 minecraft:air
fill ~-102 ~4 ~113 ~-94 ~4 ~118 minecraft:smooth_stone
fill ~-103 ~2 ~114 ~-103 ~3 ~117 minecraft:gray_stained_glass
fill ~-93 ~2 ~114 ~-93 ~3 ~117 minecraft:light_gray_stained_glass
fill ~-102 ~0 ~112 ~-99 ~3 ~112 minecraft:dark_oak_planks
setblock ~-101 ~1 ~112 minecraft:iron_door[half=lower,facing=north]
setblock ~-101 ~2 ~112 minecraft:iron_door[half=upper,facing=north]
fill ~-103 ~6 ~112 ~-93 ~6 ~119 minecraft:dark_oak_slab
# 005 shop_house -39,43 -27,54 h=8
fill ~-39 ~-3 ~43 ~-27 ~-1 ~54 minecraft:stone
fill ~-39 ~0 ~43 ~-27 ~8 ~54 minecraft:light_gray_concrete
fill ~-38 ~1 ~44 ~-28 ~7 ~53 minecraft:air
fill ~-38 ~4 ~44 ~-28 ~4 ~53 minecraft:smooth_stone
fill ~-37 ~2 ~43 ~-29 ~3 ~43 minecraft:gray_stained_glass
fill ~-37 ~2 ~54 ~-29 ~3 ~54 minecraft:light_gray_stained_glass
fill ~-37 ~6 ~43 ~-29 ~7 ~43 minecraft:gray_stained_glass
fill ~-37 ~6 ~54 ~-29 ~7 ~54 minecraft:light_gray_stained_glass
fill ~-38 ~0 ~43 ~-35 ~3 ~43 doomsday_decoration:porcelainbrickwall
setblock ~-37 ~1 ~43 minecraft:iron_door[half=lower,facing=north]
setblock ~-37 ~2 ~43 minecraft:iron_door[half=upper,facing=north]
fill ~-39 ~9 ~43 ~-27 ~9 ~54 minecraft:smooth_stone_slab
fill ~-29 ~6 ~52 ~-27 ~9 ~54 minecraft:air
setblock ~-29 ~6 ~52 minecraft:cobweb
# 006 office -101,-121 -82,-112 h=6
fill ~-101 ~-3 ~-121 ~-82 ~-1 ~-112 minecraft:stone
fill ~-101 ~0 ~-121 ~-82 ~6 ~-112 minecraft:stone_bricks
fill ~-100 ~1 ~-120 ~-83 ~5 ~-113 minecraft:air
fill ~-100 ~4 ~-120 ~-83 ~4 ~-113 minecraft:smooth_stone
fill ~-101 ~2 ~-119 ~-101 ~3 ~-114 minecraft:gray_stained_glass
fill ~-82 ~2 ~-119 ~-82 ~3 ~-114 minecraft:light_gray_stained_glass
fill ~-100 ~0 ~-121 ~-97 ~3 ~-121 doomsday_decoration:ironsheetwall_2
setblock ~-99 ~1 ~-121 minecraft:iron_door[half=lower,facing=north]
setblock ~-99 ~2 ~-121 minecraft:iron_door[half=upper,facing=north]
fill ~-101 ~7 ~-121 ~-82 ~7 ~-112 minecraft:smooth_stone_slab
# 007 clinic -41,57 -32,68 h=16
fill ~-41 ~-3 ~57 ~-32 ~-1 ~68 minecraft:stone
fill ~-41 ~0 ~57 ~-32 ~16 ~68 minecraft:light_gray_concrete
fill ~-40 ~1 ~58 ~-33 ~15 ~67 minecraft:air
fill ~-40 ~4 ~58 ~-33 ~4 ~67 minecraft:smooth_stone
fill ~-40 ~8 ~58 ~-33 ~8 ~67 minecraft:smooth_stone
fill ~-40 ~12 ~58 ~-33 ~12 ~67 minecraft:smooth_stone
fill ~-41 ~2 ~59 ~-41 ~3 ~66 minecraft:gray_stained_glass
fill ~-32 ~2 ~59 ~-32 ~3 ~66 minecraft:light_gray_stained_glass
fill ~-41 ~6 ~59 ~-41 ~7 ~66 minecraft:gray_stained_glass
fill ~-32 ~6 ~59 ~-32 ~7 ~66 minecraft:light_gray_stained_glass
fill ~-41 ~10 ~59 ~-41 ~11 ~66 minecraft:gray_stained_glass
fill ~-32 ~10 ~59 ~-32 ~11 ~66 minecraft:light_gray_stained_glass
fill ~-41 ~14 ~59 ~-41 ~15 ~66 minecraft:gray_stained_glass
fill ~-32 ~14 ~59 ~-32 ~15 ~66 minecraft:light_gray_stained_glass
fill ~-40 ~0 ~57 ~-37 ~3 ~57 doomsday_decoration:porcelainbrickwall
setblock ~-39 ~1 ~57 minecraft:iron_door[half=lower,facing=north]
setblock ~-39 ~2 ~57 minecraft:iron_door[half=upper,facing=north]
fill ~-41 ~17 ~57 ~-32 ~17 ~68 minecraft:smooth_stone_slab
# 008 community -90,115 -83,121 h=11
fill ~-90 ~-3 ~115 ~-83 ~-1 ~121 minecraft:stone
fill ~-90 ~0 ~115 ~-83 ~11 ~121 minecraft:mud_bricks
fill ~-89 ~1 ~116 ~-84 ~10 ~120 minecraft:air
fill ~-89 ~4 ~116 ~-84 ~4 ~120 minecraft:smooth_stone
fill ~-89 ~8 ~116 ~-84 ~8 ~120 minecraft:smooth_stone
fill ~-88 ~2 ~115 ~-85 ~3 ~115 minecraft:gray_stained_glass
fill ~-88 ~2 ~121 ~-85 ~3 ~121 minecraft:light_gray_stained_glass
fill ~-88 ~6 ~115 ~-85 ~7 ~115 minecraft:gray_stained_glass
fill ~-88 ~6 ~121 ~-85 ~7 ~121 minecraft:light_gray_stained_glass
fill ~-89 ~0 ~115 ~-86 ~3 ~115 minecraft:spruce_planks
setblock ~-88 ~1 ~115 minecraft:iron_door[half=lower,facing=north]
setblock ~-88 ~2 ~115 minecraft:iron_door[half=upper,facing=north]
fill ~-90 ~12 ~115 ~-83 ~12 ~121 minecraft:deepslate_tile_slab
# 009 local_shop -3,107 4,113 h=9
fill ~-3 ~-3 ~107 ~4 ~-1 ~113 minecraft:stone
fill ~-3 ~0 ~107 ~4 ~9 ~113 minecraft:mud_bricks
fill ~-2 ~1 ~108 ~3 ~8 ~112 minecraft:air
fill ~-2 ~4 ~108 ~3 ~4 ~112 minecraft:smooth_stone
fill ~-2 ~8 ~108 ~3 ~8 ~112 minecraft:smooth_stone
fill ~-3 ~2 ~109 ~-3 ~3 ~111 minecraft:gray_stained_glass
fill ~4 ~2 ~109 ~4 ~3 ~111 minecraft:light_gray_stained_glass
fill ~-3 ~6 ~109 ~-3 ~7 ~111 minecraft:gray_stained_glass
fill ~4 ~6 ~109 ~4 ~7 ~111 minecraft:light_gray_stained_glass
fill ~-2 ~0 ~107 ~1 ~3 ~107 minecraft:spruce_planks
setblock ~-1 ~1 ~107 minecraft:iron_door[half=lower,facing=north]
setblock ~-1 ~2 ~107 minecraft:iron_door[half=upper,facing=north]
fill ~-3 ~10 ~107 ~4 ~10 ~113 minecraft:deepslate_tile_slab
# 010 clinic 80,31 88,39 h=12
fill ~80 ~-3 ~31 ~88 ~-1 ~39 minecraft:stone
fill ~80 ~0 ~31 ~88 ~12 ~39 minecraft:smooth_sandstone
fill ~81 ~1 ~32 ~87 ~11 ~38 minecraft:air
fill ~81 ~4 ~32 ~87 ~4 ~38 minecraft:smooth_stone
fill ~81 ~8 ~32 ~87 ~8 ~38 minecraft:smooth_stone
fill ~82 ~2 ~31 ~86 ~3 ~31 minecraft:gray_stained_glass
fill ~82 ~2 ~39 ~86 ~3 ~39 minecraft:light_gray_stained_glass
fill ~82 ~6 ~31 ~86 ~7 ~31 minecraft:gray_stained_glass
fill ~82 ~6 ~39 ~86 ~7 ~39 minecraft:light_gray_stained_glass
fill ~82 ~10 ~31 ~86 ~11 ~31 minecraft:gray_stained_glass
fill ~82 ~10 ~39 ~86 ~11 ~39 minecraft:light_gray_stained_glass
fill ~81 ~0 ~31 ~84 ~3 ~31 minecraft:brown_terracotta
setblock ~82 ~1 ~31 minecraft:iron_door[half=lower,facing=north]
setblock ~82 ~2 ~31 minecraft:iron_door[half=upper,facing=north]
fill ~80 ~13 ~31 ~88 ~13 ~39 minecraft:stone_brick_slab
# 011 local_shop -76,95 -70,101 h=9
fill ~-76 ~-3 ~95 ~-70 ~-1 ~101 minecraft:stone
fill ~-76 ~0 ~95 ~-70 ~9 ~101 minecraft:mud_bricks
fill ~-75 ~1 ~96 ~-71 ~8 ~100 minecraft:air
fill ~-75 ~4 ~96 ~-71 ~4 ~100 minecraft:smooth_stone
fill ~-75 ~8 ~96 ~-71 ~8 ~100 minecraft:smooth_stone
fill ~-74 ~2 ~95 ~-72 ~3 ~95 minecraft:gray_stained_glass
fill ~-74 ~2 ~101 ~-72 ~3 ~101 minecraft:light_gray_stained_glass
fill ~-74 ~6 ~95 ~-72 ~7 ~95 minecraft:gray_stained_glass
fill ~-74 ~6 ~101 ~-72 ~7 ~101 minecraft:light_gray_stained_glass
fill ~-75 ~0 ~95 ~-72 ~3 ~95 minecraft:spruce_planks
setblock ~-74 ~1 ~95 minecraft:iron_door[half=lower,facing=north]
setblock ~-74 ~2 ~95 minecraft:iron_door[half=upper,facing=north]
fill ~-76 ~10 ~95 ~-70 ~10 ~101 minecraft:deepslate_tile_slab
# 012 row_house -38,108 -28,114 h=9
fill ~-38 ~-3 ~108 ~-28 ~-1 ~114 minecraft:stone
fill ~-38 ~0 ~108 ~-28 ~9 ~114 minecraft:mud_bricks
fill ~-37 ~1 ~109 ~-29 ~8 ~113 minecraft:air
fill ~-37 ~4 ~109 ~-29 ~4 ~113 minecraft:smooth_stone
fill ~-37 ~8 ~109 ~-29 ~8 ~113 minecraft:smooth_stone
fill ~-36 ~2 ~108 ~-30 ~3 ~108 minecraft:gray_stained_glass
fill ~-36 ~2 ~114 ~-30 ~3 ~114 minecraft:light_gray_stained_glass
fill ~-36 ~6 ~108 ~-30 ~7 ~108 minecraft:gray_stained_glass
fill ~-36 ~6 ~114 ~-30 ~7 ~114 minecraft:light_gray_stained_glass
fill ~-37 ~0 ~108 ~-34 ~3 ~108 minecraft:spruce_planks
setblock ~-36 ~1 ~108 minecraft:iron_door[half=lower,facing=north]
setblock ~-36 ~2 ~108 minecraft:iron_door[half=upper,facing=north]
fill ~-38 ~10 ~108 ~-28 ~10 ~114 minecraft:deepslate_tile_slab
# 013 local_shop -19,113 -13,121 h=11
fill ~-19 ~-3 ~113 ~-13 ~-1 ~121 minecraft:stone
fill ~-19 ~0 ~113 ~-13 ~11 ~121 minecraft:calcite
fill ~-18 ~1 ~114 ~-14 ~10 ~120 minecraft:air
fill ~-18 ~4 ~114 ~-14 ~4 ~120 minecraft:smooth_stone
fill ~-18 ~8 ~114 ~-14 ~8 ~120 minecraft:smooth_stone
fill ~-19 ~2 ~115 ~-19 ~3 ~119 minecraft:gray_stained_glass
fill ~-13 ~2 ~115 ~-13 ~3 ~119 minecraft:light_gray_stained_glass
fill ~-19 ~6 ~115 ~-19 ~7 ~119 minecraft:gray_stained_glass
fill ~-13 ~6 ~115 ~-13 ~7 ~119 minecraft:light_gray_stained_glass
fill ~-18 ~0 ~113 ~-15 ~3 ~113 minecraft:gray_concrete
setblock ~-17 ~1 ~113 minecraft:iron_door[half=lower,facing=north]
setblock ~-17 ~2 ~113 minecraft:iron_door[half=upper,facing=north]
fill ~-19 ~12 ~113 ~-13 ~12 ~121 minecraft:stone_brick_slab
# 014 row_house -58,91 -49,97 h=9
fill ~-58 ~-3 ~91 ~-49 ~-1 ~97 minecraft:stone
fill ~-58 ~0 ~91 ~-49 ~9 ~97 minecraft:mud_bricks
fill ~-57 ~1 ~92 ~-50 ~8 ~96 minecraft:air
fill ~-57 ~4 ~92 ~-50 ~4 ~96 minecraft:smooth_stone
fill ~-57 ~8 ~92 ~-50 ~8 ~96 minecraft:smooth_stone
fill ~-58 ~2 ~93 ~-58 ~3 ~95 minecraft:gray_stained_glass
fill ~-49 ~2 ~93 ~-49 ~3 ~95 minecraft:light_gray_stained_glass
fill ~-58 ~6 ~93 ~-58 ~7 ~95 minecraft:gray_stained_glass
fill ~-49 ~6 ~93 ~-49 ~7 ~95 minecraft:light_gray_stained_glass
fill ~-57 ~0 ~91 ~-54 ~3 ~91 minecraft:spruce_planks
setblock ~-56 ~1 ~91 minecraft:iron_door[half=lower,facing=north]
setblock ~-56 ~2 ~91 minecraft:iron_door[half=upper,facing=north]
fill ~-58 ~10 ~91 ~-49 ~10 ~97 minecraft:deepslate_tile_slab
# 015 detached_house -67,100 -57,107 h=11
fill ~-67 ~-3 ~100 ~-57 ~-1 ~107 minecraft:stone
fill ~-67 ~0 ~100 ~-57 ~11 ~107 minecraft:white_terracotta
fill ~-66 ~1 ~101 ~-58 ~10 ~106 minecraft:air
fill ~-66 ~4 ~101 ~-58 ~4 ~106 minecraft:smooth_stone
fill ~-66 ~8 ~101 ~-58 ~8 ~106 minecraft:smooth_stone
fill ~-67 ~2 ~102 ~-67 ~3 ~105 minecraft:gray_stained_glass
fill ~-57 ~2 ~102 ~-57 ~3 ~105 minecraft:light_gray_stained_glass
fill ~-67 ~6 ~102 ~-67 ~7 ~105 minecraft:gray_stained_glass
fill ~-57 ~6 ~102 ~-57 ~7 ~105 minecraft:light_gray_stained_glass
fill ~-66 ~0 ~100 ~-63 ~3 ~100 minecraft:dark_oak_planks
setblock ~-65 ~1 ~100 minecraft:iron_door[half=lower,facing=north]
setblock ~-65 ~2 ~100 minecraft:iron_door[half=upper,facing=north]
fill ~-67 ~12 ~100 ~-57 ~12 ~107 minecraft:dark_oak_slab
# 016 row_house -118,95 -113,104 h=5
fill ~-118 ~-3 ~95 ~-113 ~-1 ~104 minecraft:stone
fill ~-118 ~0 ~95 ~-113 ~5 ~104 minecraft:mud_bricks
fill ~-117 ~1 ~96 ~-114 ~4 ~103 minecraft:air
fill ~-117 ~4 ~96 ~-114 ~4 ~103 minecraft:smooth_stone
fill ~-116 ~2 ~95 ~-115 ~3 ~95 minecraft:gray_stained_glass
fill ~-116 ~2 ~104 ~-115 ~3 ~104 minecraft:light_gray_stained_glass
fill ~-117 ~0 ~95 ~-114 ~3 ~95 minecraft:spruce_planks
setblock ~-116 ~1 ~95 minecraft:iron_door[half=lower,facing=north]
setblock ~-116 ~2 ~95 minecraft:iron_door[half=upper,facing=north]
fill ~-118 ~6 ~95 ~-113 ~6 ~104 minecraft:deepslate_tile_slab
# 017 midrise_housing -48,-6 -38,9 h=12
fill ~-48 ~-3 ~-6 ~-38 ~-1 ~9 minecraft:stone
fill ~-48 ~0 ~-6 ~-38 ~12 ~9 minecraft:bricks
fill ~-47 ~1 ~-5 ~-39 ~11 ~8 minecraft:air
fill ~-47 ~4 ~-5 ~-39 ~4 ~8 minecraft:smooth_stone
fill ~-47 ~8 ~-5 ~-39 ~8 ~8 minecraft:smooth_stone
fill ~-48 ~2 ~-4 ~-48 ~3 ~7 minecraft:gray_stained_glass
fill ~-38 ~2 ~-4 ~-38 ~3 ~7 minecraft:light_gray_stained_glass
fill ~-48 ~6 ~-4 ~-48 ~7 ~7 minecraft:gray_stained_glass
fill ~-38 ~6 ~-4 ~-38 ~7 ~7 minecraft:light_gray_stained_glass
fill ~-48 ~10 ~-4 ~-48 ~11 ~7 minecraft:gray_stained_glass
fill ~-38 ~10 ~-4 ~-38 ~11 ~7 minecraft:light_gray_stained_glass
fill ~-47 ~0 ~-6 ~-44 ~3 ~-6 doomsday_decoration:redbrick
setblock ~-46 ~1 ~-6 minecraft:iron_door[half=lower,facing=north]
setblock ~-46 ~2 ~-6 minecraft:iron_door[half=upper,facing=north]
fill ~-48 ~13 ~-6 ~-38 ~13 ~9 minecraft:deepslate_tile_slab
# 018 local_shop 85,-52 92,-44 h=7
fill ~85 ~-3 ~-52 ~92 ~-1 ~-44 minecraft:stone
fill ~85 ~0 ~-52 ~92 ~7 ~-44 minecraft:calcite
fill ~86 ~1 ~-51 ~91 ~6 ~-45 minecraft:air
fill ~86 ~4 ~-51 ~91 ~4 ~-45 minecraft:smooth_stone
fill ~87 ~2 ~-52 ~90 ~3 ~-52 minecraft:gray_stained_glass
fill ~87 ~2 ~-44 ~90 ~3 ~-44 minecraft:light_gray_stained_glass
fill ~86 ~0 ~-52 ~89 ~3 ~-52 minecraft:gray_concrete
setblock ~87 ~1 ~-52 minecraft:iron_door[half=lower,facing=north]
setblock ~87 ~2 ~-52 minecraft:iron_door[half=upper,facing=north]
fill ~85 ~8 ~-52 ~92 ~8 ~-44 minecraft:stone_brick_slab
# 019 workshop -20,54 -14,67 h=16
fill ~-20 ~-3 ~54 ~-14 ~-1 ~67 minecraft:stone
fill ~-20 ~0 ~54 ~-14 ~16 ~67 minecraft:smooth_sandstone
fill ~-19 ~1 ~55 ~-15 ~15 ~66 minecraft:air
fill ~-19 ~4 ~55 ~-15 ~4 ~66 minecraft:smooth_stone
fill ~-19 ~8 ~55 ~-15 ~8 ~66 minecraft:smooth_stone
fill ~-19 ~12 ~55 ~-15 ~12 ~66 minecraft:smooth_stone
fill ~-20 ~2 ~56 ~-20 ~3 ~65 minecraft:gray_stained_glass
fill ~-14 ~2 ~56 ~-14 ~3 ~65 minecraft:light_gray_stained_glass
fill ~-20 ~6 ~56 ~-20 ~7 ~65 minecraft:gray_stained_glass
fill ~-14 ~6 ~56 ~-14 ~7 ~65 minecraft:light_gray_stained_glass
fill ~-20 ~10 ~56 ~-20 ~11 ~65 minecraft:gray_stained_glass
fill ~-14 ~10 ~56 ~-14 ~11 ~65 minecraft:light_gray_stained_glass
fill ~-20 ~14 ~56 ~-20 ~15 ~65 minecraft:gray_stained_glass
fill ~-14 ~14 ~56 ~-14 ~15 ~65 minecraft:light_gray_stained_glass
fill ~-19 ~0 ~54 ~-16 ~3 ~54 minecraft:brown_terracotta
setblock ~-18 ~1 ~54 minecraft:iron_door[half=lower,facing=north]
setblock ~-18 ~2 ~54 minecraft:iron_door[half=upper,facing=north]
fill ~-20 ~17 ~54 ~-14 ~17 ~67 minecraft:stone_brick_slab
# 020 hotel 29,1 40,13 h=24
fill ~29 ~-3 ~1 ~40 ~-1 ~13 minecraft:stone
fill ~29 ~0 ~1 ~40 ~24 ~13 minecraft:bricks
fill ~30 ~1 ~2 ~39 ~23 ~12 minecraft:air
fill ~30 ~4 ~2 ~39 ~4 ~12 minecraft:smooth_stone
fill ~30 ~8 ~2 ~39 ~8 ~12 minecraft:smooth_stone
fill ~30 ~12 ~2 ~39 ~12 ~12 minecraft:smooth_stone
fill ~30 ~16 ~2 ~39 ~16 ~12 minecraft:smooth_stone
fill ~30 ~20 ~2 ~39 ~20 ~12 minecraft:smooth_stone
fill ~31 ~2 ~1 ~38 ~3 ~1 minecraft:gray_stained_glass
fill ~31 ~2 ~13 ~38 ~3 ~13 minecraft:light_gray_stained_glass
fill ~31 ~6 ~1 ~38 ~7 ~1 minecraft:gray_stained_glass
fill ~31 ~6 ~13 ~38 ~7 ~13 minecraft:light_gray_stained_glass
fill ~31 ~10 ~1 ~38 ~11 ~1 minecraft:gray_stained_glass
fill ~31 ~10 ~13 ~38 ~11 ~13 minecraft:light_gray_stained_glass
fill ~31 ~14 ~1 ~38 ~15 ~1 minecraft:gray_stained_glass
fill ~31 ~14 ~13 ~38 ~15 ~13 minecraft:light_gray_stained_glass
fill ~31 ~18 ~1 ~38 ~19 ~1 minecraft:gray_stained_glass
fill ~31 ~18 ~13 ~38 ~19 ~13 minecraft:light_gray_stained_glass
fill ~31 ~22 ~1 ~38 ~23 ~1 minecraft:gray_stained_glass
fill ~31 ~22 ~13 ~38 ~23 ~13 minecraft:light_gray_stained_glass
fill ~30 ~0 ~1 ~33 ~3 ~1 doomsday_decoration:redbrick
setblock ~31 ~1 ~1 minecraft:iron_door[half=lower,facing=north]
setblock ~31 ~2 ~1 minecraft:iron_door[half=upper,facing=north]
fill ~29 ~25 ~1 ~40 ~25 ~13 minecraft:deepslate_tile_slab
# 021 restaurant -83,30 -74,40 h=12
fill ~-83 ~-3 ~30 ~-74 ~-1 ~40 minecraft:stone
fill ~-83 ~0 ~30 ~-74 ~12 ~40 minecraft:smooth_sandstone
fill ~-82 ~1 ~31 ~-75 ~11 ~39 minecraft:air
fill ~-82 ~4 ~31 ~-75 ~4 ~39 minecraft:smooth_stone
fill ~-82 ~8 ~31 ~-75 ~8 ~39 minecraft:smooth_stone
fill ~-81 ~2 ~30 ~-76 ~3 ~30 minecraft:gray_stained_glass
fill ~-81 ~2 ~40 ~-76 ~3 ~40 minecraft:light_gray_stained_glass
fill ~-81 ~6 ~30 ~-76 ~7 ~30 minecraft:gray_stained_glass
fill ~-81 ~6 ~40 ~-76 ~7 ~40 minecraft:light_gray_stained_glass
fill ~-81 ~10 ~30 ~-76 ~11 ~30 minecraft:gray_stained_glass
fill ~-81 ~10 ~40 ~-76 ~11 ~40 minecraft:light_gray_stained_glass
fill ~-82 ~0 ~30 ~-79 ~3 ~30 minecraft:brown_terracotta
setblock ~-81 ~1 ~30 minecraft:iron_door[half=lower,facing=north]
setblock ~-81 ~2 ~30 minecraft:iron_door[half=upper,facing=north]
fill ~-83 ~13 ~30 ~-74 ~13 ~40 minecraft:stone_brick_slab
# 022 lowrise_housing -10,61 2,70 h=16
fill ~-10 ~-3 ~61 ~2 ~-1 ~70 minecraft:stone
fill ~-10 ~0 ~61 ~2 ~16 ~70 minecraft:light_gray_concrete
fill ~-9 ~1 ~62 ~1 ~15 ~69 minecraft:air
fill ~-9 ~4 ~62 ~1 ~4 ~69 minecraft:smooth_stone
fill ~-9 ~8 ~62 ~1 ~8 ~69 minecraft:smooth_stone
fill ~-9 ~12 ~62 ~1 ~12 ~69 minecraft:smooth_stone
fill ~-8 ~2 ~61 ~0 ~3 ~61 minecraft:gray_stained_glass
fill ~-8 ~2 ~70 ~0 ~3 ~70 minecraft:light_gray_stained_glass
fill ~-8 ~6 ~61 ~0 ~7 ~61 minecraft:gray_stained_glass
fill ~-8 ~6 ~70 ~0 ~7 ~70 minecraft:light_gray_stained_glass
fill ~-8 ~10 ~61 ~0 ~11 ~61 minecraft:gray_stained_glass
fill ~-8 ~10 ~70 ~0 ~11 ~70 minecraft:light_gray_stained_glass
fill ~-8 ~14 ~61 ~0 ~15 ~61 minecraft:gray_stained_glass
fill ~-8 ~14 ~70 ~0 ~15 ~70 minecraft:light_gray_stained_glass
fill ~-9 ~0 ~61 ~-6 ~3 ~61 doomsday_decoration:porcelainbrickwall
setblock ~-8 ~1 ~61 minecraft:iron_door[half=lower,facing=north]
setblock ~-8 ~2 ~61 minecraft:iron_door[half=upper,facing=north]
fill ~-10 ~17 ~61 ~2 ~17 ~70 minecraft:smooth_stone_slab
# 023 restaurant -76,-7 -65,5 h=8
fill ~-76 ~-3 ~-7 ~-65 ~-1 ~5 minecraft:stone
fill ~-76 ~0 ~-7 ~-65 ~8 ~5 minecraft:bricks
fill ~-75 ~1 ~-6 ~-66 ~7 ~4 minecraft:air
fill ~-75 ~4 ~-6 ~-66 ~4 ~4 minecraft:smooth_stone
fill ~-74 ~2 ~-7 ~-67 ~3 ~-7 minecraft:gray_stained_glass
fill ~-74 ~2 ~5 ~-67 ~3 ~5 minecraft:light_gray_stained_glass
fill ~-74 ~6 ~-7 ~-67 ~7 ~-7 minecraft:gray_stained_glass
fill ~-74 ~6 ~5 ~-67 ~7 ~5 minecraft:light_gray_stained_glass
fill ~-75 ~0 ~-7 ~-72 ~3 ~-7 doomsday_decoration:hollowbrick
setblock ~-74 ~1 ~-7 minecraft:iron_door[half=lower,facing=north]
setblock ~-74 ~2 ~-7 minecraft:iron_door[half=upper,facing=north]
fill ~-76 ~9 ~-7 ~-65 ~9 ~5 minecraft:deepslate_tile_slab
# 024 workshop 57,32 66,47 h=16
fill ~57 ~-3 ~32 ~66 ~-1 ~47 minecraft:stone
fill ~57 ~0 ~32 ~66 ~16 ~47 minecraft:bricks
fill ~58 ~1 ~33 ~65 ~15 ~46 minecraft:air
fill ~58 ~4 ~33 ~65 ~4 ~46 minecraft:smooth_stone
fill ~58 ~8 ~33 ~65 ~8 ~46 minecraft:smooth_stone
fill ~58 ~12 ~33 ~65 ~12 ~46 minecraft:smooth_stone
fill ~57 ~2 ~34 ~57 ~3 ~45 minecraft:gray_stained_glass
fill ~66 ~2 ~34 ~66 ~3 ~45 minecraft:light_gray_stained_glass
fill ~57 ~6 ~34 ~57 ~7 ~45 minecraft:gray_stained_glass
fill ~66 ~6 ~34 ~66 ~7 ~45 minecraft:light_gray_stained_glass
fill ~57 ~10 ~34 ~57 ~11 ~45 minecraft:gray_stained_glass
fill ~66 ~10 ~34 ~66 ~11 ~45 minecraft:light_gray_stained_glass
fill ~57 ~14 ~34 ~57 ~15 ~45 minecraft:gray_stained_glass
fill ~66 ~14 ~34 ~66 ~15 ~45 minecraft:light_gray_stained_glass
fill ~58 ~0 ~32 ~61 ~3 ~32 doomsday_decoration:hollowbrick
setblock ~59 ~1 ~32 minecraft:iron_door[half=lower,facing=north]
setblock ~59 ~2 ~32 minecraft:iron_door[half=upper,facing=north]
fill ~57 ~17 ~32 ~66 ~17 ~47 minecraft:deepslate_tile_slab
fill ~64 ~14 ~45 ~66 ~17 ~47 minecraft:air
setblock ~64 ~14 ~45 minecraft:cobweb
# 025 community -85,98 -77,105 h=7
fill ~-85 ~-3 ~98 ~-77 ~-1 ~105 minecraft:stone
fill ~-85 ~0 ~98 ~-77 ~7 ~105 minecraft:mud_bricks
fill ~-84 ~1 ~99 ~-78 ~6 ~104 minecraft:air
fill ~-84 ~4 ~99 ~-78 ~4 ~104 minecraft:smooth_stone
fill ~-83 ~2 ~98 ~-79 ~3 ~98 minecraft:gray_stained_glass
fill ~-83 ~2 ~105 ~-79 ~3 ~105 minecraft:light_gray_stained_glass
fill ~-84 ~0 ~98 ~-81 ~3 ~98 minecraft:spruce_planks
setblock ~-83 ~1 ~98 minecraft:iron_door[half=lower,facing=north]
setblock ~-83 ~2 ~98 minecraft:iron_door[half=upper,facing=north]
fill ~-85 ~8 ~98 ~-77 ~8 ~105 minecraft:deepslate_tile_slab
