# Buildings 209..216
# 209 detached_house style=rowhouse context=local_front facing=east
fill ~-63 ~-3 ~46 ~-59 ~-1 ~54 minecraft:stone
fill ~-63 ~0 ~46 ~-59 ~5 ~54 minecraft:smooth_sandstone
fill ~-62 ~1 ~47 ~-60 ~4 ~53 minecraft:air
fill ~-62 ~4 ~47 ~-60 ~4 ~53 minecraft:smooth_stone
fill ~-61 ~2 ~46 ~-61 ~3 ~46 minecraft:gray_stained_glass
fill ~-61 ~2 ~54 ~-61 ~3 ~54 minecraft:light_gray_stained_glass
fill ~-63 ~2 ~48 ~-63 ~3 ~48 minecraft:gray_stained_glass
fill ~-59 ~2 ~48 ~-59 ~3 ~48 minecraft:light_gray_stained_glass
fill ~-63 ~2 ~51 ~-63 ~3 ~51 minecraft:gray_stained_glass
fill ~-59 ~2 ~51 ~-59 ~3 ~51 minecraft:light_gray_stained_glass
setblock ~-59 ~1 ~50 minecraft:iron_door[half=lower,facing=east]
setblock ~-59 ~2 ~50 minecraft:iron_door[half=upper,facing=east]
fill ~-63 ~6 ~46 ~-59 ~6 ~54 minecraft:stone_brick_slab
fill ~-62 ~7 ~47 ~-60 ~7 ~53 minecraft:stone_brick_slab
setblock ~-58 ~3 ~50 minecraft:dark_oak_slab[type=top]
# 210 workshop style=loading_bay context=back_block facing=south
fill ~-37 ~-3 ~3 ~-33 ~-1 ~11 minecraft:stone
fill ~-37 ~0 ~3 ~-33 ~10 ~11 minecraft:bricks
fill ~-36 ~1 ~4 ~-34 ~9 ~10 minecraft:air
fill ~-36 ~4 ~4 ~-34 ~4 ~10 minecraft:smooth_stone
fill ~-36 ~8 ~4 ~-34 ~8 ~10 minecraft:smooth_stone
fill ~-35 ~2 ~3 ~-35 ~3 ~3 minecraft:gray_stained_glass
fill ~-35 ~2 ~11 ~-35 ~3 ~11 minecraft:light_gray_stained_glass
fill ~-37 ~2 ~5 ~-37 ~3 ~5 minecraft:gray_stained_glass
fill ~-33 ~2 ~5 ~-33 ~3 ~5 minecraft:light_gray_stained_glass
fill ~-37 ~2 ~8 ~-37 ~3 ~8 minecraft:gray_stained_glass
fill ~-33 ~2 ~8 ~-33 ~3 ~8 minecraft:light_gray_stained_glass
fill ~-35 ~6 ~3 ~-35 ~7 ~3 minecraft:gray_stained_glass
fill ~-35 ~6 ~11 ~-35 ~7 ~11 minecraft:light_gray_stained_glass
fill ~-37 ~6 ~5 ~-37 ~7 ~5 minecraft:gray_stained_glass
fill ~-33 ~6 ~5 ~-33 ~7 ~5 minecraft:light_gray_stained_glass
fill ~-37 ~6 ~8 ~-37 ~7 ~8 minecraft:gray_stained_glass
fill ~-33 ~6 ~8 ~-33 ~7 ~8 minecraft:light_gray_stained_glass
setblock ~-35 ~1 ~11 minecraft:iron_door[half=lower,facing=south]
setblock ~-35 ~2 ~11 minecraft:iron_door[half=upper,facing=south]
fill ~-35 ~1 ~11 ~-35 ~4 ~11 minecraft:polished_blackstone
fill ~-35 ~5 ~11 ~-35 ~5 ~11 minecraft:light_blue_stained_glass
fill ~-35 ~12 ~5 ~-34 ~13 ~7 minecraft:iron_block
fill ~-37 ~11 ~3 ~-33 ~11 ~11 minecraft:deepslate_tile_slab
fill ~-35 ~12 ~5 ~-34 ~13 ~7 minecraft:light_gray_concrete
setblock ~-34 ~12 ~6 minecraft:lightning_rod
# 211 office style=civic_modern context=arterial_front facing=east
fill ~-17 ~-3 ~1 ~-13 ~-1 ~10 minecraft:stone
fill ~-17 ~0 ~1 ~-13 ~10 ~10 minecraft:light_gray_concrete
fill ~-16 ~1 ~2 ~-14 ~9 ~9 minecraft:air
fill ~-16 ~4 ~2 ~-14 ~4 ~9 minecraft:smooth_stone
fill ~-16 ~8 ~2 ~-14 ~8 ~9 minecraft:smooth_stone
fill ~-15 ~2 ~1 ~-15 ~3 ~1 minecraft:gray_stained_glass
fill ~-15 ~2 ~10 ~-15 ~3 ~10 minecraft:light_gray_stained_glass
fill ~-17 ~2 ~3 ~-17 ~3 ~3 minecraft:gray_stained_glass
fill ~-13 ~2 ~3 ~-13 ~3 ~3 minecraft:light_gray_stained_glass
fill ~-17 ~2 ~6 ~-17 ~3 ~6 minecraft:gray_stained_glass
fill ~-13 ~2 ~6 ~-13 ~3 ~6 minecraft:light_gray_stained_glass
fill ~-15 ~6 ~1 ~-15 ~7 ~1 minecraft:gray_stained_glass
fill ~-15 ~6 ~10 ~-15 ~7 ~10 minecraft:light_gray_stained_glass
fill ~-17 ~6 ~3 ~-17 ~7 ~3 minecraft:gray_stained_glass
fill ~-13 ~6 ~3 ~-13 ~7 ~3 minecraft:light_gray_stained_glass
fill ~-17 ~6 ~6 ~-17 ~7 ~6 minecraft:gray_stained_glass
fill ~-13 ~6 ~6 ~-13 ~7 ~6 minecraft:light_gray_stained_glass
setblock ~-13 ~1 ~5 minecraft:iron_door[half=lower,facing=east]
setblock ~-13 ~2 ~5 minecraft:iron_door[half=upper,facing=east]
fill ~-17 ~7 ~1 ~-13 ~10 ~10 minecraft:air
fill ~-16 ~7 ~2 ~-14 ~10 ~9 minecraft:light_gray_concrete
fill ~-15 ~8 ~3 ~-15 ~9 ~8 minecraft:air
fill ~-16 ~11 ~2 ~-14 ~11 ~9 minecraft:smooth_stone_slab
# 212 shop_house style=storefront context=collector_front facing=west
fill ~-81 ~-3 ~-7 ~-77 ~-1 ~-2 minecraft:stone
fill ~-81 ~0 ~-7 ~-77 ~7 ~-2 minecraft:smooth_sandstone
fill ~-80 ~1 ~-6 ~-78 ~6 ~-3 minecraft:air
fill ~-80 ~4 ~-6 ~-78 ~4 ~-3 minecraft:smooth_stone
fill ~-79 ~2 ~-7 ~-79 ~3 ~-7 minecraft:gray_stained_glass
fill ~-79 ~2 ~-2 ~-79 ~3 ~-2 minecraft:light_gray_stained_glass
fill ~-81 ~2 ~-5 ~-81 ~3 ~-5 minecraft:gray_stained_glass
fill ~-77 ~2 ~-5 ~-77 ~3 ~-5 minecraft:light_gray_stained_glass
setblock ~-81 ~1 ~-5 minecraft:iron_door[half=lower,facing=west]
setblock ~-81 ~2 ~-5 minecraft:iron_door[half=upper,facing=west]
fill ~-81 ~1 ~-6 ~-81 ~3 ~-3 minecraft:cyan_stained_glass
setblock ~-81 ~1 ~-5 minecraft:iron_door[half=lower,facing=west]
setblock ~-81 ~2 ~-5 minecraft:iron_door[half=upper,facing=west]
setblock ~-82 ~3 ~-5 minecraft:red_wool
fill ~-81 ~8 ~-7 ~-77 ~8 ~-2 minecraft:stone_brick_slab
# 213 mixed_use style=balcony_block context=arterial_front facing=south
fill ~48 ~-3 ~-23 ~53 ~-1 ~-15 minecraft:stone
fill ~48 ~0 ~-23 ~53 ~7 ~-15 minecraft:light_gray_concrete
fill ~49 ~1 ~-22 ~52 ~6 ~-16 minecraft:air
fill ~49 ~4 ~-22 ~52 ~4 ~-16 minecraft:smooth_stone
fill ~50 ~2 ~-23 ~50 ~3 ~-23 minecraft:gray_stained_glass
fill ~50 ~2 ~-15 ~50 ~3 ~-15 minecraft:light_gray_stained_glass
fill ~48 ~2 ~-21 ~48 ~3 ~-21 minecraft:gray_stained_glass
fill ~53 ~2 ~-21 ~53 ~3 ~-21 minecraft:light_gray_stained_glass
fill ~48 ~2 ~-18 ~48 ~3 ~-18 minecraft:gray_stained_glass
fill ~53 ~2 ~-18 ~53 ~3 ~-18 minecraft:light_gray_stained_glass
setblock ~50 ~1 ~-15 minecraft:iron_door[half=lower,facing=south]
setblock ~50 ~2 ~-15 minecraft:iron_door[half=upper,facing=south]
fill ~50 ~4 ~-14 ~51 ~4 ~-14 minecraft:smooth_stone_slab
fill ~48 ~8 ~-23 ~53 ~8 ~-15 minecraft:smooth_stone_slab
# 214 midrise_housing style=setback_block context=collector_front facing=south
fill ~-25 ~-3 ~75 ~-20 ~-1 ~82 minecraft:stone
fill ~-25 ~0 ~75 ~-20 ~5 ~82 minecraft:light_gray_concrete
fill ~-24 ~1 ~76 ~-21 ~4 ~81 minecraft:air
fill ~-24 ~4 ~76 ~-21 ~4 ~81 minecraft:smooth_stone
fill ~-23 ~2 ~75 ~-23 ~3 ~75 minecraft:gray_stained_glass
fill ~-23 ~2 ~82 ~-23 ~3 ~82 minecraft:light_gray_stained_glass
fill ~-25 ~2 ~77 ~-25 ~3 ~77 minecraft:gray_stained_glass
fill ~-20 ~2 ~77 ~-20 ~3 ~77 minecraft:light_gray_stained_glass
fill ~-25 ~2 ~80 ~-25 ~3 ~80 minecraft:gray_stained_glass
fill ~-20 ~2 ~80 ~-20 ~3 ~80 minecraft:light_gray_stained_glass
setblock ~-23 ~1 ~82 minecraft:iron_door[half=lower,facing=south]
setblock ~-23 ~2 ~82 minecraft:iron_door[half=upper,facing=south]
# 215 restaurant style=arcade_shop context=collector_front facing=south
fill ~-39 ~-3 ~12 ~-35 ~-1 ~17 minecraft:stone
fill ~-39 ~0 ~12 ~-35 ~20 ~17 minecraft:bricks
fill ~-38 ~1 ~13 ~-36 ~19 ~16 minecraft:air
fill ~-38 ~4 ~13 ~-36 ~4 ~16 minecraft:smooth_stone
fill ~-38 ~8 ~13 ~-36 ~8 ~16 minecraft:smooth_stone
fill ~-38 ~12 ~13 ~-36 ~12 ~16 minecraft:smooth_stone
fill ~-38 ~16 ~13 ~-36 ~16 ~16 minecraft:smooth_stone
fill ~-37 ~2 ~12 ~-37 ~3 ~12 minecraft:gray_stained_glass
fill ~-37 ~2 ~17 ~-37 ~3 ~17 minecraft:light_gray_stained_glass
fill ~-39 ~2 ~14 ~-39 ~3 ~14 minecraft:gray_stained_glass
fill ~-35 ~2 ~14 ~-35 ~3 ~14 minecraft:light_gray_stained_glass
fill ~-37 ~6 ~12 ~-37 ~7 ~12 minecraft:gray_stained_glass
fill ~-37 ~6 ~17 ~-37 ~7 ~17 minecraft:light_gray_stained_glass
fill ~-39 ~6 ~14 ~-39 ~7 ~14 minecraft:gray_stained_glass
fill ~-35 ~6 ~14 ~-35 ~7 ~14 minecraft:light_gray_stained_glass
fill ~-37 ~10 ~12 ~-37 ~11 ~12 minecraft:gray_stained_glass
fill ~-37 ~10 ~17 ~-37 ~11 ~17 minecraft:light_gray_stained_glass
fill ~-39 ~10 ~14 ~-39 ~11 ~14 minecraft:gray_stained_glass
fill ~-35 ~10 ~14 ~-35 ~11 ~14 minecraft:light_gray_stained_glass
fill ~-37 ~14 ~12 ~-37 ~15 ~12 minecraft:gray_stained_glass
fill ~-37 ~14 ~17 ~-37 ~15 ~17 minecraft:light_gray_stained_glass
fill ~-39 ~14 ~14 ~-39 ~15 ~14 minecraft:gray_stained_glass
fill ~-35 ~14 ~14 ~-35 ~15 ~14 minecraft:light_gray_stained_glass
fill ~-37 ~18 ~12 ~-37 ~19 ~12 minecraft:gray_stained_glass
fill ~-37 ~18 ~17 ~-37 ~19 ~17 minecraft:light_gray_stained_glass
fill ~-39 ~18 ~14 ~-39 ~19 ~14 minecraft:gray_stained_glass
fill ~-35 ~18 ~14 ~-35 ~19 ~14 minecraft:light_gray_stained_glass
setblock ~-37 ~1 ~17 minecraft:iron_door[half=lower,facing=south]
setblock ~-37 ~2 ~17 minecraft:iron_door[half=upper,facing=south]
fill ~-38 ~1 ~17 ~-36 ~3 ~17 minecraft:cyan_stained_glass
setblock ~-37 ~1 ~17 minecraft:iron_door[half=lower,facing=south]
setblock ~-37 ~2 ~17 minecraft:iron_door[half=upper,facing=south]
setblock ~-37 ~3 ~18 minecraft:red_wool
fill ~-38 ~4 ~17 ~-36 ~4 ~17 doomsday_decoration:redbrick
fill ~-39 ~21 ~12 ~-35 ~21 ~17 minecraft:deepslate_tile_slab
# 216 row_house style=stepped_house context=back_block facing=south
fill ~-114 ~-3 ~-58 ~-110 ~-1 ~-50 minecraft:stone
fill ~-114 ~0 ~-58 ~-110 ~5 ~-50 minecraft:white_terracotta
fill ~-113 ~1 ~-57 ~-111 ~4 ~-51 minecraft:air
fill ~-113 ~4 ~-57 ~-111 ~4 ~-51 minecraft:smooth_stone
fill ~-112 ~2 ~-58 ~-112 ~3 ~-58 minecraft:gray_stained_glass
fill ~-112 ~2 ~-50 ~-112 ~3 ~-50 minecraft:light_gray_stained_glass
fill ~-114 ~2 ~-56 ~-114 ~3 ~-56 minecraft:gray_stained_glass
fill ~-110 ~2 ~-56 ~-110 ~3 ~-56 minecraft:light_gray_stained_glass
fill ~-114 ~2 ~-53 ~-114 ~3 ~-53 minecraft:gray_stained_glass
fill ~-110 ~2 ~-53 ~-110 ~3 ~-53 minecraft:light_gray_stained_glass
setblock ~-112 ~1 ~-50 minecraft:iron_door[half=lower,facing=south]
setblock ~-112 ~2 ~-50 minecraft:iron_door[half=upper,facing=south]
fill ~-114 ~6 ~-58 ~-110 ~6 ~-50 minecraft:dark_oak_slab
fill ~-113 ~7 ~-57 ~-111 ~7 ~-51 minecraft:dark_oak_slab
setblock ~-112 ~3 ~-49 minecraft:dark_oak_slab[type=top]
