# Buildings 121..128
# 121 local_shop style=corner_store context=local_front facing=north
fill ~-126 ~-3 ~89 ~-119 ~-1 ~101 minecraft:stone
fill ~-126 ~0 ~89 ~-119 ~7 ~101 minecraft:mud_bricks
fill ~-125 ~1 ~90 ~-120 ~6 ~100 minecraft:air
fill ~-125 ~4 ~90 ~-120 ~4 ~100 minecraft:smooth_stone
fill ~-124 ~2 ~89 ~-124 ~3 ~89 minecraft:gray_stained_glass
fill ~-124 ~2 ~101 ~-124 ~3 ~101 minecraft:light_gray_stained_glass
fill ~-121 ~2 ~89 ~-121 ~3 ~89 minecraft:gray_stained_glass
fill ~-121 ~2 ~101 ~-121 ~3 ~101 minecraft:light_gray_stained_glass
fill ~-126 ~2 ~91 ~-126 ~3 ~91 minecraft:gray_stained_glass
fill ~-119 ~2 ~91 ~-119 ~3 ~91 minecraft:light_gray_stained_glass
fill ~-126 ~2 ~94 ~-126 ~3 ~94 minecraft:gray_stained_glass
fill ~-119 ~2 ~94 ~-119 ~3 ~94 minecraft:light_gray_stained_glass
fill ~-126 ~2 ~97 ~-126 ~3 ~97 minecraft:gray_stained_glass
fill ~-119 ~2 ~97 ~-119 ~3 ~97 minecraft:light_gray_stained_glass
setblock ~-123 ~1 ~89 minecraft:iron_door[half=lower,facing=north]
setblock ~-123 ~2 ~89 minecraft:iron_door[half=upper,facing=north]
fill ~-125 ~1 ~89 ~-120 ~3 ~89 minecraft:cyan_stained_glass
setblock ~-123 ~1 ~89 minecraft:iron_door[half=lower,facing=north]
setblock ~-123 ~2 ~89 minecraft:iron_door[half=upper,facing=north]
setblock ~-123 ~3 ~88 minecraft:red_wool
fill ~-126 ~8 ~89 ~-119 ~8 ~101 minecraft:deepslate_tile_slab
fill ~-125 ~1 ~89 ~-125 ~7 ~89 minecraft:spruce_planks
fill ~-121 ~1 ~89 ~-121 ~7 ~89 minecraft:spruce_planks
setblock ~-124 ~3 ~89 minecraft:red_carpet
# 122 lowrise_housing style=stepped_house context=local_front facing=north
fill ~-100 ~-3 ~89 ~-96 ~-1 ~95 minecraft:stone
fill ~-100 ~0 ~89 ~-96 ~11 ~95 minecraft:mud_bricks
fill ~-99 ~1 ~90 ~-97 ~10 ~94 minecraft:air
fill ~-99 ~4 ~90 ~-97 ~4 ~94 minecraft:smooth_stone
fill ~-99 ~8 ~90 ~-97 ~8 ~94 minecraft:smooth_stone
fill ~-98 ~2 ~89 ~-98 ~3 ~89 minecraft:gray_stained_glass
fill ~-98 ~2 ~95 ~-98 ~3 ~95 minecraft:light_gray_stained_glass
fill ~-100 ~2 ~91 ~-100 ~3 ~91 minecraft:gray_stained_glass
fill ~-96 ~2 ~91 ~-96 ~3 ~91 minecraft:light_gray_stained_glass
fill ~-98 ~6 ~89 ~-98 ~7 ~89 minecraft:gray_stained_glass
fill ~-98 ~6 ~95 ~-98 ~7 ~95 minecraft:light_gray_stained_glass
fill ~-100 ~6 ~91 ~-100 ~7 ~91 minecraft:gray_stained_glass
fill ~-96 ~6 ~91 ~-96 ~7 ~91 minecraft:light_gray_stained_glass
setblock ~-98 ~1 ~89 minecraft:iron_door[half=lower,facing=north]
setblock ~-98 ~2 ~89 minecraft:iron_door[half=upper,facing=north]
fill ~-100 ~12 ~89 ~-96 ~12 ~95 minecraft:deepslate_tile_slab
fill ~-99 ~13 ~90 ~-97 ~13 ~94 minecraft:deepslate_tile_slab
setblock ~-98 ~3 ~88 minecraft:dark_oak_slab[type=top]
# 123 midrise_housing style=setback_block context=collector_front facing=east
fill ~-108 ~-3 ~30 ~-101 ~-1 ~36 minecraft:stone
fill ~-108 ~0 ~30 ~-101 ~5 ~36 minecraft:white_terracotta
fill ~-107 ~1 ~31 ~-102 ~4 ~35 minecraft:air
fill ~-107 ~4 ~31 ~-102 ~4 ~35 minecraft:smooth_stone
fill ~-106 ~2 ~30 ~-106 ~3 ~30 minecraft:gray_stained_glass
fill ~-106 ~2 ~36 ~-106 ~3 ~36 minecraft:light_gray_stained_glass
fill ~-103 ~2 ~30 ~-103 ~3 ~30 minecraft:gray_stained_glass
fill ~-103 ~2 ~36 ~-103 ~3 ~36 minecraft:light_gray_stained_glass
fill ~-108 ~2 ~32 ~-108 ~3 ~32 minecraft:gray_stained_glass
fill ~-101 ~2 ~32 ~-101 ~3 ~32 minecraft:light_gray_stained_glass
setblock ~-101 ~1 ~33 minecraft:iron_door[half=lower,facing=east]
setblock ~-101 ~2 ~33 minecraft:iron_door[half=upper,facing=east]
fill ~-101 ~1 ~31 ~-101 ~5 ~31 minecraft:dark_oak_planks
fill ~-101 ~1 ~35 ~-101 ~5 ~35 minecraft:dark_oak_planks
# 124 community style=balcony_block context=collector_front facing=north
fill ~-63 ~-3 ~-82 ~-56 ~-1 ~-70 minecraft:stone
fill ~-63 ~0 ~-82 ~-56 ~16 ~-70 minecraft:bricks
fill ~-62 ~1 ~-81 ~-57 ~15 ~-71 minecraft:air
fill ~-62 ~4 ~-81 ~-57 ~4 ~-71 minecraft:smooth_stone
fill ~-62 ~8 ~-81 ~-57 ~8 ~-71 minecraft:smooth_stone
fill ~-62 ~12 ~-81 ~-57 ~12 ~-71 minecraft:smooth_stone
fill ~-61 ~2 ~-82 ~-61 ~3 ~-82 minecraft:gray_stained_glass
fill ~-61 ~2 ~-70 ~-61 ~3 ~-70 minecraft:light_gray_stained_glass
fill ~-58 ~2 ~-82 ~-58 ~3 ~-82 minecraft:gray_stained_glass
fill ~-58 ~2 ~-70 ~-58 ~3 ~-70 minecraft:light_gray_stained_glass
fill ~-63 ~2 ~-80 ~-63 ~3 ~-80 minecraft:gray_stained_glass
fill ~-56 ~2 ~-80 ~-56 ~3 ~-80 minecraft:light_gray_stained_glass
fill ~-63 ~2 ~-77 ~-63 ~3 ~-77 minecraft:gray_stained_glass
fill ~-56 ~2 ~-77 ~-56 ~3 ~-77 minecraft:light_gray_stained_glass
fill ~-63 ~2 ~-74 ~-63 ~3 ~-74 minecraft:gray_stained_glass
fill ~-56 ~2 ~-74 ~-56 ~3 ~-74 minecraft:light_gray_stained_glass
fill ~-61 ~6 ~-82 ~-61 ~7 ~-82 minecraft:gray_stained_glass
fill ~-61 ~6 ~-70 ~-61 ~7 ~-70 minecraft:light_gray_stained_glass
fill ~-58 ~6 ~-82 ~-58 ~7 ~-82 minecraft:gray_stained_glass
fill ~-58 ~6 ~-70 ~-58 ~7 ~-70 minecraft:light_gray_stained_glass
fill ~-63 ~6 ~-80 ~-63 ~7 ~-80 minecraft:gray_stained_glass
fill ~-56 ~6 ~-80 ~-56 ~7 ~-80 minecraft:light_gray_stained_glass
fill ~-63 ~6 ~-77 ~-63 ~7 ~-77 minecraft:gray_stained_glass
fill ~-56 ~6 ~-77 ~-56 ~7 ~-77 minecraft:light_gray_stained_glass
fill ~-63 ~6 ~-74 ~-63 ~7 ~-74 minecraft:gray_stained_glass
fill ~-56 ~6 ~-74 ~-56 ~7 ~-74 minecraft:light_gray_stained_glass
fill ~-61 ~10 ~-82 ~-61 ~11 ~-82 minecraft:gray_stained_glass
fill ~-61 ~10 ~-70 ~-61 ~11 ~-70 minecraft:light_gray_stained_glass
fill ~-58 ~10 ~-82 ~-58 ~11 ~-82 minecraft:gray_stained_glass
fill ~-58 ~10 ~-70 ~-58 ~11 ~-70 minecraft:light_gray_stained_glass
fill ~-63 ~10 ~-80 ~-63 ~11 ~-80 minecraft:gray_stained_glass
fill ~-56 ~10 ~-80 ~-56 ~11 ~-80 minecraft:light_gray_stained_glass
fill ~-63 ~10 ~-77 ~-63 ~11 ~-77 minecraft:gray_stained_glass
fill ~-56 ~10 ~-77 ~-56 ~11 ~-77 minecraft:light_gray_stained_glass
fill ~-63 ~10 ~-74 ~-63 ~11 ~-74 minecraft:gray_stained_glass
fill ~-56 ~10 ~-74 ~-56 ~11 ~-74 minecraft:light_gray_stained_glass
fill ~-61 ~14 ~-82 ~-61 ~15 ~-82 minecraft:gray_stained_glass
fill ~-61 ~14 ~-70 ~-61 ~15 ~-70 minecraft:light_gray_stained_glass
fill ~-58 ~14 ~-82 ~-58 ~15 ~-82 minecraft:gray_stained_glass
fill ~-58 ~14 ~-70 ~-58 ~15 ~-70 minecraft:light_gray_stained_glass
fill ~-63 ~14 ~-80 ~-63 ~15 ~-80 minecraft:gray_stained_glass
fill ~-56 ~14 ~-80 ~-56 ~15 ~-80 minecraft:light_gray_stained_glass
fill ~-63 ~14 ~-77 ~-63 ~15 ~-77 minecraft:gray_stained_glass
fill ~-56 ~14 ~-77 ~-56 ~15 ~-77 minecraft:light_gray_stained_glass
fill ~-63 ~14 ~-74 ~-63 ~15 ~-74 minecraft:gray_stained_glass
fill ~-56 ~14 ~-74 ~-56 ~15 ~-74 minecraft:light_gray_stained_glass
setblock ~-60 ~1 ~-82 minecraft:iron_door[half=lower,facing=north]
setblock ~-60 ~2 ~-82 minecraft:iron_door[half=upper,facing=north]
fill ~-61 ~4 ~-83 ~-58 ~4 ~-83 minecraft:smooth_stone_slab
fill ~-61 ~8 ~-83 ~-58 ~8 ~-83 minecraft:smooth_stone_slab
fill ~-61 ~12 ~-83 ~-58 ~12 ~-83 minecraft:smooth_stone_slab
fill ~-63 ~17 ~-82 ~-56 ~17 ~-70 minecraft:deepslate_tile_slab
fill ~-62 ~1 ~-82 ~-62 ~7 ~-82 doomsday_decoration:hollowbrick
fill ~-58 ~1 ~-82 ~-58 ~7 ~-82 doomsday_decoration:hollowbrick
# 125 hotel style=bay_office context=arterial_front facing=north
fill ~-124 ~-3 ~6 ~-114 ~-1 ~15 minecraft:stone
fill ~-124 ~0 ~6 ~-114 ~11 ~15 minecraft:mud_bricks
fill ~-123 ~1 ~7 ~-115 ~10 ~14 minecraft:air
fill ~-123 ~4 ~7 ~-115 ~4 ~14 minecraft:smooth_stone
fill ~-123 ~8 ~7 ~-115 ~8 ~14 minecraft:smooth_stone
fill ~-122 ~2 ~6 ~-122 ~3 ~6 minecraft:gray_stained_glass
fill ~-122 ~2 ~15 ~-122 ~3 ~15 minecraft:light_gray_stained_glass
fill ~-119 ~2 ~6 ~-119 ~3 ~6 minecraft:gray_stained_glass
fill ~-119 ~2 ~15 ~-119 ~3 ~15 minecraft:light_gray_stained_glass
fill ~-116 ~2 ~6 ~-116 ~3 ~6 minecraft:gray_stained_glass
fill ~-116 ~2 ~15 ~-116 ~3 ~15 minecraft:light_gray_stained_glass
fill ~-124 ~2 ~8 ~-124 ~3 ~8 minecraft:gray_stained_glass
fill ~-114 ~2 ~8 ~-114 ~3 ~8 minecraft:light_gray_stained_glass
fill ~-124 ~2 ~11 ~-124 ~3 ~11 minecraft:gray_stained_glass
fill ~-114 ~2 ~11 ~-114 ~3 ~11 minecraft:light_gray_stained_glass
fill ~-122 ~6 ~6 ~-122 ~7 ~6 minecraft:gray_stained_glass
fill ~-122 ~6 ~15 ~-122 ~7 ~15 minecraft:light_gray_stained_glass
fill ~-119 ~6 ~6 ~-119 ~7 ~6 minecraft:gray_stained_glass
fill ~-119 ~6 ~15 ~-119 ~7 ~15 minecraft:light_gray_stained_glass
fill ~-116 ~6 ~6 ~-116 ~7 ~6 minecraft:gray_stained_glass
fill ~-116 ~6 ~15 ~-116 ~7 ~15 minecraft:light_gray_stained_glass
fill ~-124 ~6 ~8 ~-124 ~7 ~8 minecraft:gray_stained_glass
fill ~-114 ~6 ~8 ~-114 ~7 ~8 minecraft:light_gray_stained_glass
fill ~-124 ~6 ~11 ~-124 ~7 ~11 minecraft:gray_stained_glass
fill ~-114 ~6 ~11 ~-114 ~7 ~11 minecraft:light_gray_stained_glass
setblock ~-119 ~1 ~6 minecraft:iron_door[half=lower,facing=north]
setblock ~-119 ~2 ~6 minecraft:iron_door[half=upper,facing=north]
fill ~-124 ~7 ~6 ~-114 ~11 ~15 minecraft:air
fill ~-123 ~7 ~7 ~-115 ~11 ~14 minecraft:mud_bricks
fill ~-122 ~8 ~8 ~-116 ~10 ~13 minecraft:air
fill ~-123 ~12 ~7 ~-115 ~12 ~14 minecraft:deepslate_tile_slab
fill ~-122 ~2 ~6 ~-116 ~7 ~6 minecraft:blue_stained_glass
fill ~-123 ~1 ~6 ~-123 ~7 ~6 minecraft:spruce_planks
fill ~-119 ~1 ~6 ~-119 ~7 ~6 minecraft:spruce_planks
fill ~-115 ~1 ~6 ~-115 ~7 ~6 minecraft:spruce_planks
# 126 supermarket style=storefront context=collector_front facing=south
fill ~97 ~-3 ~-88 ~101 ~-1 ~-76 minecraft:stone
fill ~97 ~0 ~-88 ~101 ~5 ~-76 minecraft:bricks
fill ~98 ~1 ~-87 ~100 ~4 ~-77 minecraft:air
fill ~98 ~4 ~-87 ~100 ~4 ~-77 minecraft:smooth_stone
fill ~99 ~2 ~-88 ~99 ~3 ~-88 minecraft:gray_stained_glass
fill ~99 ~2 ~-76 ~99 ~3 ~-76 minecraft:light_gray_stained_glass
fill ~97 ~2 ~-86 ~97 ~3 ~-86 minecraft:gray_stained_glass
fill ~101 ~2 ~-86 ~101 ~3 ~-86 minecraft:light_gray_stained_glass
fill ~97 ~2 ~-83 ~97 ~3 ~-83 minecraft:gray_stained_glass
fill ~101 ~2 ~-83 ~101 ~3 ~-83 minecraft:light_gray_stained_glass
fill ~97 ~2 ~-80 ~97 ~3 ~-80 minecraft:gray_stained_glass
fill ~101 ~2 ~-80 ~101 ~3 ~-80 minecraft:light_gray_stained_glass
setblock ~99 ~1 ~-76 minecraft:iron_door[half=lower,facing=south]
setblock ~99 ~2 ~-76 minecraft:iron_door[half=upper,facing=south]
fill ~98 ~1 ~-76 ~100 ~3 ~-76 minecraft:cyan_stained_glass
setblock ~99 ~1 ~-76 minecraft:iron_door[half=lower,facing=south]
setblock ~99 ~2 ~-76 minecraft:iron_door[half=upper,facing=south]
setblock ~99 ~3 ~-75 minecraft:red_wool
fill ~97 ~6 ~-88 ~101 ~6 ~-76 minecraft:deepslate_tile_slab
# 127 lowrise_housing style=rowhouse context=local_front facing=north
fill ~26 ~-3 ~87 ~31 ~-1 ~98 minecraft:stone
fill ~26 ~0 ~87 ~31 ~9 ~98 minecraft:calcite
fill ~27 ~1 ~88 ~30 ~8 ~97 minecraft:air
fill ~27 ~4 ~88 ~30 ~4 ~97 minecraft:smooth_stone
fill ~27 ~8 ~88 ~30 ~8 ~97 minecraft:smooth_stone
fill ~28 ~2 ~87 ~28 ~3 ~87 minecraft:gray_stained_glass
fill ~28 ~2 ~98 ~28 ~3 ~98 minecraft:light_gray_stained_glass
fill ~26 ~2 ~89 ~26 ~3 ~89 minecraft:gray_stained_glass
fill ~31 ~2 ~89 ~31 ~3 ~89 minecraft:light_gray_stained_glass
fill ~26 ~2 ~92 ~26 ~3 ~92 minecraft:gray_stained_glass
fill ~31 ~2 ~92 ~31 ~3 ~92 minecraft:light_gray_stained_glass
fill ~26 ~2 ~95 ~26 ~3 ~95 minecraft:gray_stained_glass
fill ~31 ~2 ~95 ~31 ~3 ~95 minecraft:light_gray_stained_glass
fill ~28 ~6 ~87 ~28 ~7 ~87 minecraft:gray_stained_glass
fill ~28 ~6 ~98 ~28 ~7 ~98 minecraft:light_gray_stained_glass
fill ~26 ~6 ~89 ~26 ~7 ~89 minecraft:gray_stained_glass
fill ~31 ~6 ~89 ~31 ~7 ~89 minecraft:light_gray_stained_glass
fill ~26 ~6 ~92 ~26 ~7 ~92 minecraft:gray_stained_glass
fill ~31 ~6 ~92 ~31 ~7 ~92 minecraft:light_gray_stained_glass
fill ~26 ~6 ~95 ~26 ~7 ~95 minecraft:gray_stained_glass
fill ~31 ~6 ~95 ~31 ~7 ~95 minecraft:light_gray_stained_glass
setblock ~28 ~1 ~87 minecraft:iron_door[half=lower,facing=north]
setblock ~28 ~2 ~87 minecraft:iron_door[half=upper,facing=north]
fill ~26 ~10 ~87 ~31 ~10 ~98 minecraft:stone_brick_slab
fill ~27 ~11 ~88 ~30 ~11 ~97 minecraft:stone_brick_slab
setblock ~28 ~3 ~86 minecraft:dark_oak_slab[type=top]
fill ~27 ~1 ~87 ~27 ~7 ~87 minecraft:gray_concrete
# 128 shop_house style=corner_store context=collector_front facing=north
fill ~-11 ~-3 ~52 ~-1 ~-1 ~63 minecraft:stone
fill ~-11 ~0 ~52 ~-1 ~12 ~63 minecraft:smooth_sandstone
fill ~-10 ~1 ~53 ~-2 ~11 ~62 minecraft:air
fill ~-10 ~4 ~53 ~-2 ~4 ~62 minecraft:smooth_stone
fill ~-10 ~8 ~53 ~-2 ~8 ~62 minecraft:smooth_stone
fill ~-9 ~2 ~52 ~-9 ~3 ~52 minecraft:gray_stained_glass
fill ~-9 ~2 ~63 ~-9 ~3 ~63 minecraft:light_gray_stained_glass
fill ~-6 ~2 ~52 ~-6 ~3 ~52 minecraft:gray_stained_glass
fill ~-6 ~2 ~63 ~-6 ~3 ~63 minecraft:light_gray_stained_glass
fill ~-3 ~2 ~52 ~-3 ~3 ~52 minecraft:gray_stained_glass
fill ~-3 ~2 ~63 ~-3 ~3 ~63 minecraft:light_gray_stained_glass
fill ~-11 ~2 ~54 ~-11 ~3 ~54 minecraft:gray_stained_glass
fill ~-1 ~2 ~54 ~-1 ~3 ~54 minecraft:light_gray_stained_glass
fill ~-11 ~2 ~57 ~-11 ~3 ~57 minecraft:gray_stained_glass
fill ~-1 ~2 ~57 ~-1 ~3 ~57 minecraft:light_gray_stained_glass
fill ~-11 ~2 ~60 ~-11 ~3 ~60 minecraft:gray_stained_glass
fill ~-1 ~2 ~60 ~-1 ~3 ~60 minecraft:light_gray_stained_glass
fill ~-9 ~6 ~52 ~-9 ~7 ~52 minecraft:gray_stained_glass
fill ~-9 ~6 ~63 ~-9 ~7 ~63 minecraft:light_gray_stained_glass
fill ~-6 ~6 ~52 ~-6 ~7 ~52 minecraft:gray_stained_glass
fill ~-6 ~6 ~63 ~-6 ~7 ~63 minecraft:light_gray_stained_glass
fill ~-3 ~6 ~52 ~-3 ~7 ~52 minecraft:gray_stained_glass
fill ~-3 ~6 ~63 ~-3 ~7 ~63 minecraft:light_gray_stained_glass
fill ~-11 ~6 ~54 ~-11 ~7 ~54 minecraft:gray_stained_glass
fill ~-1 ~6 ~54 ~-1 ~7 ~54 minecraft:light_gray_stained_glass
fill ~-11 ~6 ~57 ~-11 ~7 ~57 minecraft:gray_stained_glass
fill ~-1 ~6 ~57 ~-1 ~7 ~57 minecraft:light_gray_stained_glass
fill ~-11 ~6 ~60 ~-11 ~7 ~60 minecraft:gray_stained_glass
fill ~-1 ~6 ~60 ~-1 ~7 ~60 minecraft:light_gray_stained_glass
fill ~-9 ~10 ~52 ~-9 ~11 ~52 minecraft:gray_stained_glass
fill ~-9 ~10 ~63 ~-9 ~11 ~63 minecraft:light_gray_stained_glass
fill ~-6 ~10 ~52 ~-6 ~11 ~52 minecraft:gray_stained_glass
fill ~-6 ~10 ~63 ~-6 ~11 ~63 minecraft:light_gray_stained_glass
fill ~-3 ~10 ~52 ~-3 ~11 ~52 minecraft:gray_stained_glass
fill ~-3 ~10 ~63 ~-3 ~11 ~63 minecraft:light_gray_stained_glass
fill ~-11 ~10 ~54 ~-11 ~11 ~54 minecraft:gray_stained_glass
fill ~-1 ~10 ~54 ~-1 ~11 ~54 minecraft:light_gray_stained_glass
fill ~-11 ~10 ~57 ~-11 ~11 ~57 minecraft:gray_stained_glass
fill ~-1 ~10 ~57 ~-1 ~11 ~57 minecraft:light_gray_stained_glass
fill ~-11 ~10 ~60 ~-11 ~11 ~60 minecraft:gray_stained_glass
fill ~-1 ~10 ~60 ~-1 ~11 ~60 minecraft:light_gray_stained_glass
setblock ~-6 ~1 ~52 minecraft:iron_door[half=lower,facing=north]
setblock ~-6 ~2 ~52 minecraft:iron_door[half=upper,facing=north]
fill ~-10 ~1 ~52 ~-2 ~3 ~52 minecraft:cyan_stained_glass
setblock ~-6 ~1 ~52 minecraft:iron_door[half=lower,facing=north]
setblock ~-6 ~2 ~52 minecraft:iron_door[half=upper,facing=north]
setblock ~-6 ~3 ~51 minecraft:red_wool
fill ~-11 ~13 ~52 ~-1 ~13 ~63 minecraft:stone_brick_slab
fill ~-10 ~1 ~52 ~-10 ~7 ~52 minecraft:brown_terracotta
fill ~-6 ~1 ~52 ~-6 ~7 ~52 minecraft:brown_terracotta
fill ~-2 ~1 ~52 ~-2 ~7 ~52 minecraft:brown_terracotta
fill ~-10 ~6 ~53 ~-2 ~12 ~62 minecraft:smooth_sandstone
fill ~-9 ~7 ~54 ~-3 ~11 ~61 minecraft:air
setblock ~-9 ~3 ~52 minecraft:red_carpet
setblock ~-4 ~3 ~52 minecraft:red_carpet
