# Buildings 57..64
# 057 large_retail style=storefront context=arterial_front facing=south
fill ~-116 ~-3 ~-16 ~-110 ~-1 ~-10 minecraft:stone
fill ~-116 ~0 ~-16 ~-110 ~7 ~-10 minecraft:calcite
fill ~-115 ~1 ~-15 ~-111 ~6 ~-11 minecraft:air
fill ~-115 ~4 ~-15 ~-111 ~4 ~-11 minecraft:smooth_stone
fill ~-114 ~2 ~-16 ~-114 ~3 ~-16 minecraft:gray_stained_glass
fill ~-114 ~2 ~-10 ~-114 ~3 ~-10 minecraft:light_gray_stained_glass
fill ~-116 ~2 ~-14 ~-116 ~3 ~-14 minecraft:gray_stained_glass
fill ~-110 ~2 ~-14 ~-110 ~3 ~-14 minecraft:light_gray_stained_glass
setblock ~-113 ~1 ~-10 minecraft:iron_door[half=lower,facing=south]
setblock ~-113 ~2 ~-10 minecraft:iron_door[half=upper,facing=south]
fill ~-115 ~1 ~-10 ~-111 ~3 ~-10 minecraft:cyan_stained_glass
setblock ~-113 ~1 ~-10 minecraft:iron_door[half=lower,facing=south]
setblock ~-113 ~2 ~-10 minecraft:iron_door[half=upper,facing=south]
setblock ~-113 ~3 ~-9 minecraft:red_wool
fill ~-116 ~8 ~-16 ~-110 ~8 ~-10 minecraft:stone_brick_slab
fill ~-115 ~1 ~-10 ~-115 ~7 ~-10 minecraft:gray_concrete
fill ~-111 ~1 ~-10 ~-111 ~7 ~-10 minecraft:gray_concrete
setblock ~-114 ~3 ~-10 minecraft:red_carpet
# 058 local_shop style=arcade_shop context=local_front facing=north
fill ~-19 ~-3 ~-38 ~-10 ~-1 ~-27 minecraft:stone
fill ~-19 ~0 ~-38 ~-10 ~20 ~-27 minecraft:bricks
fill ~-18 ~1 ~-37 ~-11 ~19 ~-28 minecraft:air
fill ~-18 ~4 ~-37 ~-11 ~4 ~-28 minecraft:smooth_stone
fill ~-18 ~8 ~-37 ~-11 ~8 ~-28 minecraft:smooth_stone
fill ~-18 ~12 ~-37 ~-11 ~12 ~-28 minecraft:smooth_stone
fill ~-18 ~16 ~-37 ~-11 ~16 ~-28 minecraft:smooth_stone
fill ~-17 ~2 ~-38 ~-17 ~3 ~-38 minecraft:gray_stained_glass
fill ~-17 ~2 ~-27 ~-17 ~3 ~-27 minecraft:light_gray_stained_glass
fill ~-14 ~2 ~-38 ~-14 ~3 ~-38 minecraft:gray_stained_glass
fill ~-14 ~2 ~-27 ~-14 ~3 ~-27 minecraft:light_gray_stained_glass
fill ~-19 ~2 ~-36 ~-19 ~3 ~-36 minecraft:gray_stained_glass
fill ~-10 ~2 ~-36 ~-10 ~3 ~-36 minecraft:light_gray_stained_glass
fill ~-19 ~2 ~-33 ~-19 ~3 ~-33 minecraft:gray_stained_glass
fill ~-10 ~2 ~-33 ~-10 ~3 ~-33 minecraft:light_gray_stained_glass
fill ~-19 ~2 ~-30 ~-19 ~3 ~-30 minecraft:gray_stained_glass
fill ~-10 ~2 ~-30 ~-10 ~3 ~-30 minecraft:light_gray_stained_glass
fill ~-17 ~6 ~-38 ~-17 ~7 ~-38 minecraft:gray_stained_glass
fill ~-17 ~6 ~-27 ~-17 ~7 ~-27 minecraft:light_gray_stained_glass
fill ~-14 ~6 ~-38 ~-14 ~7 ~-38 minecraft:gray_stained_glass
fill ~-14 ~6 ~-27 ~-14 ~7 ~-27 minecraft:light_gray_stained_glass
fill ~-19 ~6 ~-36 ~-19 ~7 ~-36 minecraft:gray_stained_glass
fill ~-10 ~6 ~-36 ~-10 ~7 ~-36 minecraft:light_gray_stained_glass
fill ~-19 ~6 ~-33 ~-19 ~7 ~-33 minecraft:gray_stained_glass
fill ~-10 ~6 ~-33 ~-10 ~7 ~-33 minecraft:light_gray_stained_glass
fill ~-19 ~6 ~-30 ~-19 ~7 ~-30 minecraft:gray_stained_glass
fill ~-10 ~6 ~-30 ~-10 ~7 ~-30 minecraft:light_gray_stained_glass
fill ~-17 ~10 ~-38 ~-17 ~11 ~-38 minecraft:gray_stained_glass
fill ~-17 ~10 ~-27 ~-17 ~11 ~-27 minecraft:light_gray_stained_glass
fill ~-14 ~10 ~-38 ~-14 ~11 ~-38 minecraft:gray_stained_glass
fill ~-14 ~10 ~-27 ~-14 ~11 ~-27 minecraft:light_gray_stained_glass
fill ~-19 ~10 ~-36 ~-19 ~11 ~-36 minecraft:gray_stained_glass
fill ~-10 ~10 ~-36 ~-10 ~11 ~-36 minecraft:light_gray_stained_glass
fill ~-19 ~10 ~-33 ~-19 ~11 ~-33 minecraft:gray_stained_glass
fill ~-10 ~10 ~-33 ~-10 ~11 ~-33 minecraft:light_gray_stained_glass
fill ~-19 ~10 ~-30 ~-19 ~11 ~-30 minecraft:gray_stained_glass
fill ~-10 ~10 ~-30 ~-10 ~11 ~-30 minecraft:light_gray_stained_glass
fill ~-17 ~14 ~-38 ~-17 ~15 ~-38 minecraft:gray_stained_glass
fill ~-17 ~14 ~-27 ~-17 ~15 ~-27 minecraft:light_gray_stained_glass
fill ~-14 ~14 ~-38 ~-14 ~15 ~-38 minecraft:gray_stained_glass
fill ~-14 ~14 ~-27 ~-14 ~15 ~-27 minecraft:light_gray_stained_glass
fill ~-19 ~14 ~-36 ~-19 ~15 ~-36 minecraft:gray_stained_glass
fill ~-10 ~14 ~-36 ~-10 ~15 ~-36 minecraft:light_gray_stained_glass
fill ~-19 ~14 ~-33 ~-19 ~15 ~-33 minecraft:gray_stained_glass
fill ~-10 ~14 ~-33 ~-10 ~15 ~-33 minecraft:light_gray_stained_glass
fill ~-19 ~14 ~-30 ~-19 ~15 ~-30 minecraft:gray_stained_glass
fill ~-10 ~14 ~-30 ~-10 ~15 ~-30 minecraft:light_gray_stained_glass
fill ~-17 ~18 ~-38 ~-17 ~19 ~-38 minecraft:gray_stained_glass
fill ~-17 ~18 ~-27 ~-17 ~19 ~-27 minecraft:light_gray_stained_glass
fill ~-14 ~18 ~-38 ~-14 ~19 ~-38 minecraft:gray_stained_glass
fill ~-14 ~18 ~-27 ~-14 ~19 ~-27 minecraft:light_gray_stained_glass
fill ~-19 ~18 ~-36 ~-19 ~19 ~-36 minecraft:gray_stained_glass
fill ~-10 ~18 ~-36 ~-10 ~19 ~-36 minecraft:light_gray_stained_glass
fill ~-19 ~18 ~-33 ~-19 ~19 ~-33 minecraft:gray_stained_glass
fill ~-10 ~18 ~-33 ~-10 ~19 ~-33 minecraft:light_gray_stained_glass
fill ~-19 ~18 ~-30 ~-19 ~19 ~-30 minecraft:gray_stained_glass
fill ~-10 ~18 ~-30 ~-10 ~19 ~-30 minecraft:light_gray_stained_glass
setblock ~-15 ~1 ~-38 minecraft:iron_door[half=lower,facing=north]
setblock ~-15 ~2 ~-38 minecraft:iron_door[half=upper,facing=north]
fill ~-18 ~1 ~-38 ~-11 ~3 ~-38 minecraft:cyan_stained_glass
setblock ~-15 ~1 ~-38 minecraft:iron_door[half=lower,facing=north]
setblock ~-15 ~2 ~-38 minecraft:iron_door[half=upper,facing=north]
setblock ~-15 ~3 ~-39 minecraft:red_wool
fill ~-18 ~4 ~-38 ~-11 ~4 ~-38 doomsday_decoration:redbrick
fill ~-19 ~21 ~-38 ~-10 ~21 ~-27 minecraft:deepslate_tile_slab
fill ~-18 ~1 ~-38 ~-18 ~7 ~-38 doomsday_decoration:redbrick
fill ~-14 ~1 ~-38 ~-14 ~7 ~-38 doomsday_decoration:redbrick
fill ~-18 ~6 ~-37 ~-11 ~20 ~-28 minecraft:bricks
fill ~-17 ~7 ~-36 ~-12 ~19 ~-29 minecraft:air
setblock ~-17 ~3 ~-38 minecraft:red_carpet
setblock ~-12 ~3 ~-38 minecraft:red_carpet
# 059 shop_house style=corner_store context=collector_front facing=west
fill ~-82 ~-3 ~64 ~-72 ~-1 ~73 minecraft:stone
fill ~-82 ~0 ~64 ~-72 ~7 ~73 minecraft:white_terracotta
fill ~-81 ~1 ~65 ~-73 ~6 ~72 minecraft:air
fill ~-81 ~4 ~65 ~-73 ~4 ~72 minecraft:smooth_stone
fill ~-80 ~2 ~64 ~-80 ~3 ~64 minecraft:gray_stained_glass
fill ~-80 ~2 ~73 ~-80 ~3 ~73 minecraft:light_gray_stained_glass
fill ~-77 ~2 ~64 ~-77 ~3 ~64 minecraft:gray_stained_glass
fill ~-77 ~2 ~73 ~-77 ~3 ~73 minecraft:light_gray_stained_glass
fill ~-74 ~2 ~64 ~-74 ~3 ~64 minecraft:gray_stained_glass
fill ~-74 ~2 ~73 ~-74 ~3 ~73 minecraft:light_gray_stained_glass
fill ~-82 ~2 ~66 ~-82 ~3 ~66 minecraft:gray_stained_glass
fill ~-72 ~2 ~66 ~-72 ~3 ~66 minecraft:light_gray_stained_glass
fill ~-82 ~2 ~69 ~-82 ~3 ~69 minecraft:gray_stained_glass
fill ~-72 ~2 ~69 ~-72 ~3 ~69 minecraft:light_gray_stained_glass
setblock ~-82 ~1 ~68 minecraft:iron_door[half=lower,facing=west]
setblock ~-82 ~2 ~68 minecraft:iron_door[half=upper,facing=west]
fill ~-82 ~1 ~65 ~-82 ~3 ~72 minecraft:cyan_stained_glass
setblock ~-82 ~1 ~68 minecraft:iron_door[half=lower,facing=west]
setblock ~-82 ~2 ~68 minecraft:iron_door[half=upper,facing=west]
setblock ~-83 ~3 ~68 minecraft:red_wool
fill ~-82 ~8 ~64 ~-72 ~8 ~73 minecraft:dark_oak_slab
fill ~-82 ~1 ~65 ~-82 ~7 ~65 minecraft:dark_oak_planks
fill ~-82 ~1 ~69 ~-82 ~7 ~69 minecraft:dark_oak_planks
setblock ~-82 ~3 ~66 minecraft:red_carpet
setblock ~-82 ~3 ~71 minecraft:red_carpet
# 060 row_house style=rowhouse context=local_front facing=north
fill ~-64 ~-3 ~97 ~-57 ~-1 ~106 minecraft:stone
fill ~-64 ~0 ~97 ~-57 ~5 ~106 minecraft:calcite
fill ~-63 ~1 ~98 ~-58 ~4 ~105 minecraft:air
fill ~-63 ~4 ~98 ~-58 ~4 ~105 minecraft:smooth_stone
fill ~-62 ~2 ~97 ~-62 ~3 ~97 minecraft:gray_stained_glass
fill ~-62 ~2 ~106 ~-62 ~3 ~106 minecraft:light_gray_stained_glass
fill ~-59 ~2 ~97 ~-59 ~3 ~97 minecraft:gray_stained_glass
fill ~-59 ~2 ~106 ~-59 ~3 ~106 minecraft:light_gray_stained_glass
fill ~-64 ~2 ~99 ~-64 ~3 ~99 minecraft:gray_stained_glass
fill ~-57 ~2 ~99 ~-57 ~3 ~99 minecraft:light_gray_stained_glass
fill ~-64 ~2 ~102 ~-64 ~3 ~102 minecraft:gray_stained_glass
fill ~-57 ~2 ~102 ~-57 ~3 ~102 minecraft:light_gray_stained_glass
setblock ~-61 ~1 ~97 minecraft:iron_door[half=lower,facing=north]
setblock ~-61 ~2 ~97 minecraft:iron_door[half=upper,facing=north]
fill ~-64 ~6 ~97 ~-57 ~6 ~106 minecraft:stone_brick_slab
fill ~-63 ~7 ~98 ~-58 ~7 ~105 minecraft:stone_brick_slab
setblock ~-61 ~3 ~96 minecraft:dark_oak_slab[type=top]
fill ~-63 ~1 ~97 ~-63 ~5 ~97 minecraft:gray_concrete
fill ~-59 ~1 ~97 ~-59 ~5 ~97 minecraft:gray_concrete
# 061 medical_center style=civic_modern context=arterial_front facing=north
fill ~-29 ~-3 ~6 ~-19 ~-1 ~19 minecraft:stone
fill ~-29 ~0 ~6 ~-19 ~20 ~19 minecraft:white_terracotta
fill ~-28 ~1 ~7 ~-20 ~19 ~18 minecraft:air
fill ~-28 ~4 ~7 ~-20 ~4 ~18 minecraft:smooth_stone
fill ~-28 ~8 ~7 ~-20 ~8 ~18 minecraft:smooth_stone
fill ~-28 ~12 ~7 ~-20 ~12 ~18 minecraft:smooth_stone
fill ~-28 ~16 ~7 ~-20 ~16 ~18 minecraft:smooth_stone
fill ~-27 ~2 ~6 ~-27 ~3 ~6 minecraft:gray_stained_glass
fill ~-27 ~2 ~19 ~-27 ~3 ~19 minecraft:light_gray_stained_glass
fill ~-24 ~2 ~6 ~-24 ~3 ~6 minecraft:gray_stained_glass
fill ~-24 ~2 ~19 ~-24 ~3 ~19 minecraft:light_gray_stained_glass
fill ~-21 ~2 ~6 ~-21 ~3 ~6 minecraft:gray_stained_glass
fill ~-21 ~2 ~19 ~-21 ~3 ~19 minecraft:light_gray_stained_glass
fill ~-29 ~2 ~8 ~-29 ~3 ~8 minecraft:gray_stained_glass
fill ~-19 ~2 ~8 ~-19 ~3 ~8 minecraft:light_gray_stained_glass
fill ~-29 ~2 ~11 ~-29 ~3 ~11 minecraft:gray_stained_glass
fill ~-19 ~2 ~11 ~-19 ~3 ~11 minecraft:light_gray_stained_glass
fill ~-29 ~2 ~14 ~-29 ~3 ~14 minecraft:gray_stained_glass
fill ~-19 ~2 ~14 ~-19 ~3 ~14 minecraft:light_gray_stained_glass
fill ~-29 ~2 ~17 ~-29 ~3 ~17 minecraft:gray_stained_glass
fill ~-19 ~2 ~17 ~-19 ~3 ~17 minecraft:light_gray_stained_glass
fill ~-27 ~6 ~6 ~-27 ~7 ~6 minecraft:gray_stained_glass
fill ~-27 ~6 ~19 ~-27 ~7 ~19 minecraft:light_gray_stained_glass
fill ~-24 ~6 ~6 ~-24 ~7 ~6 minecraft:gray_stained_glass
fill ~-24 ~6 ~19 ~-24 ~7 ~19 minecraft:light_gray_stained_glass
fill ~-21 ~6 ~6 ~-21 ~7 ~6 minecraft:gray_stained_glass
fill ~-21 ~6 ~19 ~-21 ~7 ~19 minecraft:light_gray_stained_glass
fill ~-29 ~6 ~8 ~-29 ~7 ~8 minecraft:gray_stained_glass
fill ~-19 ~6 ~8 ~-19 ~7 ~8 minecraft:light_gray_stained_glass
fill ~-29 ~6 ~11 ~-29 ~7 ~11 minecraft:gray_stained_glass
fill ~-19 ~6 ~11 ~-19 ~7 ~11 minecraft:light_gray_stained_glass
fill ~-29 ~6 ~14 ~-29 ~7 ~14 minecraft:gray_stained_glass
fill ~-19 ~6 ~14 ~-19 ~7 ~14 minecraft:light_gray_stained_glass
fill ~-29 ~6 ~17 ~-29 ~7 ~17 minecraft:gray_stained_glass
fill ~-19 ~6 ~17 ~-19 ~7 ~17 minecraft:light_gray_stained_glass
fill ~-27 ~10 ~6 ~-27 ~11 ~6 minecraft:gray_stained_glass
fill ~-27 ~10 ~19 ~-27 ~11 ~19 minecraft:light_gray_stained_glass
fill ~-24 ~10 ~6 ~-24 ~11 ~6 minecraft:gray_stained_glass
fill ~-24 ~10 ~19 ~-24 ~11 ~19 minecraft:light_gray_stained_glass
fill ~-21 ~10 ~6 ~-21 ~11 ~6 minecraft:gray_stained_glass
fill ~-21 ~10 ~19 ~-21 ~11 ~19 minecraft:light_gray_stained_glass
fill ~-29 ~10 ~8 ~-29 ~11 ~8 minecraft:gray_stained_glass
fill ~-19 ~10 ~8 ~-19 ~11 ~8 minecraft:light_gray_stained_glass
fill ~-29 ~10 ~11 ~-29 ~11 ~11 minecraft:gray_stained_glass
fill ~-19 ~10 ~11 ~-19 ~11 ~11 minecraft:light_gray_stained_glass
fill ~-29 ~10 ~14 ~-29 ~11 ~14 minecraft:gray_stained_glass
fill ~-19 ~10 ~14 ~-19 ~11 ~14 minecraft:light_gray_stained_glass
fill ~-29 ~10 ~17 ~-29 ~11 ~17 minecraft:gray_stained_glass
fill ~-19 ~10 ~17 ~-19 ~11 ~17 minecraft:light_gray_stained_glass
fill ~-27 ~14 ~6 ~-27 ~15 ~6 minecraft:gray_stained_glass
fill ~-27 ~14 ~19 ~-27 ~15 ~19 minecraft:light_gray_stained_glass
fill ~-24 ~14 ~6 ~-24 ~15 ~6 minecraft:gray_stained_glass
fill ~-24 ~14 ~19 ~-24 ~15 ~19 minecraft:light_gray_stained_glass
fill ~-21 ~14 ~6 ~-21 ~15 ~6 minecraft:gray_stained_glass
fill ~-21 ~14 ~19 ~-21 ~15 ~19 minecraft:light_gray_stained_glass
fill ~-29 ~14 ~8 ~-29 ~15 ~8 minecraft:gray_stained_glass
fill ~-19 ~14 ~8 ~-19 ~15 ~8 minecraft:light_gray_stained_glass
fill ~-29 ~14 ~11 ~-29 ~15 ~11 minecraft:gray_stained_glass
fill ~-19 ~14 ~11 ~-19 ~15 ~11 minecraft:light_gray_stained_glass
fill ~-29 ~14 ~14 ~-29 ~15 ~14 minecraft:gray_stained_glass
fill ~-19 ~14 ~14 ~-19 ~15 ~14 minecraft:light_gray_stained_glass
fill ~-29 ~14 ~17 ~-29 ~15 ~17 minecraft:gray_stained_glass
fill ~-19 ~14 ~17 ~-19 ~15 ~17 minecraft:light_gray_stained_glass
fill ~-27 ~18 ~6 ~-27 ~19 ~6 minecraft:gray_stained_glass
fill ~-27 ~18 ~19 ~-27 ~19 ~19 minecraft:light_gray_stained_glass
fill ~-24 ~18 ~6 ~-24 ~19 ~6 minecraft:gray_stained_glass
fill ~-24 ~18 ~19 ~-24 ~19 ~19 minecraft:light_gray_stained_glass
fill ~-21 ~18 ~6 ~-21 ~19 ~6 minecraft:gray_stained_glass
fill ~-21 ~18 ~19 ~-21 ~19 ~19 minecraft:light_gray_stained_glass
fill ~-29 ~18 ~8 ~-29 ~19 ~8 minecraft:gray_stained_glass
fill ~-19 ~18 ~8 ~-19 ~19 ~8 minecraft:light_gray_stained_glass
fill ~-29 ~18 ~11 ~-29 ~19 ~11 minecraft:gray_stained_glass
fill ~-19 ~18 ~11 ~-19 ~19 ~11 minecraft:light_gray_stained_glass
fill ~-29 ~18 ~14 ~-29 ~19 ~14 minecraft:gray_stained_glass
fill ~-19 ~18 ~14 ~-19 ~19 ~14 minecraft:light_gray_stained_glass
fill ~-29 ~18 ~17 ~-29 ~19 ~17 minecraft:gray_stained_glass
fill ~-19 ~18 ~17 ~-19 ~19 ~17 minecraft:light_gray_stained_glass
setblock ~-24 ~1 ~6 minecraft:iron_door[half=lower,facing=north]
setblock ~-24 ~2 ~6 minecraft:iron_door[half=upper,facing=north]
fill ~-29 ~15 ~6 ~-19 ~20 ~19 minecraft:air
fill ~-28 ~15 ~7 ~-20 ~20 ~18 minecraft:white_terracotta
fill ~-27 ~16 ~8 ~-21 ~19 ~17 minecraft:air
fill ~-28 ~21 ~7 ~-20 ~21 ~18 minecraft:stone_brick_slab
fill ~-28 ~1 ~6 ~-28 ~7 ~6 minecraft:gray_concrete
fill ~-24 ~1 ~6 ~-24 ~7 ~6 minecraft:gray_concrete
fill ~-20 ~1 ~6 ~-20 ~7 ~6 minecraft:gray_concrete
# 062 restaurant style=arcade_shop context=collector_front facing=south
fill ~89 ~-3 ~-83 ~93 ~-1 ~-76 minecraft:stone
fill ~89 ~0 ~-83 ~93 ~11 ~-76 minecraft:calcite
fill ~90 ~1 ~-82 ~92 ~10 ~-77 minecraft:air
fill ~90 ~4 ~-82 ~92 ~4 ~-77 minecraft:smooth_stone
fill ~90 ~8 ~-82 ~92 ~8 ~-77 minecraft:smooth_stone
fill ~91 ~2 ~-83 ~91 ~3 ~-83 minecraft:gray_stained_glass
fill ~91 ~2 ~-76 ~91 ~3 ~-76 minecraft:light_gray_stained_glass
fill ~89 ~2 ~-81 ~89 ~3 ~-81 minecraft:gray_stained_glass
fill ~93 ~2 ~-81 ~93 ~3 ~-81 minecraft:light_gray_stained_glass
fill ~89 ~2 ~-78 ~89 ~3 ~-78 minecraft:gray_stained_glass
fill ~93 ~2 ~-78 ~93 ~3 ~-78 minecraft:light_gray_stained_glass
fill ~91 ~6 ~-83 ~91 ~7 ~-83 minecraft:gray_stained_glass
fill ~91 ~6 ~-76 ~91 ~7 ~-76 minecraft:light_gray_stained_glass
fill ~89 ~6 ~-81 ~89 ~7 ~-81 minecraft:gray_stained_glass
fill ~93 ~6 ~-81 ~93 ~7 ~-81 minecraft:light_gray_stained_glass
fill ~89 ~6 ~-78 ~89 ~7 ~-78 minecraft:gray_stained_glass
fill ~93 ~6 ~-78 ~93 ~7 ~-78 minecraft:light_gray_stained_glass
setblock ~91 ~1 ~-76 minecraft:iron_door[half=lower,facing=south]
setblock ~91 ~2 ~-76 minecraft:iron_door[half=upper,facing=south]
fill ~90 ~1 ~-76 ~92 ~3 ~-76 minecraft:cyan_stained_glass
setblock ~91 ~1 ~-76 minecraft:iron_door[half=lower,facing=south]
setblock ~91 ~2 ~-76 minecraft:iron_door[half=upper,facing=south]
setblock ~91 ~3 ~-75 minecraft:red_wool
fill ~90 ~4 ~-76 ~92 ~4 ~-76 minecraft:gray_concrete
fill ~89 ~12 ~-83 ~93 ~12 ~-76 minecraft:stone_brick_slab
# 063 mixed_use style=mixed_facade context=arterial_front facing=north
fill ~-31 ~-3 ~-104 ~-20 ~-1 ~-90 minecraft:stone
fill ~-31 ~0 ~-104 ~-20 ~9 ~-90 minecraft:bricks
fill ~-30 ~1 ~-103 ~-21 ~8 ~-91 minecraft:air
fill ~-30 ~4 ~-103 ~-21 ~4 ~-91 minecraft:smooth_stone
fill ~-30 ~8 ~-103 ~-21 ~8 ~-91 minecraft:smooth_stone
fill ~-29 ~2 ~-104 ~-29 ~3 ~-104 minecraft:gray_stained_glass
fill ~-29 ~2 ~-90 ~-29 ~3 ~-90 minecraft:light_gray_stained_glass
fill ~-26 ~2 ~-104 ~-26 ~3 ~-104 minecraft:gray_stained_glass
fill ~-26 ~2 ~-90 ~-26 ~3 ~-90 minecraft:light_gray_stained_glass
fill ~-23 ~2 ~-104 ~-23 ~3 ~-104 minecraft:gray_stained_glass
fill ~-23 ~2 ~-90 ~-23 ~3 ~-90 minecraft:light_gray_stained_glass
fill ~-31 ~2 ~-102 ~-31 ~3 ~-102 minecraft:gray_stained_glass
fill ~-20 ~2 ~-102 ~-20 ~3 ~-102 minecraft:light_gray_stained_glass
fill ~-31 ~2 ~-99 ~-31 ~3 ~-99 minecraft:gray_stained_glass
fill ~-20 ~2 ~-99 ~-20 ~3 ~-99 minecraft:light_gray_stained_glass
fill ~-31 ~2 ~-96 ~-31 ~3 ~-96 minecraft:gray_stained_glass
fill ~-20 ~2 ~-96 ~-20 ~3 ~-96 minecraft:light_gray_stained_glass
fill ~-31 ~2 ~-93 ~-31 ~3 ~-93 minecraft:gray_stained_glass
fill ~-20 ~2 ~-93 ~-20 ~3 ~-93 minecraft:light_gray_stained_glass
fill ~-29 ~6 ~-104 ~-29 ~7 ~-104 minecraft:gray_stained_glass
fill ~-29 ~6 ~-90 ~-29 ~7 ~-90 minecraft:light_gray_stained_glass
fill ~-26 ~6 ~-104 ~-26 ~7 ~-104 minecraft:gray_stained_glass
fill ~-26 ~6 ~-90 ~-26 ~7 ~-90 minecraft:light_gray_stained_glass
fill ~-23 ~6 ~-104 ~-23 ~7 ~-104 minecraft:gray_stained_glass
fill ~-23 ~6 ~-90 ~-23 ~7 ~-90 minecraft:light_gray_stained_glass
fill ~-31 ~6 ~-102 ~-31 ~7 ~-102 minecraft:gray_stained_glass
fill ~-20 ~6 ~-102 ~-20 ~7 ~-102 minecraft:light_gray_stained_glass
fill ~-31 ~6 ~-99 ~-31 ~7 ~-99 minecraft:gray_stained_glass
fill ~-20 ~6 ~-99 ~-20 ~7 ~-99 minecraft:light_gray_stained_glass
fill ~-31 ~6 ~-96 ~-31 ~7 ~-96 minecraft:gray_stained_glass
fill ~-20 ~6 ~-96 ~-20 ~7 ~-96 minecraft:light_gray_stained_glass
fill ~-31 ~6 ~-93 ~-31 ~7 ~-93 minecraft:gray_stained_glass
fill ~-20 ~6 ~-93 ~-20 ~7 ~-93 minecraft:light_gray_stained_glass
setblock ~-26 ~1 ~-104 minecraft:iron_door[half=lower,facing=north]
setblock ~-26 ~2 ~-104 minecraft:iron_door[half=upper,facing=north]
fill ~-31 ~10 ~-104 ~-20 ~10 ~-90 minecraft:deepslate_tile_slab
fill ~-29 ~11 ~-102 ~-27 ~12 ~-100 minecraft:light_gray_concrete
setblock ~-26 ~11 ~-101 minecraft:lightning_rod
fill ~-30 ~1 ~-104 ~-30 ~7 ~-104 minecraft:gray_concrete
fill ~-26 ~1 ~-104 ~-26 ~7 ~-104 minecraft:gray_concrete
fill ~-22 ~1 ~-104 ~-22 ~7 ~-104 minecraft:gray_concrete
fill ~-30 ~6 ~-103 ~-21 ~9 ~-91 minecraft:bricks
fill ~-29 ~7 ~-102 ~-22 ~8 ~-92 minecraft:air
setblock ~-29 ~3 ~-104 minecraft:red_carpet
setblock ~-24 ~3 ~-104 minecraft:red_carpet
# 064 row_house style=japanese_house context=local_front facing=east
fill ~104 ~-3 ~-93 ~112 ~-1 ~-86 minecraft:stone
fill ~104 ~0 ~-93 ~112 ~9 ~-86 minecraft:white_concrete
fill ~105 ~1 ~-92 ~111 ~8 ~-87 minecraft:air
fill ~105 ~4 ~-92 ~111 ~4 ~-87 minecraft:smooth_stone
fill ~105 ~8 ~-92 ~111 ~8 ~-87 minecraft:smooth_stone
fill ~106 ~2 ~-93 ~106 ~3 ~-93 minecraft:gray_stained_glass
fill ~106 ~2 ~-86 ~106 ~3 ~-86 minecraft:light_gray_stained_glass
fill ~109 ~2 ~-93 ~109 ~3 ~-93 minecraft:gray_stained_glass
fill ~109 ~2 ~-86 ~109 ~3 ~-86 minecraft:light_gray_stained_glass
fill ~104 ~2 ~-91 ~104 ~3 ~-91 minecraft:gray_stained_glass
fill ~112 ~2 ~-91 ~112 ~3 ~-91 minecraft:light_gray_stained_glass
fill ~104 ~2 ~-88 ~104 ~3 ~-88 minecraft:gray_stained_glass
fill ~112 ~2 ~-88 ~112 ~3 ~-88 minecraft:light_gray_stained_glass
fill ~106 ~6 ~-93 ~106 ~7 ~-93 minecraft:gray_stained_glass
fill ~106 ~6 ~-86 ~106 ~7 ~-86 minecraft:light_gray_stained_glass
fill ~109 ~6 ~-93 ~109 ~7 ~-93 minecraft:gray_stained_glass
fill ~109 ~6 ~-86 ~109 ~7 ~-86 minecraft:light_gray_stained_glass
fill ~104 ~6 ~-91 ~104 ~7 ~-91 minecraft:gray_stained_glass
fill ~112 ~6 ~-91 ~112 ~7 ~-91 minecraft:light_gray_stained_glass
fill ~104 ~6 ~-88 ~104 ~7 ~-88 minecraft:gray_stained_glass
fill ~112 ~6 ~-88 ~112 ~7 ~-88 minecraft:light_gray_stained_glass
setblock ~112 ~1 ~-90 minecraft:iron_door[half=lower,facing=east]
setblock ~112 ~2 ~-90 minecraft:iron_door[half=upper,facing=east]
fill ~104 ~10 ~-93 ~112 ~10 ~-86 minecraft:smooth_stone_slab
fill ~105 ~11 ~-92 ~111 ~11 ~-87 minecraft:smooth_stone_slab
setblock ~113 ~3 ~-90 minecraft:dark_oak_slab[type=top]
fill ~112 ~1 ~-92 ~112 ~7 ~-92 minecraft:cyan_terracotta
fill ~112 ~1 ~-88 ~112 ~7 ~-88 minecraft:cyan_terracotta
