# Buildings 76..100
# 076 station_shop -61,-125 -43,-116 h=6
fill ~-61 ~-3 ~-125 ~-43 ~-1 ~-116 minecraft:stone
fill ~-61 ~0 ~-125 ~-43 ~6 ~-116 minecraft:bricks
fill ~-60 ~1 ~-124 ~-44 ~5 ~-117 minecraft:air
fill ~-60 ~4 ~-124 ~-44 ~4 ~-117 minecraft:smooth_stone
fill ~-61 ~2 ~-123 ~-61 ~3 ~-118 minecraft:gray_stained_glass
fill ~-43 ~2 ~-123 ~-43 ~3 ~-118 minecraft:light_gray_stained_glass
fill ~-60 ~0 ~-125 ~-57 ~3 ~-125 minecraft:gray_concrete
setblock ~-59 ~1 ~-125 minecraft:iron_door[half=lower,facing=north]
setblock ~-59 ~2 ~-125 minecraft:iron_door[half=upper,facing=north]
fill ~-61 ~7 ~-125 ~-43 ~7 ~-116 minecraft:deepslate_tile_slab
# 077 row_house -98,104 -93,110 h=11
fill ~-98 ~-3 ~104 ~-93 ~-1 ~110 minecraft:stone
fill ~-98 ~0 ~104 ~-93 ~11 ~110 minecraft:mud_bricks
fill ~-97 ~1 ~105 ~-94 ~10 ~109 minecraft:air
fill ~-97 ~4 ~105 ~-94 ~4 ~109 minecraft:smooth_stone
fill ~-97 ~8 ~105 ~-94 ~8 ~109 minecraft:smooth_stone
fill ~-98 ~2 ~106 ~-98 ~3 ~108 minecraft:gray_stained_glass
fill ~-93 ~2 ~106 ~-93 ~3 ~108 minecraft:light_gray_stained_glass
fill ~-98 ~6 ~106 ~-98 ~7 ~108 minecraft:gray_stained_glass
fill ~-93 ~6 ~106 ~-93 ~7 ~108 minecraft:light_gray_stained_glass
fill ~-97 ~0 ~104 ~-94 ~3 ~104 minecraft:spruce_planks
setblock ~-96 ~1 ~104 minecraft:iron_door[half=lower,facing=north]
setblock ~-96 ~2 ~104 minecraft:iron_door[half=upper,facing=north]
fill ~-98 ~12 ~104 ~-93 ~12 ~110 minecraft:deepslate_tile_slab
# 078 restaurant 47,32 53,43 h=16
fill ~47 ~-3 ~32 ~53 ~-1 ~43 minecraft:stone
fill ~47 ~0 ~32 ~53 ~16 ~43 minecraft:bricks
fill ~48 ~1 ~33 ~52 ~15 ~42 minecraft:air
fill ~48 ~4 ~33 ~52 ~4 ~42 minecraft:smooth_stone
fill ~48 ~8 ~33 ~52 ~8 ~42 minecraft:smooth_stone
fill ~48 ~12 ~33 ~52 ~12 ~42 minecraft:smooth_stone
fill ~49 ~2 ~32 ~51 ~3 ~32 minecraft:gray_stained_glass
fill ~49 ~2 ~43 ~51 ~3 ~43 minecraft:light_gray_stained_glass
fill ~49 ~6 ~32 ~51 ~7 ~32 minecraft:gray_stained_glass
fill ~49 ~6 ~43 ~51 ~7 ~43 minecraft:light_gray_stained_glass
fill ~49 ~10 ~32 ~51 ~11 ~32 minecraft:gray_stained_glass
fill ~49 ~10 ~43 ~51 ~11 ~43 minecraft:light_gray_stained_glass
fill ~49 ~14 ~32 ~51 ~15 ~32 minecraft:gray_stained_glass
fill ~49 ~14 ~43 ~51 ~15 ~43 minecraft:light_gray_stained_glass
fill ~48 ~0 ~32 ~51 ~3 ~32 doomsday_decoration:hollowbrick
setblock ~49 ~1 ~32 minecraft:iron_door[half=lower,facing=north]
setblock ~49 ~2 ~32 minecraft:iron_door[half=upper,facing=north]
fill ~47 ~17 ~32 ~53 ~17 ~43 minecraft:deepslate_tile_slab
# 079 restaurant 38,-67 45,-52 h=12
fill ~38 ~-3 ~-67 ~45 ~-1 ~-52 minecraft:stone
fill ~38 ~0 ~-67 ~45 ~12 ~-52 minecraft:bricks
fill ~39 ~1 ~-66 ~44 ~11 ~-53 minecraft:air
fill ~39 ~4 ~-66 ~44 ~4 ~-53 minecraft:smooth_stone
fill ~39 ~8 ~-66 ~44 ~8 ~-53 minecraft:smooth_stone
fill ~38 ~2 ~-65 ~38 ~3 ~-54 minecraft:gray_stained_glass
fill ~45 ~2 ~-65 ~45 ~3 ~-54 minecraft:light_gray_stained_glass
fill ~38 ~6 ~-65 ~38 ~7 ~-54 minecraft:gray_stained_glass
fill ~45 ~6 ~-65 ~45 ~7 ~-54 minecraft:light_gray_stained_glass
fill ~38 ~10 ~-65 ~38 ~11 ~-54 minecraft:gray_stained_glass
fill ~45 ~10 ~-65 ~45 ~11 ~-54 minecraft:light_gray_stained_glass
fill ~39 ~0 ~-67 ~42 ~3 ~-67 doomsday_decoration:hollowbrick
setblock ~40 ~1 ~-67 minecraft:iron_door[half=lower,facing=north]
setblock ~40 ~2 ~-67 minecraft:iron_door[half=upper,facing=north]
fill ~38 ~13 ~-67 ~45 ~13 ~-52 minecraft:deepslate_tile_slab
# 080 row_house -12,105 -5,115 h=9
fill ~-12 ~-3 ~105 ~-5 ~-1 ~115 minecraft:stone
fill ~-12 ~0 ~105 ~-5 ~9 ~115 minecraft:mud_bricks
fill ~-11 ~1 ~106 ~-6 ~8 ~114 minecraft:air
fill ~-11 ~4 ~106 ~-6 ~4 ~114 minecraft:smooth_stone
fill ~-11 ~8 ~106 ~-6 ~8 ~114 minecraft:smooth_stone
fill ~-10 ~2 ~105 ~-7 ~3 ~105 minecraft:gray_stained_glass
fill ~-10 ~2 ~115 ~-7 ~3 ~115 minecraft:light_gray_stained_glass
fill ~-10 ~6 ~105 ~-7 ~7 ~105 minecraft:gray_stained_glass
fill ~-10 ~6 ~115 ~-7 ~7 ~115 minecraft:light_gray_stained_glass
fill ~-11 ~0 ~105 ~-8 ~3 ~105 minecraft:spruce_planks
setblock ~-10 ~1 ~105 minecraft:iron_door[half=lower,facing=north]
setblock ~-10 ~2 ~105 minecraft:iron_door[half=upper,facing=north]
fill ~-12 ~10 ~105 ~-5 ~10 ~115 minecraft:deepslate_tile_slab
# 081 community -114,26 -107,38 h=7
fill ~-114 ~-3 ~26 ~-107 ~-1 ~38 minecraft:stone
fill ~-114 ~0 ~26 ~-107 ~7 ~38 minecraft:calcite
fill ~-113 ~1 ~27 ~-108 ~6 ~37 minecraft:air
fill ~-113 ~4 ~27 ~-108 ~4 ~37 minecraft:smooth_stone
fill ~-114 ~2 ~28 ~-114 ~3 ~36 minecraft:gray_stained_glass
fill ~-107 ~2 ~28 ~-107 ~3 ~36 minecraft:light_gray_stained_glass
fill ~-113 ~0 ~26 ~-110 ~3 ~26 minecraft:gray_concrete
setblock ~-112 ~1 ~26 minecraft:iron_door[half=lower,facing=north]
setblock ~-112 ~2 ~26 minecraft:iron_door[half=upper,facing=north]
fill ~-114 ~8 ~26 ~-107 ~8 ~38 minecraft:stone_brick_slab
# 082 shop_house 25,48 31,58 h=10
fill ~25 ~-3 ~48 ~31 ~-1 ~58 minecraft:stone
fill ~25 ~0 ~48 ~31 ~10 ~58 minecraft:bricks
fill ~26 ~1 ~49 ~30 ~9 ~57 minecraft:air
fill ~26 ~4 ~49 ~30 ~4 ~57 minecraft:smooth_stone
fill ~26 ~8 ~49 ~30 ~8 ~57 minecraft:smooth_stone
fill ~25 ~2 ~50 ~25 ~3 ~56 minecraft:gray_stained_glass
fill ~31 ~2 ~50 ~31 ~3 ~56 minecraft:light_gray_stained_glass
fill ~25 ~6 ~50 ~25 ~7 ~56 minecraft:gray_stained_glass
fill ~31 ~6 ~50 ~31 ~7 ~56 minecraft:light_gray_stained_glass
fill ~26 ~0 ~48 ~29 ~3 ~48 doomsday_decoration:hollowbrick
setblock ~27 ~1 ~48 minecraft:iron_door[half=lower,facing=north]
setblock ~27 ~2 ~48 minecraft:iron_door[half=upper,facing=north]
fill ~25 ~11 ~48 ~31 ~11 ~58 minecraft:deepslate_tile_slab
# 083 midrise_housing -30,-7 -19,0 h=24
fill ~-30 ~-3 ~-7 ~-19 ~-1 ~0 minecraft:stone
fill ~-30 ~0 ~-7 ~-19 ~24 ~0 minecraft:bricks
fill ~-29 ~1 ~-6 ~-20 ~23 ~-1 minecraft:air
fill ~-29 ~4 ~-6 ~-20 ~4 ~-1 minecraft:smooth_stone
fill ~-29 ~8 ~-6 ~-20 ~8 ~-1 minecraft:smooth_stone
fill ~-29 ~12 ~-6 ~-20 ~12 ~-1 minecraft:smooth_stone
fill ~-29 ~16 ~-6 ~-20 ~16 ~-1 minecraft:smooth_stone
fill ~-29 ~20 ~-6 ~-20 ~20 ~-1 minecraft:smooth_stone
fill ~-30 ~2 ~-5 ~-30 ~3 ~-2 minecraft:gray_stained_glass
fill ~-19 ~2 ~-5 ~-19 ~3 ~-2 minecraft:light_gray_stained_glass
fill ~-30 ~6 ~-5 ~-30 ~7 ~-2 minecraft:gray_stained_glass
fill ~-19 ~6 ~-5 ~-19 ~7 ~-2 minecraft:light_gray_stained_glass
fill ~-30 ~10 ~-5 ~-30 ~11 ~-2 minecraft:gray_stained_glass
fill ~-19 ~10 ~-5 ~-19 ~11 ~-2 minecraft:light_gray_stained_glass
fill ~-30 ~14 ~-5 ~-30 ~15 ~-2 minecraft:gray_stained_glass
fill ~-19 ~14 ~-5 ~-19 ~15 ~-2 minecraft:light_gray_stained_glass
fill ~-30 ~18 ~-5 ~-30 ~19 ~-2 minecraft:gray_stained_glass
fill ~-19 ~18 ~-5 ~-19 ~19 ~-2 minecraft:light_gray_stained_glass
fill ~-30 ~22 ~-5 ~-30 ~23 ~-2 minecraft:gray_stained_glass
fill ~-19 ~22 ~-5 ~-19 ~23 ~-2 minecraft:light_gray_stained_glass
fill ~-29 ~0 ~-7 ~-26 ~3 ~-7 doomsday_decoration:redbrick
setblock ~-28 ~1 ~-7 minecraft:iron_door[half=lower,facing=north]
setblock ~-28 ~2 ~-7 minecraft:iron_door[half=upper,facing=north]
fill ~-30 ~25 ~-7 ~-19 ~25 ~0 minecraft:deepslate_tile_slab
# 084 utility 73,111 88,120 h=10
fill ~73 ~-3 ~111 ~88 ~-1 ~120 minecraft:stone
fill ~73 ~0 ~111 ~88 ~10 ~120 minecraft:stone_bricks
fill ~74 ~1 ~112 ~87 ~9 ~119 minecraft:air
fill ~74 ~4 ~112 ~87 ~4 ~119 minecraft:smooth_stone
fill ~74 ~8 ~112 ~87 ~8 ~119 minecraft:smooth_stone
fill ~73 ~2 ~113 ~73 ~3 ~118 minecraft:gray_stained_glass
fill ~88 ~2 ~113 ~88 ~3 ~118 minecraft:light_gray_stained_glass
fill ~73 ~6 ~113 ~73 ~7 ~118 minecraft:gray_stained_glass
fill ~88 ~6 ~113 ~88 ~7 ~118 minecraft:light_gray_stained_glass
fill ~74 ~0 ~111 ~77 ~3 ~111 minecraft:orange_terracotta
setblock ~75 ~1 ~111 minecraft:iron_door[half=lower,facing=north]
setblock ~75 ~2 ~111 minecraft:iron_door[half=upper,facing=north]
fill ~73 ~11 ~111 ~88 ~11 ~120 minecraft:stone_brick_slab
# 085 mixed_use -25,45 -19,53 h=24
fill ~-25 ~-3 ~45 ~-19 ~-1 ~53 minecraft:stone
fill ~-25 ~0 ~45 ~-19 ~24 ~53 minecraft:light_gray_concrete
fill ~-24 ~1 ~46 ~-20 ~23 ~52 minecraft:air
fill ~-24 ~4 ~46 ~-20 ~4 ~52 minecraft:smooth_stone
fill ~-24 ~8 ~46 ~-20 ~8 ~52 minecraft:smooth_stone
fill ~-24 ~12 ~46 ~-20 ~12 ~52 minecraft:smooth_stone
fill ~-24 ~16 ~46 ~-20 ~16 ~52 minecraft:smooth_stone
fill ~-24 ~20 ~46 ~-20 ~20 ~52 minecraft:smooth_stone
fill ~-23 ~2 ~45 ~-21 ~3 ~45 minecraft:gray_stained_glass
fill ~-23 ~2 ~53 ~-21 ~3 ~53 minecraft:light_gray_stained_glass
fill ~-23 ~6 ~45 ~-21 ~7 ~45 minecraft:gray_stained_glass
fill ~-23 ~6 ~53 ~-21 ~7 ~53 minecraft:light_gray_stained_glass
fill ~-23 ~10 ~45 ~-21 ~11 ~45 minecraft:gray_stained_glass
fill ~-23 ~10 ~53 ~-21 ~11 ~53 minecraft:light_gray_stained_glass
fill ~-23 ~14 ~45 ~-21 ~15 ~45 minecraft:gray_stained_glass
fill ~-23 ~14 ~53 ~-21 ~15 ~53 minecraft:light_gray_stained_glass
fill ~-23 ~18 ~45 ~-21 ~19 ~45 minecraft:gray_stained_glass
fill ~-23 ~18 ~53 ~-21 ~19 ~53 minecraft:light_gray_stained_glass
fill ~-23 ~22 ~45 ~-21 ~23 ~45 minecraft:gray_stained_glass
fill ~-23 ~22 ~53 ~-21 ~23 ~53 minecraft:light_gray_stained_glass
fill ~-24 ~0 ~45 ~-21 ~3 ~45 doomsday_decoration:cementwall
setblock ~-23 ~1 ~45 minecraft:iron_door[half=lower,facing=north]
setblock ~-23 ~2 ~45 minecraft:iron_door[half=upper,facing=north]
fill ~-25 ~25 ~45 ~-19 ~25 ~53 minecraft:smooth_stone_slab
# 086 detached_house -78,112 -72,123 h=9
fill ~-78 ~-3 ~112 ~-72 ~-1 ~123 minecraft:stone
fill ~-78 ~0 ~112 ~-72 ~9 ~123 minecraft:white_terracotta
fill ~-77 ~1 ~113 ~-73 ~8 ~122 minecraft:air
fill ~-77 ~4 ~113 ~-73 ~4 ~122 minecraft:smooth_stone
fill ~-77 ~8 ~113 ~-73 ~8 ~122 minecraft:smooth_stone
fill ~-78 ~2 ~114 ~-78 ~3 ~121 minecraft:gray_stained_glass
fill ~-72 ~2 ~114 ~-72 ~3 ~121 minecraft:light_gray_stained_glass
fill ~-78 ~6 ~114 ~-78 ~7 ~121 minecraft:gray_stained_glass
fill ~-72 ~6 ~114 ~-72 ~7 ~121 minecraft:light_gray_stained_glass
fill ~-77 ~0 ~112 ~-74 ~3 ~112 minecraft:dark_oak_planks
setblock ~-76 ~1 ~112 minecraft:iron_door[half=lower,facing=north]
setblock ~-76 ~2 ~112 minecraft:iron_door[half=upper,facing=north]
fill ~-78 ~10 ~112 ~-72 ~10 ~123 minecraft:dark_oak_slab
# 087 local_shop -67,81 -59,92 h=5
fill ~-67 ~-3 ~81 ~-59 ~-1 ~92 minecraft:stone
fill ~-67 ~0 ~81 ~-59 ~5 ~92 minecraft:mud_bricks
fill ~-66 ~1 ~82 ~-60 ~4 ~91 minecraft:air
fill ~-66 ~4 ~82 ~-60 ~4 ~91 minecraft:smooth_stone
fill ~-67 ~2 ~83 ~-67 ~3 ~90 minecraft:gray_stained_glass
fill ~-59 ~2 ~83 ~-59 ~3 ~90 minecraft:light_gray_stained_glass
fill ~-66 ~0 ~81 ~-63 ~3 ~81 minecraft:spruce_planks
setblock ~-65 ~1 ~81 minecraft:iron_door[half=lower,facing=north]
setblock ~-65 ~2 ~81 minecraft:iron_door[half=upper,facing=north]
fill ~-67 ~6 ~81 ~-59 ~6 ~92 minecraft:deepslate_tile_slab
# 088 apartment 101,37 107,48 h=11
fill ~101 ~-3 ~37 ~107 ~-1 ~48 minecraft:stone
fill ~101 ~0 ~37 ~107 ~11 ~48 minecraft:white_concrete
fill ~102 ~1 ~38 ~106 ~10 ~47 minecraft:air
fill ~102 ~4 ~38 ~106 ~4 ~47 minecraft:smooth_stone
fill ~102 ~8 ~38 ~106 ~8 ~47 minecraft:smooth_stone
fill ~103 ~2 ~37 ~105 ~3 ~37 minecraft:gray_stained_glass
fill ~103 ~2 ~48 ~105 ~3 ~48 minecraft:light_gray_stained_glass
fill ~103 ~6 ~37 ~105 ~7 ~37 minecraft:gray_stained_glass
fill ~103 ~6 ~48 ~105 ~7 ~48 minecraft:light_gray_stained_glass
fill ~102 ~0 ~37 ~105 ~3 ~37 minecraft:cyan_terracotta
setblock ~103 ~1 ~37 minecraft:iron_door[half=lower,facing=north]
setblock ~103 ~2 ~37 minecraft:iron_door[half=upper,facing=north]
fill ~101 ~12 ~37 ~107 ~12 ~48 minecraft:smooth_stone_slab
# 089 local_shop -106,-55 -100,-46 h=9
fill ~-106 ~-3 ~-55 ~-100 ~-1 ~-46 minecraft:stone
fill ~-106 ~0 ~-55 ~-100 ~9 ~-46 minecraft:calcite
fill ~-105 ~1 ~-54 ~-101 ~8 ~-47 minecraft:air
fill ~-105 ~4 ~-54 ~-101 ~4 ~-47 minecraft:smooth_stone
fill ~-105 ~8 ~-54 ~-101 ~8 ~-47 minecraft:smooth_stone
fill ~-104 ~2 ~-55 ~-102 ~3 ~-55 minecraft:gray_stained_glass
fill ~-104 ~2 ~-46 ~-102 ~3 ~-46 minecraft:light_gray_stained_glass
fill ~-104 ~6 ~-55 ~-102 ~7 ~-55 minecraft:gray_stained_glass
fill ~-104 ~6 ~-46 ~-102 ~7 ~-46 minecraft:light_gray_stained_glass
fill ~-105 ~0 ~-55 ~-102 ~3 ~-55 minecraft:gray_concrete
setblock ~-104 ~1 ~-55 minecraft:iron_door[half=lower,facing=north]
setblock ~-104 ~2 ~-55 minecraft:iron_door[half=upper,facing=north]
fill ~-106 ~10 ~-55 ~-100 ~10 ~-46 minecraft:stone_brick_slab
# 090 station_shop 72,-125 83,-115 h=8
fill ~72 ~-3 ~-125 ~83 ~-1 ~-115 minecraft:stone
fill ~72 ~0 ~-125 ~83 ~8 ~-115 minecraft:bricks
fill ~73 ~1 ~-124 ~82 ~7 ~-116 minecraft:air
fill ~73 ~4 ~-124 ~82 ~4 ~-116 minecraft:smooth_stone
fill ~74 ~2 ~-125 ~81 ~3 ~-125 minecraft:gray_stained_glass
fill ~74 ~2 ~-115 ~81 ~3 ~-115 minecraft:light_gray_stained_glass
fill ~74 ~6 ~-125 ~81 ~7 ~-125 minecraft:gray_stained_glass
fill ~74 ~6 ~-115 ~81 ~7 ~-115 minecraft:light_gray_stained_glass
fill ~73 ~0 ~-125 ~76 ~3 ~-125 minecraft:gray_concrete
setblock ~74 ~1 ~-125 minecraft:iron_door[half=lower,facing=north]
setblock ~74 ~2 ~-125 minecraft:iron_door[half=upper,facing=north]
fill ~72 ~9 ~-125 ~83 ~9 ~-115 minecraft:deepslate_tile_slab
# 091 garage -23,-123 -4,-113 h=12
fill ~-23 ~-3 ~-123 ~-4 ~-1 ~-113 minecraft:stone
fill ~-23 ~0 ~-123 ~-4 ~12 ~-113 minecraft:bricks
fill ~-22 ~1 ~-122 ~-5 ~11 ~-114 minecraft:air
fill ~-22 ~4 ~-122 ~-5 ~4 ~-114 minecraft:smooth_stone
fill ~-22 ~8 ~-122 ~-5 ~8 ~-114 minecraft:smooth_stone
fill ~-21 ~2 ~-123 ~-6 ~3 ~-123 minecraft:gray_stained_glass
fill ~-21 ~2 ~-113 ~-6 ~3 ~-113 minecraft:light_gray_stained_glass
fill ~-21 ~6 ~-123 ~-6 ~7 ~-123 minecraft:gray_stained_glass
fill ~-21 ~6 ~-113 ~-6 ~7 ~-113 minecraft:light_gray_stained_glass
fill ~-21 ~10 ~-123 ~-6 ~11 ~-123 minecraft:gray_stained_glass
fill ~-21 ~10 ~-113 ~-6 ~11 ~-113 minecraft:light_gray_stained_glass
fill ~-22 ~0 ~-123 ~-19 ~3 ~-123 minecraft:gray_concrete
setblock ~-21 ~1 ~-123 minecraft:iron_door[half=lower,facing=north]
setblock ~-21 ~2 ~-123 minecraft:iron_door[half=upper,facing=north]
fill ~-23 ~13 ~-123 ~-4 ~13 ~-113 minecraft:deepslate_tile_slab
# 092 row_house 89,-62 94,-53 h=5
fill ~89 ~-3 ~-62 ~94 ~-1 ~-53 minecraft:stone
fill ~89 ~0 ~-62 ~94 ~5 ~-53 minecraft:white_terracotta
fill ~90 ~1 ~-61 ~93 ~4 ~-54 minecraft:air
fill ~90 ~4 ~-61 ~93 ~4 ~-54 minecraft:smooth_stone
fill ~89 ~2 ~-60 ~89 ~3 ~-55 minecraft:gray_stained_glass
fill ~94 ~2 ~-60 ~94 ~3 ~-55 minecraft:light_gray_stained_glass
fill ~90 ~0 ~-62 ~93 ~3 ~-62 minecraft:dark_oak_planks
setblock ~91 ~1 ~-62 minecraft:iron_door[half=lower,facing=north]
setblock ~91 ~2 ~-62 minecraft:iron_door[half=upper,facing=north]
fill ~89 ~6 ~-62 ~94 ~6 ~-53 minecraft:dark_oak_slab
# 093 restaurant 98,-27 104,-21 h=7
fill ~98 ~-3 ~-27 ~104 ~-1 ~-21 minecraft:stone
fill ~98 ~0 ~-27 ~104 ~7 ~-21 minecraft:white_concrete
fill ~99 ~1 ~-26 ~103 ~6 ~-22 minecraft:air
fill ~99 ~4 ~-26 ~103 ~4 ~-22 minecraft:smooth_stone
fill ~100 ~2 ~-27 ~102 ~3 ~-27 minecraft:gray_stained_glass
fill ~100 ~2 ~-21 ~102 ~3 ~-21 minecraft:light_gray_stained_glass
fill ~99 ~0 ~-27 ~102 ~3 ~-27 minecraft:cyan_terracotta
setblock ~100 ~1 ~-27 minecraft:iron_door[half=lower,facing=north]
setblock ~100 ~2 ~-27 minecraft:iron_door[half=upper,facing=north]
fill ~98 ~8 ~-27 ~104 ~8 ~-21 minecraft:smooth_stone_slab
# 094 garage -122,-125 -108,-116 h=10
fill ~-122 ~-3 ~-125 ~-108 ~-1 ~-116 minecraft:stone
fill ~-122 ~0 ~-125 ~-108 ~10 ~-116 minecraft:stone_bricks
fill ~-121 ~1 ~-124 ~-109 ~9 ~-117 minecraft:air
fill ~-121 ~4 ~-124 ~-109 ~4 ~-117 minecraft:smooth_stone
fill ~-121 ~8 ~-124 ~-109 ~8 ~-117 minecraft:smooth_stone
fill ~-122 ~2 ~-123 ~-122 ~3 ~-118 minecraft:gray_stained_glass
fill ~-108 ~2 ~-123 ~-108 ~3 ~-118 minecraft:light_gray_stained_glass
fill ~-122 ~6 ~-123 ~-122 ~7 ~-118 minecraft:gray_stained_glass
fill ~-108 ~6 ~-123 ~-108 ~7 ~-118 minecraft:light_gray_stained_glass
fill ~-121 ~0 ~-125 ~-118 ~3 ~-125 doomsday_decoration:ironsheetwall_2
setblock ~-120 ~1 ~-125 minecraft:iron_door[half=lower,facing=north]
setblock ~-120 ~2 ~-125 minecraft:iron_door[half=upper,facing=north]
fill ~-122 ~11 ~-125 ~-108 ~11 ~-116 minecraft:smooth_stone_slab
# 095 community -100,57 -94,63 h=5
fill ~-100 ~-3 ~57 ~-94 ~-1 ~63 minecraft:stone
fill ~-100 ~0 ~57 ~-94 ~5 ~63 minecraft:mud_bricks
fill ~-99 ~1 ~58 ~-95 ~4 ~62 minecraft:air
fill ~-99 ~4 ~58 ~-95 ~4 ~62 minecraft:smooth_stone
fill ~-98 ~2 ~57 ~-96 ~3 ~57 minecraft:gray_stained_glass
fill ~-98 ~2 ~63 ~-96 ~3 ~63 minecraft:light_gray_stained_glass
fill ~-99 ~0 ~57 ~-96 ~3 ~57 minecraft:spruce_planks
setblock ~-98 ~1 ~57 minecraft:iron_door[half=lower,facing=north]
setblock ~-98 ~2 ~57 minecraft:iron_door[half=upper,facing=north]
fill ~-100 ~6 ~57 ~-94 ~6 ~63 minecraft:deepslate_tile_slab
# 096 retail 14,3 26,10 h=20
fill ~14 ~-3 ~3 ~26 ~-1 ~10 minecraft:stone
fill ~14 ~0 ~3 ~26 ~20 ~10 minecraft:white_terracotta
fill ~15 ~1 ~4 ~25 ~19 ~9 minecraft:air
fill ~15 ~4 ~4 ~25 ~4 ~9 minecraft:smooth_stone
fill ~15 ~8 ~4 ~25 ~8 ~9 minecraft:smooth_stone
fill ~15 ~12 ~4 ~25 ~12 ~9 minecraft:smooth_stone
fill ~15 ~16 ~4 ~25 ~16 ~9 minecraft:smooth_stone
fill ~16 ~2 ~3 ~24 ~3 ~3 minecraft:gray_stained_glass
fill ~16 ~2 ~10 ~24 ~3 ~10 minecraft:light_gray_stained_glass
fill ~16 ~6 ~3 ~24 ~7 ~3 minecraft:gray_stained_glass
fill ~16 ~6 ~10 ~24 ~7 ~10 minecraft:light_gray_stained_glass
fill ~16 ~10 ~3 ~24 ~11 ~3 minecraft:gray_stained_glass
fill ~16 ~10 ~10 ~24 ~11 ~10 minecraft:light_gray_stained_glass
fill ~16 ~14 ~3 ~24 ~15 ~3 minecraft:gray_stained_glass
fill ~16 ~14 ~10 ~24 ~15 ~10 minecraft:light_gray_stained_glass
fill ~16 ~18 ~3 ~24 ~19 ~3 minecraft:gray_stained_glass
fill ~16 ~18 ~10 ~24 ~19 ~10 minecraft:light_gray_stained_glass
fill ~15 ~0 ~3 ~18 ~3 ~3 minecraft:gray_concrete
setblock ~16 ~1 ~3 minecraft:iron_door[half=lower,facing=north]
setblock ~16 ~2 ~3 minecraft:iron_door[half=upper,facing=north]
fill ~14 ~21 ~3 ~26 ~21 ~10 minecraft:stone_brick_slab
# 097 local_shop -63,108 -57,116 h=7
fill ~-63 ~-3 ~108 ~-57 ~-1 ~116 minecraft:stone
fill ~-63 ~0 ~108 ~-57 ~7 ~116 minecraft:calcite
fill ~-62 ~1 ~109 ~-58 ~6 ~115 minecraft:air
fill ~-62 ~4 ~109 ~-58 ~4 ~115 minecraft:smooth_stone
fill ~-63 ~2 ~110 ~-63 ~3 ~114 minecraft:gray_stained_glass
fill ~-57 ~2 ~110 ~-57 ~3 ~114 minecraft:light_gray_stained_glass
fill ~-62 ~0 ~108 ~-59 ~3 ~108 minecraft:gray_concrete
setblock ~-61 ~1 ~108 minecraft:iron_door[half=lower,facing=north]
setblock ~-61 ~2 ~108 minecraft:iron_door[half=upper,facing=north]
fill ~-63 ~8 ~108 ~-57 ~8 ~116 minecraft:stone_brick_slab
# 098 midrise_housing 38,-31 44,-22 h=20
fill ~38 ~-3 ~-31 ~44 ~-1 ~-22 minecraft:stone
fill ~38 ~0 ~-31 ~44 ~20 ~-22 minecraft:white_terracotta
fill ~39 ~1 ~-30 ~43 ~19 ~-23 minecraft:air
fill ~39 ~4 ~-30 ~43 ~4 ~-23 minecraft:smooth_stone
fill ~39 ~8 ~-30 ~43 ~8 ~-23 minecraft:smooth_stone
fill ~39 ~12 ~-30 ~43 ~12 ~-23 minecraft:smooth_stone
fill ~39 ~16 ~-30 ~43 ~16 ~-23 minecraft:smooth_stone
fill ~40 ~2 ~-31 ~42 ~3 ~-31 minecraft:gray_stained_glass
fill ~40 ~2 ~-22 ~42 ~3 ~-22 minecraft:light_gray_stained_glass
fill ~40 ~6 ~-31 ~42 ~7 ~-31 minecraft:gray_stained_glass
fill ~40 ~6 ~-22 ~42 ~7 ~-22 minecraft:light_gray_stained_glass
fill ~40 ~10 ~-31 ~42 ~11 ~-31 minecraft:gray_stained_glass
fill ~40 ~10 ~-22 ~42 ~11 ~-22 minecraft:light_gray_stained_glass
fill ~40 ~14 ~-31 ~42 ~15 ~-31 minecraft:gray_stained_glass
fill ~40 ~14 ~-22 ~42 ~15 ~-22 minecraft:light_gray_stained_glass
fill ~40 ~18 ~-31 ~42 ~19 ~-31 minecraft:gray_stained_glass
fill ~40 ~18 ~-22 ~42 ~19 ~-22 minecraft:light_gray_stained_glass
fill ~39 ~0 ~-31 ~42 ~3 ~-31 minecraft:gray_concrete
setblock ~40 ~1 ~-31 minecraft:iron_door[half=lower,facing=north]
setblock ~40 ~2 ~-31 minecraft:iron_door[half=upper,facing=north]
fill ~38 ~21 ~-31 ~44 ~21 ~-22 minecraft:stone_brick_slab
# 099 apartment 93,72 101,80 h=9
fill ~93 ~-3 ~72 ~101 ~-1 ~80 minecraft:stone
fill ~93 ~0 ~72 ~101 ~9 ~80 minecraft:white_concrete
fill ~94 ~1 ~73 ~100 ~8 ~79 minecraft:air
fill ~94 ~4 ~73 ~100 ~4 ~79 minecraft:smooth_stone
fill ~94 ~8 ~73 ~100 ~8 ~79 minecraft:smooth_stone
fill ~95 ~2 ~72 ~99 ~3 ~72 minecraft:gray_stained_glass
fill ~95 ~2 ~80 ~99 ~3 ~80 minecraft:light_gray_stained_glass
fill ~95 ~6 ~72 ~99 ~7 ~72 minecraft:gray_stained_glass
fill ~95 ~6 ~80 ~99 ~7 ~80 minecraft:light_gray_stained_glass
fill ~94 ~0 ~72 ~97 ~3 ~72 minecraft:cyan_terracotta
setblock ~95 ~1 ~72 minecraft:iron_door[half=lower,facing=north]
setblock ~95 ~2 ~72 minecraft:iron_door[half=upper,facing=north]
fill ~93 ~10 ~72 ~101 ~10 ~80 minecraft:smooth_stone_slab
# 100 row_house -111,85 -103,93 h=11
fill ~-111 ~-3 ~85 ~-103 ~-1 ~93 minecraft:stone
fill ~-111 ~0 ~85 ~-103 ~11 ~93 minecraft:white_terracotta
fill ~-110 ~1 ~86 ~-104 ~10 ~92 minecraft:air
fill ~-110 ~4 ~86 ~-104 ~4 ~92 minecraft:smooth_stone
fill ~-110 ~8 ~86 ~-104 ~8 ~92 minecraft:smooth_stone
fill ~-111 ~2 ~87 ~-111 ~3 ~91 minecraft:gray_stained_glass
fill ~-103 ~2 ~87 ~-103 ~3 ~91 minecraft:light_gray_stained_glass
fill ~-111 ~6 ~87 ~-111 ~7 ~91 minecraft:gray_stained_glass
fill ~-103 ~6 ~87 ~-103 ~7 ~91 minecraft:light_gray_stained_glass
fill ~-110 ~0 ~85 ~-107 ~3 ~85 minecraft:dark_oak_planks
setblock ~-109 ~1 ~85 minecraft:iron_door[half=lower,facing=north]
setblock ~-109 ~2 ~85 minecraft:iron_door[half=upper,facing=north]
fill ~-111 ~12 ~85 ~-103 ~12 ~93 minecraft:dark_oak_slab
