# Buildings 233..240
# 233 shop_house style=storefront context=collector_front facing=north
fill ~-81 ~-3 ~-60 ~-77 ~-1 ~-55 minecraft:stone
fill ~-81 ~0 ~-60 ~-77 ~9 ~-55 minecraft:smooth_sandstone
fill ~-80 ~1 ~-59 ~-78 ~8 ~-56 minecraft:air
fill ~-80 ~4 ~-59 ~-78 ~4 ~-56 minecraft:smooth_stone
fill ~-80 ~8 ~-59 ~-78 ~8 ~-56 minecraft:smooth_stone
fill ~-79 ~2 ~-60 ~-79 ~3 ~-60 minecraft:gray_stained_glass
fill ~-79 ~2 ~-55 ~-79 ~3 ~-55 minecraft:light_gray_stained_glass
fill ~-81 ~2 ~-58 ~-81 ~3 ~-58 minecraft:gray_stained_glass
fill ~-77 ~2 ~-58 ~-77 ~3 ~-58 minecraft:light_gray_stained_glass
fill ~-79 ~6 ~-60 ~-79 ~7 ~-60 minecraft:gray_stained_glass
fill ~-79 ~6 ~-55 ~-79 ~7 ~-55 minecraft:light_gray_stained_glass
fill ~-81 ~6 ~-58 ~-81 ~7 ~-58 minecraft:gray_stained_glass
fill ~-77 ~6 ~-58 ~-77 ~7 ~-58 minecraft:light_gray_stained_glass
setblock ~-79 ~1 ~-60 minecraft:iron_door[half=lower,facing=north]
setblock ~-79 ~2 ~-60 minecraft:iron_door[half=upper,facing=north]
fill ~-80 ~1 ~-60 ~-78 ~3 ~-60 minecraft:cyan_stained_glass
setblock ~-79 ~1 ~-60 minecraft:iron_door[half=lower,facing=north]
setblock ~-79 ~2 ~-60 minecraft:iron_door[half=upper,facing=north]
setblock ~-79 ~3 ~-61 minecraft:red_wool
fill ~-81 ~10 ~-60 ~-77 ~10 ~-55 minecraft:stone_brick_slab
# 234 small_office style=bay_office context=back_block facing=north
fill ~-104 ~-3 ~120 ~-97 ~-1 ~125 minecraft:stone
fill ~-104 ~0 ~120 ~-97 ~11 ~125 minecraft:white_terracotta
fill ~-103 ~1 ~121 ~-98 ~10 ~124 minecraft:air
fill ~-103 ~4 ~121 ~-98 ~4 ~124 minecraft:smooth_stone
fill ~-103 ~8 ~121 ~-98 ~8 ~124 minecraft:smooth_stone
fill ~-102 ~2 ~120 ~-102 ~3 ~120 minecraft:gray_stained_glass
fill ~-102 ~2 ~125 ~-102 ~3 ~125 minecraft:light_gray_stained_glass
fill ~-99 ~2 ~120 ~-99 ~3 ~120 minecraft:gray_stained_glass
fill ~-99 ~2 ~125 ~-99 ~3 ~125 minecraft:light_gray_stained_glass
fill ~-104 ~2 ~122 ~-104 ~3 ~122 minecraft:gray_stained_glass
fill ~-97 ~2 ~122 ~-97 ~3 ~122 minecraft:light_gray_stained_glass
fill ~-102 ~6 ~120 ~-102 ~7 ~120 minecraft:gray_stained_glass
fill ~-102 ~6 ~125 ~-102 ~7 ~125 minecraft:light_gray_stained_glass
fill ~-99 ~6 ~120 ~-99 ~7 ~120 minecraft:gray_stained_glass
fill ~-99 ~6 ~125 ~-99 ~7 ~125 minecraft:light_gray_stained_glass
fill ~-104 ~6 ~122 ~-104 ~7 ~122 minecraft:gray_stained_glass
fill ~-97 ~6 ~122 ~-97 ~7 ~122 minecraft:light_gray_stained_glass
setblock ~-101 ~1 ~120 minecraft:iron_door[half=lower,facing=north]
setblock ~-101 ~2 ~120 minecraft:iron_door[half=upper,facing=north]
fill ~-104 ~7 ~120 ~-97 ~11 ~125 minecraft:air
fill ~-103 ~7 ~121 ~-98 ~11 ~124 minecraft:white_terracotta
fill ~-102 ~8 ~122 ~-99 ~10 ~123 minecraft:air
fill ~-103 ~12 ~121 ~-98 ~12 ~124 minecraft:dark_oak_slab
fill ~-102 ~2 ~120 ~-99 ~7 ~120 minecraft:blue_stained_glass
fill ~-102 ~13 ~122 ~-100 ~14 ~124 minecraft:light_gray_concrete
setblock ~-99 ~13 ~123 minecraft:lightning_rod
# 235 mixed_use style=mixed_facade context=arterial_front facing=east
fill ~3 ~-3 ~63 ~7 ~-1 ~72 minecraft:stone
fill ~3 ~0 ~63 ~7 ~5 ~72 minecraft:smooth_sandstone
fill ~4 ~1 ~64 ~6 ~4 ~71 minecraft:air
fill ~4 ~4 ~64 ~6 ~4 ~71 minecraft:smooth_stone
fill ~5 ~2 ~63 ~5 ~3 ~63 minecraft:gray_stained_glass
fill ~5 ~2 ~72 ~5 ~3 ~72 minecraft:light_gray_stained_glass
fill ~3 ~2 ~65 ~3 ~3 ~65 minecraft:gray_stained_glass
fill ~7 ~2 ~65 ~7 ~3 ~65 minecraft:light_gray_stained_glass
fill ~3 ~2 ~68 ~3 ~3 ~68 minecraft:gray_stained_glass
fill ~7 ~2 ~68 ~7 ~3 ~68 minecraft:light_gray_stained_glass
setblock ~7 ~1 ~67 minecraft:iron_door[half=lower,facing=east]
setblock ~7 ~2 ~67 minecraft:iron_door[half=upper,facing=east]
fill ~3 ~6 ~63 ~7 ~6 ~72 minecraft:stone_brick_slab
# 236 detached_house style=rowhouse context=back_block facing=north
fill ~-69 ~-3 ~90 ~-65 ~-1 ~95 minecraft:stone
fill ~-69 ~0 ~90 ~-65 ~5 ~95 minecraft:mud_bricks
fill ~-68 ~1 ~91 ~-66 ~4 ~94 minecraft:air
fill ~-68 ~4 ~91 ~-66 ~4 ~94 minecraft:smooth_stone
fill ~-67 ~2 ~90 ~-67 ~3 ~90 minecraft:gray_stained_glass
fill ~-67 ~2 ~95 ~-67 ~3 ~95 minecraft:light_gray_stained_glass
fill ~-69 ~2 ~92 ~-69 ~3 ~92 minecraft:gray_stained_glass
fill ~-65 ~2 ~92 ~-65 ~3 ~92 minecraft:light_gray_stained_glass
setblock ~-67 ~1 ~90 minecraft:iron_door[half=lower,facing=north]
setblock ~-67 ~2 ~90 minecraft:iron_door[half=upper,facing=north]
fill ~-69 ~6 ~90 ~-65 ~6 ~95 minecraft:deepslate_tile_slab
fill ~-68 ~7 ~91 ~-66 ~7 ~94 minecraft:deepslate_tile_slab
setblock ~-67 ~3 ~89 minecraft:dark_oak_slab[type=top]
# 237 lowrise_housing style=rowhouse context=back_block facing=north
fill ~-49 ~-3 ~119 ~-45 ~-1 ~125 minecraft:stone
fill ~-49 ~0 ~119 ~-45 ~9 ~125 minecraft:calcite
fill ~-48 ~1 ~120 ~-46 ~8 ~124 minecraft:air
fill ~-48 ~4 ~120 ~-46 ~4 ~124 minecraft:smooth_stone
fill ~-48 ~8 ~120 ~-46 ~8 ~124 minecraft:smooth_stone
fill ~-47 ~2 ~119 ~-47 ~3 ~119 minecraft:gray_stained_glass
fill ~-47 ~2 ~125 ~-47 ~3 ~125 minecraft:light_gray_stained_glass
fill ~-49 ~2 ~121 ~-49 ~3 ~121 minecraft:gray_stained_glass
fill ~-45 ~2 ~121 ~-45 ~3 ~121 minecraft:light_gray_stained_glass
fill ~-47 ~6 ~119 ~-47 ~7 ~119 minecraft:gray_stained_glass
fill ~-47 ~6 ~125 ~-47 ~7 ~125 minecraft:light_gray_stained_glass
fill ~-49 ~6 ~121 ~-49 ~7 ~121 minecraft:gray_stained_glass
fill ~-45 ~6 ~121 ~-45 ~7 ~121 minecraft:light_gray_stained_glass
setblock ~-47 ~1 ~119 minecraft:iron_door[half=lower,facing=north]
setblock ~-47 ~2 ~119 minecraft:iron_door[half=upper,facing=north]
fill ~-49 ~10 ~119 ~-45 ~10 ~125 minecraft:stone_brick_slab
fill ~-48 ~11 ~120 ~-46 ~11 ~124 minecraft:stone_brick_slab
setblock ~-47 ~3 ~118 minecraft:dark_oak_slab[type=top]
fill ~-47 ~11 ~121 ~-46 ~12 ~123 minecraft:light_gray_concrete
setblock ~-46 ~11 ~122 minecraft:lightning_rod
# 238 medical_center style=bay_office context=arterial_front facing=north
fill ~-68 ~-3 ~-13 ~-64 ~-1 ~-8 minecraft:stone
fill ~-68 ~0 ~-13 ~-64 ~9 ~-8 minecraft:bricks
fill ~-67 ~1 ~-12 ~-65 ~8 ~-9 minecraft:air
fill ~-67 ~4 ~-12 ~-65 ~4 ~-9 minecraft:smooth_stone
fill ~-67 ~8 ~-12 ~-65 ~8 ~-9 minecraft:smooth_stone
fill ~-66 ~2 ~-13 ~-66 ~3 ~-13 minecraft:gray_stained_glass
fill ~-66 ~2 ~-8 ~-66 ~3 ~-8 minecraft:light_gray_stained_glass
fill ~-68 ~2 ~-11 ~-68 ~3 ~-11 minecraft:gray_stained_glass
fill ~-64 ~2 ~-11 ~-64 ~3 ~-11 minecraft:light_gray_stained_glass
fill ~-66 ~6 ~-13 ~-66 ~7 ~-13 minecraft:gray_stained_glass
fill ~-66 ~6 ~-8 ~-66 ~7 ~-8 minecraft:light_gray_stained_glass
fill ~-68 ~6 ~-11 ~-68 ~7 ~-11 minecraft:gray_stained_glass
fill ~-64 ~6 ~-11 ~-64 ~7 ~-11 minecraft:light_gray_stained_glass
setblock ~-66 ~1 ~-13 minecraft:iron_door[half=lower,facing=north]
setblock ~-66 ~2 ~-13 minecraft:iron_door[half=upper,facing=north]
# 239 workshop style=rowhouse context=back_block facing=north
fill ~81 ~-3 ~119 ~85 ~-1 ~124 minecraft:stone
fill ~81 ~0 ~119 ~85 ~7 ~124 minecraft:gray_concrete
fill ~82 ~1 ~120 ~84 ~6 ~123 minecraft:air
fill ~82 ~4 ~120 ~84 ~4 ~123 minecraft:smooth_stone
fill ~83 ~2 ~119 ~83 ~3 ~119 minecraft:gray_stained_glass
fill ~83 ~2 ~124 ~83 ~3 ~124 minecraft:light_gray_stained_glass
fill ~81 ~2 ~121 ~81 ~3 ~121 minecraft:gray_stained_glass
fill ~85 ~2 ~121 ~85 ~3 ~121 minecraft:light_gray_stained_glass
setblock ~83 ~1 ~119 minecraft:iron_door[half=lower,facing=north]
setblock ~83 ~2 ~119 minecraft:iron_door[half=upper,facing=north]
fill ~81 ~8 ~119 ~85 ~8 ~124 minecraft:smooth_stone_slab
fill ~82 ~9 ~120 ~84 ~9 ~123 minecraft:smooth_stone_slab
setblock ~83 ~3 ~118 minecraft:dark_oak_slab[type=top]
# 240 workshop style=storefront context=waterfront_front facing=west
fill ~106 ~-3 ~10 ~109 ~-1 ~15 minecraft:stone
fill ~106 ~0 ~10 ~109 ~9 ~15 minecraft:bricks
fill ~107 ~1 ~11 ~108 ~8 ~14 minecraft:air
fill ~107 ~4 ~11 ~108 ~4 ~14 minecraft:smooth_stone
fill ~107 ~8 ~11 ~108 ~8 ~14 minecraft:smooth_stone
fill ~106 ~2 ~12 ~106 ~3 ~12 minecraft:gray_stained_glass
fill ~109 ~2 ~12 ~109 ~3 ~12 minecraft:light_gray_stained_glass
fill ~106 ~6 ~12 ~106 ~7 ~12 minecraft:gray_stained_glass
fill ~109 ~6 ~12 ~109 ~7 ~12 minecraft:light_gray_stained_glass
setblock ~106 ~1 ~12 minecraft:iron_door[half=lower,facing=west]
setblock ~106 ~2 ~12 minecraft:iron_door[half=upper,facing=west]
fill ~106 ~1 ~11 ~106 ~3 ~14 minecraft:cyan_stained_glass
setblock ~106 ~1 ~12 minecraft:iron_door[half=lower,facing=west]
setblock ~106 ~2 ~12 minecraft:iron_door[half=upper,facing=west]
setblock ~105 ~3 ~12 minecraft:red_wool
fill ~106 ~10 ~10 ~109 ~10 ~15 minecraft:deepslate_tile_slab
fill ~108 ~11 ~12 ~108 ~12 ~14 minecraft:light_gray_concrete
setblock ~108 ~11 ~13 minecraft:lightning_rod
