# Buildings 151..175
# 151 apartment 97,62 102,69 h=7
fill ~97 ~-3 ~62 ~102 ~-1 ~69 minecraft:stone
fill ~97 ~0 ~62 ~102 ~7 ~69 minecraft:white_concrete
fill ~98 ~1 ~63 ~101 ~6 ~68 minecraft:air
fill ~98 ~4 ~63 ~101 ~4 ~68 minecraft:smooth_stone
fill ~97 ~2 ~64 ~97 ~3 ~67 minecraft:gray_stained_glass
fill ~102 ~2 ~64 ~102 ~3 ~67 minecraft:light_gray_stained_glass
fill ~98 ~0 ~62 ~101 ~3 ~62 minecraft:cyan_terracotta
setblock ~99 ~1 ~62 minecraft:iron_door[half=lower,facing=north]
setblock ~99 ~2 ~62 minecraft:iron_door[half=upper,facing=north]
fill ~97 ~8 ~62 ~102 ~8 ~69 minecraft:smooth_stone_slab
# 152 mixed_use 41,6 47,13 h=16
fill ~41 ~-3 ~6 ~47 ~-1 ~13 minecraft:stone
fill ~41 ~0 ~6 ~47 ~16 ~13 minecraft:white_terracotta
fill ~42 ~1 ~7 ~46 ~15 ~12 minecraft:air
fill ~42 ~4 ~7 ~46 ~4 ~12 minecraft:smooth_stone
fill ~42 ~8 ~7 ~46 ~8 ~12 minecraft:smooth_stone
fill ~42 ~12 ~7 ~46 ~12 ~12 minecraft:smooth_stone
fill ~41 ~2 ~8 ~41 ~3 ~11 minecraft:gray_stained_glass
fill ~47 ~2 ~8 ~47 ~3 ~11 minecraft:light_gray_stained_glass
fill ~41 ~6 ~8 ~41 ~7 ~11 minecraft:gray_stained_glass
fill ~47 ~6 ~8 ~47 ~7 ~11 minecraft:light_gray_stained_glass
fill ~41 ~10 ~8 ~41 ~11 ~11 minecraft:gray_stained_glass
fill ~47 ~10 ~8 ~47 ~11 ~11 minecraft:light_gray_stained_glass
fill ~41 ~14 ~8 ~41 ~15 ~11 minecraft:gray_stained_glass
fill ~47 ~14 ~8 ~47 ~15 ~11 minecraft:light_gray_stained_glass
fill ~42 ~0 ~6 ~45 ~3 ~6 minecraft:gray_concrete
setblock ~43 ~1 ~6 minecraft:iron_door[half=lower,facing=north]
setblock ~43 ~2 ~6 minecraft:iron_door[half=upper,facing=north]
fill ~41 ~17 ~6 ~47 ~17 ~13 minecraft:stone_brick_slab
# 153 lowrise_housing -31,72 -20,79 h=10
fill ~-31 ~-3 ~72 ~-20 ~-1 ~79 minecraft:stone
fill ~-31 ~0 ~72 ~-20 ~10 ~79 minecraft:light_gray_concrete
fill ~-30 ~1 ~73 ~-21 ~9 ~78 minecraft:air
fill ~-30 ~4 ~73 ~-21 ~4 ~78 minecraft:smooth_stone
fill ~-30 ~8 ~73 ~-21 ~8 ~78 minecraft:smooth_stone
fill ~-29 ~2 ~72 ~-22 ~3 ~72 minecraft:gray_stained_glass
fill ~-29 ~2 ~79 ~-22 ~3 ~79 minecraft:light_gray_stained_glass
fill ~-29 ~6 ~72 ~-22 ~7 ~72 minecraft:gray_stained_glass
fill ~-29 ~6 ~79 ~-22 ~7 ~79 minecraft:light_gray_stained_glass
fill ~-30 ~0 ~72 ~-27 ~3 ~72 doomsday_decoration:porcelainbrickwall
setblock ~-29 ~1 ~72 minecraft:iron_door[half=lower,facing=north]
setblock ~-29 ~2 ~72 minecraft:iron_door[half=upper,facing=north]
fill ~-31 ~11 ~72 ~-20 ~11 ~79 minecraft:smooth_stone_slab
# 154 detached_house -68,93 -60,99 h=7
fill ~-68 ~-3 ~93 ~-60 ~-1 ~99 minecraft:stone
fill ~-68 ~0 ~93 ~-60 ~7 ~99 minecraft:calcite
fill ~-67 ~1 ~94 ~-61 ~6 ~98 minecraft:air
fill ~-67 ~4 ~94 ~-61 ~4 ~98 minecraft:smooth_stone
fill ~-66 ~2 ~93 ~-62 ~3 ~93 minecraft:gray_stained_glass
fill ~-66 ~2 ~99 ~-62 ~3 ~99 minecraft:light_gray_stained_glass
fill ~-67 ~0 ~93 ~-64 ~3 ~93 minecraft:gray_concrete
setblock ~-66 ~1 ~93 minecraft:iron_door[half=lower,facing=north]
setblock ~-66 ~2 ~93 minecraft:iron_door[half=upper,facing=north]
fill ~-68 ~8 ~93 ~-60 ~8 ~99 minecraft:stone_brick_slab
# 155 hotel 14,-44 26,-37 h=12
fill ~14 ~-3 ~-44 ~26 ~-1 ~-37 minecraft:stone
fill ~14 ~0 ~-44 ~26 ~12 ~-37 minecraft:light_gray_concrete
fill ~15 ~1 ~-43 ~25 ~11 ~-38 minecraft:air
fill ~15 ~4 ~-43 ~25 ~4 ~-38 minecraft:smooth_stone
fill ~15 ~8 ~-43 ~25 ~8 ~-38 minecraft:smooth_stone
fill ~14 ~2 ~-42 ~14 ~3 ~-39 minecraft:gray_stained_glass
fill ~26 ~2 ~-42 ~26 ~3 ~-39 minecraft:light_gray_stained_glass
fill ~14 ~6 ~-42 ~14 ~7 ~-39 minecraft:gray_stained_glass
fill ~26 ~6 ~-42 ~26 ~7 ~-39 minecraft:light_gray_stained_glass
fill ~14 ~10 ~-42 ~14 ~11 ~-39 minecraft:gray_stained_glass
fill ~26 ~10 ~-42 ~26 ~11 ~-39 minecraft:light_gray_stained_glass
fill ~15 ~0 ~-44 ~18 ~3 ~-44 doomsday_decoration:cementwall
setblock ~16 ~1 ~-44 minecraft:iron_door[half=lower,facing=north]
setblock ~16 ~2 ~-44 minecraft:iron_door[half=upper,facing=north]
fill ~14 ~13 ~-44 ~26 ~13 ~-37 minecraft:smooth_stone_slab
# 156 community -125,67 -118,73 h=11
fill ~-125 ~-3 ~67 ~-118 ~-1 ~73 minecraft:stone
fill ~-125 ~0 ~67 ~-118 ~11 ~73 minecraft:mud_bricks
fill ~-124 ~1 ~68 ~-119 ~10 ~72 minecraft:air
fill ~-124 ~4 ~68 ~-119 ~4 ~72 minecraft:smooth_stone
fill ~-124 ~8 ~68 ~-119 ~8 ~72 minecraft:smooth_stone
fill ~-123 ~2 ~67 ~-120 ~3 ~67 minecraft:gray_stained_glass
fill ~-123 ~2 ~73 ~-120 ~3 ~73 minecraft:light_gray_stained_glass
fill ~-123 ~6 ~67 ~-120 ~7 ~67 minecraft:gray_stained_glass
fill ~-123 ~6 ~73 ~-120 ~7 ~73 minecraft:light_gray_stained_glass
fill ~-124 ~0 ~67 ~-121 ~3 ~67 minecraft:spruce_planks
setblock ~-123 ~1 ~67 minecraft:iron_door[half=lower,facing=north]
setblock ~-123 ~2 ~67 minecraft:iron_door[half=upper,facing=north]
fill ~-125 ~12 ~67 ~-118 ~12 ~73 minecraft:deepslate_tile_slab
# 157 warehouse -105,-91 -96,-82 h=8
fill ~-105 ~-3 ~-91 ~-96 ~-1 ~-82 minecraft:stone
fill ~-105 ~0 ~-91 ~-96 ~8 ~-82 minecraft:bricks
fill ~-104 ~1 ~-90 ~-97 ~7 ~-83 minecraft:air
fill ~-104 ~4 ~-90 ~-97 ~4 ~-83 minecraft:smooth_stone
fill ~-103 ~2 ~-91 ~-98 ~3 ~-91 minecraft:gray_stained_glass
fill ~-103 ~2 ~-82 ~-98 ~3 ~-82 minecraft:light_gray_stained_glass
fill ~-103 ~6 ~-91 ~-98 ~7 ~-91 minecraft:gray_stained_glass
fill ~-103 ~6 ~-82 ~-98 ~7 ~-82 minecraft:light_gray_stained_glass
fill ~-104 ~0 ~-91 ~-101 ~3 ~-91 minecraft:gray_concrete
setblock ~-103 ~1 ~-91 minecraft:iron_door[half=lower,facing=north]
setblock ~-103 ~2 ~-91 minecraft:iron_door[half=upper,facing=north]
fill ~-105 ~9 ~-91 ~-96 ~9 ~-82 minecraft:deepslate_tile_slab
fill ~-98 ~6 ~-84 ~-96 ~9 ~-82 minecraft:air
setblock ~-98 ~6 ~-84 minecraft:cobweb
# 158 row_house -110,3 -105,9 h=5
fill ~-110 ~-3 ~3 ~-105 ~-1 ~9 minecraft:stone
fill ~-110 ~0 ~3 ~-105 ~5 ~9 minecraft:mud_bricks
fill ~-109 ~1 ~4 ~-106 ~4 ~8 minecraft:air
fill ~-109 ~4 ~4 ~-106 ~4 ~8 minecraft:smooth_stone
fill ~-110 ~2 ~5 ~-110 ~3 ~7 minecraft:gray_stained_glass
fill ~-105 ~2 ~5 ~-105 ~3 ~7 minecraft:light_gray_stained_glass
fill ~-109 ~0 ~3 ~-106 ~3 ~3 minecraft:spruce_planks
setblock ~-108 ~1 ~3 minecraft:iron_door[half=lower,facing=north]
setblock ~-108 ~2 ~3 minecraft:iron_door[half=upper,facing=north]
fill ~-110 ~6 ~3 ~-105 ~6 ~9 minecraft:deepslate_tile_slab
# 159 lowrise_housing -57,26 -51,33 h=16
fill ~-57 ~-3 ~26 ~-51 ~-1 ~33 minecraft:stone
fill ~-57 ~0 ~26 ~-51 ~16 ~33 minecraft:light_gray_concrete
fill ~-56 ~1 ~27 ~-52 ~15 ~32 minecraft:air
fill ~-56 ~4 ~27 ~-52 ~4 ~32 minecraft:smooth_stone
fill ~-56 ~8 ~27 ~-52 ~8 ~32 minecraft:smooth_stone
fill ~-56 ~12 ~27 ~-52 ~12 ~32 minecraft:smooth_stone
fill ~-55 ~2 ~26 ~-53 ~3 ~26 minecraft:gray_stained_glass
fill ~-55 ~2 ~33 ~-53 ~3 ~33 minecraft:light_gray_stained_glass
fill ~-55 ~6 ~26 ~-53 ~7 ~26 minecraft:gray_stained_glass
fill ~-55 ~6 ~33 ~-53 ~7 ~33 minecraft:light_gray_stained_glass
fill ~-55 ~10 ~26 ~-53 ~11 ~26 minecraft:gray_stained_glass
fill ~-55 ~10 ~33 ~-53 ~11 ~33 minecraft:light_gray_stained_glass
fill ~-55 ~14 ~26 ~-53 ~15 ~26 minecraft:gray_stained_glass
fill ~-55 ~14 ~33 ~-53 ~15 ~33 minecraft:light_gray_stained_glass
fill ~-56 ~0 ~26 ~-53 ~3 ~26 doomsday_decoration:porcelainbrickwall
setblock ~-55 ~1 ~26 minecraft:iron_door[half=lower,facing=north]
setblock ~-55 ~2 ~26 minecraft:iron_door[half=upper,facing=north]
fill ~-57 ~17 ~26 ~-51 ~17 ~33 minecraft:smooth_stone_slab
# 160 row_house -11,98 -5,104 h=5
fill ~-11 ~-3 ~98 ~-5 ~-1 ~104 minecraft:stone
fill ~-11 ~0 ~98 ~-5 ~5 ~104 minecraft:white_terracotta
fill ~-10 ~1 ~99 ~-6 ~4 ~103 minecraft:air
fill ~-10 ~4 ~99 ~-6 ~4 ~103 minecraft:smooth_stone
fill ~-9 ~2 ~98 ~-7 ~3 ~98 minecraft:gray_stained_glass
fill ~-9 ~2 ~104 ~-7 ~3 ~104 minecraft:light_gray_stained_glass
fill ~-10 ~0 ~98 ~-7 ~3 ~98 minecraft:dark_oak_planks
setblock ~-9 ~1 ~98 minecraft:iron_door[half=lower,facing=north]
setblock ~-9 ~2 ~98 minecraft:iron_door[half=upper,facing=north]
fill ~-11 ~6 ~98 ~-5 ~6 ~104 minecraft:dark_oak_slab
# 161 lowrise_housing 70,29 76,37 h=12
fill ~70 ~-3 ~29 ~76 ~-1 ~37 minecraft:stone
fill ~70 ~0 ~29 ~76 ~12 ~37 minecraft:bricks
fill ~71 ~1 ~30 ~75 ~11 ~36 minecraft:air
fill ~71 ~4 ~30 ~75 ~4 ~36 minecraft:smooth_stone
fill ~71 ~8 ~30 ~75 ~8 ~36 minecraft:smooth_stone
fill ~70 ~2 ~31 ~70 ~3 ~35 minecraft:gray_stained_glass
fill ~76 ~2 ~31 ~76 ~3 ~35 minecraft:light_gray_stained_glass
fill ~70 ~6 ~31 ~70 ~7 ~35 minecraft:gray_stained_glass
fill ~76 ~6 ~31 ~76 ~7 ~35 minecraft:light_gray_stained_glass
fill ~70 ~10 ~31 ~70 ~11 ~35 minecraft:gray_stained_glass
fill ~76 ~10 ~31 ~76 ~11 ~35 minecraft:light_gray_stained_glass
fill ~71 ~0 ~29 ~74 ~3 ~29 doomsday_decoration:hollowbrick
setblock ~72 ~1 ~29 minecraft:iron_door[half=lower,facing=north]
setblock ~72 ~2 ~29 minecraft:iron_door[half=upper,facing=north]
fill ~70 ~13 ~29 ~76 ~13 ~37 minecraft:deepslate_tile_slab
# 162 detached_house -124,24 -116,30 h=9
fill ~-124 ~-3 ~24 ~-116 ~-1 ~30 minecraft:stone
fill ~-124 ~0 ~24 ~-116 ~9 ~30 minecraft:calcite
fill ~-123 ~1 ~25 ~-117 ~8 ~29 minecraft:air
fill ~-123 ~4 ~25 ~-117 ~4 ~29 minecraft:smooth_stone
fill ~-123 ~8 ~25 ~-117 ~8 ~29 minecraft:smooth_stone
fill ~-122 ~2 ~24 ~-118 ~3 ~24 minecraft:gray_stained_glass
fill ~-122 ~2 ~30 ~-118 ~3 ~30 minecraft:light_gray_stained_glass
fill ~-122 ~6 ~24 ~-118 ~7 ~24 minecraft:gray_stained_glass
fill ~-122 ~6 ~30 ~-118 ~7 ~30 minecraft:light_gray_stained_glass
fill ~-123 ~0 ~24 ~-120 ~3 ~24 minecraft:gray_concrete
setblock ~-122 ~1 ~24 minecraft:iron_door[half=lower,facing=north]
setblock ~-122 ~2 ~24 minecraft:iron_door[half=upper,facing=north]
fill ~-124 ~10 ~24 ~-116 ~10 ~30 minecraft:stone_brick_slab
# 163 retail -25,35 -19,43 h=16
fill ~-25 ~-3 ~35 ~-19 ~-1 ~43 minecraft:stone
fill ~-25 ~0 ~35 ~-19 ~16 ~43 minecraft:bricks
fill ~-24 ~1 ~36 ~-20 ~15 ~42 minecraft:air
fill ~-24 ~4 ~36 ~-20 ~4 ~42 minecraft:smooth_stone
fill ~-24 ~8 ~36 ~-20 ~8 ~42 minecraft:smooth_stone
fill ~-24 ~12 ~36 ~-20 ~12 ~42 minecraft:smooth_stone
fill ~-23 ~2 ~35 ~-21 ~3 ~35 minecraft:gray_stained_glass
fill ~-23 ~2 ~43 ~-21 ~3 ~43 minecraft:light_gray_stained_glass
fill ~-23 ~6 ~35 ~-21 ~7 ~35 minecraft:gray_stained_glass
fill ~-23 ~6 ~43 ~-21 ~7 ~43 minecraft:light_gray_stained_glass
fill ~-23 ~10 ~35 ~-21 ~11 ~35 minecraft:gray_stained_glass
fill ~-23 ~10 ~43 ~-21 ~11 ~43 minecraft:light_gray_stained_glass
fill ~-23 ~14 ~35 ~-21 ~15 ~35 minecraft:gray_stained_glass
fill ~-23 ~14 ~43 ~-21 ~15 ~43 minecraft:light_gray_stained_glass
fill ~-24 ~0 ~35 ~-21 ~3 ~35 doomsday_decoration:redbrick
setblock ~-23 ~1 ~35 minecraft:iron_door[half=lower,facing=north]
setblock ~-23 ~2 ~35 minecraft:iron_door[half=upper,facing=north]
fill ~-25 ~17 ~35 ~-19 ~17 ~43 minecraft:deepslate_tile_slab
# 164 small_office 25,34 31,46 h=24
fill ~25 ~-3 ~34 ~31 ~-1 ~46 minecraft:stone
fill ~25 ~0 ~34 ~31 ~24 ~46 minecraft:bricks
fill ~26 ~1 ~35 ~30 ~23 ~45 minecraft:air
fill ~26 ~4 ~35 ~30 ~4 ~45 minecraft:smooth_stone
fill ~26 ~8 ~35 ~30 ~8 ~45 minecraft:smooth_stone
fill ~26 ~12 ~35 ~30 ~12 ~45 minecraft:smooth_stone
fill ~26 ~16 ~35 ~30 ~16 ~45 minecraft:smooth_stone
fill ~26 ~20 ~35 ~30 ~20 ~45 minecraft:smooth_stone
fill ~25 ~2 ~36 ~25 ~3 ~44 minecraft:gray_stained_glass
fill ~31 ~2 ~36 ~31 ~3 ~44 minecraft:light_gray_stained_glass
fill ~25 ~6 ~36 ~25 ~7 ~44 minecraft:gray_stained_glass
fill ~31 ~6 ~36 ~31 ~7 ~44 minecraft:light_gray_stained_glass
fill ~25 ~10 ~36 ~25 ~11 ~44 minecraft:gray_stained_glass
fill ~31 ~10 ~36 ~31 ~11 ~44 minecraft:light_gray_stained_glass
fill ~25 ~14 ~36 ~25 ~15 ~44 minecraft:gray_stained_glass
fill ~31 ~14 ~36 ~31 ~15 ~44 minecraft:light_gray_stained_glass
fill ~25 ~18 ~36 ~25 ~19 ~44 minecraft:gray_stained_glass
fill ~31 ~18 ~36 ~31 ~19 ~44 minecraft:light_gray_stained_glass
fill ~25 ~22 ~36 ~25 ~23 ~44 minecraft:gray_stained_glass
fill ~31 ~22 ~36 ~31 ~23 ~44 minecraft:light_gray_stained_glass
fill ~26 ~0 ~34 ~29 ~3 ~34 doomsday_decoration:redbrick
setblock ~27 ~1 ~34 minecraft:iron_door[half=lower,facing=north]
setblock ~27 ~2 ~34 minecraft:iron_door[half=upper,facing=north]
fill ~25 ~25 ~34 ~31 ~25 ~46 minecraft:deepslate_tile_slab
# 165 restaurant -13,52 -7,59 h=16
fill ~-13 ~-3 ~52 ~-7 ~-1 ~59 minecraft:stone
fill ~-13 ~0 ~52 ~-7 ~16 ~59 minecraft:light_gray_concrete
fill ~-12 ~1 ~53 ~-8 ~15 ~58 minecraft:air
fill ~-12 ~4 ~53 ~-8 ~4 ~58 minecraft:smooth_stone
fill ~-12 ~8 ~53 ~-8 ~8 ~58 minecraft:smooth_stone
fill ~-12 ~12 ~53 ~-8 ~12 ~58 minecraft:smooth_stone
fill ~-13 ~2 ~54 ~-13 ~3 ~57 minecraft:gray_stained_glass
fill ~-7 ~2 ~54 ~-7 ~3 ~57 minecraft:light_gray_stained_glass
fill ~-13 ~6 ~54 ~-13 ~7 ~57 minecraft:gray_stained_glass
fill ~-7 ~6 ~54 ~-7 ~7 ~57 minecraft:light_gray_stained_glass
fill ~-13 ~10 ~54 ~-13 ~11 ~57 minecraft:gray_stained_glass
fill ~-7 ~10 ~54 ~-7 ~11 ~57 minecraft:light_gray_stained_glass
fill ~-13 ~14 ~54 ~-13 ~15 ~57 minecraft:gray_stained_glass
fill ~-7 ~14 ~54 ~-7 ~15 ~57 minecraft:light_gray_stained_glass
fill ~-12 ~0 ~52 ~-9 ~3 ~52 doomsday_decoration:porcelainbrickwall
setblock ~-11 ~1 ~52 minecraft:iron_door[half=lower,facing=north]
setblock ~-11 ~2 ~52 minecraft:iron_door[half=upper,facing=north]
fill ~-13 ~17 ~52 ~-7 ~17 ~59 minecraft:smooth_stone_slab
# 166 restaurant 78,-50 84,-43 h=16
fill ~78 ~-3 ~-50 ~84 ~-1 ~-43 minecraft:stone
fill ~78 ~0 ~-50 ~84 ~16 ~-43 minecraft:smooth_sandstone
fill ~79 ~1 ~-49 ~83 ~15 ~-44 minecraft:air
fill ~79 ~4 ~-49 ~83 ~4 ~-44 minecraft:smooth_stone
fill ~79 ~8 ~-49 ~83 ~8 ~-44 minecraft:smooth_stone
fill ~79 ~12 ~-49 ~83 ~12 ~-44 minecraft:smooth_stone
fill ~80 ~2 ~-50 ~82 ~3 ~-50 minecraft:gray_stained_glass
fill ~80 ~2 ~-43 ~82 ~3 ~-43 minecraft:light_gray_stained_glass
fill ~80 ~6 ~-50 ~82 ~7 ~-50 minecraft:gray_stained_glass
fill ~80 ~6 ~-43 ~82 ~7 ~-43 minecraft:light_gray_stained_glass
fill ~80 ~10 ~-50 ~82 ~11 ~-50 minecraft:gray_stained_glass
fill ~80 ~10 ~-43 ~82 ~11 ~-43 minecraft:light_gray_stained_glass
fill ~80 ~14 ~-50 ~82 ~15 ~-50 minecraft:gray_stained_glass
fill ~80 ~14 ~-43 ~82 ~15 ~-43 minecraft:light_gray_stained_glass
fill ~79 ~0 ~-50 ~82 ~3 ~-50 minecraft:brown_terracotta
setblock ~80 ~1 ~-50 minecraft:iron_door[half=lower,facing=north]
setblock ~80 ~2 ~-50 minecraft:iron_door[half=upper,facing=north]
fill ~78 ~17 ~-50 ~84 ~17 ~-43 minecraft:stone_brick_slab
# 167 station_shop 36,-125 47,-115 h=10
fill ~36 ~-3 ~-125 ~47 ~-1 ~-115 minecraft:stone
fill ~36 ~0 ~-125 ~47 ~10 ~-115 minecraft:stone_bricks
fill ~37 ~1 ~-124 ~46 ~9 ~-116 minecraft:air
fill ~37 ~4 ~-124 ~46 ~4 ~-116 minecraft:smooth_stone
fill ~37 ~8 ~-124 ~46 ~8 ~-116 minecraft:smooth_stone
fill ~38 ~2 ~-125 ~45 ~3 ~-125 minecraft:gray_stained_glass
fill ~38 ~2 ~-115 ~45 ~3 ~-115 minecraft:light_gray_stained_glass
fill ~38 ~6 ~-125 ~45 ~7 ~-125 minecraft:gray_stained_glass
fill ~38 ~6 ~-115 ~45 ~7 ~-115 minecraft:light_gray_stained_glass
fill ~37 ~0 ~-125 ~40 ~3 ~-125 doomsday_decoration:ironsheetwall_2
setblock ~38 ~1 ~-125 minecraft:iron_door[half=lower,facing=north]
setblock ~38 ~2 ~-125 minecraft:iron_door[half=upper,facing=north]
fill ~36 ~11 ~-125 ~47 ~11 ~-115 minecraft:smooth_stone_slab
fill ~45 ~8 ~-117 ~47 ~11 ~-115 minecraft:air
setblock ~45 ~8 ~-117 minecraft:cobweb
# 168 clinic -48,30 -41,41 h=10
fill ~-48 ~-3 ~30 ~-41 ~-1 ~41 minecraft:stone
fill ~-48 ~0 ~30 ~-41 ~10 ~41 minecraft:bricks
fill ~-47 ~1 ~31 ~-42 ~9 ~40 minecraft:air
fill ~-47 ~4 ~31 ~-42 ~4 ~40 minecraft:smooth_stone
fill ~-47 ~8 ~31 ~-42 ~8 ~40 minecraft:smooth_stone
fill ~-48 ~2 ~32 ~-48 ~3 ~39 minecraft:gray_stained_glass
fill ~-41 ~2 ~32 ~-41 ~3 ~39 minecraft:light_gray_stained_glass
fill ~-48 ~6 ~32 ~-48 ~7 ~39 minecraft:gray_stained_glass
fill ~-41 ~6 ~32 ~-41 ~7 ~39 minecraft:light_gray_stained_glass
fill ~-47 ~0 ~30 ~-44 ~3 ~30 doomsday_decoration:hollowbrick
setblock ~-46 ~1 ~30 minecraft:iron_door[half=lower,facing=north]
setblock ~-46 ~2 ~30 minecraft:iron_door[half=upper,facing=north]
fill ~-48 ~11 ~30 ~-41 ~11 ~41 minecraft:deepslate_tile_slab
# 169 local_shop -78,-81 -72,-75 h=11
fill ~-78 ~-3 ~-81 ~-72 ~-1 ~-75 minecraft:stone
fill ~-78 ~0 ~-81 ~-72 ~11 ~-75 minecraft:calcite
fill ~-77 ~1 ~-80 ~-73 ~10 ~-76 minecraft:air
fill ~-77 ~4 ~-80 ~-73 ~4 ~-76 minecraft:smooth_stone
fill ~-77 ~8 ~-80 ~-73 ~8 ~-76 minecraft:smooth_stone
fill ~-76 ~2 ~-81 ~-74 ~3 ~-81 minecraft:gray_stained_glass
fill ~-76 ~2 ~-75 ~-74 ~3 ~-75 minecraft:light_gray_stained_glass
fill ~-76 ~6 ~-81 ~-74 ~7 ~-81 minecraft:gray_stained_glass
fill ~-76 ~6 ~-75 ~-74 ~7 ~-75 minecraft:light_gray_stained_glass
fill ~-77 ~0 ~-81 ~-74 ~3 ~-81 minecraft:gray_concrete
setblock ~-76 ~1 ~-81 minecraft:iron_door[half=lower,facing=north]
setblock ~-76 ~2 ~-81 minecraft:iron_door[half=upper,facing=north]
fill ~-78 ~12 ~-81 ~-72 ~12 ~-75 minecraft:stone_brick_slab
# 170 clinic 70,-28 76,-21 h=16
fill ~70 ~-3 ~-28 ~76 ~-1 ~-21 minecraft:stone
fill ~70 ~0 ~-28 ~76 ~16 ~-21 minecraft:light_gray_concrete
fill ~71 ~1 ~-27 ~75 ~15 ~-22 minecraft:air
fill ~71 ~4 ~-27 ~75 ~4 ~-22 minecraft:smooth_stone
fill ~71 ~8 ~-27 ~75 ~8 ~-22 minecraft:smooth_stone
fill ~71 ~12 ~-27 ~75 ~12 ~-22 minecraft:smooth_stone
fill ~70 ~2 ~-26 ~70 ~3 ~-23 minecraft:gray_stained_glass
fill ~76 ~2 ~-26 ~76 ~3 ~-23 minecraft:light_gray_stained_glass
fill ~70 ~6 ~-26 ~70 ~7 ~-23 minecraft:gray_stained_glass
fill ~76 ~6 ~-26 ~76 ~7 ~-23 minecraft:light_gray_stained_glass
fill ~70 ~10 ~-26 ~70 ~11 ~-23 minecraft:gray_stained_glass
fill ~76 ~10 ~-26 ~76 ~11 ~-23 minecraft:light_gray_stained_glass
fill ~70 ~14 ~-26 ~70 ~15 ~-23 minecraft:gray_stained_glass
fill ~76 ~14 ~-26 ~76 ~15 ~-23 minecraft:light_gray_stained_glass
fill ~71 ~0 ~-28 ~74 ~3 ~-28 doomsday_decoration:porcelainbrickwall
setblock ~72 ~1 ~-28 minecraft:iron_door[half=lower,facing=north]
setblock ~72 ~2 ~-28 minecraft:iron_door[half=upper,facing=north]
fill ~70 ~17 ~-28 ~76 ~17 ~-21 minecraft:smooth_stone_slab
# 171 detached_house -83,90 -78,96 h=5
fill ~-83 ~-3 ~90 ~-78 ~-1 ~96 minecraft:stone
fill ~-83 ~0 ~90 ~-78 ~5 ~96 minecraft:calcite
fill ~-82 ~1 ~91 ~-79 ~4 ~95 minecraft:air
fill ~-82 ~4 ~91 ~-79 ~4 ~95 minecraft:smooth_stone
fill ~-83 ~2 ~92 ~-83 ~3 ~94 minecraft:gray_stained_glass
fill ~-78 ~2 ~92 ~-78 ~3 ~94 minecraft:light_gray_stained_glass
fill ~-82 ~0 ~90 ~-79 ~3 ~90 minecraft:gray_concrete
setblock ~-81 ~1 ~90 minecraft:iron_door[half=lower,facing=north]
setblock ~-81 ~2 ~90 minecraft:iron_door[half=upper,facing=north]
fill ~-83 ~6 ~90 ~-78 ~6 ~96 minecraft:stone_brick_slab
# 172 apartment 95,-52 100,-43 h=7
fill ~95 ~-3 ~-52 ~100 ~-1 ~-43 minecraft:stone
fill ~95 ~0 ~-52 ~100 ~7 ~-43 minecraft:bricks
fill ~96 ~1 ~-51 ~99 ~6 ~-44 minecraft:air
fill ~96 ~4 ~-51 ~99 ~4 ~-44 minecraft:smooth_stone
fill ~95 ~2 ~-50 ~95 ~3 ~-45 minecraft:gray_stained_glass
fill ~100 ~2 ~-50 ~100 ~3 ~-45 minecraft:light_gray_stained_glass
fill ~96 ~0 ~-52 ~99 ~3 ~-52 minecraft:weathered_cut_copper
setblock ~97 ~1 ~-52 minecraft:iron_door[half=lower,facing=north]
setblock ~97 ~2 ~-52 minecraft:iron_door[half=upper,facing=north]
fill ~95 ~8 ~-52 ~100 ~8 ~-43 minecraft:deepslate_tile_slab
# 173 logistics 69,55 73,62 h=10
fill ~69 ~-3 ~55 ~73 ~-1 ~62 minecraft:stone
fill ~69 ~0 ~55 ~73 ~10 ~62 minecraft:gray_concrete
fill ~70 ~1 ~56 ~72 ~9 ~61 minecraft:air
fill ~70 ~4 ~56 ~72 ~4 ~61 minecraft:smooth_stone
fill ~70 ~8 ~56 ~72 ~8 ~61 minecraft:smooth_stone
fill ~69 ~2 ~57 ~69 ~3 ~60 minecraft:gray_stained_glass
fill ~73 ~2 ~57 ~73 ~3 ~60 minecraft:light_gray_stained_glass
fill ~69 ~6 ~57 ~69 ~7 ~60 minecraft:gray_stained_glass
fill ~73 ~6 ~57 ~73 ~7 ~60 minecraft:light_gray_stained_glass
fill ~70 ~0 ~55 ~72 ~3 ~55 doomsday_decoration:ironsheetwall_1
setblock ~71 ~1 ~55 minecraft:iron_door[half=lower,facing=north]
setblock ~71 ~2 ~55 minecraft:iron_door[half=upper,facing=north]
fill ~69 ~11 ~55 ~73 ~11 ~62 minecraft:smooth_stone_slab
# 174 mixed_use 24,14 28,19 h=12
fill ~24 ~-3 ~14 ~28 ~-1 ~19 minecraft:stone
fill ~24 ~0 ~14 ~28 ~12 ~19 minecraft:light_gray_concrete
fill ~25 ~1 ~15 ~27 ~11 ~18 minecraft:air
fill ~25 ~4 ~15 ~27 ~4 ~18 minecraft:smooth_stone
fill ~25 ~8 ~15 ~27 ~8 ~18 minecraft:smooth_stone
fill ~26 ~2 ~14 ~26 ~3 ~14 minecraft:gray_stained_glass
fill ~26 ~2 ~19 ~26 ~3 ~19 minecraft:light_gray_stained_glass
fill ~26 ~6 ~14 ~26 ~7 ~14 minecraft:gray_stained_glass
fill ~26 ~6 ~19 ~26 ~7 ~19 minecraft:light_gray_stained_glass
fill ~26 ~10 ~14 ~26 ~11 ~14 minecraft:gray_stained_glass
fill ~26 ~10 ~19 ~26 ~11 ~19 minecraft:light_gray_stained_glass
fill ~25 ~0 ~14 ~27 ~3 ~14 doomsday_decoration:cementwall
setblock ~26 ~1 ~14 minecraft:iron_door[half=lower,facing=north]
setblock ~26 ~2 ~14 minecraft:iron_door[half=upper,facing=north]
fill ~24 ~13 ~14 ~28 ~13 ~19 minecraft:smooth_stone_slab
# 175 logistics 49,55 55,65 h=8
fill ~49 ~-3 ~55 ~55 ~-1 ~65 minecraft:stone
fill ~49 ~0 ~55 ~55 ~8 ~65 minecraft:stone_bricks
fill ~50 ~1 ~56 ~54 ~7 ~64 minecraft:air
fill ~50 ~4 ~56 ~54 ~4 ~64 minecraft:smooth_stone
fill ~49 ~2 ~57 ~49 ~3 ~63 minecraft:gray_stained_glass
fill ~55 ~2 ~57 ~55 ~3 ~63 minecraft:light_gray_stained_glass
fill ~49 ~6 ~57 ~49 ~7 ~63 minecraft:gray_stained_glass
fill ~55 ~6 ~57 ~55 ~7 ~63 minecraft:light_gray_stained_glass
fill ~50 ~0 ~55 ~53 ~3 ~55 minecraft:orange_terracotta
setblock ~51 ~1 ~55 minecraft:iron_door[half=lower,facing=north]
setblock ~51 ~2 ~55 minecraft:iron_door[half=upper,facing=north]
fill ~49 ~9 ~55 ~55 ~9 ~65 minecraft:stone_brick_slab
