# Buildings 9..16
# 009 clinic style=mixed_facade context=collector_front facing=north
fill ~80 ~-3 ~31 ~88 ~-1 ~39 minecraft:stone
fill ~80 ~0 ~31 ~88 ~12 ~39 minecraft:smooth_sandstone
fill ~81 ~1 ~32 ~87 ~11 ~38 minecraft:air
fill ~81 ~4 ~32 ~87 ~4 ~38 minecraft:smooth_stone
fill ~81 ~8 ~32 ~87 ~8 ~38 minecraft:smooth_stone
fill ~82 ~2 ~31 ~82 ~3 ~31 minecraft:gray_stained_glass
fill ~82 ~2 ~39 ~82 ~3 ~39 minecraft:light_gray_stained_glass
fill ~85 ~2 ~31 ~85 ~3 ~31 minecraft:gray_stained_glass
fill ~85 ~2 ~39 ~85 ~3 ~39 minecraft:light_gray_stained_glass
fill ~80 ~2 ~33 ~80 ~3 ~33 minecraft:gray_stained_glass
fill ~88 ~2 ~33 ~88 ~3 ~33 minecraft:light_gray_stained_glass
fill ~80 ~2 ~36 ~80 ~3 ~36 minecraft:gray_stained_glass
fill ~88 ~2 ~36 ~88 ~3 ~36 minecraft:light_gray_stained_glass
fill ~82 ~6 ~31 ~82 ~7 ~31 minecraft:gray_stained_glass
fill ~82 ~6 ~39 ~82 ~7 ~39 minecraft:light_gray_stained_glass
fill ~85 ~6 ~31 ~85 ~7 ~31 minecraft:gray_stained_glass
fill ~85 ~6 ~39 ~85 ~7 ~39 minecraft:light_gray_stained_glass
fill ~80 ~6 ~33 ~80 ~7 ~33 minecraft:gray_stained_glass
fill ~88 ~6 ~33 ~88 ~7 ~33 minecraft:light_gray_stained_glass
fill ~80 ~6 ~36 ~80 ~7 ~36 minecraft:gray_stained_glass
fill ~88 ~6 ~36 ~88 ~7 ~36 minecraft:light_gray_stained_glass
fill ~82 ~10 ~31 ~82 ~11 ~31 minecraft:gray_stained_glass
fill ~82 ~10 ~39 ~82 ~11 ~39 minecraft:light_gray_stained_glass
fill ~85 ~10 ~31 ~85 ~11 ~31 minecraft:gray_stained_glass
fill ~85 ~10 ~39 ~85 ~11 ~39 minecraft:light_gray_stained_glass
fill ~80 ~10 ~33 ~80 ~11 ~33 minecraft:gray_stained_glass
fill ~88 ~10 ~33 ~88 ~11 ~33 minecraft:light_gray_stained_glass
fill ~80 ~10 ~36 ~80 ~11 ~36 minecraft:gray_stained_glass
fill ~88 ~10 ~36 ~88 ~11 ~36 minecraft:light_gray_stained_glass
setblock ~84 ~1 ~31 minecraft:iron_door[half=lower,facing=north]
setblock ~84 ~2 ~31 minecraft:iron_door[half=upper,facing=north]
fill ~80 ~13 ~31 ~88 ~13 ~39 minecraft:stone_brick_slab
fill ~82 ~14 ~33 ~84 ~15 ~35 minecraft:light_gray_concrete
setblock ~85 ~14 ~34 minecraft:lightning_rod
# 010 detached_house style=japanese_house context=back_block facing=west
fill ~-76 ~-3 ~95 ~-70 ~-1 ~101 minecraft:stone
fill ~-76 ~0 ~95 ~-70 ~9 ~101 minecraft:mud_bricks
fill ~-75 ~1 ~96 ~-71 ~8 ~100 minecraft:air
fill ~-75 ~4 ~96 ~-71 ~4 ~100 minecraft:smooth_stone
fill ~-75 ~8 ~96 ~-71 ~8 ~100 minecraft:smooth_stone
fill ~-74 ~2 ~95 ~-74 ~3 ~95 minecraft:gray_stained_glass
fill ~-74 ~2 ~101 ~-74 ~3 ~101 minecraft:light_gray_stained_glass
fill ~-76 ~2 ~97 ~-76 ~3 ~97 minecraft:gray_stained_glass
fill ~-70 ~2 ~97 ~-70 ~3 ~97 minecraft:light_gray_stained_glass
fill ~-74 ~6 ~95 ~-74 ~7 ~95 minecraft:gray_stained_glass
fill ~-74 ~6 ~101 ~-74 ~7 ~101 minecraft:light_gray_stained_glass
fill ~-76 ~6 ~97 ~-76 ~7 ~97 minecraft:gray_stained_glass
fill ~-70 ~6 ~97 ~-70 ~7 ~97 minecraft:light_gray_stained_glass
setblock ~-76 ~1 ~98 minecraft:iron_door[half=lower,facing=west]
setblock ~-76 ~2 ~98 minecraft:iron_door[half=upper,facing=west]
fill ~-76 ~10 ~95 ~-70 ~10 ~101 minecraft:deepslate_tile_slab
fill ~-75 ~11 ~96 ~-71 ~11 ~100 minecraft:deepslate_tile_slab
setblock ~-77 ~3 ~98 minecraft:dark_oak_slab[type=top]
# 011 row_house style=stepped_house context=local_front facing=north
fill ~-38 ~-3 ~108 ~-28 ~-1 ~114 minecraft:stone
fill ~-38 ~0 ~108 ~-28 ~9 ~114 minecraft:mud_bricks
fill ~-37 ~1 ~109 ~-29 ~8 ~113 minecraft:air
fill ~-37 ~4 ~109 ~-29 ~4 ~113 minecraft:smooth_stone
fill ~-37 ~8 ~109 ~-29 ~8 ~113 minecraft:smooth_stone
fill ~-36 ~2 ~108 ~-36 ~3 ~108 minecraft:gray_stained_glass
fill ~-36 ~2 ~114 ~-36 ~3 ~114 minecraft:light_gray_stained_glass
fill ~-33 ~2 ~108 ~-33 ~3 ~108 minecraft:gray_stained_glass
fill ~-33 ~2 ~114 ~-33 ~3 ~114 minecraft:light_gray_stained_glass
fill ~-30 ~2 ~108 ~-30 ~3 ~108 minecraft:gray_stained_glass
fill ~-30 ~2 ~114 ~-30 ~3 ~114 minecraft:light_gray_stained_glass
fill ~-38 ~2 ~110 ~-38 ~3 ~110 minecraft:gray_stained_glass
fill ~-28 ~2 ~110 ~-28 ~3 ~110 minecraft:light_gray_stained_glass
fill ~-36 ~6 ~108 ~-36 ~7 ~108 minecraft:gray_stained_glass
fill ~-36 ~6 ~114 ~-36 ~7 ~114 minecraft:light_gray_stained_glass
fill ~-33 ~6 ~108 ~-33 ~7 ~108 minecraft:gray_stained_glass
fill ~-33 ~6 ~114 ~-33 ~7 ~114 minecraft:light_gray_stained_glass
fill ~-30 ~6 ~108 ~-30 ~7 ~108 minecraft:gray_stained_glass
fill ~-30 ~6 ~114 ~-30 ~7 ~114 minecraft:light_gray_stained_glass
fill ~-38 ~6 ~110 ~-38 ~7 ~110 minecraft:gray_stained_glass
fill ~-28 ~6 ~110 ~-28 ~7 ~110 minecraft:light_gray_stained_glass
setblock ~-33 ~1 ~108 minecraft:iron_door[half=lower,facing=north]
setblock ~-33 ~2 ~108 minecraft:iron_door[half=upper,facing=north]
fill ~-38 ~10 ~108 ~-28 ~10 ~114 minecraft:deepslate_tile_slab
fill ~-37 ~11 ~109 ~-29 ~11 ~113 minecraft:deepslate_tile_slab
setblock ~-33 ~3 ~107 minecraft:dark_oak_slab[type=top]
# 012 small_office style=civic_modern context=back_block facing=north
fill ~-19 ~-3 ~113 ~-13 ~-1 ~121 minecraft:stone
fill ~-19 ~0 ~113 ~-13 ~11 ~121 minecraft:calcite
fill ~-18 ~1 ~114 ~-14 ~10 ~120 minecraft:air
fill ~-18 ~4 ~114 ~-14 ~4 ~120 minecraft:smooth_stone
fill ~-18 ~8 ~114 ~-14 ~8 ~120 minecraft:smooth_stone
fill ~-17 ~2 ~113 ~-17 ~3 ~113 minecraft:gray_stained_glass
fill ~-17 ~2 ~121 ~-17 ~3 ~121 minecraft:light_gray_stained_glass
fill ~-19 ~2 ~115 ~-19 ~3 ~115 minecraft:gray_stained_glass
fill ~-13 ~2 ~115 ~-13 ~3 ~115 minecraft:light_gray_stained_glass
fill ~-19 ~2 ~118 ~-19 ~3 ~118 minecraft:gray_stained_glass
fill ~-13 ~2 ~118 ~-13 ~3 ~118 minecraft:light_gray_stained_glass
fill ~-17 ~6 ~113 ~-17 ~7 ~113 minecraft:gray_stained_glass
fill ~-17 ~6 ~121 ~-17 ~7 ~121 minecraft:light_gray_stained_glass
fill ~-19 ~6 ~115 ~-19 ~7 ~115 minecraft:gray_stained_glass
fill ~-13 ~6 ~115 ~-13 ~7 ~115 minecraft:light_gray_stained_glass
fill ~-19 ~6 ~118 ~-19 ~7 ~118 minecraft:gray_stained_glass
fill ~-13 ~6 ~118 ~-13 ~7 ~118 minecraft:light_gray_stained_glass
setblock ~-16 ~1 ~113 minecraft:iron_door[half=lower,facing=north]
setblock ~-16 ~2 ~113 minecraft:iron_door[half=upper,facing=north]
fill ~-19 ~7 ~113 ~-13 ~11 ~121 minecraft:air
fill ~-18 ~7 ~114 ~-14 ~11 ~120 minecraft:calcite
fill ~-17 ~8 ~115 ~-15 ~10 ~119 minecraft:air
fill ~-18 ~12 ~114 ~-14 ~12 ~120 minecraft:stone_brick_slab
fill ~-17 ~13 ~115 ~-15 ~14 ~117 minecraft:light_gray_concrete
setblock ~-14 ~13 ~116 minecraft:lightning_rod
# 013 detached_house style=stepped_house context=back_block facing=north
fill ~-115 ~-3 ~112 ~-110 ~-1 ~124 minecraft:stone
fill ~-115 ~0 ~112 ~-110 ~9 ~124 minecraft:white_terracotta
fill ~-114 ~1 ~113 ~-111 ~8 ~123 minecraft:air
fill ~-114 ~4 ~113 ~-111 ~4 ~123 minecraft:smooth_stone
fill ~-114 ~8 ~113 ~-111 ~8 ~123 minecraft:smooth_stone
fill ~-113 ~2 ~112 ~-113 ~3 ~112 minecraft:gray_stained_glass
fill ~-113 ~2 ~124 ~-113 ~3 ~124 minecraft:light_gray_stained_glass
fill ~-115 ~2 ~114 ~-115 ~3 ~114 minecraft:gray_stained_glass
fill ~-110 ~2 ~114 ~-110 ~3 ~114 minecraft:light_gray_stained_glass
fill ~-115 ~2 ~117 ~-115 ~3 ~117 minecraft:gray_stained_glass
fill ~-110 ~2 ~117 ~-110 ~3 ~117 minecraft:light_gray_stained_glass
fill ~-115 ~2 ~120 ~-115 ~3 ~120 minecraft:gray_stained_glass
fill ~-110 ~2 ~120 ~-110 ~3 ~120 minecraft:light_gray_stained_glass
fill ~-113 ~6 ~112 ~-113 ~7 ~112 minecraft:gray_stained_glass
fill ~-113 ~6 ~124 ~-113 ~7 ~124 minecraft:light_gray_stained_glass
fill ~-115 ~6 ~114 ~-115 ~7 ~114 minecraft:gray_stained_glass
fill ~-110 ~6 ~114 ~-110 ~7 ~114 minecraft:light_gray_stained_glass
fill ~-115 ~6 ~117 ~-115 ~7 ~117 minecraft:gray_stained_glass
fill ~-110 ~6 ~117 ~-110 ~7 ~117 minecraft:light_gray_stained_glass
fill ~-115 ~6 ~120 ~-115 ~7 ~120 minecraft:gray_stained_glass
fill ~-110 ~6 ~120 ~-110 ~7 ~120 minecraft:light_gray_stained_glass
setblock ~-113 ~1 ~112 minecraft:iron_door[half=lower,facing=north]
setblock ~-113 ~2 ~112 minecraft:iron_door[half=upper,facing=north]
fill ~-115 ~10 ~112 ~-110 ~10 ~124 minecraft:dark_oak_slab
fill ~-114 ~11 ~113 ~-111 ~11 ~123 minecraft:dark_oak_slab
setblock ~-113 ~3 ~111 minecraft:dark_oak_slab[type=top]
# 014 lowrise_housing style=rowhouse context=local_front facing=west
fill ~-48 ~-3 ~-6 ~-38 ~-1 ~9 minecraft:stone
fill ~-48 ~0 ~-6 ~-38 ~12 ~9 minecraft:bricks
fill ~-47 ~1 ~-5 ~-39 ~11 ~8 minecraft:air
fill ~-47 ~4 ~-5 ~-39 ~4 ~8 minecraft:smooth_stone
fill ~-47 ~8 ~-5 ~-39 ~8 ~8 minecraft:smooth_stone
fill ~-46 ~2 ~-6 ~-46 ~3 ~-6 minecraft:gray_stained_glass
fill ~-46 ~2 ~9 ~-46 ~3 ~9 minecraft:light_gray_stained_glass
fill ~-43 ~2 ~-6 ~-43 ~3 ~-6 minecraft:gray_stained_glass
fill ~-43 ~2 ~9 ~-43 ~3 ~9 minecraft:light_gray_stained_glass
fill ~-40 ~2 ~-6 ~-40 ~3 ~-6 minecraft:gray_stained_glass
fill ~-40 ~2 ~9 ~-40 ~3 ~9 minecraft:light_gray_stained_glass
fill ~-48 ~2 ~-4 ~-48 ~3 ~-4 minecraft:gray_stained_glass
fill ~-38 ~2 ~-4 ~-38 ~3 ~-4 minecraft:light_gray_stained_glass
fill ~-48 ~2 ~-1 ~-48 ~3 ~-1 minecraft:gray_stained_glass
fill ~-38 ~2 ~-1 ~-38 ~3 ~-1 minecraft:light_gray_stained_glass
fill ~-48 ~2 ~2 ~-48 ~3 ~2 minecraft:gray_stained_glass
fill ~-38 ~2 ~2 ~-38 ~3 ~2 minecraft:light_gray_stained_glass
fill ~-48 ~2 ~5 ~-48 ~3 ~5 minecraft:gray_stained_glass
fill ~-38 ~2 ~5 ~-38 ~3 ~5 minecraft:light_gray_stained_glass
fill ~-46 ~6 ~-6 ~-46 ~7 ~-6 minecraft:gray_stained_glass
fill ~-46 ~6 ~9 ~-46 ~7 ~9 minecraft:light_gray_stained_glass
fill ~-43 ~6 ~-6 ~-43 ~7 ~-6 minecraft:gray_stained_glass
fill ~-43 ~6 ~9 ~-43 ~7 ~9 minecraft:light_gray_stained_glass
fill ~-40 ~6 ~-6 ~-40 ~7 ~-6 minecraft:gray_stained_glass
fill ~-40 ~6 ~9 ~-40 ~7 ~9 minecraft:light_gray_stained_glass
fill ~-48 ~6 ~-4 ~-48 ~7 ~-4 minecraft:gray_stained_glass
fill ~-38 ~6 ~-4 ~-38 ~7 ~-4 minecraft:light_gray_stained_glass
fill ~-48 ~6 ~-1 ~-48 ~7 ~-1 minecraft:gray_stained_glass
fill ~-38 ~6 ~-1 ~-38 ~7 ~-1 minecraft:light_gray_stained_glass
fill ~-48 ~6 ~2 ~-48 ~7 ~2 minecraft:gray_stained_glass
fill ~-38 ~6 ~2 ~-38 ~7 ~2 minecraft:light_gray_stained_glass
fill ~-48 ~6 ~5 ~-48 ~7 ~5 minecraft:gray_stained_glass
fill ~-38 ~6 ~5 ~-38 ~7 ~5 minecraft:light_gray_stained_glass
fill ~-46 ~10 ~-6 ~-46 ~11 ~-6 minecraft:gray_stained_glass
fill ~-46 ~10 ~9 ~-46 ~11 ~9 minecraft:light_gray_stained_glass
fill ~-43 ~10 ~-6 ~-43 ~11 ~-6 minecraft:gray_stained_glass
fill ~-43 ~10 ~9 ~-43 ~11 ~9 minecraft:light_gray_stained_glass
fill ~-40 ~10 ~-6 ~-40 ~11 ~-6 minecraft:gray_stained_glass
fill ~-40 ~10 ~9 ~-40 ~11 ~9 minecraft:light_gray_stained_glass
fill ~-48 ~10 ~-4 ~-48 ~11 ~-4 minecraft:gray_stained_glass
fill ~-38 ~10 ~-4 ~-38 ~11 ~-4 minecraft:light_gray_stained_glass
fill ~-48 ~10 ~-1 ~-48 ~11 ~-1 minecraft:gray_stained_glass
fill ~-38 ~10 ~-1 ~-38 ~11 ~-1 minecraft:light_gray_stained_glass
fill ~-48 ~10 ~2 ~-48 ~11 ~2 minecraft:gray_stained_glass
fill ~-38 ~10 ~2 ~-38 ~11 ~2 minecraft:light_gray_stained_glass
fill ~-48 ~10 ~5 ~-48 ~11 ~5 minecraft:gray_stained_glass
fill ~-38 ~10 ~5 ~-38 ~11 ~5 minecraft:light_gray_stained_glass
setblock ~-48 ~1 ~-1 minecraft:iron_door[half=lower,facing=west]
setblock ~-48 ~2 ~-1 minecraft:iron_door[half=upper,facing=west]
fill ~-48 ~13 ~-6 ~-38 ~13 ~9 minecraft:deepslate_tile_slab
fill ~-47 ~14 ~-5 ~-39 ~14 ~8 minecraft:deepslate_tile_slab
setblock ~-49 ~3 ~-1 minecraft:dark_oak_slab[type=top]
# 015 row_house style=rowhouse context=back_block facing=south
fill ~85 ~-3 ~-52 ~92 ~-1 ~-44 minecraft:stone
fill ~85 ~0 ~-52 ~92 ~7 ~-44 minecraft:calcite
fill ~86 ~1 ~-51 ~91 ~6 ~-45 minecraft:air
fill ~86 ~4 ~-51 ~91 ~4 ~-45 minecraft:smooth_stone
fill ~87 ~2 ~-52 ~87 ~3 ~-52 minecraft:gray_stained_glass
fill ~87 ~2 ~-44 ~87 ~3 ~-44 minecraft:light_gray_stained_glass
fill ~90 ~2 ~-52 ~90 ~3 ~-52 minecraft:gray_stained_glass
fill ~90 ~2 ~-44 ~90 ~3 ~-44 minecraft:light_gray_stained_glass
fill ~85 ~2 ~-50 ~85 ~3 ~-50 minecraft:gray_stained_glass
fill ~92 ~2 ~-50 ~92 ~3 ~-50 minecraft:light_gray_stained_glass
fill ~85 ~2 ~-47 ~85 ~3 ~-47 minecraft:gray_stained_glass
fill ~92 ~2 ~-47 ~92 ~3 ~-47 minecraft:light_gray_stained_glass
setblock ~88 ~1 ~-44 minecraft:iron_door[half=lower,facing=south]
setblock ~88 ~2 ~-44 minecraft:iron_door[half=upper,facing=south]
fill ~85 ~8 ~-52 ~92 ~8 ~-44 minecraft:stone_brick_slab
fill ~86 ~9 ~-51 ~91 ~9 ~-45 minecraft:stone_brick_slab
setblock ~88 ~3 ~-43 minecraft:dark_oak_slab[type=top]
# 016 workshop style=sawtooth context=back_block facing=south
fill ~-20 ~-3 ~54 ~-14 ~-1 ~67 minecraft:stone
fill ~-20 ~0 ~54 ~-14 ~16 ~67 minecraft:smooth_sandstone
fill ~-19 ~1 ~55 ~-15 ~15 ~66 minecraft:air
fill ~-19 ~4 ~55 ~-15 ~4 ~66 minecraft:smooth_stone
fill ~-19 ~8 ~55 ~-15 ~8 ~66 minecraft:smooth_stone
fill ~-19 ~12 ~55 ~-15 ~12 ~66 minecraft:smooth_stone
fill ~-18 ~2 ~54 ~-18 ~3 ~54 minecraft:gray_stained_glass
fill ~-18 ~2 ~67 ~-18 ~3 ~67 minecraft:light_gray_stained_glass
fill ~-20 ~2 ~56 ~-20 ~3 ~56 minecraft:gray_stained_glass
fill ~-14 ~2 ~56 ~-14 ~3 ~56 minecraft:light_gray_stained_glass
fill ~-20 ~2 ~59 ~-20 ~3 ~59 minecraft:gray_stained_glass
fill ~-14 ~2 ~59 ~-14 ~3 ~59 minecraft:light_gray_stained_glass
fill ~-20 ~2 ~62 ~-20 ~3 ~62 minecraft:gray_stained_glass
fill ~-14 ~2 ~62 ~-14 ~3 ~62 minecraft:light_gray_stained_glass
fill ~-20 ~2 ~65 ~-20 ~3 ~65 minecraft:gray_stained_glass
fill ~-14 ~2 ~65 ~-14 ~3 ~65 minecraft:light_gray_stained_glass
fill ~-18 ~6 ~54 ~-18 ~7 ~54 minecraft:gray_stained_glass
fill ~-18 ~6 ~67 ~-18 ~7 ~67 minecraft:light_gray_stained_glass
fill ~-20 ~6 ~56 ~-20 ~7 ~56 minecraft:gray_stained_glass
fill ~-14 ~6 ~56 ~-14 ~7 ~56 minecraft:light_gray_stained_glass
fill ~-20 ~6 ~59 ~-20 ~7 ~59 minecraft:gray_stained_glass
fill ~-14 ~6 ~59 ~-14 ~7 ~59 minecraft:light_gray_stained_glass
fill ~-20 ~6 ~62 ~-20 ~7 ~62 minecraft:gray_stained_glass
fill ~-14 ~6 ~62 ~-14 ~7 ~62 minecraft:light_gray_stained_glass
fill ~-20 ~6 ~65 ~-20 ~7 ~65 minecraft:gray_stained_glass
fill ~-14 ~6 ~65 ~-14 ~7 ~65 minecraft:light_gray_stained_glass
fill ~-18 ~10 ~54 ~-18 ~11 ~54 minecraft:gray_stained_glass
fill ~-18 ~10 ~67 ~-18 ~11 ~67 minecraft:light_gray_stained_glass
fill ~-20 ~10 ~56 ~-20 ~11 ~56 minecraft:gray_stained_glass
fill ~-14 ~10 ~56 ~-14 ~11 ~56 minecraft:light_gray_stained_glass
fill ~-20 ~10 ~59 ~-20 ~11 ~59 minecraft:gray_stained_glass
fill ~-14 ~10 ~59 ~-14 ~11 ~59 minecraft:light_gray_stained_glass
fill ~-20 ~10 ~62 ~-20 ~11 ~62 minecraft:gray_stained_glass
fill ~-14 ~10 ~62 ~-14 ~11 ~62 minecraft:light_gray_stained_glass
fill ~-20 ~10 ~65 ~-20 ~11 ~65 minecraft:gray_stained_glass
fill ~-14 ~10 ~65 ~-14 ~11 ~65 minecraft:light_gray_stained_glass
fill ~-18 ~14 ~54 ~-18 ~15 ~54 minecraft:gray_stained_glass
fill ~-18 ~14 ~67 ~-18 ~15 ~67 minecraft:light_gray_stained_glass
fill ~-20 ~14 ~56 ~-20 ~15 ~56 minecraft:gray_stained_glass
fill ~-14 ~14 ~56 ~-14 ~15 ~56 minecraft:light_gray_stained_glass
fill ~-20 ~14 ~59 ~-20 ~15 ~59 minecraft:gray_stained_glass
fill ~-14 ~14 ~59 ~-14 ~15 ~59 minecraft:light_gray_stained_glass
fill ~-20 ~14 ~62 ~-20 ~15 ~62 minecraft:gray_stained_glass
fill ~-14 ~14 ~62 ~-14 ~15 ~62 minecraft:light_gray_stained_glass
fill ~-20 ~14 ~65 ~-20 ~15 ~65 minecraft:gray_stained_glass
fill ~-14 ~14 ~65 ~-14 ~15 ~65 minecraft:light_gray_stained_glass
setblock ~-17 ~1 ~67 minecraft:iron_door[half=lower,facing=south]
setblock ~-17 ~2 ~67 minecraft:iron_door[half=upper,facing=south]
fill ~-18 ~1 ~67 ~-16 ~4 ~67 minecraft:polished_blackstone
fill ~-18 ~5 ~67 ~-16 ~5 ~67 minecraft:light_blue_stained_glass
fill ~-18 ~18 ~56 ~-16 ~19 ~58 minecraft:iron_block
fill ~-20 ~17 ~54 ~-14 ~17 ~67 minecraft:stone_brick_slab
