# Buildings 89..96
# 089 restaurant style=corner_store context=collector_front facing=east
fill ~-105 ~-3 ~52 ~-94 ~-1 ~56 minecraft:stone
fill ~-105 ~0 ~52 ~-94 ~7 ~56 minecraft:calcite
fill ~-104 ~1 ~53 ~-95 ~6 ~55 minecraft:air
fill ~-104 ~4 ~53 ~-95 ~4 ~55 minecraft:smooth_stone
fill ~-103 ~2 ~52 ~-103 ~3 ~52 minecraft:gray_stained_glass
fill ~-103 ~2 ~56 ~-103 ~3 ~56 minecraft:light_gray_stained_glass
fill ~-100 ~2 ~52 ~-100 ~3 ~52 minecraft:gray_stained_glass
fill ~-100 ~2 ~56 ~-100 ~3 ~56 minecraft:light_gray_stained_glass
fill ~-97 ~2 ~52 ~-97 ~3 ~52 minecraft:gray_stained_glass
fill ~-97 ~2 ~56 ~-97 ~3 ~56 minecraft:light_gray_stained_glass
fill ~-105 ~2 ~54 ~-105 ~3 ~54 minecraft:gray_stained_glass
fill ~-94 ~2 ~54 ~-94 ~3 ~54 minecraft:light_gray_stained_glass
setblock ~-94 ~1 ~54 minecraft:iron_door[half=lower,facing=east]
setblock ~-94 ~2 ~54 minecraft:iron_door[half=upper,facing=east]
fill ~-94 ~1 ~53 ~-94 ~3 ~55 minecraft:cyan_stained_glass
setblock ~-94 ~1 ~54 minecraft:iron_door[half=lower,facing=east]
setblock ~-94 ~2 ~54 minecraft:iron_door[half=upper,facing=east]
setblock ~-93 ~3 ~54 minecraft:red_wool
fill ~-105 ~8 ~52 ~-94 ~8 ~56 minecraft:stone_brick_slab
# 090 workshop style=industrial_shed context=local_front facing=north
fill ~106 ~-3 ~-106 ~111 ~-1 ~-97 minecraft:stone
fill ~106 ~0 ~-106 ~111 ~9 ~-97 minecraft:bricks
fill ~107 ~1 ~-105 ~110 ~8 ~-98 minecraft:air
fill ~107 ~4 ~-105 ~110 ~4 ~-98 minecraft:smooth_stone
fill ~107 ~8 ~-105 ~110 ~8 ~-98 minecraft:smooth_stone
fill ~108 ~2 ~-106 ~108 ~3 ~-106 minecraft:gray_stained_glass
fill ~108 ~2 ~-97 ~108 ~3 ~-97 minecraft:light_gray_stained_glass
fill ~106 ~2 ~-104 ~106 ~3 ~-104 minecraft:gray_stained_glass
fill ~111 ~2 ~-104 ~111 ~3 ~-104 minecraft:light_gray_stained_glass
fill ~106 ~2 ~-101 ~106 ~3 ~-101 minecraft:gray_stained_glass
fill ~111 ~2 ~-101 ~111 ~3 ~-101 minecraft:light_gray_stained_glass
fill ~108 ~6 ~-106 ~108 ~7 ~-106 minecraft:gray_stained_glass
fill ~108 ~6 ~-97 ~108 ~7 ~-97 minecraft:light_gray_stained_glass
fill ~106 ~6 ~-104 ~106 ~7 ~-104 minecraft:gray_stained_glass
fill ~111 ~6 ~-104 ~111 ~7 ~-104 minecraft:light_gray_stained_glass
fill ~106 ~6 ~-101 ~106 ~7 ~-101 minecraft:gray_stained_glass
fill ~111 ~6 ~-101 ~111 ~7 ~-101 minecraft:light_gray_stained_glass
setblock ~108 ~1 ~-106 minecraft:iron_door[half=lower,facing=north]
setblock ~108 ~2 ~-106 minecraft:iron_door[half=upper,facing=north]
fill ~108 ~1 ~-106 ~109 ~4 ~-106 minecraft:polished_blackstone
fill ~108 ~5 ~-106 ~109 ~5 ~-106 minecraft:light_blue_stained_glass
fill ~108 ~11 ~-104 ~110 ~12 ~-102 minecraft:iron_block
fill ~106 ~10 ~-106 ~111 ~10 ~-97 minecraft:deepslate_tile_slab
fill ~108 ~11 ~-104 ~110 ~12 ~-102 minecraft:light_gray_concrete
setblock ~110 ~11 ~-103 minecraft:lightning_rod
fill ~107 ~1 ~-106 ~107 ~7 ~-106 minecraft:weathered_cut_copper
# 091 community style=mixed_facade context=collector_front facing=west
fill ~-92 ~-3 ~-35 ~-82 ~-1 ~-22 minecraft:stone
fill ~-92 ~0 ~-35 ~-82 ~10 ~-22 minecraft:light_gray_concrete
fill ~-91 ~1 ~-34 ~-83 ~9 ~-23 minecraft:air
fill ~-91 ~4 ~-34 ~-83 ~4 ~-23 minecraft:smooth_stone
fill ~-91 ~8 ~-34 ~-83 ~8 ~-23 minecraft:smooth_stone
fill ~-90 ~2 ~-35 ~-90 ~3 ~-35 minecraft:gray_stained_glass
fill ~-90 ~2 ~-22 ~-90 ~3 ~-22 minecraft:light_gray_stained_glass
fill ~-87 ~2 ~-35 ~-87 ~3 ~-35 minecraft:gray_stained_glass
fill ~-87 ~2 ~-22 ~-87 ~3 ~-22 minecraft:light_gray_stained_glass
fill ~-84 ~2 ~-35 ~-84 ~3 ~-35 minecraft:gray_stained_glass
fill ~-84 ~2 ~-22 ~-84 ~3 ~-22 minecraft:light_gray_stained_glass
fill ~-92 ~2 ~-33 ~-92 ~3 ~-33 minecraft:gray_stained_glass
fill ~-82 ~2 ~-33 ~-82 ~3 ~-33 minecraft:light_gray_stained_glass
fill ~-92 ~2 ~-30 ~-92 ~3 ~-30 minecraft:gray_stained_glass
fill ~-82 ~2 ~-30 ~-82 ~3 ~-30 minecraft:light_gray_stained_glass
fill ~-92 ~2 ~-27 ~-92 ~3 ~-27 minecraft:gray_stained_glass
fill ~-82 ~2 ~-27 ~-82 ~3 ~-27 minecraft:light_gray_stained_glass
fill ~-92 ~2 ~-24 ~-92 ~3 ~-24 minecraft:gray_stained_glass
fill ~-82 ~2 ~-24 ~-82 ~3 ~-24 minecraft:light_gray_stained_glass
fill ~-90 ~6 ~-35 ~-90 ~7 ~-35 minecraft:gray_stained_glass
fill ~-90 ~6 ~-22 ~-90 ~7 ~-22 minecraft:light_gray_stained_glass
fill ~-87 ~6 ~-35 ~-87 ~7 ~-35 minecraft:gray_stained_glass
fill ~-87 ~6 ~-22 ~-87 ~7 ~-22 minecraft:light_gray_stained_glass
fill ~-84 ~6 ~-35 ~-84 ~7 ~-35 minecraft:gray_stained_glass
fill ~-84 ~6 ~-22 ~-84 ~7 ~-22 minecraft:light_gray_stained_glass
fill ~-92 ~6 ~-33 ~-92 ~7 ~-33 minecraft:gray_stained_glass
fill ~-82 ~6 ~-33 ~-82 ~7 ~-33 minecraft:light_gray_stained_glass
fill ~-92 ~6 ~-30 ~-92 ~7 ~-30 minecraft:gray_stained_glass
fill ~-82 ~6 ~-30 ~-82 ~7 ~-30 minecraft:light_gray_stained_glass
fill ~-92 ~6 ~-27 ~-92 ~7 ~-27 minecraft:gray_stained_glass
fill ~-82 ~6 ~-27 ~-82 ~7 ~-27 minecraft:light_gray_stained_glass
fill ~-92 ~6 ~-24 ~-92 ~7 ~-24 minecraft:gray_stained_glass
fill ~-82 ~6 ~-24 ~-82 ~7 ~-24 minecraft:light_gray_stained_glass
setblock ~-92 ~1 ~-30 minecraft:iron_door[half=lower,facing=west]
setblock ~-92 ~2 ~-30 minecraft:iron_door[half=upper,facing=west]
fill ~-92 ~11 ~-35 ~-82 ~11 ~-22 minecraft:smooth_stone_slab
fill ~-92 ~1 ~-34 ~-92 ~7 ~-34 doomsday_decoration:porcelainbrickwall
fill ~-92 ~1 ~-30 ~-92 ~7 ~-30 doomsday_decoration:porcelainbrickwall
fill ~-92 ~1 ~-26 ~-92 ~7 ~-26 doomsday_decoration:porcelainbrickwall
# 092 clinic style=setback_block context=collector_front facing=south
fill ~105 ~-3 ~-83 ~112 ~-1 ~-76 minecraft:stone
fill ~105 ~0 ~-83 ~112 ~11 ~-76 minecraft:bricks
fill ~106 ~1 ~-82 ~111 ~10 ~-77 minecraft:air
fill ~106 ~4 ~-82 ~111 ~4 ~-77 minecraft:smooth_stone
fill ~106 ~8 ~-82 ~111 ~8 ~-77 minecraft:smooth_stone
fill ~107 ~2 ~-83 ~107 ~3 ~-83 minecraft:gray_stained_glass
fill ~107 ~2 ~-76 ~107 ~3 ~-76 minecraft:light_gray_stained_glass
fill ~110 ~2 ~-83 ~110 ~3 ~-83 minecraft:gray_stained_glass
fill ~110 ~2 ~-76 ~110 ~3 ~-76 minecraft:light_gray_stained_glass
fill ~105 ~2 ~-81 ~105 ~3 ~-81 minecraft:gray_stained_glass
fill ~112 ~2 ~-81 ~112 ~3 ~-81 minecraft:light_gray_stained_glass
fill ~105 ~2 ~-78 ~105 ~3 ~-78 minecraft:gray_stained_glass
fill ~112 ~2 ~-78 ~112 ~3 ~-78 minecraft:light_gray_stained_glass
fill ~107 ~6 ~-83 ~107 ~7 ~-83 minecraft:gray_stained_glass
fill ~107 ~6 ~-76 ~107 ~7 ~-76 minecraft:light_gray_stained_glass
fill ~110 ~6 ~-83 ~110 ~7 ~-83 minecraft:gray_stained_glass
fill ~110 ~6 ~-76 ~110 ~7 ~-76 minecraft:light_gray_stained_glass
fill ~105 ~6 ~-81 ~105 ~7 ~-81 minecraft:gray_stained_glass
fill ~112 ~6 ~-81 ~112 ~7 ~-81 minecraft:light_gray_stained_glass
fill ~105 ~6 ~-78 ~105 ~7 ~-78 minecraft:gray_stained_glass
fill ~112 ~6 ~-78 ~112 ~7 ~-78 minecraft:light_gray_stained_glass
setblock ~108 ~1 ~-76 minecraft:iron_door[half=lower,facing=south]
setblock ~108 ~2 ~-76 minecraft:iron_door[half=upper,facing=south]
fill ~105 ~7 ~-83 ~112 ~11 ~-76 minecraft:air
fill ~106 ~7 ~-82 ~111 ~11 ~-77 minecraft:bricks
fill ~107 ~8 ~-81 ~110 ~10 ~-78 minecraft:air
fill ~106 ~12 ~-82 ~111 ~12 ~-77 minecraft:deepslate_tile_slab
fill ~106 ~1 ~-76 ~106 ~7 ~-76 minecraft:weathered_cut_copper
fill ~110 ~1 ~-76 ~110 ~7 ~-76 minecraft:weathered_cut_copper
# 093 restaurant style=arcade_shop context=waterfront_front facing=north
fill ~105 ~-3 ~77 ~114 ~-1 ~85 minecraft:stone
fill ~105 ~0 ~77 ~114 ~7 ~85 minecraft:bricks
fill ~106 ~1 ~78 ~113 ~6 ~84 minecraft:air
fill ~106 ~4 ~78 ~113 ~4 ~84 minecraft:smooth_stone
fill ~107 ~2 ~77 ~107 ~3 ~77 minecraft:gray_stained_glass
fill ~107 ~2 ~85 ~107 ~3 ~85 minecraft:light_gray_stained_glass
fill ~110 ~2 ~77 ~110 ~3 ~77 minecraft:gray_stained_glass
fill ~110 ~2 ~85 ~110 ~3 ~85 minecraft:light_gray_stained_glass
fill ~105 ~2 ~79 ~105 ~3 ~79 minecraft:gray_stained_glass
fill ~114 ~2 ~79 ~114 ~3 ~79 minecraft:light_gray_stained_glass
fill ~105 ~2 ~82 ~105 ~3 ~82 minecraft:gray_stained_glass
fill ~114 ~2 ~82 ~114 ~3 ~82 minecraft:light_gray_stained_glass
setblock ~109 ~1 ~77 minecraft:iron_door[half=lower,facing=north]
setblock ~109 ~2 ~77 minecraft:iron_door[half=upper,facing=north]
fill ~106 ~1 ~77 ~113 ~3 ~77 minecraft:cyan_stained_glass
setblock ~109 ~1 ~77 minecraft:iron_door[half=lower,facing=north]
setblock ~109 ~2 ~77 minecraft:iron_door[half=upper,facing=north]
setblock ~109 ~3 ~76 minecraft:red_wool
fill ~106 ~4 ~77 ~113 ~4 ~77 minecraft:weathered_cut_copper
fill ~105 ~8 ~77 ~114 ~8 ~85 minecraft:deepslate_tile_slab
fill ~106 ~1 ~77 ~106 ~7 ~77 minecraft:weathered_cut_copper
fill ~110 ~1 ~77 ~110 ~7 ~77 minecraft:weathered_cut_copper
setblock ~107 ~3 ~77 minecraft:red_carpet
setblock ~112 ~3 ~77 minecraft:red_carpet
# 094 mixed_use style=setback_block context=arterial_front facing=west
fill ~-31 ~-3 ~74 ~-19 ~-1 ~80 minecraft:stone
fill ~-31 ~0 ~74 ~-19 ~8 ~80 minecraft:smooth_sandstone
fill ~-30 ~1 ~75 ~-20 ~7 ~79 minecraft:air
fill ~-30 ~4 ~75 ~-20 ~4 ~79 minecraft:smooth_stone
fill ~-29 ~2 ~74 ~-29 ~3 ~74 minecraft:gray_stained_glass
fill ~-29 ~2 ~80 ~-29 ~3 ~80 minecraft:light_gray_stained_glass
fill ~-26 ~2 ~74 ~-26 ~3 ~74 minecraft:gray_stained_glass
fill ~-26 ~2 ~80 ~-26 ~3 ~80 minecraft:light_gray_stained_glass
fill ~-23 ~2 ~74 ~-23 ~3 ~74 minecraft:gray_stained_glass
fill ~-23 ~2 ~80 ~-23 ~3 ~80 minecraft:light_gray_stained_glass
fill ~-31 ~2 ~76 ~-31 ~3 ~76 minecraft:gray_stained_glass
fill ~-19 ~2 ~76 ~-19 ~3 ~76 minecraft:light_gray_stained_glass
fill ~-29 ~6 ~74 ~-29 ~7 ~74 minecraft:gray_stained_glass
fill ~-29 ~6 ~80 ~-29 ~7 ~80 minecraft:light_gray_stained_glass
fill ~-26 ~6 ~74 ~-26 ~7 ~74 minecraft:gray_stained_glass
fill ~-26 ~6 ~80 ~-26 ~7 ~80 minecraft:light_gray_stained_glass
fill ~-23 ~6 ~74 ~-23 ~7 ~74 minecraft:gray_stained_glass
fill ~-23 ~6 ~80 ~-23 ~7 ~80 minecraft:light_gray_stained_glass
fill ~-31 ~6 ~76 ~-31 ~7 ~76 minecraft:gray_stained_glass
fill ~-19 ~6 ~76 ~-19 ~7 ~76 minecraft:light_gray_stained_glass
setblock ~-31 ~1 ~77 minecraft:iron_door[half=lower,facing=west]
setblock ~-31 ~2 ~77 minecraft:iron_door[half=upper,facing=west]
fill ~-31 ~1 ~75 ~-31 ~7 ~75 minecraft:brown_terracotta
fill ~-31 ~1 ~79 ~-31 ~7 ~79 minecraft:brown_terracotta
setblock ~-31 ~3 ~76 minecraft:red_carpet
# 095 restaurant style=storefront context=collector_front facing=west
fill ~-82 ~-3 ~98 ~-76 ~-1 ~105 minecraft:stone
fill ~-82 ~0 ~98 ~-76 ~9 ~105 minecraft:calcite
fill ~-81 ~1 ~99 ~-77 ~8 ~104 minecraft:air
fill ~-81 ~4 ~99 ~-77 ~4 ~104 minecraft:smooth_stone
fill ~-81 ~8 ~99 ~-77 ~8 ~104 minecraft:smooth_stone
fill ~-80 ~2 ~98 ~-80 ~3 ~98 minecraft:gray_stained_glass
fill ~-80 ~2 ~105 ~-80 ~3 ~105 minecraft:light_gray_stained_glass
fill ~-82 ~2 ~100 ~-82 ~3 ~100 minecraft:gray_stained_glass
fill ~-76 ~2 ~100 ~-76 ~3 ~100 minecraft:light_gray_stained_glass
fill ~-82 ~2 ~103 ~-82 ~3 ~103 minecraft:gray_stained_glass
fill ~-76 ~2 ~103 ~-76 ~3 ~103 minecraft:light_gray_stained_glass
fill ~-80 ~6 ~98 ~-80 ~7 ~98 minecraft:gray_stained_glass
fill ~-80 ~6 ~105 ~-80 ~7 ~105 minecraft:light_gray_stained_glass
fill ~-82 ~6 ~100 ~-82 ~7 ~100 minecraft:gray_stained_glass
fill ~-76 ~6 ~100 ~-76 ~7 ~100 minecraft:light_gray_stained_glass
fill ~-82 ~6 ~103 ~-82 ~7 ~103 minecraft:gray_stained_glass
fill ~-76 ~6 ~103 ~-76 ~7 ~103 minecraft:light_gray_stained_glass
setblock ~-82 ~1 ~101 minecraft:iron_door[half=lower,facing=west]
setblock ~-82 ~2 ~101 minecraft:iron_door[half=upper,facing=west]
fill ~-82 ~1 ~99 ~-82 ~3 ~104 minecraft:cyan_stained_glass
setblock ~-82 ~1 ~101 minecraft:iron_door[half=lower,facing=west]
setblock ~-82 ~2 ~101 minecraft:iron_door[half=upper,facing=west]
setblock ~-83 ~3 ~101 minecraft:red_wool
fill ~-82 ~10 ~98 ~-76 ~10 ~105 minecraft:stone_brick_slab
fill ~-82 ~1 ~99 ~-82 ~7 ~99 minecraft:gray_concrete
fill ~-82 ~1 ~103 ~-82 ~7 ~103 minecraft:gray_concrete
setblock ~-82 ~3 ~100 minecraft:red_carpet
# 096 shop_house style=arcade_shop context=collector_front facing=east
fill ~32 ~-3 ~117 ~40 ~-1 ~121 minecraft:stone
fill ~32 ~0 ~117 ~40 ~9 ~121 minecraft:mud_bricks
fill ~33 ~1 ~118 ~39 ~8 ~120 minecraft:air
fill ~33 ~4 ~118 ~39 ~4 ~120 minecraft:smooth_stone
fill ~33 ~8 ~118 ~39 ~8 ~120 minecraft:smooth_stone
fill ~34 ~2 ~117 ~34 ~3 ~117 minecraft:gray_stained_glass
fill ~34 ~2 ~121 ~34 ~3 ~121 minecraft:light_gray_stained_glass
fill ~37 ~2 ~117 ~37 ~3 ~117 minecraft:gray_stained_glass
fill ~37 ~2 ~121 ~37 ~3 ~121 minecraft:light_gray_stained_glass
fill ~32 ~2 ~119 ~32 ~3 ~119 minecraft:gray_stained_glass
fill ~40 ~2 ~119 ~40 ~3 ~119 minecraft:light_gray_stained_glass
fill ~34 ~6 ~117 ~34 ~7 ~117 minecraft:gray_stained_glass
fill ~34 ~6 ~121 ~34 ~7 ~121 minecraft:light_gray_stained_glass
fill ~37 ~6 ~117 ~37 ~7 ~117 minecraft:gray_stained_glass
fill ~37 ~6 ~121 ~37 ~7 ~121 minecraft:light_gray_stained_glass
fill ~32 ~6 ~119 ~32 ~7 ~119 minecraft:gray_stained_glass
fill ~40 ~6 ~119 ~40 ~7 ~119 minecraft:light_gray_stained_glass
setblock ~40 ~1 ~119 minecraft:iron_door[half=lower,facing=east]
setblock ~40 ~2 ~119 minecraft:iron_door[half=upper,facing=east]
fill ~40 ~1 ~118 ~40 ~3 ~120 minecraft:cyan_stained_glass
setblock ~40 ~1 ~119 minecraft:iron_door[half=lower,facing=east]
setblock ~40 ~2 ~119 minecraft:iron_door[half=upper,facing=east]
setblock ~41 ~3 ~119 minecraft:red_wool
fill ~40 ~4 ~118 ~40 ~4 ~120 minecraft:spruce_planks
fill ~32 ~10 ~117 ~40 ~10 ~121 minecraft:deepslate_tile_slab
fill ~34 ~11 ~119 ~36 ~12 ~120 minecraft:light_gray_concrete
setblock ~37 ~11 ~120 minecraft:lightning_rod
