# Buildings 281..288
# 281 small_office style=rowhouse context=back_block facing=east
fill ~-73 ~-3 ~31 ~-70 ~-1 ~37 minecraft:stone
fill ~-73 ~0 ~31 ~-70 ~5 ~37 minecraft:bricks
fill ~-72 ~1 ~32 ~-71 ~4 ~36 minecraft:air
fill ~-72 ~4 ~32 ~-71 ~4 ~36 minecraft:smooth_stone
fill ~-73 ~2 ~33 ~-73 ~3 ~33 minecraft:gray_stained_glass
fill ~-70 ~2 ~33 ~-70 ~3 ~33 minecraft:light_gray_stained_glass
setblock ~-70 ~1 ~34 minecraft:iron_door[half=lower,facing=east]
setblock ~-70 ~2 ~34 minecraft:iron_door[half=upper,facing=east]
fill ~-73 ~6 ~31 ~-70 ~6 ~37 minecraft:deepslate_tile_slab
fill ~-72 ~7 ~32 ~-71 ~7 ~36 minecraft:deepslate_tile_slab
setblock ~-69 ~3 ~34 minecraft:dark_oak_slab[type=top]
# 282 row_house style=rowhouse context=back_block facing=south
fill ~24 ~-3 ~12 ~27 ~-1 ~17 minecraft:stone
fill ~24 ~0 ~12 ~27 ~9 ~17 minecraft:bricks
fill ~25 ~1 ~13 ~26 ~8 ~16 minecraft:air
fill ~25 ~4 ~13 ~26 ~4 ~16 minecraft:smooth_stone
fill ~25 ~8 ~13 ~26 ~8 ~16 minecraft:smooth_stone
fill ~24 ~2 ~14 ~24 ~3 ~14 minecraft:gray_stained_glass
fill ~27 ~2 ~14 ~27 ~3 ~14 minecraft:light_gray_stained_glass
fill ~24 ~6 ~14 ~24 ~7 ~14 minecraft:gray_stained_glass
fill ~27 ~6 ~14 ~27 ~7 ~14 minecraft:light_gray_stained_glass
setblock ~26 ~1 ~17 minecraft:iron_door[half=lower,facing=south]
setblock ~26 ~2 ~17 minecraft:iron_door[half=upper,facing=south]
fill ~24 ~10 ~12 ~27 ~10 ~17 minecraft:deepslate_tile_slab
fill ~25 ~11 ~13 ~26 ~11 ~16 minecraft:deepslate_tile_slab
setblock ~26 ~3 ~18 minecraft:dark_oak_slab[type=top]
fill ~26 ~11 ~14 ~26 ~12 ~16 minecraft:light_gray_concrete
setblock ~26 ~11 ~15 minecraft:lightning_rod
# 283 workshop style=rowhouse context=collector_front facing=north
fill ~57 ~-3 ~85 ~60 ~-1 ~90 minecraft:stone
fill ~57 ~0 ~85 ~60 ~5 ~90 minecraft:stone_bricks
fill ~58 ~1 ~86 ~59 ~4 ~89 minecraft:air
fill ~58 ~4 ~86 ~59 ~4 ~89 minecraft:smooth_stone
fill ~57 ~2 ~87 ~57 ~3 ~87 minecraft:gray_stained_glass
fill ~60 ~2 ~87 ~60 ~3 ~87 minecraft:light_gray_stained_glass
setblock ~59 ~1 ~85 minecraft:iron_door[half=lower,facing=north]
setblock ~59 ~2 ~85 minecraft:iron_door[half=upper,facing=north]
fill ~57 ~6 ~85 ~60 ~6 ~90 minecraft:stone_brick_slab
fill ~58 ~7 ~86 ~59 ~7 ~89 minecraft:stone_brick_slab
setblock ~59 ~3 ~84 minecraft:dark_oak_slab[type=top]
# 284 small_office style=storefront context=collector_front facing=north
fill ~-52 ~-3 ~86 ~-49 ~-1 ~91 minecraft:stone
fill ~-52 ~0 ~86 ~-49 ~9 ~91 minecraft:mud_bricks
fill ~-51 ~1 ~87 ~-50 ~8 ~90 minecraft:air
fill ~-51 ~4 ~87 ~-50 ~4 ~90 minecraft:smooth_stone
fill ~-51 ~8 ~87 ~-50 ~8 ~90 minecraft:smooth_stone
fill ~-52 ~2 ~88 ~-52 ~3 ~88 minecraft:gray_stained_glass
fill ~-49 ~2 ~88 ~-49 ~3 ~88 minecraft:light_gray_stained_glass
fill ~-52 ~6 ~88 ~-52 ~7 ~88 minecraft:gray_stained_glass
fill ~-49 ~6 ~88 ~-49 ~7 ~88 minecraft:light_gray_stained_glass
setblock ~-50 ~1 ~86 minecraft:iron_door[half=lower,facing=north]
setblock ~-50 ~2 ~86 minecraft:iron_door[half=upper,facing=north]
fill ~-51 ~1 ~86 ~-50 ~3 ~86 minecraft:cyan_stained_glass
setblock ~-50 ~1 ~86 minecraft:iron_door[half=lower,facing=north]
setblock ~-50 ~2 ~86 minecraft:iron_door[half=upper,facing=north]
setblock ~-50 ~3 ~85 minecraft:red_wool
fill ~-52 ~10 ~86 ~-49 ~10 ~91 minecraft:deepslate_tile_slab
# 285 shop_house style=storefront context=arterial_front facing=west
fill ~29 ~-3 ~73 ~32 ~-1 ~79 minecraft:stone
fill ~29 ~0 ~73 ~32 ~5 ~79 minecraft:light_gray_concrete
fill ~30 ~1 ~74 ~31 ~4 ~78 minecraft:air
fill ~30 ~4 ~74 ~31 ~4 ~78 minecraft:smooth_stone
fill ~29 ~2 ~75 ~29 ~3 ~75 minecraft:gray_stained_glass
fill ~32 ~2 ~75 ~32 ~3 ~75 minecraft:light_gray_stained_glass
setblock ~29 ~1 ~76 minecraft:iron_door[half=lower,facing=west]
setblock ~29 ~2 ~76 minecraft:iron_door[half=upper,facing=west]
fill ~29 ~1 ~74 ~29 ~3 ~78 minecraft:cyan_stained_glass
setblock ~29 ~1 ~76 minecraft:iron_door[half=lower,facing=west]
setblock ~29 ~2 ~76 minecraft:iron_door[half=upper,facing=west]
setblock ~28 ~3 ~76 minecraft:red_wool
fill ~29 ~6 ~73 ~32 ~6 ~79 minecraft:smooth_stone_slab
# 286 workshop style=stepped_house context=arterial_front facing=north
fill ~-14 ~-3 ~-56 ~-11 ~-1 ~-51 minecraft:stone
fill ~-14 ~0 ~-56 ~-11 ~9 ~-51 minecraft:light_gray_concrete
fill ~-13 ~1 ~-55 ~-12 ~8 ~-52 minecraft:air
fill ~-13 ~4 ~-55 ~-12 ~4 ~-52 minecraft:smooth_stone
fill ~-13 ~8 ~-55 ~-12 ~8 ~-52 minecraft:smooth_stone
fill ~-14 ~2 ~-54 ~-14 ~3 ~-54 minecraft:gray_stained_glass
fill ~-11 ~2 ~-54 ~-11 ~3 ~-54 minecraft:light_gray_stained_glass
fill ~-14 ~6 ~-54 ~-14 ~7 ~-54 minecraft:gray_stained_glass
fill ~-11 ~6 ~-54 ~-11 ~7 ~-54 minecraft:light_gray_stained_glass
setblock ~-12 ~1 ~-56 minecraft:iron_door[half=lower,facing=north]
setblock ~-12 ~2 ~-56 minecraft:iron_door[half=upper,facing=north]
fill ~-14 ~10 ~-56 ~-11 ~10 ~-51 minecraft:smooth_stone_slab
fill ~-13 ~11 ~-55 ~-12 ~11 ~-52 minecraft:smooth_stone_slab
setblock ~-12 ~3 ~-57 minecraft:dark_oak_slab[type=top]
# 287 shop_house style=storefront context=collector_front facing=south
fill ~67 ~-3 ~59 ~70 ~-1 ~65 minecraft:stone
fill ~67 ~0 ~59 ~70 ~9 ~65 minecraft:gray_concrete
fill ~68 ~1 ~60 ~69 ~8 ~64 minecraft:air
fill ~68 ~4 ~60 ~69 ~4 ~64 minecraft:smooth_stone
fill ~68 ~8 ~60 ~69 ~8 ~64 minecraft:smooth_stone
fill ~67 ~2 ~61 ~67 ~3 ~61 minecraft:gray_stained_glass
fill ~70 ~2 ~61 ~70 ~3 ~61 minecraft:light_gray_stained_glass
fill ~67 ~6 ~61 ~67 ~7 ~61 minecraft:gray_stained_glass
fill ~70 ~6 ~61 ~70 ~7 ~61 minecraft:light_gray_stained_glass
setblock ~69 ~1 ~65 minecraft:iron_door[half=lower,facing=south]
setblock ~69 ~2 ~65 minecraft:iron_door[half=upper,facing=south]
fill ~68 ~1 ~65 ~69 ~3 ~65 minecraft:cyan_stained_glass
setblock ~69 ~1 ~65 minecraft:iron_door[half=lower,facing=south]
setblock ~69 ~2 ~65 minecraft:iron_door[half=upper,facing=south]
setblock ~69 ~3 ~66 minecraft:red_wool
fill ~67 ~10 ~59 ~70 ~10 ~65 minecraft:smooth_stone_slab
# 288 small_office style=rowhouse context=local_front facing=east
fill ~-81 ~-3 ~-126 ~-78 ~-1 ~-121 minecraft:stone
fill ~-81 ~0 ~-126 ~-78 ~7 ~-121 minecraft:bricks
fill ~-80 ~1 ~-125 ~-79 ~6 ~-122 minecraft:air
fill ~-80 ~4 ~-125 ~-79 ~4 ~-122 minecraft:smooth_stone
fill ~-81 ~2 ~-124 ~-81 ~3 ~-124 minecraft:gray_stained_glass
fill ~-78 ~2 ~-124 ~-78 ~3 ~-124 minecraft:light_gray_stained_glass
setblock ~-78 ~1 ~-124 minecraft:iron_door[half=lower,facing=east]
setblock ~-78 ~2 ~-124 minecraft:iron_door[half=upper,facing=east]
fill ~-81 ~8 ~-126 ~-78 ~8 ~-121 minecraft:deepslate_tile_slab
fill ~-80 ~9 ~-125 ~-79 ~9 ~-122 minecraft:deepslate_tile_slab
setblock ~-77 ~3 ~-124 minecraft:dark_oak_slab[type=top]
