# Buildings 257..264
# 257 workshop style=loading_bay context=collector_front facing=north
fill ~-15 ~-3 ~-64 ~-12 ~-1 ~-59 minecraft:stone
fill ~-15 ~0 ~-64 ~-12 ~5 ~-59 minecraft:light_gray_concrete
fill ~-14 ~1 ~-63 ~-13 ~4 ~-60 minecraft:air
fill ~-14 ~4 ~-63 ~-13 ~4 ~-60 minecraft:smooth_stone
fill ~-15 ~2 ~-62 ~-15 ~3 ~-62 minecraft:gray_stained_glass
fill ~-12 ~2 ~-62 ~-12 ~3 ~-62 minecraft:light_gray_stained_glass
setblock ~-13 ~1 ~-64 minecraft:iron_door[half=lower,facing=north]
setblock ~-13 ~2 ~-64 minecraft:iron_door[half=upper,facing=north]
fill ~-13 ~1 ~-64 ~-14 ~4 ~-64 minecraft:polished_blackstone
fill ~-13 ~4 ~-64 ~-14 ~4 ~-64 minecraft:light_blue_stained_glass
fill ~-13 ~7 ~-62 ~-13 ~8 ~-60 minecraft:iron_block
fill ~-15 ~6 ~-64 ~-12 ~6 ~-59 minecraft:smooth_stone_slab
# 258 row_house style=rowhouse context=local_front facing=north
fill ~-2 ~-3 ~32 ~1 ~-1 ~37 minecraft:stone
fill ~-2 ~0 ~32 ~1 ~11 ~37 minecraft:light_gray_concrete
fill ~-1 ~1 ~33 ~0 ~10 ~36 minecraft:air
fill ~-1 ~4 ~33 ~0 ~4 ~36 minecraft:smooth_stone
fill ~-1 ~8 ~33 ~0 ~8 ~36 minecraft:smooth_stone
fill ~-2 ~2 ~34 ~-2 ~3 ~34 minecraft:gray_stained_glass
fill ~1 ~2 ~34 ~1 ~3 ~34 minecraft:light_gray_stained_glass
fill ~-2 ~6 ~34 ~-2 ~7 ~34 minecraft:gray_stained_glass
fill ~1 ~6 ~34 ~1 ~7 ~34 minecraft:light_gray_stained_glass
setblock ~0 ~1 ~32 minecraft:iron_door[half=lower,facing=north]
setblock ~0 ~2 ~32 minecraft:iron_door[half=upper,facing=north]
fill ~-2 ~12 ~32 ~1 ~12 ~37 minecraft:smooth_stone_slab
fill ~-1 ~13 ~33 ~0 ~13 ~36 minecraft:smooth_stone_slab
setblock ~0 ~3 ~31 minecraft:dark_oak_slab[type=top]
fill ~0 ~13 ~34 ~0 ~14 ~36 minecraft:light_gray_concrete
setblock ~0 ~13 ~35 minecraft:lightning_rod
# 259 row_house style=rowhouse context=local_front facing=north
fill ~86 ~-3 ~99 ~90 ~-1 ~105 minecraft:stone
fill ~86 ~0 ~99 ~90 ~5 ~105 minecraft:stone_bricks
fill ~87 ~1 ~100 ~89 ~4 ~104 minecraft:air
fill ~87 ~4 ~100 ~89 ~4 ~104 minecraft:smooth_stone
fill ~88 ~2 ~99 ~88 ~3 ~99 minecraft:gray_stained_glass
fill ~88 ~2 ~105 ~88 ~3 ~105 minecraft:light_gray_stained_glass
fill ~86 ~2 ~101 ~86 ~3 ~101 minecraft:gray_stained_glass
fill ~90 ~2 ~101 ~90 ~3 ~101 minecraft:light_gray_stained_glass
setblock ~88 ~1 ~99 minecraft:iron_door[half=lower,facing=north]
setblock ~88 ~2 ~99 minecraft:iron_door[half=upper,facing=north]
fill ~86 ~6 ~99 ~90 ~6 ~105 minecraft:stone_brick_slab
fill ~87 ~7 ~100 ~89 ~7 ~104 minecraft:stone_brick_slab
setblock ~88 ~3 ~98 minecraft:dark_oak_slab[type=top]
# 260 local_shop style=corner_store context=local_front facing=south
fill ~-10 ~-3 ~17 ~-7 ~-1 ~22 minecraft:stone
fill ~-10 ~0 ~17 ~-7 ~7 ~22 minecraft:bricks
fill ~-9 ~1 ~18 ~-8 ~6 ~21 minecraft:air
fill ~-9 ~4 ~18 ~-8 ~4 ~21 minecraft:smooth_stone
fill ~-10 ~2 ~19 ~-10 ~3 ~19 minecraft:gray_stained_glass
fill ~-7 ~2 ~19 ~-7 ~3 ~19 minecraft:light_gray_stained_glass
setblock ~-8 ~1 ~22 minecraft:iron_door[half=lower,facing=south]
setblock ~-8 ~2 ~22 minecraft:iron_door[half=upper,facing=south]
fill ~-9 ~1 ~22 ~-8 ~3 ~22 minecraft:cyan_stained_glass
setblock ~-8 ~1 ~22 minecraft:iron_door[half=lower,facing=south]
setblock ~-8 ~2 ~22 minecraft:iron_door[half=upper,facing=south]
setblock ~-8 ~3 ~23 minecraft:red_wool
fill ~-10 ~8 ~17 ~-7 ~8 ~22 minecraft:deepslate_tile_slab
# 261 small_office style=bay_office context=local_front facing=west
fill ~-62 ~-3 ~74 ~-57 ~-1 ~77 minecraft:stone
fill ~-62 ~0 ~74 ~-57 ~7 ~77 minecraft:mud_bricks
fill ~-61 ~1 ~75 ~-58 ~6 ~76 minecraft:air
fill ~-61 ~4 ~75 ~-58 ~4 ~76 minecraft:smooth_stone
fill ~-60 ~2 ~74 ~-60 ~3 ~74 minecraft:gray_stained_glass
fill ~-60 ~2 ~77 ~-60 ~3 ~77 minecraft:light_gray_stained_glass
setblock ~-62 ~1 ~76 minecraft:iron_door[half=lower,facing=west]
setblock ~-62 ~2 ~76 minecraft:iron_door[half=upper,facing=west]
# 262 small_office style=setback_tower context=local_front facing=north
fill ~-19 ~-3 ~-104 ~-16 ~-1 ~-99 minecraft:stone
fill ~-19 ~0 ~-104 ~-16 ~5 ~-99 minecraft:stone_bricks
fill ~-18 ~1 ~-103 ~-17 ~4 ~-100 minecraft:air
fill ~-18 ~4 ~-103 ~-17 ~4 ~-100 minecraft:smooth_stone
fill ~-19 ~2 ~-102 ~-19 ~3 ~-102 minecraft:gray_stained_glass
fill ~-16 ~2 ~-102 ~-16 ~3 ~-102 minecraft:light_gray_stained_glass
setblock ~-17 ~1 ~-104 minecraft:iron_door[half=lower,facing=north]
setblock ~-17 ~2 ~-104 minecraft:iron_door[half=upper,facing=north]
# 263 small_office style=bay_office context=collector_front facing=east
fill ~52 ~-3 ~54 ~57 ~-1 ~57 minecraft:stone
fill ~52 ~0 ~54 ~57 ~11 ~57 minecraft:gray_concrete
fill ~53 ~1 ~55 ~56 ~10 ~56 minecraft:air
fill ~53 ~4 ~55 ~56 ~4 ~56 minecraft:smooth_stone
fill ~53 ~8 ~55 ~56 ~8 ~56 minecraft:smooth_stone
fill ~54 ~2 ~54 ~54 ~3 ~54 minecraft:gray_stained_glass
fill ~54 ~2 ~57 ~54 ~3 ~57 minecraft:light_gray_stained_glass
fill ~54 ~6 ~54 ~54 ~7 ~54 minecraft:gray_stained_glass
fill ~54 ~6 ~57 ~54 ~7 ~57 minecraft:light_gray_stained_glass
setblock ~57 ~1 ~56 minecraft:iron_door[half=lower,facing=east]
setblock ~57 ~2 ~56 minecraft:iron_door[half=upper,facing=east]
fill ~52 ~7 ~54 ~57 ~11 ~57 minecraft:air
fill ~53 ~7 ~55 ~56 ~11 ~56 minecraft:gray_concrete
fill ~54 ~8 ~56 ~55 ~10 ~55 minecraft:air
fill ~53 ~12 ~55 ~56 ~12 ~56 minecraft:smooth_stone_slab
fill ~57 ~2 ~56 ~57 ~7 ~55 minecraft:blue_stained_glass
# 264 small_office style=civic_modern context=local_front facing=north
fill ~-24 ~-3 ~-38 ~-20 ~-1 ~-32 minecraft:stone
fill ~-24 ~0 ~-38 ~-20 ~7 ~-32 minecraft:bricks
fill ~-23 ~1 ~-37 ~-21 ~6 ~-33 minecraft:air
fill ~-23 ~4 ~-37 ~-21 ~4 ~-33 minecraft:smooth_stone
fill ~-22 ~2 ~-38 ~-22 ~3 ~-38 minecraft:gray_stained_glass
fill ~-22 ~2 ~-32 ~-22 ~3 ~-32 minecraft:light_gray_stained_glass
fill ~-24 ~2 ~-36 ~-24 ~3 ~-36 minecraft:gray_stained_glass
fill ~-20 ~2 ~-36 ~-20 ~3 ~-36 minecraft:light_gray_stained_glass
setblock ~-22 ~1 ~-38 minecraft:iron_door[half=lower,facing=north]
setblock ~-22 ~2 ~-38 minecraft:iron_door[half=upper,facing=north]
