# Buildings 97..104
# 097 restaurant style=corner_store context=collector_front facing=west
fill ~-82 ~-3 ~56 ~-74 ~-1 ~61 minecraft:stone
fill ~-82 ~0 ~56 ~-74 ~5 ~61 minecraft:white_terracotta
fill ~-81 ~1 ~57 ~-75 ~4 ~60 minecraft:air
fill ~-81 ~4 ~57 ~-75 ~4 ~60 minecraft:smooth_stone
fill ~-80 ~2 ~56 ~-80 ~3 ~56 minecraft:gray_stained_glass
fill ~-80 ~2 ~61 ~-80 ~3 ~61 minecraft:light_gray_stained_glass
fill ~-77 ~2 ~56 ~-77 ~3 ~56 minecraft:gray_stained_glass
fill ~-77 ~2 ~61 ~-77 ~3 ~61 minecraft:light_gray_stained_glass
fill ~-82 ~2 ~58 ~-82 ~3 ~58 minecraft:gray_stained_glass
fill ~-74 ~2 ~58 ~-74 ~3 ~58 minecraft:light_gray_stained_glass
setblock ~-82 ~1 ~58 minecraft:iron_door[half=lower,facing=west]
setblock ~-82 ~2 ~58 minecraft:iron_door[half=upper,facing=west]
fill ~-82 ~1 ~57 ~-82 ~3 ~60 minecraft:cyan_stained_glass
setblock ~-82 ~1 ~58 minecraft:iron_door[half=lower,facing=west]
setblock ~-82 ~2 ~58 minecraft:iron_door[half=upper,facing=west]
setblock ~-83 ~3 ~58 minecraft:red_wool
fill ~-82 ~6 ~56 ~-74 ~6 ~61 minecraft:dark_oak_slab
fill ~-82 ~1 ~57 ~-82 ~5 ~57 minecraft:dark_oak_planks
setblock ~-82 ~3 ~58 minecraft:red_carpet
# 098 midrise_housing style=setback_block context=arterial_front facing=west
fill ~-31 ~-3 ~119 ~-20 ~-1 ~124 minecraft:stone
fill ~-31 ~0 ~119 ~-20 ~7 ~124 minecraft:calcite
fill ~-30 ~1 ~120 ~-21 ~6 ~123 minecraft:air
fill ~-30 ~4 ~120 ~-21 ~4 ~123 minecraft:smooth_stone
fill ~-29 ~2 ~119 ~-29 ~3 ~119 minecraft:gray_stained_glass
fill ~-29 ~2 ~124 ~-29 ~3 ~124 minecraft:light_gray_stained_glass
fill ~-26 ~2 ~119 ~-26 ~3 ~119 minecraft:gray_stained_glass
fill ~-26 ~2 ~124 ~-26 ~3 ~124 minecraft:light_gray_stained_glass
fill ~-23 ~2 ~119 ~-23 ~3 ~119 minecraft:gray_stained_glass
fill ~-23 ~2 ~124 ~-23 ~3 ~124 minecraft:light_gray_stained_glass
fill ~-31 ~2 ~121 ~-31 ~3 ~121 minecraft:gray_stained_glass
fill ~-20 ~2 ~121 ~-20 ~3 ~121 minecraft:light_gray_stained_glass
setblock ~-31 ~1 ~121 minecraft:iron_door[half=lower,facing=west]
setblock ~-31 ~2 ~121 minecraft:iron_door[half=upper,facing=west]
fill ~-31 ~1 ~120 ~-31 ~7 ~120 minecraft:gray_concrete
# 099 clinic style=mixed_facade context=collector_front facing=north
fill ~18 ~-3 ~52 ~24 ~-1 ~64 minecraft:stone
fill ~18 ~0 ~52 ~24 ~8 ~64 minecraft:bricks
fill ~19 ~1 ~53 ~23 ~7 ~63 minecraft:air
fill ~19 ~4 ~53 ~23 ~4 ~63 minecraft:smooth_stone
fill ~20 ~2 ~52 ~20 ~3 ~52 minecraft:gray_stained_glass
fill ~20 ~2 ~64 ~20 ~3 ~64 minecraft:light_gray_stained_glass
fill ~18 ~2 ~54 ~18 ~3 ~54 minecraft:gray_stained_glass
fill ~24 ~2 ~54 ~24 ~3 ~54 minecraft:light_gray_stained_glass
fill ~18 ~2 ~57 ~18 ~3 ~57 minecraft:gray_stained_glass
fill ~24 ~2 ~57 ~24 ~3 ~57 minecraft:light_gray_stained_glass
fill ~18 ~2 ~60 ~18 ~3 ~60 minecraft:gray_stained_glass
fill ~24 ~2 ~60 ~24 ~3 ~60 minecraft:light_gray_stained_glass
fill ~20 ~6 ~52 ~20 ~7 ~52 minecraft:gray_stained_glass
fill ~20 ~6 ~64 ~20 ~7 ~64 minecraft:light_gray_stained_glass
fill ~18 ~6 ~54 ~18 ~7 ~54 minecraft:gray_stained_glass
fill ~24 ~6 ~54 ~24 ~7 ~54 minecraft:light_gray_stained_glass
fill ~18 ~6 ~57 ~18 ~7 ~57 minecraft:gray_stained_glass
fill ~24 ~6 ~57 ~24 ~7 ~57 minecraft:light_gray_stained_glass
fill ~18 ~6 ~60 ~18 ~7 ~60 minecraft:gray_stained_glass
fill ~24 ~6 ~60 ~24 ~7 ~60 minecraft:light_gray_stained_glass
setblock ~21 ~1 ~52 minecraft:iron_door[half=lower,facing=north]
setblock ~21 ~2 ~52 minecraft:iron_door[half=upper,facing=north]
fill ~18 ~9 ~52 ~24 ~9 ~64 minecraft:deepslate_tile_slab
fill ~20 ~10 ~54 ~22 ~11 ~56 minecraft:light_gray_concrete
setblock ~23 ~10 ~55 minecraft:lightning_rod
fill ~19 ~1 ~52 ~19 ~7 ~52 doomsday_decoration:hollowbrick
fill ~23 ~1 ~52 ~23 ~7 ~52 doomsday_decoration:hollowbrick
# 100 logistics style=industrial_shed context=local_front facing=west
fill ~70 ~-3 ~-104 ~90 ~-1 ~-88 minecraft:stone
fill ~70 ~0 ~-104 ~90 ~11 ~-88 minecraft:stone_bricks
fill ~71 ~1 ~-103 ~89 ~10 ~-89 minecraft:air
fill ~71 ~4 ~-103 ~89 ~4 ~-89 minecraft:smooth_stone
fill ~71 ~8 ~-103 ~89 ~8 ~-89 minecraft:smooth_stone
fill ~72 ~2 ~-104 ~72 ~3 ~-104 minecraft:gray_stained_glass
fill ~72 ~2 ~-88 ~72 ~3 ~-88 minecraft:light_gray_stained_glass
fill ~75 ~2 ~-104 ~75 ~3 ~-104 minecraft:gray_stained_glass
fill ~75 ~2 ~-88 ~75 ~3 ~-88 minecraft:light_gray_stained_glass
fill ~78 ~2 ~-104 ~78 ~3 ~-104 minecraft:gray_stained_glass
fill ~78 ~2 ~-88 ~78 ~3 ~-88 minecraft:light_gray_stained_glass
fill ~81 ~2 ~-104 ~81 ~3 ~-104 minecraft:gray_stained_glass
fill ~81 ~2 ~-88 ~81 ~3 ~-88 minecraft:light_gray_stained_glass
fill ~84 ~2 ~-104 ~84 ~3 ~-104 minecraft:gray_stained_glass
fill ~84 ~2 ~-88 ~84 ~3 ~-88 minecraft:light_gray_stained_glass
fill ~87 ~2 ~-104 ~87 ~3 ~-104 minecraft:gray_stained_glass
fill ~87 ~2 ~-88 ~87 ~3 ~-88 minecraft:light_gray_stained_glass
fill ~70 ~2 ~-102 ~70 ~3 ~-102 minecraft:gray_stained_glass
fill ~90 ~2 ~-102 ~90 ~3 ~-102 minecraft:light_gray_stained_glass
fill ~70 ~2 ~-99 ~70 ~3 ~-99 minecraft:gray_stained_glass
fill ~90 ~2 ~-99 ~90 ~3 ~-99 minecraft:light_gray_stained_glass
fill ~70 ~2 ~-96 ~70 ~3 ~-96 minecraft:gray_stained_glass
fill ~90 ~2 ~-96 ~90 ~3 ~-96 minecraft:light_gray_stained_glass
fill ~70 ~2 ~-93 ~70 ~3 ~-93 minecraft:gray_stained_glass
fill ~90 ~2 ~-93 ~90 ~3 ~-93 minecraft:light_gray_stained_glass
fill ~70 ~2 ~-90 ~70 ~3 ~-90 minecraft:gray_stained_glass
fill ~90 ~2 ~-90 ~90 ~3 ~-90 minecraft:light_gray_stained_glass
fill ~72 ~6 ~-104 ~72 ~7 ~-104 minecraft:gray_stained_glass
fill ~72 ~6 ~-88 ~72 ~7 ~-88 minecraft:light_gray_stained_glass
fill ~75 ~6 ~-104 ~75 ~7 ~-104 minecraft:gray_stained_glass
fill ~75 ~6 ~-88 ~75 ~7 ~-88 minecraft:light_gray_stained_glass
fill ~78 ~6 ~-104 ~78 ~7 ~-104 minecraft:gray_stained_glass
fill ~78 ~6 ~-88 ~78 ~7 ~-88 minecraft:light_gray_stained_glass
fill ~81 ~6 ~-104 ~81 ~7 ~-104 minecraft:gray_stained_glass
fill ~81 ~6 ~-88 ~81 ~7 ~-88 minecraft:light_gray_stained_glass
fill ~84 ~6 ~-104 ~84 ~7 ~-104 minecraft:gray_stained_glass
fill ~84 ~6 ~-88 ~84 ~7 ~-88 minecraft:light_gray_stained_glass
fill ~87 ~6 ~-104 ~87 ~7 ~-104 minecraft:gray_stained_glass
fill ~87 ~6 ~-88 ~87 ~7 ~-88 minecraft:light_gray_stained_glass
fill ~70 ~6 ~-102 ~70 ~7 ~-102 minecraft:gray_stained_glass
fill ~90 ~6 ~-102 ~90 ~7 ~-102 minecraft:light_gray_stained_glass
fill ~70 ~6 ~-99 ~70 ~7 ~-99 minecraft:gray_stained_glass
fill ~90 ~6 ~-99 ~90 ~7 ~-99 minecraft:light_gray_stained_glass
fill ~70 ~6 ~-96 ~70 ~7 ~-96 minecraft:gray_stained_glass
fill ~90 ~6 ~-96 ~90 ~7 ~-96 minecraft:light_gray_stained_glass
fill ~70 ~6 ~-93 ~70 ~7 ~-93 minecraft:gray_stained_glass
fill ~90 ~6 ~-93 ~90 ~7 ~-93 minecraft:light_gray_stained_glass
fill ~70 ~6 ~-90 ~70 ~7 ~-90 minecraft:gray_stained_glass
fill ~90 ~6 ~-90 ~90 ~7 ~-90 minecraft:light_gray_stained_glass
setblock ~70 ~1 ~-99 minecraft:iron_door[half=lower,facing=west]
setblock ~70 ~2 ~-99 minecraft:iron_door[half=upper,facing=west]
fill ~70 ~1 ~-102 ~70 ~4 ~-90 minecraft:polished_blackstone
fill ~70 ~5 ~-102 ~70 ~5 ~-90 minecraft:light_blue_stained_glass
fill ~72 ~13 ~-102 ~74 ~14 ~-100 minecraft:iron_block
fill ~70 ~12 ~-104 ~90 ~12 ~-88 minecraft:smooth_stone_slab
fill ~70 ~1 ~-103 ~70 ~7 ~-103 doomsday_decoration:ironsheetwall_2
fill ~70 ~1 ~-99 ~70 ~7 ~-99 doomsday_decoration:ironsheetwall_2
fill ~70 ~1 ~-95 ~70 ~7 ~-95 doomsday_decoration:ironsheetwall_2
fill ~70 ~1 ~-91 ~70 ~7 ~-91 doomsday_decoration:ironsheetwall_2
# 101 garage style=loading_bay context=local_front facing=north
fill ~64 ~-3 ~99 ~82 ~-1 ~115 minecraft:stone
fill ~64 ~0 ~99 ~82 ~11 ~115 minecraft:gray_concrete
fill ~65 ~1 ~100 ~81 ~10 ~114 minecraft:air
fill ~65 ~4 ~100 ~81 ~4 ~114 minecraft:smooth_stone
fill ~65 ~8 ~100 ~81 ~8 ~114 minecraft:smooth_stone
fill ~66 ~2 ~99 ~66 ~3 ~99 minecraft:gray_stained_glass
fill ~66 ~2 ~115 ~66 ~3 ~115 minecraft:light_gray_stained_glass
fill ~69 ~2 ~99 ~69 ~3 ~99 minecraft:gray_stained_glass
fill ~69 ~2 ~115 ~69 ~3 ~115 minecraft:light_gray_stained_glass
fill ~72 ~2 ~99 ~72 ~3 ~99 minecraft:gray_stained_glass
fill ~72 ~2 ~115 ~72 ~3 ~115 minecraft:light_gray_stained_glass
fill ~75 ~2 ~99 ~75 ~3 ~99 minecraft:gray_stained_glass
fill ~75 ~2 ~115 ~75 ~3 ~115 minecraft:light_gray_stained_glass
fill ~78 ~2 ~99 ~78 ~3 ~99 minecraft:gray_stained_glass
fill ~78 ~2 ~115 ~78 ~3 ~115 minecraft:light_gray_stained_glass
fill ~64 ~2 ~101 ~64 ~3 ~101 minecraft:gray_stained_glass
fill ~82 ~2 ~101 ~82 ~3 ~101 minecraft:light_gray_stained_glass
fill ~64 ~2 ~104 ~64 ~3 ~104 minecraft:gray_stained_glass
fill ~82 ~2 ~104 ~82 ~3 ~104 minecraft:light_gray_stained_glass
fill ~64 ~2 ~107 ~64 ~3 ~107 minecraft:gray_stained_glass
fill ~82 ~2 ~107 ~82 ~3 ~107 minecraft:light_gray_stained_glass
fill ~64 ~2 ~110 ~64 ~3 ~110 minecraft:gray_stained_glass
fill ~82 ~2 ~110 ~82 ~3 ~110 minecraft:light_gray_stained_glass
fill ~64 ~2 ~113 ~64 ~3 ~113 minecraft:gray_stained_glass
fill ~82 ~2 ~113 ~82 ~3 ~113 minecraft:light_gray_stained_glass
fill ~66 ~6 ~99 ~66 ~7 ~99 minecraft:gray_stained_glass
fill ~66 ~6 ~115 ~66 ~7 ~115 minecraft:light_gray_stained_glass
fill ~69 ~6 ~99 ~69 ~7 ~99 minecraft:gray_stained_glass
fill ~69 ~6 ~115 ~69 ~7 ~115 minecraft:light_gray_stained_glass
fill ~72 ~6 ~99 ~72 ~7 ~99 minecraft:gray_stained_glass
fill ~72 ~6 ~115 ~72 ~7 ~115 minecraft:light_gray_stained_glass
fill ~75 ~6 ~99 ~75 ~7 ~99 minecraft:gray_stained_glass
fill ~75 ~6 ~115 ~75 ~7 ~115 minecraft:light_gray_stained_glass
fill ~78 ~6 ~99 ~78 ~7 ~99 minecraft:gray_stained_glass
fill ~78 ~6 ~115 ~78 ~7 ~115 minecraft:light_gray_stained_glass
fill ~64 ~6 ~101 ~64 ~7 ~101 minecraft:gray_stained_glass
fill ~82 ~6 ~101 ~82 ~7 ~101 minecraft:light_gray_stained_glass
fill ~64 ~6 ~104 ~64 ~7 ~104 minecraft:gray_stained_glass
fill ~82 ~6 ~104 ~82 ~7 ~104 minecraft:light_gray_stained_glass
fill ~64 ~6 ~107 ~64 ~7 ~107 minecraft:gray_stained_glass
fill ~82 ~6 ~107 ~82 ~7 ~107 minecraft:light_gray_stained_glass
fill ~64 ~6 ~110 ~64 ~7 ~110 minecraft:gray_stained_glass
fill ~82 ~6 ~110 ~82 ~7 ~110 minecraft:light_gray_stained_glass
fill ~64 ~6 ~113 ~64 ~7 ~113 minecraft:gray_stained_glass
fill ~82 ~6 ~113 ~82 ~7 ~113 minecraft:light_gray_stained_glass
setblock ~69 ~1 ~99 minecraft:iron_door[half=lower,facing=north]
setblock ~69 ~2 ~99 minecraft:iron_door[half=upper,facing=north]
fill ~66 ~1 ~99 ~80 ~4 ~99 minecraft:polished_blackstone
fill ~66 ~5 ~99 ~80 ~5 ~99 minecraft:light_blue_stained_glass
fill ~66 ~13 ~101 ~68 ~14 ~103 minecraft:iron_block
fill ~64 ~12 ~99 ~82 ~12 ~115 minecraft:smooth_stone_slab
fill ~65 ~1 ~99 ~65 ~7 ~99 doomsday_decoration:ironsheetwall_1
fill ~69 ~1 ~99 ~69 ~7 ~99 doomsday_decoration:ironsheetwall_1
fill ~73 ~1 ~99 ~73 ~7 ~99 doomsday_decoration:ironsheetwall_1
fill ~77 ~1 ~99 ~77 ~7 ~99 doomsday_decoration:ironsheetwall_1
fill ~81 ~1 ~99 ~81 ~7 ~99 doomsday_decoration:ironsheetwall_1
# 102 office style=civic_modern context=arterial_front facing=south
fill ~-126 ~-3 ~-19 ~-121 ~-1 ~-10 minecraft:stone
fill ~-126 ~0 ~-19 ~-121 ~11 ~-10 minecraft:white_terracotta
fill ~-125 ~1 ~-18 ~-122 ~10 ~-11 minecraft:air
fill ~-125 ~4 ~-18 ~-122 ~4 ~-11 minecraft:smooth_stone
fill ~-125 ~8 ~-18 ~-122 ~8 ~-11 minecraft:smooth_stone
fill ~-124 ~2 ~-19 ~-124 ~3 ~-19 minecraft:gray_stained_glass
fill ~-124 ~2 ~-10 ~-124 ~3 ~-10 minecraft:light_gray_stained_glass
fill ~-126 ~2 ~-17 ~-126 ~3 ~-17 minecraft:gray_stained_glass
fill ~-121 ~2 ~-17 ~-121 ~3 ~-17 minecraft:light_gray_stained_glass
fill ~-126 ~2 ~-14 ~-126 ~3 ~-14 minecraft:gray_stained_glass
fill ~-121 ~2 ~-14 ~-121 ~3 ~-14 minecraft:light_gray_stained_glass
fill ~-124 ~6 ~-19 ~-124 ~7 ~-19 minecraft:gray_stained_glass
fill ~-124 ~6 ~-10 ~-124 ~7 ~-10 minecraft:light_gray_stained_glass
fill ~-126 ~6 ~-17 ~-126 ~7 ~-17 minecraft:gray_stained_glass
fill ~-121 ~6 ~-17 ~-121 ~7 ~-17 minecraft:light_gray_stained_glass
fill ~-126 ~6 ~-14 ~-126 ~7 ~-14 minecraft:gray_stained_glass
fill ~-121 ~6 ~-14 ~-121 ~7 ~-14 minecraft:light_gray_stained_glass
setblock ~-124 ~1 ~-10 minecraft:iron_door[half=lower,facing=south]
setblock ~-124 ~2 ~-10 minecraft:iron_door[half=upper,facing=south]
fill ~-126 ~7 ~-19 ~-121 ~11 ~-10 minecraft:air
fill ~-125 ~7 ~-18 ~-122 ~11 ~-11 minecraft:white_terracotta
fill ~-124 ~8 ~-17 ~-123 ~10 ~-12 minecraft:air
fill ~-125 ~12 ~-18 ~-122 ~12 ~-11 minecraft:dark_oak_slab
fill ~-124 ~13 ~-17 ~-122 ~14 ~-15 minecraft:light_gray_concrete
setblock ~-122 ~13 ~-16 minecraft:lightning_rod
fill ~-125 ~1 ~-10 ~-125 ~7 ~-10 minecraft:dark_oak_planks
# 103 clinic style=mixed_facade context=collector_front facing=north
fill ~-118 ~-3 ~-82 ~-112 ~-1 ~-76 minecraft:stone
fill ~-118 ~0 ~-82 ~-112 ~7 ~-76 minecraft:mud_bricks
fill ~-117 ~1 ~-81 ~-113 ~6 ~-77 minecraft:air
fill ~-117 ~4 ~-81 ~-113 ~4 ~-77 minecraft:smooth_stone
fill ~-116 ~2 ~-82 ~-116 ~3 ~-82 minecraft:gray_stained_glass
fill ~-116 ~2 ~-76 ~-116 ~3 ~-76 minecraft:light_gray_stained_glass
fill ~-118 ~2 ~-80 ~-118 ~3 ~-80 minecraft:gray_stained_glass
fill ~-112 ~2 ~-80 ~-112 ~3 ~-80 minecraft:light_gray_stained_glass
setblock ~-115 ~1 ~-82 minecraft:iron_door[half=lower,facing=north]
setblock ~-115 ~2 ~-82 minecraft:iron_door[half=upper,facing=north]
fill ~-118 ~8 ~-82 ~-112 ~8 ~-76 minecraft:deepslate_tile_slab
fill ~-117 ~1 ~-82 ~-117 ~7 ~-82 minecraft:spruce_planks
fill ~-113 ~1 ~-82 ~-113 ~7 ~-82 minecraft:spruce_planks
# 104 clinic style=setback_block context=collector_front facing=east
fill ~20 ~-3 ~66 ~32 ~-1 ~72 minecraft:stone
fill ~20 ~0 ~66 ~32 ~8 ~72 minecraft:bricks
fill ~21 ~1 ~67 ~31 ~7 ~71 minecraft:air
fill ~21 ~4 ~67 ~31 ~4 ~71 minecraft:smooth_stone
fill ~22 ~2 ~66 ~22 ~3 ~66 minecraft:gray_stained_glass
fill ~22 ~2 ~72 ~22 ~3 ~72 minecraft:light_gray_stained_glass
fill ~25 ~2 ~66 ~25 ~3 ~66 minecraft:gray_stained_glass
fill ~25 ~2 ~72 ~25 ~3 ~72 minecraft:light_gray_stained_glass
fill ~28 ~2 ~66 ~28 ~3 ~66 minecraft:gray_stained_glass
fill ~28 ~2 ~72 ~28 ~3 ~72 minecraft:light_gray_stained_glass
fill ~20 ~2 ~68 ~20 ~3 ~68 minecraft:gray_stained_glass
fill ~32 ~2 ~68 ~32 ~3 ~68 minecraft:light_gray_stained_glass
fill ~22 ~6 ~66 ~22 ~7 ~66 minecraft:gray_stained_glass
fill ~22 ~6 ~72 ~22 ~7 ~72 minecraft:light_gray_stained_glass
fill ~25 ~6 ~66 ~25 ~7 ~66 minecraft:gray_stained_glass
fill ~25 ~6 ~72 ~25 ~7 ~72 minecraft:light_gray_stained_glass
fill ~28 ~6 ~66 ~28 ~7 ~66 minecraft:gray_stained_glass
fill ~28 ~6 ~72 ~28 ~7 ~72 minecraft:light_gray_stained_glass
fill ~20 ~6 ~68 ~20 ~7 ~68 minecraft:gray_stained_glass
fill ~32 ~6 ~68 ~32 ~7 ~68 minecraft:light_gray_stained_glass
setblock ~32 ~1 ~69 minecraft:iron_door[half=lower,facing=east]
setblock ~32 ~2 ~69 minecraft:iron_door[half=upper,facing=east]
fill ~32 ~1 ~67 ~32 ~7 ~67 doomsday_decoration:hollowbrick
fill ~32 ~1 ~71 ~32 ~7 ~71 doomsday_decoration:hollowbrick
