# Buildings 217..224
# 217 office style=setback_tower context=arterial_front facing=west
fill ~-9 ~-3 ~-48 ~-5 ~-1 ~-42 minecraft:stone
fill ~-9 ~0 ~-48 ~-5 ~12 ~-42 minecraft:bricks
fill ~-8 ~1 ~-47 ~-6 ~11 ~-43 minecraft:air
fill ~-8 ~4 ~-47 ~-6 ~4 ~-43 minecraft:smooth_stone
fill ~-8 ~8 ~-47 ~-6 ~8 ~-43 minecraft:smooth_stone
fill ~-7 ~2 ~-48 ~-7 ~3 ~-48 minecraft:gray_stained_glass
fill ~-7 ~2 ~-42 ~-7 ~3 ~-42 minecraft:light_gray_stained_glass
fill ~-9 ~2 ~-46 ~-9 ~3 ~-46 minecraft:gray_stained_glass
fill ~-5 ~2 ~-46 ~-5 ~3 ~-46 minecraft:light_gray_stained_glass
fill ~-7 ~6 ~-48 ~-7 ~7 ~-48 minecraft:gray_stained_glass
fill ~-7 ~6 ~-42 ~-7 ~7 ~-42 minecraft:light_gray_stained_glass
fill ~-9 ~6 ~-46 ~-9 ~7 ~-46 minecraft:gray_stained_glass
fill ~-5 ~6 ~-46 ~-5 ~7 ~-46 minecraft:light_gray_stained_glass
fill ~-7 ~10 ~-48 ~-7 ~11 ~-48 minecraft:gray_stained_glass
fill ~-7 ~10 ~-42 ~-7 ~11 ~-42 minecraft:light_gray_stained_glass
fill ~-9 ~10 ~-46 ~-9 ~11 ~-46 minecraft:gray_stained_glass
fill ~-5 ~10 ~-46 ~-5 ~11 ~-46 minecraft:light_gray_stained_glass
setblock ~-9 ~1 ~-45 minecraft:iron_door[half=lower,facing=west]
setblock ~-9 ~2 ~-45 minecraft:iron_door[half=upper,facing=west]
fill ~-9 ~7 ~-48 ~-5 ~12 ~-42 minecraft:air
fill ~-8 ~7 ~-47 ~-6 ~12 ~-43 minecraft:bricks
fill ~-7 ~8 ~-46 ~-7 ~11 ~-44 minecraft:air
fill ~-8 ~13 ~-47 ~-6 ~13 ~-43 minecraft:deepslate_tile_slab
# 218 midrise_housing style=setback_block context=collector_front facing=east
fill ~-102 ~-3 ~-19 ~-98 ~-1 ~-13 minecraft:stone
fill ~-102 ~0 ~-19 ~-98 ~11 ~-13 minecraft:bricks
fill ~-101 ~1 ~-18 ~-99 ~10 ~-14 minecraft:air
fill ~-101 ~4 ~-18 ~-99 ~4 ~-14 minecraft:smooth_stone
fill ~-101 ~8 ~-18 ~-99 ~8 ~-14 minecraft:smooth_stone
fill ~-100 ~2 ~-19 ~-100 ~3 ~-19 minecraft:gray_stained_glass
fill ~-100 ~2 ~-13 ~-100 ~3 ~-13 minecraft:light_gray_stained_glass
fill ~-102 ~2 ~-17 ~-102 ~3 ~-17 minecraft:gray_stained_glass
fill ~-98 ~2 ~-17 ~-98 ~3 ~-17 minecraft:light_gray_stained_glass
fill ~-100 ~6 ~-19 ~-100 ~7 ~-19 minecraft:gray_stained_glass
fill ~-100 ~6 ~-13 ~-100 ~7 ~-13 minecraft:light_gray_stained_glass
fill ~-102 ~6 ~-17 ~-102 ~7 ~-17 minecraft:gray_stained_glass
fill ~-98 ~6 ~-17 ~-98 ~7 ~-17 minecraft:light_gray_stained_glass
setblock ~-98 ~1 ~-16 minecraft:iron_door[half=lower,facing=east]
setblock ~-98 ~2 ~-16 minecraft:iron_door[half=upper,facing=east]
fill ~-102 ~7 ~-19 ~-98 ~11 ~-13 minecraft:air
fill ~-101 ~7 ~-18 ~-99 ~11 ~-14 minecraft:bricks
fill ~-100 ~8 ~-17 ~-100 ~10 ~-15 minecraft:air
fill ~-101 ~12 ~-18 ~-99 ~12 ~-14 minecraft:deepslate_tile_slab
# 219 row_house style=rowhouse context=local_front facing=west
fill ~-44 ~-3 ~47 ~-40 ~-1 ~53 minecraft:stone
fill ~-44 ~0 ~47 ~-40 ~5 ~53 minecraft:bricks
fill ~-43 ~1 ~48 ~-41 ~4 ~52 minecraft:air
fill ~-43 ~4 ~48 ~-41 ~4 ~52 minecraft:smooth_stone
fill ~-42 ~2 ~47 ~-42 ~3 ~47 minecraft:gray_stained_glass
fill ~-42 ~2 ~53 ~-42 ~3 ~53 minecraft:light_gray_stained_glass
fill ~-44 ~2 ~49 ~-44 ~3 ~49 minecraft:gray_stained_glass
fill ~-40 ~2 ~49 ~-40 ~3 ~49 minecraft:light_gray_stained_glass
setblock ~-44 ~1 ~50 minecraft:iron_door[half=lower,facing=west]
setblock ~-44 ~2 ~50 minecraft:iron_door[half=upper,facing=west]
fill ~-44 ~6 ~47 ~-40 ~6 ~53 minecraft:deepslate_tile_slab
fill ~-43 ~7 ~48 ~-41 ~7 ~52 minecraft:deepslate_tile_slab
setblock ~-45 ~3 ~50 minecraft:dark_oak_slab[type=top]
# 220 factory style=industrial_shed context=local_front facing=east
fill ~53 ~-3 ~101 ~58 ~-1 ~106 minecraft:stone
fill ~53 ~0 ~101 ~58 ~8 ~106 minecraft:gray_concrete
fill ~54 ~1 ~102 ~57 ~7 ~105 minecraft:air
fill ~54 ~4 ~102 ~57 ~4 ~105 minecraft:smooth_stone
fill ~55 ~2 ~101 ~55 ~3 ~101 minecraft:gray_stained_glass
fill ~55 ~2 ~106 ~55 ~3 ~106 minecraft:light_gray_stained_glass
fill ~53 ~2 ~103 ~53 ~3 ~103 minecraft:gray_stained_glass
fill ~58 ~2 ~103 ~58 ~3 ~103 minecraft:light_gray_stained_glass
fill ~55 ~6 ~101 ~55 ~7 ~101 minecraft:gray_stained_glass
fill ~55 ~6 ~106 ~55 ~7 ~106 minecraft:light_gray_stained_glass
fill ~53 ~6 ~103 ~53 ~7 ~103 minecraft:gray_stained_glass
fill ~58 ~6 ~103 ~58 ~7 ~103 minecraft:light_gray_stained_glass
setblock ~58 ~1 ~103 minecraft:iron_door[half=lower,facing=east]
setblock ~58 ~2 ~103 minecraft:iron_door[half=upper,facing=east]
fill ~58 ~1 ~103 ~58 ~4 ~104 minecraft:polished_blackstone
fill ~58 ~5 ~103 ~58 ~5 ~104 minecraft:light_blue_stained_glass
fill ~55 ~10 ~103 ~57 ~11 ~105 minecraft:iron_block
fill ~53 ~9 ~101 ~58 ~9 ~106 minecraft:smooth_stone_slab
# 221 utility style=loading_bay context=back_block facing=west
fill ~58 ~-3 ~48 ~64 ~-1 ~53 minecraft:stone
fill ~58 ~0 ~48 ~64 ~8 ~53 minecraft:deepslate_bricks
fill ~59 ~1 ~49 ~63 ~7 ~52 minecraft:air
fill ~59 ~4 ~49 ~63 ~4 ~52 minecraft:smooth_stone
fill ~60 ~2 ~48 ~60 ~3 ~48 minecraft:gray_stained_glass
fill ~60 ~2 ~53 ~60 ~3 ~53 minecraft:light_gray_stained_glass
fill ~58 ~2 ~50 ~58 ~3 ~50 minecraft:gray_stained_glass
fill ~64 ~2 ~50 ~64 ~3 ~50 minecraft:light_gray_stained_glass
fill ~60 ~6 ~48 ~60 ~7 ~48 minecraft:gray_stained_glass
fill ~60 ~6 ~53 ~60 ~7 ~53 minecraft:light_gray_stained_glass
fill ~58 ~6 ~50 ~58 ~7 ~50 minecraft:gray_stained_glass
fill ~64 ~6 ~50 ~64 ~7 ~50 minecraft:light_gray_stained_glass
setblock ~58 ~1 ~50 minecraft:iron_door[half=lower,facing=west]
setblock ~58 ~2 ~50 minecraft:iron_door[half=upper,facing=west]
fill ~58 ~1 ~50 ~58 ~4 ~51 minecraft:polished_blackstone
fill ~58 ~5 ~50 ~58 ~5 ~51 minecraft:light_blue_stained_glass
fill ~60 ~10 ~50 ~62 ~11 ~52 minecraft:iron_block
fill ~58 ~9 ~48 ~64 ~9 ~53 minecraft:deepslate_tile_slab
# 222 utility style=sawtooth context=back_block facing=west
fill ~27 ~-3 ~-118 ~31 ~-1 ~-113 minecraft:stone
fill ~27 ~0 ~-118 ~31 ~8 ~-113 minecraft:bricks
fill ~28 ~1 ~-117 ~30 ~7 ~-114 minecraft:air
fill ~28 ~4 ~-117 ~30 ~4 ~-114 minecraft:smooth_stone
fill ~29 ~2 ~-118 ~29 ~3 ~-118 minecraft:gray_stained_glass
fill ~29 ~2 ~-113 ~29 ~3 ~-113 minecraft:light_gray_stained_glass
fill ~27 ~2 ~-116 ~27 ~3 ~-116 minecraft:gray_stained_glass
fill ~31 ~2 ~-116 ~31 ~3 ~-116 minecraft:light_gray_stained_glass
fill ~29 ~6 ~-118 ~29 ~7 ~-118 minecraft:gray_stained_glass
fill ~29 ~6 ~-113 ~29 ~7 ~-113 minecraft:light_gray_stained_glass
fill ~27 ~6 ~-116 ~27 ~7 ~-116 minecraft:gray_stained_glass
fill ~31 ~6 ~-116 ~31 ~7 ~-116 minecraft:light_gray_stained_glass
setblock ~27 ~1 ~-116 minecraft:iron_door[half=lower,facing=west]
setblock ~27 ~2 ~-116 minecraft:iron_door[half=upper,facing=west]
fill ~27 ~1 ~-116 ~27 ~4 ~-115 minecraft:polished_blackstone
fill ~27 ~5 ~-116 ~27 ~5 ~-115 minecraft:light_blue_stained_glass
fill ~29 ~10 ~-116 ~30 ~11 ~-114 minecraft:iron_block
fill ~27 ~9 ~-118 ~31 ~9 ~-113 minecraft:deepslate_tile_slab
fill ~29 ~10 ~-116 ~30 ~11 ~-114 minecraft:light_gray_concrete
setblock ~30 ~10 ~-115 minecraft:lightning_rod
# 223 local_shop style=arcade_shop context=local_front facing=east
fill ~-68 ~-3 ~-44 ~-64 ~-1 ~-39 minecraft:stone
fill ~-68 ~0 ~-44 ~-64 ~9 ~-39 minecraft:light_gray_concrete
fill ~-67 ~1 ~-43 ~-65 ~8 ~-40 minecraft:air
fill ~-67 ~4 ~-43 ~-65 ~4 ~-40 minecraft:smooth_stone
fill ~-67 ~8 ~-43 ~-65 ~8 ~-40 minecraft:smooth_stone
fill ~-66 ~2 ~-44 ~-66 ~3 ~-44 minecraft:gray_stained_glass
fill ~-66 ~2 ~-39 ~-66 ~3 ~-39 minecraft:light_gray_stained_glass
fill ~-68 ~2 ~-42 ~-68 ~3 ~-42 minecraft:gray_stained_glass
fill ~-64 ~2 ~-42 ~-64 ~3 ~-42 minecraft:light_gray_stained_glass
fill ~-66 ~6 ~-44 ~-66 ~7 ~-44 minecraft:gray_stained_glass
fill ~-66 ~6 ~-39 ~-66 ~7 ~-39 minecraft:light_gray_stained_glass
fill ~-68 ~6 ~-42 ~-68 ~7 ~-42 minecraft:gray_stained_glass
fill ~-64 ~6 ~-42 ~-64 ~7 ~-42 minecraft:light_gray_stained_glass
setblock ~-64 ~1 ~-42 minecraft:iron_door[half=lower,facing=east]
setblock ~-64 ~2 ~-42 minecraft:iron_door[half=upper,facing=east]
fill ~-64 ~1 ~-43 ~-64 ~3 ~-40 minecraft:cyan_stained_glass
setblock ~-64 ~1 ~-42 minecraft:iron_door[half=lower,facing=east]
setblock ~-64 ~2 ~-42 minecraft:iron_door[half=upper,facing=east]
setblock ~-63 ~3 ~-42 minecraft:red_wool
fill ~-64 ~4 ~-43 ~-64 ~4 ~-40 doomsday_decoration:porcelainbrickwall
fill ~-68 ~10 ~-44 ~-64 ~10 ~-39 minecraft:smooth_stone_slab
# 224 small_office style=bay_office context=back_block facing=east
fill ~-126 ~-3 ~-3 ~-122 ~-1 ~2 minecraft:stone
fill ~-126 ~0 ~-3 ~-122 ~9 ~2 minecraft:mud_bricks
fill ~-125 ~1 ~-2 ~-123 ~8 ~1 minecraft:air
fill ~-125 ~4 ~-2 ~-123 ~4 ~1 minecraft:smooth_stone
fill ~-125 ~8 ~-2 ~-123 ~8 ~1 minecraft:smooth_stone
fill ~-124 ~2 ~-3 ~-124 ~3 ~-3 minecraft:gray_stained_glass
fill ~-124 ~2 ~2 ~-124 ~3 ~2 minecraft:light_gray_stained_glass
fill ~-126 ~2 ~-1 ~-126 ~3 ~-1 minecraft:gray_stained_glass
fill ~-122 ~2 ~-1 ~-122 ~3 ~-1 minecraft:light_gray_stained_glass
fill ~-124 ~6 ~-3 ~-124 ~7 ~-3 minecraft:gray_stained_glass
fill ~-124 ~6 ~2 ~-124 ~7 ~2 minecraft:light_gray_stained_glass
fill ~-126 ~6 ~-1 ~-126 ~7 ~-1 minecraft:gray_stained_glass
fill ~-122 ~6 ~-1 ~-122 ~7 ~-1 minecraft:light_gray_stained_glass
setblock ~-122 ~1 ~-1 minecraft:iron_door[half=lower,facing=east]
setblock ~-122 ~2 ~-1 minecraft:iron_door[half=upper,facing=east]
