# Buildings 257..264
# 257 small_office style=storefront context=collector_front facing=west
fill ~59 ~-3 ~-90 ~62 ~-1 ~-85 minecraft:stone
fill ~59 ~0 ~-90 ~62 ~9 ~-85 minecraft:stone_bricks
fill ~60 ~1 ~-89 ~61 ~8 ~-86 minecraft:air
fill ~60 ~4 ~-89 ~61 ~4 ~-86 minecraft:smooth_stone
fill ~60 ~8 ~-89 ~61 ~8 ~-86 minecraft:smooth_stone
fill ~59 ~2 ~-88 ~59 ~3 ~-88 minecraft:gray_stained_glass
fill ~62 ~2 ~-88 ~62 ~3 ~-88 minecraft:light_gray_stained_glass
fill ~59 ~6 ~-88 ~59 ~7 ~-88 minecraft:gray_stained_glass
fill ~62 ~6 ~-88 ~62 ~7 ~-88 minecraft:light_gray_stained_glass
setblock ~59 ~1 ~-88 minecraft:iron_door[half=lower,facing=west]
setblock ~59 ~2 ~-88 minecraft:iron_door[half=upper,facing=west]
fill ~59 ~1 ~-89 ~59 ~3 ~-86 minecraft:cyan_stained_glass
setblock ~59 ~1 ~-88 minecraft:iron_door[half=lower,facing=west]
setblock ~59 ~2 ~-88 minecraft:iron_door[half=upper,facing=west]
setblock ~58 ~3 ~-88 minecraft:red_wool
fill ~59 ~10 ~-90 ~62 ~10 ~-85 minecraft:smooth_stone_slab
# 258 row_house style=stepped_house context=local_front facing=east
fill ~-63 ~-3 ~37 ~-60 ~-1 ~42 minecraft:stone
fill ~-63 ~0 ~37 ~-60 ~9 ~42 minecraft:bricks
fill ~-62 ~1 ~38 ~-61 ~8 ~41 minecraft:air
fill ~-62 ~4 ~38 ~-61 ~4 ~41 minecraft:smooth_stone
fill ~-62 ~8 ~38 ~-61 ~8 ~41 minecraft:smooth_stone
fill ~-63 ~2 ~39 ~-63 ~3 ~39 minecraft:gray_stained_glass
fill ~-60 ~2 ~39 ~-60 ~3 ~39 minecraft:light_gray_stained_glass
fill ~-63 ~6 ~39 ~-63 ~7 ~39 minecraft:gray_stained_glass
fill ~-60 ~6 ~39 ~-60 ~7 ~39 minecraft:light_gray_stained_glass
setblock ~-60 ~1 ~39 minecraft:iron_door[half=lower,facing=east]
setblock ~-60 ~2 ~39 minecraft:iron_door[half=upper,facing=east]
fill ~-63 ~10 ~37 ~-60 ~10 ~42 minecraft:deepslate_tile_slab
fill ~-62 ~11 ~38 ~-61 ~11 ~41 minecraft:deepslate_tile_slab
setblock ~-59 ~3 ~39 minecraft:dark_oak_slab[type=top]
fill ~-61 ~11 ~39 ~-61 ~12 ~41 minecraft:light_gray_concrete
setblock ~-61 ~11 ~40 minecraft:lightning_rod
# 259 shop_house style=storefront context=collector_front facing=east
fill ~-100 ~-3 ~21 ~-97 ~-1 ~27 minecraft:stone
fill ~-100 ~0 ~21 ~-97 ~9 ~27 minecraft:smooth_sandstone
fill ~-99 ~1 ~22 ~-98 ~8 ~26 minecraft:air
fill ~-99 ~4 ~22 ~-98 ~4 ~26 minecraft:smooth_stone
fill ~-99 ~8 ~22 ~-98 ~8 ~26 minecraft:smooth_stone
fill ~-100 ~2 ~23 ~-100 ~3 ~23 minecraft:gray_stained_glass
fill ~-97 ~2 ~23 ~-97 ~3 ~23 minecraft:light_gray_stained_glass
fill ~-100 ~6 ~23 ~-100 ~7 ~23 minecraft:gray_stained_glass
fill ~-97 ~6 ~23 ~-97 ~7 ~23 minecraft:light_gray_stained_glass
setblock ~-97 ~1 ~24 minecraft:iron_door[half=lower,facing=east]
setblock ~-97 ~2 ~24 minecraft:iron_door[half=upper,facing=east]
fill ~-97 ~1 ~22 ~-97 ~3 ~26 minecraft:cyan_stained_glass
setblock ~-97 ~1 ~24 minecraft:iron_door[half=lower,facing=east]
setblock ~-97 ~2 ~24 minecraft:iron_door[half=upper,facing=east]
setblock ~-96 ~3 ~24 minecraft:red_wool
fill ~-100 ~10 ~21 ~-97 ~10 ~27 minecraft:stone_brick_slab
# 260 workshop style=storefront context=arterial_front facing=east
fill ~-63 ~-3 ~-11 ~-60 ~-1 ~-6 minecraft:stone
fill ~-63 ~0 ~-11 ~-60 ~7 ~-6 minecraft:bricks
fill ~-62 ~1 ~-10 ~-61 ~6 ~-7 minecraft:air
fill ~-62 ~4 ~-10 ~-61 ~4 ~-7 minecraft:smooth_stone
fill ~-63 ~2 ~-9 ~-63 ~3 ~-9 minecraft:gray_stained_glass
fill ~-60 ~2 ~-9 ~-60 ~3 ~-9 minecraft:light_gray_stained_glass
setblock ~-60 ~1 ~-9 minecraft:iron_door[half=lower,facing=east]
setblock ~-60 ~2 ~-9 minecraft:iron_door[half=upper,facing=east]
fill ~-60 ~1 ~-10 ~-60 ~3 ~-7 minecraft:cyan_stained_glass
setblock ~-60 ~1 ~-9 minecraft:iron_door[half=lower,facing=east]
setblock ~-60 ~2 ~-9 minecraft:iron_door[half=upper,facing=east]
setblock ~-59 ~3 ~-9 minecraft:red_wool
fill ~-63 ~8 ~-11 ~-60 ~8 ~-6 minecraft:deepslate_tile_slab
# 261 row_house style=stepped_house context=back_block facing=south
fill ~85 ~-3 ~-126 ~88 ~-1 ~-121 minecraft:stone
fill ~85 ~0 ~-126 ~88 ~7 ~-121 minecraft:stone_bricks
fill ~86 ~1 ~-125 ~87 ~6 ~-122 minecraft:air
fill ~86 ~4 ~-125 ~87 ~4 ~-122 minecraft:smooth_stone
fill ~85 ~2 ~-124 ~85 ~3 ~-124 minecraft:gray_stained_glass
fill ~88 ~2 ~-124 ~88 ~3 ~-124 minecraft:light_gray_stained_glass
setblock ~87 ~1 ~-121 minecraft:iron_door[half=lower,facing=south]
setblock ~87 ~2 ~-121 minecraft:iron_door[half=upper,facing=south]
fill ~85 ~8 ~-126 ~88 ~8 ~-121 minecraft:smooth_stone_slab
fill ~86 ~9 ~-125 ~87 ~9 ~-122 minecraft:smooth_stone_slab
setblock ~87 ~3 ~-120 minecraft:dark_oak_slab[type=top]
# 262 local_shop style=stepped_house context=local_front facing=east
fill ~-60 ~-3 ~55 ~-57 ~-1 ~60 minecraft:stone
fill ~-60 ~0 ~55 ~-57 ~9 ~60 minecraft:bricks
fill ~-59 ~1 ~56 ~-58 ~8 ~59 minecraft:air
fill ~-59 ~4 ~56 ~-58 ~4 ~59 minecraft:smooth_stone
fill ~-59 ~8 ~56 ~-58 ~8 ~59 minecraft:smooth_stone
fill ~-60 ~2 ~57 ~-60 ~3 ~57 minecraft:gray_stained_glass
fill ~-57 ~2 ~57 ~-57 ~3 ~57 minecraft:light_gray_stained_glass
fill ~-60 ~6 ~57 ~-60 ~7 ~57 minecraft:gray_stained_glass
fill ~-57 ~6 ~57 ~-57 ~7 ~57 minecraft:light_gray_stained_glass
setblock ~-57 ~1 ~57 minecraft:iron_door[half=lower,facing=east]
setblock ~-57 ~2 ~57 minecraft:iron_door[half=upper,facing=east]
fill ~-60 ~10 ~55 ~-57 ~10 ~60 minecraft:deepslate_tile_slab
fill ~-59 ~11 ~56 ~-58 ~11 ~59 minecraft:deepslate_tile_slab
setblock ~-56 ~3 ~57 minecraft:dark_oak_slab[type=top]
# 263 row_house style=stepped_house context=collector_front facing=west
fill ~-80 ~-3 ~-1 ~-77 ~-1 ~5 minecraft:stone
fill ~-80 ~0 ~-1 ~-77 ~7 ~5 minecraft:smooth_sandstone
fill ~-79 ~1 ~0 ~-78 ~6 ~4 minecraft:air
fill ~-79 ~4 ~0 ~-78 ~4 ~4 minecraft:smooth_stone
fill ~-80 ~2 ~1 ~-80 ~3 ~1 minecraft:gray_stained_glass
fill ~-77 ~2 ~1 ~-77 ~3 ~1 minecraft:light_gray_stained_glass
setblock ~-80 ~1 ~2 minecraft:iron_door[half=lower,facing=west]
setblock ~-80 ~2 ~2 minecraft:iron_door[half=upper,facing=west]
fill ~-80 ~8 ~-1 ~-77 ~8 ~5 minecraft:stone_brick_slab
fill ~-79 ~9 ~0 ~-78 ~9 ~4 minecraft:stone_brick_slab
setblock ~-81 ~3 ~2 minecraft:dark_oak_slab[type=top]
# 264 small_office style=rowhouse context=arterial_front facing=east
fill ~-29 ~-3 ~-32 ~-25 ~-1 ~-27 minecraft:stone
fill ~-29 ~0 ~-32 ~-25 ~9 ~-27 minecraft:white_terracotta
fill ~-28 ~1 ~-31 ~-26 ~8 ~-28 minecraft:air
fill ~-28 ~4 ~-31 ~-26 ~4 ~-28 minecraft:smooth_stone
fill ~-28 ~8 ~-31 ~-26 ~8 ~-28 minecraft:smooth_stone
fill ~-27 ~2 ~-32 ~-27 ~3 ~-32 minecraft:gray_stained_glass
fill ~-27 ~2 ~-27 ~-27 ~3 ~-27 minecraft:light_gray_stained_glass
fill ~-29 ~2 ~-30 ~-29 ~3 ~-30 minecraft:gray_stained_glass
fill ~-25 ~2 ~-30 ~-25 ~3 ~-30 minecraft:light_gray_stained_glass
fill ~-27 ~6 ~-32 ~-27 ~7 ~-32 minecraft:gray_stained_glass
fill ~-27 ~6 ~-27 ~-27 ~7 ~-27 minecraft:light_gray_stained_glass
fill ~-29 ~6 ~-30 ~-29 ~7 ~-30 minecraft:gray_stained_glass
fill ~-25 ~6 ~-30 ~-25 ~7 ~-30 minecraft:light_gray_stained_glass
setblock ~-25 ~1 ~-30 minecraft:iron_door[half=lower,facing=east]
setblock ~-25 ~2 ~-30 minecraft:iron_door[half=upper,facing=east]
fill ~-29 ~10 ~-32 ~-25 ~10 ~-27 minecraft:stone_brick_slab
fill ~-28 ~11 ~-31 ~-26 ~11 ~-28 minecraft:stone_brick_slab
setblock ~-24 ~3 ~-30 minecraft:dark_oak_slab[type=top]
fill ~-27 ~11 ~-30 ~-26 ~12 ~-28 minecraft:light_gray_concrete
setblock ~-26 ~11 ~-29 minecraft:lightning_rod
