# Buildings 209..216
# 209 local_shop style=storefront context=arterial_front facing=south
fill ~50 ~-3 ~-16 ~54 ~-1 ~-10 minecraft:stone
fill ~50 ~0 ~-16 ~54 ~7 ~-10 minecraft:bricks
fill ~51 ~1 ~-15 ~53 ~6 ~-11 minecraft:air
fill ~51 ~4 ~-15 ~53 ~4 ~-11 minecraft:smooth_stone
fill ~52 ~2 ~-16 ~52 ~3 ~-16 minecraft:gray_stained_glass
fill ~52 ~2 ~-10 ~52 ~3 ~-10 minecraft:light_gray_stained_glass
fill ~50 ~2 ~-14 ~50 ~3 ~-14 minecraft:gray_stained_glass
fill ~54 ~2 ~-14 ~54 ~3 ~-14 minecraft:light_gray_stained_glass
setblock ~52 ~1 ~-10 minecraft:iron_door[half=lower,facing=south]
setblock ~52 ~2 ~-10 minecraft:iron_door[half=upper,facing=south]
fill ~51 ~1 ~-10 ~53 ~3 ~-10 minecraft:cyan_stained_glass
setblock ~52 ~1 ~-10 minecraft:iron_door[half=lower,facing=south]
setblock ~52 ~2 ~-10 minecraft:iron_door[half=upper,facing=south]
setblock ~52 ~3 ~-9 minecraft:red_wool
fill ~50 ~8 ~-16 ~54 ~8 ~-10 minecraft:deepslate_tile_slab
# 210 local_shop style=storefront context=local_front facing=south
fill ~31 ~-3 ~-95 ~35 ~-1 ~-89 minecraft:stone
fill ~31 ~0 ~-95 ~35 ~11 ~-89 minecraft:bricks
fill ~32 ~1 ~-94 ~34 ~10 ~-90 minecraft:air
fill ~32 ~4 ~-94 ~34 ~4 ~-90 minecraft:smooth_stone
fill ~32 ~8 ~-94 ~34 ~8 ~-90 minecraft:smooth_stone
fill ~33 ~2 ~-95 ~33 ~3 ~-95 minecraft:gray_stained_glass
fill ~33 ~2 ~-89 ~33 ~3 ~-89 minecraft:light_gray_stained_glass
fill ~31 ~2 ~-93 ~31 ~3 ~-93 minecraft:gray_stained_glass
fill ~35 ~2 ~-93 ~35 ~3 ~-93 minecraft:light_gray_stained_glass
fill ~33 ~6 ~-95 ~33 ~7 ~-95 minecraft:gray_stained_glass
fill ~33 ~6 ~-89 ~33 ~7 ~-89 minecraft:light_gray_stained_glass
fill ~31 ~6 ~-93 ~31 ~7 ~-93 minecraft:gray_stained_glass
fill ~35 ~6 ~-93 ~35 ~7 ~-93 minecraft:light_gray_stained_glass
setblock ~33 ~1 ~-89 minecraft:iron_door[half=lower,facing=south]
setblock ~33 ~2 ~-89 minecraft:iron_door[half=upper,facing=south]
fill ~32 ~1 ~-89 ~34 ~3 ~-89 minecraft:cyan_stained_glass
setblock ~33 ~1 ~-89 minecraft:iron_door[half=lower,facing=south]
setblock ~33 ~2 ~-89 minecraft:iron_door[half=upper,facing=south]
setblock ~33 ~3 ~-88 minecraft:red_wool
fill ~31 ~12 ~-95 ~35 ~12 ~-89 minecraft:deepslate_tile_slab
fill ~33 ~13 ~-93 ~34 ~14 ~-91 minecraft:light_gray_concrete
setblock ~34 ~13 ~-92 minecraft:lightning_rod
# 211 row_house style=stepped_house context=local_front facing=south
fill ~-120 ~-3 ~-70 ~-117 ~-1 ~-65 minecraft:stone
fill ~-120 ~0 ~-70 ~-117 ~9 ~-65 minecraft:calcite
fill ~-119 ~1 ~-69 ~-118 ~8 ~-66 minecraft:air
fill ~-119 ~4 ~-69 ~-118 ~4 ~-66 minecraft:smooth_stone
fill ~-119 ~8 ~-69 ~-118 ~8 ~-66 minecraft:smooth_stone
fill ~-120 ~2 ~-68 ~-120 ~3 ~-68 minecraft:gray_stained_glass
fill ~-117 ~2 ~-68 ~-117 ~3 ~-68 minecraft:light_gray_stained_glass
fill ~-120 ~6 ~-68 ~-120 ~7 ~-68 minecraft:gray_stained_glass
fill ~-117 ~6 ~-68 ~-117 ~7 ~-68 minecraft:light_gray_stained_glass
setblock ~-118 ~1 ~-65 minecraft:iron_door[half=lower,facing=south]
setblock ~-118 ~2 ~-65 minecraft:iron_door[half=upper,facing=south]
fill ~-120 ~10 ~-70 ~-117 ~10 ~-65 minecraft:stone_brick_slab
fill ~-119 ~11 ~-69 ~-118 ~11 ~-66 minecraft:stone_brick_slab
setblock ~-118 ~3 ~-64 minecraft:dark_oak_slab[type=top]
# 212 local_shop style=corner_store context=collector_front facing=north
fill ~12 ~-3 ~52 ~15 ~-1 ~57 minecraft:stone
fill ~12 ~0 ~52 ~15 ~9 ~57 minecraft:light_gray_concrete
fill ~13 ~1 ~53 ~14 ~8 ~56 minecraft:air
fill ~13 ~4 ~53 ~14 ~4 ~56 minecraft:smooth_stone
fill ~13 ~8 ~53 ~14 ~8 ~56 minecraft:smooth_stone
fill ~12 ~2 ~54 ~12 ~3 ~54 minecraft:gray_stained_glass
fill ~15 ~2 ~54 ~15 ~3 ~54 minecraft:light_gray_stained_glass
fill ~12 ~6 ~54 ~12 ~7 ~54 minecraft:gray_stained_glass
fill ~15 ~6 ~54 ~15 ~7 ~54 minecraft:light_gray_stained_glass
setblock ~14 ~1 ~52 minecraft:iron_door[half=lower,facing=north]
setblock ~14 ~2 ~52 minecraft:iron_door[half=upper,facing=north]
fill ~13 ~1 ~52 ~14 ~3 ~52 minecraft:cyan_stained_glass
setblock ~14 ~1 ~52 minecraft:iron_door[half=lower,facing=north]
setblock ~14 ~2 ~52 minecraft:iron_door[half=upper,facing=north]
setblock ~14 ~3 ~51 minecraft:red_wool
fill ~12 ~10 ~52 ~15 ~10 ~57 minecraft:smooth_stone_slab
# 213 workshop style=industrial_shed context=local_front facing=south
fill ~-21 ~-3 ~-53 ~-18 ~-1 ~-48 minecraft:stone
fill ~-21 ~0 ~-53 ~-18 ~9 ~-48 minecraft:white_terracotta
fill ~-20 ~1 ~-52 ~-19 ~8 ~-49 minecraft:air
fill ~-20 ~4 ~-52 ~-19 ~4 ~-49 minecraft:smooth_stone
fill ~-20 ~8 ~-52 ~-19 ~8 ~-49 minecraft:smooth_stone
fill ~-21 ~2 ~-51 ~-21 ~3 ~-51 minecraft:gray_stained_glass
fill ~-18 ~2 ~-51 ~-18 ~3 ~-51 minecraft:light_gray_stained_glass
fill ~-21 ~6 ~-51 ~-21 ~7 ~-51 minecraft:gray_stained_glass
fill ~-18 ~6 ~-51 ~-18 ~7 ~-51 minecraft:light_gray_stained_glass
setblock ~-19 ~1 ~-48 minecraft:iron_door[half=lower,facing=south]
setblock ~-19 ~2 ~-48 minecraft:iron_door[half=upper,facing=south]
fill ~-19 ~1 ~-48 ~-20 ~4 ~-48 minecraft:polished_blackstone
fill ~-19 ~5 ~-48 ~-20 ~5 ~-48 minecraft:light_blue_stained_glass
fill ~-19 ~11 ~-51 ~-19 ~12 ~-49 minecraft:iron_block
fill ~-21 ~10 ~-53 ~-18 ~10 ~-48 minecraft:stone_brick_slab
fill ~-19 ~11 ~-51 ~-19 ~12 ~-49 minecraft:light_gray_concrete
setblock ~-19 ~11 ~-50 minecraft:lightning_rod
# 214 small_office style=civic_modern context=collector_front facing=east
fill ~34 ~-3 ~112 ~40 ~-1 ~116 minecraft:stone
fill ~34 ~0 ~112 ~40 ~5 ~116 minecraft:calcite
fill ~35 ~1 ~113 ~39 ~4 ~115 minecraft:air
fill ~35 ~4 ~113 ~39 ~4 ~115 minecraft:smooth_stone
fill ~36 ~2 ~112 ~36 ~3 ~112 minecraft:gray_stained_glass
fill ~36 ~2 ~116 ~36 ~3 ~116 minecraft:light_gray_stained_glass
fill ~34 ~2 ~114 ~34 ~3 ~114 minecraft:gray_stained_glass
fill ~40 ~2 ~114 ~40 ~3 ~114 minecraft:light_gray_stained_glass
setblock ~40 ~1 ~114 minecraft:iron_door[half=lower,facing=east]
setblock ~40 ~2 ~114 minecraft:iron_door[half=upper,facing=east]
# 215 shop_house style=arcade_shop context=local_front facing=north
fill ~103 ~-3 ~-42 ~106 ~-1 ~-37 minecraft:stone
fill ~103 ~0 ~-42 ~106 ~5 ~-37 minecraft:white_concrete
fill ~104 ~1 ~-41 ~105 ~4 ~-38 minecraft:air
fill ~104 ~4 ~-41 ~105 ~4 ~-38 minecraft:smooth_stone
fill ~103 ~2 ~-40 ~103 ~3 ~-40 minecraft:gray_stained_glass
fill ~106 ~2 ~-40 ~106 ~3 ~-40 minecraft:light_gray_stained_glass
setblock ~105 ~1 ~-42 minecraft:iron_door[half=lower,facing=north]
setblock ~105 ~2 ~-42 minecraft:iron_door[half=upper,facing=north]
fill ~104 ~1 ~-42 ~105 ~3 ~-42 minecraft:cyan_stained_glass
setblock ~105 ~1 ~-42 minecraft:iron_door[half=lower,facing=north]
setblock ~105 ~2 ~-42 minecraft:iron_door[half=upper,facing=north]
setblock ~105 ~3 ~-43 minecraft:red_wool
fill ~104 ~4 ~-42 ~105 ~4 ~-42 minecraft:cyan_terracotta
fill ~103 ~6 ~-42 ~106 ~6 ~-37 minecraft:smooth_stone_slab
# 216 shop_house style=arcade_shop context=collector_front facing=west
fill ~52 ~-3 ~58 ~57 ~-1 ~61 minecraft:stone
fill ~52 ~0 ~58 ~57 ~9 ~61 minecraft:deepslate_bricks
fill ~53 ~1 ~59 ~56 ~8 ~60 minecraft:air
fill ~53 ~4 ~59 ~56 ~4 ~60 minecraft:smooth_stone
fill ~53 ~8 ~59 ~56 ~8 ~60 minecraft:smooth_stone
fill ~54 ~2 ~58 ~54 ~3 ~58 minecraft:gray_stained_glass
fill ~54 ~2 ~61 ~54 ~3 ~61 minecraft:light_gray_stained_glass
fill ~54 ~6 ~58 ~54 ~7 ~58 minecraft:gray_stained_glass
fill ~54 ~6 ~61 ~54 ~7 ~61 minecraft:light_gray_stained_glass
setblock ~52 ~1 ~60 minecraft:iron_door[half=lower,facing=west]
setblock ~52 ~2 ~60 minecraft:iron_door[half=upper,facing=west]
fill ~52 ~1 ~59 ~52 ~3 ~60 minecraft:cyan_stained_glass
setblock ~52 ~1 ~60 minecraft:iron_door[half=lower,facing=west]
setblock ~52 ~2 ~60 minecraft:iron_door[half=upper,facing=west]
setblock ~51 ~3 ~60 minecraft:red_wool
fill ~52 ~4 ~59 ~52 ~4 ~60 minecraft:oxidized_cut_copper
fill ~52 ~10 ~58 ~57 ~10 ~61 minecraft:deepslate_tile_slab
fill ~54 ~11 ~60 ~56 ~12 ~60 minecraft:light_gray_concrete
setblock ~56 ~11 ~60 minecraft:lightning_rod
