setblock ~46 ~27 ~39 minecraft:gray_stained_glass_pane
setblock ~46 ~27 ~49 minecraft:gray_stained_glass_pane
setblock ~32 ~27 ~41 minecraft:gray_stained_glass_pane
setblock ~49 ~27 ~41 minecraft:gray_stained_glass_pane
setblock ~32 ~27 ~44 minecraft:gray_stained_glass_pane
setblock ~49 ~27 ~44 minecraft:gray_stained_glass_pane
setblock ~32 ~27 ~47 minecraft:gray_stained_glass_pane
setblock ~49 ~27 ~47 minecraft:gray_stained_glass_pane
setblock ~41 ~2 ~39 minecraft:dark_oak_door[half=lower]
setblock ~41 ~3 ~39 minecraft:dark_oak_door[half=upper]
setblock ~33 ~2 ~39 minecraft:cyan_stained_glass
setblock ~35 ~2 ~39 minecraft:cyan_stained_glass
setblock ~37 ~2 ~39 minecraft:cyan_stained_glass
setblock ~39 ~2 ~39 minecraft:cyan_stained_glass
setblock ~41 ~2 ~39 minecraft:cyan_stained_glass
setblock ~43 ~2 ~39 minecraft:cyan_stained_glass
setblock ~45 ~2 ~39 minecraft:cyan_stained_glass
setblock ~47 ~2 ~39 minecraft:cyan_stained_glass
fill ~-38 ~1 ~91 ~-26 ~12 ~98 minecraft:bricks
fill ~-37 ~2 ~92 ~-27 ~11 ~97 minecraft:air
fill ~-37 ~4 ~92 ~-27 ~4 ~97 minecraft:smooth_stone
fill ~-37 ~8 ~92 ~-27 ~8 ~97 minecraft:smooth_stone
fill ~-38 ~13 ~91 ~-26 ~13 ~98 minecraft:polished_andesite
setblock ~-36 ~3 ~91 minecraft:gray_stained_glass_pane
setblock ~-36 ~3 ~98 minecraft:gray_stained_glass_pane
setblock ~-33 ~3 ~91 minecraft:gray_stained_glass_pane
setblock ~-33 ~3 ~98 minecraft:gray_stained_glass_pane
setblock ~-30 ~3 ~91 minecraft:gray_stained_glass_pane
setblock ~-30 ~3 ~98 minecraft:gray_stained_glass_pane
setblock ~-38 ~3 ~93 minecraft:gray_stained_glass_pane
setblock ~-26 ~3 ~93 minecraft:gray_stained_glass_pane
setblock ~-38 ~3 ~96 minecraft:gray_stained_glass_pane
setblock ~-26 ~3 ~96 minecraft:gray_stained_glass_pane
setblock ~-36 ~7 ~91 minecraft:gray_stained_glass_pane
setblock ~-36 ~7 ~98 minecraft:gray_stained_glass_pane
setblock ~-33 ~7 ~91 minecraft:gray_stained_glass_pane
setblock ~-33 ~7 ~98 minecraft:gray_stained_glass_pane
setblock ~-30 ~7 ~91 minecraft:gray_stained_glass_pane
setblock ~-30 ~7 ~98 minecraft:gray_stained_glass_pane
setblock ~-38 ~7 ~93 minecraft:gray_stained_glass_pane
setblock ~-26 ~7 ~93 minecraft:gray_stained_glass_pane
setblock ~-38 ~7 ~96 minecraft:gray_stained_glass_pane
setblock ~-26 ~7 ~96 minecraft:gray_stained_glass_pane
setblock ~-36 ~11 ~91 minecraft:gray_stained_glass_pane
setblock ~-36 ~11 ~98 minecraft:gray_stained_glass_pane
setblock ~-33 ~11 ~91 minecraft:gray_stained_glass_pane
setblock ~-33 ~11 ~98 minecraft:gray_stained_glass_pane
setblock ~-30 ~11 ~91 minecraft:gray_stained_glass_pane
setblock ~-30 ~11 ~98 minecraft:gray_stained_glass_pane
setblock ~-38 ~11 ~93 minecraft:gray_stained_glass_pane
setblock ~-26 ~11 ~93 minecraft:gray_stained_glass_pane
setblock ~-38 ~11 ~96 minecraft:gray_stained_glass_pane
setblock ~-26 ~11 ~96 minecraft:gray_stained_glass_pane
setblock ~-32 ~2 ~98 minecraft:dark_oak_door[half=lower]
setblock ~-32 ~3 ~98 minecraft:dark_oak_door[half=upper]
fill ~68 ~1 ~ ~77 ~16 ~7 minecraft:calcite
fill ~69 ~2 ~1 ~76 ~15 ~6 minecraft:air
fill ~69 ~4 ~1 ~76 ~4 ~6 minecraft:smooth_stone
fill ~69 ~8 ~1 ~76 ~8 ~6 minecraft:smooth_stone
fill ~69 ~12 ~1 ~76 ~12 ~6 minecraft:smooth_stone
fill ~68 ~17 ~ ~77 ~17 ~7 minecraft:cyan_terracotta
fill ~70 ~1 ~2 ~75 ~20 ~5 minecraft:calcite
fill ~71 ~2 ~3 ~74 ~19 ~4 minecraft:air
fill ~71 ~4 ~3 ~74 ~4 ~4 minecraft:smooth_stone
fill ~71 ~8 ~3 ~74 ~8 ~4 minecraft:smooth_stone
fill ~71 ~12 ~3 ~74 ~12 ~4 minecraft:smooth_stone
fill ~71 ~16 ~3 ~74 ~16 ~4 minecraft:smooth_stone
fill ~70 ~21 ~2 ~75 ~21 ~5 minecraft:cyan_terracotta
setblock ~70 ~3 ~ minecraft:gray_stained_glass_pane
setblock ~70 ~3 ~7 minecraft:gray_stained_glass_pane
setblock ~73 ~3 ~ minecraft:gray_stained_glass_pane
setblock ~73 ~3 ~7 minecraft:gray_stained_glass_pane
setblock ~68 ~3 ~2 minecraft:gray_stained_glass_pane
setblock ~77 ~3 ~2 minecraft:gray_stained_glass_pane
setblock ~68 ~3 ~5 minecraft:gray_stained_glass_pane
setblock ~77 ~3 ~5 minecraft:gray_stained_glass_pane
setblock ~70 ~7 ~ minecraft:gray_stained_glass_pane
setblock ~70 ~7 ~7 minecraft:gray_stained_glass_pane
setblock ~73 ~7 ~ minecraft:gray_stained_glass_pane
setblock ~73 ~7 ~7 minecraft:gray_stained_glass_pane
setblock ~68 ~7 ~2 minecraft:gray_stained_glass_pane
setblock ~77 ~7 ~2 minecraft:gray_stained_glass_pane
setblock ~68 ~7 ~5 minecraft:gray_stained_glass_pane
setblock ~77 ~7 ~5 minecraft:gray_stained_glass_pane
setblock ~70 ~11 ~ minecraft:gray_stained_glass_pane
setblock ~70 ~11 ~7 minecraft:gray_stained_glass_pane
setblock ~73 ~11 ~ minecraft:gray_stained_glass_pane
setblock ~73 ~11 ~7 minecraft:gray_stained_glass_pane
setblock ~68 ~11 ~2 minecraft:gray_stained_glass_pane
setblock ~77 ~11 ~2 minecraft:gray_stained_glass_pane
setblock ~68 ~11 ~5 minecraft:gray_stained_glass_pane
setblock ~77 ~11 ~5 minecraft:gray_stained_glass_pane
setblock ~70 ~15 ~ minecraft:gray_stained_glass_pane
setblock ~70 ~15 ~7 minecraft:gray_stained_glass_pane
setblock ~73 ~15 ~ minecraft:gray_stained_glass_pane
setblock ~73 ~15 ~7 minecraft:gray_stained_glass_pane
setblock ~68 ~15 ~2 minecraft:gray_stained_glass_pane
setblock ~77 ~15 ~2 minecraft:gray_stained_glass_pane
setblock ~68 ~15 ~5 minecraft:gray_stained_glass_pane
setblock ~77 ~15 ~5 minecraft:gray_stained_glass_pane
setblock ~70 ~19 ~ minecraft:gray_stained_glass_pane
setblock ~70 ~19 ~7 minecraft:gray_stained_glass_pane
setblock ~73 ~19 ~ minecraft:gray_stained_glass_pane
setblock ~73 ~19 ~7 minecraft:gray_stained_glass_pane
setblock ~68 ~19 ~2 minecraft:gray_stained_glass_pane
setblock ~77 ~19 ~2 minecraft:gray_stained_glass_pane
setblock ~68 ~19 ~5 minecraft:gray_stained_glass_pane
setblock ~77 ~19 ~5 minecraft:gray_stained_glass_pane
setblock ~73 ~2 ~ minecraft:dark_oak_door[half=lower]
setblock ~73 ~3 ~ minecraft:dark_oak_door[half=upper]
setblock ~69 ~2 ~ minecraft:cyan_stained_glass
setblock ~71 ~2 ~ minecraft:cyan_stained_glass
setblock ~73 ~2 ~ minecraft:cyan_stained_glass
setblock ~75 ~2 ~ minecraft:cyan_stained_glass
fill ~-84 ~1 ~-105 ~-73 ~12 ~-95 minecraft:calcite
fill ~-83 ~2 ~-104 ~-74 ~11 ~-96 minecraft:air
fill ~-83 ~4 ~-104 ~-74 ~4 ~-96 minecraft:smooth_stone
fill ~-83 ~8 ~-104 ~-74 ~8 ~-96 minecraft:smooth_stone
fill ~-84 ~13 ~-105 ~-73 ~13 ~-95 minecraft:cyan_terracotta
setblock ~-82 ~3 ~-105 minecraft:gray_stained_glass_pane
setblock ~-82 ~3 ~-95 minecraft:gray_stained_glass_pane
setblock ~-79 ~3 ~-105 minecraft:gray_stained_glass_pane
setblock ~-79 ~3 ~-95 minecraft:gray_stained_glass_pane
setblock ~-76 ~3 ~-105 minecraft:gray_stained_glass_pane
setblock ~-76 ~3 ~-95 minecraft:gray_stained_glass_pane
setblock ~-84 ~3 ~-103 minecraft:gray_stained_glass_pane
setblock ~-73 ~3 ~-103 minecraft:gray_stained_glass_pane
setblock ~-84 ~3 ~-100 minecraft:gray_stained_glass_pane
setblock ~-73 ~3 ~-100 minecraft:gray_stained_glass_pane
setblock ~-84 ~3 ~-97 minecraft:gray_stained_glass_pane
setblock ~-73 ~3 ~-97 minecraft:gray_stained_glass_pane
setblock ~-82 ~7 ~-105 minecraft:gray_stained_glass_pane
setblock ~-82 ~7 ~-95 minecraft:gray_stained_glass_pane
setblock ~-79 ~7 ~-105 minecraft:gray_stained_glass_pane
setblock ~-79 ~7 ~-95 minecraft:gray_stained_glass_pane
setblock ~-76 ~7 ~-105 minecraft:gray_stained_glass_pane
setblock ~-76 ~7 ~-95 minecraft:gray_stained_glass_pane
setblock ~-84 ~7 ~-103 minecraft:gray_stained_glass_pane
setblock ~-73 ~7 ~-103 minecraft:gray_stained_glass_pane
setblock ~-84 ~7 ~-100 minecraft:gray_stained_glass_pane
setblock ~-73 ~7 ~-100 minecraft:gray_stained_glass_pane
setblock ~-84 ~7 ~-97 minecraft:gray_stained_glass_pane
setblock ~-73 ~7 ~-97 minecraft:gray_stained_glass_pane
setblock ~-82 ~11 ~-105 minecraft:gray_stained_glass_pane
setblock ~-82 ~11 ~-95 minecraft:gray_stained_glass_pane
setblock ~-79 ~11 ~-105 minecraft:gray_stained_glass_pane
setblock ~-79 ~11 ~-95 minecraft:gray_stained_glass_pane
setblock ~-76 ~11 ~-105 minecraft:gray_stained_glass_pane
setblock ~-76 ~11 ~-95 minecraft:gray_stained_glass_pane
setblock ~-84 ~11 ~-103 minecraft:gray_stained_glass_pane
setblock ~-73 ~11 ~-103 minecraft:gray_stained_glass_pane
setblock ~-84 ~11 ~-100 minecraft:gray_stained_glass_pane
setblock ~-73 ~11 ~-100 minecraft:gray_stained_glass_pane
setblock ~-84 ~11 ~-97 minecraft:gray_stained_glass_pane
setblock ~-73 ~11 ~-97 minecraft:gray_stained_glass_pane
setblock ~-78 ~2 ~-105 minecraft:dark_oak_door[half=lower]
setblock ~-78 ~3 ~-105 minecraft:dark_oak_door[half=upper]
fill ~-84 ~14 ~-105 ~-73 ~14 ~-95 minecraft:deepslate_tile_slab
fill ~-83 ~15 ~-104 ~-74 ~15 ~-96 minecraft:deepslate_tile_slab
fill ~-82 ~16 ~-103 ~-75 ~16 ~-97 minecraft:deepslate_tile_slab
fill ~-106 ~1 ~-100 ~-100 ~12 ~-88 minecraft:mud_bricks
fill ~-105 ~2 ~-99 ~-101 ~11 ~-89 minecraft:air
fill ~-105 ~4 ~-99 ~-101 ~4 ~-89 minecraft:smooth_stone
fill ~-105 ~8 ~-99 ~-101 ~8 ~-89 minecraft:smooth_stone
fill ~-106 ~13 ~-100 ~-100 ~13 ~-88 minecraft:dark_oak_planks
setblock ~-104 ~3 ~-100 minecraft:gray_stained_glass_pane
setblock ~-104 ~3 ~-88 minecraft:gray_stained_glass_pane
setblock ~-106 ~3 ~-98 minecraft:gray_stained_glass_pane
setblock ~-100 ~3 ~-98 minecraft:gray_stained_glass_pane
setblock ~-106 ~3 ~-95 minecraft:gray_stained_glass_pane
setblock ~-100 ~3 ~-95 minecraft:gray_stained_glass_pane
setblock ~-106 ~3 ~-92 minecraft:gray_stained_glass_pane
setblock ~-100 ~3 ~-92 minecraft:gray_stained_glass_pane
setblock ~-104 ~7 ~-100 minecraft:gray_stained_glass_pane
setblock ~-104 ~7 ~-88 minecraft:gray_stained_glass_pane
setblock ~-106 ~7 ~-98 minecraft:gray_stained_glass_pane
setblock ~-100 ~7 ~-98 minecraft:gray_stained_glass_pane
setblock ~-106 ~7 ~-95 minecraft:gray_stained_glass_pane
setblock ~-100 ~7 ~-95 minecraft:gray_stained_glass_pane
setblock ~-106 ~7 ~-92 minecraft:gray_stained_glass_pane
setblock ~-100 ~7 ~-92 minecraft:gray_stained_glass_pane
setblock ~-104 ~11 ~-100 minecraft:gray_stained_glass_pane
setblock ~-104 ~11 ~-88 minecraft:gray_stained_glass_pane
setblock ~-106 ~11 ~-98 minecraft:gray_stained_glass_pane
setblock ~-100 ~11 ~-98 minecraft:gray_stained_glass_pane
setblock ~-106 ~11 ~-95 minecraft:gray_stained_glass_pane
setblock ~-100 ~11 ~-95 minecraft:gray_stained_glass_pane
setblock ~-106 ~11 ~-92 minecraft:gray_stained_glass_pane
setblock ~-100 ~11 ~-92 minecraft:gray_stained_glass_pane
setblock ~-103 ~2 ~-88 minecraft:dark_oak_door[half=lower]
setblock ~-103 ~3 ~-88 minecraft:dark_oak_door[half=upper]
fill ~-9 ~1 ~-81 ~-3 ~8 ~-75 minecraft:white_terracotta
fill ~-8 ~2 ~-80 ~-4 ~7 ~-76 minecraft:air
fill ~-8 ~4 ~-80 ~-4 ~4 ~-76 minecraft:smooth_stone
fill ~-9 ~9 ~-81 ~-3 ~9 ~-75 minecraft:spruce_planks
setblock ~-7 ~3 ~-81 minecraft:gray_stained_glass_pane
setblock ~-7 ~3 ~-75 minecraft:gray_stained_glass_pane
setblock ~-9 ~3 ~-79 minecraft:gray_stained_glass_pane
setblock ~-3 ~3 ~-79 minecraft:gray_stained_glass_pane
setblock ~-7 ~7 ~-81 minecraft:gray_stained_glass_pane
setblock ~-7 ~7 ~-75 minecraft:gray_stained_glass_pane
setblock ~-9 ~7 ~-79 minecraft:gray_stained_glass_pane
setblock ~-3 ~7 ~-79 minecraft:gray_stained_glass_pane
setblock ~-9 ~2 ~-78 minecraft:dark_oak_door[half=lower]
setblock ~-9 ~3 ~-78 minecraft:dark_oak_door[half=upper]
fill ~-103 ~1 ~-29 ~-94 ~24 ~-18 minecraft:white_terracotta
fill ~-102 ~2 ~-28 ~-95 ~23 ~-19 minecraft:air
fill ~-102 ~4 ~-28 ~-95 ~4 ~-19 minecraft:smooth_stone
fill ~-102 ~8 ~-28 ~-95 ~8 ~-19 minecraft:smooth_stone
fill ~-102 ~12 ~-28 ~-95 ~12 ~-19 minecraft:smooth_stone
fill ~-102 ~16 ~-28 ~-95 ~16 ~-19 minecraft:smooth_stone
fill ~-102 ~20 ~-28 ~-95 ~20 ~-19 minecraft:smooth_stone
fill ~-103 ~25 ~-29 ~-94 ~25 ~-18 minecraft:spruce_planks
setblock ~-101 ~3 ~-29 minecraft:gray_stained_glass_pane
setblock ~-101 ~3 ~-18 minecraft:gray_stained_glass_pane
setblock ~-98 ~3 ~-29 minecraft:gray_stained_glass_pane
setblock ~-98 ~3 ~-18 minecraft:gray_stained_glass_pane
setblock ~-103 ~3 ~-27 minecraft:gray_stained_glass_pane
setblock ~-94 ~3 ~-27 minecraft:gray_stained_glass_pane
setblock ~-103 ~3 ~-24 minecraft:gray_stained_glass_pane
setblock ~-94 ~3 ~-24 minecraft:gray_stained_glass_pane
setblock ~-103 ~3 ~-21 minecraft:gray_stained_glass_pane
setblock ~-94 ~3 ~-21 minecraft:gray_stained_glass_pane
setblock ~-101 ~7 ~-29 minecraft:gray_stained_glass_pane
setblock ~-101 ~7 ~-18 minecraft:gray_stained_glass_pane
setblock ~-98 ~7 ~-29 minecraft:gray_stained_glass_pane
setblock ~-98 ~7 ~-18 minecraft:gray_stained_glass_pane
setblock ~-103 ~7 ~-27 minecraft:gray_stained_glass_pane
setblock ~-94 ~7 ~-27 minecraft:gray_stained_glass_pane
setblock ~-103 ~7 ~-24 minecraft:gray_stained_glass_pane
setblock ~-94 ~7 ~-24 minecraft:gray_stained_glass_pane
setblock ~-103 ~7 ~-21 minecraft:gray_stained_glass_pane
setblock ~-94 ~7 ~-21 minecraft:gray_stained_glass_pane
setblock ~-101 ~11 ~-29 minecraft:gray_stained_glass_pane
setblock ~-101 ~11 ~-18 minecraft:gray_stained_glass_pane
setblock ~-98 ~11 ~-29 minecraft:gray_stained_glass_pane
setblock ~-98 ~11 ~-18 minecraft:gray_stained_glass_pane
setblock ~-103 ~11 ~-27 minecraft:gray_stained_glass_pane
setblock ~-94 ~11 ~-27 minecraft:gray_stained_glass_pane
setblock ~-103 ~11 ~-24 minecraft:gray_stained_glass_pane
setblock ~-94 ~11 ~-24 minecraft:gray_stained_glass_pane
setblock ~-103 ~11 ~-21 minecraft:gray_stained_glass_pane
setblock ~-94 ~11 ~-21 minecraft:gray_stained_glass_pane
setblock ~-101 ~15 ~-29 minecraft:gray_stained_glass_pane
setblock ~-101 ~15 ~-18 minecraft:gray_stained_glass_pane
setblock ~-98 ~15 ~-29 minecraft:gray_stained_glass_pane
setblock ~-98 ~15 ~-18 minecraft:gray_stained_glass_pane
setblock ~-103 ~15 ~-27 minecraft:gray_stained_glass_pane
setblock ~-94 ~15 ~-27 minecraft:gray_stained_glass_pane
setblock ~-103 ~15 ~-24 minecraft:gray_stained_glass_pane
setblock ~-94 ~15 ~-24 minecraft:gray_stained_glass_pane
setblock ~-103 ~15 ~-21 minecraft:gray_stained_glass_pane
setblock ~-94 ~15 ~-21 minecraft:gray_stained_glass_pane
setblock ~-101 ~19 ~-29 minecraft:gray_stained_glass_pane
setblock ~-101 ~19 ~-18 minecraft:gray_stained_glass_pane
setblock ~-98 ~19 ~-29 minecraft:gray_stained_glass_pane
setblock ~-98 ~19 ~-18 minecraft:gray_stained_glass_pane
setblock ~-103 ~19 ~-27 minecraft:gray_stained_glass_pane
setblock ~-94 ~19 ~-27 minecraft:gray_stained_glass_pane
setblock ~-103 ~19 ~-24 minecraft:gray_stained_glass_pane
setblock ~-94 ~19 ~-24 minecraft:gray_stained_glass_pane
setblock ~-103 ~19 ~-21 minecraft:gray_stained_glass_pane
setblock ~-94 ~19 ~-21 minecraft:gray_stained_glass_pane
setblock ~-101 ~23 ~-29 minecraft:gray_stained_glass_pane
setblock ~-101 ~23 ~-18 minecraft:gray_stained_glass_pane
setblock ~-98 ~23 ~-29 minecraft:gray_stained_glass_pane
setblock ~-98 ~23 ~-18 minecraft:gray_stained_glass_pane
setblock ~-103 ~23 ~-27 minecraft:gray_stained_glass_pane
setblock ~-94 ~23 ~-27 minecraft:gray_stained_glass_pane
setblock ~-103 ~23 ~-24 minecraft:gray_stained_glass_pane
setblock ~-94 ~23 ~-24 minecraft:gray_stained_glass_pane
setblock ~-103 ~23 ~-21 minecraft:gray_stained_glass_pane
setblock ~-94 ~23 ~-21 minecraft:gray_stained_glass_pane
setblock ~-98 ~2 ~-18 minecraft:dark_oak_door[half=lower]
setblock ~-98 ~3 ~-18 minecraft:dark_oak_door[half=upper]
setblock ~-102 ~2 ~-18 minecraft:cyan_stained_glass
setblock ~-100 ~2 ~-18 minecraft:cyan_stained_glass
setblock ~-98 ~2 ~-18 minecraft:cyan_stained_glass
setblock ~-96 ~2 ~-18 minecraft:cyan_stained_glass
fill ~38 ~1 ~74 ~48 ~12 ~79 minecraft:light_gray_concrete
fill ~39 ~2 ~75 ~47 ~11 ~78 minecraft:air
fill ~39 ~4 ~75 ~47 ~4 ~78 minecraft:smooth_stone
fill ~39 ~8 ~75 ~47 ~8 ~78 minecraft:smooth_stone
fill ~38 ~13 ~74 ~48 ~13 ~79 minecraft:gray_concrete
fill ~38 ~1 ~80 ~43 ~8 ~83 minecraft:light_gray_concrete
fill ~39 ~2 ~81 ~42 ~7 ~82 minecraft:air
fill ~39 ~4 ~81 ~42 ~4 ~82 minecraft:smooth_stone
fill ~38 ~9 ~80 ~43 ~9 ~83 minecraft:gray_concrete
setblock ~40 ~3 ~74 minecraft:gray_stained_glass_pane
setblock ~40 ~3 ~83 minecraft:gray_stained_glass_pane
setblock ~43 ~3 ~74 minecraft:gray_stained_glass_pane
setblock ~43 ~3 ~83 minecraft:gray_stained_glass_pane
setblock ~46 ~3 ~74 minecraft:gray_stained_glass_pane
setblock ~46 ~3 ~83 minecraft:gray_stained_glass_pane
setblock ~38 ~3 ~76 minecraft:gray_stained_glass_pane
setblock ~48 ~3 ~76 minecraft:gray_stained_glass_pane
setblock ~38 ~3 ~79 minecraft:gray_stained_glass_pane
setblock ~48 ~3 ~79 minecraft:gray_stained_glass_pane
setblock ~40 ~7 ~74 minecraft:gray_stained_glass_pane
setblock ~40 ~7 ~83 minecraft:gray_stained_glass_pane
setblock ~43 ~7 ~74 minecraft:gray_stained_glass_pane
setblock ~43 ~7 ~83 minecraft:gray_stained_glass_pane
setblock ~46 ~7 ~74 minecraft:gray_stained_glass_pane
setblock ~46 ~7 ~83 minecraft:gray_stained_glass_pane
setblock ~38 ~7 ~76 minecraft:gray_stained_glass_pane
setblock ~48 ~7 ~76 minecraft:gray_stained_glass_pane
setblock ~38 ~7 ~79 minecraft:gray_stained_glass_pane
setblock ~48 ~7 ~79 minecraft:gray_stained_glass_pane
setblock ~40 ~11 ~74 minecraft:gray_stained_glass_pane
setblock ~40 ~11 ~83 minecraft:gray_stained_glass_pane
setblock ~43 ~11 ~74 minecraft:gray_stained_glass_pane
setblock ~43 ~11 ~83 minecraft:gray_stained_glass_pane
setblock ~46 ~11 ~74 minecraft:gray_stained_glass_pane
setblock ~46 ~11 ~83 minecraft:gray_stained_glass_pane
setblock ~38 ~11 ~76 minecraft:gray_stained_glass_pane
setblock ~48 ~11 ~76 minecraft:gray_stained_glass_pane
setblock ~38 ~11 ~79 minecraft:gray_stained_glass_pane
setblock ~48 ~11 ~79 minecraft:gray_stained_glass_pane
setblock ~43 ~2 ~74 minecraft:dark_oak_door[half=lower]
setblock ~43 ~3 ~74 minecraft:dark_oak_door[half=upper]
fill ~-9 ~1 ~-94 ~2 ~12 ~-83 minecraft:stone_bricks
fill ~-8 ~2 ~-93 ~1 ~11 ~-84 minecraft:air
fill ~-8 ~4 ~-93 ~1 ~4 ~-84 minecraft:smooth_stone
fill ~-8 ~8 ~-93 ~1 ~8 ~-84 minecraft:smooth_stone
fill ~-9 ~13 ~-94 ~2 ~13 ~-83 minecraft:deepslate_bricks
setblock ~-7 ~3 ~-94 minecraft:gray_stained_glass_pane
setblock ~-7 ~3 ~-83 minecraft:gray_stained_glass_pane
setblock ~-4 ~3 ~-94 minecraft:gray_stained_glass_pane
setblock ~-4 ~3 ~-83 minecraft:gray_stained_glass_pane
setblock ~-1 ~3 ~-94 minecraft:gray_stained_glass_pane
setblock ~-1 ~3 ~-83 minecraft:gray_stained_glass_pane
setblock ~-9 ~3 ~-92 minecraft:gray_stained_glass_pane
setblock ~2 ~3 ~-92 minecraft:gray_stained_glass_pane
setblock ~-9 ~3 ~-89 minecraft:gray_stained_glass_pane
setblock ~2 ~3 ~-89 minecraft:gray_stained_glass_pane
setblock ~-9 ~3 ~-86 minecraft:gray_stained_glass_pane
setblock ~2 ~3 ~-86 minecraft:gray_stained_glass_pane
setblock ~-7 ~7 ~-94 minecraft:gray_stained_glass_pane
setblock ~-7 ~7 ~-83 minecraft:gray_stained_glass_pane
setblock ~-4 ~7 ~-94 minecraft:gray_stained_glass_pane
setblock ~-4 ~7 ~-83 minecraft:gray_stained_glass_pane
setblock ~-1 ~7 ~-94 minecraft:gray_stained_glass_pane
setblock ~-1 ~7 ~-83 minecraft:gray_stained_glass_pane
setblock ~-9 ~7 ~-92 minecraft:gray_stained_glass_pane
setblock ~2 ~7 ~-92 minecraft:gray_stained_glass_pane
setblock ~-9 ~7 ~-89 minecraft:gray_stained_glass_pane
setblock ~2 ~7 ~-89 minecraft:gray_stained_glass_pane
setblock ~-9 ~7 ~-86 minecraft:gray_stained_glass_pane
setblock ~2 ~7 ~-86 minecraft:gray_stained_glass_pane
setblock ~-7 ~11 ~-94 minecraft:gray_stained_glass_pane
setblock ~-7 ~11 ~-83 minecraft:gray_stained_glass_pane
setblock ~-4 ~11 ~-94 minecraft:gray_stained_glass_pane
setblock ~-4 ~11 ~-83 minecraft:gray_stained_glass_pane
setblock ~-1 ~11 ~-94 minecraft:gray_stained_glass_pane
setblock ~-1 ~11 ~-83 minecraft:gray_stained_glass_pane
setblock ~-9 ~11 ~-92 minecraft:gray_stained_glass_pane
setblock ~2 ~11 ~-92 minecraft:gray_stained_glass_pane
setblock ~-9 ~11 ~-89 minecraft:gray_stained_glass_pane
setblock ~2 ~11 ~-89 minecraft:gray_stained_glass_pane
setblock ~-9 ~11 ~-86 minecraft:gray_stained_glass_pane
setblock ~2 ~11 ~-86 minecraft:gray_stained_glass_pane
setblock ~-9 ~2 ~-88 minecraft:dark_oak_door[half=lower]
setblock ~-9 ~3 ~-88 minecraft:dark_oak_door[half=upper]
setblock ~-9 ~2 ~-93 minecraft:cyan_stained_glass
setblock ~-9 ~2 ~-91 minecraft:cyan_stained_glass
setblock ~-9 ~2 ~-89 minecraft:cyan_stained_glass
setblock ~-9 ~2 ~-87 minecraft:cyan_stained_glass
setblock ~-9 ~2 ~-85 minecraft:cyan_stained_glass
fill ~39 ~1 ~-79 ~53 ~12 ~-71 minecraft:light_gray_concrete
fill ~40 ~2 ~-78 ~52 ~11 ~-72 minecraft:air
fill ~40 ~4 ~-78 ~52 ~4 ~-72 minecraft:smooth_stone
fill ~40 ~8 ~-78 ~52 ~8 ~-72 minecraft:smooth_stone
fill ~39 ~13 ~-79 ~53 ~13 ~-71 minecraft:gray_concrete
fill ~41 ~1 ~-77 ~51 ~16 ~-73 minecraft:light_gray_concrete
fill ~42 ~2 ~-76 ~50 ~15 ~-74 minecraft:air
fill ~42 ~4 ~-76 ~50 ~4 ~-74 minecraft:smooth_stone
fill ~42 ~8 ~-76 ~50 ~8 ~-74 minecraft:smooth_stone
fill ~42 ~12 ~-76 ~50 ~12 ~-74 minecraft:smooth_stone
fill ~41 ~17 ~-77 ~51 ~17 ~-73 minecraft:gray_concrete
setblock ~41 ~3 ~-79 minecraft:gray_stained_glass_pane
setblock ~41 ~3 ~-71 minecraft:gray_stained_glass_pane
setblock ~44 ~3 ~-79 minecraft:gray_stained_glass_pane
setblock ~44 ~3 ~-71 minecraft:gray_stained_glass_pane
setblock ~47 ~3 ~-79 minecraft:gray_stained_glass_pane
setblock ~47 ~3 ~-71 minecraft:gray_stained_glass_pane
setblock ~50 ~3 ~-79 minecraft:gray_stained_glass_pane
setblock ~50 ~3 ~-71 minecraft:gray_stained_glass_pane
setblock ~39 ~3 ~-77 minecraft:gray_stained_glass_pane
setblock ~53 ~3 ~-77 minecraft:gray_stained_glass_pane
setblock ~39 ~3 ~-74 minecraft:gray_stained_glass_pane
setblock ~53 ~3 ~-74 minecraft:gray_stained_glass_pane
setblock ~41 ~7 ~-79 minecraft:gray_stained_glass_pane
setblock ~41 ~7 ~-71 minecraft:gray_stained_glass_pane
setblock ~44 ~7 ~-79 minecraft:gray_stained_glass_pane
setblock ~44 ~7 ~-71 minecraft:gray_stained_glass_pane
setblock ~47 ~7 ~-79 minecraft:gray_stained_glass_pane
setblock ~47 ~7 ~-71 minecraft:gray_stained_glass_pane
setblock ~50 ~7 ~-79 minecraft:gray_stained_glass_pane
setblock ~50 ~7 ~-71 minecraft:gray_stained_glass_pane
setblock ~39 ~7 ~-77 minecraft:gray_stained_glass_pane
setblock ~53 ~7 ~-77 minecraft:gray_stained_glass_pane
setblock ~39 ~7 ~-74 minecraft:gray_stained_glass_pane
setblock ~53 ~7 ~-74 minecraft:gray_stained_glass_pane
setblock ~41 ~11 ~-79 minecraft:gray_stained_glass_pane
setblock ~41 ~11 ~-71 minecraft:gray_stained_glass_pane
setblock ~44 ~11 ~-79 minecraft:gray_stained_glass_pane
setblock ~44 ~11 ~-71 minecraft:gray_stained_glass_pane
setblock ~47 ~11 ~-79 minecraft:gray_stained_glass_pane
setblock ~47 ~11 ~-71 minecraft:gray_stained_glass_pane
setblock ~50 ~11 ~-79 minecraft:gray_stained_glass_pane
setblock ~50 ~11 ~-71 minecraft:gray_stained_glass_pane
setblock ~39 ~11 ~-77 minecraft:gray_stained_glass_pane
setblock ~53 ~11 ~-77 minecraft:gray_stained_glass_pane
setblock ~39 ~11 ~-74 minecraft:gray_stained_glass_pane
setblock ~53 ~11 ~-74 minecraft:gray_stained_glass_pane
setblock ~41 ~15 ~-79 minecraft:gray_stained_glass_pane
setblock ~41 ~15 ~-71 minecraft:gray_stained_glass_pane
setblock ~44 ~15 ~-79 minecraft:gray_stained_glass_pane
setblock ~44 ~15 ~-71 minecraft:gray_stained_glass_pane
setblock ~47 ~15 ~-79 minecraft:gray_stained_glass_pane
setblock ~47 ~15 ~-71 minecraft:gray_stained_glass_pane
setblock ~50 ~15 ~-79 minecraft:gray_stained_glass_pane
setblock ~50 ~15 ~-71 minecraft:gray_stained_glass_pane
setblock ~39 ~15 ~-77 minecraft:gray_stained_glass_pane
setblock ~53 ~15 ~-77 minecraft:gray_stained_glass_pane
setblock ~39 ~15 ~-74 minecraft:gray_stained_glass_pane
setblock ~53 ~15 ~-74 minecraft:gray_stained_glass_pane
setblock ~46 ~2 ~-71 minecraft:dark_oak_door[half=lower]
setblock ~46 ~3 ~-71 minecraft:dark_oak_door[half=upper]
setblock ~40 ~2 ~-71 minecraft:cyan_stained_glass
setblock ~42 ~2 ~-71 minecraft:cyan_stained_glass
setblock ~44 ~2 ~-71 minecraft:cyan_stained_glass
setblock ~46 ~2 ~-71 minecraft:cyan_stained_glass
setblock ~48 ~2 ~-71 minecraft:cyan_stained_glass
setblock ~50 ~2 ~-71 minecraft:cyan_stained_glass
setblock ~52 ~2 ~-71 minecraft:cyan_stained_glass
fill ~110 ~1 ~55 ~119 ~12 ~65 minecraft:stone_bricks
fill ~111 ~2 ~56 ~118 ~11 ~64 minecraft:air
fill ~111 ~4 ~56 ~118 ~4 ~64 minecraft:smooth_stone
fill ~111 ~8 ~56 ~118 ~8 ~64 minecraft:smooth_stone
fill ~110 ~13 ~55 ~119 ~13 ~65 minecraft:deepslate_bricks
setblock ~112 ~3 ~55 minecraft:gray_stained_glass_pane
setblock ~112 ~3 ~65 minecraft:gray_stained_glass_pane
setblock ~115 ~3 ~55 minecraft:gray_stained_glass_pane
setblock ~115 ~3 ~65 minecraft:gray_stained_glass_pane
setblock ~110 ~3 ~57 minecraft:gray_stained_glass_pane
setblock ~119 ~3 ~57 minecraft:gray_stained_glass_pane
setblock ~110 ~3 ~60 minecraft:gray_stained_glass_pane
setblock ~119 ~3 ~60 minecraft:gray_stained_glass_pane
setblock ~110 ~3 ~63 minecraft:gray_stained_glass_pane
setblock ~119 ~3 ~63 minecraft:gray_stained_glass_pane
setblock ~112 ~7 ~55 minecraft:gray_stained_glass_pane
setblock ~112 ~7 ~65 minecraft:gray_stained_glass_pane
setblock ~115 ~7 ~55 minecraft:gray_stained_glass_pane
setblock ~115 ~7 ~65 minecraft:gray_stained_glass_pane
setblock ~110 ~7 ~57 minecraft:gray_stained_glass_pane
setblock ~119 ~7 ~57 minecraft:gray_stained_glass_pane
setblock ~110 ~7 ~60 minecraft:gray_stained_glass_pane
setblock ~119 ~7 ~60 minecraft:gray_stained_glass_pane
setblock ~110 ~7 ~63 minecraft:gray_stained_glass_pane
setblock ~119 ~7 ~63 minecraft:gray_stained_glass_pane
setblock ~112 ~11 ~55 minecraft:gray_stained_glass_pane
setblock ~112 ~11 ~65 minecraft:gray_stained_glass_pane
setblock ~115 ~11 ~55 minecraft:gray_stained_glass_pane
setblock ~115 ~11 ~65 minecraft:gray_stained_glass_pane
setblock ~110 ~11 ~57 minecraft:gray_stained_glass_pane
setblock ~119 ~11 ~57 minecraft:gray_stained_glass_pane
setblock ~110 ~11 ~60 minecraft:gray_stained_glass_pane
setblock ~119 ~11 ~60 minecraft:gray_stained_glass_pane
setblock ~110 ~11 ~63 minecraft:gray_stained_glass_pane
setblock ~119 ~11 ~63 minecraft:gray_stained_glass_pane
setblock ~110 ~2 ~60 minecraft:dark_oak_door[half=lower]
setblock ~110 ~3 ~60 minecraft:dark_oak_door[half=upper]
setblock ~110 ~2 ~56 minecraft:cyan_stained_glass
setblock ~110 ~2 ~58 minecraft:cyan_stained_glass
setblock ~110 ~2 ~60 minecraft:cyan_stained_glass
setblock ~110 ~2 ~62 minecraft:cyan_stained_glass
setblock ~110 ~2 ~64 minecraft:cyan_stained_glass
fill ~62 ~1 ~98 ~75 ~12 ~105 minecraft:mud_bricks
fill ~63 ~2 ~99 ~74 ~11 ~104 minecraft:air
fill ~63 ~4 ~99 ~74 ~4 ~104 minecraft:smooth_stone
fill ~63 ~8 ~99 ~74 ~8 ~104 minecraft:smooth_stone
fill ~62 ~13 ~98 ~75 ~13 ~105 minecraft:dark_oak_planks
fill ~62 ~1 ~106 ~69 ~8 ~112 minecraft:mud_bricks
fill ~63 ~2 ~107 ~68 ~7 ~111 minecraft:air
fill ~63 ~4 ~107 ~68 ~4 ~111 minecraft:smooth_stone
fill ~62 ~9 ~106 ~69 ~9 ~112 minecraft:dark_oak_planks
setblock ~64 ~3 ~98 minecraft:gray_stained_glass_pane
setblock ~64 ~3 ~112 minecraft:gray_stained_glass_pane
setblock ~67 ~3 ~98 minecraft:gray_stained_glass_pane
setblock ~67 ~3 ~112 minecraft:gray_stained_glass_pane
setblock ~70 ~3 ~98 minecraft:gray_stained_glass_pane
setblock ~70 ~3 ~112 minecraft:gray_stained_glass_pane
setblock ~73 ~3 ~98 minecraft:gray_stained_glass_pane
setblock ~73 ~3 ~112 minecraft:gray_stained_glass_pane
setblock ~62 ~3 ~100 minecraft:gray_stained_glass_pane
setblock ~75 ~3 ~100 minecraft:gray_stained_glass_pane
setblock ~62 ~3 ~103 minecraft:gray_stained_glass_pane
setblock ~75 ~3 ~103 minecraft:gray_stained_glass_pane
setblock ~62 ~3 ~106 minecraft:gray_stained_glass_pane
setblock ~75 ~3 ~106 minecraft:gray_stained_glass_pane
setblock ~62 ~3 ~109 minecraft:gray_stained_glass_pane
setblock ~75 ~3 ~109 minecraft:gray_stained_glass_pane
setblock ~64 ~7 ~98 minecraft:gray_stained_glass_pane
setblock ~64 ~7 ~112 minecraft:gray_stained_glass_pane
setblock ~67 ~7 ~98 minecraft:gray_stained_glass_pane
setblock ~67 ~7 ~112 minecraft:gray_stained_glass_pane
setblock ~70 ~7 ~98 minecraft:gray_stained_glass_pane
setblock ~70 ~7 ~112 minecraft:gray_stained_glass_pane
setblock ~73 ~7 ~98 minecraft:gray_stained_glass_pane
setblock ~73 ~7 ~112 minecraft:gray_stained_glass_pane
setblock ~62 ~7 ~100 minecraft:gray_stained_glass_pane
setblock ~75 ~7 ~100 minecraft:gray_stained_glass_pane
setblock ~62 ~7 ~103 minecraft:gray_stained_glass_pane
setblock ~75 ~7 ~103 minecraft:gray_stained_glass_pane
setblock ~62 ~7 ~106 minecraft:gray_stained_glass_pane
setblock ~75 ~7 ~106 minecraft:gray_stained_glass_pane
setblock ~62 ~7 ~109 minecraft:gray_stained_glass_pane
setblock ~75 ~7 ~109 minecraft:gray_stained_glass_pane
setblock ~64 ~11 ~98 minecraft:gray_stained_glass_pane
setblock ~64 ~11 ~112 minecraft:gray_stained_glass_pane
setblock ~67 ~11 ~98 minecraft:gray_stained_glass_pane
setblock ~67 ~11 ~112 minecraft:gray_stained_glass_pane
setblock ~70 ~11 ~98 minecraft:gray_stained_glass_pane
setblock ~70 ~11 ~112 minecraft:gray_stained_glass_pane
setblock ~73 ~11 ~98 minecraft:gray_stained_glass_pane
setblock ~73 ~11 ~112 minecraft:gray_stained_glass_pane
setblock ~62 ~11 ~100 minecraft:gray_stained_glass_pane
setblock ~75 ~11 ~100 minecraft:gray_stained_glass_pane
setblock ~62 ~11 ~103 minecraft:gray_stained_glass_pane
setblock ~75 ~11 ~103 minecraft:gray_stained_glass_pane
setblock ~62 ~11 ~106 minecraft:gray_stained_glass_pane
setblock ~75 ~11 ~106 minecraft:gray_stained_glass_pane
setblock ~62 ~11 ~109 minecraft:gray_stained_glass_pane
setblock ~75 ~11 ~109 minecraft:gray_stained_glass_pane
setblock ~69 ~2 ~98 minecraft:dark_oak_door[half=lower]
setblock ~69 ~3 ~98 minecraft:dark_oak_door[half=upper]
fill ~-100 ~1 ~2 ~-93 ~20 ~14 minecraft:bricks
fill ~-99 ~2 ~3 ~-94 ~19 ~13 minecraft:air
fill ~-99 ~4 ~3 ~-94 ~4 ~13 minecraft:smooth_stone
fill ~-99 ~8 ~3 ~-94 ~8 ~13 minecraft:smooth_stone
fill ~-99 ~12 ~3 ~-94 ~12 ~13 minecraft:smooth_stone
fill ~-99 ~16 ~3 ~-94 ~16 ~13 minecraft:smooth_stone
fill ~-100 ~21 ~2 ~-93 ~21 ~14 minecraft:polished_andesite
setblock ~-98 ~3 ~2 minecraft:gray_stained_glass_pane
setblock ~-98 ~3 ~14 minecraft:gray_stained_glass_pane
setblock ~-95 ~3 ~2 minecraft:gray_stained_glass_pane
setblock ~-95 ~3 ~14 minecraft:gray_stained_glass_pane
setblock ~-100 ~3 ~4 minecraft:gray_stained_glass_pane
setblock ~-93 ~3 ~4 minecraft:gray_stained_glass_pane
setblock ~-100 ~3 ~7 minecraft:gray_stained_glass_pane
setblock ~-93 ~3 ~7 minecraft:gray_stained_glass_pane
setblock ~-100 ~3 ~10 minecraft:gray_stained_glass_pane
setblock ~-93 ~3 ~10 minecraft:gray_stained_glass_pane
setblock ~-98 ~7 ~2 minecraft:gray_stained_glass_pane
setblock ~-98 ~7 ~14 minecraft:gray_stained_glass_pane
setblock ~-95 ~7 ~2 minecraft:gray_stained_glass_pane
setblock ~-95 ~7 ~14 minecraft:gray_stained_glass_pane
setblock ~-100 ~7 ~4 minecraft:gray_stained_glass_pane
setblock ~-93 ~7 ~4 minecraft:gray_stained_glass_pane
setblock ~-100 ~7 ~7 minecraft:gray_stained_glass_pane
setblock ~-93 ~7 ~7 minecraft:gray_stained_glass_pane
setblock ~-100 ~7 ~10 minecraft:gray_stained_glass_pane
setblock ~-93 ~7 ~10 minecraft:gray_stained_glass_pane
setblock ~-98 ~11 ~2 minecraft:gray_stained_glass_pane
setblock ~-98 ~11 ~14 minecraft:gray_stained_glass_pane
setblock ~-95 ~11 ~2 minecraft:gray_stained_glass_pane
setblock ~-95 ~11 ~14 minecraft:gray_stained_glass_pane
setblock ~-100 ~11 ~4 minecraft:gray_stained_glass_pane
setblock ~-93 ~11 ~4 minecraft:gray_stained_glass_pane
setblock ~-100 ~11 ~7 minecraft:gray_stained_glass_pane
setblock ~-93 ~11 ~7 minecraft:gray_stained_glass_pane
setblock ~-100 ~11 ~10 minecraft:gray_stained_glass_pane
setblock ~-93 ~11 ~10 minecraft:gray_stained_glass_pane
setblock ~-98 ~15 ~2 minecraft:gray_stained_glass_pane
setblock ~-98 ~15 ~14 minecraft:gray_stained_glass_pane
setblock ~-95 ~15 ~2 minecraft:gray_stained_glass_pane
setblock ~-95 ~15 ~14 minecraft:gray_stained_glass_pane
setblock ~-100 ~15 ~4 minecraft:gray_stained_glass_pane
setblock ~-93 ~15 ~4 minecraft:gray_stained_glass_pane
setblock ~-100 ~15 ~7 minecraft:gray_stained_glass_pane
setblock ~-93 ~15 ~7 minecraft:gray_stained_glass_pane
setblock ~-100 ~15 ~10 minecraft:gray_stained_glass_pane
setblock ~-93 ~15 ~10 minecraft:gray_stained_glass_pane
setblock ~-98 ~19 ~2 minecraft:gray_stained_glass_pane
setblock ~-98 ~19 ~14 minecraft:gray_stained_glass_pane
setblock ~-95 ~19 ~2 minecraft:gray_stained_glass_pane
setblock ~-95 ~19 ~14 minecraft:gray_stained_glass_pane
setblock ~-100 ~19 ~4 minecraft:gray_stained_glass_pane
setblock ~-93 ~19 ~4 minecraft:gray_stained_glass_pane
setblock ~-100 ~19 ~7 minecraft:gray_stained_glass_pane
setblock ~-93 ~19 ~7 minecraft:gray_stained_glass_pane
setblock ~-100 ~19 ~10 minecraft:gray_stained_glass_pane
setblock ~-93 ~19 ~10 minecraft:gray_stained_glass_pane
setblock ~-96 ~2 ~2 minecraft:dark_oak_door[half=lower]
setblock ~-96 ~3 ~2 minecraft:dark_oak_door[half=upper]
setblock ~-99 ~2 ~2 minecraft:cyan_stained_glass
setblock ~-97 ~2 ~2 minecraft:cyan_stained_glass
setblock ~-95 ~2 ~2 minecraft:cyan_stained_glass
fill ~113 ~1 ~14 ~120 ~20 ~23 minecraft:bricks
fill ~114 ~2 ~15 ~119 ~19 ~22 minecraft:air
fill ~114 ~4 ~15 ~119 ~4 ~22 minecraft:smooth_stone
fill ~114 ~8 ~15 ~119 ~8 ~22 minecraft:smooth_stone
fill ~114 ~12 ~15 ~119 ~12 ~22 minecraft:smooth_stone
fill ~114 ~16 ~15 ~119 ~16 ~22 minecraft:smooth_stone
fill ~113 ~21 ~14 ~120 ~21 ~23 minecraft:polished_andesite
fill ~111 ~1 ~16 ~112 ~20 ~23 minecraft:bricks
fill ~112 ~4 ~17 ~111 ~4 ~22 minecraft:smooth_stone
fill ~112 ~8 ~17 ~111 ~8 ~22 minecraft:smooth_stone
fill ~112 ~12 ~17 ~111 ~12 ~22 minecraft:smooth_stone
fill ~112 ~16 ~17 ~111 ~16 ~22 minecraft:smooth_stone
fill ~111 ~21 ~16 ~112 ~21 ~23 minecraft:polished_andesite
setblock ~113 ~3 ~14 minecraft:gray_stained_glass_pane
setblock ~113 ~3 ~23 minecraft:gray_stained_glass_pane
setblock ~116 ~3 ~14 minecraft:gray_stained_glass_pane
setblock ~116 ~3 ~23 minecraft:gray_stained_glass_pane
setblock ~111 ~3 ~16 minecraft:gray_stained_glass_pane
setblock ~120 ~3 ~16 minecraft:gray_stained_glass_pane
setblock ~111 ~3 ~19 minecraft:gray_stained_glass_pane
setblock ~120 ~3 ~19 minecraft:gray_stained_glass_pane
setblock ~113 ~7 ~14 minecraft:gray_stained_glass_pane
setblock ~113 ~7 ~23 minecraft:gray_stained_glass_pane
setblock ~116 ~7 ~14 minecraft:gray_stained_glass_pane
setblock ~116 ~7 ~23 minecraft:gray_stained_glass_pane
setblock ~111 ~7 ~16 minecraft:gray_stained_glass_pane
setblock ~120 ~7 ~16 minecraft:gray_stained_glass_pane
setblock ~111 ~7 ~19 minecraft:gray_stained_glass_pane
setblock ~120 ~7 ~19 minecraft:gray_stained_glass_pane
setblock ~113 ~11 ~14 minecraft:gray_stained_glass_pane
setblock ~113 ~11 ~23 minecraft:gray_stained_glass_pane
setblock ~116 ~11 ~14 minecraft:gray_stained_glass_pane
setblock ~116 ~11 ~23 minecraft:gray_stained_glass_pane
setblock ~111 ~11 ~16 minecraft:gray_stained_glass_pane
setblock ~120 ~11 ~16 minecraft:gray_stained_glass_pane
setblock ~111 ~11 ~19 minecraft:gray_stained_glass_pane
setblock ~120 ~11 ~19 minecraft:gray_stained_glass_pane
setblock ~113 ~15 ~14 minecraft:gray_stained_glass_pane
setblock ~113 ~15 ~23 minecraft:gray_stained_glass_pane
setblock ~116 ~15 ~14 minecraft:gray_stained_glass_pane
setblock ~116 ~15 ~23 minecraft:gray_stained_glass_pane
setblock ~111 ~15 ~16 minecraft:gray_stained_glass_pane
setblock ~120 ~15 ~16 minecraft:gray_stained_glass_pane
setblock ~111 ~15 ~19 minecraft:gray_stained_glass_pane
setblock ~120 ~15 ~19 minecraft:gray_stained_glass_pane
setblock ~113 ~19 ~14 minecraft:gray_stained_glass_pane
setblock ~113 ~19 ~23 minecraft:gray_stained_glass_pane
setblock ~116 ~19 ~14 minecraft:gray_stained_glass_pane
setblock ~116 ~19 ~23 minecraft:gray_stained_glass_pane
setblock ~111 ~19 ~16 minecraft:gray_stained_glass_pane
setblock ~120 ~19 ~16 minecraft:gray_stained_glass_pane
