# Buildings 81..88
# 081 mixed_use style=balcony_block context=station_front facing=north
fill ~-66 ~-3 ~27 ~-58 ~-1 ~37 minecraft:stone
fill ~-66 ~0 ~27 ~-58 ~16 ~37 minecraft:bricks
fill ~-65 ~1 ~28 ~-59 ~15 ~36 minecraft:air
fill ~-65 ~4 ~28 ~-59 ~4 ~36 minecraft:smooth_stone
fill ~-65 ~8 ~28 ~-59 ~8 ~36 minecraft:smooth_stone
fill ~-65 ~12 ~28 ~-59 ~12 ~36 minecraft:smooth_stone
fill ~-64 ~2 ~27 ~-64 ~3 ~27 minecraft:gray_stained_glass
fill ~-64 ~2 ~37 ~-64 ~3 ~37 minecraft:light_gray_stained_glass
fill ~-61 ~2 ~27 ~-61 ~3 ~27 minecraft:gray_stained_glass
fill ~-61 ~2 ~37 ~-61 ~3 ~37 minecraft:light_gray_stained_glass
fill ~-66 ~2 ~29 ~-66 ~3 ~29 minecraft:gray_stained_glass
fill ~-58 ~2 ~29 ~-58 ~3 ~29 minecraft:light_gray_stained_glass
fill ~-66 ~2 ~32 ~-66 ~3 ~32 minecraft:gray_stained_glass
fill ~-58 ~2 ~32 ~-58 ~3 ~32 minecraft:light_gray_stained_glass
fill ~-66 ~2 ~35 ~-66 ~3 ~35 minecraft:gray_stained_glass
fill ~-58 ~2 ~35 ~-58 ~3 ~35 minecraft:light_gray_stained_glass
fill ~-64 ~6 ~27 ~-64 ~7 ~27 minecraft:gray_stained_glass
fill ~-64 ~6 ~37 ~-64 ~7 ~37 minecraft:light_gray_stained_glass
fill ~-61 ~6 ~27 ~-61 ~7 ~27 minecraft:gray_stained_glass
fill ~-61 ~6 ~37 ~-61 ~7 ~37 minecraft:light_gray_stained_glass
fill ~-66 ~6 ~29 ~-66 ~7 ~29 minecraft:gray_stained_glass
fill ~-58 ~6 ~29 ~-58 ~7 ~29 minecraft:light_gray_stained_glass
fill ~-66 ~6 ~32 ~-66 ~7 ~32 minecraft:gray_stained_glass
fill ~-58 ~6 ~32 ~-58 ~7 ~32 minecraft:light_gray_stained_glass
fill ~-66 ~6 ~35 ~-66 ~7 ~35 minecraft:gray_stained_glass
fill ~-58 ~6 ~35 ~-58 ~7 ~35 minecraft:light_gray_stained_glass
fill ~-64 ~10 ~27 ~-64 ~11 ~27 minecraft:gray_stained_glass
fill ~-64 ~10 ~37 ~-64 ~11 ~37 minecraft:light_gray_stained_glass
fill ~-61 ~10 ~27 ~-61 ~11 ~27 minecraft:gray_stained_glass
fill ~-61 ~10 ~37 ~-61 ~11 ~37 minecraft:light_gray_stained_glass
fill ~-66 ~10 ~29 ~-66 ~11 ~29 minecraft:gray_stained_glass
fill ~-58 ~10 ~29 ~-58 ~11 ~29 minecraft:light_gray_stained_glass
fill ~-66 ~10 ~32 ~-66 ~11 ~32 minecraft:gray_stained_glass
fill ~-58 ~10 ~32 ~-58 ~11 ~32 minecraft:light_gray_stained_glass
fill ~-66 ~10 ~35 ~-66 ~11 ~35 minecraft:gray_stained_glass
fill ~-58 ~10 ~35 ~-58 ~11 ~35 minecraft:light_gray_stained_glass
fill ~-64 ~14 ~27 ~-64 ~15 ~27 minecraft:gray_stained_glass
fill ~-64 ~14 ~37 ~-64 ~15 ~37 minecraft:light_gray_stained_glass
fill ~-61 ~14 ~27 ~-61 ~15 ~27 minecraft:gray_stained_glass
fill ~-61 ~14 ~37 ~-61 ~15 ~37 minecraft:light_gray_stained_glass
fill ~-66 ~14 ~29 ~-66 ~15 ~29 minecraft:gray_stained_glass
fill ~-58 ~14 ~29 ~-58 ~15 ~29 minecraft:light_gray_stained_glass
fill ~-66 ~14 ~32 ~-66 ~15 ~32 minecraft:gray_stained_glass
fill ~-58 ~14 ~32 ~-58 ~15 ~32 minecraft:light_gray_stained_glass
fill ~-66 ~14 ~35 ~-66 ~15 ~35 minecraft:gray_stained_glass
fill ~-58 ~14 ~35 ~-58 ~15 ~35 minecraft:light_gray_stained_glass
setblock ~-62 ~1 ~27 minecraft:iron_door[half=lower,facing=north]
setblock ~-62 ~2 ~27 minecraft:iron_door[half=upper,facing=north]
fill ~-64 ~4 ~26 ~-60 ~4 ~26 minecraft:smooth_stone_slab
fill ~-64 ~8 ~26 ~-60 ~8 ~26 minecraft:smooth_stone_slab
fill ~-64 ~12 ~26 ~-60 ~12 ~26 minecraft:smooth_stone_slab
fill ~-66 ~17 ~27 ~-58 ~17 ~37 minecraft:deepslate_tile_slab
fill ~-64 ~18 ~29 ~-62 ~19 ~31 minecraft:light_gray_concrete
setblock ~-61 ~18 ~30 minecraft:lightning_rod
fill ~-65 ~1 ~27 ~-65 ~7 ~27 doomsday_decoration:hollowbrick
fill ~-61 ~1 ~27 ~-61 ~7 ~27 doomsday_decoration:hollowbrick
fill ~-65 ~6 ~28 ~-59 ~16 ~36 minecraft:bricks
fill ~-64 ~7 ~29 ~-60 ~15 ~35 minecraft:air
setblock ~-64 ~3 ~27 minecraft:red_carpet
# 082 local_shop style=arcade_shop context=local_front facing=west
fill ~10 ~-3 ~92 ~21 ~-1 ~99 minecraft:stone
fill ~10 ~0 ~92 ~21 ~5 ~99 minecraft:mud_bricks
fill ~11 ~1 ~93 ~20 ~4 ~98 minecraft:air
fill ~11 ~4 ~93 ~20 ~4 ~98 minecraft:smooth_stone
fill ~12 ~2 ~92 ~12 ~3 ~92 minecraft:gray_stained_glass
fill ~12 ~2 ~99 ~12 ~3 ~99 minecraft:light_gray_stained_glass
fill ~15 ~2 ~92 ~15 ~3 ~92 minecraft:gray_stained_glass
fill ~15 ~2 ~99 ~15 ~3 ~99 minecraft:light_gray_stained_glass
fill ~18 ~2 ~92 ~18 ~3 ~92 minecraft:gray_stained_glass
fill ~18 ~2 ~99 ~18 ~3 ~99 minecraft:light_gray_stained_glass
fill ~10 ~2 ~94 ~10 ~3 ~94 minecraft:gray_stained_glass
fill ~21 ~2 ~94 ~21 ~3 ~94 minecraft:light_gray_stained_glass
fill ~10 ~2 ~97 ~10 ~3 ~97 minecraft:gray_stained_glass
fill ~21 ~2 ~97 ~21 ~3 ~97 minecraft:light_gray_stained_glass
setblock ~10 ~1 ~95 minecraft:iron_door[half=lower,facing=west]
setblock ~10 ~2 ~95 minecraft:iron_door[half=upper,facing=west]
fill ~10 ~1 ~93 ~10 ~3 ~98 minecraft:cyan_stained_glass
setblock ~10 ~1 ~95 minecraft:iron_door[half=lower,facing=west]
setblock ~10 ~2 ~95 minecraft:iron_door[half=upper,facing=west]
setblock ~9 ~3 ~95 minecraft:red_wool
fill ~10 ~4 ~93 ~10 ~4 ~98 minecraft:spruce_planks
fill ~10 ~6 ~92 ~21 ~6 ~99 minecraft:deepslate_tile_slab
fill ~10 ~1 ~93 ~10 ~5 ~93 minecraft:spruce_planks
fill ~10 ~1 ~97 ~10 ~5 ~97 minecraft:spruce_planks
setblock ~10 ~3 ~94 minecraft:red_carpet
# 083 midrise_housing style=mixed_facade context=collector_front facing=north
fill ~-22 ~-3 ~52 ~-14 ~-1 ~59 minecraft:stone
fill ~-22 ~0 ~52 ~-14 ~16 ~59 minecraft:bricks
fill ~-21 ~1 ~53 ~-15 ~15 ~58 minecraft:air
fill ~-21 ~4 ~53 ~-15 ~4 ~58 minecraft:smooth_stone
fill ~-21 ~8 ~53 ~-15 ~8 ~58 minecraft:smooth_stone
fill ~-21 ~12 ~53 ~-15 ~12 ~58 minecraft:smooth_stone
fill ~-20 ~2 ~52 ~-20 ~3 ~52 minecraft:gray_stained_glass
fill ~-20 ~2 ~59 ~-20 ~3 ~59 minecraft:light_gray_stained_glass
fill ~-17 ~2 ~52 ~-17 ~3 ~52 minecraft:gray_stained_glass
fill ~-17 ~2 ~59 ~-17 ~3 ~59 minecraft:light_gray_stained_glass
fill ~-22 ~2 ~54 ~-22 ~3 ~54 minecraft:gray_stained_glass
fill ~-14 ~2 ~54 ~-14 ~3 ~54 minecraft:light_gray_stained_glass
fill ~-22 ~2 ~57 ~-22 ~3 ~57 minecraft:gray_stained_glass
fill ~-14 ~2 ~57 ~-14 ~3 ~57 minecraft:light_gray_stained_glass
fill ~-20 ~6 ~52 ~-20 ~7 ~52 minecraft:gray_stained_glass
fill ~-20 ~6 ~59 ~-20 ~7 ~59 minecraft:light_gray_stained_glass
fill ~-17 ~6 ~52 ~-17 ~7 ~52 minecraft:gray_stained_glass
fill ~-17 ~6 ~59 ~-17 ~7 ~59 minecraft:light_gray_stained_glass
fill ~-22 ~6 ~54 ~-22 ~7 ~54 minecraft:gray_stained_glass
fill ~-14 ~6 ~54 ~-14 ~7 ~54 minecraft:light_gray_stained_glass
fill ~-22 ~6 ~57 ~-22 ~7 ~57 minecraft:gray_stained_glass
fill ~-14 ~6 ~57 ~-14 ~7 ~57 minecraft:light_gray_stained_glass
fill ~-20 ~10 ~52 ~-20 ~11 ~52 minecraft:gray_stained_glass
fill ~-20 ~10 ~59 ~-20 ~11 ~59 minecraft:light_gray_stained_glass
fill ~-17 ~10 ~52 ~-17 ~11 ~52 minecraft:gray_stained_glass
fill ~-17 ~10 ~59 ~-17 ~11 ~59 minecraft:light_gray_stained_glass
fill ~-22 ~10 ~54 ~-22 ~11 ~54 minecraft:gray_stained_glass
fill ~-14 ~10 ~54 ~-14 ~11 ~54 minecraft:light_gray_stained_glass
fill ~-22 ~10 ~57 ~-22 ~11 ~57 minecraft:gray_stained_glass
fill ~-14 ~10 ~57 ~-14 ~11 ~57 minecraft:light_gray_stained_glass
fill ~-20 ~14 ~52 ~-20 ~15 ~52 minecraft:gray_stained_glass
fill ~-20 ~14 ~59 ~-20 ~15 ~59 minecraft:light_gray_stained_glass
fill ~-17 ~14 ~52 ~-17 ~15 ~52 minecraft:gray_stained_glass
fill ~-17 ~14 ~59 ~-17 ~15 ~59 minecraft:light_gray_stained_glass
fill ~-22 ~14 ~54 ~-22 ~15 ~54 minecraft:gray_stained_glass
fill ~-14 ~14 ~54 ~-14 ~15 ~54 minecraft:light_gray_stained_glass
fill ~-22 ~14 ~57 ~-22 ~15 ~57 minecraft:gray_stained_glass
fill ~-14 ~14 ~57 ~-14 ~15 ~57 minecraft:light_gray_stained_glass
setblock ~-18 ~1 ~52 minecraft:iron_door[half=lower,facing=north]
setblock ~-18 ~2 ~52 minecraft:iron_door[half=upper,facing=north]
fill ~-22 ~17 ~52 ~-14 ~17 ~59 minecraft:deepslate_tile_slab
fill ~-21 ~1 ~52 ~-21 ~7 ~52 doomsday_decoration:hollowbrick
fill ~-17 ~1 ~52 ~-17 ~7 ~52 doomsday_decoration:hollowbrick
fill ~-20 ~18 ~54 ~-17 ~20 ~57 minecraft:light_gray_concrete
setblock ~-16 ~18 ~57 minecraft:lightning_rod
# 084 clinic style=balcony_block context=collector_front facing=east
fill ~-112 ~-3 ~-47 ~-104 ~-1 ~-37 minecraft:stone
fill ~-112 ~0 ~-47 ~-104 ~7 ~-37 minecraft:mud_bricks
fill ~-111 ~1 ~-46 ~-105 ~6 ~-38 minecraft:air
fill ~-111 ~4 ~-46 ~-105 ~4 ~-38 minecraft:smooth_stone
fill ~-110 ~2 ~-47 ~-110 ~3 ~-47 minecraft:gray_stained_glass
fill ~-110 ~2 ~-37 ~-110 ~3 ~-37 minecraft:light_gray_stained_glass
fill ~-107 ~2 ~-47 ~-107 ~3 ~-47 minecraft:gray_stained_glass
fill ~-107 ~2 ~-37 ~-107 ~3 ~-37 minecraft:light_gray_stained_glass
fill ~-112 ~2 ~-45 ~-112 ~3 ~-45 minecraft:gray_stained_glass
fill ~-104 ~2 ~-45 ~-104 ~3 ~-45 minecraft:light_gray_stained_glass
fill ~-112 ~2 ~-42 ~-112 ~3 ~-42 minecraft:gray_stained_glass
fill ~-104 ~2 ~-42 ~-104 ~3 ~-42 minecraft:light_gray_stained_glass
fill ~-112 ~2 ~-39 ~-112 ~3 ~-39 minecraft:gray_stained_glass
fill ~-104 ~2 ~-39 ~-104 ~3 ~-39 minecraft:light_gray_stained_glass
setblock ~-104 ~1 ~-42 minecraft:iron_door[half=lower,facing=east]
setblock ~-104 ~2 ~-42 minecraft:iron_door[half=upper,facing=east]
fill ~-103 ~4 ~-45 ~-103 ~4 ~-39 minecraft:smooth_stone_slab
fill ~-112 ~8 ~-47 ~-104 ~8 ~-37 minecraft:deepslate_tile_slab
fill ~-104 ~1 ~-46 ~-104 ~7 ~-46 minecraft:spruce_planks
fill ~-104 ~1 ~-42 ~-104 ~7 ~-42 minecraft:spruce_planks
fill ~-104 ~1 ~-38 ~-104 ~7 ~-38 minecraft:spruce_planks
# 085 local_shop style=corner_store context=local_front facing=south
fill ~-124 ~-3 ~68 ~-118 ~-1 ~79 minecraft:stone
fill ~-124 ~0 ~68 ~-118 ~9 ~79 minecraft:white_terracotta
fill ~-123 ~1 ~69 ~-119 ~8 ~78 minecraft:air
fill ~-123 ~4 ~69 ~-119 ~4 ~78 minecraft:smooth_stone
fill ~-123 ~8 ~69 ~-119 ~8 ~78 minecraft:smooth_stone
fill ~-122 ~2 ~68 ~-122 ~3 ~68 minecraft:gray_stained_glass
fill ~-122 ~2 ~79 ~-122 ~3 ~79 minecraft:light_gray_stained_glass
fill ~-124 ~2 ~70 ~-124 ~3 ~70 minecraft:gray_stained_glass
fill ~-118 ~2 ~70 ~-118 ~3 ~70 minecraft:light_gray_stained_glass
fill ~-124 ~2 ~73 ~-124 ~3 ~73 minecraft:gray_stained_glass
fill ~-118 ~2 ~73 ~-118 ~3 ~73 minecraft:light_gray_stained_glass
fill ~-124 ~2 ~76 ~-124 ~3 ~76 minecraft:gray_stained_glass
fill ~-118 ~2 ~76 ~-118 ~3 ~76 minecraft:light_gray_stained_glass
fill ~-122 ~6 ~68 ~-122 ~7 ~68 minecraft:gray_stained_glass
fill ~-122 ~6 ~79 ~-122 ~7 ~79 minecraft:light_gray_stained_glass
fill ~-124 ~6 ~70 ~-124 ~7 ~70 minecraft:gray_stained_glass
fill ~-118 ~6 ~70 ~-118 ~7 ~70 minecraft:light_gray_stained_glass
fill ~-124 ~6 ~73 ~-124 ~7 ~73 minecraft:gray_stained_glass
fill ~-118 ~6 ~73 ~-118 ~7 ~73 minecraft:light_gray_stained_glass
fill ~-124 ~6 ~76 ~-124 ~7 ~76 minecraft:gray_stained_glass
fill ~-118 ~6 ~76 ~-118 ~7 ~76 minecraft:light_gray_stained_glass
setblock ~-121 ~1 ~79 minecraft:iron_door[half=lower,facing=south]
setblock ~-121 ~2 ~79 minecraft:iron_door[half=upper,facing=south]
fill ~-123 ~1 ~79 ~-119 ~3 ~79 minecraft:cyan_stained_glass
setblock ~-121 ~1 ~79 minecraft:iron_door[half=lower,facing=south]
setblock ~-121 ~2 ~79 minecraft:iron_door[half=upper,facing=south]
setblock ~-121 ~3 ~80 minecraft:red_wool
fill ~-124 ~10 ~68 ~-118 ~10 ~79 minecraft:dark_oak_slab
fill ~-123 ~1 ~79 ~-123 ~7 ~79 minecraft:dark_oak_planks
fill ~-119 ~1 ~79 ~-119 ~7 ~79 minecraft:dark_oak_planks
setblock ~-122 ~3 ~79 minecraft:red_carpet
# 086 apartment style=mixed_facade context=waterfront_front facing=south
fill ~108 ~-3 ~18 ~115 ~-1 ~27 minecraft:stone
fill ~108 ~0 ~18 ~115 ~9 ~27 minecraft:bricks
fill ~109 ~1 ~19 ~114 ~8 ~26 minecraft:air
fill ~109 ~4 ~19 ~114 ~4 ~26 minecraft:smooth_stone
fill ~109 ~8 ~19 ~114 ~8 ~26 minecraft:smooth_stone
fill ~110 ~2 ~18 ~110 ~3 ~18 minecraft:gray_stained_glass
fill ~110 ~2 ~27 ~110 ~3 ~27 minecraft:light_gray_stained_glass
fill ~113 ~2 ~18 ~113 ~3 ~18 minecraft:gray_stained_glass
fill ~113 ~2 ~27 ~113 ~3 ~27 minecraft:light_gray_stained_glass
fill ~108 ~2 ~20 ~108 ~3 ~20 minecraft:gray_stained_glass
fill ~115 ~2 ~20 ~115 ~3 ~20 minecraft:light_gray_stained_glass
fill ~108 ~2 ~23 ~108 ~3 ~23 minecraft:gray_stained_glass
fill ~115 ~2 ~23 ~115 ~3 ~23 minecraft:light_gray_stained_glass
fill ~110 ~6 ~18 ~110 ~7 ~18 minecraft:gray_stained_glass
fill ~110 ~6 ~27 ~110 ~7 ~27 minecraft:light_gray_stained_glass
fill ~113 ~6 ~18 ~113 ~7 ~18 minecraft:gray_stained_glass
fill ~113 ~6 ~27 ~113 ~7 ~27 minecraft:light_gray_stained_glass
fill ~108 ~6 ~20 ~108 ~7 ~20 minecraft:gray_stained_glass
fill ~115 ~6 ~20 ~115 ~7 ~20 minecraft:light_gray_stained_glass
fill ~108 ~6 ~23 ~108 ~7 ~23 minecraft:gray_stained_glass
fill ~115 ~6 ~23 ~115 ~7 ~23 minecraft:light_gray_stained_glass
setblock ~111 ~1 ~27 minecraft:iron_door[half=lower,facing=south]
setblock ~111 ~2 ~27 minecraft:iron_door[half=upper,facing=south]
fill ~108 ~10 ~18 ~115 ~10 ~27 minecraft:deepslate_tile_slab
fill ~109 ~1 ~27 ~109 ~7 ~27 minecraft:weathered_cut_copper
fill ~113 ~1 ~27 ~113 ~7 ~27 minecraft:weathered_cut_copper
# 087 supermarket style=arcade_shop context=collector_front facing=east
fill ~-110 ~-3 ~-24 ~-104 ~-1 ~-20 minecraft:stone
fill ~-110 ~0 ~-24 ~-104 ~7 ~-20 minecraft:mud_bricks
fill ~-109 ~1 ~-23 ~-105 ~6 ~-21 minecraft:air
fill ~-109 ~4 ~-23 ~-105 ~4 ~-21 minecraft:smooth_stone
fill ~-108 ~2 ~-24 ~-108 ~3 ~-24 minecraft:gray_stained_glass
fill ~-108 ~2 ~-20 ~-108 ~3 ~-20 minecraft:light_gray_stained_glass
fill ~-110 ~2 ~-22 ~-110 ~3 ~-22 minecraft:gray_stained_glass
fill ~-104 ~2 ~-22 ~-104 ~3 ~-22 minecraft:light_gray_stained_glass
setblock ~-104 ~1 ~-22 minecraft:iron_door[half=lower,facing=east]
setblock ~-104 ~2 ~-22 minecraft:iron_door[half=upper,facing=east]
fill ~-104 ~1 ~-23 ~-104 ~3 ~-21 minecraft:cyan_stained_glass
setblock ~-104 ~1 ~-22 minecraft:iron_door[half=lower,facing=east]
setblock ~-104 ~2 ~-22 minecraft:iron_door[half=upper,facing=east]
setblock ~-103 ~3 ~-22 minecraft:red_wool
fill ~-104 ~4 ~-23 ~-104 ~4 ~-21 minecraft:spruce_planks
fill ~-110 ~8 ~-24 ~-104 ~8 ~-20 minecraft:deepslate_tile_slab
# 088 workshop style=industrial_shed context=local_front facing=east
fill ~-9 ~-3 ~94 ~0 ~-1 ~100 minecraft:stone
fill ~-9 ~0 ~94 ~0 ~11 ~100 minecraft:calcite
fill ~-8 ~1 ~95 ~-1 ~10 ~99 minecraft:air
fill ~-8 ~4 ~95 ~-1 ~4 ~99 minecraft:smooth_stone
fill ~-8 ~8 ~95 ~-1 ~8 ~99 minecraft:smooth_stone
fill ~-7 ~2 ~94 ~-7 ~3 ~94 minecraft:gray_stained_glass
fill ~-7 ~2 ~100 ~-7 ~3 ~100 minecraft:light_gray_stained_glass
fill ~-4 ~2 ~94 ~-4 ~3 ~94 minecraft:gray_stained_glass
fill ~-4 ~2 ~100 ~-4 ~3 ~100 minecraft:light_gray_stained_glass
fill ~-9 ~2 ~96 ~-9 ~3 ~96 minecraft:gray_stained_glass
fill ~0 ~2 ~96 ~0 ~3 ~96 minecraft:light_gray_stained_glass
fill ~-7 ~6 ~94 ~-7 ~7 ~94 minecraft:gray_stained_glass
fill ~-7 ~6 ~100 ~-7 ~7 ~100 minecraft:light_gray_stained_glass
fill ~-4 ~6 ~94 ~-4 ~7 ~94 minecraft:gray_stained_glass
fill ~-4 ~6 ~100 ~-4 ~7 ~100 minecraft:light_gray_stained_glass
fill ~-9 ~6 ~96 ~-9 ~7 ~96 minecraft:gray_stained_glass
fill ~0 ~6 ~96 ~0 ~7 ~96 minecraft:light_gray_stained_glass
setblock ~0 ~1 ~97 minecraft:iron_door[half=lower,facing=east]
setblock ~0 ~2 ~97 minecraft:iron_door[half=upper,facing=east]
fill ~0 ~1 ~96 ~0 ~4 ~98 minecraft:polished_blackstone
fill ~0 ~5 ~96 ~0 ~5 ~98 minecraft:light_blue_stained_glass
fill ~-7 ~13 ~96 ~-5 ~14 ~98 minecraft:iron_block
fill ~-9 ~12 ~94 ~0 ~12 ~100 minecraft:stone_brick_slab
fill ~0 ~1 ~95 ~0 ~7 ~95 minecraft:gray_concrete
fill ~0 ~1 ~99 ~0 ~7 ~99 minecraft:gray_concrete
