# Buildings 249..256
# 249 workshop style=stepped_house context=waterfront_front facing=west
fill ~106 ~-3 ~17 ~110 ~-1 ~22 minecraft:stone
fill ~106 ~0 ~17 ~110 ~9 ~22 minecraft:white_concrete
fill ~107 ~1 ~18 ~109 ~8 ~21 minecraft:air
fill ~107 ~4 ~18 ~109 ~4 ~21 minecraft:smooth_stone
fill ~107 ~8 ~18 ~109 ~8 ~21 minecraft:smooth_stone
fill ~108 ~2 ~17 ~108 ~3 ~17 minecraft:gray_stained_glass
fill ~108 ~2 ~22 ~108 ~3 ~22 minecraft:light_gray_stained_glass
fill ~106 ~2 ~19 ~106 ~3 ~19 minecraft:gray_stained_glass
fill ~110 ~2 ~19 ~110 ~3 ~19 minecraft:light_gray_stained_glass
fill ~108 ~6 ~17 ~108 ~7 ~17 minecraft:gray_stained_glass
fill ~108 ~6 ~22 ~108 ~7 ~22 minecraft:light_gray_stained_glass
fill ~106 ~6 ~19 ~106 ~7 ~19 minecraft:gray_stained_glass
fill ~110 ~6 ~19 ~110 ~7 ~19 minecraft:light_gray_stained_glass
setblock ~106 ~1 ~19 minecraft:iron_door[half=lower,facing=west]
setblock ~106 ~2 ~19 minecraft:iron_door[half=upper,facing=west]
fill ~106 ~10 ~17 ~110 ~10 ~22 minecraft:smooth_stone_slab
fill ~107 ~11 ~18 ~109 ~11 ~21 minecraft:smooth_stone_slab
setblock ~105 ~3 ~19 minecraft:dark_oak_slab[type=top]
fill ~108 ~11 ~19 ~109 ~12 ~21 minecraft:light_gray_concrete
setblock ~109 ~11 ~20 minecraft:lightning_rod
# 250 workshop style=rowhouse context=arterial_front facing=east
fill ~-18 ~-3 ~-5 ~-15 ~-1 ~0 minecraft:stone
fill ~-18 ~0 ~-5 ~-15 ~7 ~0 minecraft:light_gray_concrete
fill ~-17 ~1 ~-4 ~-16 ~6 ~-1 minecraft:air
fill ~-17 ~4 ~-4 ~-16 ~4 ~-1 minecraft:smooth_stone
fill ~-18 ~2 ~-3 ~-18 ~3 ~-3 minecraft:gray_stained_glass
fill ~-15 ~2 ~-3 ~-15 ~3 ~-3 minecraft:light_gray_stained_glass
setblock ~-15 ~1 ~-3 minecraft:iron_door[half=lower,facing=east]
setblock ~-15 ~2 ~-3 minecraft:iron_door[half=upper,facing=east]
fill ~-18 ~8 ~-5 ~-15 ~8 ~0 minecraft:smooth_stone_slab
fill ~-17 ~9 ~-4 ~-16 ~9 ~-1 minecraft:smooth_stone_slab
setblock ~-14 ~3 ~-3 minecraft:dark_oak_slab[type=top]
# 251 local_shop style=storefront context=local_front facing=north
fill ~64 ~-3 ~119 ~68 ~-1 ~124 minecraft:stone
fill ~64 ~0 ~119 ~68 ~7 ~124 minecraft:stone_bricks
fill ~65 ~1 ~120 ~67 ~6 ~123 minecraft:air
fill ~65 ~4 ~120 ~67 ~4 ~123 minecraft:smooth_stone
fill ~66 ~2 ~119 ~66 ~3 ~119 minecraft:gray_stained_glass
fill ~66 ~2 ~124 ~66 ~3 ~124 minecraft:light_gray_stained_glass
fill ~64 ~2 ~121 ~64 ~3 ~121 minecraft:gray_stained_glass
fill ~68 ~2 ~121 ~68 ~3 ~121 minecraft:light_gray_stained_glass
setblock ~66 ~1 ~119 minecraft:iron_door[half=lower,facing=north]
setblock ~66 ~2 ~119 minecraft:iron_door[half=upper,facing=north]
fill ~65 ~1 ~119 ~67 ~3 ~119 minecraft:cyan_stained_glass
setblock ~66 ~1 ~119 minecraft:iron_door[half=lower,facing=north]
setblock ~66 ~2 ~119 minecraft:iron_door[half=upper,facing=north]
setblock ~66 ~3 ~118 minecraft:red_wool
fill ~64 ~8 ~119 ~68 ~8 ~124 minecraft:stone_brick_slab
# 252 local_shop style=storefront context=back_block facing=east
fill ~-125 ~-3 ~104 ~-122 ~-1 ~109 minecraft:stone
fill ~-125 ~0 ~104 ~-122 ~9 ~109 minecraft:white_terracotta
fill ~-124 ~1 ~105 ~-123 ~8 ~108 minecraft:air
fill ~-124 ~4 ~105 ~-123 ~4 ~108 minecraft:smooth_stone
fill ~-124 ~8 ~105 ~-123 ~8 ~108 minecraft:smooth_stone
fill ~-125 ~2 ~106 ~-125 ~3 ~106 minecraft:gray_stained_glass
fill ~-122 ~2 ~106 ~-122 ~3 ~106 minecraft:light_gray_stained_glass
fill ~-125 ~6 ~106 ~-125 ~7 ~106 minecraft:gray_stained_glass
fill ~-122 ~6 ~106 ~-122 ~7 ~106 minecraft:light_gray_stained_glass
setblock ~-122 ~1 ~106 minecraft:iron_door[half=lower,facing=east]
setblock ~-122 ~2 ~106 minecraft:iron_door[half=upper,facing=east]
fill ~-122 ~1 ~105 ~-122 ~3 ~108 minecraft:cyan_stained_glass
setblock ~-122 ~1 ~106 minecraft:iron_door[half=lower,facing=east]
setblock ~-122 ~2 ~106 minecraft:iron_door[half=upper,facing=east]
setblock ~-121 ~3 ~106 minecraft:red_wool
fill ~-125 ~10 ~104 ~-122 ~10 ~109 minecraft:dark_oak_slab
fill ~-123 ~11 ~106 ~-123 ~12 ~108 minecraft:light_gray_concrete
setblock ~-123 ~11 ~107 minecraft:lightning_rod
# 253 row_house style=stepped_house context=local_front facing=east
fill ~7 ~-3 ~117 ~10 ~-1 ~123 minecraft:stone
fill ~7 ~0 ~117 ~10 ~7 ~123 minecraft:calcite
fill ~8 ~1 ~118 ~9 ~6 ~122 minecraft:air
fill ~8 ~4 ~118 ~9 ~4 ~122 minecraft:smooth_stone
fill ~7 ~2 ~119 ~7 ~3 ~119 minecraft:gray_stained_glass
fill ~10 ~2 ~119 ~10 ~3 ~119 minecraft:light_gray_stained_glass
setblock ~10 ~1 ~120 minecraft:iron_door[half=lower,facing=east]
setblock ~10 ~2 ~120 minecraft:iron_door[half=upper,facing=east]
fill ~7 ~8 ~117 ~10 ~8 ~123 minecraft:stone_brick_slab
fill ~8 ~9 ~118 ~9 ~9 ~122 minecraft:stone_brick_slab
setblock ~11 ~3 ~120 minecraft:dark_oak_slab[type=top]
# 254 row_house style=storefront context=collector_front facing=north
fill ~-4 ~-3 ~99 ~0 ~-1 ~104 minecraft:stone
fill ~-4 ~0 ~99 ~0 ~7 ~104 minecraft:calcite
fill ~-3 ~1 ~100 ~-1 ~6 ~103 minecraft:air
fill ~-3 ~4 ~100 ~-1 ~4 ~103 minecraft:smooth_stone
fill ~-2 ~2 ~99 ~-2 ~3 ~99 minecraft:gray_stained_glass
fill ~-2 ~2 ~104 ~-2 ~3 ~104 minecraft:light_gray_stained_glass
fill ~-4 ~2 ~101 ~-4 ~3 ~101 minecraft:gray_stained_glass
fill ~0 ~2 ~101 ~0 ~3 ~101 minecraft:light_gray_stained_glass
setblock ~-2 ~1 ~99 minecraft:iron_door[half=lower,facing=north]
setblock ~-2 ~2 ~99 minecraft:iron_door[half=upper,facing=north]
fill ~-3 ~1 ~99 ~-1 ~3 ~99 minecraft:cyan_stained_glass
setblock ~-2 ~1 ~99 minecraft:iron_door[half=lower,facing=north]
setblock ~-2 ~2 ~99 minecraft:iron_door[half=upper,facing=north]
setblock ~-2 ~3 ~98 minecraft:red_wool
fill ~-4 ~8 ~99 ~0 ~8 ~104 minecraft:stone_brick_slab
# 255 workshop style=rowhouse context=collector_front facing=east
fill ~-125 ~-3 ~18 ~-122 ~-1 ~23 minecraft:stone
fill ~-125 ~0 ~18 ~-122 ~5 ~23 minecraft:calcite
fill ~-124 ~1 ~19 ~-123 ~4 ~22 minecraft:air
fill ~-124 ~4 ~19 ~-123 ~4 ~22 minecraft:smooth_stone
fill ~-125 ~2 ~20 ~-125 ~3 ~20 minecraft:gray_stained_glass
fill ~-122 ~2 ~20 ~-122 ~3 ~20 minecraft:light_gray_stained_glass
setblock ~-122 ~1 ~20 minecraft:iron_door[half=lower,facing=east]
setblock ~-122 ~2 ~20 minecraft:iron_door[half=upper,facing=east]
fill ~-125 ~6 ~18 ~-122 ~6 ~23 minecraft:stone_brick_slab
fill ~-124 ~7 ~19 ~-123 ~7 ~22 minecraft:stone_brick_slab
setblock ~-121 ~3 ~20 minecraft:dark_oak_slab[type=top]
# 256 shop_house style=stepped_house context=collector_front facing=north
fill ~32 ~-3 ~31 ~35 ~-1 ~36 minecraft:stone
fill ~32 ~0 ~31 ~35 ~5 ~36 minecraft:bricks
fill ~33 ~1 ~32 ~34 ~4 ~35 minecraft:air
fill ~33 ~4 ~32 ~34 ~4 ~35 minecraft:smooth_stone
fill ~32 ~2 ~33 ~32 ~3 ~33 minecraft:gray_stained_glass
fill ~35 ~2 ~33 ~35 ~3 ~33 minecraft:light_gray_stained_glass
setblock ~34 ~1 ~31 minecraft:iron_door[half=lower,facing=north]
setblock ~34 ~2 ~31 minecraft:iron_door[half=upper,facing=north]
fill ~32 ~6 ~31 ~35 ~6 ~36 minecraft:deepslate_tile_slab
fill ~33 ~7 ~32 ~34 ~7 ~35 minecraft:deepslate_tile_slab
setblock ~34 ~3 ~30 minecraft:dark_oak_slab[type=top]
