# Buildings 1..8
# 001 lowrise_housing style=japanese_house context=back_block facing=north
fill ~-17 ~-3 ~39 ~-7 ~-1 ~48 minecraft:stone
fill ~-17 ~0 ~39 ~-7 ~20 ~48 minecraft:bricks
fill ~-16 ~1 ~40 ~-8 ~19 ~47 minecraft:air
fill ~-16 ~4 ~40 ~-8 ~4 ~47 minecraft:smooth_stone
fill ~-16 ~8 ~40 ~-8 ~8 ~47 minecraft:smooth_stone
fill ~-16 ~12 ~40 ~-8 ~12 ~47 minecraft:smooth_stone
fill ~-16 ~16 ~40 ~-8 ~16 ~47 minecraft:smooth_stone
fill ~-15 ~2 ~39 ~-15 ~3 ~39 minecraft:gray_stained_glass
fill ~-15 ~2 ~48 ~-15 ~3 ~48 minecraft:light_gray_stained_glass
fill ~-12 ~2 ~39 ~-12 ~3 ~39 minecraft:gray_stained_glass
fill ~-12 ~2 ~48 ~-12 ~3 ~48 minecraft:light_gray_stained_glass
fill ~-9 ~2 ~39 ~-9 ~3 ~39 minecraft:gray_stained_glass
fill ~-9 ~2 ~48 ~-9 ~3 ~48 minecraft:light_gray_stained_glass
fill ~-17 ~2 ~41 ~-17 ~3 ~41 minecraft:gray_stained_glass
fill ~-7 ~2 ~41 ~-7 ~3 ~41 minecraft:light_gray_stained_glass
fill ~-17 ~2 ~44 ~-17 ~3 ~44 minecraft:gray_stained_glass
fill ~-7 ~2 ~44 ~-7 ~3 ~44 minecraft:light_gray_stained_glass
fill ~-15 ~6 ~39 ~-15 ~7 ~39 minecraft:gray_stained_glass
fill ~-15 ~6 ~48 ~-15 ~7 ~48 minecraft:light_gray_stained_glass
fill ~-12 ~6 ~39 ~-12 ~7 ~39 minecraft:gray_stained_glass
fill ~-12 ~6 ~48 ~-12 ~7 ~48 minecraft:light_gray_stained_glass
fill ~-9 ~6 ~39 ~-9 ~7 ~39 minecraft:gray_stained_glass
fill ~-9 ~6 ~48 ~-9 ~7 ~48 minecraft:light_gray_stained_glass
fill ~-17 ~6 ~41 ~-17 ~7 ~41 minecraft:gray_stained_glass
fill ~-7 ~6 ~41 ~-7 ~7 ~41 minecraft:light_gray_stained_glass
fill ~-17 ~6 ~44 ~-17 ~7 ~44 minecraft:gray_stained_glass
fill ~-7 ~6 ~44 ~-7 ~7 ~44 minecraft:light_gray_stained_glass
fill ~-15 ~10 ~39 ~-15 ~11 ~39 minecraft:gray_stained_glass
fill ~-15 ~10 ~48 ~-15 ~11 ~48 minecraft:light_gray_stained_glass
fill ~-12 ~10 ~39 ~-12 ~11 ~39 minecraft:gray_stained_glass
fill ~-12 ~10 ~48 ~-12 ~11 ~48 minecraft:light_gray_stained_glass
fill ~-9 ~10 ~39 ~-9 ~11 ~39 minecraft:gray_stained_glass
fill ~-9 ~10 ~48 ~-9 ~11 ~48 minecraft:light_gray_stained_glass
fill ~-17 ~10 ~41 ~-17 ~11 ~41 minecraft:gray_stained_glass
fill ~-7 ~10 ~41 ~-7 ~11 ~41 minecraft:light_gray_stained_glass
fill ~-17 ~10 ~44 ~-17 ~11 ~44 minecraft:gray_stained_glass
fill ~-7 ~10 ~44 ~-7 ~11 ~44 minecraft:light_gray_stained_glass
fill ~-15 ~14 ~39 ~-15 ~15 ~39 minecraft:gray_stained_glass
fill ~-15 ~14 ~48 ~-15 ~15 ~48 minecraft:light_gray_stained_glass
fill ~-12 ~14 ~39 ~-12 ~15 ~39 minecraft:gray_stained_glass
fill ~-12 ~14 ~48 ~-12 ~15 ~48 minecraft:light_gray_stained_glass
fill ~-9 ~14 ~39 ~-9 ~15 ~39 minecraft:gray_stained_glass
fill ~-9 ~14 ~48 ~-9 ~15 ~48 minecraft:light_gray_stained_glass
fill ~-17 ~14 ~41 ~-17 ~15 ~41 minecraft:gray_stained_glass
fill ~-7 ~14 ~41 ~-7 ~15 ~41 minecraft:light_gray_stained_glass
fill ~-17 ~14 ~44 ~-17 ~15 ~44 minecraft:gray_stained_glass
fill ~-7 ~14 ~44 ~-7 ~15 ~44 minecraft:light_gray_stained_glass
fill ~-15 ~18 ~39 ~-15 ~19 ~39 minecraft:gray_stained_glass
fill ~-15 ~18 ~48 ~-15 ~19 ~48 minecraft:light_gray_stained_glass
fill ~-12 ~18 ~39 ~-12 ~19 ~39 minecraft:gray_stained_glass
fill ~-12 ~18 ~48 ~-12 ~19 ~48 minecraft:light_gray_stained_glass
fill ~-9 ~18 ~39 ~-9 ~19 ~39 minecraft:gray_stained_glass
fill ~-9 ~18 ~48 ~-9 ~19 ~48 minecraft:light_gray_stained_glass
fill ~-17 ~18 ~41 ~-17 ~19 ~41 minecraft:gray_stained_glass
fill ~-7 ~18 ~41 ~-7 ~19 ~41 minecraft:light_gray_stained_glass
fill ~-17 ~18 ~44 ~-17 ~19 ~44 minecraft:gray_stained_glass
fill ~-7 ~18 ~44 ~-7 ~19 ~44 minecraft:light_gray_stained_glass
setblock ~-12 ~1 ~39 minecraft:iron_door[half=lower,facing=north]
setblock ~-12 ~2 ~39 minecraft:iron_door[half=upper,facing=north]
fill ~-17 ~21 ~39 ~-7 ~21 ~48 minecraft:deepslate_tile_slab
fill ~-16 ~22 ~40 ~-8 ~22 ~47 minecraft:deepslate_tile_slab
setblock ~-12 ~3 ~38 minecraft:dark_oak_slab[type=top]
# 002 midrise_housing style=balcony_block context=collector_front facing=south
fill ~-31 ~-3 ~5 ~-20 ~-1 ~19 minecraft:stone
fill ~-31 ~0 ~5 ~-20 ~16 ~19 minecraft:white_terracotta
fill ~-30 ~1 ~6 ~-21 ~15 ~18 minecraft:air
fill ~-30 ~4 ~6 ~-21 ~4 ~18 minecraft:smooth_stone
fill ~-30 ~8 ~6 ~-21 ~8 ~18 minecraft:smooth_stone
fill ~-30 ~12 ~6 ~-21 ~12 ~18 minecraft:smooth_stone
fill ~-29 ~2 ~5 ~-29 ~3 ~5 minecraft:gray_stained_glass
fill ~-29 ~2 ~19 ~-29 ~3 ~19 minecraft:light_gray_stained_glass
fill ~-26 ~2 ~5 ~-26 ~3 ~5 minecraft:gray_stained_glass
fill ~-26 ~2 ~19 ~-26 ~3 ~19 minecraft:light_gray_stained_glass
fill ~-23 ~2 ~5 ~-23 ~3 ~5 minecraft:gray_stained_glass
fill ~-23 ~2 ~19 ~-23 ~3 ~19 minecraft:light_gray_stained_glass
fill ~-31 ~2 ~7 ~-31 ~3 ~7 minecraft:gray_stained_glass
fill ~-20 ~2 ~7 ~-20 ~3 ~7 minecraft:light_gray_stained_glass
fill ~-31 ~2 ~10 ~-31 ~3 ~10 minecraft:gray_stained_glass
fill ~-20 ~2 ~10 ~-20 ~3 ~10 minecraft:light_gray_stained_glass
fill ~-31 ~2 ~13 ~-31 ~3 ~13 minecraft:gray_stained_glass
fill ~-20 ~2 ~13 ~-20 ~3 ~13 minecraft:light_gray_stained_glass
fill ~-31 ~2 ~16 ~-31 ~3 ~16 minecraft:gray_stained_glass
fill ~-20 ~2 ~16 ~-20 ~3 ~16 minecraft:light_gray_stained_glass
fill ~-29 ~6 ~5 ~-29 ~7 ~5 minecraft:gray_stained_glass
fill ~-29 ~6 ~19 ~-29 ~7 ~19 minecraft:light_gray_stained_glass
fill ~-26 ~6 ~5 ~-26 ~7 ~5 minecraft:gray_stained_glass
fill ~-26 ~6 ~19 ~-26 ~7 ~19 minecraft:light_gray_stained_glass
fill ~-23 ~6 ~5 ~-23 ~7 ~5 minecraft:gray_stained_glass
fill ~-23 ~6 ~19 ~-23 ~7 ~19 minecraft:light_gray_stained_glass
fill ~-31 ~6 ~7 ~-31 ~7 ~7 minecraft:gray_stained_glass
fill ~-20 ~6 ~7 ~-20 ~7 ~7 minecraft:light_gray_stained_glass
fill ~-31 ~6 ~10 ~-31 ~7 ~10 minecraft:gray_stained_glass
fill ~-20 ~6 ~10 ~-20 ~7 ~10 minecraft:light_gray_stained_glass
fill ~-31 ~6 ~13 ~-31 ~7 ~13 minecraft:gray_stained_glass
fill ~-20 ~6 ~13 ~-20 ~7 ~13 minecraft:light_gray_stained_glass
fill ~-31 ~6 ~16 ~-31 ~7 ~16 minecraft:gray_stained_glass
fill ~-20 ~6 ~16 ~-20 ~7 ~16 minecraft:light_gray_stained_glass
fill ~-29 ~10 ~5 ~-29 ~11 ~5 minecraft:gray_stained_glass
fill ~-29 ~10 ~19 ~-29 ~11 ~19 minecraft:light_gray_stained_glass
fill ~-26 ~10 ~5 ~-26 ~11 ~5 minecraft:gray_stained_glass
fill ~-26 ~10 ~19 ~-26 ~11 ~19 minecraft:light_gray_stained_glass
fill ~-23 ~10 ~5 ~-23 ~11 ~5 minecraft:gray_stained_glass
fill ~-23 ~10 ~19 ~-23 ~11 ~19 minecraft:light_gray_stained_glass
fill ~-31 ~10 ~7 ~-31 ~11 ~7 minecraft:gray_stained_glass
fill ~-20 ~10 ~7 ~-20 ~11 ~7 minecraft:light_gray_stained_glass
fill ~-31 ~10 ~10 ~-31 ~11 ~10 minecraft:gray_stained_glass
fill ~-20 ~10 ~10 ~-20 ~11 ~10 minecraft:light_gray_stained_glass
fill ~-31 ~10 ~13 ~-31 ~11 ~13 minecraft:gray_stained_glass
fill ~-20 ~10 ~13 ~-20 ~11 ~13 minecraft:light_gray_stained_glass
fill ~-31 ~10 ~16 ~-31 ~11 ~16 minecraft:gray_stained_glass
fill ~-20 ~10 ~16 ~-20 ~11 ~16 minecraft:light_gray_stained_glass
fill ~-29 ~14 ~5 ~-29 ~15 ~5 minecraft:gray_stained_glass
fill ~-29 ~14 ~19 ~-29 ~15 ~19 minecraft:light_gray_stained_glass
fill ~-26 ~14 ~5 ~-26 ~15 ~5 minecraft:gray_stained_glass
fill ~-26 ~14 ~19 ~-26 ~15 ~19 minecraft:light_gray_stained_glass
fill ~-23 ~14 ~5 ~-23 ~15 ~5 minecraft:gray_stained_glass
fill ~-23 ~14 ~19 ~-23 ~15 ~19 minecraft:light_gray_stained_glass
fill ~-31 ~14 ~7 ~-31 ~15 ~7 minecraft:gray_stained_glass
fill ~-20 ~14 ~7 ~-20 ~15 ~7 minecraft:light_gray_stained_glass
fill ~-31 ~14 ~10 ~-31 ~15 ~10 minecraft:gray_stained_glass
fill ~-20 ~14 ~10 ~-20 ~15 ~10 minecraft:light_gray_stained_glass
fill ~-31 ~14 ~13 ~-31 ~15 ~13 minecraft:gray_stained_glass
fill ~-20 ~14 ~13 ~-20 ~15 ~13 minecraft:light_gray_stained_glass
fill ~-31 ~14 ~16 ~-31 ~15 ~16 minecraft:gray_stained_glass
fill ~-20 ~14 ~16 ~-20 ~15 ~16 minecraft:light_gray_stained_glass
setblock ~-26 ~1 ~19 minecraft:iron_door[half=lower,facing=south]
setblock ~-26 ~2 ~19 minecraft:iron_door[half=upper,facing=south]
fill ~-29 ~4 ~20 ~-22 ~4 ~20 minecraft:smooth_stone_slab
fill ~-29 ~8 ~20 ~-22 ~8 ~20 minecraft:smooth_stone_slab
fill ~-29 ~12 ~20 ~-22 ~12 ~20 minecraft:smooth_stone_slab
fill ~-31 ~17 ~5 ~-20 ~17 ~19 minecraft:stone_brick_slab
fill ~-22 ~14 ~17 ~-20 ~18 ~19 minecraft:air
setblock ~-22 ~14 ~17 minecraft:cobweb
# 003 lowrise_housing style=japanese_house context=back_block facing=north
fill ~-103 ~-3 ~112 ~-93 ~-1 ~119 minecraft:stone
fill ~-103 ~0 ~112 ~-93 ~5 ~119 minecraft:white_terracotta
fill ~-102 ~1 ~113 ~-94 ~4 ~118 minecraft:air
fill ~-102 ~4 ~113 ~-94 ~4 ~118 minecraft:smooth_stone
fill ~-101 ~2 ~112 ~-101 ~3 ~112 minecraft:gray_stained_glass
fill ~-101 ~2 ~119 ~-101 ~3 ~119 minecraft:light_gray_stained_glass
fill ~-98 ~2 ~112 ~-98 ~3 ~112 minecraft:gray_stained_glass
fill ~-98 ~2 ~119 ~-98 ~3 ~119 minecraft:light_gray_stained_glass
fill ~-95 ~2 ~112 ~-95 ~3 ~112 minecraft:gray_stained_glass
fill ~-95 ~2 ~119 ~-95 ~3 ~119 minecraft:light_gray_stained_glass
fill ~-103 ~2 ~114 ~-103 ~3 ~114 minecraft:gray_stained_glass
fill ~-93 ~2 ~114 ~-93 ~3 ~114 minecraft:light_gray_stained_glass
fill ~-103 ~2 ~117 ~-103 ~3 ~117 minecraft:gray_stained_glass
fill ~-93 ~2 ~117 ~-93 ~3 ~117 minecraft:light_gray_stained_glass
setblock ~-98 ~1 ~112 minecraft:iron_door[half=lower,facing=north]
setblock ~-98 ~2 ~112 minecraft:iron_door[half=upper,facing=north]
fill ~-103 ~6 ~112 ~-93 ~6 ~119 minecraft:dark_oak_slab
fill ~-102 ~7 ~113 ~-94 ~7 ~118 minecraft:dark_oak_slab
setblock ~-98 ~3 ~111 minecraft:dark_oak_slab[type=top]
# 004 row_house style=japanese_house context=back_block facing=west
fill ~-39 ~-3 ~43 ~-27 ~-1 ~54 minecraft:stone
fill ~-39 ~0 ~43 ~-27 ~8 ~54 minecraft:light_gray_concrete
fill ~-38 ~1 ~44 ~-28 ~7 ~53 minecraft:air
fill ~-38 ~4 ~44 ~-28 ~4 ~53 minecraft:smooth_stone
fill ~-37 ~2 ~43 ~-37 ~3 ~43 minecraft:gray_stained_glass
fill ~-37 ~2 ~54 ~-37 ~3 ~54 minecraft:light_gray_stained_glass
fill ~-34 ~2 ~43 ~-34 ~3 ~43 minecraft:gray_stained_glass
fill ~-34 ~2 ~54 ~-34 ~3 ~54 minecraft:light_gray_stained_glass
fill ~-31 ~2 ~43 ~-31 ~3 ~43 minecraft:gray_stained_glass
fill ~-31 ~2 ~54 ~-31 ~3 ~54 minecraft:light_gray_stained_glass
fill ~-39 ~2 ~45 ~-39 ~3 ~45 minecraft:gray_stained_glass
fill ~-27 ~2 ~45 ~-27 ~3 ~45 minecraft:light_gray_stained_glass
fill ~-39 ~2 ~48 ~-39 ~3 ~48 minecraft:gray_stained_glass
fill ~-27 ~2 ~48 ~-27 ~3 ~48 minecraft:light_gray_stained_glass
fill ~-39 ~2 ~51 ~-39 ~3 ~51 minecraft:gray_stained_glass
fill ~-27 ~2 ~51 ~-27 ~3 ~51 minecraft:light_gray_stained_glass
fill ~-37 ~6 ~43 ~-37 ~7 ~43 minecraft:gray_stained_glass
fill ~-37 ~6 ~54 ~-37 ~7 ~54 minecraft:light_gray_stained_glass
fill ~-34 ~6 ~43 ~-34 ~7 ~43 minecraft:gray_stained_glass
fill ~-34 ~6 ~54 ~-34 ~7 ~54 minecraft:light_gray_stained_glass
fill ~-31 ~6 ~43 ~-31 ~7 ~43 minecraft:gray_stained_glass
fill ~-31 ~6 ~54 ~-31 ~7 ~54 minecraft:light_gray_stained_glass
fill ~-39 ~6 ~45 ~-39 ~7 ~45 minecraft:gray_stained_glass
fill ~-27 ~6 ~45 ~-27 ~7 ~45 minecraft:light_gray_stained_glass
fill ~-39 ~6 ~48 ~-39 ~7 ~48 minecraft:gray_stained_glass
fill ~-27 ~6 ~48 ~-27 ~7 ~48 minecraft:light_gray_stained_glass
fill ~-39 ~6 ~51 ~-39 ~7 ~51 minecraft:gray_stained_glass
fill ~-27 ~6 ~51 ~-27 ~7 ~51 minecraft:light_gray_stained_glass
setblock ~-39 ~1 ~48 minecraft:iron_door[half=lower,facing=west]
setblock ~-39 ~2 ~48 minecraft:iron_door[half=upper,facing=west]
fill ~-39 ~9 ~43 ~-27 ~9 ~54 minecraft:smooth_stone_slab
fill ~-38 ~10 ~44 ~-28 ~10 ~53 minecraft:smooth_stone_slab
setblock ~-40 ~3 ~48 minecraft:dark_oak_slab[type=top]
fill ~-29 ~6 ~52 ~-27 ~10 ~54 minecraft:air
setblock ~-29 ~6 ~52 minecraft:cobweb
# 005 utility style=loading_bay context=local_front facing=west
fill ~-101 ~-3 ~-121 ~-82 ~-1 ~-112 minecraft:stone
fill ~-101 ~0 ~-121 ~-82 ~6 ~-112 minecraft:stone_bricks
fill ~-100 ~1 ~-120 ~-83 ~5 ~-113 minecraft:air
fill ~-100 ~4 ~-120 ~-83 ~4 ~-113 minecraft:smooth_stone
fill ~-99 ~2 ~-121 ~-99 ~3 ~-121 minecraft:gray_stained_glass
fill ~-99 ~2 ~-112 ~-99 ~3 ~-112 minecraft:light_gray_stained_glass
fill ~-96 ~2 ~-121 ~-96 ~3 ~-121 minecraft:gray_stained_glass
fill ~-96 ~2 ~-112 ~-96 ~3 ~-112 minecraft:light_gray_stained_glass
fill ~-93 ~2 ~-121 ~-93 ~3 ~-121 minecraft:gray_stained_glass
fill ~-93 ~2 ~-112 ~-93 ~3 ~-112 minecraft:light_gray_stained_glass
fill ~-90 ~2 ~-121 ~-90 ~3 ~-121 minecraft:gray_stained_glass
fill ~-90 ~2 ~-112 ~-90 ~3 ~-112 minecraft:light_gray_stained_glass
fill ~-87 ~2 ~-121 ~-87 ~3 ~-121 minecraft:gray_stained_glass
fill ~-87 ~2 ~-112 ~-87 ~3 ~-112 minecraft:light_gray_stained_glass
fill ~-84 ~2 ~-121 ~-84 ~3 ~-121 minecraft:gray_stained_glass
fill ~-84 ~2 ~-112 ~-84 ~3 ~-112 minecraft:light_gray_stained_glass
fill ~-101 ~2 ~-119 ~-101 ~3 ~-119 minecraft:gray_stained_glass
fill ~-82 ~2 ~-119 ~-82 ~3 ~-119 minecraft:light_gray_stained_glass
fill ~-101 ~2 ~-116 ~-101 ~3 ~-116 minecraft:gray_stained_glass
fill ~-82 ~2 ~-116 ~-82 ~3 ~-116 minecraft:light_gray_stained_glass
setblock ~-101 ~1 ~-117 minecraft:iron_door[half=lower,facing=west]
setblock ~-101 ~2 ~-117 minecraft:iron_door[half=upper,facing=west]
fill ~-101 ~1 ~-119 ~-101 ~4 ~-114 minecraft:polished_blackstone
fill ~-101 ~5 ~-119 ~-101 ~5 ~-114 minecraft:light_blue_stained_glass
fill ~-99 ~8 ~-119 ~-97 ~9 ~-117 minecraft:iron_block
fill ~-101 ~7 ~-121 ~-82 ~7 ~-112 minecraft:smooth_stone_slab
# 006 lowrise_housing style=rowhouse context=back_block facing=west
fill ~-41 ~-3 ~57 ~-32 ~-1 ~68 minecraft:stone
fill ~-41 ~0 ~57 ~-32 ~16 ~68 minecraft:light_gray_concrete
fill ~-40 ~1 ~58 ~-33 ~15 ~67 minecraft:air
fill ~-40 ~4 ~58 ~-33 ~4 ~67 minecraft:smooth_stone
fill ~-40 ~8 ~58 ~-33 ~8 ~67 minecraft:smooth_stone
fill ~-40 ~12 ~58 ~-33 ~12 ~67 minecraft:smooth_stone
fill ~-39 ~2 ~57 ~-39 ~3 ~57 minecraft:gray_stained_glass
fill ~-39 ~2 ~68 ~-39 ~3 ~68 minecraft:light_gray_stained_glass
fill ~-36 ~2 ~57 ~-36 ~3 ~57 minecraft:gray_stained_glass
fill ~-36 ~2 ~68 ~-36 ~3 ~68 minecraft:light_gray_stained_glass
fill ~-41 ~2 ~59 ~-41 ~3 ~59 minecraft:gray_stained_glass
fill ~-32 ~2 ~59 ~-32 ~3 ~59 minecraft:light_gray_stained_glass
fill ~-41 ~2 ~62 ~-41 ~3 ~62 minecraft:gray_stained_glass
fill ~-32 ~2 ~62 ~-32 ~3 ~62 minecraft:light_gray_stained_glass
fill ~-41 ~2 ~65 ~-41 ~3 ~65 minecraft:gray_stained_glass
fill ~-32 ~2 ~65 ~-32 ~3 ~65 minecraft:light_gray_stained_glass
fill ~-39 ~6 ~57 ~-39 ~7 ~57 minecraft:gray_stained_glass
fill ~-39 ~6 ~68 ~-39 ~7 ~68 minecraft:light_gray_stained_glass
fill ~-36 ~6 ~57 ~-36 ~7 ~57 minecraft:gray_stained_glass
fill ~-36 ~6 ~68 ~-36 ~7 ~68 minecraft:light_gray_stained_glass
fill ~-41 ~6 ~59 ~-41 ~7 ~59 minecraft:gray_stained_glass
fill ~-32 ~6 ~59 ~-32 ~7 ~59 minecraft:light_gray_stained_glass
fill ~-41 ~6 ~62 ~-41 ~7 ~62 minecraft:gray_stained_glass
fill ~-32 ~6 ~62 ~-32 ~7 ~62 minecraft:light_gray_stained_glass
fill ~-41 ~6 ~65 ~-41 ~7 ~65 minecraft:gray_stained_glass
fill ~-32 ~6 ~65 ~-32 ~7 ~65 minecraft:light_gray_stained_glass
fill ~-39 ~10 ~57 ~-39 ~11 ~57 minecraft:gray_stained_glass
fill ~-39 ~10 ~68 ~-39 ~11 ~68 minecraft:light_gray_stained_glass
fill ~-36 ~10 ~57 ~-36 ~11 ~57 minecraft:gray_stained_glass
fill ~-36 ~10 ~68 ~-36 ~11 ~68 minecraft:light_gray_stained_glass
fill ~-41 ~10 ~59 ~-41 ~11 ~59 minecraft:gray_stained_glass
fill ~-32 ~10 ~59 ~-32 ~11 ~59 minecraft:light_gray_stained_glass
fill ~-41 ~10 ~62 ~-41 ~11 ~62 minecraft:gray_stained_glass
fill ~-32 ~10 ~62 ~-32 ~11 ~62 minecraft:light_gray_stained_glass
fill ~-41 ~10 ~65 ~-41 ~11 ~65 minecraft:gray_stained_glass
fill ~-32 ~10 ~65 ~-32 ~11 ~65 minecraft:light_gray_stained_glass
fill ~-39 ~14 ~57 ~-39 ~15 ~57 minecraft:gray_stained_glass
fill ~-39 ~14 ~68 ~-39 ~15 ~68 minecraft:light_gray_stained_glass
fill ~-36 ~14 ~57 ~-36 ~15 ~57 minecraft:gray_stained_glass
fill ~-36 ~14 ~68 ~-36 ~15 ~68 minecraft:light_gray_stained_glass
fill ~-41 ~14 ~59 ~-41 ~15 ~59 minecraft:gray_stained_glass
fill ~-32 ~14 ~59 ~-32 ~15 ~59 minecraft:light_gray_stained_glass
fill ~-41 ~14 ~62 ~-41 ~15 ~62 minecraft:gray_stained_glass
fill ~-32 ~14 ~62 ~-32 ~15 ~62 minecraft:light_gray_stained_glass
fill ~-41 ~14 ~65 ~-41 ~15 ~65 minecraft:gray_stained_glass
fill ~-32 ~14 ~65 ~-32 ~15 ~65 minecraft:light_gray_stained_glass
setblock ~-41 ~1 ~62 minecraft:iron_door[half=lower,facing=west]
setblock ~-41 ~2 ~62 minecraft:iron_door[half=upper,facing=west]
fill ~-41 ~17 ~57 ~-32 ~17 ~68 minecraft:smooth_stone_slab
fill ~-40 ~18 ~58 ~-33 ~18 ~67 minecraft:smooth_stone_slab
setblock ~-42 ~3 ~62 minecraft:dark_oak_slab[type=top]
fill ~-39 ~18 ~59 ~-37 ~19 ~61 minecraft:light_gray_concrete
setblock ~-36 ~18 ~60 minecraft:lightning_rod
# 007 detached_house style=rowhouse context=back_block facing=north
fill ~-90 ~-3 ~115 ~-83 ~-1 ~121 minecraft:stone
fill ~-90 ~0 ~115 ~-83 ~11 ~121 minecraft:mud_bricks
fill ~-89 ~1 ~116 ~-84 ~10 ~120 minecraft:air
fill ~-89 ~4 ~116 ~-84 ~4 ~120 minecraft:smooth_stone
fill ~-89 ~8 ~116 ~-84 ~8 ~120 minecraft:smooth_stone
fill ~-88 ~2 ~115 ~-88 ~3 ~115 minecraft:gray_stained_glass
fill ~-88 ~2 ~121 ~-88 ~3 ~121 minecraft:light_gray_stained_glass
fill ~-85 ~2 ~115 ~-85 ~3 ~115 minecraft:gray_stained_glass
fill ~-85 ~2 ~121 ~-85 ~3 ~121 minecraft:light_gray_stained_glass
fill ~-90 ~2 ~117 ~-90 ~3 ~117 minecraft:gray_stained_glass
fill ~-83 ~2 ~117 ~-83 ~3 ~117 minecraft:light_gray_stained_glass
fill ~-88 ~6 ~115 ~-88 ~7 ~115 minecraft:gray_stained_glass
fill ~-88 ~6 ~121 ~-88 ~7 ~121 minecraft:light_gray_stained_glass
fill ~-85 ~6 ~115 ~-85 ~7 ~115 minecraft:gray_stained_glass
fill ~-85 ~6 ~121 ~-85 ~7 ~121 minecraft:light_gray_stained_glass
fill ~-90 ~6 ~117 ~-90 ~7 ~117 minecraft:gray_stained_glass
fill ~-83 ~6 ~117 ~-83 ~7 ~117 minecraft:light_gray_stained_glass
setblock ~-87 ~1 ~115 minecraft:iron_door[half=lower,facing=north]
setblock ~-87 ~2 ~115 minecraft:iron_door[half=upper,facing=north]
fill ~-90 ~12 ~115 ~-83 ~12 ~121 minecraft:deepslate_tile_slab
fill ~-89 ~13 ~116 ~-84 ~13 ~120 minecraft:deepslate_tile_slab
setblock ~-87 ~3 ~114 minecraft:dark_oak_slab[type=top]
# 008 lowrise_housing style=rowhouse context=local_front facing=east
fill ~-3 ~-3 ~107 ~4 ~-1 ~113 minecraft:stone
fill ~-3 ~0 ~107 ~4 ~9 ~113 minecraft:mud_bricks
fill ~-2 ~1 ~108 ~3 ~8 ~112 minecraft:air
fill ~-2 ~4 ~108 ~3 ~4 ~112 minecraft:smooth_stone
fill ~-2 ~8 ~108 ~3 ~8 ~112 minecraft:smooth_stone
fill ~-1 ~2 ~107 ~-1 ~3 ~107 minecraft:gray_stained_glass
fill ~-1 ~2 ~113 ~-1 ~3 ~113 minecraft:light_gray_stained_glass
fill ~2 ~2 ~107 ~2 ~3 ~107 minecraft:gray_stained_glass
fill ~2 ~2 ~113 ~2 ~3 ~113 minecraft:light_gray_stained_glass
fill ~-3 ~2 ~109 ~-3 ~3 ~109 minecraft:gray_stained_glass
fill ~4 ~2 ~109 ~4 ~3 ~109 minecraft:light_gray_stained_glass
fill ~-1 ~6 ~107 ~-1 ~7 ~107 minecraft:gray_stained_glass
fill ~-1 ~6 ~113 ~-1 ~7 ~113 minecraft:light_gray_stained_glass
fill ~2 ~6 ~107 ~2 ~7 ~107 minecraft:gray_stained_glass
fill ~2 ~6 ~113 ~2 ~7 ~113 minecraft:light_gray_stained_glass
fill ~-3 ~6 ~109 ~-3 ~7 ~109 minecraft:gray_stained_glass
fill ~4 ~6 ~109 ~4 ~7 ~109 minecraft:light_gray_stained_glass
setblock ~4 ~1 ~110 minecraft:iron_door[half=lower,facing=east]
setblock ~4 ~2 ~110 minecraft:iron_door[half=upper,facing=east]
fill ~-3 ~10 ~107 ~4 ~10 ~113 minecraft:deepslate_tile_slab
fill ~-2 ~11 ~108 ~3 ~11 ~112 minecraft:deepslate_tile_slab
setblock ~5 ~3 ~110 minecraft:dark_oak_slab[type=top]
