# Buildings 17..24
# 017 lowrise_housing style=rowhouse context=local_front facing=north
fill ~51 ~-3 ~-32 ~63 ~-1 ~-20 minecraft:stone
fill ~51 ~0 ~-32 ~63 ~12 ~-20 minecraft:bricks
fill ~52 ~1 ~-31 ~62 ~11 ~-21 minecraft:air
fill ~52 ~4 ~-31 ~62 ~4 ~-21 minecraft:smooth_stone
fill ~52 ~8 ~-31 ~62 ~8 ~-21 minecraft:smooth_stone
fill ~53 ~2 ~-32 ~53 ~3 ~-32 minecraft:gray_stained_glass
fill ~53 ~2 ~-20 ~53 ~3 ~-20 minecraft:light_gray_stained_glass
fill ~56 ~2 ~-32 ~56 ~3 ~-32 minecraft:gray_stained_glass
fill ~56 ~2 ~-20 ~56 ~3 ~-20 minecraft:light_gray_stained_glass
fill ~59 ~2 ~-32 ~59 ~3 ~-32 minecraft:gray_stained_glass
fill ~59 ~2 ~-20 ~59 ~3 ~-20 minecraft:light_gray_stained_glass
fill ~51 ~2 ~-30 ~51 ~3 ~-30 minecraft:gray_stained_glass
fill ~63 ~2 ~-30 ~63 ~3 ~-30 minecraft:light_gray_stained_glass
fill ~51 ~2 ~-27 ~51 ~3 ~-27 minecraft:gray_stained_glass
fill ~63 ~2 ~-27 ~63 ~3 ~-27 minecraft:light_gray_stained_glass
fill ~51 ~2 ~-24 ~51 ~3 ~-24 minecraft:gray_stained_glass
fill ~63 ~2 ~-24 ~63 ~3 ~-24 minecraft:light_gray_stained_glass
fill ~53 ~6 ~-32 ~53 ~7 ~-32 minecraft:gray_stained_glass
fill ~53 ~6 ~-20 ~53 ~7 ~-20 minecraft:light_gray_stained_glass
fill ~56 ~6 ~-32 ~56 ~7 ~-32 minecraft:gray_stained_glass
fill ~56 ~6 ~-20 ~56 ~7 ~-20 minecraft:light_gray_stained_glass
fill ~59 ~6 ~-32 ~59 ~7 ~-32 minecraft:gray_stained_glass
fill ~59 ~6 ~-20 ~59 ~7 ~-20 minecraft:light_gray_stained_glass
fill ~51 ~6 ~-30 ~51 ~7 ~-30 minecraft:gray_stained_glass
fill ~63 ~6 ~-30 ~63 ~7 ~-30 minecraft:light_gray_stained_glass
fill ~51 ~6 ~-27 ~51 ~7 ~-27 minecraft:gray_stained_glass
fill ~63 ~6 ~-27 ~63 ~7 ~-27 minecraft:light_gray_stained_glass
fill ~51 ~6 ~-24 ~51 ~7 ~-24 minecraft:gray_stained_glass
fill ~63 ~6 ~-24 ~63 ~7 ~-24 minecraft:light_gray_stained_glass
fill ~53 ~10 ~-32 ~53 ~11 ~-32 minecraft:gray_stained_glass
fill ~53 ~10 ~-20 ~53 ~11 ~-20 minecraft:light_gray_stained_glass
fill ~56 ~10 ~-32 ~56 ~11 ~-32 minecraft:gray_stained_glass
fill ~56 ~10 ~-20 ~56 ~11 ~-20 minecraft:light_gray_stained_glass
fill ~59 ~10 ~-32 ~59 ~11 ~-32 minecraft:gray_stained_glass
fill ~59 ~10 ~-20 ~59 ~11 ~-20 minecraft:light_gray_stained_glass
fill ~51 ~10 ~-30 ~51 ~11 ~-30 minecraft:gray_stained_glass
fill ~63 ~10 ~-30 ~63 ~11 ~-30 minecraft:light_gray_stained_glass
fill ~51 ~10 ~-27 ~51 ~11 ~-27 minecraft:gray_stained_glass
fill ~63 ~10 ~-27 ~63 ~11 ~-27 minecraft:light_gray_stained_glass
fill ~51 ~10 ~-24 ~51 ~11 ~-24 minecraft:gray_stained_glass
fill ~63 ~10 ~-24 ~63 ~11 ~-24 minecraft:light_gray_stained_glass
setblock ~56 ~1 ~-32 minecraft:iron_door[half=lower,facing=north]
setblock ~56 ~2 ~-32 minecraft:iron_door[half=upper,facing=north]
fill ~51 ~13 ~-32 ~63 ~13 ~-20 minecraft:deepslate_tile_slab
fill ~52 ~14 ~-31 ~62 ~14 ~-21 minecraft:deepslate_tile_slab
setblock ~56 ~3 ~-33 minecraft:dark_oak_slab[type=top]
fill ~61 ~10 ~-22 ~63 ~14 ~-20 minecraft:air
setblock ~61 ~10 ~-22 minecraft:cobweb
fill ~52 ~1 ~-32 ~52 ~7 ~-32 doomsday_decoration:hollowbrick
fill ~56 ~1 ~-32 ~56 ~7 ~-32 doomsday_decoration:hollowbrick
fill ~60 ~1 ~-32 ~60 ~7 ~-32 doomsday_decoration:hollowbrick
# 018 supermarket style=arcade_shop context=collector_front facing=south
fill ~70 ~-3 ~-83 ~78 ~-1 ~-76 minecraft:stone
fill ~70 ~0 ~-83 ~78 ~5 ~-76 minecraft:white_terracotta
fill ~71 ~1 ~-82 ~77 ~4 ~-77 minecraft:air
fill ~71 ~4 ~-82 ~77 ~4 ~-77 minecraft:smooth_stone
fill ~72 ~2 ~-83 ~72 ~3 ~-83 minecraft:gray_stained_glass
fill ~72 ~2 ~-76 ~72 ~3 ~-76 minecraft:light_gray_stained_glass
fill ~75 ~2 ~-83 ~75 ~3 ~-83 minecraft:gray_stained_glass
fill ~75 ~2 ~-76 ~75 ~3 ~-76 minecraft:light_gray_stained_glass
fill ~70 ~2 ~-81 ~70 ~3 ~-81 minecraft:gray_stained_glass
fill ~78 ~2 ~-81 ~78 ~3 ~-81 minecraft:light_gray_stained_glass
fill ~70 ~2 ~-78 ~70 ~3 ~-78 minecraft:gray_stained_glass
fill ~78 ~2 ~-78 ~78 ~3 ~-78 minecraft:light_gray_stained_glass
setblock ~74 ~1 ~-76 minecraft:iron_door[half=lower,facing=south]
setblock ~74 ~2 ~-76 minecraft:iron_door[half=upper,facing=south]
fill ~71 ~1 ~-76 ~77 ~3 ~-76 minecraft:cyan_stained_glass
setblock ~74 ~1 ~-76 minecraft:iron_door[half=lower,facing=south]
setblock ~74 ~2 ~-76 minecraft:iron_door[half=upper,facing=south]
setblock ~74 ~3 ~-75 minecraft:red_wool
fill ~71 ~4 ~-76 ~77 ~4 ~-76 minecraft:dark_oak_planks
fill ~70 ~6 ~-83 ~78 ~6 ~-76 minecraft:dark_oak_slab
fill ~71 ~1 ~-76 ~71 ~5 ~-76 minecraft:dark_oak_planks
fill ~75 ~1 ~-76 ~75 ~5 ~-76 minecraft:dark_oak_planks
# 019 logistics style=loading_bay context=local_front facing=south
fill ~48 ~-3 ~-121 ~59 ~-1 ~-106 minecraft:stone
fill ~48 ~0 ~-121 ~59 ~11 ~-106 minecraft:stone_bricks
fill ~49 ~1 ~-120 ~58 ~10 ~-107 minecraft:air
fill ~49 ~4 ~-120 ~58 ~4 ~-107 minecraft:smooth_stone
fill ~49 ~8 ~-120 ~58 ~8 ~-107 minecraft:smooth_stone
fill ~50 ~2 ~-121 ~50 ~3 ~-121 minecraft:gray_stained_glass
fill ~50 ~2 ~-106 ~50 ~3 ~-106 minecraft:light_gray_stained_glass
fill ~53 ~2 ~-121 ~53 ~3 ~-121 minecraft:gray_stained_glass
fill ~53 ~2 ~-106 ~53 ~3 ~-106 minecraft:light_gray_stained_glass
fill ~56 ~2 ~-121 ~56 ~3 ~-121 minecraft:gray_stained_glass
fill ~56 ~2 ~-106 ~56 ~3 ~-106 minecraft:light_gray_stained_glass
fill ~48 ~2 ~-119 ~48 ~3 ~-119 minecraft:gray_stained_glass
fill ~59 ~2 ~-119 ~59 ~3 ~-119 minecraft:light_gray_stained_glass
fill ~48 ~2 ~-116 ~48 ~3 ~-116 minecraft:gray_stained_glass
fill ~59 ~2 ~-116 ~59 ~3 ~-116 minecraft:light_gray_stained_glass
fill ~48 ~2 ~-113 ~48 ~3 ~-113 minecraft:gray_stained_glass
fill ~59 ~2 ~-113 ~59 ~3 ~-113 minecraft:light_gray_stained_glass
fill ~48 ~2 ~-110 ~48 ~3 ~-110 minecraft:gray_stained_glass
fill ~59 ~2 ~-110 ~59 ~3 ~-110 minecraft:light_gray_stained_glass
fill ~50 ~6 ~-121 ~50 ~7 ~-121 minecraft:gray_stained_glass
fill ~50 ~6 ~-106 ~50 ~7 ~-106 minecraft:light_gray_stained_glass
fill ~53 ~6 ~-121 ~53 ~7 ~-121 minecraft:gray_stained_glass
fill ~53 ~6 ~-106 ~53 ~7 ~-106 minecraft:light_gray_stained_glass
fill ~56 ~6 ~-121 ~56 ~7 ~-121 minecraft:gray_stained_glass
fill ~56 ~6 ~-106 ~56 ~7 ~-106 minecraft:light_gray_stained_glass
fill ~48 ~6 ~-119 ~48 ~7 ~-119 minecraft:gray_stained_glass
fill ~59 ~6 ~-119 ~59 ~7 ~-119 minecraft:light_gray_stained_glass
fill ~48 ~6 ~-116 ~48 ~7 ~-116 minecraft:gray_stained_glass
fill ~59 ~6 ~-116 ~59 ~7 ~-116 minecraft:light_gray_stained_glass
fill ~48 ~6 ~-113 ~48 ~7 ~-113 minecraft:gray_stained_glass
fill ~59 ~6 ~-113 ~59 ~7 ~-113 minecraft:light_gray_stained_glass
fill ~48 ~6 ~-110 ~48 ~7 ~-110 minecraft:gray_stained_glass
fill ~59 ~6 ~-110 ~59 ~7 ~-110 minecraft:light_gray_stained_glass
setblock ~53 ~1 ~-106 minecraft:iron_door[half=lower,facing=south]
setblock ~53 ~2 ~-106 minecraft:iron_door[half=upper,facing=south]
fill ~50 ~1 ~-106 ~57 ~4 ~-106 minecraft:polished_blackstone
fill ~50 ~5 ~-106 ~57 ~5 ~-106 minecraft:light_blue_stained_glass
fill ~50 ~13 ~-119 ~52 ~14 ~-117 minecraft:iron_block
fill ~48 ~12 ~-121 ~59 ~12 ~-106 minecraft:smooth_stone_slab
fill ~49 ~1 ~-106 ~49 ~7 ~-106 doomsday_decoration:ironsheetwall_2
fill ~53 ~1 ~-106 ~53 ~7 ~-106 doomsday_decoration:ironsheetwall_2
fill ~57 ~1 ~-106 ~57 ~7 ~-106 doomsday_decoration:ironsheetwall_2
# 020 utility style=loading_bay context=collector_front facing=west
fill ~-96 ~-3 ~-121 ~-81 ~-1 ~-104 minecraft:stone
fill ~-96 ~0 ~-121 ~-81 ~9 ~-104 minecraft:bricks
fill ~-95 ~1 ~-120 ~-82 ~8 ~-105 minecraft:air
fill ~-95 ~4 ~-120 ~-82 ~4 ~-105 minecraft:smooth_stone
fill ~-95 ~8 ~-120 ~-82 ~8 ~-105 minecraft:smooth_stone
fill ~-94 ~2 ~-121 ~-94 ~3 ~-121 minecraft:gray_stained_glass
fill ~-94 ~2 ~-104 ~-94 ~3 ~-104 minecraft:light_gray_stained_glass
fill ~-91 ~2 ~-121 ~-91 ~3 ~-121 minecraft:gray_stained_glass
fill ~-91 ~2 ~-104 ~-91 ~3 ~-104 minecraft:light_gray_stained_glass
fill ~-88 ~2 ~-121 ~-88 ~3 ~-121 minecraft:gray_stained_glass
fill ~-88 ~2 ~-104 ~-88 ~3 ~-104 minecraft:light_gray_stained_glass
fill ~-85 ~2 ~-121 ~-85 ~3 ~-121 minecraft:gray_stained_glass
fill ~-85 ~2 ~-104 ~-85 ~3 ~-104 minecraft:light_gray_stained_glass
fill ~-96 ~2 ~-119 ~-96 ~3 ~-119 minecraft:gray_stained_glass
fill ~-81 ~2 ~-119 ~-81 ~3 ~-119 minecraft:light_gray_stained_glass
fill ~-96 ~2 ~-116 ~-96 ~3 ~-116 minecraft:gray_stained_glass
fill ~-81 ~2 ~-116 ~-81 ~3 ~-116 minecraft:light_gray_stained_glass
fill ~-96 ~2 ~-113 ~-96 ~3 ~-113 minecraft:gray_stained_glass
fill ~-81 ~2 ~-113 ~-81 ~3 ~-113 minecraft:light_gray_stained_glass
fill ~-96 ~2 ~-110 ~-96 ~3 ~-110 minecraft:gray_stained_glass
fill ~-81 ~2 ~-110 ~-81 ~3 ~-110 minecraft:light_gray_stained_glass
fill ~-96 ~2 ~-107 ~-96 ~3 ~-107 minecraft:gray_stained_glass
fill ~-81 ~2 ~-107 ~-81 ~3 ~-107 minecraft:light_gray_stained_glass
fill ~-94 ~6 ~-121 ~-94 ~7 ~-121 minecraft:gray_stained_glass
fill ~-94 ~6 ~-104 ~-94 ~7 ~-104 minecraft:light_gray_stained_glass
fill ~-91 ~6 ~-121 ~-91 ~7 ~-121 minecraft:gray_stained_glass
fill ~-91 ~6 ~-104 ~-91 ~7 ~-104 minecraft:light_gray_stained_glass
fill ~-88 ~6 ~-121 ~-88 ~7 ~-121 minecraft:gray_stained_glass
fill ~-88 ~6 ~-104 ~-88 ~7 ~-104 minecraft:light_gray_stained_glass
fill ~-85 ~6 ~-121 ~-85 ~7 ~-121 minecraft:gray_stained_glass
fill ~-85 ~6 ~-104 ~-85 ~7 ~-104 minecraft:light_gray_stained_glass
fill ~-96 ~6 ~-119 ~-96 ~7 ~-119 minecraft:gray_stained_glass
fill ~-81 ~6 ~-119 ~-81 ~7 ~-119 minecraft:light_gray_stained_glass
fill ~-96 ~6 ~-116 ~-96 ~7 ~-116 minecraft:gray_stained_glass
fill ~-81 ~6 ~-116 ~-81 ~7 ~-116 minecraft:light_gray_stained_glass
fill ~-96 ~6 ~-113 ~-96 ~7 ~-113 minecraft:gray_stained_glass
fill ~-81 ~6 ~-113 ~-81 ~7 ~-113 minecraft:light_gray_stained_glass
fill ~-96 ~6 ~-110 ~-96 ~7 ~-110 minecraft:gray_stained_glass
fill ~-81 ~6 ~-110 ~-81 ~7 ~-110 minecraft:light_gray_stained_glass
fill ~-96 ~6 ~-107 ~-96 ~7 ~-107 minecraft:gray_stained_glass
fill ~-81 ~6 ~-107 ~-81 ~7 ~-107 minecraft:light_gray_stained_glass
setblock ~-96 ~1 ~-116 minecraft:iron_door[half=lower,facing=west]
setblock ~-96 ~2 ~-116 minecraft:iron_door[half=upper,facing=west]
fill ~-96 ~1 ~-119 ~-96 ~4 ~-106 minecraft:polished_blackstone
fill ~-96 ~5 ~-119 ~-96 ~5 ~-106 minecraft:light_blue_stained_glass
fill ~-94 ~11 ~-119 ~-92 ~12 ~-117 minecraft:iron_block
fill ~-96 ~10 ~-121 ~-81 ~10 ~-104 minecraft:deepslate_tile_slab
fill ~-96 ~1 ~-120 ~-96 ~7 ~-120 minecraft:gray_concrete
fill ~-96 ~1 ~-116 ~-96 ~7 ~-116 minecraft:gray_concrete
fill ~-96 ~1 ~-112 ~-96 ~7 ~-112 minecraft:gray_concrete
fill ~-96 ~1 ~-108 ~-96 ~7 ~-108 minecraft:gray_concrete
# 021 office style=civic_modern context=arterial_front facing=west
fill ~104 ~-3 ~7 ~111 ~-1 ~13 minecraft:stone
fill ~104 ~0 ~7 ~111 ~9 ~13 minecraft:bricks
fill ~105 ~1 ~8 ~110 ~8 ~12 minecraft:air
fill ~105 ~4 ~8 ~110 ~4 ~12 minecraft:smooth_stone
fill ~105 ~8 ~8 ~110 ~8 ~12 minecraft:smooth_stone
fill ~106 ~2 ~7 ~106 ~3 ~7 minecraft:gray_stained_glass
fill ~106 ~2 ~13 ~106 ~3 ~13 minecraft:light_gray_stained_glass
fill ~109 ~2 ~7 ~109 ~3 ~7 minecraft:gray_stained_glass
fill ~109 ~2 ~13 ~109 ~3 ~13 minecraft:light_gray_stained_glass
fill ~104 ~2 ~9 ~104 ~3 ~9 minecraft:gray_stained_glass
fill ~111 ~2 ~9 ~111 ~3 ~9 minecraft:light_gray_stained_glass
fill ~106 ~6 ~7 ~106 ~7 ~7 minecraft:gray_stained_glass
fill ~106 ~6 ~13 ~106 ~7 ~13 minecraft:light_gray_stained_glass
fill ~109 ~6 ~7 ~109 ~7 ~7 minecraft:gray_stained_glass
fill ~109 ~6 ~13 ~109 ~7 ~13 minecraft:light_gray_stained_glass
fill ~104 ~6 ~9 ~104 ~7 ~9 minecraft:gray_stained_glass
fill ~111 ~6 ~9 ~111 ~7 ~9 minecraft:light_gray_stained_glass
setblock ~104 ~1 ~10 minecraft:iron_door[half=lower,facing=west]
setblock ~104 ~2 ~10 minecraft:iron_door[half=upper,facing=west]
fill ~106 ~11 ~9 ~108 ~12 ~11 minecraft:light_gray_concrete
setblock ~109 ~11 ~10 minecraft:lightning_rod
fill ~104 ~1 ~8 ~104 ~7 ~8 minecraft:weathered_cut_copper
fill ~104 ~1 ~12 ~104 ~7 ~12 minecraft:weathered_cut_copper
# 022 row_house style=stepped_house context=local_front facing=north
fill ~-114 ~-3 ~89 ~-106 ~-1 ~98 minecraft:stone
fill ~-114 ~0 ~89 ~-106 ~11 ~98 minecraft:white_terracotta
fill ~-113 ~1 ~90 ~-107 ~10 ~97 minecraft:air
fill ~-113 ~4 ~90 ~-107 ~4 ~97 minecraft:smooth_stone
fill ~-113 ~8 ~90 ~-107 ~8 ~97 minecraft:smooth_stone
fill ~-112 ~2 ~89 ~-112 ~3 ~89 minecraft:gray_stained_glass
fill ~-112 ~2 ~98 ~-112 ~3 ~98 minecraft:light_gray_stained_glass
fill ~-109 ~2 ~89 ~-109 ~3 ~89 minecraft:gray_stained_glass
fill ~-109 ~2 ~98 ~-109 ~3 ~98 minecraft:light_gray_stained_glass
fill ~-114 ~2 ~91 ~-114 ~3 ~91 minecraft:gray_stained_glass
fill ~-106 ~2 ~91 ~-106 ~3 ~91 minecraft:light_gray_stained_glass
fill ~-114 ~2 ~94 ~-114 ~3 ~94 minecraft:gray_stained_glass
fill ~-106 ~2 ~94 ~-106 ~3 ~94 minecraft:light_gray_stained_glass
fill ~-112 ~6 ~89 ~-112 ~7 ~89 minecraft:gray_stained_glass
fill ~-112 ~6 ~98 ~-112 ~7 ~98 minecraft:light_gray_stained_glass
fill ~-109 ~6 ~89 ~-109 ~7 ~89 minecraft:gray_stained_glass
fill ~-109 ~6 ~98 ~-109 ~7 ~98 minecraft:light_gray_stained_glass
fill ~-114 ~6 ~91 ~-114 ~7 ~91 minecraft:gray_stained_glass
fill ~-106 ~6 ~91 ~-106 ~7 ~91 minecraft:light_gray_stained_glass
fill ~-114 ~6 ~94 ~-114 ~7 ~94 minecraft:gray_stained_glass
fill ~-106 ~6 ~94 ~-106 ~7 ~94 minecraft:light_gray_stained_glass
setblock ~-110 ~1 ~89 minecraft:iron_door[half=lower,facing=north]
setblock ~-110 ~2 ~89 minecraft:iron_door[half=upper,facing=north]
fill ~-114 ~12 ~89 ~-106 ~12 ~98 minecraft:dark_oak_slab
fill ~-113 ~13 ~90 ~-107 ~13 ~97 minecraft:dark_oak_slab
setblock ~-110 ~3 ~88 minecraft:dark_oak_slab[type=top]
fill ~-113 ~1 ~89 ~-113 ~7 ~89 minecraft:dark_oak_planks
fill ~-109 ~1 ~89 ~-109 ~7 ~89 minecraft:dark_oak_planks
# 023 local_shop style=storefront context=local_front facing=south
fill ~-111 ~-3 ~67 ~-106 ~-1 ~79 minecraft:stone
fill ~-111 ~0 ~67 ~-106 ~9 ~79 minecraft:mud_bricks
fill ~-110 ~1 ~68 ~-107 ~8 ~78 minecraft:air
fill ~-110 ~4 ~68 ~-107 ~4 ~78 minecraft:smooth_stone
fill ~-110 ~8 ~68 ~-107 ~8 ~78 minecraft:smooth_stone
fill ~-109 ~2 ~67 ~-109 ~3 ~67 minecraft:gray_stained_glass
fill ~-109 ~2 ~79 ~-109 ~3 ~79 minecraft:light_gray_stained_glass
fill ~-111 ~2 ~69 ~-111 ~3 ~69 minecraft:gray_stained_glass
fill ~-106 ~2 ~69 ~-106 ~3 ~69 minecraft:light_gray_stained_glass
fill ~-111 ~2 ~72 ~-111 ~3 ~72 minecraft:gray_stained_glass
fill ~-106 ~2 ~72 ~-106 ~3 ~72 minecraft:light_gray_stained_glass
fill ~-111 ~2 ~75 ~-111 ~3 ~75 minecraft:gray_stained_glass
fill ~-106 ~2 ~75 ~-106 ~3 ~75 minecraft:light_gray_stained_glass
fill ~-109 ~6 ~67 ~-109 ~7 ~67 minecraft:gray_stained_glass
fill ~-109 ~6 ~79 ~-109 ~7 ~79 minecraft:light_gray_stained_glass
fill ~-111 ~6 ~69 ~-111 ~7 ~69 minecraft:gray_stained_glass
fill ~-106 ~6 ~69 ~-106 ~7 ~69 minecraft:light_gray_stained_glass
fill ~-111 ~6 ~72 ~-111 ~7 ~72 minecraft:gray_stained_glass
fill ~-106 ~6 ~72 ~-106 ~7 ~72 minecraft:light_gray_stained_glass
fill ~-111 ~6 ~75 ~-111 ~7 ~75 minecraft:gray_stained_glass
fill ~-106 ~6 ~75 ~-106 ~7 ~75 minecraft:light_gray_stained_glass
setblock ~-109 ~1 ~79 minecraft:iron_door[half=lower,facing=south]
setblock ~-109 ~2 ~79 minecraft:iron_door[half=upper,facing=south]
fill ~-110 ~1 ~79 ~-107 ~3 ~79 minecraft:cyan_stained_glass
setblock ~-109 ~1 ~79 minecraft:iron_door[half=lower,facing=south]
setblock ~-109 ~2 ~79 minecraft:iron_door[half=upper,facing=south]
setblock ~-109 ~3 ~80 minecraft:red_wool
fill ~-111 ~10 ~67 ~-106 ~10 ~79 minecraft:deepslate_tile_slab
fill ~-110 ~1 ~79 ~-110 ~7 ~79 minecraft:spruce_planks
setblock ~-109 ~3 ~79 minecraft:red_carpet
# 024 midrise_housing style=mixed_facade context=collector_front facing=north
fill ~-126 ~-3 ~52 ~-116 ~-1 ~58 minecraft:stone
fill ~-126 ~0 ~52 ~-116 ~9 ~58 minecraft:calcite
fill ~-125 ~1 ~53 ~-117 ~8 ~57 minecraft:air
fill ~-125 ~4 ~53 ~-117 ~4 ~57 minecraft:smooth_stone
fill ~-125 ~8 ~53 ~-117 ~8 ~57 minecraft:smooth_stone
fill ~-124 ~2 ~52 ~-124 ~3 ~52 minecraft:gray_stained_glass
fill ~-124 ~2 ~58 ~-124 ~3 ~58 minecraft:light_gray_stained_glass
fill ~-121 ~2 ~52 ~-121 ~3 ~52 minecraft:gray_stained_glass
fill ~-121 ~2 ~58 ~-121 ~3 ~58 minecraft:light_gray_stained_glass
fill ~-118 ~2 ~52 ~-118 ~3 ~52 minecraft:gray_stained_glass
fill ~-118 ~2 ~58 ~-118 ~3 ~58 minecraft:light_gray_stained_glass
fill ~-126 ~2 ~54 ~-126 ~3 ~54 minecraft:gray_stained_glass
fill ~-116 ~2 ~54 ~-116 ~3 ~54 minecraft:light_gray_stained_glass
fill ~-124 ~6 ~52 ~-124 ~7 ~52 minecraft:gray_stained_glass
fill ~-124 ~6 ~58 ~-124 ~7 ~58 minecraft:light_gray_stained_glass
fill ~-121 ~6 ~52 ~-121 ~7 ~52 minecraft:gray_stained_glass
fill ~-121 ~6 ~58 ~-121 ~7 ~58 minecraft:light_gray_stained_glass
fill ~-118 ~6 ~52 ~-118 ~7 ~52 minecraft:gray_stained_glass
fill ~-118 ~6 ~58 ~-118 ~7 ~58 minecraft:light_gray_stained_glass
fill ~-126 ~6 ~54 ~-126 ~7 ~54 minecraft:gray_stained_glass
fill ~-116 ~6 ~54 ~-116 ~7 ~54 minecraft:light_gray_stained_glass
setblock ~-121 ~1 ~52 minecraft:iron_door[half=lower,facing=north]
setblock ~-121 ~2 ~52 minecraft:iron_door[half=upper,facing=north]
fill ~-126 ~10 ~52 ~-116 ~10 ~58 minecraft:stone_brick_slab
fill ~-124 ~11 ~54 ~-122 ~12 ~56 minecraft:light_gray_concrete
setblock ~-121 ~11 ~55 minecraft:lightning_rod
fill ~-125 ~1 ~52 ~-125 ~7 ~52 minecraft:gray_concrete
fill ~-121 ~1 ~52 ~-121 ~7 ~52 minecraft:gray_concrete
fill ~-117 ~1 ~52 ~-117 ~7 ~52 minecraft:gray_concrete
