# Buildings 1..8
# 001 clinic style=civic_medical context=collector_front facing=east
fill ~2 ~-3 ~-64 ~12 ~-1 ~-52 minecraft:stone
fill ~2 ~0 ~-64 ~12 ~10 ~-52 minecraft:smooth_sandstone
fill ~3 ~1 ~-63 ~11 ~9 ~-53 minecraft:air
fill ~3 ~4 ~-63 ~11 ~4 ~-53 minecraft:smooth_stone
fill ~3 ~8 ~-63 ~11 ~8 ~-53 minecraft:smooth_stone
fill ~4 ~2 ~-64 ~4 ~3 ~-64 minecraft:gray_stained_glass
fill ~4 ~2 ~-52 ~4 ~3 ~-52 minecraft:light_gray_stained_glass
fill ~7 ~2 ~-64 ~7 ~3 ~-64 minecraft:gray_stained_glass
fill ~7 ~2 ~-52 ~7 ~3 ~-52 minecraft:light_gray_stained_glass
fill ~10 ~2 ~-64 ~10 ~3 ~-64 minecraft:gray_stained_glass
fill ~10 ~2 ~-52 ~10 ~3 ~-52 minecraft:light_gray_stained_glass
fill ~2 ~2 ~-62 ~2 ~3 ~-62 minecraft:gray_stained_glass
fill ~12 ~2 ~-62 ~12 ~3 ~-62 minecraft:light_gray_stained_glass
fill ~2 ~2 ~-59 ~2 ~3 ~-59 minecraft:gray_stained_glass
fill ~12 ~2 ~-59 ~12 ~3 ~-59 minecraft:light_gray_stained_glass
fill ~2 ~2 ~-56 ~2 ~3 ~-56 minecraft:gray_stained_glass
fill ~12 ~2 ~-56 ~12 ~3 ~-56 minecraft:light_gray_stained_glass
fill ~4 ~6 ~-64 ~4 ~7 ~-64 minecraft:gray_stained_glass
fill ~4 ~6 ~-52 ~4 ~7 ~-52 minecraft:light_gray_stained_glass
fill ~7 ~6 ~-64 ~7 ~7 ~-64 minecraft:gray_stained_glass
fill ~7 ~6 ~-52 ~7 ~7 ~-52 minecraft:light_gray_stained_glass
fill ~10 ~6 ~-64 ~10 ~7 ~-64 minecraft:gray_stained_glass
fill ~10 ~6 ~-52 ~10 ~7 ~-52 minecraft:light_gray_stained_glass
fill ~2 ~6 ~-62 ~2 ~7 ~-62 minecraft:gray_stained_glass
fill ~12 ~6 ~-62 ~12 ~7 ~-62 minecraft:light_gray_stained_glass
fill ~2 ~6 ~-59 ~2 ~7 ~-59 minecraft:gray_stained_glass
fill ~12 ~6 ~-59 ~12 ~7 ~-59 minecraft:light_gray_stained_glass
fill ~2 ~6 ~-56 ~2 ~7 ~-56 minecraft:gray_stained_glass
fill ~12 ~6 ~-56 ~12 ~7 ~-56 minecraft:light_gray_stained_glass
setblock ~12 ~1 ~-59 minecraft:iron_door[half=lower,facing=east]
setblock ~12 ~2 ~-59 minecraft:iron_door[half=upper,facing=east]
fill ~2 ~11 ~-64 ~12 ~11 ~-52 minecraft:stone_brick_slab
fill ~12 ~1 ~-63 ~12 ~7 ~-63 minecraft:brown_terracotta
fill ~12 ~1 ~-59 ~12 ~7 ~-59 minecraft:brown_terracotta
fill ~12 ~1 ~-55 ~12 ~7 ~-55 minecraft:brown_terracotta
# 002 fire_station style=civic_emergency context=local_front facing=east
fill ~12 ~-3 ~75 ~22 ~-1 ~89 minecraft:stone
fill ~12 ~0 ~75 ~22 ~9 ~89 minecraft:light_gray_concrete
fill ~13 ~1 ~76 ~21 ~8 ~88 minecraft:air
fill ~13 ~4 ~76 ~21 ~4 ~88 minecraft:smooth_stone
fill ~13 ~8 ~76 ~21 ~8 ~88 minecraft:smooth_stone
fill ~14 ~2 ~75 ~14 ~3 ~75 minecraft:gray_stained_glass
fill ~14 ~2 ~89 ~14 ~3 ~89 minecraft:light_gray_stained_glass
fill ~17 ~2 ~75 ~17 ~3 ~75 minecraft:gray_stained_glass
fill ~17 ~2 ~89 ~17 ~3 ~89 minecraft:light_gray_stained_glass
fill ~20 ~2 ~75 ~20 ~3 ~75 minecraft:gray_stained_glass
fill ~20 ~2 ~89 ~20 ~3 ~89 minecraft:light_gray_stained_glass
fill ~12 ~2 ~77 ~12 ~3 ~77 minecraft:gray_stained_glass
fill ~22 ~2 ~77 ~22 ~3 ~77 minecraft:light_gray_stained_glass
fill ~12 ~2 ~80 ~12 ~3 ~80 minecraft:gray_stained_glass
fill ~22 ~2 ~80 ~22 ~3 ~80 minecraft:light_gray_stained_glass
fill ~12 ~2 ~83 ~12 ~3 ~83 minecraft:gray_stained_glass
fill ~22 ~2 ~83 ~22 ~3 ~83 minecraft:light_gray_stained_glass
fill ~12 ~2 ~86 ~12 ~3 ~86 minecraft:gray_stained_glass
fill ~22 ~2 ~86 ~22 ~3 ~86 minecraft:light_gray_stained_glass
fill ~14 ~6 ~75 ~14 ~7 ~75 minecraft:gray_stained_glass
fill ~14 ~6 ~89 ~14 ~7 ~89 minecraft:light_gray_stained_glass
fill ~17 ~6 ~75 ~17 ~7 ~75 minecraft:gray_stained_glass
fill ~17 ~6 ~89 ~17 ~7 ~89 minecraft:light_gray_stained_glass
fill ~20 ~6 ~75 ~20 ~7 ~75 minecraft:gray_stained_glass
fill ~20 ~6 ~89 ~20 ~7 ~89 minecraft:light_gray_stained_glass
fill ~12 ~6 ~77 ~12 ~7 ~77 minecraft:gray_stained_glass
fill ~22 ~6 ~77 ~22 ~7 ~77 minecraft:light_gray_stained_glass
fill ~12 ~6 ~80 ~12 ~7 ~80 minecraft:gray_stained_glass
fill ~22 ~6 ~80 ~22 ~7 ~80 minecraft:light_gray_stained_glass
fill ~12 ~6 ~83 ~12 ~7 ~83 minecraft:gray_stained_glass
fill ~22 ~6 ~83 ~22 ~7 ~83 minecraft:light_gray_stained_glass
fill ~12 ~6 ~86 ~12 ~7 ~86 minecraft:gray_stained_glass
fill ~22 ~6 ~86 ~22 ~7 ~86 minecraft:light_gray_stained_glass
setblock ~22 ~1 ~80 minecraft:iron_door[half=lower,facing=east]
setblock ~22 ~2 ~80 minecraft:iron_door[half=upper,facing=east]
fill ~12 ~10 ~75 ~22 ~10 ~89 minecraft:smooth_stone_slab
fill ~22 ~1 ~76 ~22 ~7 ~76 doomsday_decoration:porcelainbrickwall
fill ~22 ~1 ~80 ~22 ~7 ~80 doomsday_decoration:porcelainbrickwall
fill ~22 ~1 ~84 ~22 ~7 ~84 doomsday_decoration:porcelainbrickwall
fill ~22 ~1 ~88 ~22 ~7 ~88 doomsday_decoration:porcelainbrickwall
# 003 police_station style=civic_security context=local_front facing=west
fill ~44 ~-3 ~30 ~56 ~-1 ~42 minecraft:stone
fill ~44 ~0 ~30 ~56 ~11 ~42 minecraft:stone_bricks
fill ~45 ~1 ~31 ~55 ~10 ~41 minecraft:air
fill ~45 ~4 ~31 ~55 ~4 ~41 minecraft:smooth_stone
fill ~45 ~8 ~31 ~55 ~8 ~41 minecraft:smooth_stone
fill ~46 ~2 ~30 ~46 ~3 ~30 minecraft:gray_stained_glass
fill ~46 ~2 ~42 ~46 ~3 ~42 minecraft:light_gray_stained_glass
fill ~49 ~2 ~30 ~49 ~3 ~30 minecraft:gray_stained_glass
fill ~49 ~2 ~42 ~49 ~3 ~42 minecraft:light_gray_stained_glass
fill ~52 ~2 ~30 ~52 ~3 ~30 minecraft:gray_stained_glass
fill ~52 ~2 ~42 ~52 ~3 ~42 minecraft:light_gray_stained_glass
fill ~44 ~2 ~32 ~44 ~3 ~32 minecraft:gray_stained_glass
fill ~56 ~2 ~32 ~56 ~3 ~32 minecraft:light_gray_stained_glass
fill ~44 ~2 ~35 ~44 ~3 ~35 minecraft:gray_stained_glass
fill ~56 ~2 ~35 ~56 ~3 ~35 minecraft:light_gray_stained_glass
fill ~44 ~2 ~38 ~44 ~3 ~38 minecraft:gray_stained_glass
fill ~56 ~2 ~38 ~56 ~3 ~38 minecraft:light_gray_stained_glass
fill ~46 ~6 ~30 ~46 ~7 ~30 minecraft:gray_stained_glass
fill ~46 ~6 ~42 ~46 ~7 ~42 minecraft:light_gray_stained_glass
fill ~49 ~6 ~30 ~49 ~7 ~30 minecraft:gray_stained_glass
fill ~49 ~6 ~42 ~49 ~7 ~42 minecraft:light_gray_stained_glass
fill ~52 ~6 ~30 ~52 ~7 ~30 minecraft:gray_stained_glass
fill ~52 ~6 ~42 ~52 ~7 ~42 minecraft:light_gray_stained_glass
fill ~44 ~6 ~32 ~44 ~7 ~32 minecraft:gray_stained_glass
fill ~56 ~6 ~32 ~56 ~7 ~32 minecraft:light_gray_stained_glass
fill ~44 ~6 ~35 ~44 ~7 ~35 minecraft:gray_stained_glass
fill ~56 ~6 ~35 ~56 ~7 ~35 minecraft:light_gray_stained_glass
fill ~44 ~6 ~38 ~44 ~7 ~38 minecraft:gray_stained_glass
fill ~56 ~6 ~38 ~56 ~7 ~38 minecraft:light_gray_stained_glass
setblock ~44 ~1 ~35 minecraft:iron_door[half=lower,facing=west]
setblock ~44 ~2 ~35 minecraft:iron_door[half=upper,facing=west]
fill ~44 ~12 ~30 ~56 ~12 ~42 minecraft:stone_brick_slab
fill ~46 ~13 ~32 ~48 ~14 ~34 minecraft:light_gray_concrete
setblock ~49 ~13 ~33 minecraft:lightning_rod
fill ~44 ~1 ~31 ~44 ~7 ~31 minecraft:orange_terracotta
fill ~44 ~1 ~35 ~44 ~7 ~35 minecraft:orange_terracotta
fill ~44 ~1 ~39 ~44 ~7 ~39 minecraft:orange_terracotta
# 004 logistics_depot style=industrial_logistics context=waterfront_front facing=west
fill ~106 ~-3 ~-26 ~117 ~-1 ~-14 minecraft:stone
fill ~106 ~0 ~-26 ~117 ~8 ~-14 minecraft:white_concrete
fill ~107 ~1 ~-25 ~116 ~7 ~-15 minecraft:air
fill ~107 ~4 ~-25 ~116 ~4 ~-15 minecraft:smooth_stone
fill ~108 ~2 ~-26 ~108 ~3 ~-26 minecraft:gray_stained_glass
fill ~108 ~2 ~-14 ~108 ~3 ~-14 minecraft:light_gray_stained_glass
fill ~111 ~2 ~-26 ~111 ~3 ~-26 minecraft:gray_stained_glass
fill ~111 ~2 ~-14 ~111 ~3 ~-14 minecraft:light_gray_stained_glass
fill ~114 ~2 ~-26 ~114 ~3 ~-26 minecraft:gray_stained_glass
fill ~114 ~2 ~-14 ~114 ~3 ~-14 minecraft:light_gray_stained_glass
fill ~106 ~2 ~-24 ~106 ~3 ~-24 minecraft:gray_stained_glass
fill ~117 ~2 ~-24 ~117 ~3 ~-24 minecraft:light_gray_stained_glass
fill ~106 ~2 ~-21 ~106 ~3 ~-21 minecraft:gray_stained_glass
fill ~117 ~2 ~-21 ~117 ~3 ~-21 minecraft:light_gray_stained_glass
fill ~106 ~2 ~-18 ~106 ~3 ~-18 minecraft:gray_stained_glass
fill ~117 ~2 ~-18 ~117 ~3 ~-18 minecraft:light_gray_stained_glass
fill ~108 ~6 ~-26 ~108 ~7 ~-26 minecraft:gray_stained_glass
fill ~108 ~6 ~-14 ~108 ~7 ~-14 minecraft:light_gray_stained_glass
fill ~111 ~6 ~-26 ~111 ~7 ~-26 minecraft:gray_stained_glass
fill ~111 ~6 ~-14 ~111 ~7 ~-14 minecraft:light_gray_stained_glass
fill ~114 ~6 ~-26 ~114 ~7 ~-26 minecraft:gray_stained_glass
fill ~114 ~6 ~-14 ~114 ~7 ~-14 minecraft:light_gray_stained_glass
fill ~106 ~6 ~-24 ~106 ~7 ~-24 minecraft:gray_stained_glass
fill ~117 ~6 ~-24 ~117 ~7 ~-24 minecraft:light_gray_stained_glass
fill ~106 ~6 ~-21 ~106 ~7 ~-21 minecraft:gray_stained_glass
fill ~117 ~6 ~-21 ~117 ~7 ~-21 minecraft:light_gray_stained_glass
fill ~106 ~6 ~-18 ~106 ~7 ~-18 minecraft:gray_stained_glass
fill ~117 ~6 ~-18 ~117 ~7 ~-18 minecraft:light_gray_stained_glass
setblock ~106 ~1 ~-21 minecraft:iron_door[half=lower,facing=west]
setblock ~106 ~2 ~-21 minecraft:iron_door[half=upper,facing=west]
fill ~106 ~9 ~-26 ~117 ~9 ~-14 minecraft:smooth_stone_slab
fill ~106 ~1 ~-25 ~106 ~7 ~-25 minecraft:cyan_terracotta
fill ~106 ~1 ~-21 ~106 ~7 ~-21 minecraft:cyan_terracotta
fill ~106 ~1 ~-17 ~106 ~7 ~-17 minecraft:cyan_terracotta
# 005 school style=civic_education context=local_front facing=west
fill ~47 ~-3 ~-90 ~59 ~-1 ~-78 minecraft:stone
fill ~47 ~0 ~-90 ~59 ~10 ~-78 minecraft:stone_bricks
fill ~48 ~1 ~-89 ~58 ~9 ~-79 minecraft:air
fill ~48 ~4 ~-89 ~58 ~4 ~-79 minecraft:smooth_stone
fill ~48 ~8 ~-89 ~58 ~8 ~-79 minecraft:smooth_stone
fill ~49 ~2 ~-90 ~49 ~3 ~-90 minecraft:gray_stained_glass
fill ~49 ~2 ~-78 ~49 ~3 ~-78 minecraft:light_gray_stained_glass
fill ~52 ~2 ~-90 ~52 ~3 ~-90 minecraft:gray_stained_glass
fill ~52 ~2 ~-78 ~52 ~3 ~-78 minecraft:light_gray_stained_glass
fill ~55 ~2 ~-90 ~55 ~3 ~-90 minecraft:gray_stained_glass
fill ~55 ~2 ~-78 ~55 ~3 ~-78 minecraft:light_gray_stained_glass
fill ~47 ~2 ~-88 ~47 ~3 ~-88 minecraft:gray_stained_glass
fill ~59 ~2 ~-88 ~59 ~3 ~-88 minecraft:light_gray_stained_glass
fill ~47 ~2 ~-85 ~47 ~3 ~-85 minecraft:gray_stained_glass
fill ~59 ~2 ~-85 ~59 ~3 ~-85 minecraft:light_gray_stained_glass
fill ~47 ~2 ~-82 ~47 ~3 ~-82 minecraft:gray_stained_glass
fill ~59 ~2 ~-82 ~59 ~3 ~-82 minecraft:light_gray_stained_glass
fill ~49 ~6 ~-90 ~49 ~7 ~-90 minecraft:gray_stained_glass
fill ~49 ~6 ~-78 ~49 ~7 ~-78 minecraft:light_gray_stained_glass
fill ~52 ~6 ~-90 ~52 ~7 ~-90 minecraft:gray_stained_glass
fill ~52 ~6 ~-78 ~52 ~7 ~-78 minecraft:light_gray_stained_glass
fill ~55 ~6 ~-90 ~55 ~7 ~-90 minecraft:gray_stained_glass
fill ~55 ~6 ~-78 ~55 ~7 ~-78 minecraft:light_gray_stained_glass
fill ~47 ~6 ~-88 ~47 ~7 ~-88 minecraft:gray_stained_glass
fill ~59 ~6 ~-88 ~59 ~7 ~-88 minecraft:light_gray_stained_glass
fill ~47 ~6 ~-85 ~47 ~7 ~-85 minecraft:gray_stained_glass
fill ~59 ~6 ~-85 ~59 ~7 ~-85 minecraft:light_gray_stained_glass
fill ~47 ~6 ~-82 ~47 ~7 ~-82 minecraft:gray_stained_glass
fill ~59 ~6 ~-82 ~59 ~7 ~-82 minecraft:light_gray_stained_glass
setblock ~47 ~1 ~-85 minecraft:iron_door[half=lower,facing=west]
setblock ~47 ~2 ~-85 minecraft:iron_door[half=upper,facing=west]
fill ~47 ~11 ~-90 ~59 ~11 ~-78 minecraft:smooth_stone_slab
fill ~47 ~1 ~-89 ~47 ~7 ~-89 doomsday_decoration:ironsheetwall_2
fill ~47 ~1 ~-85 ~47 ~7 ~-85 doomsday_decoration:ironsheetwall_2
fill ~47 ~1 ~-81 ~47 ~7 ~-81 doomsday_decoration:ironsheetwall_2
# 006 detached_house style=japanese_house context=local_front facing=south
fill ~89 ~-3 ~-126 ~98 ~-1 ~-116 minecraft:stone
fill ~89 ~0 ~-126 ~98 ~5 ~-116 minecraft:bricks
fill ~90 ~1 ~-125 ~97 ~4 ~-117 minecraft:air
fill ~90 ~4 ~-125 ~97 ~4 ~-117 minecraft:smooth_stone
fill ~91 ~2 ~-126 ~91 ~3 ~-126 minecraft:gray_stained_glass
fill ~91 ~2 ~-116 ~91 ~3 ~-116 minecraft:light_gray_stained_glass
fill ~94 ~2 ~-126 ~94 ~3 ~-126 minecraft:gray_stained_glass
fill ~94 ~2 ~-116 ~94 ~3 ~-116 minecraft:light_gray_stained_glass
fill ~89 ~2 ~-124 ~89 ~3 ~-124 minecraft:gray_stained_glass
fill ~98 ~2 ~-124 ~98 ~3 ~-124 minecraft:light_gray_stained_glass
fill ~89 ~2 ~-121 ~89 ~3 ~-121 minecraft:gray_stained_glass
fill ~98 ~2 ~-121 ~98 ~3 ~-121 minecraft:light_gray_stained_glass
fill ~89 ~2 ~-118 ~89 ~3 ~-118 minecraft:gray_stained_glass
fill ~98 ~2 ~-118 ~98 ~3 ~-118 minecraft:light_gray_stained_glass
setblock ~93 ~1 ~-116 minecraft:iron_door[half=lower,facing=south]
setblock ~93 ~2 ~-116 minecraft:iron_door[half=upper,facing=south]
fill ~89 ~6 ~-126 ~98 ~6 ~-116 minecraft:deepslate_tile_slab
fill ~90 ~7 ~-125 ~97 ~7 ~-117 minecraft:deepslate_tile_slab
setblock ~93 ~3 ~-115 minecraft:dark_oak_slab[type=top]
fill ~90 ~1 ~-116 ~90 ~5 ~-116 minecraft:weathered_cut_copper
fill ~94 ~1 ~-116 ~94 ~5 ~-116 minecraft:weathered_cut_copper
# 007 clinic style=setback_block context=collector_front facing=north
fill ~103 ~-3 ~-64 ~112 ~-1 ~-54 minecraft:stone
fill ~103 ~0 ~-64 ~112 ~7 ~-54 minecraft:bricks
fill ~104 ~1 ~-63 ~111 ~6 ~-55 minecraft:air
fill ~104 ~4 ~-63 ~111 ~4 ~-55 minecraft:smooth_stone
fill ~105 ~2 ~-64 ~105 ~3 ~-64 minecraft:gray_stained_glass
fill ~105 ~2 ~-54 ~105 ~3 ~-54 minecraft:light_gray_stained_glass
fill ~108 ~2 ~-64 ~108 ~3 ~-64 minecraft:gray_stained_glass
fill ~108 ~2 ~-54 ~108 ~3 ~-54 minecraft:light_gray_stained_glass
fill ~103 ~2 ~-62 ~103 ~3 ~-62 minecraft:gray_stained_glass
fill ~112 ~2 ~-62 ~112 ~3 ~-62 minecraft:light_gray_stained_glass
fill ~103 ~2 ~-59 ~103 ~3 ~-59 minecraft:gray_stained_glass
fill ~112 ~2 ~-59 ~112 ~3 ~-59 minecraft:light_gray_stained_glass
fill ~103 ~2 ~-56 ~103 ~3 ~-56 minecraft:gray_stained_glass
fill ~112 ~2 ~-56 ~112 ~3 ~-56 minecraft:light_gray_stained_glass
setblock ~107 ~1 ~-64 minecraft:iron_door[half=lower,facing=north]
setblock ~107 ~2 ~-64 minecraft:iron_door[half=upper,facing=north]
fill ~104 ~1 ~-64 ~104 ~7 ~-64 minecraft:weathered_cut_copper
fill ~108 ~1 ~-64 ~108 ~7 ~-64 minecraft:weathered_cut_copper
# 008 row_house style=japanese_house context=local_front facing=north
fill ~21 ~-3 ~110 ~27 ~-1 ~119 minecraft:stone
fill ~21 ~0 ~110 ~27 ~7 ~119 minecraft:calcite
fill ~22 ~1 ~111 ~26 ~6 ~118 minecraft:air
fill ~22 ~4 ~111 ~26 ~4 ~118 minecraft:smooth_stone
fill ~23 ~2 ~110 ~23 ~3 ~110 minecraft:gray_stained_glass
fill ~23 ~2 ~119 ~23 ~3 ~119 minecraft:light_gray_stained_glass
fill ~21 ~2 ~112 ~21 ~3 ~112 minecraft:gray_stained_glass
fill ~27 ~2 ~112 ~27 ~3 ~112 minecraft:light_gray_stained_glass
fill ~21 ~2 ~115 ~21 ~3 ~115 minecraft:gray_stained_glass
fill ~27 ~2 ~115 ~27 ~3 ~115 minecraft:light_gray_stained_glass
setblock ~24 ~1 ~110 minecraft:iron_door[half=lower,facing=north]
setblock ~24 ~2 ~110 minecraft:iron_door[half=upper,facing=north]
fill ~21 ~8 ~110 ~27 ~8 ~119 minecraft:stone_brick_slab
fill ~22 ~9 ~111 ~26 ~9 ~118 minecraft:stone_brick_slab
setblock ~24 ~3 ~109 minecraft:dark_oak_slab[type=top]
fill ~22 ~1 ~110 ~22 ~7 ~110 minecraft:gray_concrete
fill ~26 ~1 ~110 ~26 ~7 ~110 minecraft:gray_concrete
