# Buildings 65..72
# 065 supermarket style=corner_store context=collector_front facing=north
fill ~69 ~-3 ~30 ~79 ~-1 ~42 minecraft:stone
fill ~69 ~0 ~30 ~79 ~16 ~42 minecraft:bricks
fill ~70 ~1 ~31 ~78 ~15 ~41 minecraft:air
fill ~70 ~4 ~31 ~78 ~4 ~41 minecraft:smooth_stone
fill ~70 ~8 ~31 ~78 ~8 ~41 minecraft:smooth_stone
fill ~70 ~12 ~31 ~78 ~12 ~41 minecraft:smooth_stone
fill ~71 ~2 ~30 ~71 ~3 ~30 minecraft:gray_stained_glass
fill ~71 ~2 ~42 ~71 ~3 ~42 minecraft:light_gray_stained_glass
fill ~74 ~2 ~30 ~74 ~3 ~30 minecraft:gray_stained_glass
fill ~74 ~2 ~42 ~74 ~3 ~42 minecraft:light_gray_stained_glass
fill ~77 ~2 ~30 ~77 ~3 ~30 minecraft:gray_stained_glass
fill ~77 ~2 ~42 ~77 ~3 ~42 minecraft:light_gray_stained_glass
fill ~69 ~2 ~32 ~69 ~3 ~32 minecraft:gray_stained_glass
fill ~79 ~2 ~32 ~79 ~3 ~32 minecraft:light_gray_stained_glass
fill ~69 ~2 ~35 ~69 ~3 ~35 minecraft:gray_stained_glass
fill ~79 ~2 ~35 ~79 ~3 ~35 minecraft:light_gray_stained_glass
fill ~69 ~2 ~38 ~69 ~3 ~38 minecraft:gray_stained_glass
fill ~79 ~2 ~38 ~79 ~3 ~38 minecraft:light_gray_stained_glass
fill ~71 ~6 ~30 ~71 ~7 ~30 minecraft:gray_stained_glass
fill ~71 ~6 ~42 ~71 ~7 ~42 minecraft:light_gray_stained_glass
fill ~74 ~6 ~30 ~74 ~7 ~30 minecraft:gray_stained_glass
fill ~74 ~6 ~42 ~74 ~7 ~42 minecraft:light_gray_stained_glass
fill ~77 ~6 ~30 ~77 ~7 ~30 minecraft:gray_stained_glass
fill ~77 ~6 ~42 ~77 ~7 ~42 minecraft:light_gray_stained_glass
fill ~69 ~6 ~32 ~69 ~7 ~32 minecraft:gray_stained_glass
fill ~79 ~6 ~32 ~79 ~7 ~32 minecraft:light_gray_stained_glass
fill ~69 ~6 ~35 ~69 ~7 ~35 minecraft:gray_stained_glass
fill ~79 ~6 ~35 ~79 ~7 ~35 minecraft:light_gray_stained_glass
fill ~69 ~6 ~38 ~69 ~7 ~38 minecraft:gray_stained_glass
fill ~79 ~6 ~38 ~79 ~7 ~38 minecraft:light_gray_stained_glass
fill ~71 ~10 ~30 ~71 ~11 ~30 minecraft:gray_stained_glass
fill ~71 ~10 ~42 ~71 ~11 ~42 minecraft:light_gray_stained_glass
fill ~74 ~10 ~30 ~74 ~11 ~30 minecraft:gray_stained_glass
fill ~74 ~10 ~42 ~74 ~11 ~42 minecraft:light_gray_stained_glass
fill ~77 ~10 ~30 ~77 ~11 ~30 minecraft:gray_stained_glass
fill ~77 ~10 ~42 ~77 ~11 ~42 minecraft:light_gray_stained_glass
fill ~69 ~10 ~32 ~69 ~11 ~32 minecraft:gray_stained_glass
fill ~79 ~10 ~32 ~79 ~11 ~32 minecraft:light_gray_stained_glass
fill ~69 ~10 ~35 ~69 ~11 ~35 minecraft:gray_stained_glass
fill ~79 ~10 ~35 ~79 ~11 ~35 minecraft:light_gray_stained_glass
fill ~69 ~10 ~38 ~69 ~11 ~38 minecraft:gray_stained_glass
fill ~79 ~10 ~38 ~79 ~11 ~38 minecraft:light_gray_stained_glass
fill ~71 ~14 ~30 ~71 ~15 ~30 minecraft:gray_stained_glass
fill ~71 ~14 ~42 ~71 ~15 ~42 minecraft:light_gray_stained_glass
fill ~74 ~14 ~30 ~74 ~15 ~30 minecraft:gray_stained_glass
fill ~74 ~14 ~42 ~74 ~15 ~42 minecraft:light_gray_stained_glass
fill ~77 ~14 ~30 ~77 ~15 ~30 minecraft:gray_stained_glass
fill ~77 ~14 ~42 ~77 ~15 ~42 minecraft:light_gray_stained_glass
fill ~69 ~14 ~32 ~69 ~15 ~32 minecraft:gray_stained_glass
fill ~79 ~14 ~32 ~79 ~15 ~32 minecraft:light_gray_stained_glass
fill ~69 ~14 ~35 ~69 ~15 ~35 minecraft:gray_stained_glass
fill ~79 ~14 ~35 ~79 ~15 ~35 minecraft:light_gray_stained_glass
fill ~69 ~14 ~38 ~69 ~15 ~38 minecraft:gray_stained_glass
fill ~79 ~14 ~38 ~79 ~15 ~38 minecraft:light_gray_stained_glass
setblock ~74 ~1 ~30 minecraft:iron_door[half=lower,facing=north]
setblock ~74 ~2 ~30 minecraft:iron_door[half=upper,facing=north]
fill ~70 ~1 ~30 ~78 ~3 ~30 minecraft:cyan_stained_glass
setblock ~74 ~1 ~30 minecraft:iron_door[half=lower,facing=north]
setblock ~74 ~2 ~30 minecraft:iron_door[half=upper,facing=north]
setblock ~74 ~3 ~29 minecraft:red_wool
fill ~69 ~17 ~30 ~79 ~17 ~42 minecraft:deepslate_tile_slab
# 066 detached_house style=japanese_house context=local_front facing=north
fill ~-109 ~-3 ~111 ~-104 ~-1 ~119 minecraft:stone
fill ~-109 ~0 ~111 ~-104 ~9 ~119 minecraft:calcite
fill ~-108 ~1 ~112 ~-105 ~8 ~118 minecraft:air
fill ~-108 ~4 ~112 ~-105 ~4 ~118 minecraft:smooth_stone
fill ~-108 ~8 ~112 ~-105 ~8 ~118 minecraft:smooth_stone
fill ~-107 ~2 ~111 ~-107 ~3 ~111 minecraft:gray_stained_glass
fill ~-107 ~2 ~119 ~-107 ~3 ~119 minecraft:light_gray_stained_glass
fill ~-109 ~2 ~113 ~-109 ~3 ~113 minecraft:gray_stained_glass
fill ~-104 ~2 ~113 ~-104 ~3 ~113 minecraft:light_gray_stained_glass
fill ~-109 ~2 ~116 ~-109 ~3 ~116 minecraft:gray_stained_glass
fill ~-104 ~2 ~116 ~-104 ~3 ~116 minecraft:light_gray_stained_glass
fill ~-107 ~6 ~111 ~-107 ~7 ~111 minecraft:gray_stained_glass
fill ~-107 ~6 ~119 ~-107 ~7 ~119 minecraft:light_gray_stained_glass
fill ~-109 ~6 ~113 ~-109 ~7 ~113 minecraft:gray_stained_glass
fill ~-104 ~6 ~113 ~-104 ~7 ~113 minecraft:light_gray_stained_glass
fill ~-109 ~6 ~116 ~-109 ~7 ~116 minecraft:gray_stained_glass
fill ~-104 ~6 ~116 ~-104 ~7 ~116 minecraft:light_gray_stained_glass
setblock ~-107 ~1 ~111 minecraft:iron_door[half=lower,facing=north]
setblock ~-107 ~2 ~111 minecraft:iron_door[half=upper,facing=north]
fill ~-109 ~10 ~111 ~-104 ~10 ~119 minecraft:stone_brick_slab
fill ~-108 ~11 ~112 ~-105 ~11 ~118 minecraft:stone_brick_slab
setblock ~-107 ~3 ~110 minecraft:dark_oak_slab[type=top]
fill ~-107 ~11 ~113 ~-105 ~12 ~115 minecraft:light_gray_concrete
setblock ~-105 ~11 ~114 minecraft:lightning_rod
# 067 garage style=industrial_shed context=local_front facing=east
fill ~63 ~-3 ~-90 ~73 ~-1 ~-81 minecraft:stone
fill ~63 ~0 ~-90 ~73 ~12 ~-81 minecraft:stone_bricks
fill ~64 ~1 ~-89 ~72 ~11 ~-82 minecraft:air
fill ~64 ~4 ~-89 ~72 ~4 ~-82 minecraft:smooth_stone
fill ~64 ~8 ~-89 ~72 ~8 ~-82 minecraft:smooth_stone
fill ~65 ~2 ~-90 ~65 ~3 ~-90 minecraft:gray_stained_glass
fill ~65 ~2 ~-81 ~65 ~3 ~-81 minecraft:light_gray_stained_glass
fill ~68 ~2 ~-90 ~68 ~3 ~-90 minecraft:gray_stained_glass
fill ~68 ~2 ~-81 ~68 ~3 ~-81 minecraft:light_gray_stained_glass
fill ~71 ~2 ~-90 ~71 ~3 ~-90 minecraft:gray_stained_glass
fill ~71 ~2 ~-81 ~71 ~3 ~-81 minecraft:light_gray_stained_glass
fill ~63 ~2 ~-88 ~63 ~3 ~-88 minecraft:gray_stained_glass
fill ~73 ~2 ~-88 ~73 ~3 ~-88 minecraft:light_gray_stained_glass
fill ~63 ~2 ~-85 ~63 ~3 ~-85 minecraft:gray_stained_glass
fill ~73 ~2 ~-85 ~73 ~3 ~-85 minecraft:light_gray_stained_glass
fill ~65 ~6 ~-90 ~65 ~7 ~-90 minecraft:gray_stained_glass
fill ~65 ~6 ~-81 ~65 ~7 ~-81 minecraft:light_gray_stained_glass
fill ~68 ~6 ~-90 ~68 ~7 ~-90 minecraft:gray_stained_glass
fill ~68 ~6 ~-81 ~68 ~7 ~-81 minecraft:light_gray_stained_glass
fill ~71 ~6 ~-90 ~71 ~7 ~-90 minecraft:gray_stained_glass
fill ~71 ~6 ~-81 ~71 ~7 ~-81 minecraft:light_gray_stained_glass
fill ~63 ~6 ~-88 ~63 ~7 ~-88 minecraft:gray_stained_glass
fill ~73 ~6 ~-88 ~73 ~7 ~-88 minecraft:light_gray_stained_glass
fill ~63 ~6 ~-85 ~63 ~7 ~-85 minecraft:gray_stained_glass
fill ~73 ~6 ~-85 ~73 ~7 ~-85 minecraft:light_gray_stained_glass
fill ~65 ~10 ~-90 ~65 ~11 ~-90 minecraft:gray_stained_glass
fill ~65 ~10 ~-81 ~65 ~11 ~-81 minecraft:light_gray_stained_glass
fill ~68 ~10 ~-90 ~68 ~11 ~-90 minecraft:gray_stained_glass
fill ~68 ~10 ~-81 ~68 ~11 ~-81 minecraft:light_gray_stained_glass
fill ~71 ~10 ~-90 ~71 ~11 ~-90 minecraft:gray_stained_glass
fill ~71 ~10 ~-81 ~71 ~11 ~-81 minecraft:light_gray_stained_glass
fill ~63 ~10 ~-88 ~63 ~11 ~-88 minecraft:gray_stained_glass
fill ~73 ~10 ~-88 ~73 ~11 ~-88 minecraft:light_gray_stained_glass
fill ~63 ~10 ~-85 ~63 ~11 ~-85 minecraft:gray_stained_glass
fill ~73 ~10 ~-85 ~73 ~11 ~-85 minecraft:light_gray_stained_glass
setblock ~73 ~1 ~-86 minecraft:iron_door[half=lower,facing=east]
setblock ~73 ~2 ~-86 minecraft:iron_door[half=upper,facing=east]
fill ~73 ~1 ~-88 ~73 ~4 ~-83 minecraft:polished_blackstone
fill ~73 ~5 ~-88 ~73 ~5 ~-83 minecraft:light_blue_stained_glass
fill ~65 ~14 ~-88 ~67 ~15 ~-86 minecraft:iron_block
fill ~63 ~13 ~-90 ~73 ~13 ~-81 minecraft:smooth_stone_slab
# 068 small_office style=civic_modern context=back_block facing=south
fill ~-125 ~-3 ~-58 ~-115 ~-1 ~-50 minecraft:stone
fill ~-125 ~0 ~-58 ~-115 ~7 ~-50 minecraft:calcite
fill ~-124 ~1 ~-57 ~-116 ~6 ~-51 minecraft:air
fill ~-124 ~4 ~-57 ~-116 ~4 ~-51 minecraft:smooth_stone
fill ~-123 ~2 ~-58 ~-123 ~3 ~-58 minecraft:gray_stained_glass
fill ~-123 ~2 ~-50 ~-123 ~3 ~-50 minecraft:light_gray_stained_glass
fill ~-120 ~2 ~-58 ~-120 ~3 ~-58 minecraft:gray_stained_glass
fill ~-120 ~2 ~-50 ~-120 ~3 ~-50 minecraft:light_gray_stained_glass
fill ~-117 ~2 ~-58 ~-117 ~3 ~-58 minecraft:gray_stained_glass
fill ~-117 ~2 ~-50 ~-117 ~3 ~-50 minecraft:light_gray_stained_glass
fill ~-125 ~2 ~-56 ~-125 ~3 ~-56 minecraft:gray_stained_glass
fill ~-115 ~2 ~-56 ~-115 ~3 ~-56 minecraft:light_gray_stained_glass
fill ~-125 ~2 ~-53 ~-125 ~3 ~-53 minecraft:gray_stained_glass
fill ~-115 ~2 ~-53 ~-115 ~3 ~-53 minecraft:light_gray_stained_glass
setblock ~-120 ~1 ~-50 minecraft:iron_door[half=lower,facing=south]
setblock ~-120 ~2 ~-50 minecraft:iron_door[half=upper,facing=south]
# 069 row_house style=rowhouse context=local_front facing=west
fill ~-103 ~-3 ~52 ~-97 ~-1 ~62 minecraft:stone
fill ~-103 ~0 ~52 ~-97 ~7 ~62 minecraft:mud_bricks
fill ~-102 ~1 ~53 ~-98 ~6 ~61 minecraft:air
fill ~-102 ~4 ~53 ~-98 ~4 ~61 minecraft:smooth_stone
fill ~-101 ~2 ~52 ~-101 ~3 ~52 minecraft:gray_stained_glass
fill ~-101 ~2 ~62 ~-101 ~3 ~62 minecraft:light_gray_stained_glass
fill ~-103 ~2 ~54 ~-103 ~3 ~54 minecraft:gray_stained_glass
fill ~-97 ~2 ~54 ~-97 ~3 ~54 minecraft:light_gray_stained_glass
fill ~-103 ~2 ~57 ~-103 ~3 ~57 minecraft:gray_stained_glass
fill ~-97 ~2 ~57 ~-97 ~3 ~57 minecraft:light_gray_stained_glass
fill ~-103 ~2 ~60 ~-103 ~3 ~60 minecraft:gray_stained_glass
fill ~-97 ~2 ~60 ~-97 ~3 ~60 minecraft:light_gray_stained_glass
setblock ~-103 ~1 ~57 minecraft:iron_door[half=lower,facing=west]
setblock ~-103 ~2 ~57 minecraft:iron_door[half=upper,facing=west]
fill ~-103 ~8 ~52 ~-97 ~8 ~62 minecraft:deepslate_tile_slab
fill ~-102 ~9 ~53 ~-98 ~9 ~61 minecraft:deepslate_tile_slab
setblock ~-104 ~3 ~57 minecraft:dark_oak_slab[type=top]
# 070 row_house style=rowhouse context=back_block facing=west
fill ~-4 ~-3 ~-44 ~2 ~-1 ~-35 minecraft:stone
fill ~-4 ~0 ~-44 ~2 ~12 ~-35 minecraft:bricks
fill ~-3 ~1 ~-43 ~1 ~11 ~-36 minecraft:air
fill ~-3 ~4 ~-43 ~1 ~4 ~-36 minecraft:smooth_stone
fill ~-3 ~8 ~-43 ~1 ~8 ~-36 minecraft:smooth_stone
fill ~-2 ~2 ~-44 ~-2 ~3 ~-44 minecraft:gray_stained_glass
fill ~-2 ~2 ~-35 ~-2 ~3 ~-35 minecraft:light_gray_stained_glass
fill ~-4 ~2 ~-42 ~-4 ~3 ~-42 minecraft:gray_stained_glass
fill ~2 ~2 ~-42 ~2 ~3 ~-42 minecraft:light_gray_stained_glass
fill ~-4 ~2 ~-39 ~-4 ~3 ~-39 minecraft:gray_stained_glass
fill ~2 ~2 ~-39 ~2 ~3 ~-39 minecraft:light_gray_stained_glass
fill ~-2 ~6 ~-44 ~-2 ~7 ~-44 minecraft:gray_stained_glass
fill ~-2 ~6 ~-35 ~-2 ~7 ~-35 minecraft:light_gray_stained_glass
fill ~-4 ~6 ~-42 ~-4 ~7 ~-42 minecraft:gray_stained_glass
fill ~2 ~6 ~-42 ~2 ~7 ~-42 minecraft:light_gray_stained_glass
fill ~-4 ~6 ~-39 ~-4 ~7 ~-39 minecraft:gray_stained_glass
fill ~2 ~6 ~-39 ~2 ~7 ~-39 minecraft:light_gray_stained_glass
fill ~-2 ~10 ~-44 ~-2 ~11 ~-44 minecraft:gray_stained_glass
fill ~-2 ~10 ~-35 ~-2 ~11 ~-35 minecraft:light_gray_stained_glass
fill ~-4 ~10 ~-42 ~-4 ~11 ~-42 minecraft:gray_stained_glass
fill ~2 ~10 ~-42 ~2 ~11 ~-42 minecraft:light_gray_stained_glass
fill ~-4 ~10 ~-39 ~-4 ~11 ~-39 minecraft:gray_stained_glass
fill ~2 ~10 ~-39 ~2 ~11 ~-39 minecraft:light_gray_stained_glass
setblock ~-4 ~1 ~-40 minecraft:iron_door[half=lower,facing=west]
setblock ~-4 ~2 ~-40 minecraft:iron_door[half=upper,facing=west]
fill ~-4 ~13 ~-44 ~2 ~13 ~-35 minecraft:deepslate_tile_slab
fill ~-3 ~14 ~-43 ~1 ~14 ~-36 minecraft:deepslate_tile_slab
setblock ~-5 ~3 ~-40 minecraft:dark_oak_slab[type=top]
# 071 detached_house style=stepped_house context=back_block facing=west
fill ~-86 ~-3 ~106 ~-81 ~-1 ~112 minecraft:stone
fill ~-86 ~0 ~106 ~-81 ~5 ~112 minecraft:mud_bricks
fill ~-85 ~1 ~107 ~-82 ~4 ~111 minecraft:air
fill ~-85 ~4 ~107 ~-82 ~4 ~111 minecraft:smooth_stone
fill ~-84 ~2 ~106 ~-84 ~3 ~106 minecraft:gray_stained_glass
fill ~-84 ~2 ~112 ~-84 ~3 ~112 minecraft:light_gray_stained_glass
fill ~-86 ~2 ~108 ~-86 ~3 ~108 minecraft:gray_stained_glass
fill ~-81 ~2 ~108 ~-81 ~3 ~108 minecraft:light_gray_stained_glass
setblock ~-86 ~1 ~109 minecraft:iron_door[half=lower,facing=west]
setblock ~-86 ~2 ~109 minecraft:iron_door[half=upper,facing=west]
fill ~-86 ~6 ~106 ~-81 ~6 ~112 minecraft:deepslate_tile_slab
fill ~-85 ~7 ~107 ~-82 ~7 ~111 minecraft:deepslate_tile_slab
setblock ~-87 ~3 ~109 minecraft:dark_oak_slab[type=top]
# 072 community style=setback_block context=collector_front facing=south
fill ~-6 ~-3 ~76 ~4 ~-1 ~84 minecraft:stone
fill ~-6 ~0 ~76 ~4 ~16 ~84 minecraft:smooth_sandstone
fill ~-5 ~1 ~77 ~3 ~15 ~83 minecraft:air
fill ~-5 ~4 ~77 ~3 ~4 ~83 minecraft:smooth_stone
fill ~-5 ~8 ~77 ~3 ~8 ~83 minecraft:smooth_stone
fill ~-5 ~12 ~77 ~3 ~12 ~83 minecraft:smooth_stone
fill ~-4 ~2 ~76 ~-4 ~3 ~76 minecraft:gray_stained_glass
fill ~-4 ~2 ~84 ~-4 ~3 ~84 minecraft:light_gray_stained_glass
fill ~-1 ~2 ~76 ~-1 ~3 ~76 minecraft:gray_stained_glass
fill ~-1 ~2 ~84 ~-1 ~3 ~84 minecraft:light_gray_stained_glass
fill ~2 ~2 ~76 ~2 ~3 ~76 minecraft:gray_stained_glass
fill ~2 ~2 ~84 ~2 ~3 ~84 minecraft:light_gray_stained_glass
fill ~-6 ~2 ~78 ~-6 ~3 ~78 minecraft:gray_stained_glass
fill ~4 ~2 ~78 ~4 ~3 ~78 minecraft:light_gray_stained_glass
fill ~-6 ~2 ~81 ~-6 ~3 ~81 minecraft:gray_stained_glass
fill ~4 ~2 ~81 ~4 ~3 ~81 minecraft:light_gray_stained_glass
fill ~-4 ~6 ~76 ~-4 ~7 ~76 minecraft:gray_stained_glass
fill ~-4 ~6 ~84 ~-4 ~7 ~84 minecraft:light_gray_stained_glass
fill ~-1 ~6 ~76 ~-1 ~7 ~76 minecraft:gray_stained_glass
fill ~-1 ~6 ~84 ~-1 ~7 ~84 minecraft:light_gray_stained_glass
fill ~2 ~6 ~76 ~2 ~7 ~76 minecraft:gray_stained_glass
fill ~2 ~6 ~84 ~2 ~7 ~84 minecraft:light_gray_stained_glass
fill ~-6 ~6 ~78 ~-6 ~7 ~78 minecraft:gray_stained_glass
fill ~4 ~6 ~78 ~4 ~7 ~78 minecraft:light_gray_stained_glass
fill ~-6 ~6 ~81 ~-6 ~7 ~81 minecraft:gray_stained_glass
fill ~4 ~6 ~81 ~4 ~7 ~81 minecraft:light_gray_stained_glass
fill ~-4 ~10 ~76 ~-4 ~11 ~76 minecraft:gray_stained_glass
fill ~-4 ~10 ~84 ~-4 ~11 ~84 minecraft:light_gray_stained_glass
fill ~-1 ~10 ~76 ~-1 ~11 ~76 minecraft:gray_stained_glass
fill ~-1 ~10 ~84 ~-1 ~11 ~84 minecraft:light_gray_stained_glass
fill ~2 ~10 ~76 ~2 ~11 ~76 minecraft:gray_stained_glass
fill ~2 ~10 ~84 ~2 ~11 ~84 minecraft:light_gray_stained_glass
fill ~-6 ~10 ~78 ~-6 ~11 ~78 minecraft:gray_stained_glass
fill ~4 ~10 ~78 ~4 ~11 ~78 minecraft:light_gray_stained_glass
fill ~-6 ~10 ~81 ~-6 ~11 ~81 minecraft:gray_stained_glass
fill ~4 ~10 ~81 ~4 ~11 ~81 minecraft:light_gray_stained_glass
fill ~-4 ~14 ~76 ~-4 ~15 ~76 minecraft:gray_stained_glass
fill ~-4 ~14 ~84 ~-4 ~15 ~84 minecraft:light_gray_stained_glass
fill ~-1 ~14 ~76 ~-1 ~15 ~76 minecraft:gray_stained_glass
fill ~-1 ~14 ~84 ~-1 ~15 ~84 minecraft:light_gray_stained_glass
fill ~2 ~14 ~76 ~2 ~15 ~76 minecraft:gray_stained_glass
fill ~2 ~14 ~84 ~2 ~15 ~84 minecraft:light_gray_stained_glass
fill ~-6 ~14 ~78 ~-6 ~15 ~78 minecraft:gray_stained_glass
fill ~4 ~14 ~78 ~4 ~15 ~78 minecraft:light_gray_stained_glass
fill ~-6 ~14 ~81 ~-6 ~15 ~81 minecraft:gray_stained_glass
fill ~4 ~14 ~81 ~4 ~15 ~81 minecraft:light_gray_stained_glass
setblock ~-1 ~1 ~84 minecraft:iron_door[half=lower,facing=south]
setblock ~-1 ~2 ~84 minecraft:iron_door[half=upper,facing=south]
fill ~-6 ~11 ~76 ~4 ~16 ~84 minecraft:air
fill ~-5 ~11 ~77 ~3 ~16 ~83 minecraft:smooth_sandstone
fill ~-4 ~12 ~78 ~2 ~15 ~82 minecraft:air
fill ~-5 ~17 ~77 ~3 ~17 ~83 minecraft:stone_brick_slab
fill ~-4 ~18 ~78 ~-2 ~19 ~80 minecraft:light_gray_concrete
setblock ~-1 ~18 ~79 minecraft:lightning_rod
