# Buildings 129..136
# 129 supermarket style=storefront context=collector_front facing=east
fill ~-70 ~-3 ~-54 ~-63 ~-1 ~-45 minecraft:stone
fill ~-70 ~0 ~-54 ~-63 ~8 ~-45 minecraft:light_gray_concrete
fill ~-69 ~1 ~-53 ~-64 ~7 ~-46 minecraft:air
fill ~-69 ~4 ~-53 ~-64 ~4 ~-46 minecraft:smooth_stone
fill ~-68 ~2 ~-54 ~-68 ~3 ~-54 minecraft:gray_stained_glass
fill ~-68 ~2 ~-45 ~-68 ~3 ~-45 minecraft:light_gray_stained_glass
fill ~-65 ~2 ~-54 ~-65 ~3 ~-54 minecraft:gray_stained_glass
fill ~-65 ~2 ~-45 ~-65 ~3 ~-45 minecraft:light_gray_stained_glass
fill ~-70 ~2 ~-52 ~-70 ~3 ~-52 minecraft:gray_stained_glass
fill ~-63 ~2 ~-52 ~-63 ~3 ~-52 minecraft:light_gray_stained_glass
fill ~-70 ~2 ~-49 ~-70 ~3 ~-49 minecraft:gray_stained_glass
fill ~-63 ~2 ~-49 ~-63 ~3 ~-49 minecraft:light_gray_stained_glass
fill ~-68 ~6 ~-54 ~-68 ~7 ~-54 minecraft:gray_stained_glass
fill ~-68 ~6 ~-45 ~-68 ~7 ~-45 minecraft:light_gray_stained_glass
fill ~-65 ~6 ~-54 ~-65 ~7 ~-54 minecraft:gray_stained_glass
fill ~-65 ~6 ~-45 ~-65 ~7 ~-45 minecraft:light_gray_stained_glass
fill ~-70 ~6 ~-52 ~-70 ~7 ~-52 minecraft:gray_stained_glass
fill ~-63 ~6 ~-52 ~-63 ~7 ~-52 minecraft:light_gray_stained_glass
fill ~-70 ~6 ~-49 ~-70 ~7 ~-49 minecraft:gray_stained_glass
fill ~-63 ~6 ~-49 ~-63 ~7 ~-49 minecraft:light_gray_stained_glass
setblock ~-63 ~1 ~-50 minecraft:iron_door[half=lower,facing=east]
setblock ~-63 ~2 ~-50 minecraft:iron_door[half=upper,facing=east]
fill ~-63 ~1 ~-53 ~-63 ~3 ~-46 minecraft:cyan_stained_glass
setblock ~-63 ~1 ~-50 minecraft:iron_door[half=lower,facing=east]
setblock ~-63 ~2 ~-50 minecraft:iron_door[half=upper,facing=east]
setblock ~-62 ~3 ~-50 minecraft:red_wool
fill ~-70 ~9 ~-54 ~-63 ~9 ~-45 minecraft:smooth_stone_slab
fill ~-68 ~10 ~-52 ~-66 ~11 ~-50 minecraft:light_gray_concrete
setblock ~-65 ~10 ~-51 minecraft:lightning_rod
# 130 midrise_housing style=mixed_facade context=collector_front facing=north
fill ~37 ~-3 ~30 ~45 ~-1 ~38 minecraft:stone
fill ~37 ~0 ~30 ~45 ~16 ~38 minecraft:bricks
fill ~38 ~1 ~31 ~44 ~15 ~37 minecraft:air
fill ~38 ~4 ~31 ~44 ~4 ~37 minecraft:smooth_stone
fill ~38 ~8 ~31 ~44 ~8 ~37 minecraft:smooth_stone
fill ~38 ~12 ~31 ~44 ~12 ~37 minecraft:smooth_stone
fill ~39 ~2 ~30 ~39 ~3 ~30 minecraft:gray_stained_glass
fill ~39 ~2 ~38 ~39 ~3 ~38 minecraft:light_gray_stained_glass
fill ~42 ~2 ~30 ~42 ~3 ~30 minecraft:gray_stained_glass
fill ~42 ~2 ~38 ~42 ~3 ~38 minecraft:light_gray_stained_glass
fill ~37 ~2 ~32 ~37 ~3 ~32 minecraft:gray_stained_glass
fill ~45 ~2 ~32 ~45 ~3 ~32 minecraft:light_gray_stained_glass
fill ~37 ~2 ~35 ~37 ~3 ~35 minecraft:gray_stained_glass
fill ~45 ~2 ~35 ~45 ~3 ~35 minecraft:light_gray_stained_glass
fill ~39 ~6 ~30 ~39 ~7 ~30 minecraft:gray_stained_glass
fill ~39 ~6 ~38 ~39 ~7 ~38 minecraft:light_gray_stained_glass
fill ~42 ~6 ~30 ~42 ~7 ~30 minecraft:gray_stained_glass
fill ~42 ~6 ~38 ~42 ~7 ~38 minecraft:light_gray_stained_glass
fill ~37 ~6 ~32 ~37 ~7 ~32 minecraft:gray_stained_glass
fill ~45 ~6 ~32 ~45 ~7 ~32 minecraft:light_gray_stained_glass
fill ~37 ~6 ~35 ~37 ~7 ~35 minecraft:gray_stained_glass
fill ~45 ~6 ~35 ~45 ~7 ~35 minecraft:light_gray_stained_glass
fill ~39 ~10 ~30 ~39 ~11 ~30 minecraft:gray_stained_glass
fill ~39 ~10 ~38 ~39 ~11 ~38 minecraft:light_gray_stained_glass
fill ~42 ~10 ~30 ~42 ~11 ~30 minecraft:gray_stained_glass
fill ~42 ~10 ~38 ~42 ~11 ~38 minecraft:light_gray_stained_glass
fill ~37 ~10 ~32 ~37 ~11 ~32 minecraft:gray_stained_glass
fill ~45 ~10 ~32 ~45 ~11 ~32 minecraft:light_gray_stained_glass
fill ~37 ~10 ~35 ~37 ~11 ~35 minecraft:gray_stained_glass
fill ~45 ~10 ~35 ~45 ~11 ~35 minecraft:light_gray_stained_glass
fill ~39 ~14 ~30 ~39 ~15 ~30 minecraft:gray_stained_glass
fill ~39 ~14 ~38 ~39 ~15 ~38 minecraft:light_gray_stained_glass
fill ~42 ~14 ~30 ~42 ~15 ~30 minecraft:gray_stained_glass
fill ~42 ~14 ~38 ~42 ~15 ~38 minecraft:light_gray_stained_glass
fill ~37 ~14 ~32 ~37 ~15 ~32 minecraft:gray_stained_glass
fill ~45 ~14 ~32 ~45 ~15 ~32 minecraft:light_gray_stained_glass
fill ~37 ~14 ~35 ~37 ~15 ~35 minecraft:gray_stained_glass
fill ~45 ~14 ~35 ~45 ~15 ~35 minecraft:light_gray_stained_glass
setblock ~41 ~1 ~30 minecraft:iron_door[half=lower,facing=north]
setblock ~41 ~2 ~30 minecraft:iron_door[half=upper,facing=north]
fill ~37 ~17 ~30 ~45 ~17 ~38 minecraft:deepslate_tile_slab
# 131 shop_house style=storefront context=collector_front facing=north
fill ~-50 ~-3 ~-54 ~-44 ~-1 ~-46 minecraft:stone
fill ~-50 ~0 ~-54 ~-44 ~8 ~-46 minecraft:light_gray_concrete
fill ~-49 ~1 ~-53 ~-45 ~7 ~-47 minecraft:air
fill ~-49 ~4 ~-53 ~-45 ~4 ~-47 minecraft:smooth_stone
fill ~-48 ~2 ~-54 ~-48 ~3 ~-54 minecraft:gray_stained_glass
fill ~-48 ~2 ~-46 ~-48 ~3 ~-46 minecraft:light_gray_stained_glass
fill ~-50 ~2 ~-52 ~-50 ~3 ~-52 minecraft:gray_stained_glass
fill ~-44 ~2 ~-52 ~-44 ~3 ~-52 minecraft:light_gray_stained_glass
fill ~-50 ~2 ~-49 ~-50 ~3 ~-49 minecraft:gray_stained_glass
fill ~-44 ~2 ~-49 ~-44 ~3 ~-49 minecraft:light_gray_stained_glass
fill ~-48 ~6 ~-54 ~-48 ~7 ~-54 minecraft:gray_stained_glass
fill ~-48 ~6 ~-46 ~-48 ~7 ~-46 minecraft:light_gray_stained_glass
fill ~-50 ~6 ~-52 ~-50 ~7 ~-52 minecraft:gray_stained_glass
fill ~-44 ~6 ~-52 ~-44 ~7 ~-52 minecraft:light_gray_stained_glass
fill ~-50 ~6 ~-49 ~-50 ~7 ~-49 minecraft:gray_stained_glass
fill ~-44 ~6 ~-49 ~-44 ~7 ~-49 minecraft:light_gray_stained_glass
setblock ~-47 ~1 ~-54 minecraft:iron_door[half=lower,facing=north]
setblock ~-47 ~2 ~-54 minecraft:iron_door[half=upper,facing=north]
fill ~-49 ~1 ~-54 ~-45 ~3 ~-54 minecraft:cyan_stained_glass
setblock ~-47 ~1 ~-54 minecraft:iron_door[half=lower,facing=north]
setblock ~-47 ~2 ~-54 minecraft:iron_door[half=upper,facing=north]
setblock ~-47 ~3 ~-55 minecraft:red_wool
fill ~-50 ~9 ~-54 ~-44 ~9 ~-46 minecraft:smooth_stone_slab
# 132 fish_market style=setback_block context=waterfront_front facing=west
fill ~92 ~-3 ~97 ~97 ~-1 ~103 minecraft:stone
fill ~92 ~0 ~97 ~97 ~5 ~103 minecraft:bricks
fill ~93 ~1 ~98 ~96 ~4 ~102 minecraft:air
fill ~93 ~4 ~98 ~96 ~4 ~102 minecraft:smooth_stone
fill ~94 ~2 ~97 ~94 ~3 ~97 minecraft:gray_stained_glass
fill ~94 ~2 ~103 ~94 ~3 ~103 minecraft:light_gray_stained_glass
fill ~92 ~2 ~99 ~92 ~3 ~99 minecraft:gray_stained_glass
fill ~97 ~2 ~99 ~97 ~3 ~99 minecraft:light_gray_stained_glass
setblock ~92 ~1 ~100 minecraft:iron_door[half=lower,facing=west]
setblock ~92 ~2 ~100 minecraft:iron_door[half=upper,facing=west]
# 133 port_warehouse style=sawtooth context=waterfront_front facing=west
fill ~102 ~-3 ~-16 ~107 ~-1 ~-6 minecraft:stone
fill ~102 ~0 ~-16 ~107 ~7 ~-6 minecraft:bricks
fill ~103 ~1 ~-15 ~106 ~6 ~-7 minecraft:air
fill ~103 ~4 ~-15 ~106 ~4 ~-7 minecraft:smooth_stone
fill ~104 ~2 ~-16 ~104 ~3 ~-16 minecraft:gray_stained_glass
fill ~104 ~2 ~-6 ~104 ~3 ~-6 minecraft:light_gray_stained_glass
fill ~102 ~2 ~-14 ~102 ~3 ~-14 minecraft:gray_stained_glass
fill ~107 ~2 ~-14 ~107 ~3 ~-14 minecraft:light_gray_stained_glass
fill ~102 ~2 ~-11 ~102 ~3 ~-11 minecraft:gray_stained_glass
fill ~107 ~2 ~-11 ~107 ~3 ~-11 minecraft:light_gray_stained_glass
fill ~102 ~2 ~-8 ~102 ~3 ~-8 minecraft:gray_stained_glass
fill ~107 ~2 ~-8 ~107 ~3 ~-8 minecraft:light_gray_stained_glass
setblock ~102 ~1 ~-11 minecraft:iron_door[half=lower,facing=west]
setblock ~102 ~2 ~-11 minecraft:iron_door[half=upper,facing=west]
fill ~102 ~1 ~-14 ~102 ~4 ~-8 minecraft:polished_blackstone
fill ~102 ~5 ~-14 ~102 ~5 ~-8 minecraft:light_blue_stained_glass
fill ~104 ~9 ~-14 ~106 ~10 ~-12 minecraft:iron_block
fill ~102 ~8 ~-16 ~107 ~8 ~-6 minecraft:deepslate_tile_slab
# 134 utility style=sawtooth context=waterfront_front facing=south
fill ~84 ~-3 ~-120 ~94 ~-1 ~-111 minecraft:stone
fill ~84 ~0 ~-120 ~94 ~8 ~-111 minecraft:stone_bricks
fill ~85 ~1 ~-119 ~93 ~7 ~-112 minecraft:air
fill ~85 ~4 ~-119 ~93 ~4 ~-112 minecraft:smooth_stone
fill ~86 ~2 ~-120 ~86 ~3 ~-120 minecraft:gray_stained_glass
fill ~86 ~2 ~-111 ~86 ~3 ~-111 minecraft:light_gray_stained_glass
fill ~89 ~2 ~-120 ~89 ~3 ~-120 minecraft:gray_stained_glass
fill ~89 ~2 ~-111 ~89 ~3 ~-111 minecraft:light_gray_stained_glass
fill ~92 ~2 ~-120 ~92 ~3 ~-120 minecraft:gray_stained_glass
fill ~92 ~2 ~-111 ~92 ~3 ~-111 minecraft:light_gray_stained_glass
fill ~84 ~2 ~-118 ~84 ~3 ~-118 minecraft:gray_stained_glass
fill ~94 ~2 ~-118 ~94 ~3 ~-118 minecraft:light_gray_stained_glass
fill ~84 ~2 ~-115 ~84 ~3 ~-115 minecraft:gray_stained_glass
fill ~94 ~2 ~-115 ~94 ~3 ~-115 minecraft:light_gray_stained_glass
fill ~86 ~6 ~-120 ~86 ~7 ~-120 minecraft:gray_stained_glass
fill ~86 ~6 ~-111 ~86 ~7 ~-111 minecraft:light_gray_stained_glass
fill ~89 ~6 ~-120 ~89 ~7 ~-120 minecraft:gray_stained_glass
fill ~89 ~6 ~-111 ~89 ~7 ~-111 minecraft:light_gray_stained_glass
fill ~92 ~6 ~-120 ~92 ~7 ~-120 minecraft:gray_stained_glass
fill ~92 ~6 ~-111 ~92 ~7 ~-111 minecraft:light_gray_stained_glass
fill ~84 ~6 ~-118 ~84 ~7 ~-118 minecraft:gray_stained_glass
fill ~94 ~6 ~-118 ~94 ~7 ~-118 minecraft:light_gray_stained_glass
fill ~84 ~6 ~-115 ~84 ~7 ~-115 minecraft:gray_stained_glass
fill ~94 ~6 ~-115 ~94 ~7 ~-115 minecraft:light_gray_stained_glass
setblock ~89 ~1 ~-111 minecraft:iron_door[half=lower,facing=south]
setblock ~89 ~2 ~-111 minecraft:iron_door[half=upper,facing=south]
fill ~86 ~1 ~-111 ~92 ~4 ~-111 minecraft:polished_blackstone
fill ~86 ~5 ~-111 ~92 ~5 ~-111 minecraft:light_blue_stained_glass
fill ~86 ~10 ~-118 ~88 ~11 ~-116 minecraft:iron_block
fill ~84 ~9 ~-120 ~94 ~9 ~-111 minecraft:smooth_stone_slab
# 135 fish_market style=mixed_facade context=waterfront_front facing=west
fill ~87 ~-3 ~-80 ~95 ~-1 ~-74 minecraft:stone
fill ~87 ~0 ~-80 ~95 ~5 ~-74 minecraft:calcite
fill ~88 ~1 ~-79 ~94 ~4 ~-75 minecraft:air
fill ~88 ~4 ~-79 ~94 ~4 ~-75 minecraft:smooth_stone
fill ~89 ~2 ~-80 ~89 ~3 ~-80 minecraft:gray_stained_glass
fill ~89 ~2 ~-74 ~89 ~3 ~-74 minecraft:light_gray_stained_glass
fill ~92 ~2 ~-80 ~92 ~3 ~-80 minecraft:gray_stained_glass
fill ~92 ~2 ~-74 ~92 ~3 ~-74 minecraft:light_gray_stained_glass
fill ~87 ~2 ~-78 ~87 ~3 ~-78 minecraft:gray_stained_glass
fill ~95 ~2 ~-78 ~95 ~3 ~-78 minecraft:light_gray_stained_glass
setblock ~87 ~1 ~-77 minecraft:iron_door[half=lower,facing=west]
setblock ~87 ~2 ~-77 minecraft:iron_door[half=upper,facing=west]
fill ~87 ~6 ~-80 ~95 ~6 ~-74 minecraft:stone_brick_slab
# 136 detached_house style=rowhouse context=local_front facing=north
fill ~-92 ~-3 ~99 ~-87 ~-1 ~112 minecraft:stone
fill ~-92 ~0 ~99 ~-87 ~11 ~112 minecraft:mud_bricks
fill ~-91 ~1 ~100 ~-88 ~10 ~111 minecraft:air
fill ~-91 ~4 ~100 ~-88 ~4 ~111 minecraft:smooth_stone
fill ~-91 ~8 ~100 ~-88 ~8 ~111 minecraft:smooth_stone
fill ~-90 ~2 ~99 ~-90 ~3 ~99 minecraft:gray_stained_glass
fill ~-90 ~2 ~112 ~-90 ~3 ~112 minecraft:light_gray_stained_glass
fill ~-92 ~2 ~101 ~-92 ~3 ~101 minecraft:gray_stained_glass
fill ~-87 ~2 ~101 ~-87 ~3 ~101 minecraft:light_gray_stained_glass
fill ~-92 ~2 ~104 ~-92 ~3 ~104 minecraft:gray_stained_glass
fill ~-87 ~2 ~104 ~-87 ~3 ~104 minecraft:light_gray_stained_glass
fill ~-92 ~2 ~107 ~-92 ~3 ~107 minecraft:gray_stained_glass
fill ~-87 ~2 ~107 ~-87 ~3 ~107 minecraft:light_gray_stained_glass
fill ~-92 ~2 ~110 ~-92 ~3 ~110 minecraft:gray_stained_glass
fill ~-87 ~2 ~110 ~-87 ~3 ~110 minecraft:light_gray_stained_glass
fill ~-90 ~6 ~99 ~-90 ~7 ~99 minecraft:gray_stained_glass
fill ~-90 ~6 ~112 ~-90 ~7 ~112 minecraft:light_gray_stained_glass
fill ~-92 ~6 ~101 ~-92 ~7 ~101 minecraft:gray_stained_glass
fill ~-87 ~6 ~101 ~-87 ~7 ~101 minecraft:light_gray_stained_glass
fill ~-92 ~6 ~104 ~-92 ~7 ~104 minecraft:gray_stained_glass
fill ~-87 ~6 ~104 ~-87 ~7 ~104 minecraft:light_gray_stained_glass
fill ~-92 ~6 ~107 ~-92 ~7 ~107 minecraft:gray_stained_glass
fill ~-87 ~6 ~107 ~-87 ~7 ~107 minecraft:light_gray_stained_glass
fill ~-92 ~6 ~110 ~-92 ~7 ~110 minecraft:gray_stained_glass
fill ~-87 ~6 ~110 ~-87 ~7 ~110 minecraft:light_gray_stained_glass
setblock ~-90 ~1 ~99 minecraft:iron_door[half=lower,facing=north]
setblock ~-90 ~2 ~99 minecraft:iron_door[half=upper,facing=north]
fill ~-92 ~12 ~99 ~-87 ~12 ~112 minecraft:deepslate_tile_slab
fill ~-91 ~13 ~100 ~-88 ~13 ~111 minecraft:deepslate_tile_slab
setblock ~-90 ~3 ~98 minecraft:dark_oak_slab[type=top]
