# Buildings 97..104
# 097 restaurant style=corner_store context=collector_front facing=east
fill ~-71 ~-3 ~-81 ~-65 ~-1 ~-74 minecraft:stone
fill ~-71 ~0 ~-81 ~-65 ~7 ~-74 minecraft:calcite
fill ~-70 ~1 ~-80 ~-66 ~6 ~-75 minecraft:air
fill ~-70 ~4 ~-80 ~-66 ~4 ~-75 minecraft:smooth_stone
fill ~-69 ~2 ~-81 ~-69 ~3 ~-81 minecraft:gray_stained_glass
fill ~-69 ~2 ~-74 ~-69 ~3 ~-74 minecraft:light_gray_stained_glass
fill ~-71 ~2 ~-79 ~-71 ~3 ~-79 minecraft:gray_stained_glass
fill ~-65 ~2 ~-79 ~-65 ~3 ~-79 minecraft:light_gray_stained_glass
fill ~-71 ~2 ~-76 ~-71 ~3 ~-76 minecraft:gray_stained_glass
fill ~-65 ~2 ~-76 ~-65 ~3 ~-76 minecraft:light_gray_stained_glass
setblock ~-65 ~1 ~-78 minecraft:iron_door[half=lower,facing=east]
setblock ~-65 ~2 ~-78 minecraft:iron_door[half=upper,facing=east]
fill ~-65 ~1 ~-80 ~-65 ~3 ~-75 minecraft:cyan_stained_glass
setblock ~-65 ~1 ~-78 minecraft:iron_door[half=lower,facing=east]
setblock ~-65 ~2 ~-78 minecraft:iron_door[half=upper,facing=east]
setblock ~-64 ~3 ~-78 minecraft:red_wool
fill ~-71 ~8 ~-81 ~-65 ~8 ~-74 minecraft:stone_brick_slab
# 098 restaurant style=storefront context=collector_front facing=north
fill ~-106 ~-3 ~24 ~-101 ~-1 ~32 minecraft:stone
fill ~-106 ~0 ~24 ~-101 ~7 ~32 minecraft:calcite
fill ~-105 ~1 ~25 ~-102 ~6 ~31 minecraft:air
fill ~-105 ~4 ~25 ~-102 ~4 ~31 minecraft:smooth_stone
fill ~-104 ~2 ~24 ~-104 ~3 ~24 minecraft:gray_stained_glass
fill ~-104 ~2 ~32 ~-104 ~3 ~32 minecraft:light_gray_stained_glass
fill ~-106 ~2 ~26 ~-106 ~3 ~26 minecraft:gray_stained_glass
fill ~-101 ~2 ~26 ~-101 ~3 ~26 minecraft:light_gray_stained_glass
fill ~-106 ~2 ~29 ~-106 ~3 ~29 minecraft:gray_stained_glass
fill ~-101 ~2 ~29 ~-101 ~3 ~29 minecraft:light_gray_stained_glass
setblock ~-104 ~1 ~24 minecraft:iron_door[half=lower,facing=north]
setblock ~-104 ~2 ~24 minecraft:iron_door[half=upper,facing=north]
fill ~-105 ~1 ~24 ~-102 ~3 ~24 minecraft:cyan_stained_glass
setblock ~-104 ~1 ~24 minecraft:iron_door[half=lower,facing=north]
setblock ~-104 ~2 ~24 minecraft:iron_door[half=upper,facing=north]
setblock ~-104 ~3 ~23 minecraft:red_wool
fill ~-106 ~8 ~24 ~-101 ~8 ~32 minecraft:stone_brick_slab
# 099 restaurant style=arcade_shop context=collector_front facing=north
fill ~-40 ~-3 ~33 ~-28 ~-1 ~42 minecraft:stone
fill ~-40 ~0 ~33 ~-28 ~12 ~42 minecraft:light_gray_concrete
fill ~-39 ~1 ~34 ~-29 ~11 ~41 minecraft:air
fill ~-39 ~4 ~34 ~-29 ~4 ~41 minecraft:smooth_stone
fill ~-39 ~8 ~34 ~-29 ~8 ~41 minecraft:smooth_stone
fill ~-38 ~2 ~33 ~-38 ~3 ~33 minecraft:gray_stained_glass
fill ~-38 ~2 ~42 ~-38 ~3 ~42 minecraft:light_gray_stained_glass
fill ~-35 ~2 ~33 ~-35 ~3 ~33 minecraft:gray_stained_glass
fill ~-35 ~2 ~42 ~-35 ~3 ~42 minecraft:light_gray_stained_glass
fill ~-32 ~2 ~33 ~-32 ~3 ~33 minecraft:gray_stained_glass
fill ~-32 ~2 ~42 ~-32 ~3 ~42 minecraft:light_gray_stained_glass
fill ~-40 ~2 ~35 ~-40 ~3 ~35 minecraft:gray_stained_glass
fill ~-28 ~2 ~35 ~-28 ~3 ~35 minecraft:light_gray_stained_glass
fill ~-40 ~2 ~38 ~-40 ~3 ~38 minecraft:gray_stained_glass
fill ~-28 ~2 ~38 ~-28 ~3 ~38 minecraft:light_gray_stained_glass
fill ~-38 ~6 ~33 ~-38 ~7 ~33 minecraft:gray_stained_glass
fill ~-38 ~6 ~42 ~-38 ~7 ~42 minecraft:light_gray_stained_glass
fill ~-35 ~6 ~33 ~-35 ~7 ~33 minecraft:gray_stained_glass
fill ~-35 ~6 ~42 ~-35 ~7 ~42 minecraft:light_gray_stained_glass
fill ~-32 ~6 ~33 ~-32 ~7 ~33 minecraft:gray_stained_glass
fill ~-32 ~6 ~42 ~-32 ~7 ~42 minecraft:light_gray_stained_glass
fill ~-40 ~6 ~35 ~-40 ~7 ~35 minecraft:gray_stained_glass
fill ~-28 ~6 ~35 ~-28 ~7 ~35 minecraft:light_gray_stained_glass
fill ~-40 ~6 ~38 ~-40 ~7 ~38 minecraft:gray_stained_glass
fill ~-28 ~6 ~38 ~-28 ~7 ~38 minecraft:light_gray_stained_glass
fill ~-38 ~10 ~33 ~-38 ~11 ~33 minecraft:gray_stained_glass
fill ~-38 ~10 ~42 ~-38 ~11 ~42 minecraft:light_gray_stained_glass
fill ~-35 ~10 ~33 ~-35 ~11 ~33 minecraft:gray_stained_glass
fill ~-35 ~10 ~42 ~-35 ~11 ~42 minecraft:light_gray_stained_glass
fill ~-32 ~10 ~33 ~-32 ~11 ~33 minecraft:gray_stained_glass
fill ~-32 ~10 ~42 ~-32 ~11 ~42 minecraft:light_gray_stained_glass
fill ~-40 ~10 ~35 ~-40 ~11 ~35 minecraft:gray_stained_glass
fill ~-28 ~10 ~35 ~-28 ~11 ~35 minecraft:light_gray_stained_glass
fill ~-40 ~10 ~38 ~-40 ~11 ~38 minecraft:gray_stained_glass
fill ~-28 ~10 ~38 ~-28 ~11 ~38 minecraft:light_gray_stained_glass
setblock ~-35 ~1 ~33 minecraft:iron_door[half=lower,facing=north]
setblock ~-35 ~2 ~33 minecraft:iron_door[half=upper,facing=north]
fill ~-39 ~1 ~33 ~-29 ~3 ~33 minecraft:cyan_stained_glass
setblock ~-35 ~1 ~33 minecraft:iron_door[half=lower,facing=north]
setblock ~-35 ~2 ~33 minecraft:iron_door[half=upper,facing=north]
setblock ~-35 ~3 ~32 minecraft:red_wool
fill ~-39 ~4 ~33 ~-29 ~4 ~33 doomsday_decoration:cementwall
fill ~-40 ~13 ~33 ~-28 ~13 ~42 minecraft:smooth_stone_slab
fill ~-38 ~14 ~35 ~-36 ~15 ~37 minecraft:light_gray_concrete
setblock ~-35 ~14 ~36 minecraft:lightning_rod
# 100 office style=setback_tower context=arterial_front facing=south
fill ~-109 ~-3 ~-56 ~-100 ~-1 ~-47 minecraft:stone
fill ~-109 ~0 ~-56 ~-100 ~7 ~-47 minecraft:calcite
fill ~-108 ~1 ~-55 ~-101 ~6 ~-48 minecraft:air
fill ~-108 ~4 ~-55 ~-101 ~4 ~-48 minecraft:smooth_stone
fill ~-107 ~2 ~-56 ~-107 ~3 ~-56 minecraft:gray_stained_glass
fill ~-107 ~2 ~-47 ~-107 ~3 ~-47 minecraft:light_gray_stained_glass
fill ~-104 ~2 ~-56 ~-104 ~3 ~-56 minecraft:gray_stained_glass
fill ~-104 ~2 ~-47 ~-104 ~3 ~-47 minecraft:light_gray_stained_glass
fill ~-109 ~2 ~-54 ~-109 ~3 ~-54 minecraft:gray_stained_glass
fill ~-100 ~2 ~-54 ~-100 ~3 ~-54 minecraft:light_gray_stained_glass
fill ~-109 ~2 ~-51 ~-109 ~3 ~-51 minecraft:gray_stained_glass
fill ~-100 ~2 ~-51 ~-100 ~3 ~-51 minecraft:light_gray_stained_glass
setblock ~-105 ~1 ~-47 minecraft:iron_door[half=lower,facing=south]
setblock ~-105 ~2 ~-47 minecraft:iron_door[half=upper,facing=south]
# 101 waterfront_hotel style=civic_modern context=waterfront_front facing=south
fill ~93 ~-3 ~-52 ~98 ~-1 ~-42 minecraft:stone
fill ~93 ~0 ~-52 ~98 ~5 ~-42 minecraft:bricks
fill ~94 ~1 ~-51 ~97 ~4 ~-43 minecraft:air
fill ~94 ~4 ~-51 ~97 ~4 ~-43 minecraft:smooth_stone
fill ~95 ~2 ~-52 ~95 ~3 ~-52 minecraft:gray_stained_glass
fill ~95 ~2 ~-42 ~95 ~3 ~-42 minecraft:light_gray_stained_glass
fill ~93 ~2 ~-50 ~93 ~3 ~-50 minecraft:gray_stained_glass
fill ~98 ~2 ~-50 ~98 ~3 ~-50 minecraft:light_gray_stained_glass
fill ~93 ~2 ~-47 ~93 ~3 ~-47 minecraft:gray_stained_glass
fill ~98 ~2 ~-47 ~98 ~3 ~-47 minecraft:light_gray_stained_glass
fill ~93 ~2 ~-44 ~93 ~3 ~-44 minecraft:gray_stained_glass
fill ~98 ~2 ~-44 ~98 ~3 ~-44 minecraft:light_gray_stained_glass
setblock ~95 ~1 ~-42 minecraft:iron_door[half=lower,facing=south]
setblock ~95 ~2 ~-42 minecraft:iron_door[half=upper,facing=south]
# 102 small_office style=bay_office context=back_block facing=north
fill ~-31 ~-3 ~115 ~-21 ~-1 ~122 minecraft:stone
fill ~-31 ~0 ~115 ~-21 ~11 ~122 minecraft:calcite
fill ~-30 ~1 ~116 ~-22 ~10 ~121 minecraft:air
fill ~-30 ~4 ~116 ~-22 ~4 ~121 minecraft:smooth_stone
fill ~-30 ~8 ~116 ~-22 ~8 ~121 minecraft:smooth_stone
fill ~-29 ~2 ~115 ~-29 ~3 ~115 minecraft:gray_stained_glass
fill ~-29 ~2 ~122 ~-29 ~3 ~122 minecraft:light_gray_stained_glass
fill ~-26 ~2 ~115 ~-26 ~3 ~115 minecraft:gray_stained_glass
fill ~-26 ~2 ~122 ~-26 ~3 ~122 minecraft:light_gray_stained_glass
fill ~-23 ~2 ~115 ~-23 ~3 ~115 minecraft:gray_stained_glass
fill ~-23 ~2 ~122 ~-23 ~3 ~122 minecraft:light_gray_stained_glass
fill ~-31 ~2 ~117 ~-31 ~3 ~117 minecraft:gray_stained_glass
fill ~-21 ~2 ~117 ~-21 ~3 ~117 minecraft:light_gray_stained_glass
fill ~-31 ~2 ~120 ~-31 ~3 ~120 minecraft:gray_stained_glass
fill ~-21 ~2 ~120 ~-21 ~3 ~120 minecraft:light_gray_stained_glass
fill ~-29 ~6 ~115 ~-29 ~7 ~115 minecraft:gray_stained_glass
fill ~-29 ~6 ~122 ~-29 ~7 ~122 minecraft:light_gray_stained_glass
fill ~-26 ~6 ~115 ~-26 ~7 ~115 minecraft:gray_stained_glass
fill ~-26 ~6 ~122 ~-26 ~7 ~122 minecraft:light_gray_stained_glass
fill ~-23 ~6 ~115 ~-23 ~7 ~115 minecraft:gray_stained_glass
fill ~-23 ~6 ~122 ~-23 ~7 ~122 minecraft:light_gray_stained_glass
fill ~-31 ~6 ~117 ~-31 ~7 ~117 minecraft:gray_stained_glass
fill ~-21 ~6 ~117 ~-21 ~7 ~117 minecraft:light_gray_stained_glass
fill ~-31 ~6 ~120 ~-31 ~7 ~120 minecraft:gray_stained_glass
fill ~-21 ~6 ~120 ~-21 ~7 ~120 minecraft:light_gray_stained_glass
setblock ~-26 ~1 ~115 minecraft:iron_door[half=lower,facing=north]
setblock ~-26 ~2 ~115 minecraft:iron_door[half=upper,facing=north]
fill ~-31 ~7 ~115 ~-21 ~11 ~122 minecraft:air
fill ~-30 ~7 ~116 ~-22 ~11 ~121 minecraft:calcite
fill ~-29 ~8 ~117 ~-23 ~10 ~120 minecraft:air
fill ~-30 ~12 ~116 ~-22 ~12 ~121 minecraft:stone_brick_slab
fill ~-29 ~2 ~115 ~-23 ~7 ~115 minecraft:blue_stained_glass
fill ~-29 ~13 ~117 ~-27 ~14 ~119 minecraft:light_gray_concrete
setblock ~-26 ~13 ~118 minecraft:lightning_rod
# 103 row_house style=stepped_house context=local_front facing=north
fill ~-31 ~-3 ~99 ~-26 ~-1 ~105 minecraft:stone
fill ~-31 ~0 ~99 ~-26 ~5 ~105 minecraft:calcite
fill ~-30 ~1 ~100 ~-27 ~4 ~104 minecraft:air
fill ~-30 ~4 ~100 ~-27 ~4 ~104 minecraft:smooth_stone
fill ~-29 ~2 ~99 ~-29 ~3 ~99 minecraft:gray_stained_glass
fill ~-29 ~2 ~105 ~-29 ~3 ~105 minecraft:light_gray_stained_glass
fill ~-31 ~2 ~101 ~-31 ~3 ~101 minecraft:gray_stained_glass
fill ~-26 ~2 ~101 ~-26 ~3 ~101 minecraft:light_gray_stained_glass
setblock ~-29 ~1 ~99 minecraft:iron_door[half=lower,facing=north]
setblock ~-29 ~2 ~99 minecraft:iron_door[half=upper,facing=north]
fill ~-31 ~6 ~99 ~-26 ~6 ~105 minecraft:stone_brick_slab
fill ~-30 ~7 ~100 ~-27 ~7 ~104 minecraft:stone_brick_slab
setblock ~-29 ~3 ~98 minecraft:dark_oak_slab[type=top]
# 104 workshop style=sawtooth context=local_front facing=south
fill ~-110 ~-3 ~-20 ~-103 ~-1 ~-13 minecraft:stone
fill ~-110 ~0 ~-20 ~-103 ~5 ~-13 minecraft:calcite
fill ~-109 ~1 ~-19 ~-104 ~4 ~-14 minecraft:air
fill ~-109 ~4 ~-19 ~-104 ~4 ~-14 minecraft:smooth_stone
fill ~-108 ~2 ~-20 ~-108 ~3 ~-20 minecraft:gray_stained_glass
fill ~-108 ~2 ~-13 ~-108 ~3 ~-13 minecraft:light_gray_stained_glass
fill ~-105 ~2 ~-20 ~-105 ~3 ~-20 minecraft:gray_stained_glass
fill ~-105 ~2 ~-13 ~-105 ~3 ~-13 minecraft:light_gray_stained_glass
fill ~-110 ~2 ~-18 ~-110 ~3 ~-18 minecraft:gray_stained_glass
fill ~-103 ~2 ~-18 ~-103 ~3 ~-18 minecraft:light_gray_stained_glass
fill ~-110 ~2 ~-15 ~-110 ~3 ~-15 minecraft:gray_stained_glass
fill ~-103 ~2 ~-15 ~-103 ~3 ~-15 minecraft:light_gray_stained_glass
setblock ~-107 ~1 ~-13 minecraft:iron_door[half=lower,facing=south]
setblock ~-107 ~2 ~-13 minecraft:iron_door[half=upper,facing=south]
fill ~-108 ~1 ~-13 ~-105 ~4 ~-13 minecraft:polished_blackstone
fill ~-108 ~4 ~-13 ~-105 ~4 ~-13 minecraft:light_blue_stained_glass
fill ~-108 ~7 ~-18 ~-106 ~8 ~-16 minecraft:iron_block
fill ~-110 ~6 ~-20 ~-103 ~6 ~-13 minecraft:stone_brick_slab
