# Buildings 289..291
# 289 small_office style=storefront context=back_block facing=north
fill ~-126 ~-3 ~111 ~-123 ~-1 ~117 minecraft:stone
fill ~-126 ~0 ~111 ~-123 ~9 ~117 minecraft:mud_bricks
fill ~-125 ~1 ~112 ~-124 ~8 ~116 minecraft:air
fill ~-125 ~4 ~112 ~-124 ~4 ~116 minecraft:smooth_stone
fill ~-125 ~8 ~112 ~-124 ~8 ~116 minecraft:smooth_stone
fill ~-126 ~2 ~113 ~-126 ~3 ~113 minecraft:gray_stained_glass
fill ~-123 ~2 ~113 ~-123 ~3 ~113 minecraft:light_gray_stained_glass
fill ~-126 ~6 ~113 ~-126 ~7 ~113 minecraft:gray_stained_glass
fill ~-123 ~6 ~113 ~-123 ~7 ~113 minecraft:light_gray_stained_glass
setblock ~-124 ~1 ~111 minecraft:iron_door[half=lower,facing=north]
setblock ~-124 ~2 ~111 minecraft:iron_door[half=upper,facing=north]
fill ~-125 ~1 ~111 ~-124 ~3 ~111 minecraft:cyan_stained_glass
setblock ~-124 ~1 ~111 minecraft:iron_door[half=lower,facing=north]
setblock ~-124 ~2 ~111 minecraft:iron_door[half=upper,facing=north]
setblock ~-124 ~3 ~110 minecraft:red_wool
fill ~-126 ~10 ~111 ~-123 ~10 ~117 minecraft:deepslate_tile_slab
# 290 local_shop style=storefront context=arterial_front facing=north
fill ~25 ~-3 ~-4 ~28 ~-1 ~2 minecraft:stone
fill ~25 ~0 ~-4 ~28 ~5 ~2 minecraft:white_terracotta
fill ~26 ~1 ~-3 ~27 ~4 ~1 minecraft:air
fill ~26 ~4 ~-3 ~27 ~4 ~1 minecraft:smooth_stone
fill ~25 ~2 ~-2 ~25 ~3 ~-2 minecraft:gray_stained_glass
fill ~28 ~2 ~-2 ~28 ~3 ~-2 minecraft:light_gray_stained_glass
setblock ~27 ~1 ~-4 minecraft:iron_door[half=lower,facing=north]
setblock ~27 ~2 ~-4 minecraft:iron_door[half=upper,facing=north]
fill ~26 ~1 ~-4 ~27 ~3 ~-4 minecraft:cyan_stained_glass
setblock ~27 ~1 ~-4 minecraft:iron_door[half=lower,facing=north]
setblock ~27 ~2 ~-4 minecraft:iron_door[half=upper,facing=north]
setblock ~27 ~3 ~-5 minecraft:red_wool
fill ~25 ~6 ~-4 ~28 ~6 ~2 minecraft:stone_brick_slab
# 291 workshop style=stepped_house context=back_block facing=north
fill ~-113 ~-3 ~-67 ~-110 ~-1 ~-62 minecraft:stone
fill ~-113 ~0 ~-67 ~-110 ~7 ~-62 minecraft:mud_bricks
fill ~-112 ~1 ~-66 ~-111 ~6 ~-63 minecraft:air
fill ~-112 ~4 ~-66 ~-111 ~4 ~-63 minecraft:smooth_stone
fill ~-113 ~2 ~-65 ~-113 ~3 ~-65 minecraft:gray_stained_glass
fill ~-110 ~2 ~-65 ~-110 ~3 ~-65 minecraft:light_gray_stained_glass
setblock ~-111 ~1 ~-67 minecraft:iron_door[half=lower,facing=north]
setblock ~-111 ~2 ~-67 minecraft:iron_door[half=upper,facing=north]
fill ~-113 ~8 ~-67 ~-110 ~8 ~-62 minecraft:deepslate_tile_slab
fill ~-112 ~9 ~-66 ~-111 ~9 ~-63 minecraft:deepslate_tile_slab
setblock ~-111 ~3 ~-68 minecraft:dark_oak_slab[type=top]
