# Buildings 161..168
# 161 restaurant style=arcade_shop context=collector_front facing=north
fill ~-25 ~-3 ~35 ~-19 ~-1 ~43 minecraft:stone
fill ~-25 ~0 ~35 ~-19 ~16 ~43 minecraft:bricks
fill ~-24 ~1 ~36 ~-20 ~15 ~42 minecraft:air
fill ~-24 ~4 ~36 ~-20 ~4 ~42 minecraft:smooth_stone
fill ~-24 ~8 ~36 ~-20 ~8 ~42 minecraft:smooth_stone
fill ~-24 ~12 ~36 ~-20 ~12 ~42 minecraft:smooth_stone
fill ~-23 ~2 ~35 ~-23 ~3 ~35 minecraft:gray_stained_glass
fill ~-23 ~2 ~43 ~-23 ~3 ~43 minecraft:light_gray_stained_glass
fill ~-25 ~2 ~37 ~-25 ~3 ~37 minecraft:gray_stained_glass
fill ~-19 ~2 ~37 ~-19 ~3 ~37 minecraft:light_gray_stained_glass
fill ~-25 ~2 ~40 ~-25 ~3 ~40 minecraft:gray_stained_glass
fill ~-19 ~2 ~40 ~-19 ~3 ~40 minecraft:light_gray_stained_glass
fill ~-23 ~6 ~35 ~-23 ~7 ~35 minecraft:gray_stained_glass
fill ~-23 ~6 ~43 ~-23 ~7 ~43 minecraft:light_gray_stained_glass
fill ~-25 ~6 ~37 ~-25 ~7 ~37 minecraft:gray_stained_glass
fill ~-19 ~6 ~37 ~-19 ~7 ~37 minecraft:light_gray_stained_glass
fill ~-25 ~6 ~40 ~-25 ~7 ~40 minecraft:gray_stained_glass
fill ~-19 ~6 ~40 ~-19 ~7 ~40 minecraft:light_gray_stained_glass
fill ~-23 ~10 ~35 ~-23 ~11 ~35 minecraft:gray_stained_glass
fill ~-23 ~10 ~43 ~-23 ~11 ~43 minecraft:light_gray_stained_glass
fill ~-25 ~10 ~37 ~-25 ~11 ~37 minecraft:gray_stained_glass
fill ~-19 ~10 ~37 ~-19 ~11 ~37 minecraft:light_gray_stained_glass
fill ~-25 ~10 ~40 ~-25 ~11 ~40 minecraft:gray_stained_glass
fill ~-19 ~10 ~40 ~-19 ~11 ~40 minecraft:light_gray_stained_glass
fill ~-23 ~14 ~35 ~-23 ~15 ~35 minecraft:gray_stained_glass
fill ~-23 ~14 ~43 ~-23 ~15 ~43 minecraft:light_gray_stained_glass
fill ~-25 ~14 ~37 ~-25 ~15 ~37 minecraft:gray_stained_glass
fill ~-19 ~14 ~37 ~-19 ~15 ~37 minecraft:light_gray_stained_glass
fill ~-25 ~14 ~40 ~-25 ~15 ~40 minecraft:gray_stained_glass
fill ~-19 ~14 ~40 ~-19 ~15 ~40 minecraft:light_gray_stained_glass
setblock ~-22 ~1 ~35 minecraft:iron_door[half=lower,facing=north]
setblock ~-22 ~2 ~35 minecraft:iron_door[half=upper,facing=north]
fill ~-24 ~1 ~35 ~-20 ~3 ~35 minecraft:cyan_stained_glass
setblock ~-22 ~1 ~35 minecraft:iron_door[half=lower,facing=north]
setblock ~-22 ~2 ~35 minecraft:iron_door[half=upper,facing=north]
setblock ~-22 ~3 ~34 minecraft:red_wool
fill ~-24 ~4 ~35 ~-20 ~4 ~35 doomsday_decoration:redbrick
fill ~-25 ~17 ~35 ~-19 ~17 ~43 minecraft:deepslate_tile_slab
# 162 office style=setback_tower context=arterial_front facing=west
fill ~25 ~-3 ~34 ~31 ~-1 ~46 minecraft:stone
fill ~25 ~0 ~34 ~31 ~24 ~46 minecraft:bricks
fill ~26 ~1 ~35 ~30 ~23 ~45 minecraft:air
fill ~26 ~4 ~35 ~30 ~4 ~45 minecraft:smooth_stone
fill ~26 ~8 ~35 ~30 ~8 ~45 minecraft:smooth_stone
fill ~26 ~12 ~35 ~30 ~12 ~45 minecraft:smooth_stone
fill ~26 ~16 ~35 ~30 ~16 ~45 minecraft:smooth_stone
fill ~26 ~20 ~35 ~30 ~20 ~45 minecraft:smooth_stone
fill ~27 ~2 ~34 ~27 ~3 ~34 minecraft:gray_stained_glass
fill ~27 ~2 ~46 ~27 ~3 ~46 minecraft:light_gray_stained_glass
fill ~25 ~2 ~36 ~25 ~3 ~36 minecraft:gray_stained_glass
fill ~31 ~2 ~36 ~31 ~3 ~36 minecraft:light_gray_stained_glass
fill ~25 ~2 ~39 ~25 ~3 ~39 minecraft:gray_stained_glass
fill ~31 ~2 ~39 ~31 ~3 ~39 minecraft:light_gray_stained_glass
fill ~25 ~2 ~42 ~25 ~3 ~42 minecraft:gray_stained_glass
fill ~31 ~2 ~42 ~31 ~3 ~42 minecraft:light_gray_stained_glass
fill ~27 ~6 ~34 ~27 ~7 ~34 minecraft:gray_stained_glass
fill ~27 ~6 ~46 ~27 ~7 ~46 minecraft:light_gray_stained_glass
fill ~25 ~6 ~36 ~25 ~7 ~36 minecraft:gray_stained_glass
fill ~31 ~6 ~36 ~31 ~7 ~36 minecraft:light_gray_stained_glass
fill ~25 ~6 ~39 ~25 ~7 ~39 minecraft:gray_stained_glass
fill ~31 ~6 ~39 ~31 ~7 ~39 minecraft:light_gray_stained_glass
fill ~25 ~6 ~42 ~25 ~7 ~42 minecraft:gray_stained_glass
fill ~31 ~6 ~42 ~31 ~7 ~42 minecraft:light_gray_stained_glass
fill ~27 ~10 ~34 ~27 ~11 ~34 minecraft:gray_stained_glass
fill ~27 ~10 ~46 ~27 ~11 ~46 minecraft:light_gray_stained_glass
fill ~25 ~10 ~36 ~25 ~11 ~36 minecraft:gray_stained_glass
fill ~31 ~10 ~36 ~31 ~11 ~36 minecraft:light_gray_stained_glass
fill ~25 ~10 ~39 ~25 ~11 ~39 minecraft:gray_stained_glass
fill ~31 ~10 ~39 ~31 ~11 ~39 minecraft:light_gray_stained_glass
fill ~25 ~10 ~42 ~25 ~11 ~42 minecraft:gray_stained_glass
fill ~31 ~10 ~42 ~31 ~11 ~42 minecraft:light_gray_stained_glass
fill ~27 ~14 ~34 ~27 ~15 ~34 minecraft:gray_stained_glass
fill ~27 ~14 ~46 ~27 ~15 ~46 minecraft:light_gray_stained_glass
fill ~25 ~14 ~36 ~25 ~15 ~36 minecraft:gray_stained_glass
fill ~31 ~14 ~36 ~31 ~15 ~36 minecraft:light_gray_stained_glass
fill ~25 ~14 ~39 ~25 ~15 ~39 minecraft:gray_stained_glass
fill ~31 ~14 ~39 ~31 ~15 ~39 minecraft:light_gray_stained_glass
fill ~25 ~14 ~42 ~25 ~15 ~42 minecraft:gray_stained_glass
fill ~31 ~14 ~42 ~31 ~15 ~42 minecraft:light_gray_stained_glass
fill ~27 ~18 ~34 ~27 ~19 ~34 minecraft:gray_stained_glass
fill ~27 ~18 ~46 ~27 ~19 ~46 minecraft:light_gray_stained_glass
fill ~25 ~18 ~36 ~25 ~19 ~36 minecraft:gray_stained_glass
fill ~31 ~18 ~36 ~31 ~19 ~36 minecraft:light_gray_stained_glass
fill ~25 ~18 ~39 ~25 ~19 ~39 minecraft:gray_stained_glass
fill ~31 ~18 ~39 ~31 ~19 ~39 minecraft:light_gray_stained_glass
fill ~25 ~18 ~42 ~25 ~19 ~42 minecraft:gray_stained_glass
fill ~31 ~18 ~42 ~31 ~19 ~42 minecraft:light_gray_stained_glass
fill ~27 ~22 ~34 ~27 ~23 ~34 minecraft:gray_stained_glass
fill ~27 ~22 ~46 ~27 ~23 ~46 minecraft:light_gray_stained_glass
fill ~25 ~22 ~36 ~25 ~23 ~36 minecraft:gray_stained_glass
fill ~31 ~22 ~36 ~31 ~23 ~36 minecraft:light_gray_stained_glass
fill ~25 ~22 ~39 ~25 ~23 ~39 minecraft:gray_stained_glass
fill ~31 ~22 ~39 ~31 ~23 ~39 minecraft:light_gray_stained_glass
fill ~25 ~22 ~42 ~25 ~23 ~42 minecraft:gray_stained_glass
fill ~31 ~22 ~42 ~31 ~23 ~42 minecraft:light_gray_stained_glass
setblock ~25 ~1 ~39 minecraft:iron_door[half=lower,facing=west]
setblock ~25 ~2 ~39 minecraft:iron_door[half=upper,facing=west]
fill ~25 ~19 ~34 ~31 ~24 ~46 minecraft:air
fill ~26 ~19 ~35 ~30 ~24 ~45 minecraft:bricks
fill ~27 ~20 ~36 ~29 ~23 ~44 minecraft:air
fill ~26 ~25 ~35 ~30 ~25 ~45 minecraft:deepslate_tile_slab
fill ~27 ~26 ~36 ~29 ~27 ~38 minecraft:light_gray_concrete
setblock ~30 ~26 ~37 minecraft:lightning_rod
# 163 lowrise_housing style=stepped_house context=back_block facing=north
fill ~-13 ~-3 ~52 ~-7 ~-1 ~59 minecraft:stone
fill ~-13 ~0 ~52 ~-7 ~16 ~59 minecraft:light_gray_concrete
fill ~-12 ~1 ~53 ~-8 ~15 ~58 minecraft:air
fill ~-12 ~4 ~53 ~-8 ~4 ~58 minecraft:smooth_stone
fill ~-12 ~8 ~53 ~-8 ~8 ~58 minecraft:smooth_stone
fill ~-12 ~12 ~53 ~-8 ~12 ~58 minecraft:smooth_stone
fill ~-11 ~2 ~52 ~-11 ~3 ~52 minecraft:gray_stained_glass
fill ~-11 ~2 ~59 ~-11 ~3 ~59 minecraft:light_gray_stained_glass
fill ~-13 ~2 ~54 ~-13 ~3 ~54 minecraft:gray_stained_glass
fill ~-7 ~2 ~54 ~-7 ~3 ~54 minecraft:light_gray_stained_glass
fill ~-13 ~2 ~57 ~-13 ~3 ~57 minecraft:gray_stained_glass
fill ~-7 ~2 ~57 ~-7 ~3 ~57 minecraft:light_gray_stained_glass
fill ~-11 ~6 ~52 ~-11 ~7 ~52 minecraft:gray_stained_glass
fill ~-11 ~6 ~59 ~-11 ~7 ~59 minecraft:light_gray_stained_glass
fill ~-13 ~6 ~54 ~-13 ~7 ~54 minecraft:gray_stained_glass
fill ~-7 ~6 ~54 ~-7 ~7 ~54 minecraft:light_gray_stained_glass
fill ~-13 ~6 ~57 ~-13 ~7 ~57 minecraft:gray_stained_glass
fill ~-7 ~6 ~57 ~-7 ~7 ~57 minecraft:light_gray_stained_glass
fill ~-11 ~10 ~52 ~-11 ~11 ~52 minecraft:gray_stained_glass
fill ~-11 ~10 ~59 ~-11 ~11 ~59 minecraft:light_gray_stained_glass
fill ~-13 ~10 ~54 ~-13 ~11 ~54 minecraft:gray_stained_glass
fill ~-7 ~10 ~54 ~-7 ~11 ~54 minecraft:light_gray_stained_glass
fill ~-13 ~10 ~57 ~-13 ~11 ~57 minecraft:gray_stained_glass
fill ~-7 ~10 ~57 ~-7 ~11 ~57 minecraft:light_gray_stained_glass
fill ~-11 ~14 ~52 ~-11 ~15 ~52 minecraft:gray_stained_glass
fill ~-11 ~14 ~59 ~-11 ~15 ~59 minecraft:light_gray_stained_glass
fill ~-13 ~14 ~54 ~-13 ~15 ~54 minecraft:gray_stained_glass
fill ~-7 ~14 ~54 ~-7 ~15 ~54 minecraft:light_gray_stained_glass
fill ~-13 ~14 ~57 ~-13 ~15 ~57 minecraft:gray_stained_glass
fill ~-7 ~14 ~57 ~-7 ~15 ~57 minecraft:light_gray_stained_glass
setblock ~-10 ~1 ~52 minecraft:iron_door[half=lower,facing=north]
setblock ~-10 ~2 ~52 minecraft:iron_door[half=upper,facing=north]
fill ~-13 ~17 ~52 ~-7 ~17 ~59 minecraft:smooth_stone_slab
fill ~-12 ~18 ~53 ~-8 ~18 ~58 minecraft:smooth_stone_slab
setblock ~-10 ~3 ~51 minecraft:dark_oak_slab[type=top]
# 164 supermarket style=storefront context=collector_front facing=north
fill ~-48 ~-3 ~30 ~-41 ~-1 ~41 minecraft:stone
fill ~-48 ~0 ~30 ~-41 ~10 ~41 minecraft:bricks
fill ~-47 ~1 ~31 ~-42 ~9 ~40 minecraft:air
fill ~-47 ~4 ~31 ~-42 ~4 ~40 minecraft:smooth_stone
fill ~-47 ~8 ~31 ~-42 ~8 ~40 minecraft:smooth_stone
fill ~-46 ~2 ~30 ~-46 ~3 ~30 minecraft:gray_stained_glass
fill ~-46 ~2 ~41 ~-46 ~3 ~41 minecraft:light_gray_stained_glass
fill ~-43 ~2 ~30 ~-43 ~3 ~30 minecraft:gray_stained_glass
fill ~-43 ~2 ~41 ~-43 ~3 ~41 minecraft:light_gray_stained_glass
fill ~-48 ~2 ~32 ~-48 ~3 ~32 minecraft:gray_stained_glass
fill ~-41 ~2 ~32 ~-41 ~3 ~32 minecraft:light_gray_stained_glass
fill ~-48 ~2 ~35 ~-48 ~3 ~35 minecraft:gray_stained_glass
fill ~-41 ~2 ~35 ~-41 ~3 ~35 minecraft:light_gray_stained_glass
fill ~-48 ~2 ~38 ~-48 ~3 ~38 minecraft:gray_stained_glass
fill ~-41 ~2 ~38 ~-41 ~3 ~38 minecraft:light_gray_stained_glass
fill ~-46 ~6 ~30 ~-46 ~7 ~30 minecraft:gray_stained_glass
fill ~-46 ~6 ~41 ~-46 ~7 ~41 minecraft:light_gray_stained_glass
fill ~-43 ~6 ~30 ~-43 ~7 ~30 minecraft:gray_stained_glass
fill ~-43 ~6 ~41 ~-43 ~7 ~41 minecraft:light_gray_stained_glass
fill ~-48 ~6 ~32 ~-48 ~7 ~32 minecraft:gray_stained_glass
fill ~-41 ~6 ~32 ~-41 ~7 ~32 minecraft:light_gray_stained_glass
fill ~-48 ~6 ~35 ~-48 ~7 ~35 minecraft:gray_stained_glass
fill ~-41 ~6 ~35 ~-41 ~7 ~35 minecraft:light_gray_stained_glass
fill ~-48 ~6 ~38 ~-48 ~7 ~38 minecraft:gray_stained_glass
fill ~-41 ~6 ~38 ~-41 ~7 ~38 minecraft:light_gray_stained_glass
setblock ~-45 ~1 ~30 minecraft:iron_door[half=lower,facing=north]
setblock ~-45 ~2 ~30 minecraft:iron_door[half=upper,facing=north]
fill ~-47 ~1 ~30 ~-42 ~3 ~30 minecraft:cyan_stained_glass
setblock ~-45 ~1 ~30 minecraft:iron_door[half=lower,facing=north]
setblock ~-45 ~2 ~30 minecraft:iron_door[half=upper,facing=north]
setblock ~-45 ~3 ~29 minecraft:red_wool
fill ~-48 ~11 ~30 ~-41 ~11 ~41 minecraft:deepslate_tile_slab
# 165 clinic style=mixed_facade context=collector_front facing=south
fill ~-78 ~-3 ~-81 ~-72 ~-1 ~-75 minecraft:stone
fill ~-78 ~0 ~-81 ~-72 ~11 ~-75 minecraft:calcite
fill ~-77 ~1 ~-80 ~-73 ~10 ~-76 minecraft:air
fill ~-77 ~4 ~-80 ~-73 ~4 ~-76 minecraft:smooth_stone
fill ~-77 ~8 ~-80 ~-73 ~8 ~-76 minecraft:smooth_stone
fill ~-76 ~2 ~-81 ~-76 ~3 ~-81 minecraft:gray_stained_glass
fill ~-76 ~2 ~-75 ~-76 ~3 ~-75 minecraft:light_gray_stained_glass
fill ~-78 ~2 ~-79 ~-78 ~3 ~-79 minecraft:gray_stained_glass
fill ~-72 ~2 ~-79 ~-72 ~3 ~-79 minecraft:light_gray_stained_glass
fill ~-76 ~6 ~-81 ~-76 ~7 ~-81 minecraft:gray_stained_glass
fill ~-76 ~6 ~-75 ~-76 ~7 ~-75 minecraft:light_gray_stained_glass
fill ~-78 ~6 ~-79 ~-78 ~7 ~-79 minecraft:gray_stained_glass
fill ~-72 ~6 ~-79 ~-72 ~7 ~-79 minecraft:light_gray_stained_glass
setblock ~-75 ~1 ~-75 minecraft:iron_door[half=lower,facing=south]
setblock ~-75 ~2 ~-75 minecraft:iron_door[half=upper,facing=south]
fill ~-78 ~12 ~-81 ~-72 ~12 ~-75 minecraft:stone_brick_slab
fill ~-76 ~13 ~-79 ~-74 ~14 ~-77 minecraft:light_gray_concrete
setblock ~-73 ~13 ~-78 minecraft:lightning_rod
# 166 midrise_housing style=setback_block context=collector_front facing=east
fill ~70 ~-3 ~-28 ~76 ~-1 ~-21 minecraft:stone
fill ~70 ~0 ~-28 ~76 ~16 ~-21 minecraft:light_gray_concrete
fill ~71 ~1 ~-27 ~75 ~15 ~-22 minecraft:air
fill ~71 ~4 ~-27 ~75 ~4 ~-22 minecraft:smooth_stone
fill ~71 ~8 ~-27 ~75 ~8 ~-22 minecraft:smooth_stone
fill ~71 ~12 ~-27 ~75 ~12 ~-22 minecraft:smooth_stone
fill ~72 ~2 ~-28 ~72 ~3 ~-28 minecraft:gray_stained_glass
fill ~72 ~2 ~-21 ~72 ~3 ~-21 minecraft:light_gray_stained_glass
fill ~70 ~2 ~-26 ~70 ~3 ~-26 minecraft:gray_stained_glass
fill ~76 ~2 ~-26 ~76 ~3 ~-26 minecraft:light_gray_stained_glass
fill ~70 ~2 ~-23 ~70 ~3 ~-23 minecraft:gray_stained_glass
fill ~76 ~2 ~-23 ~76 ~3 ~-23 minecraft:light_gray_stained_glass
fill ~72 ~6 ~-28 ~72 ~7 ~-28 minecraft:gray_stained_glass
fill ~72 ~6 ~-21 ~72 ~7 ~-21 minecraft:light_gray_stained_glass
fill ~70 ~6 ~-26 ~70 ~7 ~-26 minecraft:gray_stained_glass
fill ~76 ~6 ~-26 ~76 ~7 ~-26 minecraft:light_gray_stained_glass
fill ~70 ~6 ~-23 ~70 ~7 ~-23 minecraft:gray_stained_glass
fill ~76 ~6 ~-23 ~76 ~7 ~-23 minecraft:light_gray_stained_glass
fill ~72 ~10 ~-28 ~72 ~11 ~-28 minecraft:gray_stained_glass
fill ~72 ~10 ~-21 ~72 ~11 ~-21 minecraft:light_gray_stained_glass
fill ~70 ~10 ~-26 ~70 ~11 ~-26 minecraft:gray_stained_glass
fill ~76 ~10 ~-26 ~76 ~11 ~-26 minecraft:light_gray_stained_glass
fill ~70 ~10 ~-23 ~70 ~11 ~-23 minecraft:gray_stained_glass
fill ~76 ~10 ~-23 ~76 ~11 ~-23 minecraft:light_gray_stained_glass
fill ~72 ~14 ~-28 ~72 ~15 ~-28 minecraft:gray_stained_glass
fill ~72 ~14 ~-21 ~72 ~15 ~-21 minecraft:light_gray_stained_glass
fill ~70 ~14 ~-26 ~70 ~15 ~-26 minecraft:gray_stained_glass
fill ~76 ~14 ~-26 ~76 ~15 ~-26 minecraft:light_gray_stained_glass
fill ~70 ~14 ~-23 ~70 ~15 ~-23 minecraft:gray_stained_glass
fill ~76 ~14 ~-23 ~76 ~15 ~-23 minecraft:light_gray_stained_glass
setblock ~76 ~1 ~-25 minecraft:iron_door[half=lower,facing=east]
setblock ~76 ~2 ~-25 minecraft:iron_door[half=upper,facing=east]
fill ~70 ~11 ~-28 ~76 ~16 ~-21 minecraft:air
fill ~71 ~11 ~-27 ~75 ~16 ~-22 minecraft:light_gray_concrete
fill ~72 ~12 ~-26 ~74 ~15 ~-23 minecraft:air
fill ~71 ~17 ~-27 ~75 ~17 ~-22 minecraft:smooth_stone_slab
# 167 clinic style=balcony_block context=collector_front facing=north
fill ~-83 ~-3 ~90 ~-78 ~-1 ~96 minecraft:stone
fill ~-83 ~0 ~90 ~-78 ~5 ~96 minecraft:calcite
fill ~-82 ~1 ~91 ~-79 ~4 ~95 minecraft:air
fill ~-82 ~4 ~91 ~-79 ~4 ~95 minecraft:smooth_stone
fill ~-81 ~2 ~90 ~-81 ~3 ~90 minecraft:gray_stained_glass
fill ~-81 ~2 ~96 ~-81 ~3 ~96 minecraft:light_gray_stained_glass
fill ~-83 ~2 ~92 ~-83 ~3 ~92 minecraft:gray_stained_glass
fill ~-78 ~2 ~92 ~-78 ~3 ~92 minecraft:light_gray_stained_glass
setblock ~-81 ~1 ~90 minecraft:iron_door[half=lower,facing=north]
setblock ~-81 ~2 ~90 minecraft:iron_door[half=upper,facing=north]
fill ~-81 ~4 ~89 ~-80 ~4 ~89 minecraft:smooth_stone_slab
fill ~-83 ~6 ~90 ~-78 ~6 ~96 minecraft:stone_brick_slab
# 168 logistics style=loading_bay context=local_front facing=south
fill ~-109 ~-3 ~-124 ~-104 ~-1 ~-117 minecraft:stone
fill ~-109 ~0 ~-124 ~-104 ~10 ~-117 minecraft:bricks
fill ~-108 ~1 ~-123 ~-105 ~9 ~-118 minecraft:air
fill ~-108 ~4 ~-123 ~-105 ~4 ~-118 minecraft:smooth_stone
fill ~-108 ~8 ~-123 ~-105 ~8 ~-118 minecraft:smooth_stone
fill ~-107 ~2 ~-124 ~-107 ~3 ~-124 minecraft:gray_stained_glass
fill ~-107 ~2 ~-117 ~-107 ~3 ~-117 minecraft:light_gray_stained_glass
fill ~-109 ~2 ~-122 ~-109 ~3 ~-122 minecraft:gray_stained_glass
fill ~-104 ~2 ~-122 ~-104 ~3 ~-122 minecraft:light_gray_stained_glass
fill ~-109 ~2 ~-119 ~-109 ~3 ~-119 minecraft:gray_stained_glass
fill ~-104 ~2 ~-119 ~-104 ~3 ~-119 minecraft:light_gray_stained_glass
fill ~-107 ~6 ~-124 ~-107 ~7 ~-124 minecraft:gray_stained_glass
fill ~-107 ~6 ~-117 ~-107 ~7 ~-117 minecraft:light_gray_stained_glass
fill ~-109 ~6 ~-122 ~-109 ~7 ~-122 minecraft:gray_stained_glass
fill ~-104 ~6 ~-122 ~-104 ~7 ~-122 minecraft:light_gray_stained_glass
fill ~-109 ~6 ~-119 ~-109 ~7 ~-119 minecraft:gray_stained_glass
fill ~-104 ~6 ~-119 ~-104 ~7 ~-119 minecraft:light_gray_stained_glass
setblock ~-107 ~1 ~-117 minecraft:iron_door[half=lower,facing=south]
setblock ~-107 ~2 ~-117 minecraft:iron_door[half=upper,facing=south]
fill ~-107 ~1 ~-117 ~-106 ~4 ~-117 minecraft:polished_blackstone
fill ~-107 ~5 ~-117 ~-106 ~5 ~-117 minecraft:light_blue_stained_glass
fill ~-107 ~12 ~-122 ~-105 ~13 ~-120 minecraft:iron_block
fill ~-109 ~11 ~-124 ~-104 ~11 ~-117 minecraft:deepslate_tile_slab
fill ~-107 ~12 ~-122 ~-105 ~13 ~-120 minecraft:light_gray_concrete
setblock ~-105 ~12 ~-121 minecraft:lightning_rod
