# Buildings 129..136
# 129 restaurant style=storefront context=collector_front facing=east
fill ~-106 ~-3 ~104 ~-94 ~-1 ~111 minecraft:stone
fill ~-106 ~0 ~104 ~-94 ~11 ~111 minecraft:mud_bricks
fill ~-105 ~1 ~105 ~-95 ~10 ~110 minecraft:air
fill ~-105 ~4 ~105 ~-95 ~4 ~110 minecraft:smooth_stone
fill ~-105 ~8 ~105 ~-95 ~8 ~110 minecraft:smooth_stone
fill ~-104 ~2 ~104 ~-104 ~3 ~104 minecraft:gray_stained_glass
fill ~-104 ~2 ~111 ~-104 ~3 ~111 minecraft:light_gray_stained_glass
fill ~-101 ~2 ~104 ~-101 ~3 ~104 minecraft:gray_stained_glass
fill ~-101 ~2 ~111 ~-101 ~3 ~111 minecraft:light_gray_stained_glass
fill ~-98 ~2 ~104 ~-98 ~3 ~104 minecraft:gray_stained_glass
fill ~-98 ~2 ~111 ~-98 ~3 ~111 minecraft:light_gray_stained_glass
fill ~-106 ~2 ~106 ~-106 ~3 ~106 minecraft:gray_stained_glass
fill ~-94 ~2 ~106 ~-94 ~3 ~106 minecraft:light_gray_stained_glass
fill ~-106 ~2 ~109 ~-106 ~3 ~109 minecraft:gray_stained_glass
fill ~-94 ~2 ~109 ~-94 ~3 ~109 minecraft:light_gray_stained_glass
fill ~-104 ~6 ~104 ~-104 ~7 ~104 minecraft:gray_stained_glass
fill ~-104 ~6 ~111 ~-104 ~7 ~111 minecraft:light_gray_stained_glass
fill ~-101 ~6 ~104 ~-101 ~7 ~104 minecraft:gray_stained_glass
fill ~-101 ~6 ~111 ~-101 ~7 ~111 minecraft:light_gray_stained_glass
fill ~-98 ~6 ~104 ~-98 ~7 ~104 minecraft:gray_stained_glass
fill ~-98 ~6 ~111 ~-98 ~7 ~111 minecraft:light_gray_stained_glass
fill ~-106 ~6 ~106 ~-106 ~7 ~106 minecraft:gray_stained_glass
fill ~-94 ~6 ~106 ~-94 ~7 ~106 minecraft:light_gray_stained_glass
fill ~-106 ~6 ~109 ~-106 ~7 ~109 minecraft:gray_stained_glass
fill ~-94 ~6 ~109 ~-94 ~7 ~109 minecraft:light_gray_stained_glass
setblock ~-94 ~1 ~107 minecraft:iron_door[half=lower,facing=east]
setblock ~-94 ~2 ~107 minecraft:iron_door[half=upper,facing=east]
fill ~-94 ~1 ~105 ~-94 ~3 ~110 minecraft:cyan_stained_glass
setblock ~-94 ~1 ~107 minecraft:iron_door[half=lower,facing=east]
setblock ~-94 ~2 ~107 minecraft:iron_door[half=upper,facing=east]
setblock ~-93 ~3 ~107 minecraft:red_wool
fill ~-106 ~12 ~104 ~-94 ~12 ~111 minecraft:deepslate_tile_slab
fill ~-104 ~13 ~106 ~-102 ~14 ~108 minecraft:light_gray_concrete
setblock ~-101 ~13 ~107 minecraft:lightning_rod
fill ~-94 ~1 ~105 ~-94 ~7 ~105 minecraft:spruce_planks
fill ~-94 ~1 ~109 ~-94 ~7 ~109 minecraft:spruce_planks
fill ~-105 ~6 ~105 ~-95 ~11 ~110 minecraft:mud_bricks
fill ~-104 ~7 ~106 ~-96 ~10 ~109 minecraft:air
setblock ~-94 ~3 ~106 minecraft:red_carpet
# 130 large_retail style=corner_store context=arterial_front facing=north
fill ~-30 ~-3 ~32 ~-19 ~-1 ~40 minecraft:stone
fill ~-30 ~0 ~32 ~-19 ~16 ~40 minecraft:bricks
fill ~-29 ~1 ~33 ~-20 ~15 ~39 minecraft:air
fill ~-29 ~4 ~33 ~-20 ~4 ~39 minecraft:smooth_stone
fill ~-29 ~8 ~33 ~-20 ~8 ~39 minecraft:smooth_stone
fill ~-29 ~12 ~33 ~-20 ~12 ~39 minecraft:smooth_stone
fill ~-28 ~2 ~32 ~-28 ~3 ~32 minecraft:gray_stained_glass
fill ~-28 ~2 ~40 ~-28 ~3 ~40 minecraft:light_gray_stained_glass
fill ~-25 ~2 ~32 ~-25 ~3 ~32 minecraft:gray_stained_glass
fill ~-25 ~2 ~40 ~-25 ~3 ~40 minecraft:light_gray_stained_glass
fill ~-22 ~2 ~32 ~-22 ~3 ~32 minecraft:gray_stained_glass
fill ~-22 ~2 ~40 ~-22 ~3 ~40 minecraft:light_gray_stained_glass
fill ~-30 ~2 ~34 ~-30 ~3 ~34 minecraft:gray_stained_glass
fill ~-19 ~2 ~34 ~-19 ~3 ~34 minecraft:light_gray_stained_glass
fill ~-30 ~2 ~37 ~-30 ~3 ~37 minecraft:gray_stained_glass
fill ~-19 ~2 ~37 ~-19 ~3 ~37 minecraft:light_gray_stained_glass
fill ~-28 ~6 ~32 ~-28 ~7 ~32 minecraft:gray_stained_glass
fill ~-28 ~6 ~40 ~-28 ~7 ~40 minecraft:light_gray_stained_glass
fill ~-25 ~6 ~32 ~-25 ~7 ~32 minecraft:gray_stained_glass
fill ~-25 ~6 ~40 ~-25 ~7 ~40 minecraft:light_gray_stained_glass
fill ~-22 ~6 ~32 ~-22 ~7 ~32 minecraft:gray_stained_glass
fill ~-22 ~6 ~40 ~-22 ~7 ~40 minecraft:light_gray_stained_glass
fill ~-30 ~6 ~34 ~-30 ~7 ~34 minecraft:gray_stained_glass
fill ~-19 ~6 ~34 ~-19 ~7 ~34 minecraft:light_gray_stained_glass
fill ~-30 ~6 ~37 ~-30 ~7 ~37 minecraft:gray_stained_glass
fill ~-19 ~6 ~37 ~-19 ~7 ~37 minecraft:light_gray_stained_glass
fill ~-28 ~10 ~32 ~-28 ~11 ~32 minecraft:gray_stained_glass
fill ~-28 ~10 ~40 ~-28 ~11 ~40 minecraft:light_gray_stained_glass
fill ~-25 ~10 ~32 ~-25 ~11 ~32 minecraft:gray_stained_glass
fill ~-25 ~10 ~40 ~-25 ~11 ~40 minecraft:light_gray_stained_glass
fill ~-22 ~10 ~32 ~-22 ~11 ~32 minecraft:gray_stained_glass
fill ~-22 ~10 ~40 ~-22 ~11 ~40 minecraft:light_gray_stained_glass
fill ~-30 ~10 ~34 ~-30 ~11 ~34 minecraft:gray_stained_glass
fill ~-19 ~10 ~34 ~-19 ~11 ~34 minecraft:light_gray_stained_glass
fill ~-30 ~10 ~37 ~-30 ~11 ~37 minecraft:gray_stained_glass
fill ~-19 ~10 ~37 ~-19 ~11 ~37 minecraft:light_gray_stained_glass
fill ~-28 ~14 ~32 ~-28 ~15 ~32 minecraft:gray_stained_glass
fill ~-28 ~14 ~40 ~-28 ~15 ~40 minecraft:light_gray_stained_glass
fill ~-25 ~14 ~32 ~-25 ~15 ~32 minecraft:gray_stained_glass
fill ~-25 ~14 ~40 ~-25 ~15 ~40 minecraft:light_gray_stained_glass
fill ~-22 ~14 ~32 ~-22 ~15 ~32 minecraft:gray_stained_glass
fill ~-22 ~14 ~40 ~-22 ~15 ~40 minecraft:light_gray_stained_glass
fill ~-30 ~14 ~34 ~-30 ~15 ~34 minecraft:gray_stained_glass
fill ~-19 ~14 ~34 ~-19 ~15 ~34 minecraft:light_gray_stained_glass
fill ~-30 ~14 ~37 ~-30 ~15 ~37 minecraft:gray_stained_glass
fill ~-19 ~14 ~37 ~-19 ~15 ~37 minecraft:light_gray_stained_glass
setblock ~-25 ~1 ~32 minecraft:iron_door[half=lower,facing=north]
setblock ~-25 ~2 ~32 minecraft:iron_door[half=upper,facing=north]
fill ~-29 ~1 ~32 ~-20 ~3 ~32 minecraft:cyan_stained_glass
setblock ~-25 ~1 ~32 minecraft:iron_door[half=lower,facing=north]
setblock ~-25 ~2 ~32 minecraft:iron_door[half=upper,facing=north]
setblock ~-25 ~3 ~31 minecraft:red_wool
fill ~-30 ~17 ~32 ~-19 ~17 ~40 minecraft:deepslate_tile_slab
fill ~-29 ~1 ~32 ~-29 ~7 ~32 doomsday_decoration:redbrick
fill ~-25 ~1 ~32 ~-25 ~7 ~32 doomsday_decoration:redbrick
fill ~-21 ~1 ~32 ~-21 ~7 ~32 doomsday_decoration:redbrick
fill ~-29 ~6 ~33 ~-20 ~16 ~39 minecraft:bricks
fill ~-28 ~7 ~34 ~-21 ~15 ~38 minecraft:air
setblock ~-28 ~3 ~32 minecraft:red_carpet
setblock ~-23 ~3 ~32 minecraft:red_carpet
# 131 factory style=loading_bay context=local_front facing=north
fill ~-10 ~-3 ~-104 ~3 ~-1 ~-93 minecraft:stone
fill ~-10 ~0 ~-104 ~3 ~13 ~-93 minecraft:bricks
fill ~-9 ~1 ~-103 ~2 ~12 ~-94 minecraft:air
fill ~-9 ~4 ~-103 ~2 ~4 ~-94 minecraft:smooth_stone
fill ~-9 ~8 ~-103 ~2 ~8 ~-94 minecraft:smooth_stone
fill ~-9 ~12 ~-103 ~2 ~12 ~-94 minecraft:smooth_stone
fill ~-8 ~2 ~-104 ~-8 ~3 ~-104 minecraft:gray_stained_glass
fill ~-8 ~2 ~-93 ~-8 ~3 ~-93 minecraft:light_gray_stained_glass
fill ~-5 ~2 ~-104 ~-5 ~3 ~-104 minecraft:gray_stained_glass
fill ~-5 ~2 ~-93 ~-5 ~3 ~-93 minecraft:light_gray_stained_glass
fill ~-2 ~2 ~-104 ~-2 ~3 ~-104 minecraft:gray_stained_glass
fill ~-2 ~2 ~-93 ~-2 ~3 ~-93 minecraft:light_gray_stained_glass
fill ~1 ~2 ~-104 ~1 ~3 ~-104 minecraft:gray_stained_glass
fill ~1 ~2 ~-93 ~1 ~3 ~-93 minecraft:light_gray_stained_glass
fill ~-10 ~2 ~-102 ~-10 ~3 ~-102 minecraft:gray_stained_glass
fill ~3 ~2 ~-102 ~3 ~3 ~-102 minecraft:light_gray_stained_glass
fill ~-10 ~2 ~-99 ~-10 ~3 ~-99 minecraft:gray_stained_glass
fill ~3 ~2 ~-99 ~3 ~3 ~-99 minecraft:light_gray_stained_glass
fill ~-10 ~2 ~-96 ~-10 ~3 ~-96 minecraft:gray_stained_glass
fill ~3 ~2 ~-96 ~3 ~3 ~-96 minecraft:light_gray_stained_glass
fill ~-8 ~6 ~-104 ~-8 ~7 ~-104 minecraft:gray_stained_glass
fill ~-8 ~6 ~-93 ~-8 ~7 ~-93 minecraft:light_gray_stained_glass
fill ~-5 ~6 ~-104 ~-5 ~7 ~-104 minecraft:gray_stained_glass
fill ~-5 ~6 ~-93 ~-5 ~7 ~-93 minecraft:light_gray_stained_glass
fill ~-2 ~6 ~-104 ~-2 ~7 ~-104 minecraft:gray_stained_glass
fill ~-2 ~6 ~-93 ~-2 ~7 ~-93 minecraft:light_gray_stained_glass
fill ~1 ~6 ~-104 ~1 ~7 ~-104 minecraft:gray_stained_glass
fill ~1 ~6 ~-93 ~1 ~7 ~-93 minecraft:light_gray_stained_glass
fill ~-10 ~6 ~-102 ~-10 ~7 ~-102 minecraft:gray_stained_glass
fill ~3 ~6 ~-102 ~3 ~7 ~-102 minecraft:light_gray_stained_glass
fill ~-10 ~6 ~-99 ~-10 ~7 ~-99 minecraft:gray_stained_glass
fill ~3 ~6 ~-99 ~3 ~7 ~-99 minecraft:light_gray_stained_glass
fill ~-10 ~6 ~-96 ~-10 ~7 ~-96 minecraft:gray_stained_glass
fill ~3 ~6 ~-96 ~3 ~7 ~-96 minecraft:light_gray_stained_glass
fill ~-8 ~10 ~-104 ~-8 ~11 ~-104 minecraft:gray_stained_glass
fill ~-8 ~10 ~-93 ~-8 ~11 ~-93 minecraft:light_gray_stained_glass
fill ~-5 ~10 ~-104 ~-5 ~11 ~-104 minecraft:gray_stained_glass
fill ~-5 ~10 ~-93 ~-5 ~11 ~-93 minecraft:light_gray_stained_glass
fill ~-2 ~10 ~-104 ~-2 ~11 ~-104 minecraft:gray_stained_glass
fill ~-2 ~10 ~-93 ~-2 ~11 ~-93 minecraft:light_gray_stained_glass
fill ~1 ~10 ~-104 ~1 ~11 ~-104 minecraft:gray_stained_glass
fill ~1 ~10 ~-93 ~1 ~11 ~-93 minecraft:light_gray_stained_glass
fill ~-10 ~10 ~-102 ~-10 ~11 ~-102 minecraft:gray_stained_glass
fill ~3 ~10 ~-102 ~3 ~11 ~-102 minecraft:light_gray_stained_glass
fill ~-10 ~10 ~-99 ~-10 ~11 ~-99 minecraft:gray_stained_glass
fill ~3 ~10 ~-99 ~3 ~11 ~-99 minecraft:light_gray_stained_glass
fill ~-10 ~10 ~-96 ~-10 ~11 ~-96 minecraft:gray_stained_glass
fill ~3 ~10 ~-96 ~3 ~11 ~-96 minecraft:light_gray_stained_glass
setblock ~-5 ~1 ~-104 minecraft:iron_door[half=lower,facing=north]
setblock ~-5 ~2 ~-104 minecraft:iron_door[half=upper,facing=north]
fill ~-8 ~1 ~-104 ~1 ~4 ~-104 minecraft:polished_blackstone
fill ~-8 ~5 ~-104 ~1 ~5 ~-104 minecraft:light_blue_stained_glass
fill ~-8 ~15 ~-102 ~-6 ~16 ~-100 minecraft:iron_block
fill ~-10 ~14 ~-104 ~3 ~14 ~-93 minecraft:deepslate_tile_slab
fill ~-9 ~1 ~-104 ~-9 ~7 ~-104 minecraft:gray_concrete
fill ~-5 ~1 ~-104 ~-5 ~7 ~-104 minecraft:gray_concrete
fill ~-1 ~1 ~-104 ~-1 ~7 ~-104 minecraft:gray_concrete
# 132 row_house style=rowhouse context=local_front facing=south
fill ~100 ~-3 ~99 ~104 ~-1 ~106 minecraft:stone
fill ~100 ~0 ~99 ~104 ~5 ~106 minecraft:white_concrete
fill ~101 ~1 ~100 ~103 ~4 ~105 minecraft:air
fill ~101 ~4 ~100 ~103 ~4 ~105 minecraft:smooth_stone
fill ~102 ~2 ~99 ~102 ~3 ~99 minecraft:gray_stained_glass
fill ~102 ~2 ~106 ~102 ~3 ~106 minecraft:light_gray_stained_glass
fill ~100 ~2 ~101 ~100 ~3 ~101 minecraft:gray_stained_glass
fill ~104 ~2 ~101 ~104 ~3 ~101 minecraft:light_gray_stained_glass
fill ~100 ~2 ~104 ~100 ~3 ~104 minecraft:gray_stained_glass
fill ~104 ~2 ~104 ~104 ~3 ~104 minecraft:light_gray_stained_glass
setblock ~102 ~1 ~106 minecraft:iron_door[half=lower,facing=south]
setblock ~102 ~2 ~106 minecraft:iron_door[half=upper,facing=south]
fill ~100 ~6 ~99 ~104 ~6 ~106 minecraft:smooth_stone_slab
fill ~101 ~7 ~100 ~103 ~7 ~105 minecraft:smooth_stone_slab
setblock ~102 ~3 ~107 minecraft:dark_oak_slab[type=top]
# 133 community style=setback_block context=collector_front facing=north
fill ~-126 ~-3 ~-82 ~-121 ~-1 ~-70 minecraft:stone
fill ~-126 ~0 ~-82 ~-121 ~9 ~-70 minecraft:mud_bricks
fill ~-125 ~1 ~-81 ~-122 ~8 ~-71 minecraft:air
fill ~-125 ~4 ~-81 ~-122 ~4 ~-71 minecraft:smooth_stone
fill ~-125 ~8 ~-81 ~-122 ~8 ~-71 minecraft:smooth_stone
fill ~-124 ~2 ~-82 ~-124 ~3 ~-82 minecraft:gray_stained_glass
fill ~-124 ~2 ~-70 ~-124 ~3 ~-70 minecraft:light_gray_stained_glass
fill ~-126 ~2 ~-80 ~-126 ~3 ~-80 minecraft:gray_stained_glass
fill ~-121 ~2 ~-80 ~-121 ~3 ~-80 minecraft:light_gray_stained_glass
fill ~-126 ~2 ~-77 ~-126 ~3 ~-77 minecraft:gray_stained_glass
fill ~-121 ~2 ~-77 ~-121 ~3 ~-77 minecraft:light_gray_stained_glass
fill ~-126 ~2 ~-74 ~-126 ~3 ~-74 minecraft:gray_stained_glass
fill ~-121 ~2 ~-74 ~-121 ~3 ~-74 minecraft:light_gray_stained_glass
fill ~-124 ~6 ~-82 ~-124 ~7 ~-82 minecraft:gray_stained_glass
fill ~-124 ~6 ~-70 ~-124 ~7 ~-70 minecraft:light_gray_stained_glass
fill ~-126 ~6 ~-80 ~-126 ~7 ~-80 minecraft:gray_stained_glass
fill ~-121 ~6 ~-80 ~-121 ~7 ~-80 minecraft:light_gray_stained_glass
fill ~-126 ~6 ~-77 ~-126 ~7 ~-77 minecraft:gray_stained_glass
fill ~-121 ~6 ~-77 ~-121 ~7 ~-77 minecraft:light_gray_stained_glass
fill ~-126 ~6 ~-74 ~-126 ~7 ~-74 minecraft:gray_stained_glass
fill ~-121 ~6 ~-74 ~-121 ~7 ~-74 minecraft:light_gray_stained_glass
setblock ~-124 ~1 ~-82 minecraft:iron_door[half=lower,facing=north]
setblock ~-124 ~2 ~-82 minecraft:iron_door[half=upper,facing=north]
fill ~-125 ~1 ~-82 ~-125 ~7 ~-82 minecraft:spruce_planks
# 134 station_department_store style=civic_modern context=station_front facing=south
fill ~-79 ~-3 ~-21 ~-70 ~-1 ~-10 minecraft:stone
fill ~-79 ~0 ~-21 ~-70 ~8 ~-10 minecraft:smooth_sandstone
fill ~-78 ~1 ~-20 ~-71 ~7 ~-11 minecraft:air
fill ~-78 ~4 ~-20 ~-71 ~4 ~-11 minecraft:smooth_stone
fill ~-77 ~2 ~-21 ~-77 ~3 ~-21 minecraft:gray_stained_glass
fill ~-77 ~2 ~-10 ~-77 ~3 ~-10 minecraft:light_gray_stained_glass
fill ~-74 ~2 ~-21 ~-74 ~3 ~-21 minecraft:gray_stained_glass
fill ~-74 ~2 ~-10 ~-74 ~3 ~-10 minecraft:light_gray_stained_glass
fill ~-79 ~2 ~-19 ~-79 ~3 ~-19 minecraft:gray_stained_glass
fill ~-70 ~2 ~-19 ~-70 ~3 ~-19 minecraft:light_gray_stained_glass
fill ~-79 ~2 ~-16 ~-79 ~3 ~-16 minecraft:gray_stained_glass
fill ~-70 ~2 ~-16 ~-70 ~3 ~-16 minecraft:light_gray_stained_glass
fill ~-79 ~2 ~-13 ~-79 ~3 ~-13 minecraft:gray_stained_glass
fill ~-70 ~2 ~-13 ~-70 ~3 ~-13 minecraft:light_gray_stained_glass
fill ~-77 ~6 ~-21 ~-77 ~7 ~-21 minecraft:gray_stained_glass
fill ~-77 ~6 ~-10 ~-77 ~7 ~-10 minecraft:light_gray_stained_glass
fill ~-74 ~6 ~-21 ~-74 ~7 ~-21 minecraft:gray_stained_glass
fill ~-74 ~6 ~-10 ~-74 ~7 ~-10 minecraft:light_gray_stained_glass
fill ~-79 ~6 ~-19 ~-79 ~7 ~-19 minecraft:gray_stained_glass
fill ~-70 ~6 ~-19 ~-70 ~7 ~-19 minecraft:light_gray_stained_glass
fill ~-79 ~6 ~-16 ~-79 ~7 ~-16 minecraft:gray_stained_glass
fill ~-70 ~6 ~-16 ~-70 ~7 ~-16 minecraft:light_gray_stained_glass
fill ~-79 ~6 ~-13 ~-79 ~7 ~-13 minecraft:gray_stained_glass
fill ~-70 ~6 ~-13 ~-70 ~7 ~-13 minecraft:light_gray_stained_glass
setblock ~-75 ~1 ~-10 minecraft:iron_door[half=lower,facing=south]
setblock ~-75 ~2 ~-10 minecraft:iron_door[half=upper,facing=south]
fill ~-78 ~1 ~-10 ~-78 ~7 ~-10 minecraft:brown_terracotta
fill ~-74 ~1 ~-10 ~-74 ~7 ~-10 minecraft:brown_terracotta
# 135 midrise_housing style=balcony_block context=collector_front facing=east
fill ~-101 ~-3 ~75 ~-94 ~-1 ~79 minecraft:stone
fill ~-101 ~0 ~75 ~-94 ~9 ~79 minecraft:white_terracotta
fill ~-100 ~1 ~76 ~-95 ~8 ~78 minecraft:air
fill ~-100 ~4 ~76 ~-95 ~4 ~78 minecraft:smooth_stone
fill ~-100 ~8 ~76 ~-95 ~8 ~78 minecraft:smooth_stone
fill ~-99 ~2 ~75 ~-99 ~3 ~75 minecraft:gray_stained_glass
fill ~-99 ~2 ~79 ~-99 ~3 ~79 minecraft:light_gray_stained_glass
fill ~-96 ~2 ~75 ~-96 ~3 ~75 minecraft:gray_stained_glass
fill ~-96 ~2 ~79 ~-96 ~3 ~79 minecraft:light_gray_stained_glass
fill ~-101 ~2 ~77 ~-101 ~3 ~77 minecraft:gray_stained_glass
fill ~-94 ~2 ~77 ~-94 ~3 ~77 minecraft:light_gray_stained_glass
fill ~-99 ~6 ~75 ~-99 ~7 ~75 minecraft:gray_stained_glass
fill ~-99 ~6 ~79 ~-99 ~7 ~79 minecraft:light_gray_stained_glass
fill ~-96 ~6 ~75 ~-96 ~7 ~75 minecraft:gray_stained_glass
fill ~-96 ~6 ~79 ~-96 ~7 ~79 minecraft:light_gray_stained_glass
fill ~-101 ~6 ~77 ~-101 ~7 ~77 minecraft:gray_stained_glass
fill ~-94 ~6 ~77 ~-94 ~7 ~77 minecraft:light_gray_stained_glass
setblock ~-94 ~1 ~77 minecraft:iron_door[half=lower,facing=east]
setblock ~-94 ~2 ~77 minecraft:iron_door[half=upper,facing=east]
fill ~-93 ~4 ~77 ~-93 ~4 ~77 minecraft:smooth_stone_slab
fill ~-93 ~8 ~77 ~-93 ~8 ~77 minecraft:smooth_stone_slab
fill ~-101 ~10 ~75 ~-94 ~10 ~79 minecraft:dark_oak_slab
fill ~-99 ~11 ~77 ~-97 ~12 ~78 minecraft:light_gray_concrete
setblock ~-96 ~11 ~78 minecraft:lightning_rod
# 136 shop_house style=corner_store context=collector_front facing=north
fill ~-112 ~-3 ~52 ~-107 ~-1 ~62 minecraft:stone
fill ~-112 ~0 ~52 ~-107 ~9 ~62 minecraft:white_terracotta
fill ~-111 ~1 ~53 ~-108 ~8 ~61 minecraft:air
fill ~-111 ~4 ~53 ~-108 ~4 ~61 minecraft:smooth_stone
fill ~-111 ~8 ~53 ~-108 ~8 ~61 minecraft:smooth_stone
fill ~-110 ~2 ~52 ~-110 ~3 ~52 minecraft:gray_stained_glass
fill ~-110 ~2 ~62 ~-110 ~3 ~62 minecraft:light_gray_stained_glass
fill ~-112 ~2 ~54 ~-112 ~3 ~54 minecraft:gray_stained_glass
fill ~-107 ~2 ~54 ~-107 ~3 ~54 minecraft:light_gray_stained_glass
fill ~-112 ~2 ~57 ~-112 ~3 ~57 minecraft:gray_stained_glass
fill ~-107 ~2 ~57 ~-107 ~3 ~57 minecraft:light_gray_stained_glass
fill ~-112 ~2 ~60 ~-112 ~3 ~60 minecraft:gray_stained_glass
fill ~-107 ~2 ~60 ~-107 ~3 ~60 minecraft:light_gray_stained_glass
fill ~-110 ~6 ~52 ~-110 ~7 ~52 minecraft:gray_stained_glass
fill ~-110 ~6 ~62 ~-110 ~7 ~62 minecraft:light_gray_stained_glass
fill ~-112 ~6 ~54 ~-112 ~7 ~54 minecraft:gray_stained_glass
fill ~-107 ~6 ~54 ~-107 ~7 ~54 minecraft:light_gray_stained_glass
fill ~-112 ~6 ~57 ~-112 ~7 ~57 minecraft:gray_stained_glass
fill ~-107 ~6 ~57 ~-107 ~7 ~57 minecraft:light_gray_stained_glass
fill ~-112 ~6 ~60 ~-112 ~7 ~60 minecraft:gray_stained_glass
fill ~-107 ~6 ~60 ~-107 ~7 ~60 minecraft:light_gray_stained_glass
setblock ~-110 ~1 ~52 minecraft:iron_door[half=lower,facing=north]
setblock ~-110 ~2 ~52 minecraft:iron_door[half=upper,facing=north]
fill ~-111 ~1 ~52 ~-108 ~3 ~52 minecraft:cyan_stained_glass
setblock ~-110 ~1 ~52 minecraft:iron_door[half=lower,facing=north]
setblock ~-110 ~2 ~52 minecraft:iron_door[half=upper,facing=north]
setblock ~-110 ~3 ~51 minecraft:red_wool
fill ~-112 ~10 ~52 ~-107 ~10 ~62 minecraft:dark_oak_slab
fill ~-111 ~1 ~52 ~-111 ~7 ~52 minecraft:dark_oak_planks
setblock ~-110 ~3 ~52 minecraft:red_carpet
