# Buildings 81..88
# 081 medical_center style=civic_modern context=arterial_front facing=north
fill ~-30 ~-3 ~-7 ~-19 ~-1 ~0 minecraft:stone
fill ~-30 ~0 ~-7 ~-19 ~24 ~0 minecraft:bricks
fill ~-29 ~1 ~-6 ~-20 ~23 ~-1 minecraft:air
fill ~-29 ~4 ~-6 ~-20 ~4 ~-1 minecraft:smooth_stone
fill ~-29 ~8 ~-6 ~-20 ~8 ~-1 minecraft:smooth_stone
fill ~-29 ~12 ~-6 ~-20 ~12 ~-1 minecraft:smooth_stone
fill ~-29 ~16 ~-6 ~-20 ~16 ~-1 minecraft:smooth_stone
fill ~-29 ~20 ~-6 ~-20 ~20 ~-1 minecraft:smooth_stone
fill ~-28 ~2 ~-7 ~-28 ~3 ~-7 minecraft:gray_stained_glass
fill ~-28 ~2 ~0 ~-28 ~3 ~0 minecraft:light_gray_stained_glass
fill ~-25 ~2 ~-7 ~-25 ~3 ~-7 minecraft:gray_stained_glass
fill ~-25 ~2 ~0 ~-25 ~3 ~0 minecraft:light_gray_stained_glass
fill ~-22 ~2 ~-7 ~-22 ~3 ~-7 minecraft:gray_stained_glass
fill ~-22 ~2 ~0 ~-22 ~3 ~0 minecraft:light_gray_stained_glass
fill ~-30 ~2 ~-5 ~-30 ~3 ~-5 minecraft:gray_stained_glass
fill ~-19 ~2 ~-5 ~-19 ~3 ~-5 minecraft:light_gray_stained_glass
fill ~-30 ~2 ~-2 ~-30 ~3 ~-2 minecraft:gray_stained_glass
fill ~-19 ~2 ~-2 ~-19 ~3 ~-2 minecraft:light_gray_stained_glass
fill ~-28 ~6 ~-7 ~-28 ~7 ~-7 minecraft:gray_stained_glass
fill ~-28 ~6 ~0 ~-28 ~7 ~0 minecraft:light_gray_stained_glass
fill ~-25 ~6 ~-7 ~-25 ~7 ~-7 minecraft:gray_stained_glass
fill ~-25 ~6 ~0 ~-25 ~7 ~0 minecraft:light_gray_stained_glass
fill ~-22 ~6 ~-7 ~-22 ~7 ~-7 minecraft:gray_stained_glass
fill ~-22 ~6 ~0 ~-22 ~7 ~0 minecraft:light_gray_stained_glass
fill ~-30 ~6 ~-5 ~-30 ~7 ~-5 minecraft:gray_stained_glass
fill ~-19 ~6 ~-5 ~-19 ~7 ~-5 minecraft:light_gray_stained_glass
fill ~-30 ~6 ~-2 ~-30 ~7 ~-2 minecraft:gray_stained_glass
fill ~-19 ~6 ~-2 ~-19 ~7 ~-2 minecraft:light_gray_stained_glass
fill ~-28 ~10 ~-7 ~-28 ~11 ~-7 minecraft:gray_stained_glass
fill ~-28 ~10 ~0 ~-28 ~11 ~0 minecraft:light_gray_stained_glass
fill ~-25 ~10 ~-7 ~-25 ~11 ~-7 minecraft:gray_stained_glass
fill ~-25 ~10 ~0 ~-25 ~11 ~0 minecraft:light_gray_stained_glass
fill ~-22 ~10 ~-7 ~-22 ~11 ~-7 minecraft:gray_stained_glass
fill ~-22 ~10 ~0 ~-22 ~11 ~0 minecraft:light_gray_stained_glass
fill ~-30 ~10 ~-5 ~-30 ~11 ~-5 minecraft:gray_stained_glass
fill ~-19 ~10 ~-5 ~-19 ~11 ~-5 minecraft:light_gray_stained_glass
fill ~-30 ~10 ~-2 ~-30 ~11 ~-2 minecraft:gray_stained_glass
fill ~-19 ~10 ~-2 ~-19 ~11 ~-2 minecraft:light_gray_stained_glass
fill ~-28 ~14 ~-7 ~-28 ~15 ~-7 minecraft:gray_stained_glass
fill ~-28 ~14 ~0 ~-28 ~15 ~0 minecraft:light_gray_stained_glass
fill ~-25 ~14 ~-7 ~-25 ~15 ~-7 minecraft:gray_stained_glass
fill ~-25 ~14 ~0 ~-25 ~15 ~0 minecraft:light_gray_stained_glass
fill ~-22 ~14 ~-7 ~-22 ~15 ~-7 minecraft:gray_stained_glass
fill ~-22 ~14 ~0 ~-22 ~15 ~0 minecraft:light_gray_stained_glass
fill ~-30 ~14 ~-5 ~-30 ~15 ~-5 minecraft:gray_stained_glass
fill ~-19 ~14 ~-5 ~-19 ~15 ~-5 minecraft:light_gray_stained_glass
fill ~-30 ~14 ~-2 ~-30 ~15 ~-2 minecraft:gray_stained_glass
fill ~-19 ~14 ~-2 ~-19 ~15 ~-2 minecraft:light_gray_stained_glass
fill ~-28 ~18 ~-7 ~-28 ~19 ~-7 minecraft:gray_stained_glass
fill ~-28 ~18 ~0 ~-28 ~19 ~0 minecraft:light_gray_stained_glass
fill ~-25 ~18 ~-7 ~-25 ~19 ~-7 minecraft:gray_stained_glass
fill ~-25 ~18 ~0 ~-25 ~19 ~0 minecraft:light_gray_stained_glass
fill ~-22 ~18 ~-7 ~-22 ~19 ~-7 minecraft:gray_stained_glass
fill ~-22 ~18 ~0 ~-22 ~19 ~0 minecraft:light_gray_stained_glass
fill ~-30 ~18 ~-5 ~-30 ~19 ~-5 minecraft:gray_stained_glass
fill ~-19 ~18 ~-5 ~-19 ~19 ~-5 minecraft:light_gray_stained_glass
fill ~-30 ~18 ~-2 ~-30 ~19 ~-2 minecraft:gray_stained_glass
fill ~-19 ~18 ~-2 ~-19 ~19 ~-2 minecraft:light_gray_stained_glass
fill ~-28 ~22 ~-7 ~-28 ~23 ~-7 minecraft:gray_stained_glass
fill ~-28 ~22 ~0 ~-28 ~23 ~0 minecraft:light_gray_stained_glass
fill ~-25 ~22 ~-7 ~-25 ~23 ~-7 minecraft:gray_stained_glass
fill ~-25 ~22 ~0 ~-25 ~23 ~0 minecraft:light_gray_stained_glass
fill ~-22 ~22 ~-7 ~-22 ~23 ~-7 minecraft:gray_stained_glass
fill ~-22 ~22 ~0 ~-22 ~23 ~0 minecraft:light_gray_stained_glass
fill ~-30 ~22 ~-5 ~-30 ~23 ~-5 minecraft:gray_stained_glass
fill ~-19 ~22 ~-5 ~-19 ~23 ~-5 minecraft:light_gray_stained_glass
fill ~-30 ~22 ~-2 ~-30 ~23 ~-2 minecraft:gray_stained_glass
fill ~-19 ~22 ~-2 ~-19 ~23 ~-2 minecraft:light_gray_stained_glass
setblock ~-25 ~1 ~-7 minecraft:iron_door[half=lower,facing=north]
setblock ~-25 ~2 ~-7 minecraft:iron_door[half=upper,facing=north]
fill ~-30 ~19 ~-7 ~-19 ~24 ~0 minecraft:air
fill ~-29 ~19 ~-6 ~-20 ~24 ~-1 minecraft:bricks
fill ~-28 ~20 ~-5 ~-21 ~23 ~-2 minecraft:air
fill ~-29 ~25 ~-6 ~-20 ~25 ~-1 minecraft:deepslate_tile_slab
fill ~-28 ~26 ~-5 ~-26 ~27 ~-3 minecraft:light_gray_concrete
setblock ~-25 ~26 ~-4 minecraft:lightning_rod
# 082 logistics style=industrial_shed context=back_block facing=east
fill ~32 ~-3 ~-121 ~42 ~-1 ~-111 minecraft:stone
fill ~32 ~0 ~-121 ~42 ~10 ~-111 minecraft:stone_bricks
fill ~33 ~1 ~-120 ~41 ~9 ~-112 minecraft:air
fill ~33 ~4 ~-120 ~41 ~4 ~-112 minecraft:smooth_stone
fill ~33 ~8 ~-120 ~41 ~8 ~-112 minecraft:smooth_stone
fill ~34 ~2 ~-121 ~34 ~3 ~-121 minecraft:gray_stained_glass
fill ~34 ~2 ~-111 ~34 ~3 ~-111 minecraft:light_gray_stained_glass
fill ~37 ~2 ~-121 ~37 ~3 ~-121 minecraft:gray_stained_glass
fill ~37 ~2 ~-111 ~37 ~3 ~-111 minecraft:light_gray_stained_glass
fill ~40 ~2 ~-121 ~40 ~3 ~-121 minecraft:gray_stained_glass
fill ~40 ~2 ~-111 ~40 ~3 ~-111 minecraft:light_gray_stained_glass
fill ~32 ~2 ~-119 ~32 ~3 ~-119 minecraft:gray_stained_glass
fill ~42 ~2 ~-119 ~42 ~3 ~-119 minecraft:light_gray_stained_glass
fill ~32 ~2 ~-116 ~32 ~3 ~-116 minecraft:gray_stained_glass
fill ~42 ~2 ~-116 ~42 ~3 ~-116 minecraft:light_gray_stained_glass
fill ~32 ~2 ~-113 ~32 ~3 ~-113 minecraft:gray_stained_glass
fill ~42 ~2 ~-113 ~42 ~3 ~-113 minecraft:light_gray_stained_glass
fill ~34 ~6 ~-121 ~34 ~7 ~-121 minecraft:gray_stained_glass
fill ~34 ~6 ~-111 ~34 ~7 ~-111 minecraft:light_gray_stained_glass
fill ~37 ~6 ~-121 ~37 ~7 ~-121 minecraft:gray_stained_glass
fill ~37 ~6 ~-111 ~37 ~7 ~-111 minecraft:light_gray_stained_glass
fill ~40 ~6 ~-121 ~40 ~7 ~-121 minecraft:gray_stained_glass
fill ~40 ~6 ~-111 ~40 ~7 ~-111 minecraft:light_gray_stained_glass
fill ~32 ~6 ~-119 ~32 ~7 ~-119 minecraft:gray_stained_glass
fill ~42 ~6 ~-119 ~42 ~7 ~-119 minecraft:light_gray_stained_glass
fill ~32 ~6 ~-116 ~32 ~7 ~-116 minecraft:gray_stained_glass
fill ~42 ~6 ~-116 ~42 ~7 ~-116 minecraft:light_gray_stained_glass
fill ~32 ~6 ~-113 ~32 ~7 ~-113 minecraft:gray_stained_glass
fill ~42 ~6 ~-113 ~42 ~7 ~-113 minecraft:light_gray_stained_glass
setblock ~42 ~1 ~-116 minecraft:iron_door[half=lower,facing=east]
setblock ~42 ~2 ~-116 minecraft:iron_door[half=upper,facing=east]
fill ~42 ~1 ~-119 ~42 ~4 ~-113 minecraft:polished_blackstone
fill ~42 ~5 ~-119 ~42 ~5 ~-113 minecraft:light_blue_stained_glass
fill ~34 ~12 ~-119 ~36 ~13 ~-117 minecraft:iron_block
fill ~32 ~11 ~-121 ~42 ~11 ~-111 minecraft:smooth_stone_slab
# 083 detached_house style=stepped_house context=back_block facing=north
fill ~-25 ~-3 ~45 ~-19 ~-1 ~53 minecraft:stone
fill ~-25 ~0 ~45 ~-19 ~24 ~53 minecraft:light_gray_concrete
fill ~-24 ~1 ~46 ~-20 ~23 ~52 minecraft:air
fill ~-24 ~4 ~46 ~-20 ~4 ~52 minecraft:smooth_stone
fill ~-24 ~8 ~46 ~-20 ~8 ~52 minecraft:smooth_stone
fill ~-24 ~12 ~46 ~-20 ~12 ~52 minecraft:smooth_stone
fill ~-24 ~16 ~46 ~-20 ~16 ~52 minecraft:smooth_stone
fill ~-24 ~20 ~46 ~-20 ~20 ~52 minecraft:smooth_stone
fill ~-23 ~2 ~45 ~-23 ~3 ~45 minecraft:gray_stained_glass
fill ~-23 ~2 ~53 ~-23 ~3 ~53 minecraft:light_gray_stained_glass
fill ~-25 ~2 ~47 ~-25 ~3 ~47 minecraft:gray_stained_glass
fill ~-19 ~2 ~47 ~-19 ~3 ~47 minecraft:light_gray_stained_glass
fill ~-25 ~2 ~50 ~-25 ~3 ~50 minecraft:gray_stained_glass
fill ~-19 ~2 ~50 ~-19 ~3 ~50 minecraft:light_gray_stained_glass
fill ~-23 ~6 ~45 ~-23 ~7 ~45 minecraft:gray_stained_glass
fill ~-23 ~6 ~53 ~-23 ~7 ~53 minecraft:light_gray_stained_glass
fill ~-25 ~6 ~47 ~-25 ~7 ~47 minecraft:gray_stained_glass
fill ~-19 ~6 ~47 ~-19 ~7 ~47 minecraft:light_gray_stained_glass
fill ~-25 ~6 ~50 ~-25 ~7 ~50 minecraft:gray_stained_glass
fill ~-19 ~6 ~50 ~-19 ~7 ~50 minecraft:light_gray_stained_glass
fill ~-23 ~10 ~45 ~-23 ~11 ~45 minecraft:gray_stained_glass
fill ~-23 ~10 ~53 ~-23 ~11 ~53 minecraft:light_gray_stained_glass
fill ~-25 ~10 ~47 ~-25 ~11 ~47 minecraft:gray_stained_glass
fill ~-19 ~10 ~47 ~-19 ~11 ~47 minecraft:light_gray_stained_glass
fill ~-25 ~10 ~50 ~-25 ~11 ~50 minecraft:gray_stained_glass
fill ~-19 ~10 ~50 ~-19 ~11 ~50 minecraft:light_gray_stained_glass
fill ~-23 ~14 ~45 ~-23 ~15 ~45 minecraft:gray_stained_glass
fill ~-23 ~14 ~53 ~-23 ~15 ~53 minecraft:light_gray_stained_glass
fill ~-25 ~14 ~47 ~-25 ~15 ~47 minecraft:gray_stained_glass
fill ~-19 ~14 ~47 ~-19 ~15 ~47 minecraft:light_gray_stained_glass
fill ~-25 ~14 ~50 ~-25 ~15 ~50 minecraft:gray_stained_glass
fill ~-19 ~14 ~50 ~-19 ~15 ~50 minecraft:light_gray_stained_glass
fill ~-23 ~18 ~45 ~-23 ~19 ~45 minecraft:gray_stained_glass
fill ~-23 ~18 ~53 ~-23 ~19 ~53 minecraft:light_gray_stained_glass
fill ~-25 ~18 ~47 ~-25 ~19 ~47 minecraft:gray_stained_glass
fill ~-19 ~18 ~47 ~-19 ~19 ~47 minecraft:light_gray_stained_glass
fill ~-25 ~18 ~50 ~-25 ~19 ~50 minecraft:gray_stained_glass
fill ~-19 ~18 ~50 ~-19 ~19 ~50 minecraft:light_gray_stained_glass
fill ~-23 ~22 ~45 ~-23 ~23 ~45 minecraft:gray_stained_glass
fill ~-23 ~22 ~53 ~-23 ~23 ~53 minecraft:light_gray_stained_glass
fill ~-25 ~22 ~47 ~-25 ~23 ~47 minecraft:gray_stained_glass
fill ~-19 ~22 ~47 ~-19 ~23 ~47 minecraft:light_gray_stained_glass
fill ~-25 ~22 ~50 ~-25 ~23 ~50 minecraft:gray_stained_glass
fill ~-19 ~22 ~50 ~-19 ~23 ~50 minecraft:light_gray_stained_glass
setblock ~-22 ~1 ~45 minecraft:iron_door[half=lower,facing=north]
setblock ~-22 ~2 ~45 minecraft:iron_door[half=upper,facing=north]
fill ~-25 ~25 ~45 ~-19 ~25 ~53 minecraft:smooth_stone_slab
fill ~-24 ~26 ~46 ~-20 ~26 ~52 minecraft:smooth_stone_slab
setblock ~-22 ~3 ~44 minecraft:dark_oak_slab[type=top]
# 084 detached_house style=japanese_house context=back_block facing=east
fill ~-78 ~-3 ~112 ~-72 ~-1 ~123 minecraft:stone
fill ~-78 ~0 ~112 ~-72 ~9 ~123 minecraft:white_terracotta
fill ~-77 ~1 ~113 ~-73 ~8 ~122 minecraft:air
fill ~-77 ~4 ~113 ~-73 ~4 ~122 minecraft:smooth_stone
fill ~-77 ~8 ~113 ~-73 ~8 ~122 minecraft:smooth_stone
fill ~-76 ~2 ~112 ~-76 ~3 ~112 minecraft:gray_stained_glass
fill ~-76 ~2 ~123 ~-76 ~3 ~123 minecraft:light_gray_stained_glass
fill ~-78 ~2 ~114 ~-78 ~3 ~114 minecraft:gray_stained_glass
fill ~-72 ~2 ~114 ~-72 ~3 ~114 minecraft:light_gray_stained_glass
fill ~-78 ~2 ~117 ~-78 ~3 ~117 minecraft:gray_stained_glass
fill ~-72 ~2 ~117 ~-72 ~3 ~117 minecraft:light_gray_stained_glass
fill ~-78 ~2 ~120 ~-78 ~3 ~120 minecraft:gray_stained_glass
fill ~-72 ~2 ~120 ~-72 ~3 ~120 minecraft:light_gray_stained_glass
fill ~-76 ~6 ~112 ~-76 ~7 ~112 minecraft:gray_stained_glass
fill ~-76 ~6 ~123 ~-76 ~7 ~123 minecraft:light_gray_stained_glass
fill ~-78 ~6 ~114 ~-78 ~7 ~114 minecraft:gray_stained_glass
fill ~-72 ~6 ~114 ~-72 ~7 ~114 minecraft:light_gray_stained_glass
fill ~-78 ~6 ~117 ~-78 ~7 ~117 minecraft:gray_stained_glass
fill ~-72 ~6 ~117 ~-72 ~7 ~117 minecraft:light_gray_stained_glass
fill ~-78 ~6 ~120 ~-78 ~7 ~120 minecraft:gray_stained_glass
fill ~-72 ~6 ~120 ~-72 ~7 ~120 minecraft:light_gray_stained_glass
setblock ~-72 ~1 ~117 minecraft:iron_door[half=lower,facing=east]
setblock ~-72 ~2 ~117 minecraft:iron_door[half=upper,facing=east]
fill ~-78 ~10 ~112 ~-72 ~10 ~123 minecraft:dark_oak_slab
fill ~-77 ~11 ~113 ~-73 ~11 ~122 minecraft:dark_oak_slab
setblock ~-71 ~3 ~117 minecraft:dark_oak_slab[type=top]
fill ~-76 ~11 ~114 ~-74 ~12 ~116 minecraft:light_gray_concrete
setblock ~-73 ~11 ~115 minecraft:lightning_rod
# 085 factory style=loading_bay context=waterfront_front facing=west
fill ~83 ~-3 ~108 ~94 ~-1 ~118 minecraft:stone
fill ~83 ~0 ~108 ~94 ~8 ~118 minecraft:stone_bricks
fill ~84 ~1 ~109 ~93 ~7 ~117 minecraft:air
fill ~84 ~4 ~109 ~93 ~4 ~117 minecraft:smooth_stone
fill ~85 ~2 ~108 ~85 ~3 ~108 minecraft:gray_stained_glass
fill ~85 ~2 ~118 ~85 ~3 ~118 minecraft:light_gray_stained_glass
fill ~88 ~2 ~108 ~88 ~3 ~108 minecraft:gray_stained_glass
fill ~88 ~2 ~118 ~88 ~3 ~118 minecraft:light_gray_stained_glass
fill ~91 ~2 ~108 ~91 ~3 ~108 minecraft:gray_stained_glass
fill ~91 ~2 ~118 ~91 ~3 ~118 minecraft:light_gray_stained_glass
fill ~83 ~2 ~110 ~83 ~3 ~110 minecraft:gray_stained_glass
fill ~94 ~2 ~110 ~94 ~3 ~110 minecraft:light_gray_stained_glass
fill ~83 ~2 ~113 ~83 ~3 ~113 minecraft:gray_stained_glass
fill ~94 ~2 ~113 ~94 ~3 ~113 minecraft:light_gray_stained_glass
fill ~83 ~2 ~116 ~83 ~3 ~116 minecraft:gray_stained_glass
fill ~94 ~2 ~116 ~94 ~3 ~116 minecraft:light_gray_stained_glass
fill ~85 ~6 ~108 ~85 ~7 ~108 minecraft:gray_stained_glass
fill ~85 ~6 ~118 ~85 ~7 ~118 minecraft:light_gray_stained_glass
fill ~88 ~6 ~108 ~88 ~7 ~108 minecraft:gray_stained_glass
fill ~88 ~6 ~118 ~88 ~7 ~118 minecraft:light_gray_stained_glass
fill ~91 ~6 ~108 ~91 ~7 ~108 minecraft:gray_stained_glass
fill ~91 ~6 ~118 ~91 ~7 ~118 minecraft:light_gray_stained_glass
fill ~83 ~6 ~110 ~83 ~7 ~110 minecraft:gray_stained_glass
fill ~94 ~6 ~110 ~94 ~7 ~110 minecraft:light_gray_stained_glass
fill ~83 ~6 ~113 ~83 ~7 ~113 minecraft:gray_stained_glass
fill ~94 ~6 ~113 ~94 ~7 ~113 minecraft:light_gray_stained_glass
fill ~83 ~6 ~116 ~83 ~7 ~116 minecraft:gray_stained_glass
fill ~94 ~6 ~116 ~94 ~7 ~116 minecraft:light_gray_stained_glass
setblock ~83 ~1 ~113 minecraft:iron_door[half=lower,facing=west]
setblock ~83 ~2 ~113 minecraft:iron_door[half=upper,facing=west]
fill ~83 ~1 ~110 ~83 ~4 ~116 minecraft:polished_blackstone
fill ~83 ~5 ~110 ~83 ~5 ~116 minecraft:light_blue_stained_glass
fill ~85 ~10 ~110 ~87 ~11 ~112 minecraft:iron_block
fill ~83 ~9 ~108 ~94 ~9 ~118 minecraft:stone_brick_slab
# 086 factory style=loading_bay context=back_block facing=west
fill ~72 ~-3 ~-125 ~83 ~-1 ~-115 minecraft:stone
fill ~72 ~0 ~-125 ~83 ~8 ~-115 minecraft:bricks
fill ~73 ~1 ~-124 ~82 ~7 ~-116 minecraft:air
fill ~73 ~4 ~-124 ~82 ~4 ~-116 minecraft:smooth_stone
fill ~74 ~2 ~-125 ~74 ~3 ~-125 minecraft:gray_stained_glass
fill ~74 ~2 ~-115 ~74 ~3 ~-115 minecraft:light_gray_stained_glass
fill ~77 ~2 ~-125 ~77 ~3 ~-125 minecraft:gray_stained_glass
fill ~77 ~2 ~-115 ~77 ~3 ~-115 minecraft:light_gray_stained_glass
fill ~80 ~2 ~-125 ~80 ~3 ~-125 minecraft:gray_stained_glass
fill ~80 ~2 ~-115 ~80 ~3 ~-115 minecraft:light_gray_stained_glass
fill ~72 ~2 ~-123 ~72 ~3 ~-123 minecraft:gray_stained_glass
fill ~83 ~2 ~-123 ~83 ~3 ~-123 minecraft:light_gray_stained_glass
fill ~72 ~2 ~-120 ~72 ~3 ~-120 minecraft:gray_stained_glass
fill ~83 ~2 ~-120 ~83 ~3 ~-120 minecraft:light_gray_stained_glass
fill ~72 ~2 ~-117 ~72 ~3 ~-117 minecraft:gray_stained_glass
fill ~83 ~2 ~-117 ~83 ~3 ~-117 minecraft:light_gray_stained_glass
fill ~74 ~6 ~-125 ~74 ~7 ~-125 minecraft:gray_stained_glass
fill ~74 ~6 ~-115 ~74 ~7 ~-115 minecraft:light_gray_stained_glass
fill ~77 ~6 ~-125 ~77 ~7 ~-125 minecraft:gray_stained_glass
fill ~77 ~6 ~-115 ~77 ~7 ~-115 minecraft:light_gray_stained_glass
fill ~80 ~6 ~-125 ~80 ~7 ~-125 minecraft:gray_stained_glass
fill ~80 ~6 ~-115 ~80 ~7 ~-115 minecraft:light_gray_stained_glass
fill ~72 ~6 ~-123 ~72 ~7 ~-123 minecraft:gray_stained_glass
fill ~83 ~6 ~-123 ~83 ~7 ~-123 minecraft:light_gray_stained_glass
fill ~72 ~6 ~-120 ~72 ~7 ~-120 minecraft:gray_stained_glass
fill ~83 ~6 ~-120 ~83 ~7 ~-120 minecraft:light_gray_stained_glass
fill ~72 ~6 ~-117 ~72 ~7 ~-117 minecraft:gray_stained_glass
fill ~83 ~6 ~-117 ~83 ~7 ~-117 minecraft:light_gray_stained_glass
setblock ~72 ~1 ~-120 minecraft:iron_door[half=lower,facing=west]
setblock ~72 ~2 ~-120 minecraft:iron_door[half=upper,facing=west]
fill ~72 ~1 ~-123 ~72 ~4 ~-117 minecraft:polished_blackstone
fill ~72 ~5 ~-123 ~72 ~5 ~-117 minecraft:light_blue_stained_glass
fill ~74 ~10 ~-123 ~76 ~11 ~-121 minecraft:iron_block
fill ~72 ~9 ~-125 ~83 ~9 ~-115 minecraft:deepslate_tile_slab
# 087 hotel style=bay_office context=arterial_front facing=west
fill ~-23 ~-3 ~-123 ~-4 ~-1 ~-113 minecraft:stone
fill ~-23 ~0 ~-123 ~-4 ~12 ~-113 minecraft:bricks
fill ~-22 ~1 ~-122 ~-5 ~11 ~-114 minecraft:air
fill ~-22 ~4 ~-122 ~-5 ~4 ~-114 minecraft:smooth_stone
fill ~-22 ~8 ~-122 ~-5 ~8 ~-114 minecraft:smooth_stone
fill ~-21 ~2 ~-123 ~-21 ~3 ~-123 minecraft:gray_stained_glass
fill ~-21 ~2 ~-113 ~-21 ~3 ~-113 minecraft:light_gray_stained_glass
fill ~-18 ~2 ~-123 ~-18 ~3 ~-123 minecraft:gray_stained_glass
fill ~-18 ~2 ~-113 ~-18 ~3 ~-113 minecraft:light_gray_stained_glass
fill ~-15 ~2 ~-123 ~-15 ~3 ~-123 minecraft:gray_stained_glass
fill ~-15 ~2 ~-113 ~-15 ~3 ~-113 minecraft:light_gray_stained_glass
fill ~-12 ~2 ~-123 ~-12 ~3 ~-123 minecraft:gray_stained_glass
fill ~-12 ~2 ~-113 ~-12 ~3 ~-113 minecraft:light_gray_stained_glass
fill ~-9 ~2 ~-123 ~-9 ~3 ~-123 minecraft:gray_stained_glass
fill ~-9 ~2 ~-113 ~-9 ~3 ~-113 minecraft:light_gray_stained_glass
fill ~-6 ~2 ~-123 ~-6 ~3 ~-123 minecraft:gray_stained_glass
fill ~-6 ~2 ~-113 ~-6 ~3 ~-113 minecraft:light_gray_stained_glass
fill ~-23 ~2 ~-121 ~-23 ~3 ~-121 minecraft:gray_stained_glass
fill ~-4 ~2 ~-121 ~-4 ~3 ~-121 minecraft:light_gray_stained_glass
fill ~-23 ~2 ~-118 ~-23 ~3 ~-118 minecraft:gray_stained_glass
fill ~-4 ~2 ~-118 ~-4 ~3 ~-118 minecraft:light_gray_stained_glass
fill ~-23 ~2 ~-115 ~-23 ~3 ~-115 minecraft:gray_stained_glass
fill ~-4 ~2 ~-115 ~-4 ~3 ~-115 minecraft:light_gray_stained_glass
fill ~-21 ~6 ~-123 ~-21 ~7 ~-123 minecraft:gray_stained_glass
fill ~-21 ~6 ~-113 ~-21 ~7 ~-113 minecraft:light_gray_stained_glass
fill ~-18 ~6 ~-123 ~-18 ~7 ~-123 minecraft:gray_stained_glass
fill ~-18 ~6 ~-113 ~-18 ~7 ~-113 minecraft:light_gray_stained_glass
fill ~-15 ~6 ~-123 ~-15 ~7 ~-123 minecraft:gray_stained_glass
fill ~-15 ~6 ~-113 ~-15 ~7 ~-113 minecraft:light_gray_stained_glass
fill ~-12 ~6 ~-123 ~-12 ~7 ~-123 minecraft:gray_stained_glass
fill ~-12 ~6 ~-113 ~-12 ~7 ~-113 minecraft:light_gray_stained_glass
fill ~-9 ~6 ~-123 ~-9 ~7 ~-123 minecraft:gray_stained_glass
fill ~-9 ~6 ~-113 ~-9 ~7 ~-113 minecraft:light_gray_stained_glass
fill ~-6 ~6 ~-123 ~-6 ~7 ~-123 minecraft:gray_stained_glass
fill ~-6 ~6 ~-113 ~-6 ~7 ~-113 minecraft:light_gray_stained_glass
fill ~-23 ~6 ~-121 ~-23 ~7 ~-121 minecraft:gray_stained_glass
fill ~-4 ~6 ~-121 ~-4 ~7 ~-121 minecraft:light_gray_stained_glass
fill ~-23 ~6 ~-118 ~-23 ~7 ~-118 minecraft:gray_stained_glass
fill ~-4 ~6 ~-118 ~-4 ~7 ~-118 minecraft:light_gray_stained_glass
fill ~-23 ~6 ~-115 ~-23 ~7 ~-115 minecraft:gray_stained_glass
fill ~-4 ~6 ~-115 ~-4 ~7 ~-115 minecraft:light_gray_stained_glass
fill ~-21 ~10 ~-123 ~-21 ~11 ~-123 minecraft:gray_stained_glass
fill ~-21 ~10 ~-113 ~-21 ~11 ~-113 minecraft:light_gray_stained_glass
fill ~-18 ~10 ~-123 ~-18 ~11 ~-123 minecraft:gray_stained_glass
fill ~-18 ~10 ~-113 ~-18 ~11 ~-113 minecraft:light_gray_stained_glass
fill ~-15 ~10 ~-123 ~-15 ~11 ~-123 minecraft:gray_stained_glass
fill ~-15 ~10 ~-113 ~-15 ~11 ~-113 minecraft:light_gray_stained_glass
fill ~-12 ~10 ~-123 ~-12 ~11 ~-123 minecraft:gray_stained_glass
fill ~-12 ~10 ~-113 ~-12 ~11 ~-113 minecraft:light_gray_stained_glass
fill ~-9 ~10 ~-123 ~-9 ~11 ~-123 minecraft:gray_stained_glass
fill ~-9 ~10 ~-113 ~-9 ~11 ~-113 minecraft:light_gray_stained_glass
fill ~-6 ~10 ~-123 ~-6 ~11 ~-123 minecraft:gray_stained_glass
fill ~-6 ~10 ~-113 ~-6 ~11 ~-113 minecraft:light_gray_stained_glass
fill ~-23 ~10 ~-121 ~-23 ~11 ~-121 minecraft:gray_stained_glass
fill ~-4 ~10 ~-121 ~-4 ~11 ~-121 minecraft:light_gray_stained_glass
fill ~-23 ~10 ~-118 ~-23 ~11 ~-118 minecraft:gray_stained_glass
fill ~-4 ~10 ~-118 ~-4 ~11 ~-118 minecraft:light_gray_stained_glass
fill ~-23 ~10 ~-115 ~-23 ~11 ~-115 minecraft:gray_stained_glass
fill ~-4 ~10 ~-115 ~-4 ~11 ~-115 minecraft:light_gray_stained_glass
setblock ~-23 ~1 ~-118 minecraft:iron_door[half=lower,facing=west]
setblock ~-23 ~2 ~-118 minecraft:iron_door[half=upper,facing=west]
fill ~-23 ~7 ~-123 ~-4 ~12 ~-113 minecraft:air
fill ~-22 ~7 ~-122 ~-5 ~12 ~-114 minecraft:bricks
fill ~-21 ~8 ~-121 ~-6 ~11 ~-115 minecraft:air
fill ~-22 ~13 ~-122 ~-5 ~13 ~-114 minecraft:deepslate_tile_slab
fill ~-23 ~2 ~-121 ~-23 ~7 ~-115 minecraft:blue_stained_glass
fill ~-21 ~14 ~-121 ~-19 ~15 ~-119 minecraft:light_gray_concrete
setblock ~-18 ~14 ~-120 minecraft:lightning_rod
# 088 waterfront_hotel style=civic_modern context=waterfront_front facing=south
fill ~89 ~-3 ~-62 ~94 ~-1 ~-53 minecraft:stone
fill ~89 ~0 ~-62 ~94 ~5 ~-53 minecraft:white_terracotta
fill ~90 ~1 ~-61 ~93 ~4 ~-54 minecraft:air
fill ~90 ~4 ~-61 ~93 ~4 ~-54 minecraft:smooth_stone
fill ~91 ~2 ~-62 ~91 ~3 ~-62 minecraft:gray_stained_glass
fill ~91 ~2 ~-53 ~91 ~3 ~-53 minecraft:light_gray_stained_glass
fill ~89 ~2 ~-60 ~89 ~3 ~-60 minecraft:gray_stained_glass
fill ~94 ~2 ~-60 ~94 ~3 ~-60 minecraft:light_gray_stained_glass
fill ~89 ~2 ~-57 ~89 ~3 ~-57 minecraft:gray_stained_glass
fill ~94 ~2 ~-57 ~94 ~3 ~-57 minecraft:light_gray_stained_glass
setblock ~91 ~1 ~-53 minecraft:iron_door[half=lower,facing=south]
setblock ~91 ~2 ~-53 minecraft:iron_door[half=upper,facing=south]
