# Buildings 137..144
# 137 utility style=sawtooth context=local_front facing=south
fill ~-26 ~-3 ~-125 ~-9 ~-1 ~-114 minecraft:stone
fill ~-26 ~0 ~-125 ~-9 ~7 ~-114 minecraft:bricks
fill ~-25 ~1 ~-124 ~-10 ~6 ~-115 minecraft:air
fill ~-25 ~4 ~-124 ~-10 ~4 ~-115 minecraft:smooth_stone
fill ~-24 ~2 ~-125 ~-24 ~3 ~-125 minecraft:gray_stained_glass
fill ~-24 ~2 ~-114 ~-24 ~3 ~-114 minecraft:light_gray_stained_glass
fill ~-21 ~2 ~-125 ~-21 ~3 ~-125 minecraft:gray_stained_glass
fill ~-21 ~2 ~-114 ~-21 ~3 ~-114 minecraft:light_gray_stained_glass
fill ~-18 ~2 ~-125 ~-18 ~3 ~-125 minecraft:gray_stained_glass
fill ~-18 ~2 ~-114 ~-18 ~3 ~-114 minecraft:light_gray_stained_glass
fill ~-15 ~2 ~-125 ~-15 ~3 ~-125 minecraft:gray_stained_glass
fill ~-15 ~2 ~-114 ~-15 ~3 ~-114 minecraft:light_gray_stained_glass
fill ~-12 ~2 ~-125 ~-12 ~3 ~-125 minecraft:gray_stained_glass
fill ~-12 ~2 ~-114 ~-12 ~3 ~-114 minecraft:light_gray_stained_glass
fill ~-26 ~2 ~-123 ~-26 ~3 ~-123 minecraft:gray_stained_glass
fill ~-9 ~2 ~-123 ~-9 ~3 ~-123 minecraft:light_gray_stained_glass
fill ~-26 ~2 ~-120 ~-26 ~3 ~-120 minecraft:gray_stained_glass
fill ~-9 ~2 ~-120 ~-9 ~3 ~-120 minecraft:light_gray_stained_glass
fill ~-26 ~2 ~-117 ~-26 ~3 ~-117 minecraft:gray_stained_glass
fill ~-9 ~2 ~-117 ~-9 ~3 ~-117 minecraft:light_gray_stained_glass
setblock ~-21 ~1 ~-114 minecraft:iron_door[half=lower,facing=south]
setblock ~-21 ~2 ~-114 minecraft:iron_door[half=upper,facing=south]
fill ~-24 ~1 ~-114 ~-11 ~4 ~-114 minecraft:polished_blackstone
fill ~-24 ~5 ~-114 ~-11 ~5 ~-114 minecraft:light_blue_stained_glass
fill ~-24 ~9 ~-123 ~-22 ~10 ~-121 minecraft:iron_block
fill ~-26 ~8 ~-125 ~-9 ~8 ~-114 minecraft:deepslate_tile_slab
fill ~-25 ~1 ~-114 ~-25 ~7 ~-114 minecraft:gray_concrete
fill ~-21 ~1 ~-114 ~-21 ~7 ~-114 minecraft:gray_concrete
fill ~-17 ~1 ~-114 ~-17 ~7 ~-114 minecraft:gray_concrete
fill ~-13 ~1 ~-114 ~-13 ~7 ~-114 minecraft:gray_concrete
# 138 clinic style=balcony_block context=collector_front facing=east
fill ~84 ~-3 ~32 ~92 ~-1 ~38 minecraft:stone
fill ~84 ~0 ~32 ~92 ~7 ~38 minecraft:bricks
fill ~85 ~1 ~33 ~91 ~6 ~37 minecraft:air
fill ~85 ~4 ~33 ~91 ~4 ~37 minecraft:smooth_stone
fill ~86 ~2 ~32 ~86 ~3 ~32 minecraft:gray_stained_glass
fill ~86 ~2 ~38 ~86 ~3 ~38 minecraft:light_gray_stained_glass
fill ~89 ~2 ~32 ~89 ~3 ~32 minecraft:gray_stained_glass
fill ~89 ~2 ~38 ~89 ~3 ~38 minecraft:light_gray_stained_glass
fill ~84 ~2 ~34 ~84 ~3 ~34 minecraft:gray_stained_glass
fill ~92 ~2 ~34 ~92 ~3 ~34 minecraft:light_gray_stained_glass
setblock ~92 ~1 ~35 minecraft:iron_door[half=lower,facing=east]
setblock ~92 ~2 ~35 minecraft:iron_door[half=upper,facing=east]
fill ~93 ~4 ~34 ~93 ~4 ~36 minecraft:smooth_stone_slab
fill ~84 ~8 ~32 ~92 ~8 ~38 minecraft:deepslate_tile_slab
fill ~92 ~1 ~33 ~92 ~7 ~33 minecraft:weathered_cut_copper
fill ~92 ~1 ~37 ~92 ~7 ~37 minecraft:weathered_cut_copper
# 139 clinic style=mixed_facade context=collector_front facing=east
fill ~-85 ~-3 ~31 ~-78 ~-1 ~39 minecraft:stone
fill ~-85 ~0 ~31 ~-78 ~10 ~39 minecraft:smooth_sandstone
fill ~-84 ~1 ~32 ~-79 ~9 ~38 minecraft:air
fill ~-84 ~4 ~32 ~-79 ~4 ~38 minecraft:smooth_stone
fill ~-84 ~8 ~32 ~-79 ~8 ~38 minecraft:smooth_stone
fill ~-83 ~2 ~31 ~-83 ~3 ~31 minecraft:gray_stained_glass
fill ~-83 ~2 ~39 ~-83 ~3 ~39 minecraft:light_gray_stained_glass
fill ~-80 ~2 ~31 ~-80 ~3 ~31 minecraft:gray_stained_glass
fill ~-80 ~2 ~39 ~-80 ~3 ~39 minecraft:light_gray_stained_glass
fill ~-85 ~2 ~33 ~-85 ~3 ~33 minecraft:gray_stained_glass
fill ~-78 ~2 ~33 ~-78 ~3 ~33 minecraft:light_gray_stained_glass
fill ~-85 ~2 ~36 ~-85 ~3 ~36 minecraft:gray_stained_glass
fill ~-78 ~2 ~36 ~-78 ~3 ~36 minecraft:light_gray_stained_glass
fill ~-83 ~6 ~31 ~-83 ~7 ~31 minecraft:gray_stained_glass
fill ~-83 ~6 ~39 ~-83 ~7 ~39 minecraft:light_gray_stained_glass
fill ~-80 ~6 ~31 ~-80 ~7 ~31 minecraft:gray_stained_glass
fill ~-80 ~6 ~39 ~-80 ~7 ~39 minecraft:light_gray_stained_glass
fill ~-85 ~6 ~33 ~-85 ~7 ~33 minecraft:gray_stained_glass
fill ~-78 ~6 ~33 ~-78 ~7 ~33 minecraft:light_gray_stained_glass
fill ~-85 ~6 ~36 ~-85 ~7 ~36 minecraft:gray_stained_glass
fill ~-78 ~6 ~36 ~-78 ~7 ~36 minecraft:light_gray_stained_glass
setblock ~-78 ~1 ~35 minecraft:iron_door[half=lower,facing=east]
setblock ~-78 ~2 ~35 minecraft:iron_door[half=upper,facing=east]
fill ~-85 ~11 ~31 ~-78 ~11 ~39 minecraft:stone_brick_slab
fill ~-78 ~1 ~32 ~-78 ~7 ~32 minecraft:brown_terracotta
fill ~-78 ~1 ~36 ~-78 ~7 ~36 minecraft:brown_terracotta
# 140 supermarket style=storefront context=collector_front facing=south
fill ~81 ~-3 ~-82 ~86 ~-1 ~-76 minecraft:stone
fill ~81 ~0 ~-82 ~86 ~7 ~-76 minecraft:white_terracotta
fill ~82 ~1 ~-81 ~85 ~6 ~-77 minecraft:air
fill ~82 ~4 ~-81 ~85 ~4 ~-77 minecraft:smooth_stone
fill ~83 ~2 ~-82 ~83 ~3 ~-82 minecraft:gray_stained_glass
fill ~83 ~2 ~-76 ~83 ~3 ~-76 minecraft:light_gray_stained_glass
fill ~81 ~2 ~-80 ~81 ~3 ~-80 minecraft:gray_stained_glass
fill ~86 ~2 ~-80 ~86 ~3 ~-80 minecraft:light_gray_stained_glass
setblock ~83 ~1 ~-76 minecraft:iron_door[half=lower,facing=south]
setblock ~83 ~2 ~-76 minecraft:iron_door[half=upper,facing=south]
fill ~82 ~1 ~-76 ~85 ~3 ~-76 minecraft:cyan_stained_glass
setblock ~83 ~1 ~-76 minecraft:iron_door[half=lower,facing=south]
setblock ~83 ~2 ~-76 minecraft:iron_door[half=upper,facing=south]
setblock ~83 ~3 ~-75 minecraft:red_wool
fill ~81 ~8 ~-82 ~86 ~8 ~-76 minecraft:dark_oak_slab
fill ~82 ~1 ~-76 ~82 ~7 ~-76 minecraft:dark_oak_planks
# 141 midrise_housing style=balcony_block context=collector_front facing=east
fill ~50 ~-3 ~-64 ~57 ~-1 ~-53 minecraft:stone
fill ~50 ~0 ~-64 ~57 ~10 ~-53 minecraft:smooth_sandstone
fill ~51 ~1 ~-63 ~56 ~9 ~-54 minecraft:air
fill ~51 ~4 ~-63 ~56 ~4 ~-54 minecraft:smooth_stone
fill ~51 ~8 ~-63 ~56 ~8 ~-54 minecraft:smooth_stone
fill ~52 ~2 ~-64 ~52 ~3 ~-64 minecraft:gray_stained_glass
fill ~52 ~2 ~-53 ~52 ~3 ~-53 minecraft:light_gray_stained_glass
fill ~55 ~2 ~-64 ~55 ~3 ~-64 minecraft:gray_stained_glass
fill ~55 ~2 ~-53 ~55 ~3 ~-53 minecraft:light_gray_stained_glass
fill ~50 ~2 ~-62 ~50 ~3 ~-62 minecraft:gray_stained_glass
fill ~57 ~2 ~-62 ~57 ~3 ~-62 minecraft:light_gray_stained_glass
fill ~50 ~2 ~-59 ~50 ~3 ~-59 minecraft:gray_stained_glass
fill ~57 ~2 ~-59 ~57 ~3 ~-59 minecraft:light_gray_stained_glass
fill ~50 ~2 ~-56 ~50 ~3 ~-56 minecraft:gray_stained_glass
fill ~57 ~2 ~-56 ~57 ~3 ~-56 minecraft:light_gray_stained_glass
fill ~52 ~6 ~-64 ~52 ~7 ~-64 minecraft:gray_stained_glass
fill ~52 ~6 ~-53 ~52 ~7 ~-53 minecraft:light_gray_stained_glass
fill ~55 ~6 ~-64 ~55 ~7 ~-64 minecraft:gray_stained_glass
fill ~55 ~6 ~-53 ~55 ~7 ~-53 minecraft:light_gray_stained_glass
fill ~50 ~6 ~-62 ~50 ~7 ~-62 minecraft:gray_stained_glass
fill ~57 ~6 ~-62 ~57 ~7 ~-62 minecraft:light_gray_stained_glass
fill ~50 ~6 ~-59 ~50 ~7 ~-59 minecraft:gray_stained_glass
fill ~57 ~6 ~-59 ~57 ~7 ~-59 minecraft:light_gray_stained_glass
fill ~50 ~6 ~-56 ~50 ~7 ~-56 minecraft:gray_stained_glass
fill ~57 ~6 ~-56 ~57 ~7 ~-56 minecraft:light_gray_stained_glass
setblock ~57 ~1 ~-59 minecraft:iron_door[half=lower,facing=east]
setblock ~57 ~2 ~-59 minecraft:iron_door[half=upper,facing=east]
fill ~58 ~4 ~-62 ~58 ~4 ~-55 minecraft:smooth_stone_slab
fill ~58 ~8 ~-62 ~58 ~8 ~-55 minecraft:smooth_stone_slab
fill ~50 ~11 ~-64 ~57 ~11 ~-53 minecraft:stone_brick_slab
fill ~52 ~12 ~-62 ~54 ~13 ~-60 minecraft:light_gray_concrete
setblock ~55 ~12 ~-61 minecraft:lightning_rod
fill ~57 ~1 ~-63 ~57 ~7 ~-63 minecraft:brown_terracotta
fill ~57 ~1 ~-59 ~57 ~7 ~-59 minecraft:brown_terracotta
fill ~57 ~1 ~-55 ~57 ~7 ~-55 minecraft:brown_terracotta
# 142 workshop style=loading_bay context=local_front facing=west
fill ~67 ~-3 ~28 ~75 ~-1 ~40 minecraft:stone
fill ~67 ~0 ~28 ~75 ~16 ~40 minecraft:bricks
fill ~68 ~1 ~29 ~74 ~15 ~39 minecraft:air
fill ~68 ~4 ~29 ~74 ~4 ~39 minecraft:smooth_stone
fill ~68 ~8 ~29 ~74 ~8 ~39 minecraft:smooth_stone
fill ~68 ~12 ~29 ~74 ~12 ~39 minecraft:smooth_stone
fill ~69 ~2 ~28 ~69 ~3 ~28 minecraft:gray_stained_glass
fill ~69 ~2 ~40 ~69 ~3 ~40 minecraft:light_gray_stained_glass
fill ~72 ~2 ~28 ~72 ~3 ~28 minecraft:gray_stained_glass
fill ~72 ~2 ~40 ~72 ~3 ~40 minecraft:light_gray_stained_glass
fill ~67 ~2 ~30 ~67 ~3 ~30 minecraft:gray_stained_glass
fill ~75 ~2 ~30 ~75 ~3 ~30 minecraft:light_gray_stained_glass
fill ~67 ~2 ~33 ~67 ~3 ~33 minecraft:gray_stained_glass
fill ~75 ~2 ~33 ~75 ~3 ~33 minecraft:light_gray_stained_glass
fill ~67 ~2 ~36 ~67 ~3 ~36 minecraft:gray_stained_glass
fill ~75 ~2 ~36 ~75 ~3 ~36 minecraft:light_gray_stained_glass
fill ~69 ~6 ~28 ~69 ~7 ~28 minecraft:gray_stained_glass
fill ~69 ~6 ~40 ~69 ~7 ~40 minecraft:light_gray_stained_glass
fill ~72 ~6 ~28 ~72 ~7 ~28 minecraft:gray_stained_glass
fill ~72 ~6 ~40 ~72 ~7 ~40 minecraft:light_gray_stained_glass
fill ~67 ~6 ~30 ~67 ~7 ~30 minecraft:gray_stained_glass
fill ~75 ~6 ~30 ~75 ~7 ~30 minecraft:light_gray_stained_glass
fill ~67 ~6 ~33 ~67 ~7 ~33 minecraft:gray_stained_glass
fill ~75 ~6 ~33 ~75 ~7 ~33 minecraft:light_gray_stained_glass
fill ~67 ~6 ~36 ~67 ~7 ~36 minecraft:gray_stained_glass
fill ~75 ~6 ~36 ~75 ~7 ~36 minecraft:light_gray_stained_glass
fill ~69 ~10 ~28 ~69 ~11 ~28 minecraft:gray_stained_glass
fill ~69 ~10 ~40 ~69 ~11 ~40 minecraft:light_gray_stained_glass
fill ~72 ~10 ~28 ~72 ~11 ~28 minecraft:gray_stained_glass
fill ~72 ~10 ~40 ~72 ~11 ~40 minecraft:light_gray_stained_glass
fill ~67 ~10 ~30 ~67 ~11 ~30 minecraft:gray_stained_glass
fill ~75 ~10 ~30 ~75 ~11 ~30 minecraft:light_gray_stained_glass
fill ~67 ~10 ~33 ~67 ~11 ~33 minecraft:gray_stained_glass
fill ~75 ~10 ~33 ~75 ~11 ~33 minecraft:light_gray_stained_glass
fill ~67 ~10 ~36 ~67 ~11 ~36 minecraft:gray_stained_glass
fill ~75 ~10 ~36 ~75 ~11 ~36 minecraft:light_gray_stained_glass
fill ~69 ~14 ~28 ~69 ~15 ~28 minecraft:gray_stained_glass
fill ~69 ~14 ~40 ~69 ~15 ~40 minecraft:light_gray_stained_glass
fill ~72 ~14 ~28 ~72 ~15 ~28 minecraft:gray_stained_glass
fill ~72 ~14 ~40 ~72 ~15 ~40 minecraft:light_gray_stained_glass
fill ~67 ~14 ~30 ~67 ~15 ~30 minecraft:gray_stained_glass
fill ~75 ~14 ~30 ~75 ~15 ~30 minecraft:light_gray_stained_glass
fill ~67 ~14 ~33 ~67 ~15 ~33 minecraft:gray_stained_glass
fill ~75 ~14 ~33 ~75 ~15 ~33 minecraft:light_gray_stained_glass
fill ~67 ~14 ~36 ~67 ~15 ~36 minecraft:gray_stained_glass
fill ~75 ~14 ~36 ~75 ~15 ~36 minecraft:light_gray_stained_glass
setblock ~67 ~1 ~33 minecraft:iron_door[half=lower,facing=west]
setblock ~67 ~2 ~33 minecraft:iron_door[half=upper,facing=west]
fill ~67 ~1 ~30 ~67 ~4 ~38 minecraft:polished_blackstone
fill ~67 ~5 ~30 ~67 ~5 ~38 minecraft:light_blue_stained_glass
fill ~69 ~18 ~30 ~71 ~19 ~32 minecraft:iron_block
fill ~67 ~17 ~28 ~75 ~17 ~40 minecraft:deepslate_tile_slab
fill ~67 ~1 ~29 ~67 ~7 ~29 doomsday_decoration:hollowbrick
fill ~67 ~1 ~33 ~67 ~7 ~33 doomsday_decoration:hollowbrick
fill ~67 ~1 ~37 ~67 ~7 ~37 doomsday_decoration:hollowbrick
# 143 detached_house style=rowhouse context=local_front facing=north
fill ~98 ~-3 ~116 ~103 ~-1 ~124 minecraft:stone
fill ~98 ~0 ~116 ~103 ~7 ~124 minecraft:white_concrete
fill ~99 ~1 ~117 ~102 ~6 ~123 minecraft:air
fill ~99 ~4 ~117 ~102 ~4 ~123 minecraft:smooth_stone
fill ~100 ~2 ~116 ~100 ~3 ~116 minecraft:gray_stained_glass
fill ~100 ~2 ~124 ~100 ~3 ~124 minecraft:light_gray_stained_glass
fill ~98 ~2 ~118 ~98 ~3 ~118 minecraft:gray_stained_glass
fill ~103 ~2 ~118 ~103 ~3 ~118 minecraft:light_gray_stained_glass
fill ~98 ~2 ~121 ~98 ~3 ~121 minecraft:gray_stained_glass
fill ~103 ~2 ~121 ~103 ~3 ~121 minecraft:light_gray_stained_glass
setblock ~100 ~1 ~116 minecraft:iron_door[half=lower,facing=north]
setblock ~100 ~2 ~116 minecraft:iron_door[half=upper,facing=north]
fill ~98 ~8 ~116 ~103 ~8 ~124 minecraft:smooth_stone_slab
fill ~99 ~9 ~117 ~102 ~9 ~123 minecraft:smooth_stone_slab
setblock ~100 ~3 ~115 minecraft:dark_oak_slab[type=top]
fill ~99 ~1 ~116 ~99 ~7 ~116 minecraft:cyan_terracotta
# 144 detached_house style=stepped_house context=local_front facing=west
fill ~-62 ~-3 ~78 ~-56 ~-1 ~82 minecraft:stone
fill ~-62 ~0 ~78 ~-56 ~7 ~82 minecraft:calcite
fill ~-61 ~1 ~79 ~-57 ~6 ~81 minecraft:air
fill ~-61 ~4 ~79 ~-57 ~4 ~81 minecraft:smooth_stone
fill ~-60 ~2 ~78 ~-60 ~3 ~78 minecraft:gray_stained_glass
fill ~-60 ~2 ~82 ~-60 ~3 ~82 minecraft:light_gray_stained_glass
fill ~-62 ~2 ~80 ~-62 ~3 ~80 minecraft:gray_stained_glass
fill ~-56 ~2 ~80 ~-56 ~3 ~80 minecraft:light_gray_stained_glass
setblock ~-62 ~1 ~80 minecraft:iron_door[half=lower,facing=west]
setblock ~-62 ~2 ~80 minecraft:iron_door[half=upper,facing=west]
fill ~-62 ~8 ~78 ~-56 ~8 ~82 minecraft:stone_brick_slab
fill ~-61 ~9 ~79 ~-57 ~9 ~81 minecraft:stone_brick_slab
setblock ~-63 ~3 ~80 minecraft:dark_oak_slab[type=top]
