# Buildings 193..200
# 193 local_shop style=corner_store context=collector_front facing=west
fill ~-92 ~-3 ~-49 ~-86 ~-1 ~-45 minecraft:stone
fill ~-92 ~0 ~-49 ~-86 ~7 ~-45 minecraft:bricks
fill ~-91 ~1 ~-48 ~-87 ~6 ~-46 minecraft:air
fill ~-91 ~4 ~-48 ~-87 ~4 ~-46 minecraft:smooth_stone
fill ~-90 ~2 ~-49 ~-90 ~3 ~-49 minecraft:gray_stained_glass
fill ~-90 ~2 ~-45 ~-90 ~3 ~-45 minecraft:light_gray_stained_glass
fill ~-92 ~2 ~-47 ~-92 ~3 ~-47 minecraft:gray_stained_glass
fill ~-86 ~2 ~-47 ~-86 ~3 ~-47 minecraft:light_gray_stained_glass
setblock ~-92 ~1 ~-47 minecraft:iron_door[half=lower,facing=west]
setblock ~-92 ~2 ~-47 minecraft:iron_door[half=upper,facing=west]
fill ~-92 ~1 ~-48 ~-92 ~3 ~-46 minecraft:cyan_stained_glass
setblock ~-92 ~1 ~-47 minecraft:iron_door[half=lower,facing=west]
setblock ~-92 ~2 ~-47 minecraft:iron_door[half=upper,facing=west]
setblock ~-93 ~3 ~-47 minecraft:red_wool
fill ~-92 ~8 ~-49 ~-86 ~8 ~-45 minecraft:deepslate_tile_slab
# 194 local_shop style=arcade_shop context=arterial_front facing=south
fill ~-108 ~-3 ~-16 ~-104 ~-1 ~-10 minecraft:stone
fill ~-108 ~0 ~-16 ~-104 ~9 ~-10 minecraft:white_terracotta
fill ~-107 ~1 ~-15 ~-105 ~8 ~-11 minecraft:air
fill ~-107 ~4 ~-15 ~-105 ~4 ~-11 minecraft:smooth_stone
fill ~-107 ~8 ~-15 ~-105 ~8 ~-11 minecraft:smooth_stone
fill ~-106 ~2 ~-16 ~-106 ~3 ~-16 minecraft:gray_stained_glass
fill ~-106 ~2 ~-10 ~-106 ~3 ~-10 minecraft:light_gray_stained_glass
fill ~-108 ~2 ~-14 ~-108 ~3 ~-14 minecraft:gray_stained_glass
fill ~-104 ~2 ~-14 ~-104 ~3 ~-14 minecraft:light_gray_stained_glass
fill ~-106 ~6 ~-16 ~-106 ~7 ~-16 minecraft:gray_stained_glass
fill ~-106 ~6 ~-10 ~-106 ~7 ~-10 minecraft:light_gray_stained_glass
fill ~-108 ~6 ~-14 ~-108 ~7 ~-14 minecraft:gray_stained_glass
fill ~-104 ~6 ~-14 ~-104 ~7 ~-14 minecraft:light_gray_stained_glass
setblock ~-106 ~1 ~-10 minecraft:iron_door[half=lower,facing=south]
setblock ~-106 ~2 ~-10 minecraft:iron_door[half=upper,facing=south]
fill ~-107 ~1 ~-10 ~-105 ~3 ~-10 minecraft:cyan_stained_glass
setblock ~-106 ~1 ~-10 minecraft:iron_door[half=lower,facing=south]
setblock ~-106 ~2 ~-10 minecraft:iron_door[half=upper,facing=south]
setblock ~-106 ~3 ~-9 minecraft:red_wool
fill ~-107 ~4 ~-10 ~-105 ~4 ~-10 minecraft:dark_oak_planks
fill ~-108 ~10 ~-16 ~-104 ~10 ~-10 minecraft:dark_oak_slab
# 195 small_office style=bay_office context=local_front facing=north
fill ~-59 ~-3 ~-104 ~-56 ~-1 ~-99 minecraft:stone
fill ~-59 ~0 ~-104 ~-56 ~9 ~-99 minecraft:stone_bricks
fill ~-58 ~1 ~-103 ~-57 ~8 ~-100 minecraft:air
fill ~-58 ~4 ~-103 ~-57 ~4 ~-100 minecraft:smooth_stone
fill ~-58 ~8 ~-103 ~-57 ~8 ~-100 minecraft:smooth_stone
fill ~-59 ~2 ~-102 ~-59 ~3 ~-102 minecraft:gray_stained_glass
fill ~-56 ~2 ~-102 ~-56 ~3 ~-102 minecraft:light_gray_stained_glass
fill ~-59 ~6 ~-102 ~-59 ~7 ~-102 minecraft:gray_stained_glass
fill ~-56 ~6 ~-102 ~-56 ~7 ~-102 minecraft:light_gray_stained_glass
setblock ~-57 ~1 ~-104 minecraft:iron_door[half=lower,facing=north]
setblock ~-57 ~2 ~-104 minecraft:iron_door[half=upper,facing=north]
fill ~-57 ~11 ~-102 ~-57 ~12 ~-100 minecraft:light_gray_concrete
setblock ~-57 ~11 ~-101 minecraft:lightning_rod
# 196 shop_house style=arcade_shop context=local_front facing=south
fill ~-6 ~-3 ~15 ~-1 ~-1 ~22 minecraft:stone
fill ~-6 ~0 ~15 ~-1 ~11 ~22 minecraft:bricks
fill ~-5 ~1 ~16 ~-2 ~10 ~21 minecraft:air
fill ~-5 ~4 ~16 ~-2 ~4 ~21 minecraft:smooth_stone
fill ~-5 ~8 ~16 ~-2 ~8 ~21 minecraft:smooth_stone
fill ~-4 ~2 ~15 ~-4 ~3 ~15 minecraft:gray_stained_glass
fill ~-4 ~2 ~22 ~-4 ~3 ~22 minecraft:light_gray_stained_glass
fill ~-6 ~2 ~17 ~-6 ~3 ~17 minecraft:gray_stained_glass
fill ~-1 ~2 ~17 ~-1 ~3 ~17 minecraft:light_gray_stained_glass
fill ~-6 ~2 ~20 ~-6 ~3 ~20 minecraft:gray_stained_glass
fill ~-1 ~2 ~20 ~-1 ~3 ~20 minecraft:light_gray_stained_glass
fill ~-4 ~6 ~15 ~-4 ~7 ~15 minecraft:gray_stained_glass
fill ~-4 ~6 ~22 ~-4 ~7 ~22 minecraft:light_gray_stained_glass
fill ~-6 ~6 ~17 ~-6 ~7 ~17 minecraft:gray_stained_glass
fill ~-1 ~6 ~17 ~-1 ~7 ~17 minecraft:light_gray_stained_glass
fill ~-6 ~6 ~20 ~-6 ~7 ~20 minecraft:gray_stained_glass
fill ~-1 ~6 ~20 ~-1 ~7 ~20 minecraft:light_gray_stained_glass
setblock ~-4 ~1 ~22 minecraft:iron_door[half=lower,facing=south]
setblock ~-4 ~2 ~22 minecraft:iron_door[half=upper,facing=south]
fill ~-5 ~1 ~22 ~-2 ~3 ~22 minecraft:cyan_stained_glass
setblock ~-4 ~1 ~22 minecraft:iron_door[half=lower,facing=south]
setblock ~-4 ~2 ~22 minecraft:iron_door[half=upper,facing=south]
setblock ~-4 ~3 ~23 minecraft:red_wool
fill ~-5 ~4 ~22 ~-2 ~4 ~22 doomsday_decoration:redbrick
fill ~-6 ~12 ~15 ~-1 ~12 ~22 minecraft:deepslate_tile_slab
fill ~-5 ~1 ~22 ~-5 ~7 ~22 doomsday_decoration:redbrick
setblock ~-4 ~3 ~22 minecraft:red_carpet
# 197 small_office style=bay_office context=local_front facing=north
fill ~29 ~-3 ~23 ~32 ~-1 ~28 minecraft:stone
fill ~29 ~0 ~23 ~32 ~7 ~28 minecraft:bricks
fill ~30 ~1 ~24 ~31 ~6 ~27 minecraft:air
fill ~30 ~4 ~24 ~31 ~4 ~27 minecraft:smooth_stone
fill ~29 ~2 ~25 ~29 ~3 ~25 minecraft:gray_stained_glass
fill ~32 ~2 ~25 ~32 ~3 ~25 minecraft:light_gray_stained_glass
setblock ~31 ~1 ~23 minecraft:iron_door[half=lower,facing=north]
setblock ~31 ~2 ~23 minecraft:iron_door[half=upper,facing=north]
# 198 small_office style=setback_tower context=collector_front facing=east
fill ~23 ~-3 ~-51 ~28 ~-1 ~-48 minecraft:stone
fill ~23 ~0 ~-51 ~28 ~7 ~-48 minecraft:smooth_sandstone
fill ~24 ~1 ~-50 ~27 ~6 ~-49 minecraft:air
fill ~24 ~4 ~-50 ~27 ~4 ~-49 minecraft:smooth_stone
fill ~25 ~2 ~-51 ~25 ~3 ~-51 minecraft:gray_stained_glass
fill ~25 ~2 ~-48 ~25 ~3 ~-48 minecraft:light_gray_stained_glass
setblock ~28 ~1 ~-49 minecraft:iron_door[half=lower,facing=east]
setblock ~28 ~2 ~-49 minecraft:iron_door[half=upper,facing=east]
# 199 shop_house style=corner_store context=local_front facing=north
fill ~41 ~-3 ~23 ~45 ~-1 ~29 minecraft:stone
fill ~41 ~0 ~23 ~45 ~7 ~29 minecraft:smooth_sandstone
fill ~42 ~1 ~24 ~44 ~6 ~28 minecraft:air
fill ~42 ~4 ~24 ~44 ~4 ~28 minecraft:smooth_stone
fill ~43 ~2 ~23 ~43 ~3 ~23 minecraft:gray_stained_glass
fill ~43 ~2 ~29 ~43 ~3 ~29 minecraft:light_gray_stained_glass
fill ~41 ~2 ~25 ~41 ~3 ~25 minecraft:gray_stained_glass
fill ~45 ~2 ~25 ~45 ~3 ~25 minecraft:light_gray_stained_glass
setblock ~43 ~1 ~23 minecraft:iron_door[half=lower,facing=north]
setblock ~43 ~2 ~23 minecraft:iron_door[half=upper,facing=north]
fill ~42 ~1 ~23 ~44 ~3 ~23 minecraft:cyan_stained_glass
setblock ~43 ~1 ~23 minecraft:iron_door[half=lower,facing=north]
setblock ~43 ~2 ~23 minecraft:iron_door[half=upper,facing=north]
setblock ~43 ~3 ~22 minecraft:red_wool
fill ~41 ~8 ~23 ~45 ~8 ~29 minecraft:stone_brick_slab
# 200 row_house style=stepped_house context=local_front facing=south
fill ~-77 ~-3 ~-123 ~-74 ~-1 ~-118 minecraft:stone
fill ~-77 ~0 ~-123 ~-74 ~11 ~-118 minecraft:stone_bricks
fill ~-76 ~1 ~-122 ~-75 ~10 ~-119 minecraft:air
fill ~-76 ~4 ~-122 ~-75 ~4 ~-119 minecraft:smooth_stone
fill ~-76 ~8 ~-122 ~-75 ~8 ~-119 minecraft:smooth_stone
fill ~-77 ~2 ~-121 ~-77 ~3 ~-121 minecraft:gray_stained_glass
fill ~-74 ~2 ~-121 ~-74 ~3 ~-121 minecraft:light_gray_stained_glass
fill ~-77 ~6 ~-121 ~-77 ~7 ~-121 minecraft:gray_stained_glass
fill ~-74 ~6 ~-121 ~-74 ~7 ~-121 minecraft:light_gray_stained_glass
setblock ~-75 ~1 ~-118 minecraft:iron_door[half=lower,facing=south]
setblock ~-75 ~2 ~-118 minecraft:iron_door[half=upper,facing=south]
fill ~-77 ~12 ~-123 ~-74 ~12 ~-118 minecraft:smooth_stone_slab
fill ~-76 ~13 ~-122 ~-75 ~13 ~-119 minecraft:smooth_stone_slab
setblock ~-75 ~3 ~-117 minecraft:dark_oak_slab[type=top]
