# Buildings 241..248
# 241 row_house style=stepped_house context=arterial_front facing=south
fill ~-88 ~-3 ~-49 ~-85 ~-1 ~-43 minecraft:stone
fill ~-88 ~0 ~-49 ~-85 ~7 ~-43 minecraft:light_gray_concrete
fill ~-87 ~1 ~-48 ~-86 ~6 ~-44 minecraft:air
fill ~-87 ~4 ~-48 ~-86 ~4 ~-44 minecraft:smooth_stone
fill ~-88 ~2 ~-47 ~-88 ~3 ~-47 minecraft:gray_stained_glass
fill ~-85 ~2 ~-47 ~-85 ~3 ~-47 minecraft:light_gray_stained_glass
setblock ~-86 ~1 ~-43 minecraft:iron_door[half=lower,facing=south]
setblock ~-86 ~2 ~-43 minecraft:iron_door[half=upper,facing=south]
fill ~-88 ~8 ~-49 ~-85 ~8 ~-43 minecraft:smooth_stone_slab
fill ~-87 ~9 ~-48 ~-86 ~9 ~-44 minecraft:smooth_stone_slab
setblock ~-86 ~3 ~-42 minecraft:dark_oak_slab[type=top]
# 242 small_office style=rowhouse context=local_front facing=east
fill ~-81 ~-3 ~-113 ~-78 ~-1 ~-108 minecraft:stone
fill ~-81 ~0 ~-113 ~-78 ~7 ~-108 minecraft:stone_bricks
fill ~-80 ~1 ~-112 ~-79 ~6 ~-109 minecraft:air
fill ~-80 ~4 ~-112 ~-79 ~4 ~-109 minecraft:smooth_stone
fill ~-81 ~2 ~-111 ~-81 ~3 ~-111 minecraft:gray_stained_glass
fill ~-78 ~2 ~-111 ~-78 ~3 ~-111 minecraft:light_gray_stained_glass
setblock ~-78 ~1 ~-111 minecraft:iron_door[half=lower,facing=east]
setblock ~-78 ~2 ~-111 minecraft:iron_door[half=upper,facing=east]
fill ~-81 ~8 ~-113 ~-78 ~8 ~-108 minecraft:smooth_stone_slab
fill ~-80 ~9 ~-112 ~-79 ~9 ~-109 minecraft:smooth_stone_slab
setblock ~-77 ~3 ~-111 minecraft:dark_oak_slab[type=top]
# 243 local_shop style=stepped_house context=waterfront_front facing=south
fill ~93 ~-3 ~-126 ~97 ~-1 ~-121 minecraft:stone
fill ~93 ~0 ~-126 ~97 ~9 ~-121 minecraft:bricks
fill ~94 ~1 ~-125 ~96 ~8 ~-122 minecraft:air
fill ~94 ~4 ~-125 ~96 ~4 ~-122 minecraft:smooth_stone
fill ~94 ~8 ~-125 ~96 ~8 ~-122 minecraft:smooth_stone
fill ~95 ~2 ~-126 ~95 ~3 ~-126 minecraft:gray_stained_glass
fill ~95 ~2 ~-121 ~95 ~3 ~-121 minecraft:light_gray_stained_glass
fill ~93 ~2 ~-124 ~93 ~3 ~-124 minecraft:gray_stained_glass
fill ~97 ~2 ~-124 ~97 ~3 ~-124 minecraft:light_gray_stained_glass
fill ~95 ~6 ~-126 ~95 ~7 ~-126 minecraft:gray_stained_glass
fill ~95 ~6 ~-121 ~95 ~7 ~-121 minecraft:light_gray_stained_glass
fill ~93 ~6 ~-124 ~93 ~7 ~-124 minecraft:gray_stained_glass
fill ~97 ~6 ~-124 ~97 ~7 ~-124 minecraft:light_gray_stained_glass
setblock ~95 ~1 ~-121 minecraft:iron_door[half=lower,facing=south]
setblock ~95 ~2 ~-121 minecraft:iron_door[half=upper,facing=south]
fill ~93 ~10 ~-126 ~97 ~10 ~-121 minecraft:deepslate_tile_slab
fill ~94 ~11 ~-125 ~96 ~11 ~-122 minecraft:deepslate_tile_slab
setblock ~95 ~3 ~-120 minecraft:dark_oak_slab[type=top]
fill ~95 ~11 ~-124 ~96 ~12 ~-122 minecraft:light_gray_concrete
setblock ~96 ~11 ~-123 minecraft:lightning_rod
# 244 row_house style=rowhouse context=back_block facing=south
fill ~79 ~-3 ~-47 ~82 ~-1 ~-42 minecraft:stone
fill ~79 ~0 ~-47 ~82 ~9 ~-42 minecraft:bricks
fill ~80 ~1 ~-46 ~81 ~8 ~-43 minecraft:air
fill ~80 ~4 ~-46 ~81 ~4 ~-43 minecraft:smooth_stone
fill ~80 ~8 ~-46 ~81 ~8 ~-43 minecraft:smooth_stone
fill ~79 ~2 ~-45 ~79 ~3 ~-45 minecraft:gray_stained_glass
fill ~82 ~2 ~-45 ~82 ~3 ~-45 minecraft:light_gray_stained_glass
fill ~79 ~6 ~-45 ~79 ~7 ~-45 minecraft:gray_stained_glass
fill ~82 ~6 ~-45 ~82 ~7 ~-45 minecraft:light_gray_stained_glass
setblock ~81 ~1 ~-42 minecraft:iron_door[half=lower,facing=south]
setblock ~81 ~2 ~-42 minecraft:iron_door[half=upper,facing=south]
fill ~79 ~10 ~-47 ~82 ~10 ~-42 minecraft:deepslate_tile_slab
fill ~80 ~11 ~-46 ~81 ~11 ~-43 minecraft:deepslate_tile_slab
setblock ~81 ~3 ~-41 minecraft:dark_oak_slab[type=top]
# 245 workshop style=stepped_house context=back_block facing=south
fill ~-24 ~-3 ~69 ~-21 ~-1 ~74 minecraft:stone
fill ~-24 ~0 ~69 ~-21 ~5 ~74 minecraft:bricks
fill ~-23 ~1 ~70 ~-22 ~4 ~73 minecraft:air
fill ~-23 ~4 ~70 ~-22 ~4 ~73 minecraft:smooth_stone
fill ~-24 ~2 ~71 ~-24 ~3 ~71 minecraft:gray_stained_glass
fill ~-21 ~2 ~71 ~-21 ~3 ~71 minecraft:light_gray_stained_glass
setblock ~-22 ~1 ~74 minecraft:iron_door[half=lower,facing=south]
setblock ~-22 ~2 ~74 minecraft:iron_door[half=upper,facing=south]
fill ~-24 ~6 ~69 ~-21 ~6 ~74 minecraft:deepslate_tile_slab
fill ~-23 ~7 ~70 ~-22 ~7 ~73 minecraft:deepslate_tile_slab
setblock ~-22 ~3 ~75 minecraft:dark_oak_slab[type=top]
# 246 workshop style=stepped_house context=local_front facing=west
fill ~-44 ~-3 ~-44 ~-40 ~-1 ~-39 minecraft:stone
fill ~-44 ~0 ~-44 ~-40 ~7 ~-39 minecraft:bricks
fill ~-43 ~1 ~-43 ~-41 ~6 ~-40 minecraft:air
fill ~-43 ~4 ~-43 ~-41 ~4 ~-40 minecraft:smooth_stone
fill ~-42 ~2 ~-44 ~-42 ~3 ~-44 minecraft:gray_stained_glass
fill ~-42 ~2 ~-39 ~-42 ~3 ~-39 minecraft:light_gray_stained_glass
fill ~-44 ~2 ~-42 ~-44 ~3 ~-42 minecraft:gray_stained_glass
fill ~-40 ~2 ~-42 ~-40 ~3 ~-42 minecraft:light_gray_stained_glass
setblock ~-44 ~1 ~-42 minecraft:iron_door[half=lower,facing=west]
setblock ~-44 ~2 ~-42 minecraft:iron_door[half=upper,facing=west]
fill ~-44 ~8 ~-44 ~-40 ~8 ~-39 minecraft:deepslate_tile_slab
fill ~-43 ~9 ~-43 ~-41 ~9 ~-40 minecraft:deepslate_tile_slab
setblock ~-45 ~3 ~-42 minecraft:dark_oak_slab[type=top]
# 247 workshop style=storefront context=waterfront_front facing=north
fill ~100 ~-3 ~-44 ~103 ~-1 ~-38 minecraft:stone
fill ~100 ~0 ~-44 ~103 ~9 ~-38 minecraft:white_concrete
fill ~101 ~1 ~-43 ~102 ~8 ~-39 minecraft:air
fill ~101 ~4 ~-43 ~102 ~4 ~-39 minecraft:smooth_stone
fill ~101 ~8 ~-43 ~102 ~8 ~-39 minecraft:smooth_stone
fill ~100 ~2 ~-42 ~100 ~3 ~-42 minecraft:gray_stained_glass
fill ~103 ~2 ~-42 ~103 ~3 ~-42 minecraft:light_gray_stained_glass
fill ~100 ~6 ~-42 ~100 ~7 ~-42 minecraft:gray_stained_glass
fill ~103 ~6 ~-42 ~103 ~7 ~-42 minecraft:light_gray_stained_glass
setblock ~102 ~1 ~-44 minecraft:iron_door[half=lower,facing=north]
setblock ~102 ~2 ~-44 minecraft:iron_door[half=upper,facing=north]
fill ~101 ~1 ~-44 ~102 ~3 ~-44 minecraft:cyan_stained_glass
setblock ~102 ~1 ~-44 minecraft:iron_door[half=lower,facing=north]
setblock ~102 ~2 ~-44 minecraft:iron_door[half=upper,facing=north]
setblock ~102 ~3 ~-45 minecraft:red_wool
fill ~100 ~10 ~-44 ~103 ~10 ~-38 minecraft:smooth_stone_slab
# 248 local_shop style=rowhouse context=collector_front facing=north
fill ~47 ~-3 ~-67 ~50 ~-1 ~-62 minecraft:stone
fill ~47 ~0 ~-67 ~50 ~9 ~-62 minecraft:smooth_sandstone
fill ~48 ~1 ~-66 ~49 ~8 ~-63 minecraft:air
fill ~48 ~4 ~-66 ~49 ~4 ~-63 minecraft:smooth_stone
fill ~48 ~8 ~-66 ~49 ~8 ~-63 minecraft:smooth_stone
fill ~47 ~2 ~-65 ~47 ~3 ~-65 minecraft:gray_stained_glass
fill ~50 ~2 ~-65 ~50 ~3 ~-65 minecraft:light_gray_stained_glass
fill ~47 ~6 ~-65 ~47 ~7 ~-65 minecraft:gray_stained_glass
fill ~50 ~6 ~-65 ~50 ~7 ~-65 minecraft:light_gray_stained_glass
setblock ~49 ~1 ~-67 minecraft:iron_door[half=lower,facing=north]
setblock ~49 ~2 ~-67 minecraft:iron_door[half=upper,facing=north]
fill ~47 ~10 ~-67 ~50 ~10 ~-62 minecraft:stone_brick_slab
fill ~48 ~11 ~-66 ~49 ~11 ~-63 minecraft:stone_brick_slab
setblock ~49 ~3 ~-68 minecraft:dark_oak_slab[type=top]
