# Buildings 265..272
# 265 workshop style=industrial_shed context=local_front facing=west
fill ~67 ~-3 ~-46 ~72 ~-1 ~-43 minecraft:stone
fill ~67 ~0 ~-46 ~72 ~11 ~-43 minecraft:smooth_sandstone
fill ~68 ~1 ~-45 ~71 ~10 ~-44 minecraft:air
fill ~68 ~4 ~-45 ~71 ~4 ~-44 minecraft:smooth_stone
fill ~68 ~8 ~-45 ~71 ~8 ~-44 minecraft:smooth_stone
fill ~69 ~2 ~-46 ~69 ~3 ~-46 minecraft:gray_stained_glass
fill ~69 ~2 ~-43 ~69 ~3 ~-43 minecraft:light_gray_stained_glass
fill ~69 ~6 ~-46 ~69 ~7 ~-46 minecraft:gray_stained_glass
fill ~69 ~6 ~-43 ~69 ~7 ~-43 minecraft:light_gray_stained_glass
setblock ~67 ~1 ~-44 minecraft:iron_door[half=lower,facing=west]
setblock ~67 ~2 ~-44 minecraft:iron_door[half=upper,facing=west]
fill ~67 ~1 ~-44 ~67 ~4 ~-45 minecraft:polished_blackstone
fill ~67 ~5 ~-44 ~67 ~5 ~-45 minecraft:light_blue_stained_glass
fill ~69 ~13 ~-44 ~71 ~14 ~-44 minecraft:iron_block
fill ~67 ~12 ~-46 ~72 ~12 ~-43 minecraft:stone_brick_slab
# 266 shop_house style=storefront context=station_front facing=north
fill ~-61 ~-3 ~-45 ~-58 ~-1 ~-40 minecraft:stone
fill ~-61 ~0 ~-45 ~-58 ~7 ~-40 minecraft:light_gray_concrete
fill ~-60 ~1 ~-44 ~-59 ~6 ~-41 minecraft:air
fill ~-60 ~4 ~-44 ~-59 ~4 ~-41 minecraft:smooth_stone
fill ~-61 ~2 ~-43 ~-61 ~3 ~-43 minecraft:gray_stained_glass
fill ~-58 ~2 ~-43 ~-58 ~3 ~-43 minecraft:light_gray_stained_glass
setblock ~-59 ~1 ~-45 minecraft:iron_door[half=lower,facing=north]
setblock ~-59 ~2 ~-45 minecraft:iron_door[half=upper,facing=north]
fill ~-60 ~1 ~-45 ~-59 ~3 ~-45 minecraft:cyan_stained_glass
setblock ~-59 ~1 ~-45 minecraft:iron_door[half=lower,facing=north]
setblock ~-59 ~2 ~-45 minecraft:iron_door[half=upper,facing=north]
setblock ~-59 ~3 ~-46 minecraft:red_wool
fill ~-61 ~8 ~-45 ~-58 ~8 ~-40 minecraft:smooth_stone_slab
# 267 small_office style=setback_tower context=local_front facing=south
fill ~33 ~-3 ~8 ~36 ~-1 ~13 minecraft:stone
fill ~33 ~0 ~8 ~36 ~11 ~13 minecraft:light_gray_concrete
fill ~34 ~1 ~9 ~35 ~10 ~12 minecraft:air
fill ~34 ~4 ~9 ~35 ~4 ~12 minecraft:smooth_stone
fill ~34 ~8 ~9 ~35 ~8 ~12 minecraft:smooth_stone
fill ~33 ~2 ~10 ~33 ~3 ~10 minecraft:gray_stained_glass
fill ~36 ~2 ~10 ~36 ~3 ~10 minecraft:light_gray_stained_glass
fill ~33 ~6 ~10 ~33 ~7 ~10 minecraft:gray_stained_glass
fill ~36 ~6 ~10 ~36 ~7 ~10 minecraft:light_gray_stained_glass
setblock ~35 ~1 ~13 minecraft:iron_door[half=lower,facing=south]
setblock ~35 ~2 ~13 minecraft:iron_door[half=upper,facing=south]
fill ~33 ~7 ~8 ~36 ~11 ~13 minecraft:air
fill ~34 ~7 ~9 ~35 ~11 ~12 minecraft:light_gray_concrete
fill ~35 ~8 ~10 ~34 ~10 ~11 minecraft:air
fill ~34 ~12 ~9 ~35 ~12 ~12 minecraft:smooth_stone_slab
fill ~35 ~13 ~10 ~35 ~14 ~12 minecraft:light_gray_concrete
setblock ~35 ~13 ~11 minecraft:lightning_rod
# 268 workshop style=industrial_shed context=arterial_front facing=west
fill ~-31 ~-3 ~-89 ~-26 ~-1 ~-86 minecraft:stone
fill ~-31 ~0 ~-89 ~-26 ~11 ~-86 minecraft:bricks
fill ~-30 ~1 ~-88 ~-27 ~10 ~-87 minecraft:air
fill ~-30 ~4 ~-88 ~-27 ~4 ~-87 minecraft:smooth_stone
fill ~-30 ~8 ~-88 ~-27 ~8 ~-87 minecraft:smooth_stone
fill ~-29 ~2 ~-89 ~-29 ~3 ~-89 minecraft:gray_stained_glass
fill ~-29 ~2 ~-86 ~-29 ~3 ~-86 minecraft:light_gray_stained_glass
fill ~-29 ~6 ~-89 ~-29 ~7 ~-89 minecraft:gray_stained_glass
fill ~-29 ~6 ~-86 ~-29 ~7 ~-86 minecraft:light_gray_stained_glass
setblock ~-31 ~1 ~-87 minecraft:iron_door[half=lower,facing=west]
setblock ~-31 ~2 ~-87 minecraft:iron_door[half=upper,facing=west]
fill ~-31 ~1 ~-87 ~-31 ~4 ~-88 minecraft:polished_blackstone
fill ~-31 ~5 ~-87 ~-31 ~5 ~-88 minecraft:light_blue_stained_glass
fill ~-29 ~13 ~-87 ~-27 ~14 ~-87 minecraft:iron_block
fill ~-31 ~12 ~-89 ~-26 ~12 ~-86 minecraft:deepslate_tile_slab
# 269 shop_house style=corner_store context=local_front facing=south
fill ~-105 ~-3 ~74 ~-102 ~-1 ~79 minecraft:stone
fill ~-105 ~0 ~74 ~-102 ~11 ~79 minecraft:mud_bricks
fill ~-104 ~1 ~75 ~-103 ~10 ~78 minecraft:air
fill ~-104 ~4 ~75 ~-103 ~4 ~78 minecraft:smooth_stone
fill ~-104 ~8 ~75 ~-103 ~8 ~78 minecraft:smooth_stone
fill ~-105 ~2 ~76 ~-105 ~3 ~76 minecraft:gray_stained_glass
fill ~-102 ~2 ~76 ~-102 ~3 ~76 minecraft:light_gray_stained_glass
fill ~-105 ~6 ~76 ~-105 ~7 ~76 minecraft:gray_stained_glass
fill ~-102 ~6 ~76 ~-102 ~7 ~76 minecraft:light_gray_stained_glass
setblock ~-103 ~1 ~79 minecraft:iron_door[half=lower,facing=south]
setblock ~-103 ~2 ~79 minecraft:iron_door[half=upper,facing=south]
fill ~-104 ~1 ~79 ~-103 ~3 ~79 minecraft:cyan_stained_glass
setblock ~-103 ~1 ~79 minecraft:iron_door[half=lower,facing=south]
setblock ~-103 ~2 ~79 minecraft:iron_door[half=upper,facing=south]
setblock ~-103 ~3 ~80 minecraft:red_wool
fill ~-105 ~12 ~74 ~-102 ~12 ~79 minecraft:deepslate_tile_slab
# 270 shop_house style=arcade_shop context=collector_front facing=north
fill ~39 ~-3 ~41 ~42 ~-1 ~46 minecraft:stone
fill ~39 ~0 ~41 ~42 ~9 ~46 minecraft:light_gray_concrete
fill ~40 ~1 ~42 ~41 ~8 ~45 minecraft:air
fill ~40 ~4 ~42 ~41 ~4 ~45 minecraft:smooth_stone
fill ~40 ~8 ~42 ~41 ~8 ~45 minecraft:smooth_stone
fill ~39 ~2 ~43 ~39 ~3 ~43 minecraft:gray_stained_glass
fill ~42 ~2 ~43 ~42 ~3 ~43 minecraft:light_gray_stained_glass
fill ~39 ~6 ~43 ~39 ~7 ~43 minecraft:gray_stained_glass
fill ~42 ~6 ~43 ~42 ~7 ~43 minecraft:light_gray_stained_glass
setblock ~41 ~1 ~41 minecraft:iron_door[half=lower,facing=north]
setblock ~41 ~2 ~41 minecraft:iron_door[half=upper,facing=north]
fill ~40 ~1 ~41 ~41 ~3 ~41 minecraft:cyan_stained_glass
setblock ~41 ~1 ~41 minecraft:iron_door[half=lower,facing=north]
setblock ~41 ~2 ~41 minecraft:iron_door[half=upper,facing=north]
setblock ~41 ~3 ~40 minecraft:red_wool
fill ~40 ~4 ~41 ~41 ~4 ~41 doomsday_decoration:porcelainbrickwall
fill ~39 ~10 ~41 ~42 ~10 ~46 minecraft:smooth_stone_slab
fill ~41 ~11 ~43 ~41 ~12 ~45 minecraft:light_gray_concrete
setblock ~41 ~11 ~44 minecraft:lightning_rod
# 271 small_office style=civic_modern context=local_front facing=west
fill ~-62 ~-3 ~83 ~-56 ~-1 ~87 minecraft:stone
fill ~-62 ~0 ~83 ~-56 ~9 ~87 minecraft:mud_bricks
fill ~-61 ~1 ~84 ~-57 ~8 ~86 minecraft:air
fill ~-61 ~4 ~84 ~-57 ~4 ~86 minecraft:smooth_stone
fill ~-61 ~8 ~84 ~-57 ~8 ~86 minecraft:smooth_stone
fill ~-60 ~2 ~83 ~-60 ~3 ~83 minecraft:gray_stained_glass
fill ~-60 ~2 ~87 ~-60 ~3 ~87 minecraft:light_gray_stained_glass
fill ~-62 ~2 ~85 ~-62 ~3 ~85 minecraft:gray_stained_glass
fill ~-56 ~2 ~85 ~-56 ~3 ~85 minecraft:light_gray_stained_glass
fill ~-60 ~6 ~83 ~-60 ~7 ~83 minecraft:gray_stained_glass
fill ~-60 ~6 ~87 ~-60 ~7 ~87 minecraft:light_gray_stained_glass
fill ~-62 ~6 ~85 ~-62 ~7 ~85 minecraft:gray_stained_glass
fill ~-56 ~6 ~85 ~-56 ~7 ~85 minecraft:light_gray_stained_glass
setblock ~-62 ~1 ~85 minecraft:iron_door[half=lower,facing=west]
setblock ~-62 ~2 ~85 minecraft:iron_door[half=upper,facing=west]
# 272 shop_house style=corner_store context=local_front facing=north
fill ~59 ~-3 ~99 ~62 ~-1 ~104 minecraft:stone
fill ~59 ~0 ~99 ~62 ~9 ~104 minecraft:gray_concrete
fill ~60 ~1 ~100 ~61 ~8 ~103 minecraft:air
fill ~60 ~4 ~100 ~61 ~4 ~103 minecraft:smooth_stone
fill ~60 ~8 ~100 ~61 ~8 ~103 minecraft:smooth_stone
fill ~59 ~2 ~101 ~59 ~3 ~101 minecraft:gray_stained_glass
fill ~62 ~2 ~101 ~62 ~3 ~101 minecraft:light_gray_stained_glass
fill ~59 ~6 ~101 ~59 ~7 ~101 minecraft:gray_stained_glass
fill ~62 ~6 ~101 ~62 ~7 ~101 minecraft:light_gray_stained_glass
setblock ~61 ~1 ~99 minecraft:iron_door[half=lower,facing=north]
setblock ~61 ~2 ~99 minecraft:iron_door[half=upper,facing=north]
fill ~60 ~1 ~99 ~61 ~3 ~99 minecraft:cyan_stained_glass
setblock ~61 ~1 ~99 minecraft:iron_door[half=lower,facing=north]
setblock ~61 ~2 ~99 minecraft:iron_door[half=upper,facing=north]
setblock ~61 ~3 ~98 minecraft:red_wool
fill ~59 ~10 ~99 ~62 ~10 ~104 minecraft:smooth_stone_slab
