# Buildings 73..80
# 073 detached_house style=rowhouse context=local_front facing=north
fill ~-5 ~-3 ~110 ~4 ~-1 ~117 minecraft:stone
fill ~-5 ~0 ~110 ~4 ~7 ~117 minecraft:white_terracotta
fill ~-4 ~1 ~111 ~3 ~6 ~116 minecraft:air
fill ~-4 ~4 ~111 ~3 ~4 ~116 minecraft:smooth_stone
fill ~-3 ~2 ~110 ~-3 ~3 ~110 minecraft:gray_stained_glass
fill ~-3 ~2 ~117 ~-3 ~3 ~117 minecraft:light_gray_stained_glass
fill ~0 ~2 ~110 ~0 ~3 ~110 minecraft:gray_stained_glass
fill ~0 ~2 ~117 ~0 ~3 ~117 minecraft:light_gray_stained_glass
fill ~-5 ~2 ~112 ~-5 ~3 ~112 minecraft:gray_stained_glass
fill ~4 ~2 ~112 ~4 ~3 ~112 minecraft:light_gray_stained_glass
fill ~-5 ~2 ~115 ~-5 ~3 ~115 minecraft:gray_stained_glass
fill ~4 ~2 ~115 ~4 ~3 ~115 minecraft:light_gray_stained_glass
setblock ~-1 ~1 ~110 minecraft:iron_door[half=lower,facing=north]
setblock ~-1 ~2 ~110 minecraft:iron_door[half=upper,facing=north]
fill ~-5 ~8 ~110 ~4 ~8 ~117 minecraft:dark_oak_slab
fill ~-4 ~9 ~111 ~3 ~9 ~116 minecraft:dark_oak_slab
setblock ~-1 ~3 ~109 minecraft:dark_oak_slab[type=top]
fill ~-4 ~1 ~110 ~-4 ~7 ~110 minecraft:dark_oak_planks
fill ~0 ~1 ~110 ~0 ~7 ~110 minecraft:dark_oak_planks
# 074 workshop style=industrial_shed context=local_front facing=north
fill ~-20 ~-3 ~110 ~-12 ~-1 ~116 minecraft:stone
fill ~-20 ~0 ~110 ~-12 ~7 ~116 minecraft:white_terracotta
fill ~-19 ~1 ~111 ~-13 ~6 ~115 minecraft:air
fill ~-19 ~4 ~111 ~-13 ~4 ~115 minecraft:smooth_stone
fill ~-18 ~2 ~110 ~-18 ~3 ~110 minecraft:gray_stained_glass
fill ~-18 ~2 ~116 ~-18 ~3 ~116 minecraft:light_gray_stained_glass
fill ~-15 ~2 ~110 ~-15 ~3 ~110 minecraft:gray_stained_glass
fill ~-15 ~2 ~116 ~-15 ~3 ~116 minecraft:light_gray_stained_glass
fill ~-20 ~2 ~112 ~-20 ~3 ~112 minecraft:gray_stained_glass
fill ~-12 ~2 ~112 ~-12 ~3 ~112 minecraft:light_gray_stained_glass
setblock ~-16 ~1 ~110 minecraft:iron_door[half=lower,facing=north]
setblock ~-16 ~2 ~110 minecraft:iron_door[half=upper,facing=north]
fill ~-18 ~1 ~110 ~-14 ~4 ~110 minecraft:polished_blackstone
fill ~-18 ~5 ~110 ~-14 ~5 ~110 minecraft:light_blue_stained_glass
fill ~-18 ~9 ~112 ~-16 ~10 ~114 minecraft:iron_block
fill ~-20 ~8 ~110 ~-12 ~8 ~116 minecraft:dark_oak_slab
fill ~-19 ~1 ~110 ~-19 ~7 ~110 minecraft:dark_oak_planks
fill ~-15 ~1 ~110 ~-15 ~7 ~110 minecraft:dark_oak_planks
# 075 shop_house style=storefront context=collector_front facing=north
fill ~-27 ~-3 ~-64 ~-16 ~-1 ~-56 minecraft:stone
fill ~-27 ~0 ~-64 ~-16 ~12 ~-56 minecraft:smooth_sandstone
fill ~-26 ~1 ~-63 ~-17 ~11 ~-57 minecraft:air
fill ~-26 ~4 ~-63 ~-17 ~4 ~-57 minecraft:smooth_stone
fill ~-26 ~8 ~-63 ~-17 ~8 ~-57 minecraft:smooth_stone
fill ~-25 ~2 ~-64 ~-25 ~3 ~-64 minecraft:gray_stained_glass
fill ~-25 ~2 ~-56 ~-25 ~3 ~-56 minecraft:light_gray_stained_glass
fill ~-22 ~2 ~-64 ~-22 ~3 ~-64 minecraft:gray_stained_glass
fill ~-22 ~2 ~-56 ~-22 ~3 ~-56 minecraft:light_gray_stained_glass
fill ~-19 ~2 ~-64 ~-19 ~3 ~-64 minecraft:gray_stained_glass
fill ~-19 ~2 ~-56 ~-19 ~3 ~-56 minecraft:light_gray_stained_glass
fill ~-27 ~2 ~-62 ~-27 ~3 ~-62 minecraft:gray_stained_glass
fill ~-16 ~2 ~-62 ~-16 ~3 ~-62 minecraft:light_gray_stained_glass
fill ~-27 ~2 ~-59 ~-27 ~3 ~-59 minecraft:gray_stained_glass
fill ~-16 ~2 ~-59 ~-16 ~3 ~-59 minecraft:light_gray_stained_glass
fill ~-25 ~6 ~-64 ~-25 ~7 ~-64 minecraft:gray_stained_glass
fill ~-25 ~6 ~-56 ~-25 ~7 ~-56 minecraft:light_gray_stained_glass
fill ~-22 ~6 ~-64 ~-22 ~7 ~-64 minecraft:gray_stained_glass
fill ~-22 ~6 ~-56 ~-22 ~7 ~-56 minecraft:light_gray_stained_glass
fill ~-19 ~6 ~-64 ~-19 ~7 ~-64 minecraft:gray_stained_glass
fill ~-19 ~6 ~-56 ~-19 ~7 ~-56 minecraft:light_gray_stained_glass
fill ~-27 ~6 ~-62 ~-27 ~7 ~-62 minecraft:gray_stained_glass
fill ~-16 ~6 ~-62 ~-16 ~7 ~-62 minecraft:light_gray_stained_glass
fill ~-27 ~6 ~-59 ~-27 ~7 ~-59 minecraft:gray_stained_glass
fill ~-16 ~6 ~-59 ~-16 ~7 ~-59 minecraft:light_gray_stained_glass
fill ~-25 ~10 ~-64 ~-25 ~11 ~-64 minecraft:gray_stained_glass
fill ~-25 ~10 ~-56 ~-25 ~11 ~-56 minecraft:light_gray_stained_glass
fill ~-22 ~10 ~-64 ~-22 ~11 ~-64 minecraft:gray_stained_glass
fill ~-22 ~10 ~-56 ~-22 ~11 ~-56 minecraft:light_gray_stained_glass
fill ~-19 ~10 ~-64 ~-19 ~11 ~-64 minecraft:gray_stained_glass
fill ~-19 ~10 ~-56 ~-19 ~11 ~-56 minecraft:light_gray_stained_glass
fill ~-27 ~10 ~-62 ~-27 ~11 ~-62 minecraft:gray_stained_glass
fill ~-16 ~10 ~-62 ~-16 ~11 ~-62 minecraft:light_gray_stained_glass
fill ~-27 ~10 ~-59 ~-27 ~11 ~-59 minecraft:gray_stained_glass
fill ~-16 ~10 ~-59 ~-16 ~11 ~-59 minecraft:light_gray_stained_glass
setblock ~-22 ~1 ~-64 minecraft:iron_door[half=lower,facing=north]
setblock ~-22 ~2 ~-64 minecraft:iron_door[half=upper,facing=north]
fill ~-26 ~1 ~-64 ~-17 ~3 ~-64 minecraft:cyan_stained_glass
setblock ~-22 ~1 ~-64 minecraft:iron_door[half=lower,facing=north]
setblock ~-22 ~2 ~-64 minecraft:iron_door[half=upper,facing=north]
setblock ~-22 ~3 ~-65 minecraft:red_wool
fill ~-27 ~13 ~-64 ~-16 ~13 ~-56 minecraft:stone_brick_slab
fill ~-25 ~14 ~-62 ~-23 ~15 ~-60 minecraft:light_gray_concrete
setblock ~-22 ~14 ~-61 minecraft:lightning_rod
fill ~-26 ~1 ~-64 ~-26 ~7 ~-64 minecraft:brown_terracotta
fill ~-22 ~1 ~-64 ~-22 ~7 ~-64 minecraft:brown_terracotta
fill ~-18 ~1 ~-64 ~-18 ~7 ~-64 minecraft:brown_terracotta
fill ~-26 ~6 ~-63 ~-17 ~12 ~-57 minecraft:smooth_sandstone
fill ~-25 ~7 ~-62 ~-18 ~11 ~-58 minecraft:air
setblock ~-25 ~3 ~-64 minecraft:red_carpet
setblock ~-20 ~3 ~-64 minecraft:red_carpet
# 076 clinic style=balcony_block context=collector_front facing=west
fill ~-82 ~-3 ~77 ~-73 ~-1 ~81 minecraft:stone
fill ~-82 ~0 ~77 ~-73 ~9 ~81 minecraft:white_terracotta
fill ~-81 ~1 ~78 ~-74 ~8 ~80 minecraft:air
fill ~-81 ~4 ~78 ~-74 ~4 ~80 minecraft:smooth_stone
fill ~-81 ~8 ~78 ~-74 ~8 ~80 minecraft:smooth_stone
fill ~-80 ~2 ~77 ~-80 ~3 ~77 minecraft:gray_stained_glass
fill ~-80 ~2 ~81 ~-80 ~3 ~81 minecraft:light_gray_stained_glass
fill ~-77 ~2 ~77 ~-77 ~3 ~77 minecraft:gray_stained_glass
fill ~-77 ~2 ~81 ~-77 ~3 ~81 minecraft:light_gray_stained_glass
fill ~-82 ~2 ~79 ~-82 ~3 ~79 minecraft:gray_stained_glass
fill ~-73 ~2 ~79 ~-73 ~3 ~79 minecraft:light_gray_stained_glass
fill ~-80 ~6 ~77 ~-80 ~7 ~77 minecraft:gray_stained_glass
fill ~-80 ~6 ~81 ~-80 ~7 ~81 minecraft:light_gray_stained_glass
fill ~-77 ~6 ~77 ~-77 ~7 ~77 minecraft:gray_stained_glass
fill ~-77 ~6 ~81 ~-77 ~7 ~81 minecraft:light_gray_stained_glass
fill ~-82 ~6 ~79 ~-82 ~7 ~79 minecraft:gray_stained_glass
fill ~-73 ~6 ~79 ~-73 ~7 ~79 minecraft:light_gray_stained_glass
setblock ~-82 ~1 ~79 minecraft:iron_door[half=lower,facing=west]
setblock ~-82 ~2 ~79 minecraft:iron_door[half=upper,facing=west]
fill ~-83 ~4 ~79 ~-83 ~4 ~79 minecraft:smooth_stone_slab
fill ~-83 ~8 ~79 ~-83 ~8 ~79 minecraft:smooth_stone_slab
fill ~-82 ~10 ~77 ~-73 ~10 ~81 minecraft:dark_oak_slab
# 077 clinic style=setback_block context=collector_front facing=south
fill ~6 ~-3 ~-86 ~16 ~-1 ~-76 minecraft:stone
fill ~6 ~0 ~-86 ~16 ~8 ~-76 minecraft:smooth_sandstone
fill ~7 ~1 ~-85 ~15 ~7 ~-77 minecraft:air
fill ~7 ~4 ~-85 ~15 ~4 ~-77 minecraft:smooth_stone
fill ~8 ~2 ~-86 ~8 ~3 ~-86 minecraft:gray_stained_glass
fill ~8 ~2 ~-76 ~8 ~3 ~-76 minecraft:light_gray_stained_glass
fill ~11 ~2 ~-86 ~11 ~3 ~-86 minecraft:gray_stained_glass
fill ~11 ~2 ~-76 ~11 ~3 ~-76 minecraft:light_gray_stained_glass
fill ~14 ~2 ~-86 ~14 ~3 ~-86 minecraft:gray_stained_glass
fill ~14 ~2 ~-76 ~14 ~3 ~-76 minecraft:light_gray_stained_glass
fill ~6 ~2 ~-84 ~6 ~3 ~-84 minecraft:gray_stained_glass
fill ~16 ~2 ~-84 ~16 ~3 ~-84 minecraft:light_gray_stained_glass
fill ~6 ~2 ~-81 ~6 ~3 ~-81 minecraft:gray_stained_glass
fill ~16 ~2 ~-81 ~16 ~3 ~-81 minecraft:light_gray_stained_glass
fill ~6 ~2 ~-78 ~6 ~3 ~-78 minecraft:gray_stained_glass
fill ~16 ~2 ~-78 ~16 ~3 ~-78 minecraft:light_gray_stained_glass
fill ~8 ~6 ~-86 ~8 ~7 ~-86 minecraft:gray_stained_glass
fill ~8 ~6 ~-76 ~8 ~7 ~-76 minecraft:light_gray_stained_glass
fill ~11 ~6 ~-86 ~11 ~7 ~-86 minecraft:gray_stained_glass
fill ~11 ~6 ~-76 ~11 ~7 ~-76 minecraft:light_gray_stained_glass
fill ~14 ~6 ~-86 ~14 ~7 ~-86 minecraft:gray_stained_glass
fill ~14 ~6 ~-76 ~14 ~7 ~-76 minecraft:light_gray_stained_glass
fill ~6 ~6 ~-84 ~6 ~7 ~-84 minecraft:gray_stained_glass
fill ~16 ~6 ~-84 ~16 ~7 ~-84 minecraft:light_gray_stained_glass
fill ~6 ~6 ~-81 ~6 ~7 ~-81 minecraft:gray_stained_glass
fill ~16 ~6 ~-81 ~16 ~7 ~-81 minecraft:light_gray_stained_glass
fill ~6 ~6 ~-78 ~6 ~7 ~-78 minecraft:gray_stained_glass
fill ~16 ~6 ~-78 ~16 ~7 ~-78 minecraft:light_gray_stained_glass
setblock ~11 ~1 ~-76 minecraft:iron_door[half=lower,facing=south]
setblock ~11 ~2 ~-76 minecraft:iron_door[half=upper,facing=south]
fill ~7 ~1 ~-76 ~7 ~7 ~-76 minecraft:brown_terracotta
fill ~11 ~1 ~-76 ~11 ~7 ~-76 minecraft:brown_terracotta
fill ~15 ~1 ~-76 ~15 ~7 ~-76 minecraft:brown_terracotta
# 078 port_warehouse style=sawtooth context=waterfront_front facing=south
fill ~109 ~-3 ~97 ~119 ~-1 ~106 minecraft:stone
fill ~109 ~0 ~97 ~119 ~9 ~106 minecraft:bricks
fill ~110 ~1 ~98 ~118 ~8 ~105 minecraft:air
fill ~110 ~4 ~98 ~118 ~4 ~105 minecraft:smooth_stone
fill ~110 ~8 ~98 ~118 ~8 ~105 minecraft:smooth_stone
fill ~111 ~2 ~97 ~111 ~3 ~97 minecraft:gray_stained_glass
fill ~111 ~2 ~106 ~111 ~3 ~106 minecraft:light_gray_stained_glass
fill ~114 ~2 ~97 ~114 ~3 ~97 minecraft:gray_stained_glass
fill ~114 ~2 ~106 ~114 ~3 ~106 minecraft:light_gray_stained_glass
fill ~117 ~2 ~97 ~117 ~3 ~97 minecraft:gray_stained_glass
fill ~117 ~2 ~106 ~117 ~3 ~106 minecraft:light_gray_stained_glass
fill ~109 ~2 ~99 ~109 ~3 ~99 minecraft:gray_stained_glass
fill ~119 ~2 ~99 ~119 ~3 ~99 minecraft:light_gray_stained_glass
fill ~109 ~2 ~102 ~109 ~3 ~102 minecraft:gray_stained_glass
fill ~119 ~2 ~102 ~119 ~3 ~102 minecraft:light_gray_stained_glass
fill ~111 ~6 ~97 ~111 ~7 ~97 minecraft:gray_stained_glass
fill ~111 ~6 ~106 ~111 ~7 ~106 minecraft:light_gray_stained_glass
fill ~114 ~6 ~97 ~114 ~7 ~97 minecraft:gray_stained_glass
fill ~114 ~6 ~106 ~114 ~7 ~106 minecraft:light_gray_stained_glass
fill ~117 ~6 ~97 ~117 ~7 ~97 minecraft:gray_stained_glass
fill ~117 ~6 ~106 ~117 ~7 ~106 minecraft:light_gray_stained_glass
fill ~109 ~6 ~99 ~109 ~7 ~99 minecraft:gray_stained_glass
fill ~119 ~6 ~99 ~119 ~7 ~99 minecraft:light_gray_stained_glass
fill ~109 ~6 ~102 ~109 ~7 ~102 minecraft:gray_stained_glass
fill ~119 ~6 ~102 ~119 ~7 ~102 minecraft:light_gray_stained_glass
setblock ~114 ~1 ~106 minecraft:iron_door[half=lower,facing=south]
setblock ~114 ~2 ~106 minecraft:iron_door[half=upper,facing=south]
fill ~111 ~1 ~106 ~117 ~4 ~106 minecraft:polished_blackstone
fill ~111 ~5 ~106 ~117 ~5 ~106 minecraft:light_blue_stained_glass
fill ~111 ~11 ~99 ~113 ~12 ~101 minecraft:iron_block
fill ~109 ~10 ~97 ~119 ~10 ~106 minecraft:deepslate_tile_slab
fill ~111 ~11 ~99 ~113 ~12 ~101 minecraft:light_gray_concrete
setblock ~114 ~11 ~100 minecraft:lightning_rod
fill ~110 ~1 ~106 ~110 ~7 ~106 minecraft:weathered_cut_copper
fill ~114 ~1 ~106 ~114 ~7 ~106 minecraft:weathered_cut_copper
fill ~118 ~1 ~106 ~118 ~7 ~106 minecraft:weathered_cut_copper
# 079 shop_house style=storefront context=collector_front facing=south
fill ~91 ~-3 ~-59 ~100 ~-1 ~-52 minecraft:stone
fill ~91 ~0 ~-59 ~100 ~11 ~-52 minecraft:bricks
fill ~92 ~1 ~-58 ~99 ~10 ~-53 minecraft:air
fill ~92 ~4 ~-58 ~99 ~4 ~-53 minecraft:smooth_stone
fill ~92 ~8 ~-58 ~99 ~8 ~-53 minecraft:smooth_stone
fill ~93 ~2 ~-59 ~93 ~3 ~-59 minecraft:gray_stained_glass
fill ~93 ~2 ~-52 ~93 ~3 ~-52 minecraft:light_gray_stained_glass
fill ~96 ~2 ~-59 ~96 ~3 ~-59 minecraft:gray_stained_glass
fill ~96 ~2 ~-52 ~96 ~3 ~-52 minecraft:light_gray_stained_glass
fill ~91 ~2 ~-57 ~91 ~3 ~-57 minecraft:gray_stained_glass
fill ~100 ~2 ~-57 ~100 ~3 ~-57 minecraft:light_gray_stained_glass
fill ~91 ~2 ~-54 ~91 ~3 ~-54 minecraft:gray_stained_glass
fill ~100 ~2 ~-54 ~100 ~3 ~-54 minecraft:light_gray_stained_glass
fill ~93 ~6 ~-59 ~93 ~7 ~-59 minecraft:gray_stained_glass
fill ~93 ~6 ~-52 ~93 ~7 ~-52 minecraft:light_gray_stained_glass
fill ~96 ~6 ~-59 ~96 ~7 ~-59 minecraft:gray_stained_glass
fill ~96 ~6 ~-52 ~96 ~7 ~-52 minecraft:light_gray_stained_glass
fill ~91 ~6 ~-57 ~91 ~7 ~-57 minecraft:gray_stained_glass
fill ~100 ~6 ~-57 ~100 ~7 ~-57 minecraft:light_gray_stained_glass
fill ~91 ~6 ~-54 ~91 ~7 ~-54 minecraft:gray_stained_glass
fill ~100 ~6 ~-54 ~100 ~7 ~-54 minecraft:light_gray_stained_glass
setblock ~95 ~1 ~-52 minecraft:iron_door[half=lower,facing=south]
setblock ~95 ~2 ~-52 minecraft:iron_door[half=upper,facing=south]
fill ~92 ~1 ~-52 ~99 ~3 ~-52 minecraft:cyan_stained_glass
setblock ~95 ~1 ~-52 minecraft:iron_door[half=lower,facing=south]
setblock ~95 ~2 ~-52 minecraft:iron_door[half=upper,facing=south]
setblock ~95 ~3 ~-51 minecraft:red_wool
fill ~91 ~12 ~-59 ~100 ~12 ~-52 minecraft:deepslate_tile_slab
fill ~92 ~1 ~-52 ~92 ~7 ~-52 minecraft:weathered_cut_copper
fill ~96 ~1 ~-52 ~96 ~7 ~-52 minecraft:weathered_cut_copper
fill ~92 ~6 ~-58 ~99 ~11 ~-53 minecraft:bricks
fill ~93 ~7 ~-57 ~98 ~10 ~-54 minecraft:air
setblock ~93 ~3 ~-52 minecraft:red_carpet
setblock ~98 ~3 ~-52 minecraft:red_carpet
# 080 factory style=loading_bay context=local_front facing=north
fill ~-125 ~-3 ~-112 ~-110 ~-1 ~-97 minecraft:stone
fill ~-125 ~0 ~-112 ~-110 ~9 ~-97 minecraft:stone_bricks
fill ~-124 ~1 ~-111 ~-111 ~8 ~-98 minecraft:air
fill ~-124 ~4 ~-111 ~-111 ~4 ~-98 minecraft:smooth_stone
fill ~-124 ~8 ~-111 ~-111 ~8 ~-98 minecraft:smooth_stone
fill ~-123 ~2 ~-112 ~-123 ~3 ~-112 minecraft:gray_stained_glass
fill ~-123 ~2 ~-97 ~-123 ~3 ~-97 minecraft:light_gray_stained_glass
fill ~-120 ~2 ~-112 ~-120 ~3 ~-112 minecraft:gray_stained_glass
fill ~-120 ~2 ~-97 ~-120 ~3 ~-97 minecraft:light_gray_stained_glass
fill ~-117 ~2 ~-112 ~-117 ~3 ~-112 minecraft:gray_stained_glass
fill ~-117 ~2 ~-97 ~-117 ~3 ~-97 minecraft:light_gray_stained_glass
fill ~-114 ~2 ~-112 ~-114 ~3 ~-112 minecraft:gray_stained_glass
fill ~-114 ~2 ~-97 ~-114 ~3 ~-97 minecraft:light_gray_stained_glass
fill ~-125 ~2 ~-110 ~-125 ~3 ~-110 minecraft:gray_stained_glass
fill ~-110 ~2 ~-110 ~-110 ~3 ~-110 minecraft:light_gray_stained_glass
fill ~-125 ~2 ~-107 ~-125 ~3 ~-107 minecraft:gray_stained_glass
fill ~-110 ~2 ~-107 ~-110 ~3 ~-107 minecraft:light_gray_stained_glass
fill ~-125 ~2 ~-104 ~-125 ~3 ~-104 minecraft:gray_stained_glass
fill ~-110 ~2 ~-104 ~-110 ~3 ~-104 minecraft:light_gray_stained_glass
fill ~-125 ~2 ~-101 ~-125 ~3 ~-101 minecraft:gray_stained_glass
fill ~-110 ~2 ~-101 ~-110 ~3 ~-101 minecraft:light_gray_stained_glass
fill ~-123 ~6 ~-112 ~-123 ~7 ~-112 minecraft:gray_stained_glass
fill ~-123 ~6 ~-97 ~-123 ~7 ~-97 minecraft:light_gray_stained_glass
fill ~-120 ~6 ~-112 ~-120 ~7 ~-112 minecraft:gray_stained_glass
fill ~-120 ~6 ~-97 ~-120 ~7 ~-97 minecraft:light_gray_stained_glass
fill ~-117 ~6 ~-112 ~-117 ~7 ~-112 minecraft:gray_stained_glass
fill ~-117 ~6 ~-97 ~-117 ~7 ~-97 minecraft:light_gray_stained_glass
fill ~-114 ~6 ~-112 ~-114 ~7 ~-112 minecraft:gray_stained_glass
fill ~-114 ~6 ~-97 ~-114 ~7 ~-97 minecraft:light_gray_stained_glass
fill ~-125 ~6 ~-110 ~-125 ~7 ~-110 minecraft:gray_stained_glass
fill ~-110 ~6 ~-110 ~-110 ~7 ~-110 minecraft:light_gray_stained_glass
fill ~-125 ~6 ~-107 ~-125 ~7 ~-107 minecraft:gray_stained_glass
fill ~-110 ~6 ~-107 ~-110 ~7 ~-107 minecraft:light_gray_stained_glass
fill ~-125 ~6 ~-104 ~-125 ~7 ~-104 minecraft:gray_stained_glass
fill ~-110 ~6 ~-104 ~-110 ~7 ~-104 minecraft:light_gray_stained_glass
fill ~-125 ~6 ~-101 ~-125 ~7 ~-101 minecraft:gray_stained_glass
fill ~-110 ~6 ~-101 ~-110 ~7 ~-101 minecraft:light_gray_stained_glass
setblock ~-120 ~1 ~-112 minecraft:iron_door[half=lower,facing=north]
setblock ~-120 ~2 ~-112 minecraft:iron_door[half=upper,facing=north]
fill ~-123 ~1 ~-112 ~-112 ~4 ~-112 minecraft:polished_blackstone
fill ~-123 ~5 ~-112 ~-112 ~5 ~-112 minecraft:light_blue_stained_glass
fill ~-123 ~11 ~-110 ~-121 ~12 ~-108 minecraft:iron_block
fill ~-125 ~10 ~-112 ~-110 ~10 ~-97 minecraft:smooth_stone_slab
fill ~-124 ~1 ~-112 ~-124 ~7 ~-112 doomsday_decoration:ironsheetwall_2
fill ~-120 ~1 ~-112 ~-120 ~7 ~-112 doomsday_decoration:ironsheetwall_2
fill ~-116 ~1 ~-112 ~-116 ~7 ~-112 doomsday_decoration:ironsheetwall_2
fill ~-112 ~1 ~-112 ~-112 ~7 ~-112 doomsday_decoration:ironsheetwall_2
