# Buildings 273..280
# 273 workshop style=stepped_house context=arterial_front facing=south
fill ~-62 ~-3 ~-39 ~-59 ~-1 ~-33 minecraft:stone
fill ~-62 ~0 ~-39 ~-59 ~7 ~-33 minecraft:smooth_sandstone
fill ~-61 ~1 ~-38 ~-60 ~6 ~-34 minecraft:air
fill ~-61 ~4 ~-38 ~-60 ~4 ~-34 minecraft:smooth_stone
fill ~-62 ~2 ~-37 ~-62 ~3 ~-37 minecraft:gray_stained_glass
fill ~-59 ~2 ~-37 ~-59 ~3 ~-37 minecraft:light_gray_stained_glass
setblock ~-60 ~1 ~-33 minecraft:iron_door[half=lower,facing=south]
setblock ~-60 ~2 ~-33 minecraft:iron_door[half=upper,facing=south]
fill ~-62 ~8 ~-39 ~-59 ~8 ~-33 minecraft:stone_brick_slab
fill ~-61 ~9 ~-38 ~-60 ~9 ~-34 minecraft:stone_brick_slab
setblock ~-60 ~3 ~-32 minecraft:dark_oak_slab[type=top]
# 274 small_office style=rowhouse context=collector_front facing=west
fill ~74 ~-3 ~78 ~77 ~-1 ~84 minecraft:stone
fill ~74 ~0 ~78 ~77 ~5 ~84 minecraft:stone_bricks
fill ~75 ~1 ~79 ~76 ~4 ~83 minecraft:air
fill ~75 ~4 ~79 ~76 ~4 ~83 minecraft:smooth_stone
fill ~74 ~2 ~80 ~74 ~3 ~80 minecraft:gray_stained_glass
fill ~77 ~2 ~80 ~77 ~3 ~80 minecraft:light_gray_stained_glass
setblock ~74 ~1 ~81 minecraft:iron_door[half=lower,facing=west]
setblock ~74 ~2 ~81 minecraft:iron_door[half=upper,facing=west]
fill ~74 ~6 ~78 ~77 ~6 ~84 minecraft:stone_brick_slab
fill ~75 ~7 ~79 ~76 ~7 ~83 minecraft:stone_brick_slab
setblock ~73 ~3 ~81 minecraft:dark_oak_slab[type=top]
# 275 small_office style=rowhouse context=collector_front facing=east
fill ~43 ~-3 ~-116 ~46 ~-1 ~-111 minecraft:stone
fill ~43 ~0 ~-116 ~46 ~7 ~-111 minecraft:bricks
fill ~44 ~1 ~-115 ~45 ~6 ~-112 minecraft:air
fill ~44 ~4 ~-115 ~45 ~4 ~-112 minecraft:smooth_stone
fill ~43 ~2 ~-114 ~43 ~3 ~-114 minecraft:gray_stained_glass
fill ~46 ~2 ~-114 ~46 ~3 ~-114 minecraft:light_gray_stained_glass
setblock ~46 ~1 ~-114 minecraft:iron_door[half=lower,facing=east]
setblock ~46 ~2 ~-114 minecraft:iron_door[half=upper,facing=east]
fill ~43 ~8 ~-116 ~46 ~8 ~-111 minecraft:deepslate_tile_slab
fill ~44 ~9 ~-115 ~45 ~9 ~-112 minecraft:deepslate_tile_slab
setblock ~47 ~3 ~-114 minecraft:dark_oak_slab[type=top]
# 276 local_shop style=stepped_house context=back_block facing=north
fill ~-126 ~-3 ~82 ~-123 ~-1 ~87 minecraft:stone
fill ~-126 ~0 ~82 ~-123 ~7 ~87 minecraft:white_terracotta
fill ~-125 ~1 ~83 ~-124 ~6 ~86 minecraft:air
fill ~-125 ~4 ~83 ~-124 ~4 ~86 minecraft:smooth_stone
fill ~-126 ~2 ~84 ~-126 ~3 ~84 minecraft:gray_stained_glass
fill ~-123 ~2 ~84 ~-123 ~3 ~84 minecraft:light_gray_stained_glass
setblock ~-124 ~1 ~82 minecraft:iron_door[half=lower,facing=north]
setblock ~-124 ~2 ~82 minecraft:iron_door[half=upper,facing=north]
fill ~-126 ~8 ~82 ~-123 ~8 ~87 minecraft:dark_oak_slab
fill ~-125 ~9 ~83 ~-124 ~9 ~86 minecraft:dark_oak_slab
setblock ~-124 ~3 ~81 minecraft:dark_oak_slab[type=top]
# 277 local_shop style=rowhouse context=back_block facing=east
fill ~-70 ~-3 ~102 ~-67 ~-1 ~108 minecraft:stone
fill ~-70 ~0 ~102 ~-67 ~9 ~108 minecraft:mud_bricks
fill ~-69 ~1 ~103 ~-68 ~8 ~107 minecraft:air
fill ~-69 ~4 ~103 ~-68 ~4 ~107 minecraft:smooth_stone
fill ~-69 ~8 ~103 ~-68 ~8 ~107 minecraft:smooth_stone
fill ~-70 ~2 ~104 ~-70 ~3 ~104 minecraft:gray_stained_glass
fill ~-67 ~2 ~104 ~-67 ~3 ~104 minecraft:light_gray_stained_glass
fill ~-70 ~6 ~104 ~-70 ~7 ~104 minecraft:gray_stained_glass
fill ~-67 ~6 ~104 ~-67 ~7 ~104 minecraft:light_gray_stained_glass
setblock ~-67 ~1 ~105 minecraft:iron_door[half=lower,facing=east]
setblock ~-67 ~2 ~105 minecraft:iron_door[half=upper,facing=east]
fill ~-70 ~10 ~102 ~-67 ~10 ~108 minecraft:deepslate_tile_slab
fill ~-69 ~11 ~103 ~-68 ~11 ~107 minecraft:deepslate_tile_slab
setblock ~-66 ~3 ~105 minecraft:dark_oak_slab[type=top]
# 278 workshop style=rowhouse context=back_block facing=north
fill ~-109 ~-3 ~120 ~-105 ~-1 ~125 minecraft:stone
fill ~-109 ~0 ~120 ~-105 ~9 ~125 minecraft:calcite
fill ~-108 ~1 ~121 ~-106 ~8 ~124 minecraft:air
fill ~-108 ~4 ~121 ~-106 ~4 ~124 minecraft:smooth_stone
fill ~-108 ~8 ~121 ~-106 ~8 ~124 minecraft:smooth_stone
fill ~-107 ~2 ~120 ~-107 ~3 ~120 minecraft:gray_stained_glass
fill ~-107 ~2 ~125 ~-107 ~3 ~125 minecraft:light_gray_stained_glass
fill ~-109 ~2 ~122 ~-109 ~3 ~122 minecraft:gray_stained_glass
fill ~-105 ~2 ~122 ~-105 ~3 ~122 minecraft:light_gray_stained_glass
fill ~-107 ~6 ~120 ~-107 ~7 ~120 minecraft:gray_stained_glass
fill ~-107 ~6 ~125 ~-107 ~7 ~125 minecraft:light_gray_stained_glass
fill ~-109 ~6 ~122 ~-109 ~7 ~122 minecraft:gray_stained_glass
fill ~-105 ~6 ~122 ~-105 ~7 ~122 minecraft:light_gray_stained_glass
setblock ~-107 ~1 ~120 minecraft:iron_door[half=lower,facing=north]
setblock ~-107 ~2 ~120 minecraft:iron_door[half=upper,facing=north]
fill ~-109 ~10 ~120 ~-105 ~10 ~125 minecraft:stone_brick_slab
fill ~-108 ~11 ~121 ~-106 ~11 ~124 minecraft:stone_brick_slab
setblock ~-107 ~3 ~119 minecraft:dark_oak_slab[type=top]
# 279 local_shop style=storefront context=arterial_front facing=west
fill ~99 ~-3 ~0 ~102 ~-1 ~5 minecraft:stone
fill ~99 ~0 ~0 ~102 ~5 ~5 minecraft:bricks
fill ~100 ~1 ~1 ~101 ~4 ~4 minecraft:air
fill ~100 ~4 ~1 ~101 ~4 ~4 minecraft:smooth_stone
fill ~99 ~2 ~2 ~99 ~3 ~2 minecraft:gray_stained_glass
fill ~102 ~2 ~2 ~102 ~3 ~2 minecraft:light_gray_stained_glass
setblock ~99 ~1 ~2 minecraft:iron_door[half=lower,facing=west]
setblock ~99 ~2 ~2 minecraft:iron_door[half=upper,facing=west]
fill ~99 ~1 ~1 ~99 ~3 ~4 minecraft:cyan_stained_glass
setblock ~99 ~1 ~2 minecraft:iron_door[half=lower,facing=west]
setblock ~99 ~2 ~2 minecraft:iron_door[half=upper,facing=west]
setblock ~98 ~3 ~2 minecraft:red_wool
fill ~99 ~6 ~0 ~102 ~6 ~5 minecraft:deepslate_tile_slab
# 280 restaurant_block style=arcade_shop context=station_front facing=east
fill ~40 ~-3 ~-91 ~43 ~-1 ~-85 minecraft:stone
fill ~40 ~0 ~-91 ~43 ~5 ~-85 minecraft:stone_bricks
fill ~41 ~1 ~-90 ~42 ~4 ~-86 minecraft:air
fill ~41 ~4 ~-90 ~42 ~4 ~-86 minecraft:smooth_stone
fill ~40 ~2 ~-89 ~40 ~3 ~-89 minecraft:gray_stained_glass
fill ~43 ~2 ~-89 ~43 ~3 ~-89 minecraft:light_gray_stained_glass
setblock ~43 ~1 ~-88 minecraft:iron_door[half=lower,facing=east]
setblock ~43 ~2 ~-88 minecraft:iron_door[half=upper,facing=east]
fill ~43 ~1 ~-90 ~43 ~3 ~-86 minecraft:cyan_stained_glass
setblock ~43 ~1 ~-88 minecraft:iron_door[half=lower,facing=east]
setblock ~43 ~2 ~-88 minecraft:iron_door[half=upper,facing=east]
setblock ~44 ~3 ~-88 minecraft:red_wool
fill ~43 ~4 ~-90 ~43 ~4 ~-86 doomsday_decoration:ironsheetwall_2
fill ~40 ~6 ~-91 ~43 ~6 ~-85 minecraft:smooth_stone_slab
