# Buildings 225..232
# 225 medical_center style=bay_office context=station_front facing=east
fill ~-35 ~-3 ~-73 ~-31 ~-1 ~-67 minecraft:stone
fill ~-35 ~0 ~-73 ~-31 ~7 ~-67 minecraft:light_gray_concrete
fill ~-34 ~1 ~-72 ~-32 ~6 ~-68 minecraft:air
fill ~-34 ~4 ~-72 ~-32 ~4 ~-68 minecraft:smooth_stone
fill ~-33 ~2 ~-73 ~-33 ~3 ~-73 minecraft:gray_stained_glass
fill ~-33 ~2 ~-67 ~-33 ~3 ~-67 minecraft:light_gray_stained_glass
fill ~-35 ~2 ~-71 ~-35 ~3 ~-71 minecraft:gray_stained_glass
fill ~-31 ~2 ~-71 ~-31 ~3 ~-71 minecraft:light_gray_stained_glass
setblock ~-31 ~1 ~-70 minecraft:iron_door[half=lower,facing=east]
setblock ~-31 ~2 ~-70 minecraft:iron_door[half=upper,facing=east]
# 226 community style=setback_block context=collector_front facing=north
fill ~-61 ~-3 ~82 ~-56 ~-1 ~87 minecraft:stone
fill ~-61 ~0 ~82 ~-56 ~11 ~87 minecraft:calcite
fill ~-60 ~1 ~83 ~-57 ~10 ~86 minecraft:air
fill ~-60 ~4 ~83 ~-57 ~4 ~86 minecraft:smooth_stone
fill ~-60 ~8 ~83 ~-57 ~8 ~86 minecraft:smooth_stone
fill ~-59 ~2 ~82 ~-59 ~3 ~82 minecraft:gray_stained_glass
fill ~-59 ~2 ~87 ~-59 ~3 ~87 minecraft:light_gray_stained_glass
fill ~-61 ~2 ~84 ~-61 ~3 ~84 minecraft:gray_stained_glass
fill ~-56 ~2 ~84 ~-56 ~3 ~84 minecraft:light_gray_stained_glass
fill ~-59 ~6 ~82 ~-59 ~7 ~82 minecraft:gray_stained_glass
fill ~-59 ~6 ~87 ~-59 ~7 ~87 minecraft:light_gray_stained_glass
fill ~-61 ~6 ~84 ~-61 ~7 ~84 minecraft:gray_stained_glass
fill ~-56 ~6 ~84 ~-56 ~7 ~84 minecraft:light_gray_stained_glass
setblock ~-59 ~1 ~82 minecraft:iron_door[half=lower,facing=north]
setblock ~-59 ~2 ~82 minecraft:iron_door[half=upper,facing=north]
fill ~-61 ~7 ~82 ~-56 ~11 ~87 minecraft:air
fill ~-60 ~7 ~83 ~-57 ~11 ~86 minecraft:calcite
fill ~-59 ~8 ~84 ~-58 ~10 ~85 minecraft:air
fill ~-60 ~12 ~83 ~-57 ~12 ~86 minecraft:stone_brick_slab
# 227 garage style=loading_bay context=local_front facing=west
fill ~48 ~-3 ~53 ~52 ~-1 ~60 minecraft:stone
fill ~48 ~0 ~53 ~52 ~10 ~60 minecraft:stone_bricks
fill ~49 ~1 ~54 ~51 ~9 ~59 minecraft:air
fill ~49 ~4 ~54 ~51 ~4 ~59 minecraft:smooth_stone
fill ~49 ~8 ~54 ~51 ~8 ~59 minecraft:smooth_stone
fill ~50 ~2 ~53 ~50 ~3 ~53 minecraft:gray_stained_glass
fill ~50 ~2 ~60 ~50 ~3 ~60 minecraft:light_gray_stained_glass
fill ~48 ~2 ~55 ~48 ~3 ~55 minecraft:gray_stained_glass
fill ~52 ~2 ~55 ~52 ~3 ~55 minecraft:light_gray_stained_glass
fill ~48 ~2 ~58 ~48 ~3 ~58 minecraft:gray_stained_glass
fill ~52 ~2 ~58 ~52 ~3 ~58 minecraft:light_gray_stained_glass
fill ~50 ~6 ~53 ~50 ~7 ~53 minecraft:gray_stained_glass
fill ~50 ~6 ~60 ~50 ~7 ~60 minecraft:light_gray_stained_glass
fill ~48 ~6 ~55 ~48 ~7 ~55 minecraft:gray_stained_glass
fill ~52 ~6 ~55 ~52 ~7 ~55 minecraft:light_gray_stained_glass
fill ~48 ~6 ~58 ~48 ~7 ~58 minecraft:gray_stained_glass
fill ~52 ~6 ~58 ~52 ~7 ~58 minecraft:light_gray_stained_glass
setblock ~48 ~1 ~56 minecraft:iron_door[half=lower,facing=west]
setblock ~48 ~2 ~56 minecraft:iron_door[half=upper,facing=west]
fill ~48 ~1 ~55 ~48 ~4 ~58 minecraft:polished_blackstone
fill ~48 ~5 ~55 ~48 ~5 ~58 minecraft:light_blue_stained_glass
fill ~50 ~12 ~55 ~51 ~13 ~57 minecraft:iron_block
fill ~48 ~11 ~53 ~52 ~11 ~60 minecraft:stone_brick_slab
# 228 warehouse style=industrial_shed context=back_block facing=north
fill ~-123 ~-3 ~-126 ~-119 ~-1 ~-121 minecraft:stone
fill ~-123 ~0 ~-126 ~-119 ~6 ~-121 minecraft:bricks
fill ~-122 ~1 ~-125 ~-120 ~5 ~-122 minecraft:air
fill ~-122 ~4 ~-125 ~-120 ~4 ~-122 minecraft:smooth_stone
fill ~-121 ~2 ~-126 ~-121 ~3 ~-126 minecraft:gray_stained_glass
fill ~-121 ~2 ~-121 ~-121 ~3 ~-121 minecraft:light_gray_stained_glass
fill ~-123 ~2 ~-124 ~-123 ~3 ~-124 minecraft:gray_stained_glass
fill ~-119 ~2 ~-124 ~-119 ~3 ~-124 minecraft:light_gray_stained_glass
setblock ~-121 ~1 ~-126 minecraft:iron_door[half=lower,facing=north]
setblock ~-121 ~2 ~-126 minecraft:iron_door[half=upper,facing=north]
fill ~-121 ~1 ~-126 ~-121 ~4 ~-126 minecraft:polished_blackstone
fill ~-121 ~5 ~-126 ~-121 ~5 ~-126 minecraft:light_blue_stained_glass
fill ~-121 ~8 ~-124 ~-120 ~9 ~-122 minecraft:iron_block
fill ~-123 ~7 ~-126 ~-119 ~7 ~-121 minecraft:deepslate_tile_slab
# 229 office_tower style=civic_modern context=station_front facing=north
fill ~19 ~-3 ~-64 ~26 ~-1 ~-59 minecraft:stone
fill ~19 ~0 ~-64 ~26 ~5 ~-59 minecraft:light_gray_concrete
fill ~20 ~1 ~-63 ~25 ~4 ~-60 minecraft:air
fill ~20 ~4 ~-63 ~25 ~4 ~-60 minecraft:smooth_stone
fill ~21 ~2 ~-64 ~21 ~3 ~-64 minecraft:gray_stained_glass
fill ~21 ~2 ~-59 ~21 ~3 ~-59 minecraft:light_gray_stained_glass
fill ~24 ~2 ~-64 ~24 ~3 ~-64 minecraft:gray_stained_glass
fill ~24 ~2 ~-59 ~24 ~3 ~-59 minecraft:light_gray_stained_glass
fill ~19 ~2 ~-62 ~19 ~3 ~-62 minecraft:gray_stained_glass
fill ~26 ~2 ~-62 ~26 ~3 ~-62 minecraft:light_gray_stained_glass
setblock ~22 ~1 ~-64 minecraft:iron_door[half=lower,facing=north]
setblock ~22 ~2 ~-64 minecraft:iron_door[half=upper,facing=north]
# 230 office style=bay_office context=arterial_front facing=south
fill ~5 ~-3 ~78 ~9 ~-1 ~84 minecraft:stone
fill ~5 ~0 ~78 ~9 ~5 ~84 minecraft:smooth_sandstone
fill ~6 ~1 ~79 ~8 ~4 ~83 minecraft:air
fill ~6 ~4 ~79 ~8 ~4 ~83 minecraft:smooth_stone
fill ~7 ~2 ~78 ~7 ~3 ~78 minecraft:gray_stained_glass
fill ~7 ~2 ~84 ~7 ~3 ~84 minecraft:light_gray_stained_glass
fill ~5 ~2 ~80 ~5 ~3 ~80 minecraft:gray_stained_glass
fill ~9 ~2 ~80 ~9 ~3 ~80 minecraft:light_gray_stained_glass
setblock ~7 ~1 ~84 minecraft:iron_door[half=lower,facing=south]
setblock ~7 ~2 ~84 minecraft:iron_door[half=upper,facing=south]
# 231 workshop style=loading_bay context=back_block facing=west
fill ~-78 ~-3 ~41 ~-74 ~-1 ~46 minecraft:stone
fill ~-78 ~0 ~41 ~-74 ~7 ~46 minecraft:smooth_sandstone
fill ~-77 ~1 ~42 ~-75 ~6 ~45 minecraft:air
fill ~-77 ~4 ~42 ~-75 ~4 ~45 minecraft:smooth_stone
fill ~-76 ~2 ~41 ~-76 ~3 ~41 minecraft:gray_stained_glass
fill ~-76 ~2 ~46 ~-76 ~3 ~46 minecraft:light_gray_stained_glass
fill ~-78 ~2 ~43 ~-78 ~3 ~43 minecraft:gray_stained_glass
fill ~-74 ~2 ~43 ~-74 ~3 ~43 minecraft:light_gray_stained_glass
setblock ~-78 ~1 ~43 minecraft:iron_door[half=lower,facing=west]
setblock ~-78 ~2 ~43 minecraft:iron_door[half=upper,facing=west]
fill ~-78 ~1 ~43 ~-78 ~4 ~44 minecraft:polished_blackstone
fill ~-78 ~5 ~43 ~-78 ~5 ~44 minecraft:light_blue_stained_glass
fill ~-76 ~9 ~43 ~-75 ~10 ~45 minecraft:iron_block
fill ~-78 ~8 ~41 ~-74 ~8 ~46 minecraft:stone_brick_slab
# 232 shop_house style=corner_store context=collector_front facing=north
fill ~89 ~-3 ~32 ~93 ~-1 ~39 minecraft:stone
fill ~89 ~0 ~32 ~93 ~5 ~39 minecraft:calcite
fill ~90 ~1 ~33 ~92 ~4 ~38 minecraft:air
fill ~90 ~4 ~33 ~92 ~4 ~38 minecraft:smooth_stone
fill ~91 ~2 ~32 ~91 ~3 ~32 minecraft:gray_stained_glass
fill ~91 ~2 ~39 ~91 ~3 ~39 minecraft:light_gray_stained_glass
fill ~89 ~2 ~34 ~89 ~3 ~34 minecraft:gray_stained_glass
fill ~93 ~2 ~34 ~93 ~3 ~34 minecraft:light_gray_stained_glass
fill ~89 ~2 ~37 ~89 ~3 ~37 minecraft:gray_stained_glass
fill ~93 ~2 ~37 ~93 ~3 ~37 minecraft:light_gray_stained_glass
setblock ~91 ~1 ~32 minecraft:iron_door[half=lower,facing=north]
setblock ~91 ~2 ~32 minecraft:iron_door[half=upper,facing=north]
fill ~90 ~1 ~32 ~92 ~3 ~32 minecraft:cyan_stained_glass
setblock ~91 ~1 ~32 minecraft:iron_door[half=lower,facing=north]
setblock ~91 ~2 ~32 minecraft:iron_door[half=upper,facing=north]
setblock ~91 ~3 ~31 minecraft:red_wool
fill ~89 ~6 ~32 ~93 ~6 ~39 minecraft:stone_brick_slab
