# Buildings 226..246
# 226 shop_house -44,45 -40,50 h=9
fill ~-44 ~-3 ~45 ~-40 ~-1 ~50 minecraft:stone
fill ~-44 ~0 ~45 ~-40 ~9 ~50 minecraft:smooth_sandstone
fill ~-43 ~1 ~46 ~-41 ~8 ~49 minecraft:air
fill ~-43 ~4 ~46 ~-41 ~4 ~49 minecraft:smooth_stone
fill ~-43 ~8 ~46 ~-41 ~8 ~49 minecraft:smooth_stone
fill ~-44 ~2 ~47 ~-44 ~3 ~48 minecraft:gray_stained_glass
fill ~-40 ~2 ~47 ~-40 ~3 ~48 minecraft:light_gray_stained_glass
fill ~-44 ~6 ~47 ~-44 ~7 ~48 minecraft:gray_stained_glass
fill ~-40 ~6 ~47 ~-40 ~7 ~48 minecraft:light_gray_stained_glass
fill ~-43 ~0 ~45 ~-41 ~3 ~45 minecraft:brown_terracotta
setblock ~-42 ~1 ~45 minecraft:iron_door[half=lower,facing=north]
setblock ~-42 ~2 ~45 minecraft:iron_door[half=upper,facing=north]
fill ~-44 ~10 ~45 ~-40 ~10 ~50 minecraft:stone_brick_slab
# 227 detached_house 89,33 93,38 h=7
fill ~89 ~-3 ~33 ~93 ~-1 ~38 minecraft:stone
fill ~89 ~0 ~33 ~93 ~7 ~38 minecraft:mud_bricks
fill ~90 ~1 ~34 ~92 ~6 ~37 minecraft:air
fill ~90 ~4 ~34 ~92 ~4 ~37 minecraft:smooth_stone
fill ~89 ~2 ~35 ~89 ~3 ~36 minecraft:gray_stained_glass
fill ~93 ~2 ~35 ~93 ~3 ~36 minecraft:light_gray_stained_glass
fill ~90 ~0 ~33 ~92 ~3 ~33 minecraft:spruce_planks
setblock ~91 ~1 ~33 minecraft:iron_door[half=lower,facing=north]
setblock ~91 ~2 ~33 minecraft:iron_door[half=upper,facing=north]
fill ~89 ~8 ~33 ~93 ~8 ~38 minecraft:deepslate_tile_slab
# 228 logistics 45,45 49,50 h=6
fill ~45 ~-3 ~45 ~49 ~-1 ~50 minecraft:stone
fill ~45 ~0 ~45 ~49 ~6 ~50 minecraft:gray_concrete
fill ~46 ~1 ~46 ~48 ~5 ~49 minecraft:air
fill ~46 ~4 ~46 ~48 ~4 ~49 minecraft:smooth_stone
fill ~47 ~2 ~45 ~47 ~3 ~45 minecraft:gray_stained_glass
fill ~47 ~2 ~50 ~47 ~3 ~50 minecraft:light_gray_stained_glass
fill ~46 ~0 ~45 ~48 ~3 ~45 doomsday_decoration:ironsheetwall_1
setblock ~47 ~1 ~45 minecraft:iron_door[half=lower,facing=north]
setblock ~47 ~2 ~45 minecraft:iron_door[half=upper,facing=north]
fill ~45 ~7 ~45 ~49 ~7 ~50 minecraft:smooth_stone_slab
# 229 community -126,120 -122,125 h=7
fill ~-126 ~-3 ~120 ~-122 ~-1 ~125 minecraft:stone
fill ~-126 ~0 ~120 ~-122 ~7 ~125 minecraft:white_terracotta
fill ~-125 ~1 ~121 ~-123 ~6 ~124 minecraft:air
fill ~-125 ~4 ~121 ~-123 ~4 ~124 minecraft:smooth_stone
fill ~-126 ~2 ~122 ~-126 ~3 ~123 minecraft:gray_stained_glass
fill ~-122 ~2 ~122 ~-122 ~3 ~123 minecraft:light_gray_stained_glass
fill ~-125 ~0 ~120 ~-123 ~3 ~120 minecraft:dark_oak_planks
setblock ~-124 ~1 ~120 minecraft:iron_door[half=lower,facing=north]
setblock ~-124 ~2 ~120 minecraft:iron_door[half=upper,facing=north]
fill ~-126 ~8 ~120 ~-122 ~8 ~125 minecraft:dark_oak_slab
# 230 detached_house -126,81 -119,86 h=11
fill ~-126 ~-3 ~81 ~-119 ~-1 ~86 minecraft:stone
fill ~-126 ~0 ~81 ~-119 ~11 ~86 minecraft:mud_bricks
fill ~-125 ~1 ~82 ~-120 ~10 ~85 minecraft:air
fill ~-125 ~4 ~82 ~-120 ~4 ~85 minecraft:smooth_stone
fill ~-125 ~8 ~82 ~-120 ~8 ~85 minecraft:smooth_stone
fill ~-126 ~2 ~83 ~-126 ~3 ~84 minecraft:gray_stained_glass
fill ~-119 ~2 ~83 ~-119 ~3 ~84 minecraft:light_gray_stained_glass
fill ~-126 ~6 ~83 ~-126 ~7 ~84 minecraft:gray_stained_glass
fill ~-119 ~6 ~83 ~-119 ~7 ~84 minecraft:light_gray_stained_glass
fill ~-125 ~0 ~81 ~-122 ~3 ~81 minecraft:spruce_planks
setblock ~-124 ~1 ~81 minecraft:iron_door[half=lower,facing=north]
setblock ~-124 ~2 ~81 minecraft:iron_door[half=upper,facing=north]
fill ~-126 ~12 ~81 ~-119 ~12 ~86 minecraft:deepslate_tile_slab
# 231 office 73,-114 80,-108 h=6
fill ~73 ~-3 ~-114 ~80 ~-1 ~-108 minecraft:stone
fill ~73 ~0 ~-114 ~80 ~6 ~-108 minecraft:bricks
fill ~74 ~1 ~-113 ~79 ~5 ~-109 minecraft:air
fill ~74 ~4 ~-113 ~79 ~4 ~-109 minecraft:smooth_stone
fill ~75 ~2 ~-114 ~78 ~3 ~-114 minecraft:gray_stained_glass
fill ~75 ~2 ~-108 ~78 ~3 ~-108 minecraft:light_gray_stained_glass
fill ~74 ~0 ~-114 ~77 ~3 ~-114 minecraft:gray_concrete
setblock ~75 ~1 ~-114 minecraft:iron_door[half=lower,facing=north]
setblock ~75 ~2 ~-114 minecraft:iron_door[half=upper,facing=north]
fill ~73 ~7 ~-114 ~80 ~7 ~-108 minecraft:deepslate_tile_slab
# 232 retail -41,-35 -37,-27 h=12
fill ~-41 ~-3 ~-35 ~-37 ~-1 ~-27 minecraft:stone
fill ~-41 ~0 ~-35 ~-37 ~12 ~-27 minecraft:light_gray_concrete
fill ~-40 ~1 ~-34 ~-38 ~11 ~-28 minecraft:air
fill ~-40 ~4 ~-34 ~-38 ~4 ~-28 minecraft:smooth_stone
fill ~-40 ~8 ~-34 ~-38 ~8 ~-28 minecraft:smooth_stone
fill ~-39 ~2 ~-35 ~-39 ~3 ~-35 minecraft:gray_stained_glass
fill ~-39 ~2 ~-27 ~-39 ~3 ~-27 minecraft:light_gray_stained_glass
fill ~-39 ~6 ~-35 ~-39 ~7 ~-35 minecraft:gray_stained_glass
fill ~-39 ~6 ~-27 ~-39 ~7 ~-27 minecraft:light_gray_stained_glass
fill ~-39 ~10 ~-35 ~-39 ~11 ~-35 minecraft:gray_stained_glass
fill ~-39 ~10 ~-27 ~-39 ~11 ~-27 minecraft:light_gray_stained_glass
fill ~-40 ~0 ~-35 ~-38 ~3 ~-35 doomsday_decoration:cementwall
setblock ~-39 ~1 ~-35 minecraft:iron_door[half=lower,facing=north]
setblock ~-39 ~2 ~-35 minecraft:iron_door[half=upper,facing=north]
fill ~-41 ~13 ~-35 ~-37 ~13 ~-27 minecraft:smooth_stone_slab
# 233 small_office -3,-37 2,-31 h=12
fill ~-3 ~-3 ~-37 ~2 ~-1 ~-31 minecraft:stone
fill ~-3 ~0 ~-37 ~2 ~12 ~-31 minecraft:white_terracotta
fill ~-2 ~1 ~-36 ~1 ~11 ~-32 minecraft:air
fill ~-2 ~4 ~-36 ~1 ~4 ~-32 minecraft:smooth_stone
fill ~-2 ~8 ~-36 ~1 ~8 ~-32 minecraft:smooth_stone
fill ~-1 ~2 ~-37 ~0 ~3 ~-37 minecraft:gray_stained_glass
fill ~-1 ~2 ~-31 ~0 ~3 ~-31 minecraft:light_gray_stained_glass
fill ~-1 ~6 ~-37 ~0 ~7 ~-37 minecraft:gray_stained_glass
fill ~-1 ~6 ~-31 ~0 ~7 ~-31 minecraft:light_gray_stained_glass
fill ~-1 ~10 ~-37 ~0 ~11 ~-37 minecraft:gray_stained_glass
fill ~-1 ~10 ~-31 ~0 ~11 ~-31 minecraft:light_gray_stained_glass
fill ~-2 ~0 ~-37 ~1 ~3 ~-37 minecraft:gray_concrete
setblock ~-1 ~1 ~-37 minecraft:iron_door[half=lower,facing=north]
setblock ~-1 ~2 ~-37 minecraft:iron_door[half=upper,facing=north]
fill ~-3 ~13 ~-37 ~2 ~13 ~-31 minecraft:stone_brick_slab
# 234 warehouse 12,-126 18,-121 h=6
fill ~12 ~-3 ~-126 ~18 ~-1 ~-121 minecraft:stone
fill ~12 ~0 ~-126 ~18 ~6 ~-121 minecraft:stone_bricks
fill ~13 ~1 ~-125 ~17 ~5 ~-122 minecraft:air
fill ~13 ~4 ~-125 ~17 ~4 ~-122 minecraft:smooth_stone
fill ~12 ~2 ~-124 ~12 ~3 ~-123 minecraft:gray_stained_glass
fill ~18 ~2 ~-124 ~18 ~3 ~-123 minecraft:light_gray_stained_glass
fill ~13 ~0 ~-126 ~16 ~3 ~-126 doomsday_decoration:ironsheetwall_2
setblock ~14 ~1 ~-126 minecraft:iron_door[half=lower,facing=north]
setblock ~14 ~2 ~-126 minecraft:iron_door[half=upper,facing=north]
fill ~12 ~7 ~-126 ~18 ~7 ~-121 minecraft:smooth_stone_slab
# 235 restaurant -63,46 -58,52 h=7
fill ~-63 ~-3 ~46 ~-58 ~-1 ~52 minecraft:stone
fill ~-63 ~0 ~46 ~-58 ~7 ~52 minecraft:light_gray_concrete
fill ~-62 ~1 ~47 ~-59 ~6 ~51 minecraft:air
fill ~-62 ~4 ~47 ~-59 ~4 ~51 minecraft:smooth_stone
fill ~-63 ~2 ~48 ~-63 ~3 ~50 minecraft:gray_stained_glass
fill ~-58 ~2 ~48 ~-58 ~3 ~50 minecraft:light_gray_stained_glass
fill ~-62 ~0 ~46 ~-59 ~3 ~46 doomsday_decoration:porcelainbrickwall
setblock ~-61 ~1 ~46 minecraft:iron_door[half=lower,facing=north]
setblock ~-61 ~2 ~46 minecraft:iron_door[half=upper,facing=north]
fill ~-63 ~8 ~46 ~-58 ~8 ~52 minecraft:smooth_stone_slab
# 236 mixed_use -39,10 -33,16 h=10
fill ~-39 ~-3 ~10 ~-33 ~-1 ~16 minecraft:stone
fill ~-39 ~0 ~10 ~-33 ~10 ~16 minecraft:bricks
fill ~-38 ~1 ~11 ~-34 ~9 ~15 minecraft:air
fill ~-38 ~4 ~11 ~-34 ~4 ~15 minecraft:smooth_stone
fill ~-38 ~8 ~11 ~-34 ~8 ~15 minecraft:smooth_stone
fill ~-39 ~2 ~12 ~-39 ~3 ~14 minecraft:gray_stained_glass
fill ~-33 ~2 ~12 ~-33 ~3 ~14 minecraft:light_gray_stained_glass
fill ~-39 ~6 ~12 ~-39 ~7 ~14 minecraft:gray_stained_glass
fill ~-33 ~6 ~12 ~-33 ~7 ~14 minecraft:light_gray_stained_glass
fill ~-38 ~0 ~10 ~-35 ~3 ~10 doomsday_decoration:redbrick
setblock ~-37 ~1 ~10 minecraft:iron_door[half=lower,facing=north]
setblock ~-37 ~2 ~10 minecraft:iron_door[half=upper,facing=north]
fill ~-39 ~11 ~10 ~-33 ~11 ~16 minecraft:deepslate_tile_slab
# 237 utility 74,78 78,84 h=8
fill ~74 ~-3 ~78 ~78 ~-1 ~84 minecraft:stone
fill ~74 ~0 ~78 ~78 ~8 ~84 minecraft:deepslate_bricks
fill ~75 ~1 ~79 ~77 ~7 ~83 minecraft:air
fill ~75 ~4 ~79 ~77 ~4 ~83 minecraft:smooth_stone
fill ~76 ~2 ~78 ~76 ~3 ~78 minecraft:gray_stained_glass
fill ~76 ~2 ~84 ~76 ~3 ~84 minecraft:light_gray_stained_glass
fill ~76 ~6 ~78 ~76 ~7 ~78 minecraft:gray_stained_glass
fill ~76 ~6 ~84 ~76 ~7 ~84 minecraft:light_gray_stained_glass
fill ~75 ~0 ~78 ~77 ~3 ~78 minecraft:oxidized_cut_copper
setblock ~76 ~1 ~78 minecraft:iron_door[half=lower,facing=north]
setblock ~76 ~2 ~78 minecraft:iron_door[half=upper,facing=north]
fill ~74 ~9 ~78 ~78 ~9 ~84 minecraft:deepslate_tile_slab
# 238 retail -18,5 -12,10 h=16
fill ~-18 ~-3 ~5 ~-12 ~-1 ~10 minecraft:stone
fill ~-18 ~0 ~5 ~-12 ~16 ~10 minecraft:white_terracotta
fill ~-17 ~1 ~6 ~-13 ~15 ~9 minecraft:air
fill ~-17 ~4 ~6 ~-13 ~4 ~9 minecraft:smooth_stone
fill ~-17 ~8 ~6 ~-13 ~8 ~9 minecraft:smooth_stone
fill ~-17 ~12 ~6 ~-13 ~12 ~9 minecraft:smooth_stone
fill ~-16 ~2 ~5 ~-14 ~3 ~5 minecraft:gray_stained_glass
fill ~-16 ~2 ~10 ~-14 ~3 ~10 minecraft:light_gray_stained_glass
fill ~-16 ~6 ~5 ~-14 ~7 ~5 minecraft:gray_stained_glass
fill ~-16 ~6 ~10 ~-14 ~7 ~10 minecraft:light_gray_stained_glass
fill ~-16 ~10 ~5 ~-14 ~11 ~5 minecraft:gray_stained_glass
fill ~-16 ~10 ~10 ~-14 ~11 ~10 minecraft:light_gray_stained_glass
fill ~-16 ~14 ~5 ~-14 ~15 ~5 minecraft:gray_stained_glass
fill ~-16 ~14 ~10 ~-14 ~15 ~10 minecraft:light_gray_stained_glass
fill ~-17 ~0 ~5 ~-14 ~3 ~5 minecraft:gray_concrete
setblock ~-16 ~1 ~5 minecraft:iron_door[half=lower,facing=north]
setblock ~-16 ~2 ~5 minecraft:iron_door[half=upper,facing=north]
fill ~-18 ~17 ~5 ~-12 ~17 ~10 minecraft:stone_brick_slab
# 239 shop_house -50,-54 -46,-48 h=11
fill ~-50 ~-3 ~-54 ~-46 ~-1 ~-48 minecraft:stone
fill ~-50 ~0 ~-54 ~-46 ~11 ~-48 minecraft:smooth_sandstone
fill ~-49 ~1 ~-53 ~-47 ~10 ~-49 minecraft:air
fill ~-49 ~4 ~-53 ~-47 ~4 ~-49 minecraft:smooth_stone
fill ~-49 ~8 ~-53 ~-47 ~8 ~-49 minecraft:smooth_stone
fill ~-50 ~2 ~-52 ~-50 ~3 ~-50 minecraft:gray_stained_glass
fill ~-46 ~2 ~-52 ~-46 ~3 ~-50 minecraft:light_gray_stained_glass
fill ~-50 ~6 ~-52 ~-50 ~7 ~-50 minecraft:gray_stained_glass
fill ~-46 ~6 ~-52 ~-46 ~7 ~-50 minecraft:light_gray_stained_glass
fill ~-49 ~0 ~-54 ~-47 ~3 ~-54 minecraft:brown_terracotta
setblock ~-48 ~1 ~-54 minecraft:iron_door[half=lower,facing=north]
setblock ~-48 ~2 ~-54 minecraft:iron_door[half=upper,facing=north]
fill ~-50 ~12 ~-54 ~-46 ~12 ~-48 minecraft:stone_brick_slab
# 240 clinic -80,41 -73,46 h=5
fill ~-80 ~-3 ~41 ~-73 ~-1 ~46 minecraft:stone
fill ~-80 ~0 ~41 ~-73 ~5 ~46 minecraft:light_gray_concrete
fill ~-79 ~1 ~42 ~-74 ~4 ~45 minecraft:air
fill ~-79 ~4 ~42 ~-74 ~4 ~45 minecraft:smooth_stone
fill ~-80 ~2 ~43 ~-80 ~3 ~44 minecraft:gray_stained_glass
fill ~-73 ~2 ~43 ~-73 ~3 ~44 minecraft:light_gray_stained_glass
fill ~-79 ~0 ~41 ~-76 ~3 ~41 doomsday_decoration:porcelainbrickwall
setblock ~-78 ~1 ~41 minecraft:iron_door[half=lower,facing=north]
setblock ~-78 ~2 ~41 minecraft:iron_door[half=upper,facing=north]
fill ~-80 ~6 ~41 ~-73 ~6 ~46 minecraft:smooth_stone_slab
# 241 restaurant -62,-38 -58,-33 h=9
fill ~-62 ~-3 ~-38 ~-58 ~-1 ~-33 minecraft:stone
fill ~-62 ~0 ~-38 ~-58 ~9 ~-33 minecraft:light_gray_concrete
fill ~-61 ~1 ~-37 ~-59 ~8 ~-34 minecraft:air
fill ~-61 ~4 ~-37 ~-59 ~4 ~-34 minecraft:smooth_stone
fill ~-61 ~8 ~-37 ~-59 ~8 ~-34 minecraft:smooth_stone
fill ~-62 ~2 ~-36 ~-62 ~3 ~-35 minecraft:gray_stained_glass
fill ~-58 ~2 ~-36 ~-58 ~3 ~-35 minecraft:light_gray_stained_glass
fill ~-62 ~6 ~-36 ~-62 ~7 ~-35 minecraft:gray_stained_glass
fill ~-58 ~6 ~-36 ~-58 ~7 ~-35 minecraft:light_gray_stained_glass
fill ~-61 ~0 ~-38 ~-59 ~3 ~-38 doomsday_decoration:porcelainbrickwall
setblock ~-60 ~1 ~-38 minecraft:iron_door[half=lower,facing=north]
setblock ~-60 ~2 ~-38 minecraft:iron_door[half=upper,facing=north]
fill ~-62 ~10 ~-38 ~-58 ~10 ~-33 minecraft:smooth_stone_slab
# 242 market 96,-34 102,-28 h=11
fill ~96 ~-3 ~-34 ~102 ~-1 ~-28 minecraft:stone
fill ~96 ~0 ~-34 ~102 ~11 ~-28 minecraft:white_concrete
fill ~97 ~1 ~-33 ~101 ~10 ~-29 minecraft:air
fill ~97 ~4 ~-33 ~101 ~4 ~-29 minecraft:smooth_stone
fill ~97 ~8 ~-33 ~101 ~8 ~-29 minecraft:smooth_stone
fill ~98 ~2 ~-34 ~100 ~3 ~-34 minecraft:gray_stained_glass
fill ~98 ~2 ~-28 ~100 ~3 ~-28 minecraft:light_gray_stained_glass
fill ~98 ~6 ~-34 ~100 ~7 ~-34 minecraft:gray_stained_glass
fill ~98 ~6 ~-28 ~100 ~7 ~-28 minecraft:light_gray_stained_glass
fill ~97 ~0 ~-34 ~100 ~3 ~-34 minecraft:cyan_terracotta
setblock ~98 ~1 ~-34 minecraft:iron_door[half=lower,facing=north]
setblock ~98 ~2 ~-34 minecraft:iron_door[half=upper,facing=north]
fill ~96 ~12 ~-34 ~102 ~12 ~-28 minecraft:smooth_stone_slab
# 243 restaurant -36,69 -32,74 h=9
fill ~-36 ~-3 ~69 ~-32 ~-1 ~74 minecraft:stone
fill ~-36 ~0 ~69 ~-32 ~9 ~74 minecraft:smooth_sandstone
fill ~-35 ~1 ~70 ~-33 ~8 ~73 minecraft:air
fill ~-35 ~4 ~70 ~-33 ~4 ~73 minecraft:smooth_stone
fill ~-35 ~8 ~70 ~-33 ~8 ~73 minecraft:smooth_stone
fill ~-36 ~2 ~71 ~-36 ~3 ~72 minecraft:gray_stained_glass
fill ~-32 ~2 ~71 ~-32 ~3 ~72 minecraft:light_gray_stained_glass
fill ~-36 ~6 ~71 ~-36 ~7 ~72 minecraft:gray_stained_glass
fill ~-32 ~6 ~71 ~-32 ~7 ~72 minecraft:light_gray_stained_glass
fill ~-35 ~0 ~69 ~-33 ~3 ~69 minecraft:brown_terracotta
setblock ~-34 ~1 ~69 minecraft:iron_door[half=lower,facing=north]
setblock ~-34 ~2 ~69 minecraft:iron_door[half=upper,facing=north]
fill ~-36 ~10 ~69 ~-32 ~10 ~74 minecraft:stone_brick_slab
# 244 apartment 95,-61 99,-56 h=5
fill ~95 ~-3 ~-61 ~99 ~-1 ~-56 minecraft:stone
fill ~95 ~0 ~-61 ~99 ~5 ~-56 minecraft:white_concrete
fill ~96 ~1 ~-60 ~98 ~4 ~-57 minecraft:air
fill ~96 ~4 ~-60 ~98 ~4 ~-57 minecraft:smooth_stone
fill ~97 ~2 ~-61 ~97 ~3 ~-61 minecraft:gray_stained_glass
fill ~97 ~2 ~-56 ~97 ~3 ~-56 minecraft:light_gray_stained_glass
fill ~96 ~0 ~-61 ~98 ~3 ~-61 minecraft:cyan_terracotta
setblock ~97 ~1 ~-61 minecraft:iron_door[half=lower,facing=north]
setblock ~97 ~2 ~-61 minecraft:iron_door[half=upper,facing=north]
fill ~95 ~6 ~-61 ~99 ~6 ~-56 minecraft:smooth_stone_slab
# 245 shop_house 3,63 7,72 h=11
fill ~3 ~-3 ~63 ~7 ~-1 ~72 minecraft:stone
fill ~3 ~0 ~63 ~7 ~11 ~72 minecraft:smooth_sandstone
fill ~4 ~1 ~64 ~6 ~10 ~71 minecraft:air
fill ~4 ~4 ~64 ~6 ~4 ~71 minecraft:smooth_stone
fill ~4 ~8 ~64 ~6 ~8 ~71 minecraft:smooth_stone
fill ~3 ~2 ~65 ~3 ~3 ~70 minecraft:gray_stained_glass
fill ~7 ~2 ~65 ~7 ~3 ~70 minecraft:light_gray_stained_glass
fill ~3 ~6 ~65 ~3 ~7 ~70 minecraft:gray_stained_glass
fill ~7 ~6 ~65 ~7 ~7 ~70 minecraft:light_gray_stained_glass
fill ~4 ~0 ~63 ~6 ~3 ~63 minecraft:brown_terracotta
setblock ~5 ~1 ~63 minecraft:iron_door[half=lower,facing=north]
setblock ~5 ~2 ~63 minecraft:iron_door[half=upper,facing=north]
fill ~3 ~12 ~63 ~7 ~12 ~72 minecraft:stone_brick_slab
# 246 row_house -24,112 -20,119 h=11
fill ~-24 ~-3 ~112 ~-20 ~-1 ~119 minecraft:stone
fill ~-24 ~0 ~112 ~-20 ~11 ~119 minecraft:mud_bricks
fill ~-23 ~1 ~113 ~-21 ~10 ~118 minecraft:air
fill ~-23 ~4 ~113 ~-21 ~4 ~118 minecraft:smooth_stone
fill ~-23 ~8 ~113 ~-21 ~8 ~118 minecraft:smooth_stone
fill ~-24 ~2 ~114 ~-24 ~3 ~117 minecraft:gray_stained_glass
fill ~-20 ~2 ~114 ~-20 ~3 ~117 minecraft:light_gray_stained_glass
fill ~-24 ~6 ~114 ~-24 ~7 ~117 minecraft:gray_stained_glass
fill ~-20 ~6 ~114 ~-20 ~7 ~117 minecraft:light_gray_stained_glass
fill ~-23 ~0 ~112 ~-21 ~3 ~112 minecraft:spruce_planks
setblock ~-22 ~1 ~112 minecraft:iron_door[half=lower,facing=north]
setblock ~-22 ~2 ~112 minecraft:iron_door[half=upper,facing=north]
fill ~-24 ~12 ~112 ~-20 ~12 ~119 minecraft:deepslate_tile_slab
