# Buildings 177..184
# 177 supermarket style=storefront context=collector_front facing=east
fill ~-126 ~-3 ~5 ~-122 ~-1 ~13 minecraft:stone
fill ~-126 ~0 ~5 ~-122 ~11 ~13 minecraft:white_terracotta
fill ~-125 ~1 ~6 ~-123 ~10 ~12 minecraft:air
fill ~-125 ~4 ~6 ~-123 ~4 ~12 minecraft:smooth_stone
fill ~-125 ~8 ~6 ~-123 ~8 ~12 minecraft:smooth_stone
fill ~-124 ~2 ~5 ~-124 ~3 ~5 minecraft:gray_stained_glass
fill ~-124 ~2 ~13 ~-124 ~3 ~13 minecraft:light_gray_stained_glass
fill ~-126 ~2 ~7 ~-126 ~3 ~7 minecraft:gray_stained_glass
fill ~-122 ~2 ~7 ~-122 ~3 ~7 minecraft:light_gray_stained_glass
fill ~-126 ~2 ~10 ~-126 ~3 ~10 minecraft:gray_stained_glass
fill ~-122 ~2 ~10 ~-122 ~3 ~10 minecraft:light_gray_stained_glass
fill ~-124 ~6 ~5 ~-124 ~7 ~5 minecraft:gray_stained_glass
fill ~-124 ~6 ~13 ~-124 ~7 ~13 minecraft:light_gray_stained_glass
fill ~-126 ~6 ~7 ~-126 ~7 ~7 minecraft:gray_stained_glass
fill ~-122 ~6 ~7 ~-122 ~7 ~7 minecraft:light_gray_stained_glass
fill ~-126 ~6 ~10 ~-126 ~7 ~10 minecraft:gray_stained_glass
fill ~-122 ~6 ~10 ~-122 ~7 ~10 minecraft:light_gray_stained_glass
setblock ~-122 ~1 ~9 minecraft:iron_door[half=lower,facing=east]
setblock ~-122 ~2 ~9 minecraft:iron_door[half=upper,facing=east]
fill ~-122 ~1 ~6 ~-122 ~3 ~12 minecraft:cyan_stained_glass
setblock ~-122 ~1 ~9 minecraft:iron_door[half=lower,facing=east]
setblock ~-122 ~2 ~9 minecraft:iron_door[half=upper,facing=east]
setblock ~-121 ~3 ~9 minecraft:red_wool
fill ~-126 ~12 ~5 ~-122 ~12 ~13 minecraft:dark_oak_slab
fill ~-124 ~13 ~7 ~-123 ~14 ~9 minecraft:light_gray_concrete
setblock ~-123 ~13 ~8 minecraft:lightning_rod
# 178 small_office style=setback_tower context=back_block facing=north
fill ~-123 ~-3 ~118 ~-119 ~-1 ~125 minecraft:stone
fill ~-123 ~0 ~118 ~-119 ~7 ~125 minecraft:mud_bricks
fill ~-122 ~1 ~119 ~-120 ~6 ~124 minecraft:air
fill ~-122 ~4 ~119 ~-120 ~4 ~124 minecraft:smooth_stone
fill ~-121 ~2 ~118 ~-121 ~3 ~118 minecraft:gray_stained_glass
fill ~-121 ~2 ~125 ~-121 ~3 ~125 minecraft:light_gray_stained_glass
fill ~-123 ~2 ~120 ~-123 ~3 ~120 minecraft:gray_stained_glass
fill ~-119 ~2 ~120 ~-119 ~3 ~120 minecraft:light_gray_stained_glass
fill ~-123 ~2 ~123 ~-123 ~3 ~123 minecraft:gray_stained_glass
fill ~-119 ~2 ~123 ~-119 ~3 ~123 minecraft:light_gray_stained_glass
setblock ~-121 ~1 ~118 minecraft:iron_door[half=lower,facing=north]
setblock ~-121 ~2 ~118 minecraft:iron_door[half=upper,facing=north]
# 179 utility style=loading_bay context=back_block facing=west
fill ~50 ~-3 ~45 ~56 ~-1 ~51 minecraft:stone
fill ~50 ~0 ~45 ~56 ~8 ~51 minecraft:deepslate_bricks
fill ~51 ~1 ~46 ~55 ~7 ~50 minecraft:air
fill ~51 ~4 ~46 ~55 ~4 ~50 minecraft:smooth_stone
fill ~52 ~2 ~45 ~52 ~3 ~45 minecraft:gray_stained_glass
fill ~52 ~2 ~51 ~52 ~3 ~51 minecraft:light_gray_stained_glass
fill ~50 ~2 ~47 ~50 ~3 ~47 minecraft:gray_stained_glass
fill ~56 ~2 ~47 ~56 ~3 ~47 minecraft:light_gray_stained_glass
fill ~52 ~6 ~45 ~52 ~7 ~45 minecraft:gray_stained_glass
fill ~52 ~6 ~51 ~52 ~7 ~51 minecraft:light_gray_stained_glass
fill ~50 ~6 ~47 ~50 ~7 ~47 minecraft:gray_stained_glass
fill ~56 ~6 ~47 ~56 ~7 ~47 minecraft:light_gray_stained_glass
setblock ~50 ~1 ~48 minecraft:iron_door[half=lower,facing=west]
setblock ~50 ~2 ~48 minecraft:iron_door[half=upper,facing=west]
fill ~50 ~1 ~47 ~50 ~4 ~49 minecraft:polished_blackstone
fill ~50 ~5 ~47 ~50 ~5 ~49 minecraft:light_blue_stained_glass
fill ~52 ~10 ~47 ~54 ~11 ~49 minecraft:iron_block
fill ~50 ~9 ~45 ~56 ~9 ~51 minecraft:deepslate_tile_slab
# 180 warehouse style=sawtooth context=waterfront_front facing=north
fill ~86 ~-3 ~120 ~90 ~-1 ~125 minecraft:stone
fill ~86 ~0 ~120 ~90 ~10 ~125 minecraft:stone_bricks
fill ~87 ~1 ~121 ~89 ~9 ~124 minecraft:air
fill ~87 ~4 ~121 ~89 ~4 ~124 minecraft:smooth_stone
fill ~87 ~8 ~121 ~89 ~8 ~124 minecraft:smooth_stone
fill ~88 ~2 ~120 ~88 ~3 ~120 minecraft:gray_stained_glass
fill ~88 ~2 ~125 ~88 ~3 ~125 minecraft:light_gray_stained_glass
fill ~86 ~2 ~122 ~86 ~3 ~122 minecraft:gray_stained_glass
fill ~90 ~2 ~122 ~90 ~3 ~122 minecraft:light_gray_stained_glass
fill ~88 ~6 ~120 ~88 ~7 ~120 minecraft:gray_stained_glass
fill ~88 ~6 ~125 ~88 ~7 ~125 minecraft:light_gray_stained_glass
fill ~86 ~6 ~122 ~86 ~7 ~122 minecraft:gray_stained_glass
fill ~90 ~6 ~122 ~90 ~7 ~122 minecraft:light_gray_stained_glass
setblock ~88 ~1 ~120 minecraft:iron_door[half=lower,facing=north]
setblock ~88 ~2 ~120 minecraft:iron_door[half=upper,facing=north]
fill ~88 ~1 ~120 ~88 ~4 ~120 minecraft:polished_blackstone
fill ~88 ~5 ~120 ~88 ~5 ~120 minecraft:light_blue_stained_glass
fill ~88 ~12 ~122 ~89 ~13 ~124 minecraft:iron_block
fill ~86 ~11 ~120 ~90 ~11 ~125 minecraft:stone_brick_slab
fill ~88 ~12 ~122 ~89 ~13 ~124 minecraft:light_gray_concrete
setblock ~89 ~12 ~123 minecraft:lightning_rod
# 181 utility style=sawtooth context=local_front facing=east
fill ~-125 ~-3 ~-119 ~-119 ~-1 ~-111 minecraft:stone
fill ~-125 ~0 ~-119 ~-119 ~8 ~-111 minecraft:stone_bricks
fill ~-124 ~1 ~-118 ~-120 ~7 ~-112 minecraft:air
fill ~-124 ~4 ~-118 ~-120 ~4 ~-112 minecraft:smooth_stone
fill ~-123 ~2 ~-119 ~-123 ~3 ~-119 minecraft:gray_stained_glass
fill ~-123 ~2 ~-111 ~-123 ~3 ~-111 minecraft:light_gray_stained_glass
fill ~-125 ~2 ~-117 ~-125 ~3 ~-117 minecraft:gray_stained_glass
fill ~-119 ~2 ~-117 ~-119 ~3 ~-117 minecraft:light_gray_stained_glass
fill ~-125 ~2 ~-114 ~-125 ~3 ~-114 minecraft:gray_stained_glass
fill ~-119 ~2 ~-114 ~-119 ~3 ~-114 minecraft:light_gray_stained_glass
fill ~-123 ~6 ~-119 ~-123 ~7 ~-119 minecraft:gray_stained_glass
fill ~-123 ~6 ~-111 ~-123 ~7 ~-111 minecraft:light_gray_stained_glass
fill ~-125 ~6 ~-117 ~-125 ~7 ~-117 minecraft:gray_stained_glass
fill ~-119 ~6 ~-117 ~-119 ~7 ~-117 minecraft:light_gray_stained_glass
fill ~-125 ~6 ~-114 ~-125 ~7 ~-114 minecraft:gray_stained_glass
fill ~-119 ~6 ~-114 ~-119 ~7 ~-114 minecraft:light_gray_stained_glass
setblock ~-119 ~1 ~-115 minecraft:iron_door[half=lower,facing=east]
setblock ~-119 ~2 ~-115 minecraft:iron_door[half=upper,facing=east]
fill ~-119 ~1 ~-117 ~-119 ~4 ~-113 minecraft:polished_blackstone
fill ~-119 ~5 ~-117 ~-119 ~5 ~-113 minecraft:light_blue_stained_glass
fill ~-123 ~10 ~-117 ~-121 ~11 ~-115 minecraft:iron_block
fill ~-125 ~9 ~-119 ~-119 ~9 ~-111 minecraft:smooth_stone_slab
# 182 small_office style=civic_modern context=back_block facing=west
fill ~71 ~-3 ~-44 ~77 ~-1 ~-39 minecraft:stone
fill ~71 ~0 ~-44 ~77 ~5 ~-39 minecraft:light_gray_concrete
fill ~72 ~1 ~-43 ~76 ~4 ~-40 minecraft:air
fill ~72 ~4 ~-43 ~76 ~4 ~-40 minecraft:smooth_stone
fill ~73 ~2 ~-44 ~73 ~3 ~-44 minecraft:gray_stained_glass
fill ~73 ~2 ~-39 ~73 ~3 ~-39 minecraft:light_gray_stained_glass
fill ~71 ~2 ~-42 ~71 ~3 ~-42 minecraft:gray_stained_glass
fill ~77 ~2 ~-42 ~77 ~3 ~-42 minecraft:light_gray_stained_glass
setblock ~71 ~1 ~-42 minecraft:iron_door[half=lower,facing=west]
setblock ~71 ~2 ~-42 minecraft:iron_door[half=upper,facing=west]
# 183 small_office style=civic_modern context=back_block facing=east
fill ~-79 ~-3 ~106 ~-72 ~-1 ~111 minecraft:stone
fill ~-79 ~0 ~106 ~-72 ~9 ~111 minecraft:calcite
fill ~-78 ~1 ~107 ~-73 ~8 ~110 minecraft:air
fill ~-78 ~4 ~107 ~-73 ~4 ~110 minecraft:smooth_stone
fill ~-78 ~8 ~107 ~-73 ~8 ~110 minecraft:smooth_stone
fill ~-77 ~2 ~106 ~-77 ~3 ~106 minecraft:gray_stained_glass
fill ~-77 ~2 ~111 ~-77 ~3 ~111 minecraft:light_gray_stained_glass
fill ~-74 ~2 ~106 ~-74 ~3 ~106 minecraft:gray_stained_glass
fill ~-74 ~2 ~111 ~-74 ~3 ~111 minecraft:light_gray_stained_glass
fill ~-79 ~2 ~108 ~-79 ~3 ~108 minecraft:gray_stained_glass
fill ~-72 ~2 ~108 ~-72 ~3 ~108 minecraft:light_gray_stained_glass
fill ~-77 ~6 ~106 ~-77 ~7 ~106 minecraft:gray_stained_glass
fill ~-77 ~6 ~111 ~-77 ~7 ~111 minecraft:light_gray_stained_glass
fill ~-74 ~6 ~106 ~-74 ~7 ~106 minecraft:gray_stained_glass
fill ~-74 ~6 ~111 ~-74 ~7 ~111 minecraft:light_gray_stained_glass
fill ~-79 ~6 ~108 ~-79 ~7 ~108 minecraft:gray_stained_glass
fill ~-72 ~6 ~108 ~-72 ~7 ~108 minecraft:light_gray_stained_glass
setblock ~-72 ~1 ~108 minecraft:iron_door[half=lower,facing=east]
setblock ~-72 ~2 ~108 minecraft:iron_door[half=upper,facing=east]
fill ~-77 ~11 ~108 ~-75 ~12 ~110 minecraft:light_gray_concrete
setblock ~-74 ~11 ~109 minecraft:lightning_rod
# 184 logistics style=loading_bay context=local_front facing=west
fill ~-84 ~-3 ~-90 ~-80 ~-1 ~-80 minecraft:stone
fill ~-84 ~0 ~-90 ~-80 ~6 ~-80 minecraft:bricks
fill ~-83 ~1 ~-89 ~-81 ~5 ~-81 minecraft:air
fill ~-83 ~4 ~-89 ~-81 ~4 ~-81 minecraft:smooth_stone
fill ~-82 ~2 ~-90 ~-82 ~3 ~-90 minecraft:gray_stained_glass
fill ~-82 ~2 ~-80 ~-82 ~3 ~-80 minecraft:light_gray_stained_glass
fill ~-84 ~2 ~-88 ~-84 ~3 ~-88 minecraft:gray_stained_glass
fill ~-80 ~2 ~-88 ~-80 ~3 ~-88 minecraft:light_gray_stained_glass
fill ~-84 ~2 ~-85 ~-84 ~3 ~-85 minecraft:gray_stained_glass
fill ~-80 ~2 ~-85 ~-80 ~3 ~-85 minecraft:light_gray_stained_glass
fill ~-84 ~2 ~-82 ~-84 ~3 ~-82 minecraft:gray_stained_glass
fill ~-80 ~2 ~-82 ~-80 ~3 ~-82 minecraft:light_gray_stained_glass
setblock ~-84 ~1 ~-85 minecraft:iron_door[half=lower,facing=west]
setblock ~-84 ~2 ~-85 minecraft:iron_door[half=upper,facing=west]
fill ~-84 ~1 ~-88 ~-84 ~4 ~-82 minecraft:polished_blackstone
fill ~-84 ~5 ~-88 ~-84 ~5 ~-82 minecraft:light_blue_stained_glass
fill ~-82 ~8 ~-88 ~-81 ~9 ~-86 minecraft:iron_block
fill ~-84 ~7 ~-90 ~-80 ~7 ~-80 minecraft:deepslate_tile_slab
