# Buildings 73..80
# 073 utility style=industrial_shed context=local_front facing=west
fill ~-61 ~-3 ~-125 ~-43 ~-1 ~-116 minecraft:stone
fill ~-61 ~0 ~-125 ~-43 ~6 ~-116 minecraft:bricks
fill ~-60 ~1 ~-124 ~-44 ~5 ~-117 minecraft:air
fill ~-60 ~4 ~-124 ~-44 ~4 ~-117 minecraft:smooth_stone
fill ~-59 ~2 ~-125 ~-59 ~3 ~-125 minecraft:gray_stained_glass
fill ~-59 ~2 ~-116 ~-59 ~3 ~-116 minecraft:light_gray_stained_glass
fill ~-56 ~2 ~-125 ~-56 ~3 ~-125 minecraft:gray_stained_glass
fill ~-56 ~2 ~-116 ~-56 ~3 ~-116 minecraft:light_gray_stained_glass
fill ~-53 ~2 ~-125 ~-53 ~3 ~-125 minecraft:gray_stained_glass
fill ~-53 ~2 ~-116 ~-53 ~3 ~-116 minecraft:light_gray_stained_glass
fill ~-50 ~2 ~-125 ~-50 ~3 ~-125 minecraft:gray_stained_glass
fill ~-50 ~2 ~-116 ~-50 ~3 ~-116 minecraft:light_gray_stained_glass
fill ~-47 ~2 ~-125 ~-47 ~3 ~-125 minecraft:gray_stained_glass
fill ~-47 ~2 ~-116 ~-47 ~3 ~-116 minecraft:light_gray_stained_glass
fill ~-61 ~2 ~-123 ~-61 ~3 ~-123 minecraft:gray_stained_glass
fill ~-43 ~2 ~-123 ~-43 ~3 ~-123 minecraft:light_gray_stained_glass
fill ~-61 ~2 ~-120 ~-61 ~3 ~-120 minecraft:gray_stained_glass
fill ~-43 ~2 ~-120 ~-43 ~3 ~-120 minecraft:light_gray_stained_glass
setblock ~-61 ~1 ~-121 minecraft:iron_door[half=lower,facing=west]
setblock ~-61 ~2 ~-121 minecraft:iron_door[half=upper,facing=west]
fill ~-61 ~1 ~-123 ~-61 ~4 ~-118 minecraft:polished_blackstone
fill ~-61 ~5 ~-123 ~-61 ~5 ~-118 minecraft:light_blue_stained_glass
fill ~-59 ~8 ~-123 ~-57 ~9 ~-121 minecraft:iron_block
fill ~-61 ~7 ~-125 ~-43 ~7 ~-116 minecraft:deepslate_tile_slab
# 074 detached_house style=japanese_house context=local_front facing=west
fill ~-98 ~-3 ~104 ~-93 ~-1 ~110 minecraft:stone
fill ~-98 ~0 ~104 ~-93 ~11 ~110 minecraft:mud_bricks
fill ~-97 ~1 ~105 ~-94 ~10 ~109 minecraft:air
fill ~-97 ~4 ~105 ~-94 ~4 ~109 minecraft:smooth_stone
fill ~-97 ~8 ~105 ~-94 ~8 ~109 minecraft:smooth_stone
fill ~-96 ~2 ~104 ~-96 ~3 ~104 minecraft:gray_stained_glass
fill ~-96 ~2 ~110 ~-96 ~3 ~110 minecraft:light_gray_stained_glass
fill ~-98 ~2 ~106 ~-98 ~3 ~106 minecraft:gray_stained_glass
fill ~-93 ~2 ~106 ~-93 ~3 ~106 minecraft:light_gray_stained_glass
fill ~-96 ~6 ~104 ~-96 ~7 ~104 minecraft:gray_stained_glass
fill ~-96 ~6 ~110 ~-96 ~7 ~110 minecraft:light_gray_stained_glass
fill ~-98 ~6 ~106 ~-98 ~7 ~106 minecraft:gray_stained_glass
fill ~-93 ~6 ~106 ~-93 ~7 ~106 minecraft:light_gray_stained_glass
setblock ~-98 ~1 ~107 minecraft:iron_door[half=lower,facing=west]
setblock ~-98 ~2 ~107 minecraft:iron_door[half=upper,facing=west]
fill ~-98 ~12 ~104 ~-93 ~12 ~110 minecraft:deepslate_tile_slab
fill ~-97 ~13 ~105 ~-94 ~13 ~109 minecraft:deepslate_tile_slab
setblock ~-99 ~3 ~107 minecraft:dark_oak_slab[type=top]
# 075 workshop style=sawtooth context=back_block facing=north
fill ~47 ~-3 ~32 ~53 ~-1 ~43 minecraft:stone
fill ~47 ~0 ~32 ~53 ~16 ~43 minecraft:bricks
fill ~48 ~1 ~33 ~52 ~15 ~42 minecraft:air
fill ~48 ~4 ~33 ~52 ~4 ~42 minecraft:smooth_stone
fill ~48 ~8 ~33 ~52 ~8 ~42 minecraft:smooth_stone
fill ~48 ~12 ~33 ~52 ~12 ~42 minecraft:smooth_stone
fill ~49 ~2 ~32 ~49 ~3 ~32 minecraft:gray_stained_glass
fill ~49 ~2 ~43 ~49 ~3 ~43 minecraft:light_gray_stained_glass
fill ~47 ~2 ~34 ~47 ~3 ~34 minecraft:gray_stained_glass
fill ~53 ~2 ~34 ~53 ~3 ~34 minecraft:light_gray_stained_glass
fill ~47 ~2 ~37 ~47 ~3 ~37 minecraft:gray_stained_glass
fill ~53 ~2 ~37 ~53 ~3 ~37 minecraft:light_gray_stained_glass
fill ~47 ~2 ~40 ~47 ~3 ~40 minecraft:gray_stained_glass
fill ~53 ~2 ~40 ~53 ~3 ~40 minecraft:light_gray_stained_glass
fill ~49 ~6 ~32 ~49 ~7 ~32 minecraft:gray_stained_glass
fill ~49 ~6 ~43 ~49 ~7 ~43 minecraft:light_gray_stained_glass
fill ~47 ~6 ~34 ~47 ~7 ~34 minecraft:gray_stained_glass
fill ~53 ~6 ~34 ~53 ~7 ~34 minecraft:light_gray_stained_glass
fill ~47 ~6 ~37 ~47 ~7 ~37 minecraft:gray_stained_glass
fill ~53 ~6 ~37 ~53 ~7 ~37 minecraft:light_gray_stained_glass
fill ~47 ~6 ~40 ~47 ~7 ~40 minecraft:gray_stained_glass
fill ~53 ~6 ~40 ~53 ~7 ~40 minecraft:light_gray_stained_glass
fill ~49 ~10 ~32 ~49 ~11 ~32 minecraft:gray_stained_glass
fill ~49 ~10 ~43 ~49 ~11 ~43 minecraft:light_gray_stained_glass
fill ~47 ~10 ~34 ~47 ~11 ~34 minecraft:gray_stained_glass
fill ~53 ~10 ~34 ~53 ~11 ~34 minecraft:light_gray_stained_glass
fill ~47 ~10 ~37 ~47 ~11 ~37 minecraft:gray_stained_glass
fill ~53 ~10 ~37 ~53 ~11 ~37 minecraft:light_gray_stained_glass
fill ~47 ~10 ~40 ~47 ~11 ~40 minecraft:gray_stained_glass
fill ~53 ~10 ~40 ~53 ~11 ~40 minecraft:light_gray_stained_glass
fill ~49 ~14 ~32 ~49 ~15 ~32 minecraft:gray_stained_glass
fill ~49 ~14 ~43 ~49 ~15 ~43 minecraft:light_gray_stained_glass
fill ~47 ~14 ~34 ~47 ~15 ~34 minecraft:gray_stained_glass
fill ~53 ~14 ~34 ~53 ~15 ~34 minecraft:light_gray_stained_glass
fill ~47 ~14 ~37 ~47 ~15 ~37 minecraft:gray_stained_glass
fill ~53 ~14 ~37 ~53 ~15 ~37 minecraft:light_gray_stained_glass
fill ~47 ~14 ~40 ~47 ~15 ~40 minecraft:gray_stained_glass
fill ~53 ~14 ~40 ~53 ~15 ~40 minecraft:light_gray_stained_glass
setblock ~50 ~1 ~32 minecraft:iron_door[half=lower,facing=north]
setblock ~50 ~2 ~32 minecraft:iron_door[half=upper,facing=north]
fill ~49 ~1 ~32 ~51 ~4 ~32 minecraft:polished_blackstone
fill ~49 ~5 ~32 ~51 ~5 ~32 minecraft:light_blue_stained_glass
fill ~49 ~18 ~34 ~51 ~19 ~36 minecraft:iron_block
fill ~47 ~17 ~32 ~53 ~17 ~43 minecraft:deepslate_tile_slab
fill ~49 ~18 ~34 ~51 ~19 ~36 minecraft:light_gray_concrete
setblock ~52 ~18 ~35 minecraft:lightning_rod
# 076 station_department_store style=civic_modern context=station_front facing=north
fill ~38 ~-3 ~-67 ~45 ~-1 ~-52 minecraft:stone
fill ~38 ~0 ~-67 ~45 ~12 ~-52 minecraft:bricks
fill ~39 ~1 ~-66 ~44 ~11 ~-53 minecraft:air
fill ~39 ~4 ~-66 ~44 ~4 ~-53 minecraft:smooth_stone
fill ~39 ~8 ~-66 ~44 ~8 ~-53 minecraft:smooth_stone
fill ~40 ~2 ~-67 ~40 ~3 ~-67 minecraft:gray_stained_glass
fill ~40 ~2 ~-52 ~40 ~3 ~-52 minecraft:light_gray_stained_glass
fill ~43 ~2 ~-67 ~43 ~3 ~-67 minecraft:gray_stained_glass
fill ~43 ~2 ~-52 ~43 ~3 ~-52 minecraft:light_gray_stained_glass
fill ~38 ~2 ~-65 ~38 ~3 ~-65 minecraft:gray_stained_glass
fill ~45 ~2 ~-65 ~45 ~3 ~-65 minecraft:light_gray_stained_glass
fill ~38 ~2 ~-62 ~38 ~3 ~-62 minecraft:gray_stained_glass
fill ~45 ~2 ~-62 ~45 ~3 ~-62 minecraft:light_gray_stained_glass
fill ~38 ~2 ~-59 ~38 ~3 ~-59 minecraft:gray_stained_glass
fill ~45 ~2 ~-59 ~45 ~3 ~-59 minecraft:light_gray_stained_glass
fill ~38 ~2 ~-56 ~38 ~3 ~-56 minecraft:gray_stained_glass
fill ~45 ~2 ~-56 ~45 ~3 ~-56 minecraft:light_gray_stained_glass
fill ~40 ~6 ~-67 ~40 ~7 ~-67 minecraft:gray_stained_glass
fill ~40 ~6 ~-52 ~40 ~7 ~-52 minecraft:light_gray_stained_glass
fill ~43 ~6 ~-67 ~43 ~7 ~-67 minecraft:gray_stained_glass
fill ~43 ~6 ~-52 ~43 ~7 ~-52 minecraft:light_gray_stained_glass
fill ~38 ~6 ~-65 ~38 ~7 ~-65 minecraft:gray_stained_glass
fill ~45 ~6 ~-65 ~45 ~7 ~-65 minecraft:light_gray_stained_glass
fill ~38 ~6 ~-62 ~38 ~7 ~-62 minecraft:gray_stained_glass
fill ~45 ~6 ~-62 ~45 ~7 ~-62 minecraft:light_gray_stained_glass
fill ~38 ~6 ~-59 ~38 ~7 ~-59 minecraft:gray_stained_glass
fill ~45 ~6 ~-59 ~45 ~7 ~-59 minecraft:light_gray_stained_glass
fill ~38 ~6 ~-56 ~38 ~7 ~-56 minecraft:gray_stained_glass
fill ~45 ~6 ~-56 ~45 ~7 ~-56 minecraft:light_gray_stained_glass
fill ~40 ~10 ~-67 ~40 ~11 ~-67 minecraft:gray_stained_glass
fill ~40 ~10 ~-52 ~40 ~11 ~-52 minecraft:light_gray_stained_glass
fill ~43 ~10 ~-67 ~43 ~11 ~-67 minecraft:gray_stained_glass
fill ~43 ~10 ~-52 ~43 ~11 ~-52 minecraft:light_gray_stained_glass
fill ~38 ~10 ~-65 ~38 ~11 ~-65 minecraft:gray_stained_glass
fill ~45 ~10 ~-65 ~45 ~11 ~-65 minecraft:light_gray_stained_glass
fill ~38 ~10 ~-62 ~38 ~11 ~-62 minecraft:gray_stained_glass
fill ~45 ~10 ~-62 ~45 ~11 ~-62 minecraft:light_gray_stained_glass
fill ~38 ~10 ~-59 ~38 ~11 ~-59 minecraft:gray_stained_glass
fill ~45 ~10 ~-59 ~45 ~11 ~-59 minecraft:light_gray_stained_glass
fill ~38 ~10 ~-56 ~38 ~11 ~-56 minecraft:gray_stained_glass
fill ~45 ~10 ~-56 ~45 ~11 ~-56 minecraft:light_gray_stained_glass
setblock ~41 ~1 ~-67 minecraft:iron_door[half=lower,facing=north]
setblock ~41 ~2 ~-67 minecraft:iron_door[half=upper,facing=north]
fill ~38 ~7 ~-67 ~45 ~12 ~-52 minecraft:air
fill ~39 ~7 ~-66 ~44 ~12 ~-53 minecraft:bricks
fill ~40 ~8 ~-65 ~43 ~11 ~-54 minecraft:air
fill ~39 ~13 ~-66 ~44 ~13 ~-53 minecraft:deepslate_tile_slab
# 077 detached_house style=japanese_house context=back_block facing=north
fill ~-12 ~-3 ~105 ~-5 ~-1 ~115 minecraft:stone
fill ~-12 ~0 ~105 ~-5 ~9 ~115 minecraft:mud_bricks
fill ~-11 ~1 ~106 ~-6 ~8 ~114 minecraft:air
fill ~-11 ~4 ~106 ~-6 ~4 ~114 minecraft:smooth_stone
fill ~-11 ~8 ~106 ~-6 ~8 ~114 minecraft:smooth_stone
fill ~-10 ~2 ~105 ~-10 ~3 ~105 minecraft:gray_stained_glass
fill ~-10 ~2 ~115 ~-10 ~3 ~115 minecraft:light_gray_stained_glass
fill ~-7 ~2 ~105 ~-7 ~3 ~105 minecraft:gray_stained_glass
fill ~-7 ~2 ~115 ~-7 ~3 ~115 minecraft:light_gray_stained_glass
fill ~-12 ~2 ~107 ~-12 ~3 ~107 minecraft:gray_stained_glass
fill ~-5 ~2 ~107 ~-5 ~3 ~107 minecraft:light_gray_stained_glass
fill ~-12 ~2 ~110 ~-12 ~3 ~110 minecraft:gray_stained_glass
fill ~-5 ~2 ~110 ~-5 ~3 ~110 minecraft:light_gray_stained_glass
fill ~-12 ~2 ~113 ~-12 ~3 ~113 minecraft:gray_stained_glass
fill ~-5 ~2 ~113 ~-5 ~3 ~113 minecraft:light_gray_stained_glass
fill ~-10 ~6 ~105 ~-10 ~7 ~105 minecraft:gray_stained_glass
fill ~-10 ~6 ~115 ~-10 ~7 ~115 minecraft:light_gray_stained_glass
fill ~-7 ~6 ~105 ~-7 ~7 ~105 minecraft:gray_stained_glass
fill ~-7 ~6 ~115 ~-7 ~7 ~115 minecraft:light_gray_stained_glass
fill ~-12 ~6 ~107 ~-12 ~7 ~107 minecraft:gray_stained_glass
fill ~-5 ~6 ~107 ~-5 ~7 ~107 minecraft:light_gray_stained_glass
fill ~-12 ~6 ~110 ~-12 ~7 ~110 minecraft:gray_stained_glass
fill ~-5 ~6 ~110 ~-5 ~7 ~110 minecraft:light_gray_stained_glass
fill ~-12 ~6 ~113 ~-12 ~7 ~113 minecraft:gray_stained_glass
fill ~-5 ~6 ~113 ~-5 ~7 ~113 minecraft:light_gray_stained_glass
setblock ~-9 ~1 ~105 minecraft:iron_door[half=lower,facing=north]
setblock ~-9 ~2 ~105 minecraft:iron_door[half=upper,facing=north]
fill ~-12 ~10 ~105 ~-5 ~10 ~115 minecraft:deepslate_tile_slab
fill ~-11 ~11 ~106 ~-6 ~11 ~114 minecraft:deepslate_tile_slab
setblock ~-9 ~3 ~104 minecraft:dark_oak_slab[type=top]
# 078 detached_house style=stepped_house context=back_block facing=north
fill ~79 ~-3 ~-54 ~84 ~-1 ~-48 minecraft:stone
fill ~79 ~0 ~-54 ~84 ~11 ~-48 minecraft:calcite
fill ~80 ~1 ~-53 ~83 ~10 ~-49 minecraft:air
fill ~80 ~4 ~-53 ~83 ~4 ~-49 minecraft:smooth_stone
fill ~80 ~8 ~-53 ~83 ~8 ~-49 minecraft:smooth_stone
fill ~81 ~2 ~-54 ~81 ~3 ~-54 minecraft:gray_stained_glass
fill ~81 ~2 ~-48 ~81 ~3 ~-48 minecraft:light_gray_stained_glass
fill ~79 ~2 ~-52 ~79 ~3 ~-52 minecraft:gray_stained_glass
fill ~84 ~2 ~-52 ~84 ~3 ~-52 minecraft:light_gray_stained_glass
fill ~81 ~6 ~-54 ~81 ~7 ~-54 minecraft:gray_stained_glass
fill ~81 ~6 ~-48 ~81 ~7 ~-48 minecraft:light_gray_stained_glass
fill ~79 ~6 ~-52 ~79 ~7 ~-52 minecraft:gray_stained_glass
fill ~84 ~6 ~-52 ~84 ~7 ~-52 minecraft:light_gray_stained_glass
setblock ~81 ~1 ~-54 minecraft:iron_door[half=lower,facing=north]
setblock ~81 ~2 ~-54 minecraft:iron_door[half=upper,facing=north]
fill ~79 ~12 ~-54 ~84 ~12 ~-48 minecraft:stone_brick_slab
fill ~80 ~13 ~-53 ~83 ~13 ~-49 minecraft:stone_brick_slab
setblock ~81 ~3 ~-55 minecraft:dark_oak_slab[type=top]
fill ~81 ~13 ~-52 ~83 ~14 ~-50 minecraft:light_gray_concrete
setblock ~83 ~13 ~-51 minecraft:lightning_rod
# 079 workshop style=loading_bay context=local_front facing=north
fill ~-114 ~-3 ~26 ~-107 ~-1 ~38 minecraft:stone
fill ~-114 ~0 ~26 ~-107 ~7 ~38 minecraft:calcite
fill ~-113 ~1 ~27 ~-108 ~6 ~37 minecraft:air
fill ~-113 ~4 ~27 ~-108 ~4 ~37 minecraft:smooth_stone
fill ~-112 ~2 ~26 ~-112 ~3 ~26 minecraft:gray_stained_glass
fill ~-112 ~2 ~38 ~-112 ~3 ~38 minecraft:light_gray_stained_glass
fill ~-109 ~2 ~26 ~-109 ~3 ~26 minecraft:gray_stained_glass
fill ~-109 ~2 ~38 ~-109 ~3 ~38 minecraft:light_gray_stained_glass
fill ~-114 ~2 ~28 ~-114 ~3 ~28 minecraft:gray_stained_glass
fill ~-107 ~2 ~28 ~-107 ~3 ~28 minecraft:light_gray_stained_glass
fill ~-114 ~2 ~31 ~-114 ~3 ~31 minecraft:gray_stained_glass
fill ~-107 ~2 ~31 ~-107 ~3 ~31 minecraft:light_gray_stained_glass
fill ~-114 ~2 ~34 ~-114 ~3 ~34 minecraft:gray_stained_glass
fill ~-107 ~2 ~34 ~-107 ~3 ~34 minecraft:light_gray_stained_glass
setblock ~-111 ~1 ~26 minecraft:iron_door[half=lower,facing=north]
setblock ~-111 ~2 ~26 minecraft:iron_door[half=upper,facing=north]
fill ~-112 ~1 ~26 ~-109 ~4 ~26 minecraft:polished_blackstone
fill ~-112 ~5 ~26 ~-109 ~5 ~26 minecraft:light_blue_stained_glass
fill ~-112 ~9 ~28 ~-110 ~10 ~30 minecraft:iron_block
fill ~-114 ~8 ~26 ~-107 ~8 ~38 minecraft:stone_brick_slab
# 080 midrise_housing style=balcony_block context=arterial_front facing=west
fill ~25 ~-3 ~48 ~31 ~-1 ~58 minecraft:stone
fill ~25 ~0 ~48 ~31 ~10 ~58 minecraft:bricks
fill ~26 ~1 ~49 ~30 ~9 ~57 minecraft:air
fill ~26 ~4 ~49 ~30 ~4 ~57 minecraft:smooth_stone
fill ~26 ~8 ~49 ~30 ~8 ~57 minecraft:smooth_stone
fill ~27 ~2 ~48 ~27 ~3 ~48 minecraft:gray_stained_glass
fill ~27 ~2 ~58 ~27 ~3 ~58 minecraft:light_gray_stained_glass
fill ~25 ~2 ~50 ~25 ~3 ~50 minecraft:gray_stained_glass
fill ~31 ~2 ~50 ~31 ~3 ~50 minecraft:light_gray_stained_glass
fill ~25 ~2 ~53 ~25 ~3 ~53 minecraft:gray_stained_glass
fill ~31 ~2 ~53 ~31 ~3 ~53 minecraft:light_gray_stained_glass
fill ~25 ~2 ~56 ~25 ~3 ~56 minecraft:gray_stained_glass
fill ~31 ~2 ~56 ~31 ~3 ~56 minecraft:light_gray_stained_glass
fill ~27 ~6 ~48 ~27 ~7 ~48 minecraft:gray_stained_glass
fill ~27 ~6 ~58 ~27 ~7 ~58 minecraft:light_gray_stained_glass
fill ~25 ~6 ~50 ~25 ~7 ~50 minecraft:gray_stained_glass
fill ~31 ~6 ~50 ~31 ~7 ~50 minecraft:light_gray_stained_glass
fill ~25 ~6 ~53 ~25 ~7 ~53 minecraft:gray_stained_glass
fill ~31 ~6 ~53 ~31 ~7 ~53 minecraft:light_gray_stained_glass
fill ~25 ~6 ~56 ~25 ~7 ~56 minecraft:gray_stained_glass
fill ~31 ~6 ~56 ~31 ~7 ~56 minecraft:light_gray_stained_glass
setblock ~25 ~1 ~53 minecraft:iron_door[half=lower,facing=west]
setblock ~25 ~2 ~53 minecraft:iron_door[half=upper,facing=west]
fill ~24 ~4 ~50 ~24 ~4 ~56 minecraft:smooth_stone_slab
fill ~24 ~8 ~50 ~24 ~8 ~56 minecraft:smooth_stone_slab
fill ~25 ~11 ~48 ~31 ~11 ~58 minecraft:deepslate_tile_slab
