# Buildings 161..168
# 161 shop_house style=arcade_shop context=collector_front facing=west
fill ~52 ~-3 ~120 ~57 ~-1 ~123 minecraft:stone
fill ~52 ~0 ~120 ~57 ~9 ~123 minecraft:deepslate_bricks
fill ~53 ~1 ~121 ~56 ~8 ~122 minecraft:air
fill ~53 ~4 ~121 ~56 ~4 ~122 minecraft:smooth_stone
fill ~53 ~8 ~121 ~56 ~8 ~122 minecraft:smooth_stone
fill ~54 ~2 ~120 ~54 ~3 ~120 minecraft:gray_stained_glass
fill ~54 ~2 ~123 ~54 ~3 ~123 minecraft:light_gray_stained_glass
fill ~54 ~6 ~120 ~54 ~7 ~120 minecraft:gray_stained_glass
fill ~54 ~6 ~123 ~54 ~7 ~123 minecraft:light_gray_stained_glass
setblock ~52 ~1 ~122 minecraft:iron_door[half=lower,facing=west]
setblock ~52 ~2 ~122 minecraft:iron_door[half=upper,facing=west]
fill ~52 ~1 ~121 ~52 ~3 ~122 minecraft:cyan_stained_glass
setblock ~52 ~1 ~122 minecraft:iron_door[half=lower,facing=west]
setblock ~52 ~2 ~122 minecraft:iron_door[half=upper,facing=west]
setblock ~51 ~3 ~122 minecraft:red_wool
fill ~52 ~4 ~121 ~52 ~4 ~122 minecraft:oxidized_cut_copper
fill ~52 ~10 ~120 ~57 ~10 ~123 minecraft:deepslate_tile_slab
# 162 workshop style=industrial_shed context=local_front facing=east
fill ~52 ~-3 ~-49 ~57 ~-1 ~-46 minecraft:stone
fill ~52 ~0 ~-49 ~57 ~9 ~-46 minecraft:smooth_sandstone
fill ~53 ~1 ~-48 ~56 ~8 ~-47 minecraft:air
fill ~53 ~4 ~-48 ~56 ~4 ~-47 minecraft:smooth_stone
fill ~53 ~8 ~-48 ~56 ~8 ~-47 minecraft:smooth_stone
fill ~54 ~2 ~-49 ~54 ~3 ~-49 minecraft:gray_stained_glass
fill ~54 ~2 ~-46 ~54 ~3 ~-46 minecraft:light_gray_stained_glass
fill ~54 ~6 ~-49 ~54 ~7 ~-49 minecraft:gray_stained_glass
fill ~54 ~6 ~-46 ~54 ~7 ~-46 minecraft:light_gray_stained_glass
setblock ~57 ~1 ~-47 minecraft:iron_door[half=lower,facing=east]
setblock ~57 ~2 ~-47 minecraft:iron_door[half=upper,facing=east]
fill ~57 ~1 ~-47 ~57 ~4 ~-48 minecraft:polished_blackstone
fill ~57 ~5 ~-47 ~57 ~5 ~-48 minecraft:light_blue_stained_glass
fill ~54 ~11 ~-47 ~56 ~12 ~-47 minecraft:iron_block
fill ~52 ~10 ~-49 ~57 ~10 ~-46 minecraft:stone_brick_slab
fill ~54 ~11 ~-47 ~56 ~12 ~-47 minecraft:light_gray_concrete
setblock ~56 ~11 ~-47 minecraft:lightning_rod
# 163 local_shop style=corner_store context=arterial_front facing=north
fill ~91 ~-3 ~-15 ~94 ~-1 ~-10 minecraft:stone
fill ~91 ~0 ~-15 ~94 ~5 ~-10 minecraft:white_concrete
fill ~92 ~1 ~-14 ~93 ~4 ~-11 minecraft:air
fill ~92 ~4 ~-14 ~93 ~4 ~-11 minecraft:smooth_stone
fill ~91 ~2 ~-13 ~91 ~3 ~-13 minecraft:gray_stained_glass
fill ~94 ~2 ~-13 ~94 ~3 ~-13 minecraft:light_gray_stained_glass
setblock ~93 ~1 ~-15 minecraft:iron_door[half=lower,facing=north]
setblock ~93 ~2 ~-15 minecraft:iron_door[half=upper,facing=north]
fill ~92 ~1 ~-15 ~93 ~3 ~-15 minecraft:cyan_stained_glass
setblock ~93 ~1 ~-15 minecraft:iron_door[half=lower,facing=north]
setblock ~93 ~2 ~-15 minecraft:iron_door[half=upper,facing=north]
setblock ~93 ~3 ~-16 minecraft:red_wool
fill ~91 ~6 ~-15 ~94 ~6 ~-10 minecraft:smooth_stone_slab
# 164 local_shop style=storefront context=local_front facing=north
fill ~42 ~-3 ~-32 ~47 ~-1 ~-25 minecraft:stone
fill ~42 ~0 ~-32 ~47 ~11 ~-25 minecraft:bricks
fill ~43 ~1 ~-31 ~46 ~10 ~-26 minecraft:air
fill ~43 ~4 ~-31 ~46 ~4 ~-26 minecraft:smooth_stone
fill ~43 ~8 ~-31 ~46 ~8 ~-26 minecraft:smooth_stone
fill ~44 ~2 ~-32 ~44 ~3 ~-32 minecraft:gray_stained_glass
fill ~44 ~2 ~-25 ~44 ~3 ~-25 minecraft:light_gray_stained_glass
fill ~42 ~2 ~-30 ~42 ~3 ~-30 minecraft:gray_stained_glass
fill ~47 ~2 ~-30 ~47 ~3 ~-30 minecraft:light_gray_stained_glass
fill ~42 ~2 ~-27 ~42 ~3 ~-27 minecraft:gray_stained_glass
fill ~47 ~2 ~-27 ~47 ~3 ~-27 minecraft:light_gray_stained_glass
fill ~44 ~6 ~-32 ~44 ~7 ~-32 minecraft:gray_stained_glass
fill ~44 ~6 ~-25 ~44 ~7 ~-25 minecraft:light_gray_stained_glass
fill ~42 ~6 ~-30 ~42 ~7 ~-30 minecraft:gray_stained_glass
fill ~47 ~6 ~-30 ~47 ~7 ~-30 minecraft:light_gray_stained_glass
fill ~42 ~6 ~-27 ~42 ~7 ~-27 minecraft:gray_stained_glass
fill ~47 ~6 ~-27 ~47 ~7 ~-27 minecraft:light_gray_stained_glass
setblock ~44 ~1 ~-32 minecraft:iron_door[half=lower,facing=north]
setblock ~44 ~2 ~-32 minecraft:iron_door[half=upper,facing=north]
fill ~43 ~1 ~-32 ~46 ~3 ~-32 minecraft:cyan_stained_glass
setblock ~44 ~1 ~-32 minecraft:iron_door[half=lower,facing=north]
setblock ~44 ~2 ~-32 minecraft:iron_door[half=upper,facing=north]
setblock ~44 ~3 ~-33 minecraft:red_wool
fill ~42 ~12 ~-32 ~47 ~12 ~-25 minecraft:deepslate_tile_slab
fill ~43 ~1 ~-32 ~43 ~7 ~-32 doomsday_decoration:hollowbrick
setblock ~44 ~3 ~-32 minecraft:red_carpet
# 165 shop_house style=arcade_shop context=collector_front facing=west
fill ~-96 ~-3 ~-125 ~-91 ~-1 ~-122 minecraft:stone
fill ~-96 ~0 ~-125 ~-91 ~5 ~-122 minecraft:stone_bricks
fill ~-95 ~1 ~-124 ~-92 ~4 ~-123 minecraft:air
fill ~-95 ~4 ~-124 ~-92 ~4 ~-123 minecraft:smooth_stone
fill ~-94 ~2 ~-125 ~-94 ~3 ~-125 minecraft:gray_stained_glass
fill ~-94 ~2 ~-122 ~-94 ~3 ~-122 minecraft:light_gray_stained_glass
setblock ~-96 ~1 ~-123 minecraft:iron_door[half=lower,facing=west]
setblock ~-96 ~2 ~-123 minecraft:iron_door[half=upper,facing=west]
fill ~-96 ~1 ~-124 ~-96 ~3 ~-123 minecraft:cyan_stained_glass
setblock ~-96 ~1 ~-123 minecraft:iron_door[half=lower,facing=west]
setblock ~-96 ~2 ~-123 minecraft:iron_door[half=upper,facing=west]
setblock ~-97 ~3 ~-123 minecraft:red_wool
fill ~-96 ~4 ~-124 ~-96 ~4 ~-123 doomsday_decoration:ironsheetwall_2
fill ~-96 ~6 ~-125 ~-91 ~6 ~-122 minecraft:smooth_stone_slab
# 166 workshop style=loading_bay context=arterial_front facing=west
fill ~-31 ~-3 ~97 ~-26 ~-1 ~100 minecraft:stone
fill ~-31 ~0 ~97 ~-26 ~9 ~100 minecraft:mud_bricks
fill ~-30 ~1 ~98 ~-27 ~8 ~99 minecraft:air
fill ~-30 ~4 ~98 ~-27 ~4 ~99 minecraft:smooth_stone
fill ~-30 ~8 ~98 ~-27 ~8 ~99 minecraft:smooth_stone
fill ~-29 ~2 ~97 ~-29 ~3 ~97 minecraft:gray_stained_glass
fill ~-29 ~2 ~100 ~-29 ~3 ~100 minecraft:light_gray_stained_glass
fill ~-29 ~6 ~97 ~-29 ~7 ~97 minecraft:gray_stained_glass
fill ~-29 ~6 ~100 ~-29 ~7 ~100 minecraft:light_gray_stained_glass
setblock ~-31 ~1 ~99 minecraft:iron_door[half=lower,facing=west]
setblock ~-31 ~2 ~99 minecraft:iron_door[half=upper,facing=west]
fill ~-31 ~1 ~99 ~-31 ~4 ~98 minecraft:polished_blackstone
fill ~-31 ~5 ~99 ~-31 ~5 ~98 minecraft:light_blue_stained_glass
fill ~-29 ~11 ~99 ~-27 ~12 ~99 minecraft:iron_block
fill ~-31 ~10 ~97 ~-26 ~10 ~100 minecraft:deepslate_tile_slab
# 167 small_office style=setback_tower context=local_front facing=south
fill ~-6 ~-3 ~-119 ~-3 ~-1 ~-114 minecraft:stone
fill ~-6 ~0 ~-119 ~-3 ~9 ~-114 minecraft:bricks
fill ~-5 ~1 ~-118 ~-4 ~8 ~-115 minecraft:air
fill ~-5 ~4 ~-118 ~-4 ~4 ~-115 minecraft:smooth_stone
fill ~-5 ~8 ~-118 ~-4 ~8 ~-115 minecraft:smooth_stone
fill ~-6 ~2 ~-117 ~-6 ~3 ~-117 minecraft:gray_stained_glass
fill ~-3 ~2 ~-117 ~-3 ~3 ~-117 minecraft:light_gray_stained_glass
fill ~-6 ~6 ~-117 ~-6 ~7 ~-117 minecraft:gray_stained_glass
fill ~-3 ~6 ~-117 ~-3 ~7 ~-117 minecraft:light_gray_stained_glass
setblock ~-4 ~1 ~-114 minecraft:iron_door[half=lower,facing=south]
setblock ~-4 ~2 ~-114 minecraft:iron_door[half=upper,facing=south]
# 168 shop_house style=arcade_shop context=collector_front facing=north
fill ~-75 ~-3 ~-82 ~-71 ~-1 ~-76 minecraft:stone
fill ~-75 ~0 ~-82 ~-71 ~11 ~-76 minecraft:calcite
fill ~-74 ~1 ~-81 ~-72 ~10 ~-77 minecraft:air
fill ~-74 ~4 ~-81 ~-72 ~4 ~-77 minecraft:smooth_stone
fill ~-74 ~8 ~-81 ~-72 ~8 ~-77 minecraft:smooth_stone
fill ~-73 ~2 ~-82 ~-73 ~3 ~-82 minecraft:gray_stained_glass
fill ~-73 ~2 ~-76 ~-73 ~3 ~-76 minecraft:light_gray_stained_glass
fill ~-75 ~2 ~-80 ~-75 ~3 ~-80 minecraft:gray_stained_glass
fill ~-71 ~2 ~-80 ~-71 ~3 ~-80 minecraft:light_gray_stained_glass
fill ~-73 ~6 ~-82 ~-73 ~7 ~-82 minecraft:gray_stained_glass
fill ~-73 ~6 ~-76 ~-73 ~7 ~-76 minecraft:light_gray_stained_glass
fill ~-75 ~6 ~-80 ~-75 ~7 ~-80 minecraft:gray_stained_glass
fill ~-71 ~6 ~-80 ~-71 ~7 ~-80 minecraft:light_gray_stained_glass
setblock ~-73 ~1 ~-82 minecraft:iron_door[half=lower,facing=north]
setblock ~-73 ~2 ~-82 minecraft:iron_door[half=upper,facing=north]
fill ~-74 ~1 ~-82 ~-72 ~3 ~-82 minecraft:cyan_stained_glass
setblock ~-73 ~1 ~-82 minecraft:iron_door[half=lower,facing=north]
setblock ~-73 ~2 ~-82 minecraft:iron_door[half=upper,facing=north]
setblock ~-73 ~3 ~-83 minecraft:red_wool
fill ~-74 ~4 ~-82 ~-72 ~4 ~-82 minecraft:gray_concrete
fill ~-75 ~12 ~-82 ~-71 ~12 ~-76 minecraft:stone_brick_slab
fill ~-73 ~13 ~-80 ~-72 ~14 ~-78 minecraft:light_gray_concrete
setblock ~-72 ~13 ~-79 minecraft:lightning_rod
