# Buildings 126..150
# 126 shop_house -70,-54 -63,-45 h=8
fill ~-70 ~-3 ~-54 ~-63 ~-1 ~-45 minecraft:stone
fill ~-70 ~0 ~-54 ~-63 ~8 ~-45 minecraft:light_gray_concrete
fill ~-69 ~1 ~-53 ~-64 ~7 ~-46 minecraft:air
fill ~-69 ~4 ~-53 ~-64 ~4 ~-46 minecraft:smooth_stone
fill ~-70 ~2 ~-52 ~-70 ~3 ~-47 minecraft:gray_stained_glass
fill ~-63 ~2 ~-52 ~-63 ~3 ~-47 minecraft:light_gray_stained_glass
fill ~-70 ~6 ~-52 ~-70 ~7 ~-47 minecraft:gray_stained_glass
fill ~-63 ~6 ~-52 ~-63 ~7 ~-47 minecraft:light_gray_stained_glass
fill ~-69 ~0 ~-54 ~-66 ~3 ~-54 doomsday_decoration:porcelainbrickwall
setblock ~-68 ~1 ~-54 minecraft:iron_door[half=lower,facing=north]
setblock ~-68 ~2 ~-54 minecraft:iron_door[half=upper,facing=north]
fill ~-70 ~9 ~-54 ~-63 ~9 ~-45 minecraft:smooth_stone_slab
# 127 workshop 37,30 45,38 h=16
fill ~37 ~-3 ~30 ~45 ~-1 ~38 minecraft:stone
fill ~37 ~0 ~30 ~45 ~16 ~38 minecraft:bricks
fill ~38 ~1 ~31 ~44 ~15 ~37 minecraft:air
fill ~38 ~4 ~31 ~44 ~4 ~37 minecraft:smooth_stone
fill ~38 ~8 ~31 ~44 ~8 ~37 minecraft:smooth_stone
fill ~38 ~12 ~31 ~44 ~12 ~37 minecraft:smooth_stone
fill ~37 ~2 ~32 ~37 ~3 ~36 minecraft:gray_stained_glass
fill ~45 ~2 ~32 ~45 ~3 ~36 minecraft:light_gray_stained_glass
fill ~37 ~6 ~32 ~37 ~7 ~36 minecraft:gray_stained_glass
fill ~45 ~6 ~32 ~45 ~7 ~36 minecraft:light_gray_stained_glass
fill ~37 ~10 ~32 ~37 ~11 ~36 minecraft:gray_stained_glass
fill ~45 ~10 ~32 ~45 ~11 ~36 minecraft:light_gray_stained_glass
fill ~37 ~14 ~32 ~37 ~15 ~36 minecraft:gray_stained_glass
fill ~45 ~14 ~32 ~45 ~15 ~36 minecraft:light_gray_stained_glass
fill ~38 ~0 ~30 ~41 ~3 ~30 doomsday_decoration:hollowbrick
setblock ~39 ~1 ~30 minecraft:iron_door[half=lower,facing=north]
setblock ~39 ~2 ~30 minecraft:iron_door[half=upper,facing=north]
fill ~37 ~17 ~30 ~45 ~17 ~38 minecraft:deepslate_tile_slab
# 128 market 92,97 97,103 h=5
fill ~92 ~-3 ~97 ~97 ~-1 ~103 minecraft:stone
fill ~92 ~0 ~97 ~97 ~5 ~103 minecraft:bricks
fill ~93 ~1 ~98 ~96 ~4 ~102 minecraft:air
fill ~93 ~4 ~98 ~96 ~4 ~102 minecraft:smooth_stone
fill ~94 ~2 ~97 ~95 ~3 ~97 minecraft:gray_stained_glass
fill ~94 ~2 ~103 ~95 ~3 ~103 minecraft:light_gray_stained_glass
fill ~93 ~0 ~97 ~96 ~3 ~97 minecraft:weathered_cut_copper
setblock ~94 ~1 ~97 minecraft:iron_door[half=lower,facing=north]
setblock ~94 ~2 ~97 minecraft:iron_door[half=upper,facing=north]
fill ~92 ~6 ~97 ~97 ~6 ~103 minecraft:deepslate_tile_slab
# 129 restaurant 102,-16 107,-6 h=7
fill ~102 ~-3 ~-16 ~107 ~-1 ~-6 minecraft:stone
fill ~102 ~0 ~-16 ~107 ~7 ~-6 minecraft:bricks
fill ~103 ~1 ~-15 ~106 ~6 ~-7 minecraft:air
fill ~103 ~4 ~-15 ~106 ~4 ~-7 minecraft:smooth_stone
fill ~104 ~2 ~-16 ~105 ~3 ~-16 minecraft:gray_stained_glass
fill ~104 ~2 ~-6 ~105 ~3 ~-6 minecraft:light_gray_stained_glass
fill ~103 ~0 ~-16 ~106 ~3 ~-16 minecraft:weathered_cut_copper
setblock ~104 ~1 ~-16 minecraft:iron_door[half=lower,facing=north]
setblock ~104 ~2 ~-16 minecraft:iron_door[half=upper,facing=north]
fill ~102 ~8 ~-16 ~107 ~8 ~-6 minecraft:deepslate_tile_slab
# 130 office 84,-120 94,-111 h=8
fill ~84 ~-3 ~-120 ~94 ~-1 ~-111 minecraft:stone
fill ~84 ~0 ~-120 ~94 ~8 ~-111 minecraft:stone_bricks
fill ~85 ~1 ~-119 ~93 ~7 ~-112 minecraft:air
fill ~85 ~4 ~-119 ~93 ~4 ~-112 minecraft:smooth_stone
fill ~84 ~2 ~-118 ~84 ~3 ~-113 minecraft:gray_stained_glass
fill ~94 ~2 ~-118 ~94 ~3 ~-113 minecraft:light_gray_stained_glass
fill ~84 ~6 ~-118 ~84 ~7 ~-113 minecraft:gray_stained_glass
fill ~94 ~6 ~-118 ~94 ~7 ~-113 minecraft:light_gray_stained_glass
fill ~85 ~0 ~-120 ~88 ~3 ~-120 doomsday_decoration:ironsheetwall_2
setblock ~86 ~1 ~-120 minecraft:iron_door[half=lower,facing=north]
setblock ~86 ~2 ~-120 minecraft:iron_door[half=upper,facing=north]
fill ~84 ~9 ~-120 ~94 ~9 ~-111 minecraft:smooth_stone_slab
# 131 community 87,-80 95,-74 h=5
fill ~87 ~-3 ~-80 ~95 ~-1 ~-74 minecraft:stone
fill ~87 ~0 ~-80 ~95 ~5 ~-74 minecraft:calcite
fill ~88 ~1 ~-79 ~94 ~4 ~-75 minecraft:air
fill ~88 ~4 ~-79 ~94 ~4 ~-75 minecraft:smooth_stone
fill ~89 ~2 ~-80 ~93 ~3 ~-80 minecraft:gray_stained_glass
fill ~89 ~2 ~-74 ~93 ~3 ~-74 minecraft:light_gray_stained_glass
fill ~88 ~0 ~-80 ~91 ~3 ~-80 minecraft:gray_concrete
setblock ~89 ~1 ~-80 minecraft:iron_door[half=lower,facing=north]
setblock ~89 ~2 ~-80 minecraft:iron_door[half=upper,facing=north]
fill ~87 ~6 ~-80 ~95 ~6 ~-74 minecraft:stone_brick_slab
# 132 local_shop -112,-56 -107,-46 h=11
fill ~-112 ~-3 ~-56 ~-107 ~-1 ~-46 minecraft:stone
fill ~-112 ~0 ~-56 ~-107 ~11 ~-46 minecraft:calcite
fill ~-111 ~1 ~-55 ~-108 ~10 ~-47 minecraft:air
fill ~-111 ~4 ~-55 ~-108 ~4 ~-47 minecraft:smooth_stone
fill ~-111 ~8 ~-55 ~-108 ~8 ~-47 minecraft:smooth_stone
fill ~-112 ~2 ~-54 ~-112 ~3 ~-48 minecraft:gray_stained_glass
fill ~-107 ~2 ~-54 ~-107 ~3 ~-48 minecraft:light_gray_stained_glass
fill ~-112 ~6 ~-54 ~-112 ~7 ~-48 minecraft:gray_stained_glass
fill ~-107 ~6 ~-54 ~-107 ~7 ~-48 minecraft:light_gray_stained_glass
fill ~-111 ~0 ~-56 ~-108 ~3 ~-56 minecraft:gray_concrete
setblock ~-110 ~1 ~-56 minecraft:iron_door[half=lower,facing=north]
setblock ~-110 ~2 ~-56 minecraft:iron_door[half=upper,facing=north]
fill ~-112 ~12 ~-56 ~-107 ~12 ~-46 minecraft:stone_brick_slab
# 133 local_shop -92,99 -87,112 h=11
fill ~-92 ~-3 ~99 ~-87 ~-1 ~112 minecraft:stone
fill ~-92 ~0 ~99 ~-87 ~11 ~112 minecraft:mud_bricks
fill ~-91 ~1 ~100 ~-88 ~10 ~111 minecraft:air
fill ~-91 ~4 ~100 ~-88 ~4 ~111 minecraft:smooth_stone
fill ~-91 ~8 ~100 ~-88 ~8 ~111 minecraft:smooth_stone
fill ~-92 ~2 ~101 ~-92 ~3 ~110 minecraft:gray_stained_glass
fill ~-87 ~2 ~101 ~-87 ~3 ~110 minecraft:light_gray_stained_glass
fill ~-92 ~6 ~101 ~-92 ~7 ~110 minecraft:gray_stained_glass
fill ~-87 ~6 ~101 ~-87 ~7 ~110 minecraft:light_gray_stained_glass
fill ~-91 ~0 ~99 ~-88 ~3 ~99 minecraft:spruce_planks
setblock ~-90 ~1 ~99 minecraft:iron_door[half=lower,facing=north]
setblock ~-90 ~2 ~99 minecraft:iron_door[half=upper,facing=north]
fill ~-92 ~12 ~99 ~-87 ~12 ~112 minecraft:deepslate_tile_slab
# 134 midrise_housing 4,-36 10,-29 h=12
fill ~4 ~-3 ~-36 ~10 ~-1 ~-29 minecraft:stone
fill ~4 ~0 ~-36 ~10 ~12 ~-29 minecraft:bricks
fill ~5 ~1 ~-35 ~9 ~11 ~-30 minecraft:air
fill ~5 ~4 ~-35 ~9 ~4 ~-30 minecraft:smooth_stone
fill ~5 ~8 ~-35 ~9 ~8 ~-30 minecraft:smooth_stone
fill ~6 ~2 ~-36 ~8 ~3 ~-36 minecraft:gray_stained_glass
fill ~6 ~2 ~-29 ~8 ~3 ~-29 minecraft:light_gray_stained_glass
fill ~6 ~6 ~-36 ~8 ~7 ~-36 minecraft:gray_stained_glass
fill ~6 ~6 ~-29 ~8 ~7 ~-29 minecraft:light_gray_stained_glass
fill ~6 ~10 ~-36 ~8 ~11 ~-36 minecraft:gray_stained_glass
fill ~6 ~10 ~-29 ~8 ~11 ~-29 minecraft:light_gray_stained_glass
fill ~5 ~0 ~-36 ~8 ~3 ~-36 doomsday_decoration:redbrick
setblock ~6 ~1 ~-36 minecraft:iron_door[half=lower,facing=north]
setblock ~6 ~2 ~-36 minecraft:iron_door[half=upper,facing=north]
fill ~4 ~13 ~-36 ~10 ~13 ~-29 minecraft:deepslate_tile_slab
# 135 factory 81,74 91,83 h=12
fill ~81 ~-3 ~74 ~91 ~-1 ~83 minecraft:stone
fill ~81 ~0 ~74 ~91 ~12 ~83 minecraft:stone_bricks
fill ~82 ~1 ~75 ~90 ~11 ~82 minecraft:air
fill ~82 ~4 ~75 ~90 ~4 ~82 minecraft:smooth_stone
fill ~82 ~8 ~75 ~90 ~8 ~82 minecraft:smooth_stone
fill ~81 ~2 ~76 ~81 ~3 ~81 minecraft:gray_stained_glass
fill ~91 ~2 ~76 ~91 ~3 ~81 minecraft:light_gray_stained_glass
fill ~81 ~6 ~76 ~81 ~7 ~81 minecraft:gray_stained_glass
fill ~91 ~6 ~76 ~91 ~7 ~81 minecraft:light_gray_stained_glass
fill ~81 ~10 ~76 ~81 ~11 ~81 minecraft:gray_stained_glass
fill ~91 ~10 ~76 ~91 ~11 ~81 minecraft:light_gray_stained_glass
fill ~82 ~0 ~74 ~85 ~3 ~74 minecraft:orange_terracotta
setblock ~83 ~1 ~74 minecraft:iron_door[half=lower,facing=north]
setblock ~83 ~2 ~74 minecraft:iron_door[half=upper,facing=north]
fill ~81 ~13 ~74 ~91 ~13 ~83 minecraft:stone_brick_slab
# 136 station_shop -76,-92 -67,-82 h=6
fill ~-76 ~-3 ~-92 ~-67 ~-1 ~-82 minecraft:stone
fill ~-76 ~0 ~-92 ~-67 ~6 ~-82 minecraft:bricks
fill ~-75 ~1 ~-91 ~-68 ~5 ~-83 minecraft:air
fill ~-75 ~4 ~-91 ~-68 ~4 ~-83 minecraft:smooth_stone
fill ~-76 ~2 ~-90 ~-76 ~3 ~-84 minecraft:gray_stained_glass
fill ~-67 ~2 ~-90 ~-67 ~3 ~-84 minecraft:light_gray_stained_glass
fill ~-75 ~0 ~-92 ~-72 ~3 ~-92 minecraft:gray_concrete
setblock ~-74 ~1 ~-92 minecraft:iron_door[half=lower,facing=north]
setblock ~-74 ~2 ~-92 minecraft:iron_door[half=upper,facing=north]
fill ~-76 ~7 ~-92 ~-67 ~7 ~-82 minecraft:deepslate_tile_slab
fill ~-69 ~4 ~-84 ~-67 ~7 ~-82 minecraft:air
setblock ~-69 ~4 ~-84 minecraft:cobweb
# 137 local_shop -124,74 -118,80 h=7
fill ~-124 ~-3 ~74 ~-118 ~-1 ~80 minecraft:stone
fill ~-124 ~0 ~74 ~-118 ~7 ~80 minecraft:white_terracotta
fill ~-123 ~1 ~75 ~-119 ~6 ~79 minecraft:air
fill ~-123 ~4 ~75 ~-119 ~4 ~79 minecraft:smooth_stone
fill ~-122 ~2 ~74 ~-120 ~3 ~74 minecraft:gray_stained_glass
fill ~-122 ~2 ~80 ~-120 ~3 ~80 minecraft:light_gray_stained_glass
fill ~-123 ~0 ~74 ~-120 ~3 ~74 minecraft:dark_oak_planks
setblock ~-122 ~1 ~74 minecraft:iron_door[half=lower,facing=north]
setblock ~-122 ~2 ~74 minecraft:iron_door[half=upper,facing=north]
fill ~-124 ~8 ~74 ~-118 ~8 ~80 minecraft:dark_oak_slab
# 138 apartment 95,23 101,29 h=5
fill ~95 ~-3 ~23 ~101 ~-1 ~29 minecraft:stone
fill ~95 ~0 ~23 ~101 ~5 ~29 minecraft:bricks
fill ~96 ~1 ~24 ~100 ~4 ~28 minecraft:air
fill ~96 ~4 ~24 ~100 ~4 ~28 minecraft:smooth_stone
fill ~97 ~2 ~23 ~99 ~3 ~23 minecraft:gray_stained_glass
fill ~97 ~2 ~29 ~99 ~3 ~29 minecraft:light_gray_stained_glass
fill ~96 ~0 ~23 ~99 ~3 ~23 minecraft:weathered_cut_copper
setblock ~97 ~1 ~23 minecraft:iron_door[half=lower,facing=north]
setblock ~97 ~2 ~23 minecraft:iron_door[half=upper,facing=north]
fill ~95 ~6 ~23 ~101 ~6 ~29 minecraft:deepslate_tile_slab
# 139 detached_house -48,89 -43,95 h=7
fill ~-48 ~-3 ~89 ~-43 ~-1 ~95 minecraft:stone
fill ~-48 ~0 ~89 ~-43 ~7 ~95 minecraft:white_terracotta
fill ~-47 ~1 ~90 ~-44 ~6 ~94 minecraft:air
fill ~-47 ~4 ~90 ~-44 ~4 ~94 minecraft:smooth_stone
fill ~-46 ~2 ~89 ~-45 ~3 ~89 minecraft:gray_stained_glass
fill ~-46 ~2 ~95 ~-45 ~3 ~95 minecraft:light_gray_stained_glass
fill ~-47 ~0 ~89 ~-44 ~3 ~89 minecraft:dark_oak_planks
setblock ~-46 ~1 ~89 minecraft:iron_door[half=lower,facing=north]
setblock ~-46 ~2 ~89 minecraft:iron_door[half=upper,facing=north]
fill ~-48 ~8 ~89 ~-43 ~8 ~95 minecraft:dark_oak_slab
# 140 local_shop 91,-23 97,-16 h=9
fill ~91 ~-3 ~-23 ~97 ~-1 ~-16 minecraft:stone
fill ~91 ~0 ~-23 ~97 ~9 ~-16 minecraft:white_terracotta
fill ~92 ~1 ~-22 ~96 ~8 ~-17 minecraft:air
fill ~92 ~4 ~-22 ~96 ~4 ~-17 minecraft:smooth_stone
fill ~92 ~8 ~-22 ~96 ~8 ~-17 minecraft:smooth_stone
fill ~91 ~2 ~-21 ~91 ~3 ~-18 minecraft:gray_stained_glass
fill ~97 ~2 ~-21 ~97 ~3 ~-18 minecraft:light_gray_stained_glass
fill ~91 ~6 ~-21 ~91 ~7 ~-18 minecraft:gray_stained_glass
fill ~97 ~6 ~-21 ~97 ~7 ~-18 minecraft:light_gray_stained_glass
fill ~92 ~0 ~-23 ~95 ~3 ~-23 minecraft:dark_oak_planks
setblock ~93 ~1 ~-23 minecraft:iron_door[half=lower,facing=north]
setblock ~93 ~2 ~-23 minecraft:iron_door[half=upper,facing=north]
fill ~91 ~10 ~-23 ~97 ~10 ~-16 minecraft:dark_oak_slab
# 141 row_house -125,112 -119,119 h=5
fill ~-125 ~-3 ~112 ~-119 ~-1 ~119 minecraft:stone
fill ~-125 ~0 ~112 ~-119 ~5 ~119 minecraft:mud_bricks
fill ~-124 ~1 ~113 ~-120 ~4 ~118 minecraft:air
fill ~-124 ~4 ~113 ~-120 ~4 ~118 minecraft:smooth_stone
fill ~-125 ~2 ~114 ~-125 ~3 ~117 minecraft:gray_stained_glass
fill ~-119 ~2 ~114 ~-119 ~3 ~117 minecraft:light_gray_stained_glass
fill ~-124 ~0 ~112 ~-121 ~3 ~112 minecraft:spruce_planks
setblock ~-123 ~1 ~112 minecraft:iron_door[half=lower,facing=north]
setblock ~-123 ~2 ~112 minecraft:iron_door[half=upper,facing=north]
fill ~-125 ~6 ~112 ~-119 ~6 ~119 minecraft:deepslate_tile_slab
# 142 detached_house -106,58 -101,66 h=9
fill ~-106 ~-3 ~58 ~-101 ~-1 ~66 minecraft:stone
fill ~-106 ~0 ~58 ~-101 ~9 ~66 minecraft:mud_bricks
fill ~-105 ~1 ~59 ~-102 ~8 ~65 minecraft:air
fill ~-105 ~4 ~59 ~-102 ~4 ~65 minecraft:smooth_stone
fill ~-105 ~8 ~59 ~-102 ~8 ~65 minecraft:smooth_stone
fill ~-106 ~2 ~60 ~-106 ~3 ~64 minecraft:gray_stained_glass
fill ~-101 ~2 ~60 ~-101 ~3 ~64 minecraft:light_gray_stained_glass
fill ~-106 ~6 ~60 ~-106 ~7 ~64 minecraft:gray_stained_glass
fill ~-101 ~6 ~60 ~-101 ~7 ~64 minecraft:light_gray_stained_glass
fill ~-105 ~0 ~58 ~-102 ~3 ~58 minecraft:spruce_planks
setblock ~-104 ~1 ~58 minecraft:iron_door[half=lower,facing=north]
setblock ~-104 ~2 ~58 minecraft:iron_door[half=upper,facing=north]
fill ~-106 ~10 ~58 ~-101 ~10 ~66 minecraft:deepslate_tile_slab
# 143 shop_house 78,-41 84,-33 h=12
fill ~78 ~-3 ~-41 ~84 ~-1 ~-33 minecraft:stone
fill ~78 ~0 ~-41 ~84 ~12 ~-33 minecraft:bricks
fill ~79 ~1 ~-40 ~83 ~11 ~-34 minecraft:air
fill ~79 ~4 ~-40 ~83 ~4 ~-34 minecraft:smooth_stone
fill ~79 ~8 ~-40 ~83 ~8 ~-34 minecraft:smooth_stone
fill ~78 ~2 ~-39 ~78 ~3 ~-35 minecraft:gray_stained_glass
fill ~84 ~2 ~-39 ~84 ~3 ~-35 minecraft:light_gray_stained_glass
fill ~78 ~6 ~-39 ~78 ~7 ~-35 minecraft:gray_stained_glass
fill ~84 ~6 ~-39 ~84 ~7 ~-35 minecraft:light_gray_stained_glass
fill ~78 ~10 ~-39 ~78 ~11 ~-35 minecraft:gray_stained_glass
fill ~84 ~10 ~-39 ~84 ~11 ~-35 minecraft:light_gray_stained_glass
fill ~79 ~0 ~-41 ~82 ~3 ~-41 doomsday_decoration:hollowbrick
setblock ~80 ~1 ~-41 minecraft:iron_door[half=lower,facing=north]
setblock ~80 ~2 ~-41 minecraft:iron_door[half=upper,facing=north]
fill ~78 ~13 ~-41 ~84 ~13 ~-33 minecraft:deepslate_tile_slab
# 144 restaurant -70,57 -62,64 h=10
fill ~-70 ~-3 ~57 ~-62 ~-1 ~64 minecraft:stone
fill ~-70 ~0 ~57 ~-62 ~10 ~64 minecraft:light_gray_concrete
fill ~-69 ~1 ~58 ~-63 ~9 ~63 minecraft:air
fill ~-69 ~4 ~58 ~-63 ~4 ~63 minecraft:smooth_stone
fill ~-69 ~8 ~58 ~-63 ~8 ~63 minecraft:smooth_stone
fill ~-70 ~2 ~59 ~-70 ~3 ~62 minecraft:gray_stained_glass
fill ~-62 ~2 ~59 ~-62 ~3 ~62 minecraft:light_gray_stained_glass
fill ~-70 ~6 ~59 ~-70 ~7 ~62 minecraft:gray_stained_glass
fill ~-62 ~6 ~59 ~-62 ~7 ~62 minecraft:light_gray_stained_glass
fill ~-69 ~0 ~57 ~-66 ~3 ~57 doomsday_decoration:porcelainbrickwall
setblock ~-68 ~1 ~57 minecraft:iron_door[half=lower,facing=north]
setblock ~-68 ~2 ~57 minecraft:iron_door[half=upper,facing=north]
fill ~-70 ~11 ~57 ~-62 ~11 ~64 minecraft:smooth_stone_slab
# 145 shop_house 72,-64 79,-57 h=12
fill ~72 ~-3 ~-64 ~79 ~-1 ~-57 minecraft:stone
fill ~72 ~0 ~-64 ~79 ~12 ~-57 minecraft:smooth_sandstone
fill ~73 ~1 ~-63 ~78 ~11 ~-58 minecraft:air
fill ~73 ~4 ~-63 ~78 ~4 ~-58 minecraft:smooth_stone
fill ~73 ~8 ~-63 ~78 ~8 ~-58 minecraft:smooth_stone
fill ~72 ~2 ~-62 ~72 ~3 ~-59 minecraft:gray_stained_glass
fill ~79 ~2 ~-62 ~79 ~3 ~-59 minecraft:light_gray_stained_glass
fill ~72 ~6 ~-62 ~72 ~7 ~-59 minecraft:gray_stained_glass
fill ~79 ~6 ~-62 ~79 ~7 ~-59 minecraft:light_gray_stained_glass
fill ~72 ~10 ~-62 ~72 ~11 ~-59 minecraft:gray_stained_glass
fill ~79 ~10 ~-62 ~79 ~11 ~-59 minecraft:light_gray_stained_glass
fill ~73 ~0 ~-64 ~76 ~3 ~-64 minecraft:brown_terracotta
setblock ~74 ~1 ~-64 minecraft:iron_door[half=lower,facing=north]
setblock ~74 ~2 ~-64 minecraft:iron_door[half=upper,facing=north]
fill ~72 ~13 ~-64 ~79 ~13 ~-57 minecraft:stone_brick_slab
# 146 detached_house -43,115 -38,123 h=5
fill ~-43 ~-3 ~115 ~-38 ~-1 ~123 minecraft:stone
fill ~-43 ~0 ~115 ~-38 ~5 ~123 minecraft:white_terracotta
fill ~-42 ~1 ~116 ~-39 ~4 ~122 minecraft:air
fill ~-42 ~4 ~116 ~-39 ~4 ~122 minecraft:smooth_stone
fill ~-43 ~2 ~117 ~-43 ~3 ~121 minecraft:gray_stained_glass
fill ~-38 ~2 ~117 ~-38 ~3 ~121 minecraft:light_gray_stained_glass
fill ~-42 ~0 ~115 ~-39 ~3 ~115 minecraft:dark_oak_planks
setblock ~-41 ~1 ~115 minecraft:iron_door[half=lower,facing=north]
setblock ~-41 ~2 ~115 minecraft:iron_door[half=upper,facing=north]
fill ~-43 ~6 ~115 ~-38 ~6 ~123 minecraft:dark_oak_slab
# 147 shop_house -80,21 -72,28 h=16
fill ~-80 ~-3 ~21 ~-72 ~-1 ~28 minecraft:stone
fill ~-80 ~0 ~21 ~-72 ~16 ~28 minecraft:light_gray_concrete
fill ~-79 ~1 ~22 ~-73 ~15 ~27 minecraft:air
fill ~-79 ~4 ~22 ~-73 ~4 ~27 minecraft:smooth_stone
fill ~-79 ~8 ~22 ~-73 ~8 ~27 minecraft:smooth_stone
fill ~-79 ~12 ~22 ~-73 ~12 ~27 minecraft:smooth_stone
fill ~-80 ~2 ~23 ~-80 ~3 ~26 minecraft:gray_stained_glass
fill ~-72 ~2 ~23 ~-72 ~3 ~26 minecraft:light_gray_stained_glass
fill ~-80 ~6 ~23 ~-80 ~7 ~26 minecraft:gray_stained_glass
fill ~-72 ~6 ~23 ~-72 ~7 ~26 minecraft:light_gray_stained_glass
fill ~-80 ~10 ~23 ~-80 ~11 ~26 minecraft:gray_stained_glass
fill ~-72 ~10 ~23 ~-72 ~11 ~26 minecraft:light_gray_stained_glass
fill ~-80 ~14 ~23 ~-80 ~15 ~26 minecraft:gray_stained_glass
fill ~-72 ~14 ~23 ~-72 ~15 ~26 minecraft:light_gray_stained_glass
fill ~-79 ~0 ~21 ~-76 ~3 ~21 doomsday_decoration:porcelainbrickwall
setblock ~-78 ~1 ~21 minecraft:iron_door[half=lower,facing=north]
setblock ~-78 ~2 ~21 minecraft:iron_door[half=upper,facing=north]
fill ~-80 ~17 ~21 ~-72 ~17 ~28 minecraft:smooth_stone_slab
# 148 row_house -76,77 -69,83 h=7
fill ~-76 ~-3 ~77 ~-69 ~-1 ~83 minecraft:stone
fill ~-76 ~0 ~77 ~-69 ~7 ~83 minecraft:white_terracotta
fill ~-75 ~1 ~78 ~-70 ~6 ~82 minecraft:air
fill ~-75 ~4 ~78 ~-70 ~4 ~82 minecraft:smooth_stone
fill ~-76 ~2 ~79 ~-76 ~3 ~81 minecraft:gray_stained_glass
fill ~-69 ~2 ~79 ~-69 ~3 ~81 minecraft:light_gray_stained_glass
fill ~-75 ~0 ~77 ~-72 ~3 ~77 minecraft:dark_oak_planks
setblock ~-74 ~1 ~77 minecraft:iron_door[half=lower,facing=north]
setblock ~-74 ~2 ~77 minecraft:iron_door[half=upper,facing=north]
fill ~-76 ~8 ~77 ~-69 ~8 ~83 minecraft:dark_oak_slab
# 149 market 98,54 104,61 h=11
fill ~98 ~-3 ~54 ~104 ~-1 ~61 minecraft:stone
fill ~98 ~0 ~54 ~104 ~11 ~61 minecraft:bricks
fill ~99 ~1 ~55 ~103 ~10 ~60 minecraft:air
fill ~99 ~4 ~55 ~103 ~4 ~60 minecraft:smooth_stone
fill ~99 ~8 ~55 ~103 ~8 ~60 minecraft:smooth_stone
fill ~100 ~2 ~54 ~102 ~3 ~54 minecraft:gray_stained_glass
fill ~100 ~2 ~61 ~102 ~3 ~61 minecraft:light_gray_stained_glass
fill ~100 ~6 ~54 ~102 ~7 ~54 minecraft:gray_stained_glass
fill ~100 ~6 ~61 ~102 ~7 ~61 minecraft:light_gray_stained_glass
fill ~99 ~0 ~54 ~102 ~3 ~54 minecraft:weathered_cut_copper
setblock ~100 ~1 ~54 minecraft:iron_door[half=lower,facing=north]
setblock ~100 ~2 ~54 minecraft:iron_door[half=upper,facing=north]
fill ~98 ~12 ~54 ~104 ~12 ~61 minecraft:deepslate_tile_slab
# 150 midrise_housing -6,38 3,45 h=20
fill ~-6 ~-3 ~38 ~3 ~-1 ~45 minecraft:stone
fill ~-6 ~0 ~38 ~3 ~20 ~45 minecraft:white_terracotta
fill ~-5 ~1 ~39 ~2 ~19 ~44 minecraft:air
fill ~-5 ~4 ~39 ~2 ~4 ~44 minecraft:smooth_stone
fill ~-5 ~8 ~39 ~2 ~8 ~44 minecraft:smooth_stone
fill ~-5 ~12 ~39 ~2 ~12 ~44 minecraft:smooth_stone
fill ~-5 ~16 ~39 ~2 ~16 ~44 minecraft:smooth_stone
fill ~-4 ~2 ~38 ~1 ~3 ~38 minecraft:gray_stained_glass
fill ~-4 ~2 ~45 ~1 ~3 ~45 minecraft:light_gray_stained_glass
fill ~-4 ~6 ~38 ~1 ~7 ~38 minecraft:gray_stained_glass
fill ~-4 ~6 ~45 ~1 ~7 ~45 minecraft:light_gray_stained_glass
fill ~-4 ~10 ~38 ~1 ~11 ~38 minecraft:gray_stained_glass
fill ~-4 ~10 ~45 ~1 ~11 ~45 minecraft:light_gray_stained_glass
fill ~-4 ~14 ~38 ~1 ~15 ~38 minecraft:gray_stained_glass
fill ~-4 ~14 ~45 ~1 ~15 ~45 minecraft:light_gray_stained_glass
fill ~-4 ~18 ~38 ~1 ~19 ~38 minecraft:gray_stained_glass
fill ~-4 ~18 ~45 ~1 ~19 ~45 minecraft:light_gray_stained_glass
fill ~-5 ~0 ~38 ~-2 ~3 ~38 minecraft:gray_concrete
setblock ~-4 ~1 ~38 minecraft:iron_door[half=lower,facing=north]
setblock ~-4 ~2 ~38 minecraft:iron_door[half=upper,facing=north]
fill ~-6 ~21 ~38 ~3 ~21 ~45 minecraft:stone_brick_slab
