{
  "xsize": 16,
  "zsize": 16,
  "palette": {
    "palette": [
      {
        "char": "",
        "block": "minecraft:air"
      },
      {
        "char": "",
        "block": "minecraft:yellow_terracotta"
      },
      {
        "char": "",
        "block": "minecraft:light_gray_concrete"
      },
      {
        "char": "",
        "block": "apocalypsenow:sandbags"
      },
      {
        "char": "",
        "block": "minecraft:white_bed[facing=north,occupied=false,part=head]",
        "tag": {
          "id": "minecraft:bed"
        }
      },
      {
        "char": "",
        "block": "apocalypsenow:medical_box",
        "tag": {
          "id": "apocalypsenow:medical_box"
        },
        "loot": "project_deadzone:chests/hospital_pharmacy"
      },
      {
        "char": "",
        "block": "minecraft:chest[facing=south,type=single,waterlogged=false]",
        "tag": {
          "id": "minecraft:chest"
        }
      },
      {
        "char": "",
        "block": "minecraft:white_bed[facing=north,occupied=false,part=foot]",
        "tag": {
          "id": "minecraft:bed"
        }
      },
      {
        "char": "",
        "block": "minecraft:quartz_slab[type=top,waterlogged=false]"
      },
      {
        "char": "",
        "block": "minecraft:quartz_stairs[facing=east,half=top,shape=straight,waterlogged=false]"
      },
      {
        "char": "",
        "block": "minecraft:white_bed[facing=south,occupied=false,part=foot]",
        "tag": {
          "id": "minecraft:bed"
        }
      },
      {
        "char": "",
        "block": "minecraft:quartz_stairs[facing=south,half=top,shape=straight,waterlogged=false]"
      },
      {
        "char": "",
        "block": "minecraft:chest[facing=north,type=single,waterlogged=false]",
        "tag": {
          "id": "minecraft:chest"
        }
      },
      {
        "char": "",
        "block": "minecraft:oak_stairs[facing=south,half=bottom,shape=straight,waterlogged=false]"
      },
      {
        "char": "",
        "block": "minecraft:white_bed[facing=south,occupied=false,part=head]",
        "tag": {
          "id": "minecraft:bed"
        }
      },
      {
        "char": "",
        "block": "apocalypsenow:medicine_boxes[facing=south,waterlogged=false]",
        "tag": {
          "id": "apocalypsenow:medicine_boxes"
        },
        "loot": "project_deadzone:chests/hospital_pharmacy"
      },
      {
        "char": "",
        "block": "apocalypsenow:medicine_boxes[facing=west,waterlogged=false]",
        "tag": {
          "id": "apocalypsenow:medicine_boxes"
        },
        "loot": "project_deadzone:chests/hospital_pharmacy"
      },
      {
        "char": "",
        "block": "apocalypsenow:medical_storage[facing=north,waterlogged=false]",
        "tag": {
          "Items": [],
          "id": "apocalypsenow:medical_storage"
        },
        "loot": "project_deadzone:chests/hospital_pharmacy"
      },
      {
        "char": "",
        "block": "apocalypsenow:medicine_boxes[facing=north,waterlogged=false]",
        "tag": {
          "id": "apocalypsenow:medicine_boxes"
        },
        "loot": "project_deadzone:chests/hospital_pharmacy"
      },
      {
        "char": "",
        "block": "apocalypsenow:spikes"
      }
    ]
  },
  "slices": [
    [
      "",
      "",
      "",
      "",
      "",
      "",
      "",
      "",
      "",
      "",
      "",
      "",
      "",
      "",
      "",
      ""
    ],
    [
      "",
      "",
      "",
      "",
      "",
      "",
      "",
      "",
      "",
      "",
      "",
      "",
      "",
      "",
      "",
      ""
    ],
    [
      "",
      "",
      "",
      "",
      "",
      "",
      "",
      "",
      "",
      "",
      "",
      "",
      "",
      "",
      "",
      ""
    ],
    [
      "",
      "",
      "",
      "",
      "",
      "",
      "",
      "",
      "",
      "",
      "",
      "",
      "",
      "",
      "",
      ""
    ],
    [
      "",
      "",
      "",
      "",
      "",
      "",
      "",
      "",
      "",
      "",
      "",
      "",
      "",
      "",
      "",
      ""
    ],
    [
      "",
      "",
      "",
      "",
      "",
      "",
      "",
      "",
      "",
      "",
      "",
      "",
      "",
      "",
      "",
      ""
    ]
  ]
}
