{
  "xsize": 16,
  "zsize": 16,
  "palette": {
    "palette": [
      {
        "char": "",
        "block": "minecraft:air"
      },
      {
        "char": "",
        "block": "minecraft:black_concrete"
      },
      {
        "char": "",
        "block": "minecraft:smooth_stone"
      },
      {
        "char": "",
        "block": "minecraft:red_concrete"
      },
      {
        "char": "",
        "block": "minecraft:oak_leaves[distance=7,persistent=true,waterlogged=false]"
      },
      {
        "char": "",
        "block": "apocalypsenow:papersvariant_2[facing=east]"
      },
      {
        "char": "",
        "block": "apocalypsenow:paperstrash[facing=south]"
      },
      {
        "char": "",
        "block": "apocalypsenow:papertrash[facing=west]"
      },
      {
        "char": "",
        "block": "apocalypsenow:paperstrashvariant_2[facing=east]"
      },
      {
        "char": "",
        "block": "apocalypsenow:papertrash[facing=east]"
      },
      {
        "char": "",
        "block": "apocalypsenow:papertrashvariant[facing=south]"
      },
      {
        "char": "",
        "block": "apocalypsenow:paperstrash[facing=east]"
      },
      {
        "char": "",
        "block": "refurbished_furniture:oak_crate",
        "loot": "project_deadzone:chests/generic_low_filled"
      },
      {
        "char": "",
        "block": "apocalypsenow:redconcretebricks"
      },
      {
        "char": "",
        "block": "apocalypsenow:paperstrashvariant_2[facing=south]"
      },
      {
        "char": "",
        "block": "apocalypsenow:paperstrash[facing=west]"
      },
      {
        "char": "",
        "block": "apocalypsenow:paperstrashvariant_2[facing=west]"
      },
      {
        "char": "",
        "block": "minecraft:chest[facing=north,type=single,waterlogged=false]",
        "tag": {
          "id": "minecraft:chest"
        }
      }
    ]
  },
  "slices": [
    [
      "",
      "",
      "",
      "",
      "",
      "",
      "",
      "",
      "",
      "",
      "",
      "",
      "",
      "",
      "",
      ""
    ],
    [
      "",
      "",
      "",
      "",
      "",
      "",
      "",
      "",
      "",
      "",
      "",
      "",
      "",
      "",
      "",
      ""
    ],
    [
      "",
      "",
      "",
      "",
      "",
      "",
      "",
      "",
      "",
      "",
      "",
      "",
      "",
      "",
      "",
      ""
    ],
    [
      "",
      "",
      "",
      "",
      "",
      "",
      "",
      "",
      "",
      "",
      "",
      "",
      "",
      "",
      "",
      ""
    ],
    [
      "",
      "",
      "",
      "",
      "",
      "",
      "",
      "",
      "",
      "",
      "",
      "",
      "",
      "",
      "",
      ""
    ],
    [
      "",
      "",
      "",
      "",
      "",
      "",
      "",
      "",
      "",
      "",
      "",
      "",
      "",
      "",
      "",
      ""
    ]
  ]
}
