{
  "xsize": 16,
  "zsize": 16,
  "palette": {
    "palette": [
      {
        "char": "",
        "block": "minecraft:air"
      },
      {
        "char": "",
        "block": "minecraft:red_concrete"
      },
      {
        "char": "",
        "block": "minecraft:smooth_stone"
      },
      {
        "char": "",
        "block": "minecraft:black_concrete"
      },
      {
        "char": "",
        "block": "apocalypsenow:redconcretebricks"
      },
      {
        "char": "",
        "block": "apocalypsenow:large_shelves[facing=south,waterlogged=false]",
        "tag": {
          "id": "apocalypsenow:large_shelves"
        },
        "loot": "project_deadzone:generic_low_filled"
      },
      {
        "char": "",
        "block": "apocalypsenow:large_shelves_fill[facing=west,waterlogged=false]",
        "tag": {
          "id": "apocalypsenow:large_shelves_fill"
        },
        "loot": "project_deadzone:generic_low_filled"
      },
      {
        "char": "",
        "block": "minecraft:light_gray_concrete"
      },
      {
        "char": "",
        "block": "apocalypsenow:large_shelves_fill[facing=north,waterlogged=false]",
        "tag": {
          "id": "apocalypsenow:large_shelves_fill"
        },
        "loot": "project_deadzone:generic_low_filled"
      },
      {
        "char": "",
        "block": "apocalypsenow:large_shelves[facing=north,waterlogged=false]",
        "tag": {
          "id": "apocalypsenow:large_shelves"
        },
        "loot": "project_deadzone:generic_low_filled"
      },
      {
        "char": "",
        "block": "apocalypsenow:large_shelves_fill[facing=south,waterlogged=false]",
        "tag": {
          "id": "apocalypsenow:large_shelves_fill"
        },
        "loot": "project_deadzone:generic_low_filled"
      },
      {
        "char": "",
        "block": "minecraft:chest[facing=south,type=single,waterlogged=false]",
        "tag": {
          "id": "minecraft:chest"
        }
      },
      {
        "char": "",
        "block": "apocalypsenow:large_shelves[facing=west,waterlogged=false]",
        "tag": {
          "id": "apocalypsenow:large_shelves"
        },
        "loot": "project_deadzone:generic_low_filled"
      }
    ]
  },
  "slices": [
    [
      "",
      "",
      "",
      "",
      "",
      "",
      "",
      "",
      "",
      "",
      "",
      "",
      "",
      "",
      "",
      ""
    ],
    [
      "",
      "",
      "",
      "",
      "",
      "",
      "",
      "",
      "",
      "",
      "",
      "",
      "",
      "",
      "",
      ""
    ],
    [
      "",
      "",
      "",
      "",
      "",
      "",
      "",
      "",
      "",
      "",
      "",
      "",
      "",
      "",
      "",
      ""
    ],
    [
      "",
      "",
      "",
      "",
      "",
      "",
      "",
      "",
      "",
      "",
      "",
      "",
      "",
      "",
      "",
      ""
    ],
    [
      "",
      "",
      "",
      "",
      "",
      "",
      "",
      "",
      "",
      "",
      "",
      "",
      "",
      "",
      "",
      ""
    ],
    [
      "",
      "",
      "",
      "",
      "",
      "",
      "",
      "",
      "",
      "",
      "",
      "",
      "",
      "",
      "",
      ""
    ]
  ]
}
