{
  "xsize": 16,
  "zsize": 16,
  "palette": {
    "palette": [
      {
        "char": "",
        "block": "minecraft:air"
      },
      {
        "char": "",
        "block": "minecraft:dirt"
      },
      {
        "char": "",
        "block": "minecraft:grass_block[snowy=false]"
      },
      {
        "char": "",
        "block": "minecraft:white_concrete"
      },
      {
        "char": "",
        "block": "minecraft:smooth_stone"
      },
      {
        "char": "",
        "block": "apocalypsenow:empty_market_shelves[facing=south,waterlogged=false]",
        "tag": {
          "Items": [],
          "id": "apocalypsenow:empty_market_shelves"
        },
        "loot": "project_deadzone:gasstation_food_t1"
      },
      {
        "char": "",
        "block": "minecraft:red_concrete"
      },
      {
        "char": "",
        "block": "apocalypsenow:paperstrash[facing=west]"
      },
      {
        "char": "",
        "block": "apocalypsenow:papertrashvariant[facing=east]"
      },
      {
        "char": "",
        "block": "apocalypsenow:paperstrashvariant_2[facing=east]"
      },
      {
        "char": "",
        "block": "apocalypsenow:papertrash[facing=west]"
      },
      {
        "char": "",
        "block": "apocalypsenow:empty_market_shelves[facing=north,waterlogged=false]",
        "tag": {
          "Items": [],
          "id": "apocalypsenow:empty_market_shelves"
        },
        "loot": "project_deadzone:gasstation_food_t1"
      },
      {
        "char": "",
        "block": "apocalypsenow:market_shelves[facing=south,waterlogged=false]",
        "tag": {
          "Items": [],
          "id": "apocalypsenow:market_shelves"
        },
        "loot": "project_deadzone:gasstation_food_t1"
      },
      {
        "char": "",
        "block": "apocalypsenow:market_shelves[facing=north,waterlogged=false]",
        "tag": {
          "Items": [],
          "id": "apocalypsenow:market_shelves"
        },
        "loot": "project_deadzone:gasstation_food_t1"
      },
      {
        "char": "",
        "block": "minecraft:smooth_stone_slab[type=top,waterlogged=false]"
      }
    ]
  },
  "slices": [
    [
      "",
      "",
      "",
      "",
      "",
      "",
      "",
      "",
      "",
      "",
      "",
      "",
      "",
      "",
      "",
      ""
    ],
    [
      "",
      "",
      "",
      "",
      "",
      "",
      "",
      "",
      "",
      "",
      "",
      "",
      "",
      "",
      "",
      ""
    ],
    [
      "",
      "",
      "",
      "",
      "",
      "",
      "",
      "",
      "",
      "",
      "",
      "",
      "",
      "",
      "",
      ""
    ],
    [
      "",
      "",
      "",
      "",
      "",
      "",
      "",
      "",
      "",
      "",
      "",
      "",
      "",
      "",
      "",
      ""
    ],
    [
      "",
      "",
      "",
      "",
      "",
      "",
      "",
      "",
      "",
      "",
      "",
      "",
      "",
      "",
      "",
      ""
    ],
    [
      "",
      "",
      "",
      "",
      "",
      "",
      "",
      "",
      "",
      "",
      "",
      "",
      "",
      "",
      "",
      ""
    ]
  ]
}
