{
  "xsize": 16,
  "zsize": 16,
  "palette": {
    "palette": [
      {
        "char": " ",
        "block": "minecraft:air"
      },
      {
        "char": "w",
        "block": "minecraft:air"
      },
      {
        "char": "u",
        "block": "minecraft:air"
      },
      {
        "char": "z",
        "block": "minecraft:air"
      },
      {
        "char": "A",
        "block": "minecraft:air"
      },
      {
        "char": "t",
        "block": "minecraft:air"
      },
      {
        "char": "B",
        "block": "minecraft:air"
      },
      {
        "char": "a",
        "block": "minecraft:air"
      },
      {
        "char": "e",
        "block": "minecraft:air"
      },
      {
        "char": "o",
        "block": "minecraft:air"
      },
      {
        "char": "N",
        "block": "minecraft:air"
      },
      {
        "char": "4",
        "block": "minecraft:air"
      },
      {
        "char": "L",
        "block": "minecraft:air"
      },
      {
        "char": "v",
        "block": "minecraft:grass"
      },
      {
        "char": "p",
        "block": "minecraft:air"
      },
      {
        "char": "g",
        "block": "minecraft:air"
      },
      {
        "char": "P",
        "block": "minecraft:tall_grass[half=lower]"
      },
      {
        "char": "α",
        "block": "minecraft:air"
      },
      {
        "char": "ε",
        "block": "minecraft:air"
      },
      {
        "char": "π",
        "block": "minecraft:air"
      },
      {
        "char": "ά",
        "block": "minecraft:air"
      },
      {
        "char": "V",
        "block": "minecraft:air"
      },
      {
        "char": "8",
        "block": "minecraft:air"
      },
      {
        "char": "d",
        "block": "minecraft:air"
      },
      {
        "char": "Q",
        "block": "minecraft:tall_grass[half=upper]"
      },
      {
        "char": "ϵ",
        "block": "minecraft:air"
      },
      {
        "char": "Ό",
        "block": "minecraft:air"
      },
      {
        "char": ";",
        "block": "minecraft:air"
      }
    ]
  },
  "slices": [
    [
      "wuzwAzwuAzwAwwwt",
      "utwttzwAtuzuztwt",
      "ztAAzAutzwtwuAuw",
      "ttwAwwzAtuAuAuzt",
      "BaeeBeoaBeaaBaae",
      "BeoeBooeBaeeBeea",
      "BeaeBeoeBeeaBooa",
      "BeaooeeaBaaooeee",
      "BoaaBaeeBeaaBeea",
      "eaoeoeeaeeoeeaee",
      "eeoeeeooeeeeeaee",
      "eeeoaaeeeeeeaoae",
      "aeeeeeeooeeeoeoe",
      "eeeeeoaoeeeeeeee",
      "N44NNL4LNNLLoeae",
      "4NN4NLLLo4Noeoee"
    ],
    [
      "                ",
      "                ",
      "                ",
      "                ",
      "      v     p   ",
      "g v  Pv p     p ",
      "α     P      Pv ",
      "g  vv      vP   ",
      " v    p       p ",
      "α v v     v     ",
      "  v   vv       p",
      "   vp      p v  ",
      " p     Pv   ε π ",
      "     v v  p ά   ",
      "p           V p ",
      "8d8dddddvdddVv  "
    ],
    [
      "                ",
      "                ",
      "                ",
      "                ",
      "                ",
      "g    Q          ",
      "      Q      Q  ",
      "g           Q   ",
      "                ",
      "g               ",
      "                ",
      "                ",
      "       Q    ϵ   ",
      "            ε   ",
      "            V   ",
      "8d8dddddddddV   "
    ],
    [
      "                ",
      "                ",
      "                ",
      "                ",
      "                ",
      "                ",
      "                ",
      "                ",
      "                ",
      "g               ",
      "                ",
      "                ",
      "            Ό   ",
      "            ά   ",
      "            V   ",
      "8d8dddddddddV   "
    ],
    [
      "                ",
      "                ",
      "                ",
      "                ",
      "                ",
      "                ",
      "                ",
      "                ",
      "                ",
      "                ",
      "                ",
      "                ",
      "            Ό   ",
      "            ά   ",
      "            V   ",
      "8d8dddddddddV   "
    ],
    [
      "                ",
      "                ",
      "                ",
      "                ",
      "                ",
      "                ",
      "                ",
      "                ",
      "                ",
      "                ",
      "                ",
      "                ",
      "            ;   ",
      "            ;   ",
      "            ;   ",
      "dddddddddddd;   "
    ]
  ]
}