{
  "xsize": 16,
  "zsize": 16,
  "palette": {
    "palette": [
      {
        "char": "",
        "block": "minecraft:air"
      },
      {
        "char": "",
        "block": "minecraft:grass_block[snowy=false]"
      },
      {
        "char": "",
        "block": "minecraft:dirt"
      },
      {
        "char": "",
        "block": "minecraft:smooth_stone"
      },
      {
        "char": "",
        "block": "minecraft:white_concrete"
      },
      {
        "char": "",
        "block": "minecraft:red_concrete"
      },
      {
        "char": "",
        "block": "apocalypsenow:empty_market_shelves[facing=east,waterlogged=false]",
        "tag": {
          "Items": [],
          "id": "apocalypsenow:empty_market_shelves"
        },
        "loot": "project_deadzone:chests/gasstation_food_t1"
      },
      {
        "char": "",
        "block": "minecraft:light_blue_terracotta"
      },
      {
        "char": "",
        "block": "apocalypsenow:ice[facing=east,waterlogged=false]",
        "tag": {
          "Items": [],
          "id": "apocalypsenow:ice"
        }
      },
      {
        "char": "",
        "block": "apocalypsenow:papertrash[facing=south]"
      },
      {
        "char": "",
        "block": "minecraft:chest[facing=west,type=single,waterlogged=false]",
        "tag": {
          "id": "minecraft:chest"
        }
      },
      {
        "char": "",
        "block": "apocalypsenow:papertrash[facing=north]"
      },
      {
        "char": "",
        "block": "apocalypsenow:papersvariant_2[facing=north]"
      },
      {
        "char": "",
        "block": "refurbished_furniture:oak_crate",
        "loot": "project_deadzone:chests/gasstation_food_t1"
      },
      {
        "char": "",
        "block": "minecraft:chest[facing=east,type=single,waterlogged=false]",
        "tag": {
          "id": "minecraft:chest"
        }
      },
      {
        "char": "",
        "block": "apocalypsenow:ice[facing=west,waterlogged=false]",
        "tag": {
          "Items": [],
          "id": "apocalypsenow:ice"
        }
      },
      {
        "char": "",
        "block": "apocalypsenow:papertrashvariant[facing=north]"
      },
      {
        "char": "",
        "block": "apocalypsenow:corpsecloth[facing=east]",
        "tag": {
          "Items": [],
          "id": "apocalypsenow:corpsecloth"
        }
      },
      {
        "char": "",
        "block": "apocalypsenow:market_shelves[facing=east,waterlogged=false]",
        "tag": {
          "Items": [],
          "id": "apocalypsenow:market_shelves"
        },
        "loot": "project_deadzone:chests/gasstation_food_t1"
      },
      {
        "char": "",
        "block": "apocalypsenow:paperstrash[facing=south]"
      },
      {
        "char": "",
        "block": "apocalypsenow:paperstrash[facing=north]"
      },
      {
        "char": "",
        "block": "minecraft:smooth_stone_slab[type=top,waterlogged=false]"
      }
    ]
  },
  "slices": [
    [
      "",
      "",
      "",
      "",
      "",
      "",
      "",
      "",
      "",
      "",
      "",
      "",
      "",
      "",
      "",
      ""
    ],
    [
      "",
      "",
      "",
      "",
      "",
      "",
      "",
      "",
      "",
      "",
      "",
      "",
      "",
      "",
      "",
      ""
    ],
    [
      "",
      "",
      "",
      "",
      "",
      "",
      "",
      "",
      "",
      "",
      "",
      "",
      "",
      "",
      "",
      ""
    ],
    [
      "",
      "",
      "",
      "",
      "",
      "",
      "",
      "",
      "",
      "",
      "",
      "",
      "",
      "",
      "",
      ""
    ],
    [
      "",
      "",
      "",
      "",
      "",
      "",
      "",
      "",
      "",
      "",
      "",
      "",
      "",
      "",
      "",
      ""
    ],
    [
      "",
      "",
      "",
      "",
      "",
      "",
      "",
      "",
      "",
      "",
      "",
      "",
      "",
      "",
      "",
      ""
    ]
  ]
}
