{
  "xsize": 16,
  "zsize": 16,
  "palette": {
    "palette": [
      {
        "char": "",
        "block": "minecraft:air"
      },
      {
        "char": "",
        "block": "minecraft:black_concrete"
      },
      {
        "char": "",
        "block": "minecraft:smooth_stone"
      },
      {
        "char": "",
        "block": "minecraft:red_concrete"
      },
      {
        "char": "",
        "block": "minecraft:oak_leaves[distance=7,persistent=true,waterlogged=false]"
      },
      {
        "char": "",
        "block": "apocalypsenow:papersvariant_2[facing=north]"
      },
      {
        "char": "",
        "block": "apocalypsenow:paperstrash[facing=west]"
      },
      {
        "char": "",
        "block": "apocalypsenow:papertrash[facing=south]"
      },
      {
        "char": "",
        "block": "apocalypsenow:pallet_slab[waterlogged=false]"
      },
      {
        "char": "",
        "block": "apocalypsenow:paperstrash[facing=east]"
      },
      {
        "char": "",
        "block": "apocalypsenow:papertrash[facing=east]"
      },
      {
        "char": "",
        "block": "apocalypsenow:papertrash[facing=north]"
      },
      {
        "char": "",
        "block": "apocalypsenow:papertrashvariant[facing=north]"
      },
      {
        "char": "",
        "block": "apocalypsenow:paperstrashvariant_2[facing=north]"
      },
      {
        "char": "",
        "block": "apocalypsenow:paperstrashvariant_2[facing=south]"
      },
      {
        "char": "",
        "block": "apocalypsenow:redconcretebricks"
      },
      {
        "char": "",
        "block": "minecraft:cobweb"
      },
      {
        "char": "",
        "block": "apocalypsenow:pallet_storage[waterlogged=false]",
        "tag": {
          "Items": [],
          "id": "apocalypsenow:pallet_storage"
        },
        "loot": "project_deadzone:generic_low_filled"
      },
      {
        "char": "",
        "block": "apocalypsenow:paperstrash[facing=south]"
      },
      {
        "char": "",
        "block": "apocalypsenow:paperstrashvariant_2[facing=east]"
      },
      {
        "char": "",
        "block": "apocalypsenow:pallet[waterlogged=false]"
      },
      {
        "char": "",
        "block": "apocalypsenow:paperstrash[facing=north]"
      },
      {
        "char": "",
        "block": "apocalypsenow:papertrashvariant[facing=east]"
      },
      {
        "char": "",
        "block": "minecraft:spruce_slab[type=bottom,waterlogged=false]"
      },
      {
        "char": "",
        "block": "minecraft:spruce_stairs[facing=east,half=bottom,shape=straight,waterlogged=false]"
      },
      {
        "char": "",
        "block": "apocalypsenow:papertrashvariant[facing=south]"
      },
      {
        "char": "",
        "block": "apocalypsenow:papertrash[facing=west]"
      },
      {
        "char": "",
        "block": "refurbished_furniture:oak_crate",
        "loot": "project_deadzone:generic_low_filled"
      }
    ]
  },
  "slices": [
    [
      "",
      "",
      "",
      "",
      "",
      "",
      "",
      "",
      "",
      "",
      "",
      "",
      "",
      "",
      "",
      ""
    ],
    [
      "",
      "",
      "",
      "",
      "",
      "",
      "",
      "",
      "",
      "",
      "",
      "",
      "",
      "",
      "",
      ""
    ],
    [
      "",
      "",
      "",
      "",
      "",
      "",
      "",
      "",
      "",
      "",
      "",
      "",
      "",
      "",
      "",
      ""
    ],
    [
      "",
      "",
      "",
      "",
      "",
      "",
      "",
      "",
      "",
      "",
      "",
      "",
      "",
      "",
      "",
      ""
    ],
    [
      "",
      "",
      "",
      "",
      "",
      "",
      "",
      "",
      "",
      "",
      "",
      "",
      "",
      "",
      "",
      ""
    ],
    [
      "",
      "",
      "",
      "",
      "",
      "",
      "",
      "",
      "",
      "",
      "",
      "",
      "",
      "",
      "",
      ""
    ]
  ]
}
