{
  "xsize": 16,
  "zsize": 16,
  "palette": {
    "palette": [
      {
        "char": "",
        "block": "minecraft:air"
      },
      {
        "char": "",
        "block": "apocalypsenow:redconcretebricks"
      },
      {
        "char": "",
        "block": "minecraft:smooth_stone"
      },
      {
        "char": "",
        "block": "minecraft:red_concrete"
      },
      {
        "char": "",
        "block": "apocalypsenow:papertrashvariant[facing=south]"
      },
      {
        "char": "",
        "block": "apocalypsenow:military_storage[facing=west,waterlogged=false]",
        "tag": {
          "Items": [],
          "id": "apocalypsenow:military_storage"
        },
        "loot": "project_deadzone:generic_high_filled"
      },
      {
        "char": "",
        "block": "minecraft:red_bed[facing=east,occupied=false,part=foot]",
        "tag": {
          "id": "minecraft:bed"
        }
      },
      {
        "char": "",
        "block": "minecraft:red_bed[facing=east,occupied=false,part=head]",
        "tag": {
          "id": "minecraft:bed"
        }
      },
      {
        "char": "",
        "block": "apocalypsenow:papertrash[facing=north]"
      },
      {
        "char": "",
        "block": "apocalypsenow:iron_locker[facing=north,waterlogged=false]",
        "tag": {
          "Items": [],
          "id": "apocalypsenow:iron_locker"
        },
        "loot": "project_deadzone:firestation_equipment"
      },
      {
        "char": "",
        "block": "minecraft:glass_pane[east=false,north=true,south=false,waterlogged=false,west=false]"
      },
      {
        "char": "",
        "block": "minecraft:glass_pane[east=false,north=false,south=true,waterlogged=false,west=false]"
      },
      {
        "char": "",
        "block": "minecraft:glass_pane[east=false,north=true,south=true,waterlogged=false,west=false]"
      },
      {
        "char": "",
        "block": "minecraft:polished_andesite_slab[type=top,waterlogged=false]"
      }
    ]
  },
  "slices": [
    [
      "",
      "",
      "",
      "",
      "",
      "",
      "",
      "",
      "",
      "",
      "",
      "",
      "",
      "",
      "",
      ""
    ],
    [
      "",
      "",
      "",
      "",
      "",
      "",
      "",
      "",
      "",
      "",
      "",
      "",
      "",
      "",
      "",
      ""
    ],
    [
      "",
      "",
      "",
      "",
      "",
      "",
      "",
      "",
      "",
      "",
      "",
      "",
      "",
      "",
      "",
      ""
    ],
    [
      "",
      "",
      "",
      "",
      "",
      "",
      "",
      "",
      "",
      "",
      "",
      "",
      "",
      "",
      "",
      ""
    ],
    [
      "",
      "",
      "",
      "",
      "",
      "",
      "",
      "",
      "",
      "",
      "",
      "",
      "",
      "",
      "",
      ""
    ],
    [
      "",
      "",
      "",
      "",
      "",
      "",
      "",
      "",
      "",
      "",
      "",
      "",
      "",
      "",
      "",
      ""
    ]
  ]
}
