{
  "xsize": 16,
  "zsize": 16,
  "palette": {
    "palette": [
      {
        "char": "",
        "block": "minecraft:air"
      },
      {
        "char": "",
        "block": "minecraft:vine[east=true,north=false,south=true,up=true,west=false]"
      },
      {
        "char": "",
        "block": "minecraft:cyan_terracotta"
      },
      {
        "char": "",
        "block": "minecraft:cracked_stone_bricks"
      },
      {
        "char": "",
        "block": "minecraft:mossy_stone_bricks"
      },
      {
        "char": "",
        "block": "minecraft:stone_bricks[weathering=true]"
      },
      {
        "char": "",
        "block": "minecraft:cobbled_deepslate"
      },
      {
        "char": "",
        "block": "minecraft:stone_bricks[weathering=false]"
      },
      {
        "char": "",
        "block": "minecraft:mossy_cobblestone"
      },
      {
        "char": "",
        "block": "minecraft:grass"
      },
      {
        "char": "",
        "block": "minecraft:deepslate[axis=y]"
      },
      {
        "char": "",
        "block": "minecraft:cobblestone[weathering=false]"
      },
      {
        "char": "",
        "block": "minecraft:basalt[axis=x]"
      },
      {
        "char": "",
        "block": "minecraft:grass_block[snowy=false]"
      }
    ]
  },
  "slices": [
    [
      "",
      "",
      "",
      "",
      "",
      "",
      "",
      "",
      "",
      "",
      "",
      "",
      "",
      "",
      "",
      ""
    ],
    [
      "",
      "",
      "",
      "",
      "",
      "",
      "",
      "",
      "",
      "",
      "",
      "",
      "",
      "",
      "",
      ""
    ],
    [
      "",
      "",
      "",
      "",
      "",
      "",
      "",
      "",
      "",
      "",
      "",
      "",
      "",
      "",
      "",
      ""
    ],
    [
      "",
      "",
      "",
      "",
      "",
      "",
      "",
      "",
      "",
      "",
      "",
      "",
      "",
      "",
      "",
      ""
    ],
    [
      "",
      "",
      "",
      "",
      "",
      "",
      "",
      "",
      "",
      "",
      "",
      "",
      "",
      "",
      "",
      ""
    ],
    [
      "",
      "",
      "",
      "",
      "",
      "",
      "",
      "",
      "",
      "",
      "",
      "",
      "",
      "",
      "",
      ""
    ]
  ]
}