{
  "xsize": 16,
  "zsize": 16,
  "palette": {
    "palette": [
      {
        "char": "",
        "block": "minecraft:air"
      },
      {
        "char": "",
        "block": "minecraft:black_terracotta"
      },
      {
        "char": "",
        "block": "minecraft:stone_button[face=wall,facing=east,powered=false]"
      },
      {
        "char": "",
        "block": "minecraft:stone_button[face=wall,facing=south,powered=false]"
      },
      {
        "char": "",
        "block": "apocalypsenow:prison_door[facing=east,half=upper,hinge=left,open=false,powered=false]"
      },
      {
        "char": "",
        "block": "minecraft:stone_button[face=wall,facing=north,powered=false]"
      },
      {
        "char": "",
        "block": "apocalypsenow:prison_door[facing=east,half=upper,hinge=right,open=false,powered=false]"
      }
    ]
  },
  "slices": [
    [
      "",
      "",
      "",
      "",
      "",
      "",
      "",
      "",
      "",
      "",
      "",
      "",
      "",
      "",
      "",
      ""
    ],
    [
      "",
      "",
      "",
      "",
      "",
      "",
      "",
      "",
      "",
      "",
      "",
      "",
      "",
      "",
      "",
      ""
    ],
    [
      "",
      "",
      "",
      "",
      "",
      "",
      "",
      "",
      "",
      "",
      "",
      "",
      "",
      "",
      "",
      ""
    ],
    [
      "",
      "",
      "",
      "",
      "",
      "",
      "",
      "",
      "",
      "",
      "",
      "",
      "",
      "",
      "",
      ""
    ],
    [
      "",
      "",
      "",
      "",
      "",
      "",
      "",
      "",
      "",
      "",
      "",
      "",
      "",
      "",
      "",
      ""
    ]
  ]
}
