{
  "xsize": 16,
  "zsize": 16,
  "palette": {
    "palette": [
      {
        "char": "",
        "block": "minecraft:air"
      },
      {
        "char": "",
        "block": "apocalypsenow:iron_grid[east=true,north=false,south=true,waterlogged=false,west=false]"
      },
      {
        "char": "",
        "block": "apocalypsenow:iron_grid[east=true,north=false,south=false,waterlogged=false,west=true]"
      },
      {
        "char": "",
        "block": "apocalypsenow:iron_grid[east=false,north=true,south=false,waterlogged=false,west=true]"
      },
      {
        "char": "",
        "block": "apocalypsenow:iron_grid[east=false,north=true,south=true,waterlogged=false,west=false]"
      }
    ]
  },
  "slices": [
    [
      "",
      "",
      "",
      "",
      "",
      "",
      "",
      "",
      "",
      "",
      "",
      "",
      "",
      "",
      "",
      ""
    ],
    [
      "",
      "",
      "",
      "",
      "",
      "",
      "",
      "",
      "",
      "",
      "",
      "",
      "",
      "",
      "",
      ""
    ],
    [
      "",
      "",
      "",
      "",
      "",
      "",
      "",
      "",
      "",
      "",
      "",
      "",
      "",
      "",
      "",
      ""
    ],
    [
      "",
      "",
      "",
      "",
      "",
      "",
      "",
      "",
      "",
      "",
      "",
      "",
      "",
      "",
      "",
      ""
    ]
  ]
}
