{
  "xsize": 16,
  "zsize": 16,
  "palette": {
    "palette": [
      {
        "char": "",
        "block": "minecraft:air"
      },
      {
        "char": "",
        "block": "minecraft:polished_andesite"
      },
      {
        "char": "",
        "block": "apocalypsenow:blue_concrete_bricks"
      },
      {
        "char": "",
        "block": "minecraft:stripped_dark_oak_wood[axis=z]"
      },
      {
        "char": "",
        "block": "minecraft:oak_door[facing=east,half=lower,hinge=right,open=false,powered=false]"
      },
      {
        "char": "",
        "block": "apocalypsenow:papertrash[facing=south]"
      },
      {
        "char": "",
        "block": "apocalypsenow:metalshelvesfive[facing=north,waterlogged=false]",
        "tag": {
          "id": "apocalypsenow:metalshelvesfive"
        },
        "loot": "project_deadzone:chests/generic_low_filled"
      },
      {
        "char": "",
        "block": "apocalypsenow:metal_shelves[facing=north,waterlogged=false]",
        "tag": {
          "Items": [],
          "id": "apocalypsenow:metal_shelves"
        },
        "loot": "project_deadzone:chests/generic_low_filled"
      },
      {
        "char": "",
        "block": "minecraft:dark_oak_stairs[facing=north,half=bottom,shape=straight,waterlogged=false]"
      },
      {
        "char": "",
        "block": "apocalypsenow:paperstrash[facing=north]"
      },
      {
        "char": "",
        "block": "apocalypsenow:corpsesack[facing=north]",
        "tag": {
          "Items": [],
          "id": "apocalypsenow:corpsesack"
        }
      },
      {
        "char": "",
        "block": "apocalypsenow:papersvariant_2[facing=north]"
      },
      {
        "char": "",
        "block": "minecraft:oak_door[facing=east,half=upper,hinge=right,open=false,powered=false]"
      },
      {
        "char": "",
        "block": "apocalypsenow:metalshelvesone[facing=north,waterlogged=false]",
        "tag": {
          "Items": [],
          "id": "apocalypsenow:metalshelvesone"
        },
        "loot": "project_deadzone:chests/generic_low_filled"
      },
      {
        "char": "",
        "block": "apocalypsenow:metelshelvesfour[facing=north,waterlogged=false]",
        "tag": {
          "id": "apocalypsenow:metelshelvesfour"
        },
        "loot": "project_deadzone:chests/generic_low_filled"
      },
      {
        "char": "",
        "block": "apocalypsenow:metal_shelves_three[facing=north,waterlogged=false]",
        "tag": {
          "id": "apocalypsenow:metal_shelves_three"
        },
        "loot": "project_deadzone:chests/generic_low_filled"
      },
      {
        "char": "",
        "block": "minecraft:oak_leaves[distance=7,persistent=true,waterlogged=false]"
      },
      {
        "char": "",
        "block": "minecraft:stripped_dark_oak_wood[axis=y]"
      },
      {
        "char": "",
        "block": "minecraft:stone_slab[type=top,waterlogged=false]"
      }
    ]
  },
  "slices": [
    [
      "",
      "",
      "",
      "",
      "",
      "",
      "",
      "",
      "",
      "",
      "",
      "",
      "",
      "",
      "",
      ""
    ],
    [
      "",
      "",
      "",
      "",
      "",
      "",
      "",
      "",
      "",
      "",
      "",
      "",
      "",
      "",
      "",
      ""
    ],
    [
      "",
      "",
      "",
      "",
      "",
      "",
      "",
      "",
      "",
      "",
      "",
      "",
      "",
      "",
      "",
      ""
    ],
    [
      "",
      "",
      "",
      "",
      "",
      "",
      "",
      "",
      "",
      "",
      "",
      "",
      "",
      "",
      "",
      ""
    ],
    [
      "",
      "",
      "",
      "",
      "",
      "",
      "",
      "",
      "",
      "",
      "",
      "",
      "",
      "",
      "",
      ""
    ],
    [
      "",
      "",
      "",
      "",
      "",
      "",
      "",
      "",
      "",
      "",
      "",
      "",
      "",
      "",
      "",
      ""
    ]
  ]
}
