{
  "xsize": 16,
  "zsize": 16,
  "palette": {
    "palette": [
      {
        "char": "",
        "block": "minecraft:air"
      },
      {
        "char": "",
        "block": "minecraft:smooth_stone"
      },
      {
        "char": "",
        "block": "minecraft:polished_andesite_slab[type=bottom,waterlogged=false]"
      },
      {
        "char": "",
        "block": "minecraft:cyan_terracotta"
      },
      {
        "char": "",
        "block": "minecraft:black_concrete"
      },
      {
        "char": "",
        "block": "minecraft:yellow_terracotta"
      },
      {
        "char": "",
        "block": "apocalypsenow:papertrashvariant[facing=north]"
      },
      {
        "char": "",
        "block": "apocalypsenow:paperstrash[facing=west]"
      },
      {
        "char": "",
        "block": "apocalypsenow:papertrash[facing=south]"
      },
      {
        "char": "",
        "block": "minecraft:redstone_torch[lit=true]"
      },
      {
        "char": "",
        "block": "apocalypsenow:paperstrashvariant_2[facing=west]"
      },
      {
        "char": "",
        "block": "apocalypsenow:paperstrash[facing=north]"
      },
      {
        "char": "",
        "block": "apocalypsenow:paperstrashvariant_2[facing=north]"
      },
      {
        "char": "",
        "block": "apocalypsenow:papertrashvariant[facing=east]"
      },
      {
        "char": "",
        "block": "apocalypsenow:paperstrash[facing=east]"
      },
      {
        "char": "",
        "block": "apocalypsenow:pallet_slab[waterlogged=false]"
      },
      {
        "char": "",
        "block": "apocalypsenow:papertrash[facing=west]"
      }
    ]
  },
  "slices": [
    [
      "",
      "",
      "",
      "",
      "",
      "",
      "",
      "",
      "",
      "",
      "",
      "",
      "",
      "",
      "",
      ""
    ],
    [
      "",
      "",
      "",
      "",
      "",
      "",
      "",
      "",
      "",
      "",
      "",
      "",
      "",
      "",
      "",
      ""
    ],
    [
      "",
      "",
      "",
      "",
      "",
      "",
      "",
      "",
      "",
      "",
      "",
      "",
      "",
      "",
      "",
      ""
    ],
    [
      "",
      "",
      "",
      "",
      "",
      "",
      "",
      "",
      "",
      "",
      "",
      "",
      "",
      "",
      "",
      ""
    ],
    [
      "",
      "",
      "",
      "",
      "",
      "",
      "",
      "",
      "",
      "",
      "",
      "",
      "",
      "",
      "",
      ""
    ],
    [
      "",
      "",
      "",
      "",
      "",
      "",
      "",
      "",
      "",
      "",
      "",
      "",
      "",
      "",
      "",
      ""
    ]
  ]
}
