{
  "xsize": 16,
  "zsize": 16,
  "palette": {
    "palette": [
      {
        "char": "",
        "block": "minecraft:air"
      },
      {
        "char": "",
        "block": "minecraft:brick_stairs[facing=east,half=bottom,shape=straight,waterlogged=false]"
      },
      {
        "char": "",
        "block": "minecraft:spruce_planks"
      },
      {
        "char": "",
        "block": "minecraft:brick_stairs[facing=north,half=bottom,shape=outer_right,waterlogged=false]"
      },
      {
        "char": "",
        "block": "minecraft:brick_stairs[facing=north,half=bottom,shape=straight,waterlogged=false]"
      },
      {
        "char": "",
        "block": "minecraft:bricks"
      },
      {
        "char": "",
        "block": "minecraft:brick_stairs[facing=west,half=bottom,shape=straight,waterlogged=false]"
      },
      {
        "char": "",
        "block": "apocalypsenow:mossbricks"
      },
      {
        "char": "",
        "block": "apocalypsenow:mosstairs[facing=east,half=bottom,shape=straight,waterlogged=false]"
      },
      {
        "char": "",
        "block": "minecraft:brick_stairs[facing=east,half=bottom,shape=outer_left,waterlogged=false]"
      },
      {
        "char": "",
        "block": "minecraft:brick_stairs[facing=south,half=bottom,shape=inner_right,waterlogged=false]"
      },
      {
        "char": "",
        "block": "minecraft:brick_stairs[facing=south,half=bottom,shape=inner_left,waterlogged=false]"
      },
      {
        "char": "",
        "block": "minecraft:brick_stairs[facing=north,half=bottom,shape=outer_left,waterlogged=false]"
      }
    ]
  },
  "slices": [
    [
      "",
      "",
      "",
      "",
      "",
      "",
      "",
      "",
      "",
      "",
      "",
      "",
      "",
      "",
      "",
      ""
    ],
    [
      "",
      "",
      "",
      "",
      "",
      "",
      "",
      "",
      "",
      "",
      "",
      "",
      "",
      "",
      "",
      ""
    ],
    [
      "",
      "",
      "",
      "",
      "",
      "",
      "",
      "",
      "",
      "",
      "",
      "",
      "",
      "",
      "",
      ""
    ],
    [
      "",
      "",
      "",
      "",
      "",
      "",
      "",
      "",
      "",
      "",
      "",
      "",
      "",
      "",
      "",
      ""
    ],
    [
      "",
      "",
      "",
      "",
      "",
      "",
      "",
      "",
      "",
      "",
      "",
      "",
      "",
      "",
      "",
      ""
    ],
    [
      "",
      "",
      "",
      "",
      "",
      "",
      "",
      "",
      "",
      "",
      "",
      "",
      "",
      "",
      "",
      ""
    ]
  ]
}
