{
  "xsize": 16,
  "zsize": 16,
  "palette": {
    "palette": [
      {
        "char": "",
        "block": "minecraft:air"
      },
      {
        "char": "",
        "block": "minecraft:grass_block[snowy=false]"
      },
      {
        "char": "",
        "block": "minecraft:dirt"
      },
      {
        "char": "",
        "block": "minecraft:smooth_stone"
      },
      {
        "char": "",
        "block": "minecraft:white_concrete"
      },
      {
        "char": "",
        "block": "minecraft:red_concrete"
      },
      {
        "char": "",
        "block": "apocalypsenow:market_shelves[facing=west,waterlogged=false]",
        "tag": {
          "Items": [],
          "id": "apocalypsenow:market_shelves"
        },
        "loot": "project_deadzone:gasstation_food_t1"
      },
      {
        "char": "",
        "block": "minecraft:chest[facing=west,type=single,waterlogged=false]",
        "tag": {
          "id": "minecraft:chest"
        }
      },
      {
        "char": "",
        "block": "apocalypsenow:papertrashvariant[facing=south]"
      },
      {
        "char": "",
        "block": "apocalypsenow:empty_market_shelves[facing=west,waterlogged=false]",
        "tag": {
          "Items": [],
          "id": "apocalypsenow:empty_market_shelves"
        },
        "loot": "project_deadzone:gasstation_food_t1"
      },
      {
        "char": "",
        "block": "apocalypsenow:papertrash[facing=north]"
      },
      {
        "char": "",
        "block": "refurbished_furniture:oak_crate",
        "loot": "project_deadzone:gasstation_food_t1"
      },
      {
        "char": "",
        "block": "apocalypsenow:papersvariant_2[facing=south]"
      },
      {
        "char": "",
        "block": "apocalypsenow:corpsecloth[facing=south]",
        "tag": {
          "Items": [],
          "id": "apocalypsenow:corpsecloth"
        }
      },
      {
        "char": "",
        "block": "apocalypsenow:washing_machine[facing=north]",
        "tag": {
          "Items": [],
          "id": "apocalypsenow:washing_machine"
        }
      },
      {
        "char": "",
        "block": "minecraft:smooth_stone_slab[type=top,waterlogged=false]"
      }
    ]
  },
  "slices": [
    [
      "",
      "",
      "",
      "",
      "",
      "",
      "",
      "",
      "",
      "",
      "",
      "",
      "",
      "",
      "",
      ""
    ],
    [
      "",
      "",
      "",
      "",
      "",
      "",
      "",
      "",
      "",
      "",
      "",
      "",
      "",
      "",
      "",
      ""
    ],
    [
      "",
      "",
      "",
      "",
      "",
      "",
      "",
      "",
      "",
      "",
      "",
      "",
      "",
      "",
      "",
      ""
    ],
    [
      "",
      "",
      "",
      "",
      "",
      "",
      "",
      "",
      "",
      "",
      "",
      "",
      "",
      "",
      "",
      ""
    ],
    [
      "",
      "",
      "",
      "",
      "",
      "",
      "",
      "",
      "",
      "",
      "",
      "",
      "",
      "",
      "",
      ""
    ],
    [
      "",
      "",
      "",
      "",
      "",
      "",
      "",
      "",
      "",
      "",
      "",
      "",
      "",
      "",
      "",
      ""
    ]
  ]
}
