{
  "xsize": 16,
  "zsize": 16,
  "palette": {
    "palette": [
      {
        "char": " ",
        "block": "minecraft:air"
      },
      {
        "char": "t",
        "block": "minecraft:air"
      },
      {
        "char": "z",
        "block": "minecraft:air"
      },
      {
        "char": "w",
        "block": "minecraft:air"
      },
      {
        "char": "A",
        "block": "minecraft:air"
      },
      {
        "char": "u",
        "block": "minecraft:air"
      },
      {
        "char": "B",
        "block": "minecraft:air"
      },
      {
        "char": "a",
        "block": "minecraft:air"
      },
      {
        "char": "e",
        "block": "minecraft:air"
      },
      {
        "char": "o",
        "block": "minecraft:air"
      },
      {
        "char": "Γ",
        "block": "minecraft:air"
      },
      {
        "char": "0",
        "block": "minecraft:air"
      },
      {
        "char": "N",
        "block": "minecraft:air"
      },
      {
        "char": "L",
        "block": "minecraft:air"
      },
      {
        "char": "4",
        "block": "minecraft:air"
      },
      {
        "char": "p",
        "block": "minecraft:air"
      },
      {
        "char": "v",
        "block": "minecraft:grass"
      },
      {
        "char": "d",
        "block": "minecraft:air"
      },
      {
        "char": "j",
        "block": "minecraft:air"
      },
      {
        "char": "υ",
        "block": "minecraft:air"
      },
      {
        "char": "΄",
        "block": "minecraft:air"
      },
      {
        "char": "Η",
        "block": "minecraft:air"
      },
      {
        "char": "ξ",
        "block": "minecraft:air"
      },
      {
        "char": "I",
        "block": "minecraft:air"
      },
      {
        "char": "P",
        "block": "minecraft:tall_grass[half=lower]"
      },
      {
        "char": "i",
        "block": "minecraft:air"
      },
      {
        "char": "π",
        "block": "minecraft:air"
      },
      {
        "char": "ϲ",
        "block": "minecraft:air"
      },
      {
        "char": "Z",
        "block": "minecraft:air"
      },
      {
        "char": "ͳ",
        "block": "minecraft:air"
      },
      {
        "char": "Q",
        "block": "minecraft:tall_grass[half=upper]"
      },
      {
        "char": "ψ",
        "block": "minecraft:air",
        "loot": "project_deadzone:gunstore",
        "tag": {
          "z": 701,
          "x": 198,
          "ForgeData": {
            "LockFlag": "1b"
          },
          "ForgeCaps": {},
          "id": "minecraft:chest",
          "y": 133,
          "Items": []
        }
      },
      {
        "char": "Ϝ",
        "block": "minecraft:air"
      },
      {
        "char": "ϣ",
        "block": "minecraft:air"
      },
      {
        "char": "Ϸ",
        "block": "minecraft:air"
      },
      {
        "char": "ϧ",
        "block": "minecraft:air"
      },
      {
        "char": "ϗ",
        "block": "minecraft:air"
      },
      {
        "char": "Ώ",
        "block": "minecraft:air"
      },
      {
        "char": "Ϩ",
        "block": "minecraft:air"
      },
      {
        "char": "3",
        "block": "minecraft:air"
      },
      {
        "char": "ϛ",
        "block": "minecraft:air"
      },
      {
        "char": "Ϲ",
        "block": "minecraft:air"
      }
    ]
  },
  "slices": [
    [
      "tztzwtAztAAzAAtw",
      "tzutztuuwutzuwtt",
      "wttuAwwAuuzwwwut",
      "ztwuwwtwwzutuAwA",
      "zuttBaaeBeoeBeaa",
      "wwwzBeeeBaaeBeee",
      "uwwABaeeBeeeBeeΓ",
      "twzzBaeaBeeeoeee",
      "zttABeeaBaeeBoee",
      "wuwAeeeoeeeeeeeΓ",
      "uuuAoeaoeao00eee",
      "uwuAeooeaoee0aee",
      "AAAuoeoeeeoeaeee",
      "tuuteoeeaeoeaeoe",
      "zAAuNLNLNNLLNLLL",
      "zztAL44NLoL4NN4o"
    ],
    [
      "                ",
      "                ",
      "                ",
      "                ",
      "        p v    d",
      "            jυ΄Η",
      "      pp p  ξI I",
      "          p v΄ ΄",
      "         p  j΄ ΄",
      "       v    ξI I",
      "    v  Pp vpjΗΗυ",
      "     vP  v     i",
      "    P v p v p  p",
      "     P    v   π ",
      "     p    p   p ",
      "       ddvdd d v"
    ],
    [
      "                ",
      "                ",
      "                ",
      "                ",
      "              ϲd",
      "            jZZZ",
      "            jZͳZ",
      "             ZͳZ",
      "            jͳͳͳ",
      "            jͳͳͳ",
      "       Q    jZψZ",
      "      Q       Ϝi",
      "    Q           ",
      "     Q          ",
      "                ",
      "       ddddd d d"
    ],
    [
      "                ",
      "                ",
      "                ",
      "                ",
      "                ",
      "              ϣ ",
      "             Ϸϧϗ",
      "             Ώ Ώ",
      "             Ώ Ώ",
      "            jZZZ",
      "             iϨi",
      "                ",
      "                ",
      "                ",
      "                ",
      "       ddddd d d"
    ],
    [
      "                ",
      "                ",
      "                ",
      "                ",
      "                ",
      "                ",
      "             333",
      "             3ϛ3",
      "             3Ϲ3",
      "             333",
      "                ",
      "                ",
      "                ",
      "                ",
      "                ",
      "       ddddd d d"
    ],
    [
      "                ",
      "                ",
      "                ",
      "                ",
      "                ",
      "                ",
      "                ",
      "                ",
      "                ",
      "                ",
      "                ",
      "                ",
      "                ",
      "                ",
      "                ",
      "       ddddd d d"
    ]
  ]
}