{
  "xsize": 16,
  "zsize": 16,
  "palette": {
    "palette": [
      {
        "char": "",
        "block": "minecraft:air"
      },
      {
        "char": "",
        "block": "minecraft:polished_andesite"
      },
      {
        "char": "",
        "block": "apocalypsenow:blue_concrete_bricks"
      },
      {
        "char": "",
        "block": "minecraft:oak_leaves[distance=7,persistent=true,waterlogged=false]"
      },
      {
        "char": "",
        "block": "minecraft:smooth_quartz_stairs[facing=north,half=bottom,shape=straight,waterlogged=false]"
      },
      {
        "char": "",
        "block": "minecraft:cauldron"
      },
      {
        "char": "",
        "block": "apocalypsenow:paperstrash[facing=north]"
      },
      {
        "char": "",
        "block": "minecraft:quartz_slab[type=top,waterlogged=false]"
      },
      {
        "char": "",
        "block": "minecraft:dark_oak_door[facing=west,half=lower,hinge=right,open=false,powered=false]"
      },
      {
        "char": "",
        "block": "apocalypsenow:papersvariant_2[facing=east]"
      },
      {
        "char": "",
        "block": "minecraft:quartz_slab[type=double,waterlogged=false]"
      },
      {
        "char": "",
        "block": "apocalypsenow:washing_machine[facing=south]",
        "tag": {
          "Items": [],
          "id": "apocalypsenow:washing_machine"
        }
      },
      {
        "char": "",
        "block": "apocalypsenow:medical_storage[facing=west,waterlogged=false]",
        "tag": {
          "Items": [],
          "id": "apocalypsenow:medical_storage"
        },
        "loot": "project_deadzone:chests/hospital_pharmacy"
      },
      {
        "char": "",
        "block": "minecraft:dark_oak_door[facing=west,half=upper,hinge=right,open=false,powered=false]"
      },
      {
        "char": "",
        "block": "minecraft:glass_pane[east=false,north=true,south=true,waterlogged=false,west=false]"
      },
      {
        "char": "",
        "block": "minecraft:stone_slab[type=top,waterlogged=false]"
      }
    ]
  },
  "slices": [
    [
      "",
      "",
      "",
      "",
      "",
      "",
      "",
      "",
      "",
      "",
      "",
      "",
      "",
      "",
      "",
      ""
    ],
    [
      "",
      "",
      "",
      "",
      "",
      "",
      "",
      "",
      "",
      "",
      "",
      "",
      "",
      "",
      "",
      ""
    ],
    [
      "",
      "",
      "",
      "",
      "",
      "",
      "",
      "",
      "",
      "",
      "",
      "",
      "",
      "",
      "",
      ""
    ],
    [
      "",
      "",
      "",
      "",
      "",
      "",
      "",
      "",
      "",
      "",
      "",
      "",
      "",
      "",
      "",
      ""
    ],
    [
      "",
      "",
      "",
      "",
      "",
      "",
      "",
      "",
      "",
      "",
      "",
      "",
      "",
      "",
      "",
      ""
    ],
    [
      "",
      "",
      "",
      "",
      "",
      "",
      "",
      "",
      "",
      "",
      "",
      "",
      "",
      "",
      "",
      ""
    ]
  ]
}
