{
  "xsize": 16,
  "zsize": 16,
  "palette": {
    "palette": [
      {
        "char": " ",
        "block": "minecraft:air"
      },
      {
        "char": "m",
        "block": "minecraft:air"
      },
      {
        "char": "b",
        "block": "minecraft:air"
      },
      {
        "char": "g",
        "block": "minecraft:air"
      },
      {
        "char": "X",
        "block": "minecraft:air"
      },
      {
        "char": "i",
        "block": "minecraft:air"
      },
      {
        "char": "a",
        "block": "minecraft:air"
      },
      {
        "char": "c",
        "block": "minecraft:air"
      },
      {
        "char": "o",
        "block": "minecraft:air"
      },
      {
        "char": "T",
        "block": "minecraft:air"
      },
      {
        "char": "H",
        "block": "minecraft:air"
      },
      {
        "char": "Ϡ",
        "block": "minecraft:air"
      },
      {
        "char": "v",
        "block": "minecraft:grass"
      },
      {
        "char": "ϐ",
        "block": "minecraft:air"
      }
    ]
  },
  "slices": [
    [
      "mmmmmmmmmmmm    ",
      "bbbmbbbbbbbmg   ",
      "bbbmbbbbbbbm    ",
      "bbbmbbbbbbbmg   ",
      "bbbmbbbXbbbmg   ",
      "bbbmbbbbbbbmg   ",
      "mmmmbbbbbbbm    ",
      "bbbmbbbbbbbm    ",
      "bbbmbbbXbbbm    ",
      "bbbmbbbbbbbmg   ",
      "bbbmbbbbbbbm    ",
      "bbbmbbbbbbbmg   ",
      "mmmmmmmmmmmm    ",
      "i      i  i     ",
      "                ",
      "                "
    ],
    [
      "acaaacacaocaT   ",
      "ccccaacccaocT   ",
      "accaaccaccacT   ",
      "caaaccaaccaaT   ",
      "accccaccccaaT   ",
      "aaacaaacaacaT   ",
      "aaaccaccaaaaT   ",
      "ccaaccacaaccT   ",
      "ccaccccaoccaT   ",
      "ccacaaaaccacT   ",
      "accacccccoaaT   ",
      "caccccccoccaT   ",
      "acaacaccaacaT   ",
      "HHHHHHHHHHHHϠ   ",
      "                ",
      "                "
    ],
    [
      "         v      ",
      "          v     ",
      "                ",
      "                ",
      "                ",
      "                ",
      "                ",
      "                ",
      "        v       ",
      "                ",
      "         ϐ      ",
      "        v       ",
      "                ",
      "                ",
      "                ",
      "                "
    ],
    [
      "                ",
      "                ",
      "                ",
      "                ",
      "                ",
      "                ",
      "                ",
      "                ",
      "                ",
      "                ",
      "                ",
      "                ",
      "                ",
      "                ",
      "                ",
      "                "
    ],
    [
      "                ",
      "                ",
      "                ",
      "                ",
      "                ",
      "                ",
      "                ",
      "                ",
      "                ",
      "                ",
      "                ",
      "                ",
      "                ",
      "                ",
      "                ",
      "                "
    ],
    [
      "                ",
      "                ",
      "                ",
      "                ",
      "                ",
      "                ",
      "                ",
      "                ",
      "                ",
      "                ",
      "                ",
      "                ",
      "                ",
      "                ",
      "                ",
      "                "
    ]
  ]
}