{
  "xsize": 16,
  "zsize": 16,
  "palette": {
    "palette": [
      {
        "char": "",
        "block": "minecraft:air"
      },
      {
        "char": "",
        "block": "minecraft:dirt"
      },
      {
        "char": "",
        "block": "minecraft:blackstone"
      },
      {
        "char": "",
        "block": "minecraft:cobbled_deepslate"
      },
      {
        "char": "",
        "block": "minecraft:grass_block[snowy=false]"
      },
      {
        "char": "",
        "block": "minecraft:basalt[axis=x]"
      },
      {
        "char": "",
        "block": "minecraft:cyan_terracotta"
      },
      {
        "char": "",
        "block": "minecraft:deepslate[axis=y]"
      },
      {
        "char": "",
        "block": "minecraft:spawner",
        "tag": {
          "MaxNearbyEntities": 6,
          "RequiredPlayerRange": 16,
          "SpawnCount": 4,
          "SpawnData": {
            "entity": {}
          },
          "MaxSpawnDelay": 800,
          "id": "minecraft:mob_spawner",
          "SpawnRange": 4,
          "Delay": 88,
          "MinSpawnDelay": 200,
          "SpawnPotentials": []
        }
      },
      {
        "char": "",
        "block": "minecraft:polished_diorite"
      },
      {
        "char": "",
        "block": "minecraft:quartz_block"
      },
      {
        "char": "",
        "block": "minecraft:diorite"
      },
      {
        "char": "",
        "block": "minecraft:stone_bricks[weathering=false]"
      },
      {
        "char": "",
        "block": "minecraft:green_terracotta"
      },
      {
        "char": "",
        "block": "minecraft:cracked_stone_bricks"
      },
      {
        "char": "",
        "block": "minecraft:grass"
      },
      {
        "char": "",
        "block": "minecraft:cornflower"
      },
      {
        "char": "",
        "block": "immersive_weathering:weathered_iron_bars[east=false,north=false,south=true,waterlogged=false,west=true]"
      },
      {
        "char": "",
        "block": "minecraft:mossy_stone_bricks"
      },
      {
        "char": "",
        "block": "immersive_weathering:weathered_iron_bars[east=false,north=true,south=false,waterlogged=false,west=true]"
      },
      {
        "char": "",
        "block": "minecraft:cobblestone_slab[type=bottom,waterlogged=false,weathering=false]"
      },
      {
        "char": "",
        "block": "immersive_weathering:weathered_iron_bars[east=false,north=true,south=true,waterlogged=false,west=false]"
      },
      {
        "char": "",
        "block": "minecraft:cobbled_deepslate_stairs[facing=north,half=bottom,shape=straight,waterlogged=false]"
      },
      {
        "char": "",
        "block": "minecraft:blackstone_stairs[facing=north,half=bottom,shape=straight,waterlogged=false]"
      },
      {
        "char": "",
        "block": "minecraft:mossy_cobblestone"
      },
      {
        "char": "",
        "block": "minecraft:stone_button[face=floor,facing=east,powered=false]"
      },
      {
        "char": "",
        "block": "minecraft:stone_button[face=floor,facing=north,powered=false]"
      },
      {
        "char": "",
        "block": "minecraft:stone_button[face=floor,facing=south,powered=false]"
      },
      {
        "char": "",
        "block": "minecraft:oak_trapdoor[facing=west,half=bottom,open=false,powered=false,waterlogged=false]"
      },
      {
        "char": "",
        "block": "immersive_weathering:weathered_iron_bars[east=true,north=true,south=true,waterlogged=false,west=false]"
      },
      {
        "char": "",
        "block": "immersive_weathering:weathered_iron_bars[east=false,north=false,south=false,waterlogged=false,west=true]"
      },
      {
        "char": "",
        "block": "immersive_weathering:weathered_iron_bars[east=false,north=true,south=false,waterlogged=false,west=false]"
      },
      {
        "char": "",
        "block": "minecraft:vine[east=false,north=true,south=false,up=false,west=false]"
      },
      {
        "char": "",
        "block": "minecraft:mossy_stone_brick_wall[east=low,north=none,south=none,up=true,waterlogged=false,west=none]"
      },
      {
        "char": "",
        "block": "minecraft:mossy_stone_brick_wall[east=low,north=none,south=none,up=false,waterlogged=false,west=low]"
      },
      {
        "char": "",
        "block": "minecraft:mossy_stone_brick_wall[east=none,north=none,south=none,up=true,waterlogged=false,west=low]"
      },
      {
        "char": "",
        "block": "decocraft:security_camera_black[facing=south]",
        "tag": {
          "meta": {
            "shape": "security_camera_black",
            "hidden": 0,
            "culling": 1,
            "tabs": "tech",
            "decoref": "security_camera_black",
            "scale": 1.0,
            "type": "animated",
            "material": "security_camera_black",
            "passable": 0,
            "transparency": 0,
            "name": "Security Camera Black",
            "model": "security_camera",
            "default_animation": "animation.camera_idle"
          },
          "model": {
            "animationsPerName.values[0]": {
              "snapping": 24,
              "saved": 0,
              "length": 8.0,
              "anim_time_update": "",
              "uuid": "8d2e1b70-e872-8cbd-1769-ea045e55dc9c",
              "path": "",
              "start_delay": "",
              "blend_weight": "",
              "loop": "loop",
              "name": "animation.camera_swivel",
              "loop_delay": "",
              "override": 0,
              "selected": 0
            },
            "animationsPerName.values[1]": {
              "snapping": 25,
              "saved": 0,
              "length": 0.0,
              "anim_time_update": "",
              "uuid": "edf17c1f-8c1a-d686-5e07-6fb64a1f6e9c",
              "path": "",
              "start_delay": "",
              "blend_weight": "",
              "loop": "loop",
              "name": "animation.camera_idle",
              "loop_delay": "",
              "override": 0,
              "selected": 0
            },
            "name": "security_camera",
            "animationsPerName.size": 2,
            "animationsPerName.keys[0]": "animation.camera_swivel",
            "animationsPerName.keys[1]": "animation.camera_idle"
          },
          "isUnmodifiable": 1,
          "id": "decocraft:decocraft_animated",
          "animName": "animation.camera_idle"
        }
      },
      {
        "char": "",
        "block": "minecraft:smooth_stone_slab[type=top,waterlogged=false]"
      },
      {
        "char": "",
        "block": "minecraft:cobblestone[weathering=false]"
      },
      {
        "char": "",
        "block": "minecraft:yellow_concrete"
      },
      {
        "char": "",
        "block": "minecraft:quartz_stairs[facing=west,half=top,shape=straight,waterlogged=false]"
      },
      {
        "char": "",
        "block": "minecraft:quartz_stairs[facing=east,half=bottom,shape=straight,waterlogged=false]"
      },
      {
        "char": "",
        "block": "minecraft:cobblestone[weathering=true]"
      }
    ]
  },
  "slices": [
    [
      "",
      "",
      "",
      "",
      "",
      "",
      "",
      "",
      "",
      "",
      "",
      "",
      "",
      "",
      "",
      ""
    ],
    [
      "",
      "",
      "",
      "",
      "",
      "",
      "",
      "",
      "",
      "",
      "",
      "",
      "",
      "",
      "",
      ""
    ],
    [
      "",
      "",
      "",
      "",
      "",
      "",
      "",
      "",
      "",
      "",
      "",
      "",
      "",
      "",
      "",
      ""
    ],
    [
      "",
      "",
      "",
      "",
      "",
      "",
      "",
      "",
      "",
      "",
      "",
      "",
      "",
      "",
      "",
      ""
    ],
    [
      "",
      "",
      "",
      "",
      "",
      "",
      "",
      "",
      "",
      "",
      "",
      "",
      "",
      "",
      "",
      ""
    ],
    [
      "",
      "",
      "",
      "",
      "",
      "",
      "",
      "",
      "",
      "",
      "",
      "",
      "",
      "",
      "",
      ""
    ],
    [
      "",
      "",
      "",
      "",
      "",
      "",
      "",
      "",
      "",
      "",
      "",
      "",
      "",
      "",
      "",
      ""
    ],
    [
      "",
      "",
      "",
      "",
      "",
      "",
      "",
      "",
      "",
      "",
      "",
      "",
      "",
      "",
      "",
      ""
    ],
    [
      "",
      "",
      "",
      "",
      "",
      "",
      "",
      "",
      "",
      "",
      "",
      "",
      "",
      "",
      "",
      ""
    ],
    [
      "",
      "",
      "",
      "",
      "",
      "",
      "",
      "",
      "",
      "",
      "",
      "",
      "",
      "",
      "",
      ""
    ],
    [
      "",
      "",
      "",
      "",
      "",
      "",
      "",
      "",
      "",
      "",
      "",
      "",
      "",
      "",
      "",
      ""
    ],
    [
      "",
      "",
      "",
      "",
      "",
      "",
      "",
      "",
      "",
      "",
      "",
      "",
      "",
      "",
      "",
      ""
    ],
    [
      "",
      "",
      "",
      "",
      "",
      "",
      "",
      "",
      "",
      "",
      "",
      "",
      "",
      "",
      "",
      ""
    ],
    [
      "",
      "",
      "",
      "",
      "",
      "",
      "",
      "",
      "",
      "",
      "",
      "",
      "",
      "",
      "",
      ""
    ],
    [
      "",
      "",
      "",
      "",
      "",
      "",
      "",
      "",
      "",
      "",
      "",
      "",
      "",
      "",
      "",
      ""
    ],
    [
      "",
      "",
      "",
      "",
      "",
      "",
      "",
      "",
      "",
      "",
      "",
      "",
      "",
      "",
      "",
      ""
    ],
    [
      "",
      "",
      "",
      "",
      "",
      "",
      "",
      "",
      "",
      "",
      "",
      "",
      "",
      "",
      "",
      ""
    ],
    [
      "",
      "",
      "",
      "",
      "",
      "",
      "",
      "",
      "",
      "",
      "",
      "",
      "",
      "",
      "",
      ""
    ],
    [
      "",
      "",
      "",
      "",
      "",
      "",
      "",
      "",
      "",
      "",
      "",
      "",
      "",
      "",
      "",
      ""
    ],
    [
      "",
      "",
      "",
      "",
      "",
      "",
      "",
      "",
      "",
      "",
      "",
      "",
      "",
      "",
      "",
      ""
    ],
    [
      "",
      "",
      "",
      "",
      "",
      "",
      "",
      "",
      "",
      "",
      "",
      "",
      "",
      "",
      "",
      ""
    ],
    [
      "",
      "",
      "",
      "",
      "",
      "",
      "",
      "",
      "",
      "",
      "",
      "",
      "",
      "",
      "",
      ""
    ],
    [
      "",
      "",
      "",
      "",
      "",
      "",
      "",
      "",
      "",
      "",
      "",
      "",
      "",
      "",
      "",
      ""
    ],
    [
      "",
      "",
      "",
      "",
      "",
      "",
      "",
      "",
      "",
      "",
      "",
      "",
      "",
      "",
      "",
      ""
    ],
    [
      "",
      "",
      "",
      "",
      "",
      "",
      "",
      "",
      "",
      "",
      "",
      "",
      "",
      "",
      "",
      ""
    ],
    [
      "",
      "",
      "",
      "",
      "",
      "",
      "",
      "",
      "",
      "",
      "",
      "",
      "",
      "",
      "",
      ""
    ],
    [
      "",
      "",
      "",
      "",
      "",
      "",
      "",
      "",
      "",
      "",
      "",
      "",
      "",
      "",
      "",
      ""
    ],
    [
      "",
      "",
      "",
      "",
      "",
      "",
      "",
      "",
      "",
      "",
      "",
      "",
      "",
      "",
      "",
      ""
    ],
    [
      "",
      "",
      "",
      "",
      "",
      "",
      "",
      "",
      "",
      "",
      "",
      "",
      "",
      "",
      "",
      ""
    ],
    [
      "",
      "",
      "",
      "",
      "",
      "",
      "",
      "",
      "",
      "",
      "",
      "",
      "",
      "",
      "",
      ""
    ]
  ]
}