{
  "xsize": 16,
  "zsize": 16,
  "palette": {
    "palette": [
      {
        "char": "",
        "block": "minecraft:air"
      },
      {
        "char": "",
        "block": "minecraft:black_wool"
      },
      {
        "char": "",
        "block": "minecraft:white_wool"
      },
      {
        "char": "",
        "block": "minecraft:red_wool"
      },
      {
        "char": "",
        "block": "framedblocks:framed_double_slab[glowing=false,propagates_skylight=false,solid=true]",
        "tag": {
          "intangible": 0,
          "glowing": 0,
          "camo_two": {
            "state": {
              "Name": "minecraft:white_wool"
            },
            "type": "framedblocks:block"
          },
          "id": "framedblocks:framed_double_slab",
          "reinforced": 0,
          "updated": 3,
          "camo": {
            "state": {
              "Name": "minecraft:red_wool"
            },
            "type": "framedblocks:block"
          }
        }
      },
      {
        "char": "",
        "block": "framedblocks:framed_double_slab[glowing=false,propagates_skylight=false,solid=true]",
        "tag": {
          "intangible": 0,
          "glowing": 0,
          "camo_two": {
            "state": {
              "Name": "minecraft:red_wool"
            },
            "type": "framedblocks:block"
          },
          "id": "framedblocks:framed_double_slab",
          "reinforced": 0,
          "updated": 3,
          "camo": {
            "state": {
              "Name": "minecraft:white_wool"
            },
            "type": "framedblocks:block"
          }
        }
      },
      {
        "char": "",
        "block": "immersive_weathering:exposed_iron_bars[east=false,north=true,south=false,waterlogged=false,west=false]"
      },
      {
        "char": "",
        "block": "immersive_weathering:exposed_iron_bars[east=true,north=true,south=false,waterlogged=false,west=false]"
      },
      {
        "char": "",
        "block": "immersive_weathering:exposed_iron_bars[east=true,north=true,south=false,waterlogged=false,west=true]"
      }
    ]
  },
  "slices": [
    [
      "",
      "",
      "",
      "",
      "",
      "",
      "",
      "",
      "",
      "",
      "",
      "",
      "",
      "",
      "",
      ""
    ],
    [
      "",
      "",
      "",
      "",
      "",
      "",
      "",
      "",
      "",
      "",
      "",
      "",
      "",
      "",
      "",
      ""
    ],
    [
      "",
      "",
      "",
      "",
      "",
      "",
      "",
      "",
      "",
      "",
      "",
      "",
      "",
      "",
      "",
      ""
    ],
    [
      "",
      "",
      "",
      "",
      "",
      "",
      "",
      "",
      "",
      "",
      "",
      "",
      "",
      "",
      "",
      ""
    ],
    [
      "",
      "",
      "",
      "",
      "",
      "",
      "",
      "",
      "",
      "",
      "",
      "",
      "",
      "",
      "",
      ""
    ],
    [
      "",
      "",
      "",
      "",
      "",
      "",
      "",
      "",
      "",
      "",
      "",
      "",
      "",
      "",
      "",
      ""
    ]
  ]
}