{
  "xsize": 16,
  "zsize": 16,
  "palette": {
    "palette": [
      {
        "char": "",
        "block": "minecraft:air"
      },
      {
        "char": "",
        "block": "apocalypsenow:redconcretebricks"
      },
      {
        "char": "",
        "block": "minecraft:red_concrete"
      },
      {
        "char": "",
        "block": "minecraft:cobweb"
      },
      {
        "char": "",
        "block": "minecraft:iron_bars[east=false,north=false,south=false,waterlogged=false,west=false]"
      },
      {
        "char": "",
        "block": "minecraft:smooth_stone"
      },
      {
        "char": "",
        "block": "minecraft:polished_andesite_slab[type=top,waterlogged=false]"
      },
      {
        "char": "",
        "block": "minecraft:yellow_concrete"
      },
      {
        "char": "",
        "block": "minecraft:stone"
      },
      {
        "char": "",
        "block": "apocalypsenow:papertrashvariant[facing=east]"
      },
      {
        "char": "",
        "block": "apocalypsenow:papertrashvariant[facing=south]"
      },
      {
        "char": "",
        "block": "apocalypsenow:papertrash[facing=north]"
      },
      {
        "char": "",
        "block": "minecraft:oak_leaves[distance=7,persistent=true,waterlogged=false]"
      },
      {
        "char": "",
        "block": "apocalypsenow:paperstrash[facing=south]"
      },
      {
        "char": "",
        "block": "minecraft:polished_andesite_stairs[facing=east,half=bottom,shape=straight,waterlogged=false]"
      },
      {
        "char": "",
        "block": "minecraft:glass_pane[east=false,north=true,south=false,waterlogged=false,west=false]"
      },
      {
        "char": "",
        "block": "minecraft:glass_pane[east=false,north=false,south=true,waterlogged=false,west=false]"
      },
      {
        "char": "",
        "block": "minecraft:glass_pane[east=false,north=true,south=true,waterlogged=false,west=false]"
      }
    ]
  },
  "slices": [
    [
      "",
      "",
      "",
      "",
      "",
      "",
      "",
      "",
      "",
      "",
      "",
      "",
      "",
      "",
      "",
      ""
    ],
    [
      "",
      "",
      "",
      "",
      "",
      "",
      "",
      "",
      "",
      "",
      "",
      "",
      "",
      "",
      "",
      ""
    ],
    [
      "",
      "",
      "",
      "",
      "",
      "",
      "",
      "",
      "",
      "",
      "",
      "",
      "",
      "",
      "",
      ""
    ],
    [
      "",
      "",
      "",
      "",
      "",
      "",
      "",
      "",
      "",
      "",
      "",
      "",
      "",
      "",
      "",
      ""
    ],
    [
      "",
      "",
      "",
      "",
      "",
      "",
      "",
      "",
      "",
      "",
      "",
      "",
      "",
      "",
      "",
      ""
    ],
    [
      "",
      "",
      "",
      "",
      "",
      "",
      "",
      "",
      "",
      "",
      "",
      "",
      "",
      "",
      "",
      ""
    ]
  ]
}
