{
  "xsize": 16,
  "zsize": 16,
  "palette": {
    "palette": [
      {
        "char": "",
        "block": "minecraft:air"
      },
      {
        "char": "",
        "block": "minecraft:polished_diorite"
      },
      {
        "char": "",
        "block": "apocalypsenow:white_concrete_bricks"
      },
      {
        "char": "",
        "block": "minecraft:spruce_planks"
      },
      {
        "char": "",
        "block": "minecraft:oak_leaves[distance=7,persistent=true,waterlogged=false]"
      },
      {
        "char": "",
        "block": "minecraft:white_concrete"
      },
      {
        "char": "",
        "block": "minecraft:polished_diorite_slab[type=top,waterlogged=false]"
      },
      {
        "char": "",
        "block": "minecraft:light_blue_terracotta"
      },
      {
        "char": "",
        "block": "minecraft:spruce_slab[type=top,waterlogged=false]"
      },
      {
        "char": "",
        "block": "minecraft:prismarine_brick_stairs[facing=east,half=bottom,shape=straight,waterlogged=false]"
      },
      {
        "char": "",
        "block": "minecraft:moss_carpet"
      },
      {
        "char": "",
        "block": "apocalypsenow:corpsecloth[facing=east]",
        "tag": {
          "Items": [],
          "id": "apocalypsenow:corpsecloth"
        }
      },
      {
        "char": "",
        "block": "minecraft:bookshelf",
        "loot": "project_deadzone:hospital_emergency"
      },
      {
        "char": "",
        "block": "minecraft:spruce_stairs[facing=west,half=top,shape=straight,waterlogged=false]"
      },
      {
        "char": "",
        "block": "minecraft:spruce_stairs[facing=east,half=top,shape=straight,waterlogged=false]"
      },
      {
        "char": "",
        "block": "minecraft:dark_oak_door[facing=west,half=lower,hinge=right,open=false,powered=false]"
      },
      {
        "char": "",
        "block": "minecraft:light_blue_stained_glass_pane[east=false,north=true,south=true,waterlogged=false,west=false]"
      },
      {
        "char": "",
        "block": "minecraft:chest[facing=south,type=single,waterlogged=false]",
        "tag": {
          "id": "minecraft:chest"
        }
      },
      {
        "char": "",
        "block": "minecraft:dark_oak_door[facing=west,half=upper,hinge=right,open=false,powered=false]"
      },
      {
        "char": "",
        "block": "minecraft:spruce_slab[type=bottom,waterlogged=false]"
      },
      {
        "char": "",
        "block": "apocalypsenow:broken_plasma_tv[facing=east]"
      },
      {
        "char": "",
        "block": "minecraft:stripped_spruce_wood[axis=z]"
      },
      {
        "char": "",
        "block": "minecraft:smooth_stone_slab[type=bottom,waterlogged=false]"
      },
      {
        "char": "",
        "block": "minecraft:stripped_spruce_wood[axis=x]"
      }
    ]
  },
  "slices": [
    [
      "",
      "",
      "",
      "",
      "",
      "",
      "",
      "",
      "",
      "",
      "",
      "",
      "",
      "",
      "",
      ""
    ],
    [
      "",
      "",
      "",
      "",
      "",
      "",
      "",
      "",
      "",
      "",
      "",
      "",
      "",
      "",
      "",
      ""
    ],
    [
      "",
      "",
      "",
      "",
      "",
      "",
      "",
      "",
      "",
      "",
      "",
      "",
      "",
      "",
      "",
      ""
    ],
    [
      "",
      "",
      "",
      "",
      "",
      "",
      "",
      "",
      "",
      "",
      "",
      "",
      "",
      "",
      "",
      ""
    ],
    [
      "",
      "",
      "",
      "",
      "",
      "",
      "",
      "",
      "",
      "",
      "",
      "",
      "",
      "",
      "",
      ""
    ],
    [
      "",
      "",
      "",
      "",
      "",
      "",
      "",
      "",
      "",
      "",
      "",
      "",
      "",
      "",
      "",
      ""
    ]
  ]
}
