{
  "xsize": 16,
  "zsize": 16,
  "palette": {
    "palette": [
      {
        "char": "",
        "block": "minecraft:air"
      },
      {
        "char": "",
        "block": "minecraft:smooth_stone"
      },
      {
        "char": "",
        "block": "minecraft:yellow_concrete"
      },
      {
        "char": "",
        "block": "minecraft:polished_andesite_slab[type=bottom,waterlogged=false]"
      },
      {
        "char": "",
        "block": "apocalypsenow:papertrash[facing=east]"
      },
      {
        "char": "",
        "block": "apocalypsenow:papersvariant_2[facing=west]"
      },
      {
        "char": "",
        "block": "apocalypsenow:paperstrashvariant_2[facing=west]"
      },
      {
        "char": "",
        "block": "apocalypsenow:papertrashvariant[facing=south]"
      },
      {
        "char": "",
        "block": "apocalypsenow:cyan_petrol_barrel[facing=east]",
        "tag": {
          "fluidTank": {
            "FluidName": "minecraft:empty",
            "Amount": 0
          },
          "Items": [],
          "id": "apocalypsenow:cyan_petrol_barrel"
        }
      },
      {
        "char": "",
        "block": "apocalypsenow:papertrash[facing=north]"
      },
      {
        "char": "",
        "block": "apocalypsenow:papertrash[facing=south]"
      },
      {
        "char": "",
        "block": "apocalypsenow:papertrashvariant[facing=east]"
      },
      {
        "char": "",
        "block": "apocalypsenow:papersvariant_2[facing=east]"
      },
      {
        "char": "",
        "block": "apocalypsenow:paperstrash[facing=east]"
      },
      {
        "char": "",
        "block": "apocalypsenow:papertrash[facing=west]"
      },
      {
        "char": "",
        "block": "apocalypsenow:paperstrash[facing=north]"
      }
    ]
  },
  "slices": [
    [
      "",
      "",
      "",
      "",
      "",
      "",
      "",
      "",
      "",
      "",
      "",
      "",
      "",
      "",
      "",
      ""
    ],
    [
      "",
      "",
      "",
      "",
      "",
      "",
      "",
      "",
      "",
      "",
      "",
      "",
      "",
      "",
      "",
      ""
    ],
    [
      "",
      "",
      "",
      "",
      "",
      "",
      "",
      "",
      "",
      "",
      "",
      "",
      "",
      "",
      "",
      ""
    ],
    [
      "",
      "",
      "",
      "",
      "",
      "",
      "",
      "",
      "",
      "",
      "",
      "",
      "",
      "",
      "",
      ""
    ],
    [
      "",
      "",
      "",
      "",
      "",
      "",
      "",
      "",
      "",
      "",
      "",
      "",
      "",
      "",
      "",
      ""
    ],
    [
      "",
      "",
      "",
      "",
      "",
      "",
      "",
      "",
      "",
      "",
      "",
      "",
      "",
      "",
      "",
      ""
    ]
  ]
}
