{
  "xsize": 16,
  "zsize": 16,
  "palette": {
    "palette": [
      {
        "char": " ",
        "block": "minecraft:air"
      },
      {
        "char": "m",
        "block": "minecraft:air"
      },
      {
        "char": "b",
        "block": "minecraft:air"
      },
      {
        "char": "j",
        "block": "minecraft:air"
      },
      {
        "char": "X",
        "block": "minecraft:air"
      },
      {
        "char": "i",
        "block": "minecraft:air"
      },
      {
        "char": "U",
        "block": "minecraft:air"
      },
      {
        "char": "c",
        "block": "minecraft:air"
      },
      {
        "char": "a",
        "block": "minecraft:air"
      },
      {
        "char": "o",
        "block": "minecraft:air"
      },
      {
        "char": "Ϣ",
        "block": "minecraft:air"
      },
      {
        "char": "H",
        "block": "minecraft:air"
      },
      {
        "char": "v",
        "block": "minecraft:grass"
      },
      {
        "char": "F",
        "block": "minecraft:air"
      },
      {
        "char": "γ",
        "block": "minecraft:air"
      },
      {
        "char": "R",
        "block": "minecraft:air"
      },
      {
        "char": "J",
        "block": "minecraft:air"
      },
      {
        "char": "ϋ",
        "block": "minecraft:air"
      },
      {
        "char": "Ε",
        "block": "minecraft:air"
      }
    ]
  },
  "slices": [
    [
      "       mmmmmmmmm",
      "       mbbbbbbbb",
      "      jmbbbbbbbb",
      "       mbbbbbbbb",
      "       mbbbXbbbX",
      "       mbbbbbbbb",
      "      jmmmmmmmmm",
      "      jmbbbbbmbb",
      "       mbbbXbmbX",
      "       mbbbbbmbb",
      "       mbbbbbmbb",
      "       mbbbbbmbb",
      "       mmmmmmmmm",
      "       iiii   i ",
      "                ",
      "                "
    ],
    [
      "      Ucccccccaa",
      "      Uaccccacca",
      "      Uacocacaaa",
      "      Uaaccccacc",
      "      Uaacccaoca",
      "      Uccacaacca",
      "      Ucccaacaac",
      "      Uaacacacac",
      "      Ucaaccaccc",
      "      Uaaaccccca",
      "      Uaoccaacaa",
      "      Uccaacacac",
      "      Uaccaooacc",
      "      ϢHHHHHHHHH",
      "                ",
      "                "
    ],
    [
      "                ",
      "                ",
      "         v      ",
      "                ",
      "             v  ",
      "                ",
      "                ",
      "                ",
      "                ",
      "       F        ",
      "        v       ",
      "                ",
      "          Fvv   ",
      "                ",
      "                ",
      "                "
    ],
    [
      "                ",
      "                ",
      "                ",
      "                ",
      "                ",
      "                ",
      "                ",
      "                ",
      "                ",
      "       F        ",
      "                ",
      "                ",
      "          F     ",
      "                ",
      "                ",
      "                "
    ],
    [
      "                ",
      "                ",
      "                ",
      "                ",
      "                ",
      "                ",
      "                ",
      "                ",
      "                ",
      "       F        ",
      "       γ        ",
      "                ",
      "         γF     ",
      "                ",
      "                ",
      "                "
    ],
    [
      "                ",
      "                ",
      "                ",
      "                ",
      "                ",
      "                ",
      "                ",
      "                ",
      "      RJ        ",
      "       RJ       ",
      "        Rϋ      ",
      "         RJ     ",
      "          RJ    ",
      "           Ε    ",
      "                ",
      "                "
    ]
  ]
}