{
  "xsize": 16,
  "zsize": 16,
  "palette": {
    "palette": [
      {
        "char": "",
        "block": "minecraft:air"
      },
      {
        "char": "",
        "block": "minecraft:gray_concrete"
      },
      {
        "char": "",
        "block": "apocalypsenow:concrete_bricks"
      },
      {
        "char": "",
        "block": "apocalypsenow:large_shelves[facing=north,waterlogged=false]",
        "tag": {
          "id": "apocalypsenow:large_shelves"
        },
        "loot": "project_deadzone:generic_mid_filled"
      },
      {
        "char": "",
        "block": "apocalypsenow:white_concrete_bricks"
      },
      {
        "char": "",
        "block": "apocalypsenow:large_shelves_fill[facing=north,waterlogged=false]",
        "tag": {
          "id": "apocalypsenow:large_shelves_fill"
        },
        "loot": "project_deadzone:generic_mid_filled"
      },
      {
        "char": "",
        "block": "apocalypsenow:black_concrete_bricks"
      }
    ]
  },
  "slices": [
    [
      "",
      "",
      "",
      "",
      "",
      "",
      "",
      "",
      "",
      "",
      "",
      "",
      "",
      "",
      "",
      ""
    ],
    [
      "",
      "",
      "",
      "",
      "",
      "",
      "",
      "",
      "",
      "",
      "",
      "",
      "",
      "",
      "",
      ""
    ],
    [
      "",
      "",
      "",
      "",
      "",
      "",
      "",
      "",
      "",
      "",
      "",
      "",
      "",
      "",
      "",
      ""
    ],
    [
      "",
      "",
      "",
      "",
      "",
      "",
      "",
      "",
      "",
      "",
      "",
      "",
      "",
      "",
      "",
      ""
    ],
    [
      "",
      "",
      "",
      "",
      "",
      "",
      "",
      "",
      "",
      "",
      "",
      "",
      "",
      "",
      "",
      ""
    ],
    [
      "",
      "",
      "",
      "",
      "",
      "",
      "",
      "",
      "",
      "",
      "",
      "",
      "",
      "",
      "",
      ""
    ]
  ]
}
