{
  "xsize": 16,
  "zsize": 16,
  "palette": {
    "palette": [
      {
        "char": "",
        "block": "minecraft:air"
      },
      {
        "char": "",
        "block": "apocalypsenow:iron_grid[east=false,north=true,south=true,waterlogged=false,west=false]"
      },
      {
        "char": "",
        "block": "apocalypsenow:iron_grid[east=true,north=true,south=false,waterlogged=false,west=false]"
      },
      {
        "char": "",
        "block": "apocalypsenow:iron_grid[east=true,north=false,south=false,waterlogged=false,west=true]"
      },
      {
        "char": "",
        "block": "apocalypsenow:iron_grid[east=false,north=false,south=true,waterlogged=false,west=true]"
      },
      {
        "char": "",
        "block": "minecraft:polished_andesite"
      },
      {
        "char": "",
        "block": "apocalypsenow:iron_grid_door[facing=south,half=upper,hinge=right,open=false,powered=false]"
      },
      {
        "char": "",
        "block": "apocalypsenow:iron_grid[east=true,north=false,south=true,waterlogged=false,west=false]"
      },
      {
        "char": "",
        "block": "apocalypsenow:iron_grid[east=false,north=true,south=false,waterlogged=false,west=true]"
      }
    ]
  },
  "slices": [
    [
      "",
      "",
      "",
      "",
      "",
      "",
      "",
      "",
      "",
      "",
      "",
      "",
      "",
      "",
      "",
      ""
    ],
    [
      "",
      "",
      "",
      "",
      "",
      "",
      "",
      "",
      "",
      "",
      "",
      "",
      "",
      "",
      "",
      ""
    ],
    [
      "",
      "",
      "",
      "",
      "",
      "",
      "",
      "",
      "",
      "",
      "",
      "",
      "",
      "",
      "",
      ""
    ],
    [
      "",
      "",
      "",
      "",
      "",
      "",
      "",
      "",
      "",
      "",
      "",
      "",
      "",
      "",
      "",
      ""
    ]
  ]
}
