{
  "xsize": 16,
  "zsize": 16,
  "palette": {
    "palette": [
      {
        "char": "",
        "block": "minecraft:air"
      },
      {
        "char": "",
        "block": "minecraft:vine[east=false,north=true,south=false,up=false,west=false]"
      },
      {
        "char": "",
        "block": "decocraft:security_camera_black[facing=south]",
        "tag": {
          "meta": {
            "shape": "security_camera_black",
            "hidden": 0,
            "culling": 1,
            "tabs": "tech",
            "decoref": "security_camera_black",
            "scale": 1.0,
            "type": "animated",
            "material": "security_camera_black",
            "passable": 0,
            "transparency": 0,
            "name": "Security Camera Black",
            "model": "security_camera",
            "default_animation": "animation.camera_idle"
          },
          "model": {
            "animationsPerName.values[0]": {
              "snapping": 24,
              "saved": 0,
              "length": 8.0,
              "anim_time_update": "",
              "uuid": "8d2e1b70-e872-8cbd-1769-ea045e55dc9c",
              "path": "",
              "start_delay": "",
              "blend_weight": "",
              "loop": "loop",
              "name": "animation.camera_swivel",
              "loop_delay": "",
              "override": 0,
              "selected": 0
            },
            "animationsPerName.values[1]": {
              "snapping": 25,
              "saved": 0,
              "length": 0.0,
              "anim_time_update": "",
              "uuid": "edf17c1f-8c1a-d686-5e07-6fb64a1f6e9c",
              "path": "",
              "start_delay": "",
              "blend_weight": "",
              "loop": "loop",
              "name": "animation.camera_idle",
              "loop_delay": "",
              "override": 0,
              "selected": 0
            },
            "name": "security_camera",
            "animationsPerName.size": 2,
            "animationsPerName.keys[0]": "animation.camera_swivel",
            "animationsPerName.keys[1]": "animation.camera_idle"
          },
          "isUnmodifiable": 1,
          "id": "decocraft:decocraft_animated",
          "animName": "animation.camera_idle"
        }
      },
      {
        "char": "",
        "block": "minecraft:vine[east=false,north=true,south=false,up=true,west=false]"
      }
    ]
  },
  "slices": [
    [
      "",
      "",
      "",
      "",
      "",
      "",
      "",
      "",
      "",
      "",
      "",
      "",
      "",
      "",
      "",
      ""
    ],
    [
      "",
      "",
      "",
      "",
      "",
      "",
      "",
      "",
      "",
      "",
      "",
      "",
      "",
      "",
      "",
      ""
    ],
    [
      "",
      "",
      "",
      "",
      "",
      "",
      "",
      "",
      "",
      "",
      "",
      "",
      "",
      "",
      "",
      ""
    ],
    [
      "",
      "",
      "",
      "",
      "",
      "",
      "",
      "",
      "",
      "",
      "",
      "",
      "",
      "",
      "",
      ""
    ],
    [
      "",
      "",
      "",
      "",
      "",
      "",
      "",
      "",
      "",
      "",
      "",
      "",
      "",
      "",
      "",
      ""
    ],
    [
      "",
      "",
      "",
      "",
      "",
      "",
      "",
      "",
      "",
      "",
      "",
      "",
      "",
      "",
      "",
      ""
    ]
  ]
}