{
  "xsize": 16,
  "zsize": 16,
  "palette": {
    "palette": [
      {
        "char": "",
        "block": "minecraft:air"
      },
      {
        "char": "",
        "block": "minecraft:polished_andesite"
      },
      {
        "char": "",
        "block": "apocalypsenow:blue_concrete_bricks"
      },
      {
        "char": "",
        "block": "minecraft:oak_leaves[distance=7,persistent=true,waterlogged=false]"
      },
      {
        "char": "",
        "block": "apocalypsenow:papertrash[facing=south]"
      },
      {
        "char": "",
        "block": "minecraft:glass_pane[east=false,north=false,south=true,waterlogged=false,west=false]"
      },
      {
        "char": "",
        "block": "minecraft:glass_pane[east=false,north=true,south=true,waterlogged=false,west=false]"
      },
      {
        "char": "",
        "block": "minecraft:glass_pane[east=true,north=false,south=false,waterlogged=false,west=false]"
      },
      {
        "char": "",
        "block": "minecraft:glass_pane[east=true,north=false,south=false,waterlogged=false,west=true]"
      },
      {
        "char": "",
        "block": "minecraft:glass_pane[east=false,north=true,south=false,waterlogged=false,west=true]"
      },
      {
        "char": "",
        "block": "minecraft:stone_slab[type=top,waterlogged=false]"
      },
      {
        "char": "",
        "block": "minecraft:polished_andesite_stairs[facing=south,half=top,shape=outer_left,waterlogged=false]"
      },
      {
        "char": "",
        "block": "minecraft:polished_andesite_stairs[facing=south,half=top,shape=straight,waterlogged=false]"
      },
      {
        "char": "",
        "block": "minecraft:polished_andesite_stairs[facing=east,half=top,shape=straight,waterlogged=false]"
      },
      {
        "char": "",
        "block": "apocalypsenow:iron_grid[east=true,north=false,south=true,waterlogged=false,west=false]"
      },
      {
        "char": "",
        "block": "apocalypsenow:iron_grid[east=true,north=false,south=false,waterlogged=false,west=true]"
      },
      {
        "char": "",
        "block": "apocalypsenow:iron_grid[east=false,north=true,south=true,waterlogged=false,west=false]"
      },
      {
        "char": "",
        "block": "minecraft:light_blue_terracotta"
      }
    ]
  },
  "slices": [
    [
      "",
      "",
      "",
      "",
      "",
      "",
      "",
      "",
      "",
      "",
      "",
      "",
      "",
      "",
      "",
      ""
    ],
    [
      "",
      "",
      "",
      "",
      "",
      "",
      "",
      "",
      "",
      "",
      "",
      "",
      "",
      "",
      "",
      ""
    ],
    [
      "",
      "",
      "",
      "",
      "",
      "",
      "",
      "",
      "",
      "",
      "",
      "",
      "",
      "",
      "",
      ""
    ],
    [
      "",
      "",
      "",
      "",
      "",
      "",
      "",
      "",
      "",
      "",
      "",
      "",
      "",
      "",
      "",
      ""
    ],
    [
      "",
      "",
      "",
      "",
      "",
      "",
      "",
      "",
      "",
      "",
      "",
      "",
      "",
      "",
      "",
      ""
    ],
    [
      "",
      "",
      "",
      "",
      "",
      "",
      "",
      "",
      "",
      "",
      "",
      "",
      "",
      "",
      "",
      ""
    ]
  ]
}
