{
  "xsize": 16,
  "zsize": 16,
  "palette": {
    "palette": [
      {
        "char": "",
        "block": "minecraft:air"
      },
      {
        "char": "",
        "block": "minecraft:quartz_pillar[axis=y]"
      },
      {
        "char": "",
        "block": "minecraft:smooth_stone_slab[type=top,waterlogged=false]"
      },
      {
        "char": "",
        "block": "minecraft:vine[east=false,north=false,south=false,up=false,west=true]"
      },
      {
        "char": "",
        "block": "minecraft:redstone_lamp[lit=false]"
      },
      {
        "char": "",
        "block": "minecraft:vine[east=false,north=true,south=false,up=false,west=false]"
      },
      {
        "char": "",
        "block": "minecraft:andesite"
      },
      {
        "char": "",
        "block": "minecraft:polished_andesite"
      },
      {
        "char": "",
        "block": "minecraft:grass_block[snowy=false]"
      },
      {
        "char": "",
        "block": "infectious:barbed_wire[facing=south,waterlogged=false]"
      },
      {
        "char": "",
        "block": "immersive_weathering:cracked_deepslate_tile_wall[east=none,north=none,south=tall,up=true,waterlogged=false,west=none]"
      },
      {
        "char": "",
        "block": "minecraft:grass"
      },
      {
        "char": "",
        "block": "doomsday_decoration:sandbag_4[facing=south,waterlogged=false]"
      },
      {
        "char": "",
        "block": "doomsday_decoration:sandbag[facing=south,waterlogged=false]"
      },
      {
        "char": "",
        "block": "doomsday_decoration:sandbag_3[facing=south,waterlogged=false]"
      },
      {
        "char": "",
        "block": "immersive_weathering:exposed_iron_bars[east=false,north=true,south=false,waterlogged=false,west=false]"
      },
      {
        "char": "",
        "block": "horror_element_mod:marine_body[facing=south,waterlogged=false]"
      },
      {
        "char": "",
        "block": "doomsday_decoration:sandbag_4[facing=west,waterlogged=false]"
      },
      {
        "char": "",
        "block": "doomsday_decoration:sandbag[facing=west,waterlogged=false]"
      },
      {
        "char": "",
        "block": "infectious:barbed_wire[facing=west,waterlogged=false]"
      },
      {
        "char": "",
        "block": "doomsday_decoration:floodlight[facing=west,waterlogged=false]"
      },
      {
        "char": "",
        "block": "doomsday_decoration:sandbag_3[facing=west,waterlogged=false]"
      },
      {
        "char": "",
        "block": "minecraft:azure_bluet"
      },
      {
        "char": "",
        "block": "infectious:barbed_wire[facing=north,waterlogged=false]"
      },
      {
        "char": "",
        "block": "minecraft:black_wool"
      },
      {
        "char": "",
        "block": "minecraft:red_wool"
      },
      {
        "char": "",
        "block": "minecraft:white_wool"
      }
    ]
  },
  "slices": [
    [
      "",
      "",
      "",
      "",
      "",
      "",
      "",
      "",
      "",
      "",
      "",
      "",
      "",
      "",
      "",
      ""
    ],
    [
      "",
      "",
      "",
      "",
      "",
      "",
      "",
      "",
      "",
      "",
      "",
      "",
      "",
      "",
      "",
      ""
    ],
    [
      "",
      "",
      "",
      "",
      "",
      "",
      "",
      "",
      "",
      "",
      "",
      "",
      "",
      "",
      "",
      ""
    ],
    [
      "",
      "",
      "",
      "",
      "",
      "",
      "",
      "",
      "",
      "",
      "",
      "",
      "",
      "",
      "",
      ""
    ],
    [
      "",
      "",
      "",
      "",
      "",
      "",
      "",
      "",
      "",
      "",
      "",
      "",
      "",
      "",
      "",
      ""
    ],
    [
      "",
      "",
      "",
      "",
      "",
      "",
      "",
      "",
      "",
      "",
      "",
      "",
      "",
      "",
      "",
      ""
    ]
  ]
}