{
  "xsize": 16,
  "zsize": 16,
  "palette": {
    "palette": [
      {
        "char": "",
        "block": "minecraft:air"
      },
      {
        "char": "",
        "block": "minecraft:vine[east=false,north=false,south=true,up=true,west=false]"
      },
      {
        "char": "",
        "block": "minecraft:cobweb"
      },
      {
        "char": "",
        "block": "minecraft:polished_andesite"
      },
      {
        "char": "",
        "block": "minecraft:vine[east=false,north=false,south=false,up=false,west=true]"
      },
      {
        "char": "",
        "block": "minecraft:smooth_quartz"
      },
      {
        "char": "",
        "block": "minecraft:vine[east=false,north=true,south=false,up=false,west=false]"
      },
      {
        "char": "",
        "block": "minecraft:vine[east=true,north=true,south=false,up=false,west=false]"
      },
      {
        "char": "",
        "block": "minecraft:diorite"
      },
      {
        "char": "",
        "block": "minecraft:white_concrete"
      },
      {
        "char": "",
        "block": "immersive_weathering:mossy_stone"
      },
      {
        "char": "",
        "block": "minecraft:spruce_stairs[facing=west,half=top,shape=inner_left,waterlogged=false]"
      },
      {
        "char": "",
        "block": "minecraft:spruce_stairs[facing=south,half=top,shape=straight,waterlogged=false]"
      },
      {
        "char": "",
        "block": "minecraft:smoker[facing=north,lit=false]",
        "tag": {
          "CookTime": 0,
          "ForgeData": {
            "LockFlag": 1
          },
          "BurnTime": 0,
          "ForgeCaps": {
            "polymorph:block_entity_recipe_data": {}
          },
          "Items": [],
          "id": "minecraft:smoker",
          "CookTimeTotal": 0,
          "RecipesUsed": {}
        }
      },
      {
        "char": "",
        "block": "cfm:stripped_oak_bedside_cabinet[facing=south,open=false]",
        "tag": {
          "Items": [],
          "id": "cfm:bedside_cabinet"
        }
      },
      {
        "char": "",
        "block": "minecraft:stone[weathering=false]"
      },
      {
        "char": "",
        "block": "minecraft:zombie_head[rotation=2]",
        "tag": {
          "id": "minecraft:skull"
        }
      },
      {
        "char": "",
        "block": "minecraft:zombie_head[rotation=15]",
        "tag": {
          "id": "minecraft:skull"
        }
      },
      {
        "char": "",
        "block": "minecraft:vine[east=false,north=false,south=true,up=false,west=false]"
      },
      {
        "char": "",
        "block": "minecraft:oak_leaves[distance=7,persistent=true,waterlogged=false]"
      },
      {
        "char": "",
        "block": "minecraft:gray_stained_glass"
      },
      {
        "char": "",
        "block": "minecraft:vine[east=false,north=true,south=false,up=true,west=false]"
      },
      {
        "char": "",
        "block": "minecraft:polished_andesite_slab[type=bottom,waterlogged=false]"
      },
      {
        "char": "",
        "block": "minecraft:stone_slab[type=bottom,waterlogged=false,weathering=false]"
      }
    ]
  },
  "slices": [
    [
      "",
      "",
      "",
      "",
      "",
      "",
      "",
      "",
      "",
      "",
      "",
      "",
      "",
      "",
      "",
      ""
    ],
    [
      "",
      "",
      "",
      "",
      "",
      "",
      "",
      "",
      "",
      "",
      "",
      "",
      "",
      "",
      "",
      ""
    ],
    [
      "",
      "",
      "",
      "",
      "",
      "",
      "",
      "",
      "",
      "",
      "",
      "",
      "",
      "",
      "",
      ""
    ],
    [
      "",
      "",
      "",
      "",
      "",
      "",
      "",
      "",
      "",
      "",
      "",
      "",
      "",
      "",
      "",
      ""
    ],
    [
      "",
      "",
      "",
      "",
      "",
      "",
      "",
      "",
      "",
      "",
      "",
      "",
      "",
      "",
      "",
      ""
    ],
    [
      "",
      "",
      "",
      "",
      "",
      "",
      "",
      "",
      "",
      "",
      "",
      "",
      "",
      "",
      "",
      ""
    ]
  ]
}