{
  "xsize": 16,
  "zsize": 16,
  "palette": {
    "palette": [
      {
        "char": "",
        "block": "minecraft:air"
      },
      {
        "char": "",
        "block": "minecraft:vine[east=true,north=false,south=false,up=false,west=false]"
      },
      {
        "char": "",
        "block": "minecraft:oak_leaves[distance=7,persistent=true,waterlogged=false]"
      },
      {
        "char": "",
        "block": "minecraft:vine[east=false,north=false,south=true,up=true,west=false]"
      },
      {
        "char": "",
        "block": "minecraft:vine[east=true,north=false,south=false,up=true,west=false]"
      },
      {
        "char": "",
        "block": "minecraft:diorite"
      },
      {
        "char": "",
        "block": "minecraft:vine[east=false,north=false,south=true,up=false,west=true]"
      },
      {
        "char": "",
        "block": "minecraft:vine[east=false,north=false,south=true,up=false,west=false]"
      },
      {
        "char": "",
        "block": "immersive_weathering:exposed_iron_bars[east=true,north=false,south=false,waterlogged=false,west=false]"
      },
      {
        "char": "",
        "block": "minecraft:loom[facing=west]"
      },
      {
        "char": "",
        "block": "minecraft:gray_stained_glass"
      },
      {
        "char": "",
        "block": "minecraft:smooth_quartz"
      },
      {
        "char": "",
        "block": "minecraft:stone_slab[type=bottom,waterlogged=false,weathering=false]"
      },
      {
        "char": "",
        "block": "minecraft:vine[east=false,north=true,south=false,up=false,west=false]"
      },
      {
        "char": "",
        "block": "minecraft:polished_andesite"
      },
      {
        "char": "",
        "block": "minecraft:vine[east=false,north=true,south=false,up=false,west=true]"
      },
      {
        "char": "",
        "block": "minecraft:stone[weathering=false]"
      },
      {
        "char": "",
        "block": "minecraft:polished_andesite_slab[type=bottom,waterlogged=false]"
      },
      {
        "char": "",
        "block": "immersive_weathering:exposed_iron_bars[east=false,north=true,south=false,waterlogged=false,west=false]"
      },
      {
        "char": "",
        "block": "minecraft:white_concrete"
      },
      {
        "char": "",
        "block": "immersive_weathering:mossy_stone"
      },
      {
        "char": "",
        "block": "immersive_weathering:exposed_iron_bars[east=false,north=false,south=false,waterlogged=false,west=false]"
      },
      {
        "char": "",
        "block": "minecraft:vine[east=false,north=false,south=false,up=true,west=false]"
      },
      {
        "char": "",
        "block": "minecraft:stone[weathering=true]"
      },
      {
        "char": "",
        "block": "minecraft:vine[east=false,north=true,south=false,up=true,west=false]"
      },
      {
        "char": "",
        "block": "immersive_weathering:exposed_iron_bars[east=true,north=true,south=true,waterlogged=false,west=false]"
      },
      {
        "char": "",
        "block": "immersive_weathering:weathered_iron_bars[east=true,north=true,south=false,waterlogged=false,west=false]"
      }
    ]
  },
  "slices": [
    [
      "",
      "",
      "",
      "",
      "",
      "",
      "",
      "",
      "",
      "",
      "",
      "",
      "",
      "",
      "",
      ""
    ],
    [
      "",
      "",
      "",
      "",
      "",
      "",
      "",
      "",
      "",
      "",
      "",
      "",
      "",
      "",
      "",
      ""
    ],
    [
      "",
      "",
      "",
      "",
      "",
      "",
      "",
      "",
      "",
      "",
      "",
      "",
      "",
      "",
      "",
      ""
    ],
    [
      "",
      "",
      "",
      "",
      "",
      "",
      "",
      "",
      "",
      "",
      "",
      "",
      "",
      "",
      "",
      ""
    ],
    [
      "",
      "",
      "",
      "",
      "",
      "",
      "",
      "",
      "",
      "",
      "",
      "",
      "",
      "",
      "",
      ""
    ],
    [
      "",
      "",
      "",
      "",
      "",
      "",
      "",
      "",
      "",
      "",
      "",
      "",
      "",
      "",
      "",
      ""
    ]
  ]
}