{
  "xsize": 16,
  "zsize": 16,
  "palette": {
    "palette": [
      {
        "char": "",
        "block": "minecraft:air"
      },
      {
        "char": "",
        "block": "minecraft:smooth_stone_slab[type=bottom,waterlogged=false]"
      },
      {
        "char": "",
        "block": "minecraft:oak_fence[east=true,north=false,south=false,waterlogged=false,west=true]"
      },
      {
        "char": "",
        "block": "minecraft:oak_fence[east=false,north=false,south=true,waterlogged=false,west=true]"
      },
      {
        "char": "",
        "block": "minecraft:oak_fence[east=false,north=true,south=true,waterlogged=false,west=false]"
      },
      {
        "char": "",
        "block": "minecraft:oak_leaves[distance=7,persistent=true,waterlogged=false]"
      },
      {
        "char": "",
        "block": "minecraft:oak_fence[east=true,north=false,south=true,waterlogged=false,west=true]"
      },
      {
        "char": "",
        "block": "minecraft:oak_fence[east=false,north=true,south=false,waterlogged=false,west=true]"
      },
      {
        "char": "",
        "block": "minecraft:quartz_pillar[axis=y]"
      },
      {
        "char": "",
        "block": "minecraft:daylight_detector[inverted=false,power=15]",
        "tag": {
          "id": "minecraft:daylight_detector"
        }
      },
      {
        "char": "",
        "block": "minecraft:rail[shape=south_west,waterlogged=false]"
      },
      {
        "char": "",
        "block": "minecraft:rail[shape=north_west,waterlogged=false]"
      }
    ]
  },
  "slices": [
    [
      "",
      "",
      "",
      "",
      "",
      "",
      "",
      "",
      "",
      "",
      "",
      "",
      "",
      "",
      "",
      ""
    ],
    [
      "",
      "",
      "",
      "",
      "",
      "",
      "",
      "",
      "",
      "",
      "",
      "",
      "",
      "",
      "",
      ""
    ],
    [
      "",
      "",
      "",
      "",
      "",
      "",
      "",
      "",
      "",
      "",
      "",
      "",
      "",
      "",
      "",
      ""
    ],
    [
      "",
      "",
      "",
      "",
      "",
      "",
      "",
      "",
      "",
      "",
      "",
      "",
      "",
      "",
      "",
      ""
    ],
    [
      "",
      "",
      "",
      "",
      "",
      "",
      "",
      "",
      "",
      "",
      "",
      "",
      "",
      "",
      "",
      ""
    ],
    [
      "",
      "",
      "",
      "",
      "",
      "",
      "",
      "",
      "",
      "",
      "",
      "",
      "",
      "",
      "",
      ""
    ]
  ]
}