{
  "xsize": 16,
  "zsize": 16,
  "palette": {
    "palette": [
      {
        "char": "",
        "block": "minecraft:air"
      },
      {
        "char": "",
        "block": "immersive_weathering:weathered_iron_bars[east=false,north=false,south=true,waterlogged=false,west=false]"
      },
      {
        "char": "",
        "block": "immersive_weathering:exposed_iron_bars[east=true,north=false,south=false,waterlogged=false,west=false]"
      },
      {
        "char": "",
        "block": "immersive_weathering:exposed_iron_bars[east=false,north=true,south=true,waterlogged=false,west=true]"
      },
      {
        "char": "",
        "block": "immersive_weathering:exposed_iron_bars[east=true,north=true,south=false,waterlogged=false,west=false]"
      },
      {
        "char": "",
        "block": "immersive_weathering:weathered_iron_bars[east=true,north=false,south=false,waterlogged=false,west=true]"
      },
      {
        "char": "",
        "block": "immersive_weathering:weathered_iron_bars[east=false,north=false,south=true,waterlogged=false,west=true]"
      },
      {
        "char": "",
        "block": "immersive_weathering:weathered_iron_bars[east=false,north=true,south=false,waterlogged=false,west=false]"
      },
      {
        "char": "",
        "block": "immersive_weathering:exposed_iron_bars[east=false,north=false,south=true,waterlogged=false,west=false]"
      },
      {
        "char": "",
        "block": "immersive_weathering:exposed_iron_bars[east=false,north=true,south=false,waterlogged=false,west=false]"
      },
      {
        "char": "",
        "block": "immersive_weathering:weathered_iron_bars[east=true,north=true,south=false,waterlogged=false,west=false]"
      },
      {
        "char": "",
        "block": "immersive_weathering:exposed_iron_bars[east=false,north=false,south=true,waterlogged=false,west=true]"
      },
      {
        "char": "",
        "block": "immersive_weathering:exposed_iron_bars[east=false,north=true,south=true,waterlogged=false,west=false]"
      },
      {
        "char": "",
        "block": "minecraft:redstone_block"
      }
    ]
  },
  "slices": [
    [
      "",
      "",
      "",
      "",
      "",
      "",
      "",
      "",
      "",
      "",
      "",
      "",
      "",
      "",
      "",
      ""
    ],
    [
      "",
      "",
      "",
      "",
      "",
      "",
      "",
      "",
      "",
      "",
      "",
      "",
      "",
      "",
      "",
      ""
    ],
    [
      "",
      "",
      "",
      "",
      "",
      "",
      "",
      "",
      "",
      "",
      "",
      "",
      "",
      "",
      "",
      ""
    ],
    [
      "",
      "",
      "",
      "",
      "",
      "",
      "",
      "",
      "",
      "",
      "",
      "",
      "",
      "",
      "",
      ""
    ],
    [
      "",
      "",
      "",
      "",
      "",
      "",
      "",
      "",
      "",
      "",
      "",
      "",
      "",
      "",
      "",
      ""
    ],
    [
      "",
      "",
      "",
      "",
      "",
      "",
      "",
      "",
      "",
      "",
      "",
      "",
      "",
      "",
      "",
      ""
    ]
  ]
}