{
  "xsize": 16,
  "zsize": 16,
  "palette": {
    "palette": [
      {
        "char": " ",
        "block": "minecraft:air"
      },
      {
        "char": "f",
        "block": "minecraft:air"
      },
      {
        "char": "j",
        "block": "minecraft:air"
      },
      {
        "char": "p",
        "block": "minecraft:air"
      },
      {
        "char": "w",
        "block": "minecraft:air"
      },
      {
        "char": "e",
        "block": "minecraft:air"
      },
      {
        "char": "A",
        "block": "minecraft:air"
      },
      {
        "char": "m",
        "block": "minecraft:air"
      },
      {
        "char": "W",
        "block": "minecraft:air"
      },
      {
        "char": "n",
        "block": "minecraft:air"
      },
      {
        "char": "ͱ",
        "block": "minecraft:air"
      },
      {
        "char": "I",
        "block": "minecraft:air"
      },
      {
        "char": "ͷ",
        "block": "minecraft:air"
      },
      {
        "char": "d",
        "block": "minecraft:air"
      },
      {
        "char": "C",
        "block": "minecraft:tall_grass[half=lower]"
      },
      {
        "char": "t",
        "block": "minecraft:grass"
      },
      {
        "char": "Ά",
        "block": "minecraft:air"
      },
      {
        "char": "ю",
        "block": "minecraft:air"
      },
      {
        "char": "k",
        "block": "minecraft:air"
      },
      {
        "char": "g",
        "block": "minecraft:air"
      },
      {
        "char": "o",
        "block": "minecraft:air"
      },
      {
        "char": "h",
        "block": "minecraft:air"
      },
      {
        "char": "l",
        "block": "minecraft:air"
      },
      {
        "char": "b",
        "block": "minecraft:air"
      },
      {
        "char": "S",
        "block": "minecraft:air"
      },
      {
        "char": "c",
        "block": "minecraft:air"
      },
      {
        "char": "Ѷ",
        "block": "minecraft:air"
      },
      {
        "char": "ђ",
        "block": "minecraft:air"
      },
      {
        "char": "Ϛ",
        "block": "minecraft:air"
      },
      {
        "char": "Ϧ",
        "block": "minecraft:air"
      },
      {
        "char": "π",
        "block": "minecraft:air"
      },
      {
        "char": "ь",
        "block": "minecraft:air"
      },
      {
        "char": "ϧ",
        "block": "minecraft:air"
      },
      {
        "char": "1",
        "block": "minecraft:air"
      },
      {
        "char": "т",
        "block": "minecraft:air"
      },
      {
        "char": "΅",
        "block": "minecraft:air"
      },
      {
        "char": "R",
        "block": "minecraft:air"
      },
      {
        "char": "D",
        "block": "minecraft:tall_grass[half=upper]"
      },
      {
        "char": "Ι",
        "block": "minecraft:air"
      },
      {
        "char": "P",
        "block": "minecraft:air"
      },
      {
        "char": "a",
        "block": "minecraft:air"
      },
      {
        "char": "v",
        "block": "minecraft:air"
      },
      {
        "char": "0",
        "block": "minecraft:air"
      },
      {
        "char": "q",
        "block": "minecraft:air"
      }
    ]
  },
  "slices": [
    [
      "ffjpjjppfffjweAA",
      "fjjpfffjmfmjweee",
      "wpwwwwwwwwwwwWee",
      "wwwpjjfjmmwwwAee",
      "wwwfpmpmmmwwwnee",
      "fjmmmjfjmfmjeeͱe",
      "jImffjjjjmmmAWen",
      "fIfmjmjjjmppeppp",
      "jIfjpfmpjjppeppp",
      "fImfjjmjpffpeppp",
      "fIffjpfjmjffnppp",
      "jImmmmjfjpmfnppp",
      "jImmfpfffjmjeppp",
      "mIffmpmmjmffeppp",
      "eͷeeenneͱeeeeppp",
      "nennneenennnnppp"
    ],
    [
      " ddCddtt  Άюkg  ",
      "oootdddddhkolg  ",
      "btlSISISISbkkg  ",
      "bllt   cccoblg  ",
      "Ѷeђ Cct   ϚeϦ   ",
      " π         ь    ",
      "                ",
      "          tC tCt",
      "    t  t  t  tt ",
      "       ϧΆ  t tCt",
      "     t1т1    CtC",
      "       ΅ C    t ",
      "     t   R   tCt",
      "     C      Rt t",
      "           R  tC",
      "             Ctt"
    ],
    [
      " ddDddΙΙ  dPog  ",
      "oko d dddhbkbg  ",
      "kbbaaaaaaabbkg  ",
      "bbo    cc bbbg  ",
      "heg Dc     nc   ",
      " c              ",
      "                ",
      "           D  D ",
      "                ",
      "              D ",
      "             D D",
      "         D      ",
      "              D ",
      "     D          ",
      "               D",
      "             D  "
    ],
    [
      " dd dd    dPog  ",
      "kko d  dd lblg  ",
      "lbbavvavvablbg  ",
      "olo    c  obbg  ",
      "heg  c     0c   ",
      " c              ",
      "                ",
      "                ",
      "                ",
      "                ",
      "                ",
      "                ",
      "                ",
      "                ",
      "                ",
      "                "
    ],
    [
      " dd dd    dPlg  ",
      "bko d  dd bbkg  ",
      "lbbaaaaaaallkg  ",
      "obo    c  bblg  ",
      "hng  c     ec   ",
      " c              ",
      "                ",
      "                ",
      "                ",
      "                ",
      "                ",
      "                ",
      "                ",
      "                ",
      "                ",
      "                "
    ],
    [
      " dd ddqq  ddbg  ",
      "oko    dd bobg  ",
      "bllavvavvalbog  ",
      "oko       lbog  ",
      "heg  c     ec   ",
      " c              ",
      "                ",
      "                ",
      "                ",
      "                ",
      "                ",
      "                ",
      "                ",
      "                ",
      "                ",
      "                "
    ]
  ]
}