{
  "xsize": 16,
  "zsize": 16,
  "palette": {
    "palette": [
      {
        "char": " ",
        "block": "minecraft:air"
      },
      {
        "char": "k",
        "block": "minecraft:air"
      },
      {
        "char": "g",
        "block": "minecraft:air"
      },
      {
        "char": "j",
        "block": "minecraft:air"
      },
      {
        "char": "l",
        "block": "minecraft:air"
      },
      {
        "char": "h",
        "block": "minecraft:air"
      },
      {
        "char": "a",
        "block": "minecraft:air"
      },
      {
        "char": "R",
        "block": "minecraft:air"
      },
      {
        "char": "M",
        "block": "minecraft:air"
      },
      {
        "char": "m",
        "block": "minecraft:air"
      },
      {
        "char": "d",
        "block": "minecraft:air"
      },
      {
        "char": "ε",
        "block": "minecraft:air"
      },
      {
        "char": "c",
        "block": "minecraft:grass"
      },
      {
        "char": "G",
        "block": "minecraft:air"
      },
      {
        "char": "e",
        "block": "minecraft:air"
      },
      {
        "char": "q",
        "block": "minecraft:air"
      },
      {
        "char": "s",
        "block": "minecraft:air"
      },
      {
        "char": "f",
        "block": "minecraft:air"
      },
      {
        "char": "b",
        "block": "minecraft:air"
      },
      {
        "char": "i",
        "block": "minecraft:air"
      },
      {
        "char": "β",
        "block": "minecraft:air"
      },
      {
        "char": "r",
        "block": "minecraft:air"
      },
      {
        "char": "Φ",
        "block": "minecraft:air"
      },
      {
        "char": "o",
        "block": "minecraft:air"
      },
      {
        "char": "Θ",
        "block": "minecraft:air"
      },
      {
        "char": "έ",
        "block": "minecraft:air"
      },
      {
        "char": "Ε",
        "block": "minecraft:air"
      }
    ]
  },
  "slices": [
    [
      "kgjlghgahhhjghgh",
      "RRMmRdjεhlkgggjg",
      "ddddddgεjkjjgahl",
      "aaddddjεjhhlhhha",
      "aaamddhggjjjhlkc",
      "jhGGkkgkhglhhlgg",
      "lllGddagljjkjgkk",
      "jalgaagagahhkkhj",
      "jjghddgakhajjgjg",
      "ljgkkalkghggljkj",
      "kaghddlgkllgjhhh",
      "gajaggglkglhklhg",
      "mmaaddggagghhaaa",
      "mmaaaGgkklgkggka",
      "mmaaddlggjhjkkhh",
      "glgaghjljgkljglk"
    ],
    [
      "   e  cc        ",
      "  qsf           ",
      "  q f  c        ",
      " cq f     c   cc",
      " ccbf           ",
      "   i            ",
      "                ",
      "ece cc c c c    ",
      "     f c  β     ",
      "     f          ",
      " c   f          ",
      " c ccf    c     ",
      "rr c    c    ccc",
      "Φrcccf         c",
      "rrcc f  c       ",
      "   c f          "
    ],
    [
      "   e            ",
      "  qsf           ",
      "  q f           ",
      "  q f           ",
      "  qof           ",
      "   i            ",
      "                ",
      "e e e           ",
      "     f          ",
      "     f          ",
      "     f          ",
      "     f          ",
      "                ",
      "Θf   f          ",
      "i    f          ",
      "     f          "
    ],
    [
      "   e            ",
      "  qbf           ",
      "  q f           ",
      "  q f           ",
      "  qof           ",
      "   i            ",
      "                ",
      "e e e           ",
      "     f          ",
      "     f          ",
      "     f          ",
      "     f          ",
      "                ",
      "of   f          ",
      "i    f          ",
      "     f          "
    ],
    [
      "   e            ",
      "  qbf           ",
      "  qέf           ",
      "  qΕf           ",
      "  qof           ",
      "   i            ",
      "                ",
      "e e e           ",
      "     f          ",
      "     f          ",
      "     f          ",
      "     f          ",
      "                ",
      "of   f          ",
      "i    f          ",
      "     f          "
    ],
    [
      "                ",
      "  qsf           ",
      "  qsf           ",
      "  qsf           ",
      "  qof           ",
      "   i            ",
      "                ",
      "e e e           ",
      "     f          ",
      "     f          ",
      "     f          ",
      "     f          ",
      "                ",
      "b    f          ",
      "i    f          ",
      "     f          "
    ]
  ]
}