{
  "xsize": 16,
  "zsize": 16,
  "palette": {
    "palette": [
      {
        "char": " ",
        "block": "minecraft:air"
      },
      {
        "char": "k",
        "block": "minecraft:air"
      },
      {
        "char": "p",
        "block": "minecraft:air"
      },
      {
        "char": "a",
        "block": "minecraft:air"
      },
      {
        "char": "d",
        "block": "minecraft:air"
      },
      {
        "char": "h",
        "block": "minecraft:air"
      },
      {
        "char": "g",
        "block": "minecraft:air"
      },
      {
        "char": "j",
        "block": "minecraft:air"
      },
      {
        "char": "l",
        "block": "minecraft:air"
      },
      {
        "char": "R",
        "block": "minecraft:air"
      },
      {
        "char": "m",
        "block": "minecraft:air"
      },
      {
        "char": "M",
        "block": "minecraft:air"
      },
      {
        "char": "c",
        "block": "minecraft:grass"
      },
      {
        "char": "e",
        "block": "minecraft:air"
      },
      {
        "char": "ό",
        "block": "minecraft:tall_grass[half=lower]"
      },
      {
        "char": "b",
        "block": "minecraft:air"
      },
      {
        "char": "o",
        "block": "minecraft:air"
      },
      {
        "char": "В",
        "block": "minecraft:air"
      },
      {
        "char": "s",
        "block": "minecraft:air"
      },
      {
        "char": "F",
        "block": "minecraft:air"
      },
      {
        "char": "B",
        "block": "minecraft:air"
      },
      {
        "char": "w",
        "block": "minecraft:air"
      },
      {
        "char": "T",
        "block": "minecraft:air"
      },
      {
        "char": "ϻ",
        "block": "minecraft:air",
        "tag": {
          "z": 600,
          "x": 112,
          "ForgeData": {
            "LockFlag": "1b"
          },
          "ForgeCaps": {},
          "id": "minecraft:trapped_chest",
          "y": 133,
          "Items": []
        }
      },
      {
        "char": "Ζ",
        "block": "minecraft:air"
      },
      {
        "char": "Ѕ",
        "block": "minecraft:air"
      },
      {
        "char": "ϡ",
        "block": "minecraft:air"
      },
      {
        "char": "α",
        "block": "minecraft:air"
      },
      {
        "char": "π",
        "block": "minecraft:tall_grass[half=upper]"
      },
      {
        "char": "f",
        "block": "minecraft:air"
      },
      {
        "char": "i",
        "block": "minecraft:air"
      },
      {
        "char": "r",
        "block": "minecraft:air"
      },
      {
        "char": "Ͱ",
        "block": "minecraft:air"
      },
      {
        "char": "ν",
        "block": "minecraft:air"
      },
      {
        "char": "n",
        "block": "minecraft:air"
      },
      {
        "char": "O",
        "block": "minecraft:air"
      },
      {
        "char": "z",
        "block": "minecraft:air"
      },
      {
        "char": "D",
        "block": "minecraft:air"
      }
    ]
  },
  "slices": [
    [
      "kpaaddhhaggkakgh",
      "apaaddkgjklkglhl",
      "gpaadRhhkghjjggk",
      "mmaaRMkhgghlljhg",
      "dmaaMMgkgllaghkg",
      "dmaaRdhjakkllhlj",
      "dmaaRdjhkjgjkhkh",
      "dmaaddlkkhahklll",
      "dmaaddhaakkghjjk",
      "dmaadMalaahjjhhj",
      "dmaadRhjgjallaah",
      "dmaaRdgghhhjlgkg",
      "dmaadMjklhhggkka",
      "dmaaddhalhgkajhj",
      "mmaaMdlggjhkglhk",
      "aaaaaMajhhkkghak"
    ],
    [
      "  cc    c  cc   ",
      "c cc            ",
      "eeόc            ",
      "boВcc           ",
      "esFc            ",
      "Bbcc    c       ",
      "wbTc          c ",
      "woFcc     c     ",
      "ϻscc   cc c     ",
      "wsFc  c cc      ",
      "woccc     c  cc ",
      "woFc  ΖЅϡ       ",
      "BbFc            ",
      " bFc   c    c   ",
      "sbcc      c     ",
      "αcccc c     c c "
    ],
    [
      "                ",
      "                ",
      "eeπ             ",
      "oof             ",
      " of             ",
      "Bsf             ",
      "wb              ",
      "wbT             ",
      "wo              ",
      "wb              ",
      "wb              ",
      "wbf             ",
      "Bbf             ",
      " bf             ",
      "ssf             ",
      " i              "
    ],
    [
      "                ",
      "                ",
      "ee              ",
      "obf             ",
      " bf             ",
      "rbf             ",
      " b              ",
      "Ͱb              ",
      " bT             ",
      "νb              ",
      " b              ",
      "Ͱsf             ",
      "rbf             ",
      " of             ",
      "bbf             ",
      " i              "
    ],
    [
      "                ",
      "                ",
      "ee              ",
      "nnf             ",
      "bnf             ",
      "bnf             ",
      "bn              ",
      "bnT             ",
      "bn              ",
      "bnT             ",
      "onO             ",
      "bnf             ",
      "bnf             ",
      "bnf             ",
      "nnf             ",
      " i              "
    ],
    [
      "                ",
      "                ",
      "ee              ",
      "zz              ",
      " z              ",
      "TD              ",
      "TzT             ",
      " D              ",
      " z              ",
      " D              ",
      " zT             ",
      " D              ",
      " z              ",
      " D              ",
      "Dz              ",
      " i              "
    ]
  ]
}