{
  "xsize": 16,
  "zsize": 16,
  "palette": {
    "palette": [
      {
        "char": "",
        "block": "minecraft:air"
      },
      {
        "char": "",
        "block": "minecraft:blackstone"
      },
      {
        "char": "",
        "block": "minecraft:cyan_terracotta"
      },
      {
        "char": "",
        "block": "minecraft:cobbled_deepslate"
      },
      {
        "char": "",
        "block": "minecraft:basalt[axis=x]"
      },
      {
        "char": "",
        "block": "minecraft:deepslate[axis=y]"
      },
      {
        "char": "",
        "block": "minecraft:grass_block[snowy=false]"
      },
      {
        "char": "",
        "block": "minecraft:polished_diorite"
      },
      {
        "char": "",
        "block": "minecraft:diorite"
      },
      {
        "char": "",
        "block": "minecraft:dirt"
      },
      {
        "char": "",
        "block": "minecraft:quartz_block"
      },
      {
        "char": "",
        "block": "minecraft:white_concrete"
      },
      {
        "char": "",
        "block": "immersive_weathering:mossy_stone"
      },
      {
        "char": "",
        "block": "minecraft:vine[east=false,north=false,south=true,up=false,west=false]"
      },
      {
        "char": "",
        "block": "minecraft:grass"
      },
      {
        "char": "",
        "block": "minecraft:vine[east=true,north=false,south=false,up=false,west=false]"
      },
      {
        "char": "",
        "block": "minecraft:cracked_stone_bricks"
      },
      {
        "char": "",
        "block": "minecraft:vine[east=false,north=false,south=false,up=false,west=true]"
      },
      {
        "char": "",
        "block": "infectious:barbed_wire[facing=north,waterlogged=false]"
      },
      {
        "char": "",
        "block": "infectious:wooden_barricades[facing=north,waterlogged=false]"
      },
      {
        "char": "",
        "block": "minecraft:mossy_stone_bricks"
      },
      {
        "char": "",
        "block": "minecraft:vine[east=false,north=true,south=false,up=false,west=false]"
      },
      {
        "char": "",
        "block": "minecraft:azure_bluet"
      },
      {
        "char": "",
        "block": "minecraft:smooth_stone_slab[type=bottom,waterlogged=false]"
      },
      {
        "char": "",
        "block": "minecraft:mossy_cobblestone_slab[type=double,waterlogged=false]"
      },
      {
        "char": "",
        "block": "minecraft:mossy_cobblestone"
      },
      {
        "char": "",
        "block": "minecraft:stone_bricks[weathering=false]"
      },
      {
        "char": "",
        "block": "immersive_weathering:cracked_stone_brick_stairs[facing=north,half=top,shape=straight,waterlogged=false]"
      },
      {
        "char": "",
        "block": "minecraft:stone_brick_stairs[facing=south,half=top,shape=straight,waterlogged=false,weathering=false]"
      }
    ]
  },
  "slices": [
    [
      "",
      "",
      "",
      "",
      "",
      "",
      "",
      "",
      "",
      "",
      "",
      "",
      "",
      "",
      "",
      ""
    ],
    [
      "",
      "",
      "",
      "",
      "",
      "",
      "",
      "",
      "",
      "",
      "",
      "",
      "",
      "",
      "",
      ""
    ],
    [
      "",
      "",
      "",
      "",
      "",
      "",
      "",
      "",
      "",
      "",
      "",
      "",
      "",
      "",
      "",
      ""
    ],
    [
      "",
      "",
      "",
      "",
      "",
      "",
      "",
      "",
      "",
      "",
      "",
      "",
      "",
      "",
      "",
      ""
    ],
    [
      "",
      "",
      "",
      "",
      "",
      "",
      "",
      "",
      "",
      "",
      "",
      "",
      "",
      "",
      "",
      ""
    ],
    [
      "",
      "",
      "",
      "",
      "",
      "",
      "",
      "",
      "",
      "",
      "",
      "",
      "",
      "",
      "",
      ""
    ]
  ]
}